Workbook

Sheet 2024
A1: Evolución de las exportaciones con origen en la provincia de Santa Fe, según destino. Período enero - diciembre de 2024.
B4: Enero - diciembre 2024
A5: País de destino | B5: Valor F.O.B. | C5: Peso Neto
B6: (en Dólares) | C6: (en Kilos)
A8: TOTAL | B8: 1.4741189e+10 | C8: 2.7122805e+10
A10: AFRICA | B10: 1.1020422e+09 | C10: 2.5123924e+09
A11: Burkina Faso | B11: 31015.42 | C11: 55525.25
A12: Argelia | B12: 2.4129376e+08 | C12: 5.2202884e+08
A13: Camerún | B13: 32010378 | C13: 79977519
A14: Congo | B14: 4304223.5 | C14: 11921413
A15: Rep. Democrática del Congo (ex Zaire) | B15: 10976255 | C15: 14804866
A16: Costa de Marfil | B16: 52849964 | C16: 1.3351468e+08
A17: Benin | B17: 23401.21 | C17: 41900.6
A18: Egipto | B18: 1.5466429e+08 | C18: 4.1845477e+08
A19: Gabón | B19: 4658601.3 | C19: 1441291.9
A20: Gambia | B20: 610839.92 | C20: 2317593.6
... A75: Bahrein | B75: 702487.02 | C75: 160970.3
A76: Myanmar (ex Birmania) Unión de | B76: - | C76: -
A77: Camboya (ex Kampuchea) | B77: 2049541.5 | C77: 272570.6
A78: Corea Republicana | B78: 1.4803087e+08 | C78: 4.1755326e+08
A79: China | B79: 1.0848704e+09 | C79: 1.3916531e+09
A80: Filipinas | B80: 1.4139776e+08 | C80: 3.6373312e+08
A81: Taiwan | B81: 22514308 | C81: 43596891
A82: India | B82: 1.719881e+09 | C82: 1.8433775e+09
A83: Indonesia | B83: 2.8846134e+08 | C83: 8.1283454e+08
A84: Iraq | B84: 1.1761041e+08 | C84: 2.9692189e+08
A85: Israel | B85: 1.2987891e+08 | C85: 2.0021424e+08
A86: Japón | B86: 8439999.9 | C86: 13408132
A87: Jordania | B87: 97901110 | C87: 2.4852462e+08
A88: Qatar | B88: 3099972.4 | C88: 8023226.8
... A92: Omán | B92: 40661376 | C92: 98138089
A93: Mongolia | B93: - | C93: -
A94: Nepal | B94: 547100.19 | C94: 1091768.7
A95: Emiratos Arabes Unidos | B95: 48666738 | C95: 1.326091e+08
A96: Paquistán | B96: 1.1170687e+08 | C96: 1.1062023e+08
A97: Singapur | B97: 2015747.1 | C97: 1148455.4
A98: Siria | B98: 254129.88 | C98: 1371859.5
A99: Tailandia | B99: 79232978 | C99: 67910452
A100: Vietnam | B100: 1.1736001e+09 | C100: 3.2269568e+09
A101: Hong Kong | B101: 6170272.8 | C101: 2622048.4
...

Sheet Hoja1
C1: =+SUM(C4:C209) -> 1 | D1: =+SUM(D4:D209) -> 0.99427098 | E1: =1-D1 -> 0.0057290164
C3: 2001 | D3: 2001
B4: Afganistán | C4: =IF(ISNA(VLOOKUP(B4,'2001'!$F$9:$G$142,2,FALSE)),"",VLOOKUP(B4,'2001'!$F$9:$G$142,2,FALSE)) | D4: =IF(ISNA(VLOOKUP(C4,'2001'!$F$9:$G$142,2,FALSE)),"",VLOOKUP(C4,'2001'!$F$9:$G$142,2,FALSE))
B5: Albania | C5: =IF(ISNA(VLOOKUP($B5,'2001'!$F$9:$G$142,2,FALSE)),"",VLOOKUP($B5,'2001'!$F$9:$G$142,2,FALSE)) -> 2.466326e-05 | D5: =IF(ISNA(VLOOKUP($B5,'2002'!$F$9:$G$142,2,FALSE)),"",VLOOKUP($B5,'2002'!$F$9:$G$142,2,FALSE)) -> 4.9415226e-05
B6: Argelia | C6: =IF(ISNA(VLOOKUP($B6,'2001'!$F$9:$G$142,2,FALSE)),"",VLOOKUP($B6,'2001'!$F$9:$G$142,2,FALSE)) -> 0.010150497 | D6: =IF(ISNA(VLOOKUP($B6,'2002'!$F$9:$G$142,2,FALSE)),"",VLOOKUP($B6,'2002'!$F$9:$G$142,2,FALSE)) -> 0.010615883
B7: Andorra | C7: =IF(ISNA(VLOOKUP($B7,'2001'!$F$9:$G$142,2,FALSE)),"",VLOOKUP($B7,'2001'!$F$9:$G$142,2,FALSE)) | D7: =IF(ISNA(VLOOKUP($B7,'2002'!$F$9:$G$142,2,FALSE)),"",VLOOKUP($B7,'2002'!$F$9:$G$142,2,FALSE))
B8: Angola | C8: =IF(ISNA(VLOOKUP($B8,'2001'!$F$9:$G$142,2,FALSE)),"",VLOOKUP($B8,'2001'!$F$9:$G$142,2,FALSE)) -> 0.00011048815 | D8: =IF(ISNA(VLOOKUP($B8,'2002'!$F$9:$G$142,2,FALSE)),"",VLOOKUP($B8,'2002'!$F$9:$G$142,2,FALSE)) -> 0.00030802196
B9: Antigua y Barbuda | C9: =IF(ISNA(VLOOKUP($B9,'2001'!$F$9:$G$142,2,FALSE)),"",VLOOKUP($B9,'2001'!$F$9:$G$142,2,FALSE)) -> 1.1037597e-05 | D9: =IF(ISNA(VLOOKUP($B9,'2002'!$F$9:$G$142,2,FALSE)),"",VLOOKUP($B9,'2002'!$F$9:$G$142,2,FALSE)) -> 5.0026492e-06
B10: Armenia | C10: =IF(ISNA(VLOOKUP($B10,'2001'!$F$9:$G$142,2,FALSE)),"",VLOOKUP($B10,'2001'!$F$9:$G$142,2,FALSE)) | D10: =IF(ISNA(VLOOKUP($B10,'2002'!$F$9:$G$142,2,FALSE)),"",VLOOKUP($B10,'2002'!$F$9:$G$142,2,FALSE))
B11: Aruba | C11: =IF(ISNA(VLOOKUP($B11,'2001'!$F$9:$G$142,2,FALSE)),"",VLOOKUP($B11,'2001'!$F$9:$G$142,2,FALSE)) | D11: =IF(ISNA(VLOOKUP($B11,'2002'!$F$9:$G$142,2,FALSE)),"",VLOOKUP($B11,'2002'!$F$9:$G$142,2,FALSE))
B12: Australia | C12: =IF(ISNA(VLOOKUP($B12,'2001'!$F$9:$G$142,2,FALSE)),"",VLOOKUP($B12,'2001'!$F$9:$G$142,2,FALSE)) -> 0.0049196107 | D12: =IF(ISNA(VLOOKUP($B12,'2002'!$F$9:$G$142,2,FALSE)),"",VLOOKUP($B12,'2002'!$F$9:$G$142,2,FALSE))
B13: Austria | C13: =IF(ISNA(VLOOKUP($B13,'2001'!$F$9:$G$142,2,FALSE)),"",VLOOKUP($B13,'2001'!$F$9:$G$142,2,FALSE)) -> 7.6266455e-05 | D13: =IF(ISNA(VLOOKUP($B13,'2002'!$F$9:$G$142,2,FALSE)),"",VLOOKUP($B13,'2002'!$F$9:$G$142,2,FALSE)) -> 7.3817205e-05
B14: Azerbaiján | C14: =IF(ISNA(VLOOKUP($B14,'2001'!$F$9:$G$142,2,FALSE)),"",VLOOKUP($B14,'2001'!$F$9:$G$142,2,FALSE)) | D14: =IF(ISNA(VLOOKUP($B14,'2002'!$F$9:$G$142,2,FALSE)),"",VLOOKUP($B14,'2002'!$F$9:$G$142,2,FALSE))
B15: Bahamas | C15: =IF(ISNA(VLOOKUP($B15,'2001'!$F$9:$G$142,2,FALSE)),"",VLOOKUP($B15,'2001'!$F$9:$G$142,2,FALSE)) | D15: =IF(ISNA(VLOOKUP($B15,'2002'!$F$9:$G$142,2,FALSE)),"",VLOOKUP($B15,'2002'!$F$9:$G$142,2,FALSE)) -> 1.2780752e-05
B16: Bahrein | C16: =IF(ISNA(VLOOKUP($B16,'2001'!$F$9:$G$142,2,FALSE)),"",VLOOKUP($B16,'2001'!$F$9:$G$142,2,FALSE)) -> 6.5546019e-05 | D16: =IF(ISNA(VLOOKUP($B16,'2002'!$F$9:$G$142,2,FALSE)),"",VLOOKUP($B16,'2002'!$F$9:$G$142,2,FALSE))
... B40: Comoras | C40: =IF(ISNA(VLOOKUP($B40,'2001'!$F$9:$G$142,2,FALSE)),"",VLOOKUP($B40,'2001'!$F$9:$G$142,2,FALSE)) | D40: =IF(ISNA(VLOOKUP($B40,'2002'!$F$9:$G$142,2,FALSE)),"",VLOOKUP($B40,'2002'!$F$9:$G$142,2,FALSE))
A41: Rep. Democrática del Congo (ex Zaire) | B41: Rep. Democrática del Congo | C41: =IF(ISNA(VLOOKUP($B41,'2001'!$F$9:$G$142,2,FALSE)),"",VLOOKUP($B41,'2001'!$F$9:$G$142,2,FALSE)) -> 5.1539717e-06 | D41: =IF(ISNA(VLOOKUP($B41,'2002'!$F$9:$G$142,2,FALSE)),"",VLOOKUP($B41,'2002'!$F$9:$G$142,2,FALSE)) -> 0.00010537804
B42: Congo | C42: =IF(ISNA(VLOOKUP($B42,'2001'!$F$9:$G$142,2,FALSE)),"",VLOOKUP($B42,'2001'!$F$9:$G$142,2,FALSE)) -> 0.00015674879 | D42: =IF(ISNA(VLOOKUP($B42,'2002'!$F$9:$G$142,2,FALSE)),"",VLOOKUP($B42,'2002'!$F$9:$G$142,2,FALSE)) -> 0.00081456361
B43: Costa Rica | C43: =IF(ISNA(VLOOKUP($B43,'2001'!$F$9:$G$142,2,FALSE)),"",VLOOKUP($B43,'2001'!$F$9:$G$142,2,FALSE)) -> 0.00087148173 | D43: =IF(ISNA(VLOOKUP($B43,'2002'!$F$9:$G$142,2,FALSE)),"",VLOOKUP($B43,'2002'!$F$9:$G$142,2,FALSE)) -> 0.00044245992
B44: Costa de Marfil | C44: =IF(ISNA(VLOOKUP($B44,'2001'!$F$9:$G$142,2,FALSE)),"",VLOOKUP($B44,'2001'!$F$9:$G$142,2,FALSE)) -> 0.00022874212 | D44: =IF(ISNA(VLOOKUP($B44,'2002'!$F$9:$G$142,2,FALSE)),"",VLOOKUP($B44,'2002'!$F$9:$G$142,2,FALSE)) -> 8.89659e-05
B45: Croacia | C45: =IF(ISNA(VLOOKUP($B45,'2001'!$F$9:$G$142,2,FALSE)),"",VLOOKUP($B45,'2001'!$F$9:$G$142,2,FALSE)) -> 0.00016490355 | D45: =IF(ISNA(VLOOKUP($B45,'2002'!$F$9:$G$142,2,FALSE)),"",VLOOKUP($B45,'2002'!$F$9:$G$142,2,FALSE))
B46: Curazao | C46: =IF(ISNA(VLOOKUP($B46,'2001'!$F$9:$G$142,2,FALSE)),"",VLOOKUP($B46,'2001'!$F$9:$G$142,2,FALSE)) | D46: =IF(ISNA(VLOOKUP($B46,'2002'!$F$9:$G$142,2,FALSE)),"",VLOOKUP($B46,'2002'!$F$9:$G$142,2,FALSE))
B47: Chipre | C47: =IF(ISNA(VLOOKUP($B47,'2001'!$F$9:$G$142,2,FALSE)),"",VLOOKUP($B47,'2001'!$F$9:$G$142,2,FALSE)) -> 0.0017523776 | D47: =IF(ISNA(VLOOKUP($B47,'2002'!$F$9:$G$142,2,FALSE)),"",VLOOKUP($B47,'2002'!$F$9:$G$142,2,FALSE)) -> 0.0020435775
B48: República Checa | C48: =IF(ISNA(VLOOKUP($B48,'2001'!$F$9:$G$142,2,FALSE)),"",VLOOKUP($B48,'2001'!$F$9:$G$142,2,FALSE)) -> 1.035711e-05 | D48: =IF(ISNA(VLOOKUP($B48,'2002'!$F$9:$G$142,2,FALSE)),"",VLOOKUP($B48,'2002'!$F$9:$G$142,2,FALSE))
B49: Dinamarca | C49: =IF(ISNA(VLOOKUP($B49,'2001'!$F$9:$G$142,2,FALSE)),"",VLOOKUP($B49,'2001'!$F$9:$G$142,2,FALSE)) -> 0.04001595 | D49: =IF(ISNA(VLOOKUP($B49,'2002'!$F$9:$G$142,2,FALSE)),"",VLOOKUP($B49,'2002'!$F$9:$G$142,2,FALSE)) -> 0.028932943
B50: Djibouti | C50: =IF(ISNA(VLOOKUP($B50,'2001'!$F$9:$G$142,2,FALSE)),"",VLOOKUP($B50,'2001'!$F$9:$G$142,2,FALSE)) | D50: =IF(ISNA(VLOOKUP($B50,'2002'!$F$9:$G$142,2,FALSE)),"",VLOOKUP($B50,'2002'!$F$9:$G$142,2,FALSE))
B51: Dominica | C51: =IF(ISNA(VLOOKUP($B51,'2001'!$F$9:$G$142,2,FALSE)),"",VLOOKUP($B51,'2001'!$F$9:$G$142,2,FALSE)) -> 4.651224e-06 | D51: =IF(ISNA(VLOOKUP($B51,'2002'!$F$9:$G$142,2,FALSE)),"",VLOOKUP($B51,'2002'!$F$9:$G$142,2,FALSE)) -> 3.6111378e-06
B52: República Dominicana | C52: =IF(ISNA(VLOOKUP($B52,'2001'!$F$9:$G$142,2,FALSE)),"",VLOOKUP($B52,'2001'!$F$9:$G$142,2,FALSE)) -> 0.0077331777 | D52: =IF(ISNA(VLOOKUP($B52,'2002'!$F$9:$G$142,2,FALSE)),"",VLOOKUP($B52,'2002'!$F$9:$G$142,2,FALSE)) -> 0.0082123724
B53: Ecuador | C53: =IF(ISNA(VLOOKUP($B53,'2001'!$F$9:$G$142,2,FALSE)),"",VLOOKUP($B53,'2001'!$F$9:$G$142,2,FALSE)) -> 0.0037146457 | D53: =IF(ISNA(VLOOKUP($B53,'2002'!$F$9:$G$142,2,FALSE)),"",VLOOKUP($B53,'2002'!$F$9:$G$142,2,FALSE)) -> 0.0054246268
... B75: Honduras | C75: =IF(ISNA(VLOOKUP($B75,'2001'!$F$9:$G$142,2,FALSE)),"",VLOOKUP($B75,'2001'!$F$9:$G$142,2,FALSE)) -> 0.00014160242 | D75: =IF(ISNA(VLOOKUP($B75,'2002'!$F$9:$G$142,2,FALSE)),"",VLOOKUP($B75,'2002'!$F$9:$G$142,2,FALSE)) -> 0.00013026875
A76: Hong Kong | B76: Hong Kong (China) | C76: =IF(ISNA(VLOOKUP($B76,'2001'!$F$9:$G$142,2,FALSE)),"",VLOOKUP($B76,'2001'!$F$9:$G$142,2,FALSE)) -> 0.0016344286 | D76: =IF(ISNA(VLOOKUP($B76,'2002'!$F$9:$G$142,2,FALSE)),"",VLOOKUP($B76,'2002'!$F$9:$G$142,2,FALSE)) -> 0.0020372793
B77: Hungría | C77: =IF(ISNA(VLOOKUP($B77,'2001'!$F$9:$G$142,2,FALSE)),"",VLOOKUP($B77,'2001'!$F$9:$G$142,2,FALSE)) -> 1.9979027e-05 | D77: =IF(ISNA(VLOOKUP($B77,'2002'!$F$9:$G$142,2,FALSE)),"",VLOOKUP($B77,'2002'!$F$9:$G$142,2,FALSE))
B78: Islandia | C78: =IF(ISNA(VLOOKUP($B78,'2001'!$F$9:$G$142,2,FALSE)),"",VLOOKUP($B78,'2001'!$F$9:$G$142,2,FALSE)) | D78: =IF(ISNA(VLOOKUP($B78,'2002'!$F$9:$G$142,2,FALSE)),"",VLOOKUP($B78,'2002'!$F$9:$G$142,2,FALSE))
B79: India | C79: =IF(ISNA(VLOOKUP($B79,'2001'!$F$9:$G$142,2,FALSE)),"",VLOOKUP($B79,'2001'!$F$9:$G$142,2,FALSE)) -> 0.057864148 | D79: =IF(ISNA(VLOOKUP($B79,'2002'!$F$9:$G$142,2,FALSE)),"",VLOOKUP($B79,'2002'!$F$9:$G$142,2,FALSE)) -> 0.060109724
B80: Indonesia | C80: =IF(ISNA(VLOOKUP($B80,'2001'!$F$9:$G$142,2,FALSE)),"",VLOOKUP($B80,'2001'!$F$9:$G$142,2,FALSE)) -> 0.0027500188 | D80: =IF(ISNA(VLOOKUP($B80,'2002'!$F$9:$G$142,2,FALSE)),"",VLOOKUP($B80,'2002'!$F$9:$G$142,2,FALSE)) -> 0.0061513217
B81: Irán | C81: =IF(ISNA(VLOOKUP($B81,'2001'!$F$9:$G$142,2,FALSE)),"",VLOOKUP($B81,'2001'!$F$9:$G$142,2,FALSE)) -> 0.02475185 | D81: =IF(ISNA(VLOOKUP($B81,'2002'!$F$9:$G$142,2,FALSE)),"",VLOOKUP($B81,'2002'!$F$9:$G$142,2,FALSE)) -> 0.021678065
B82: Iraq | C82: =IF(ISNA(VLOOKUP($B82,'2001'!$F$9:$G$142,2,FALSE)),"",VLOOKUP($B82,'2001'!$F$9:$G$142,2,FALSE)) -> 0.0017142542 | D82: =IF(ISNA(VLOOKUP($B82,'2002'!$F$9:$G$142,2,FALSE)),"",VLOOKUP($B82,'2002'!$F$9:$G$142,2,FALSE))
B83: Irlanda | C83: =IF(ISNA(VLOOKUP($B83,'2001'!$F$9:$G$142,2,FALSE)),"",VLOOKUP($B83,'2001'!$F$9:$G$142,2,FALSE)) -> 0.0026207736 | D83: =IF(ISNA(VLOOKUP($B83,'2002'!$F$9:$G$142,2,FALSE)),"",VLOOKUP($B83,'2002'!$F$9:$G$142,2,FALSE)) -> 0.0039012223
B84: Israel | C84: =IF(ISNA(VLOOKUP($B84,'2001'!$F$9:$G$142,2,FALSE)),"",VLOOKUP($B84,'2001'!$F$9:$G$142,2,FALSE)) -> 0.0038592713 | D84: =IF(ISNA(VLOOKUP($B84,'2002'!$F$9:$G$142,2,FALSE)),"",VLOOKUP($B84,'2002'!$F$9:$G$142,2,FALSE)) -> 0.0021933831
B85: Italia | C85: =IF(ISNA(VLOOKUP($B85,'2001'!$F$9:$G$142,2,FALSE)),"",VLOOKUP($B85,'2001'!$F$9:$G$142,2,FALSE)) -> 0.05925471 | D85: =IF(ISNA(VLOOKUP($B85,'2002'!$F$9:$G$142,2,FALSE)),"",VLOOKUP($B85,'2002'!$F$9:$G$142,2,FALSE)) -> 0.065343247
...

Sheet 2023
A1: Evolución de las exportaciones con origen en la provincia de Santa Fe, según destino. Período enero - diciembre de 2023.
B4: Enero - diciembre 2023
A5: País de destino | B5: Valor F.O.B. | C5: Peso Neto
B6: (en Dólares) | C6: (en Kilos)
A8: TOTAL | B8: 1.1632871e+10 | C8: 1.7467878e+10
A10: AFRICA | B10: 1.0606058e+09 | C10: 2.0531358e+09
A11: Burkina Faso | B11: 9852.18 | C11: 15304.5
A12: Argelia | B12: 2.2555616e+08 | C12: 4.6004873e+08
A13: Camerún | B13: 25269124 | C13: 43085774
A14: Congo | B14: 4140561.4 | C14: 6676966.9
A15: Rep. Democrática del Congo (ex Zaire) | B15: 7884983.6 | C15: 5483325.6
A16: Costa de Marfil | B16: 22854539 | C16: 40964314
A17: Benin | B17: 39528.69 | C17: 51518.11
A18: Egipto | B18: 3.512363e+08 | C18: 7.4721571e+08
A19: Gabón | B19: 4967264.5 | C19: 1154896.8
A20: Gambia | B20: - | C20: -
A21: Ghana | B21: 14082021 | C21: 26544971
A22: Guinea | B22: 73884.19 | C22: 94314.6
A23: Guinea Ecuatorial | B23: - | C23: -
A24: Kenya | B24: 101903.96 | C24: 14402.34
A25: Liberia | B25: 228817.45 | C25: 617978.64
A26: Libia | B26: 96928387 | C26: 1.9622151e+08
A27: Madagascar | B27: - | C27: -
A28: Malawi | B28: - | C28: -
A29: Mali | B29: 23057.86 | C29: 32598.16
A30: Marruecos | B30: 1.2837873e+08 | C30: 2.5195718e+08
A31: Mauricio | B31: 19492683 | C31: 32178532
A32: Mauritania | B32: - | C32: -
A33: Níger | B33: 18653.88 | C33: 25183.5
A34: Nigeria | B34: 4696656.3 | C34: 5142395.3
A35: Senegal | B35: 35177240 | C35: 80346121
A36: Tanzania | B36: 15694.38 | C36: 22671.91
A37: Togo | B37: 47071.75 | C37: 64841.4
A38: Túnez | B38: 801686.68 | C38: 3311104.2
A39: Uganda | B39: - | C39: -
A40: Angola | B40: 7101833.7 | C40: 10266782
A41: Cabo Verde | B41: 697272.39 | C41: 2427984.8
A42: Mozambique | B42: 52851944 | C42: 52939432
A43: Djibouti | B43: 80265.63 | C43: 106210.8
A44: Sudáfrica | B44: 57849719 | C44: 86125004
...

Sheet 2022
A1: Evolución de las exportaciones con origen en la provincia de Santa Fe, según destino. Período enero - diciembre de 2022.
B4: Enero - diciembre 2022
A5: País de destino | B5: Valor F.O.B. | C5: Peso Neto
B6: (en Dólares) | C6: (en Kilos)
A8: TOTAL | B8: 1.9196644e+10 | C8: 2.8893068e+10
A10: AFRICA | B10: 1.7555252e+09 | C10: 3.4920814e+09
A11: Burkina Faso | B11: 2074022.8 | C11: 6556734.6
A12: Argelia | B12: 3.9903363e+08 | C12: 6.9188183e+08
A13: Burundi | B13: - | C13: -
A14: Camerún | B14: 45463735 | C14: 1.0299861e+08
A15: Congo | B15: 15263369 | C15: 41625420
A16: Rep. Democrática del Congo (ex Zaire) | B16: 7594193.8 | C16: 16955103
A17: Costa de Marfil | B17: 53038316 | C17: 1.1869668e+08
A18: Benin | B18: 191822.45 | C18: 304584.41
A19: Egipto | B19: 2.0001908e+08 | C19: 4.4830544e+08
A20: Gabón | B20: 497293.48 | C20: 284645.48
A21: Gambia | B21: 4038342.8 | C21: 14075863
A22: Ghana | B22: 44306002 | C22: 99523046
A23: Guinea | B23: 1191080.1 | C23: 4052978.4
A24: Guinea Ecuatorial | B24: 123457 | C24: 57137.74
A25: Kenya | B25: 31180684 | C25: 1.0271687e+08
... A35: Nigeria | B35: 65804167 | C35: 1.7675226e+08
A36: Rwanda | B36: - | C36: -
A37: Senegal | B37: 59949928 | C37: 1.3261035e+08
A38: Sierra Leona | B38: - | C38: -
A39: Tanzania | B39: 12673930 | C39: 41578066
A40: Togo | B40: 2096692.2 | C40: 6974028.6
A41: Túnez | B41: 71213347 | C41: 1.5448145e+08
A42: Uganda | B42: 9521994 | C42: 31628898
A43: Angola | B43: 36248584 | C43: 80453553
A44: Cabo Verde | B44: 1787984.7 | C44: 6882564.6
A45: Mozambique | B45: 87159867 | C45: 68054906
A46: Djibouti | B46: 144283.79 | C46: 253106.4
A47: Sudáfrica | B47: 1.6975392e+08 | C47: 3.2501328e+08
A48: Etiopía | B48: 10587528 | C48: 34727633
A49: Sudán | B49: - | C49: -
A51: AMERICA | B51: 4.7842536e+09 | C51: 5.7544286e+09
A52: Bolivia | B52: 75572704 | C52: 64407880
A53: Brasil | B53: 1.5507331e+09 | C53: 1.5993442e+09
A54: Canadá | B54: 36573760 | C54: 26177898
...

Sheet 2021
A1: Evolución de las exportaciones con origen en la provincia de Santa Fe, según destino. Período enero - diciembre de 2021.
B4: Enero - diciembre 2021
A5: País de destino | B5: Valor F.O.B. | C5: Peso Neto
B6: (en Dólares) | C6: (en Kilos)
A8: TOTAL | B8: 17920340707 | C8: 31828253608
A10: AFRICA | B10: 1720665398 | C10: 3725660852
A11: Burkina Faso | B11: 102224 | C11: 349775
A12: Argelia | B12: 453526780 | C12: 865103592
A13: Burundi | B13: 295071 | C13: 1175460
A14: Camerún | B14: 6067502 | C14: 14246651
A15: Congo | B15: 5175469 | C15: 15241637
A16: Rep. Democrática del Congo (ex Zaire) | B16: - | C16: -
A17: Costa de Marfil | B17: 40163416 | C17: 109521817
A18: Benin | B18: 168087 | C18: 280185
A19: Egipto | B19: 407588137 | C19: 845564195
A20: Gabón | B20: 42428 | C20: 70173
A21: Gambia | B21: 1948075 | C21: 7968785
A22: Ghana | B22: 25783529 | C22: 67596153
A23: Guinea | B23: 2599797 | C23: 11513877
A24: Kenya | B24: 20384761 | C24: 77224803
A25: Liberia | B25: 580687 | C25: 2067808
A26: Libia | B26: 56825741 | C26: 130617387
A27: Madagascar | B27: - | C27: -
A28: Mali | B28: 1797707 | C28: 7313391
A29: Marruecos | B29: 175143996 | C29: 489320145
A30: Mauricio | B30: 24715131 | C30: 51365531
A31: Mauritania | B31: 8624364 | C31: 33498401
A32: Níger | B32: 39172 | C32: 66912
A33: Nigeria | B33: 40206135 | C33: 80350802
A34: Rwanda | B34: 1228959 | C34: 4973100
A35: Senegal | B35: 31951692 | C35: 100187595
A36: Sierra Leona | B36: 58767 | C36: 100975
A37: Tanzania | B37: 5254086 | C37: 21475716
A38: Togo | B38: 154883 | C38: 684744
A39: Túnez | B39: 49078528 | C39: 112670615
... A45: Sudáfrica | B45: 231934443 | C45: 491775475
A46: Etiopía | B46: - | C46: -
A47: Sudán | B47: 1185988 | C47: 120982
A49: AMERICA | B49: 3916572756 | C49: 5813369497
A50: Bolivia | B50: 84202736 | C50: 119605427
...

Sheet 2020
A1: Evolución de las exportaciones con origen en la provincia de Santa Fe, según destino. Período enero - diciembre de 2020.
B4: Enero - diciembre 2020
A5: País de destino | B5: Valor F.O.B. | C5: Peso Neto
B6: (en Dólares) | C6: (en Kilos)
A8: TOTAL | B8: 11378190324 | C8: 27336662291
A10: AFRICA | B10: 1157908995 | C10: 3577642443
A11: Burkina Faso | B11: 8691 | C11: 16280
A12: Argelia | B12: 329641439 | C12: 972058346
A13: Camerún | B13: 8045153 | C13: 24442841
A14: Congo | B14: 1240847 | C14: 5676401
A15: Rep. Democrática del Congo (ex Zaire) | B15: 2711144 | C15: 9612601
A16: Costa de Marfil | B16: 18727371 | C16: 54726399
A17: Benin | B17: 38471 | C17: 71934
A18: Egipto | B18: 254233127 | C18: 860440434
A19: Gabón | B19: 28956 | C19: 55515
A20: Gambia | B20: 1009688 | C20: 4669380
... A29: Mauricio | B29: 17372100 | C29: 53744879
A30: Mauritania | B30: - | C30: -
A31: Níger | B31: 26811 | C31: 52247
A32: Nigeria | B32: 13751629 | C32: 74509821
A33: Senegal | B33: 20823099 | C33: 80325553
A34: Sierra Leona | B34: 30229 | C34: 59062
A35: Tanzania | B35: 2656636 | C35: 13821570
A36: Togo | B36: 14129 | C36: 29215
A37: Túnez | B37: 28528554 | C37: 95374730
A38: Uganda | B38: 6602896 | C38: 33200068
A39: Angola | B39: 2833139 | C39: 11452904
A40: Cabo Verde | B40: 801430 | C40: 4797660
A41: Mozambique | B41: 59381933 | C41: 84734148
A42: Djibouti | B42: 310005 | C42: 605328
... A47: AMERICA | B47: 2448502199 | C47: 4481800322
A48: Barbados | B48: - | C48: -
A49: Bolivia | B49: 78812364 | C49: 140826482
A50: Brasil | B50: 919799474 | C50: 1527756526
A51: Canadá | B51: 2106454 | C51: 923966
A52: Colombia | B52: 60121325 | C52: 131015837
A53: Costa Rica | B53: 6825717 | C53: 15087137
A54: Cuba | B54: 44741724 | C54: 172080579
A55: Chile | B55: 447857632 | C55: 911232135
A56: República Dominicana | B56: 16773447 | C56: 31952246
...

Sheet 2019
A1: Evolución de las exportaciones con origen en la provincia de Santa Fe, según destino. Período enero - diciembre de 2019.
B4: Enero - diciembre 2019
A5: País de destino | B5: Valor F.O.B. | C5: Peso Neto
B6: (en Dólares) | C6: (en Kilos)
A8: TOTAL | B8: 14276570992 | C8: 34746482719
A10: AFRICA | B10: 1544908028 | C10: 4760784368
A11: Burkina Faso | B11: 14354 | C11: 30873
A12: Argelia | B12: 573207503 | C12: 1752652747
A13: Camerún | B13: 13470062 | C13: 42897335
A14: Congo | B14: 2265660 | C14: 9154326
A15: Rep. Democrática del Congo (ex Zaire) | B15: 1906265 | C15: 7235950
A16: Costa de Marfil | B16: 31820035 | C16: 101405706
A17: Benin | B17: 44078 | C17: 95807
A18: Egipto | B18: 308783549 | C18: 874922185
A19: Gabón | B19: 20231 | C19: 42745
A20: Gambia | B20: 439123 | C20: 1533187
... A44: Etiopía | B44: 3411563 | C44: 16774752
A45: Sudán | B45: - | C45: -
A47: AMERICA | B47: 2819432406 | C47: 4466607698
A48: Barbados | B48: 257081 | C48: 120870
A49: Bolivia | B49: 91336276 | C49: 116623517
A50: Brasil | B50: 1114937768 | C50: 1275127325
A51: Canadá | B51: 12577314 | C51: 15408754
A52: Colombia | B52: 78338486 | C52: 214481850
A53: Costa Rica | B53: 4507532 | C53: 10090554
A54: Cuba | B54: 57752831 | C54: 208065060
A55: Chile | B55: 409885093 | C55: 813625316
A56: República Dominicana | B56: 50537012 | C56: 96578116
A57: Ecuador | B57: 79490008 | C57: 229954800
A58: El Salvador | B58: 943247 | C58: 662456
... A63: Honduras | B63: 1825089 | C63: 892682
A64: Jamaica | B64: - | C64: -
A65: México | B65: 49196327 | C65: 27149087
A66: Nicaragua | B66: 1840043 | C66: 168599
A67: Panamá | B67: 7568435 | C67: 9102868
A68: Paraguay | B68: 153115869 | C68: 153083668
A69: Perú | B69: 389080602 | C69: 873740508
A70: Puerto Rico(Estado Asociado) | B70: 3972712 | C70: 15102126
A71: Trinidad y Tobago | B71: 376528 | C71: 586955
A72: Uruguay | B72: 105264418 | C72: 148962887
...

Sheet 2018
A1: Evolución de las exportaciones con origen en la provincia de Santa Fe, según destino. Período enero - diciembre de 2018.
B4: Enero - diciembre 2018
A5: País de destino | B5: Valor F.O.B. | C5: Peso Neto
B6: (en Dólares) | C6: (en Kilos)
A8: TOTAL | B8: 1.3659627e+10 | C8: 2.8231705e+10
A10: AFRICA | B10: 1.6556214e+09 | C10: 4.2499859e+09
A11: Burkina Faso | B11: 195781.29 | C11: 1080319.1
A12: Argelia | B12: 6.9360365e+08 | C12: 1.8451169e+09
A13: Camerún | B13: 20969821 | C13: 55735577
A14: Congo | B14: 2560641.3 | C14: 5880033.8
A15: Rep. Democrática del Congo (ex Zaire) | B15: 2368487.7 | C15: 9539603
A16: Costa de Marfil | B16: 29818106 | C16: 80041484
A17: Benin | B17: 55243.13 | C17: 107578.06
A18: Egipto | B18: 3.7551273e+08 | C18: 9.89435e+08
A19: Gabón | B19: 571528.09 | C19: 308213.99
A20: Gambia | B20: 267725.93 | C20: 1134871
... A30: Mauritania | B30: 5198406.9 | C30: 27770004
A31: Níger | B31: - | C31: -
A32: Nigeria | B32: 9740106.4 | C32: 40876411
A33: Senegal | B33: 21882286 | C33: 79664702
A34: Sierra Leona | B34: 56827.16 | C34: 110632.72
A35: Tanzania | B35: 1776387.8 | C35: 9619414
A36: Togo | B36: 26707.7 | C36: 53534.48
A37: Túnez | B37: 25285484 | C37: 52687706
A38: Uganda | B38: 2352904.2 | C38: 12415722
A39: Angola | B39: 2834534.8 | C39: 5835966.4
A40: Cabo Verde | B40: 741739.44 | C40: 4168667.8
A41: Mozambique | B41: 47817477 | C41: 68472670
A42: Djibouti | B42: 110984.07 | C42: 231697
A43: Sudáfrica | B43: 1.7390964e+08 | C43: 3.9380465e+08
... A47: AMERICA | B47: 3.0855284e+09 | C47: 4.1114306e+09
A48: Barbados | B48: - | C48: -
A49: Bolivia | B49: 90074748 | C49: 1.1366348e+08
A50: Brasil | B50: 1.27624e+09 | C50: 1.3223041e+09
A51: Canadá | B51: 28714765 | C51: 38515461
A52: Colombia | B52: 52406810 | C52: 79566487
A53: Costa Rica | B53: 2121448.3 | C53: 2257787.9
A54: Cuba | B54: 52715506 | C54: 1.6575137e+08
A55: Chile | B55: 3.9991855e+08 | C55: 6.9835331e+08
A56: República Dominicana | B56: 9564584.4 | C56: 16028825
...

Sheet 2017
A1: Evolución de las exportaciones con origen en la provincia de Santa Fe, según destino. Período enero - diciembre de 2017.
B4: Enero - diciembre 2017
A5: País de destino | B5: Valor F.O.B. | C5: Peso Neto
B6: (en Dólares) | C6: (en Kilos)
A8: TOTAL | B8: 13760730242 | C8: 32478765441
A10: AFRICA | B10: 1657302681 | C10: 5046525614
A11: Burkina Faso | B11: 496327 | C11: 2627186
A12: Argelia | B12: 512609156 | C12: 1656412330
A13: Burundi | B13: 551533 | C13: 3010866
A14: Camerún | B14: 8551764 | C14: 32113917
A15: Congo | B15: 1446228 | C15: 3227467
A16: Rep. Democrática del Congo (ex Zaire) | B16: 3794232 | C16: 14689775
A17: Costa de Marfil | B17: 16481267 | C17: 56816169
A18: Benin | B18: 154144 | C18: 161179
A19: Egipto | B19: 531252094 | C19: 1549214272
A20: Gabón | B20: 1052316 | C20: 2843521
... A178: Islas Salomón | B178: 17907 | C178: 33329
A180: DESCONOCIDO | B180: - | C180: -
A181: SIN DECLARAR - DESCONOCIDO - IGNORADO (CONTINENTE) | B181: - | C181: -
A182: Nota: Los datos se presentan protegidos de acuerdo a la normativa vigente sobre secreto estadístico y protección de datos individuales (art. 10º de la ley 17.622; título VI del decreto 3.110; art. 1º de la disposición 176/99, entre otros).
A183: (-) dato igual a cero.
A184: /// Dato que no corresponde presentar debido a la naturaleza de las cosas o del cálculo.
A185: Fuente: IPEC - INDEC.

Sheet 2016
A1: Evolución de las exportaciones con origen en la provincia de Santa Fe, según destino. Enero - diciembre de 2016.
B4: A Ñ O 2 0 1 6
A5: PAIS DE DESTINO | B5: VALOR F.O.B. | C5: PESO NETO
B6: (en Dólares) | C6: (en Kilos)
A8: TOTAL | B8: 13829380695 | C8: 32170096041
A10: AFRICA | B10: 1858395967 | C10: 5239322058 | D10: =+B10/$B$8 -> 0.13438027 | F10: {=+_xlfn.UNIQUE(A10:A155)} -> AFRICA | G10: =+SUMIF(A10:A155,F10,D10:D155) -> 0.13438027
A11: Burkina Faso | B11: 216064 | C11: 115436 | D11: =+B11/$B$8 -> 1.5623548e-05 | F11: Burkina Faso | G11: =+SUMIF(A11:A156,F11,D11:D156) -> 1.5623548e-05
A12: Argelia | B12: 517143557 | C12: 1476332755 | D12: =+B12/$B$8 -> 0.037394556 | F12: Argelia | G12: =+SUMIF(A12:A157,F12,D12:D157) -> 0.037394556
A13: Botswana | B13: 94624 | C13: 12460 | D13: =+B13/$B$8 -> 6.8422442e-06 | F13: Botswana | G13: =+SUMIF(A13:A158,F13,D13:D158) -> 6.8422442e-06
A14: Burundi | B14: 58989 | C14: 331400 | D14: =+B14/$B$8 -> 4.2654838e-06 | F14: Burundi | G14: =+SUMIF(A14:A159,F14,D14:D159) -> 4.2654838e-06
A15: Camerún | B15: 9049337 | C15: 26705595 | D15: =+B15/$B$8 -> 0.00065435591 | F15: Camerún | G15: =+SUMIF(A15:A160,F15,D15:D160) -> 0.00065435591
A16: Congo | B16: 403642 | C16: 450418 | D16: =+B16/$B$8 -> 2.918728e-05 | F16: Congo | G16: =+SUMIF(A16:A161,F16,D16:D161) -> 2.918728e-05
A17: Rep. Democrática del Congo (ex Zaire) | B17: 975837 | C17: 2784665 | D17: =+B17/$B$8 -> 7.0562596e-05 | F17: Rep. Democrática del Congo (ex Zaire) | G17: =+SUMIF(A17:A162,F17,D17:D162) -> 7.0562596e-05
A18: Costa de Marfil | B18: 8879317 | C18: 27183300 | D18: =+B18/$B$8 -> 0.0006420618 | F18: Costa de Marfil | G18: =+SUMIF(A18:A163,F18,D18:D163) -> 0.0006420618
A19: Chad | B19: - | C19: - | D19: =+B19/$B$8 -> #VALUE! | F19: Chad | G19: =+SUMIF(A19:A164,F19,D19:D164) -> #VALUE!
A20: Benin | B20: 45281 | C20: 94740 | D20: =+B20/$B$8 -> 3.2742609e-06 | F20: Benin | G20: =+SUMIF(A20:A165,F20,D20:D165) -> 3.2742609e-06
A21: Egipto | B21: 741395315 | C21: 1875674186 | D21: =+B21/$B$8 -> 0.05361016 | F21: Egipto | G21: =+SUMIF(A21:A166,F21,D21:D166) -> 0.05361016
A22: Gabón | B22: 43570 | C22: 65830 | D22: =+B22/$B$8 -> 3.1505388e-06 | F22: Gabón | G22: =+SUMIF(A22:A167,F22,D22:D167) -> 3.1505388e-06
A23: Gambia | B23: 388143 | C23: 1324584 | D23: =+B23/$B$8 -> 2.806655e-05 | F23: Gambia | G23: =+SUMIF(A23:A168,F23,D23:D168) -> 2.806655e-05
A24: Ghana | B24: 5558807 | C24: 18992784 | D24: =+B24/$B$8 -> 0.00040195632 | F24: Ghana | G24: =+SUMIF(A24:A169,F24,D24:D169) -> 0.00040195632
A25: Guinea | B25: 104926 | C25: 91183 | D25: =+B25/$B$8 -> 7.58718e-06 | F25: Guinea | G25: =+SUMIF(A25:A170,F25,D25:D170) -> 7.58718e-06
A26: Kenya | B26: 3121770 | C26: 15296708 | D26: =+B26/$B$8 -> 0.00022573462 | F26: Kenya | G26: =+SUMIF(A26:A171,F26,D26:D171) -> 0.00022573462
A27: Lesotho | B27: 107397 | C27: 74631 | D27: =+B27/$B$8 -> 7.7658575e-06 | F27: Lesotho | G27: =+SUMIF(A27:A172,F27,D27:D172) -> 7.7658575e-06
A28: Liberia | B28: 73519 | C28: 154140 | D28: =+B28/$B$8 -> 5.3161455e-06 | F28: Liberia | G28: =+SUMIF(A28:A173,F28,D28:D173) -> 5.3161455e-06
A29: Libia | B29: 40022967 | C29: 116256469 | D29: =+B29/$B$8 -> 0.0028940535 | F29: Libia | G29: =+SUMIF(A29:A174,F29,D29:D174) -> 0.0028940535
A30: Madagascar | B30: 10661247 | C30: 16288530 | D30: =+B30/$B$8 -> 0.00077091283 | F30: Madagascar | G30: =+SUMIF(A30:A175,F30,D30:D175) -> 0.00077091283
A31: Malawi | B31: 855343 | C31: 4805300 | D31: =+B31/$B$8 -> 6.1849697e-05 | F31: Malawi | G31: =+SUMIF(A31:A176,F31,D31:D176) -> 6.1849697e-05
... A47: Angola | B47: 2375988 | C47: 4897423 | D47: =+B47/$B$8 -> 0.00017180726 | F47: Angola | G47: =+SUMIF(A47:A192,F47,D47:D192) -> 0.00017180726
A48: Cabo Verde | B48: 169143 | C48: 1040315 | D48: =+B48/$B$8 -> 1.22307e-05 | F48: Cabo Verde
A49: Mozambique | B49: 17815115 | C49: 34497462 | D49: =+B49/$B$8 -> 0.0012882077 | F49: Mozambique | G49: =+SUMIF(A49:A194,F49,D49:D194) -> 0.0012882077
A50: Djibouti | B50: 30284 | C50: 56685 | D50: =+B50/$B$8 -> 2.1898305e-06 | F50: Djibouti | G50: =+SUMIF(A50:A195,F50,D50:D195) -> 2.1898305e-06
A51: Namibia | B51: 566898 | C51: 3425831 | D51: =+B51/$B$8 -> 4.0992291e-05 | F51: Namibia | G51: =+SUMIF(A51:A196,F51,D51:D196) -> 4.0992291e-05
A52: Sudáfrica | B52: 241646237 | C52: 819756341 | D52: =+B52/$B$8 -> 0.017473395 | F52: Sudáfrica | G52: =+SUMIF(A52:A197,F52,D52:D197) -> 0.017473395
A53: Eritrea | B53: 6786 | C53: 12635 | D53: =+B53/$B$8 -> 4.9069442e-07 | F53: Eritrea | G53: =+SUMIF(A53:A198,F53,D53:D198) -> 4.9069442e-07
A54: Etiopía | B54: 110115 | C54: 229805 | D54: =+B54/$B$8 -> 7.9623956e-06 | F54: Etiopía | G54: =+SUMIF(A54:A199,F54,D54:D199) -> 7.9623956e-06
A55: Sudán | B55: 6703375 | C55: 16028142 | D55: =+B55/$B$8 -> 0.00048471983 | F55: Sudán | G55: =+SUMIF(A55:A200,F55,D55:D200) -> 0.00048471983
A56: Sudán del Sur | B56: 2931 | C56: 5151 | D56: =+B56/$B$8 -> 2.1194008e-07 | F56: Sudán del Sur | G56: =+SUMIF(A56:A201,F56,D56:D201) -> 2.1194008e-07
D57: =+B57/$B$8 -> #VALUE! | G57: =+SUMIF(A57:A202,F57,D57:D202) -> #VALUE!
A58: AMERICA | B58: 3347218593 | C58: 4521443325 | D58: =+B58/$B$8 -> 0.24203677 | F58: AMERICA | G58: =+SUMIF(A58:A203,F58,D58:D203) -> 0.24203677
A59: Barbados | B59: 1880 | C59: 5 | D59: =+B59/$B$8 -> 1.3594246e-07 | F59: Barbados | G59: =+SUMIF(A59:A204,F59,D59:D204) -> 1.3594246e-07
...

Sheet 2015
A1: Evolución de las exportaciones con origen en la provincia de Santa Fe, según destino. Enero - diciembre de 2015.
B4: A Ñ O 2 0 1 5
A5: PAIS DE DESTINO | B5: VALOR F.O.B. | C5: PESO NETO
B6: (en Dólares) | C6: (en Kilos)
A8: TOTAL | B8: 13206825658 | C8: 29734481208
A10: AFRICA | B10: 1560117758 | C10: 4275619294 | D10: =+B10/$B$8 -> 0.11812965 | F10: {=+_xlfn.UNIQUE(A10:A155)} -> AFRICA | G10: =+SUMIF(A10:A155,F10,D10:D155) -> 0.11812965
A11: Burkina Faso | B11: 205106 | C11: 106912 | D11: =+B11/$B$8 -> 1.5530303e-05 | F11: Burkina Faso | G11: =+SUMIF(A11:A156,F11,D11:D156) -> 1.5530303e-05
A12: Argelia | B12: 555954051 | C12: 1551384496 | D12: =+B12/$B$8 -> 0.042095964 | F12: Argelia | G12: =+SUMIF(A12:A157,F12,D12:D157) -> 0.042095964
A13: Burundi | B13: 2243 | C13: 6776 | D13: =+B13/$B$8 -> 1.6983642e-07 | F13: Burundi | G13: =+SUMIF(A13:A158,F13,D13:D158) -> 1.6983642e-07
A14: Camerún | B14: 14934902 | C14: 40476596 | D14: =+B14/$B$8 -> 0.0011308472 | F14: Camerún | G14: =+SUMIF(A14:A159,F14,D14:D159) -> 0.0011308472
A15: Congo | B15: 3474628 | C15: 9539609 | D15: =+B15/$B$8 -> 0.00026309335 | F15: Congo | G15: =+SUMIF(A15:A160,F15,D15:D160) -> 0.00026309335
A16: Rep. Democrática del Congo (ex Zaire) | B16: 1018883 | C16: 1223506 | D16: =+B16/$B$8 -> 7.7148213e-05 | F16: Rep. Democrática del Congo (ex Zaire) | G16: =+SUMIF(A16:A161,F16,D16:D161) -> 7.7148213e-05
A17: Costa de Marfil | B17: 9667983 | C17: 25734840 | D17: =+B17/$B$8 -> 0.00073204442 | F17: Costa de Marfil | G17: =+SUMIF(A17:A162,F17,D17:D162) -> 0.00073204442
A18: Chad | B18: 145920 | C18: 45600 | D18: =+B18/$B$8 -> 1.1048832e-05 | F18: Chad | G18: =+SUMIF(A18:A163,F18,D18:D163) -> 1.1048832e-05
A19: Benin | B19: 152634 | C19: 220665 | D19: =+B19/$B$8 -> 1.1557206e-05 | F19: Benin | G19: =+SUMIF(A19:A164,F19,D19:D164) -> 1.1557206e-05
A20: Egipto | B20: 433722377 | C20: 1175075228 | D20: =+B20/$B$8 -> 0.032840774 | F20: Egipto | G20: =+SUMIF(A20:A165,F20,D20:D165) -> 0.032840774
A21: Gabón | B21: 233324 | C21: 222649 | D21: =+B21/$B$8 -> 1.7666925e-05 | F21: Gabón | G21: =+SUMIF(A21:A166,F21,D21:D166) -> 1.7666925e-05
A22: Gambia | B22: 45310 | C22: 119800 | D22: =+B22/$B$8 -> 3.4308017e-06 | F22: Gambia | G22: =+SUMIF(A22:A167,F22,D22:D167) -> 3.4308017e-06
... A24: Guinea | B24: 26103 | C24: 64108 | D24: =+B24/$B$8 -> 1.976478e-06 | F24: Guinea | G24: =+SUMIF(A24:A169,F24,D24:D169) -> 1.976478e-06
A25: Guinea Ecuatorial | B25: - | C25: - | D25: =+B25/$B$8 -> #VALUE! | F25: Guinea Ecuatorial | G25: =+SUMIF(A25:A170,F25,D25:D170) -> #VALUE!
A26: Kenya | B26: 1779286 | C26: 5952987 | D26: =+B26/$B$8 -> 0.00013472473 | F26: Kenya | G26: =+SUMIF(A26:A171,F26,D26:D171) -> 0.00013472473
A27: Liberia | B27: 64764 | C27: 158419 | D27: =+B27/$B$8 -> 4.9038279e-06 | F27: Liberia | G27: =+SUMIF(A27:A172,F27,D27:D172) -> 4.9038279e-06
A28: Libia | B28: 46926291 | C28: 127295746 | D28: =+B28/$B$8 -> 0.0035531847 | F28: Libia | G28: =+SUMIF(A28:A173,F28,D28:D173) -> 0.0035531847
A29: Madagascar | B29: 7404349 | C29: 12622365 | D29: =+B29/$B$8 -> 0.00056064562 | F29: Madagascar | G29: =+SUMIF(A29:A174,F29,D29:D174) -> 0.00056064562
A30: Mali | B30: 66177 | C30: 78840 | D30: =+B30/$B$8 -> 5.010818e-06 | F30: Mali | G30: =+SUMIF(A30:A175,F30,D30:D175) -> 5.010818e-06
A31: Marruecos | B31: 110438927 | C31: 397023911 | D31: =+B31/$B$8 -> 0.0083622613 | F31: Marruecos | G31: =+SUMIF(A31:A176,F31,D31:D176) -> 0.0083622613
A32: Mauricio | B32: 20275553 | C32: 53062925 | D32: =+B32/$B$8 -> 0.0015352329 | F32: Mauricio | G32: =+SUMIF(A32:A177,F32,D32:D177) -> 0.0015352329
A33: Mauritania | B33: 71305 | C33: 31090 | D33: =+B33/$B$8 -> 5.3991021e-06 | F33: Mauritania | G33: =+SUMIF(A33:A178,F33,D33:D178) -> 5.3991021e-06
A34: Níger | B34: 9619189 | C34: 2976123 | D34: =+B34/$B$8 -> 0.00072834981 | F34: Níger | G34: =+SUMIF(A34:A179,F34,D34:D179) -> 0.00072834981
A35: Nigeria | B35: 53087677 | C35: 142749679 | D35: =+B35/$B$8 -> 0.0040197151 | F35: Nigeria | G35: =+SUMIF(A35:A180,F35,D35:D180) -> 0.0040197151
A36: Zimbabwe | B36: 3270 | C36: 120 | D36: =+B36/$B$8 -> 2.4759924e-07 | F36: Zimbabwe | G36: =+SUMIF(A36:A181,F36,D36:D181) -> 2.4759924e-07
A37: Rwanda | B37: - | C37: - | D37: =+B37/$B$8 -> #VALUE! | F37: Rwanda | G37: =+SUMIF(A37:A182,F37,D37:D182) -> #VALUE!
A38: Senegal | B38: 14879187 | C38: 50132300 | D38: =+B38/$B$8 -> 0.0011266286 | F38: Senegal | G38: =+SUMIF(A38:A183,F38,D38:D183) -> 0.0011266286
A39: Sierra Leona | B39: 35181 | C39: 91078 | D39: =+B39/$B$8 -> 2.6638498e-06 | F39: Sierra Leona | G39: =+SUMIF(A39:A184,F39,D39:D184) -> 2.6638498e-06
A40: Tanzania | B40: 10297 | C40: 29917 | D40: =+B40/$B$8 -> 7.7967259e-07 | F40: Tanzania | G40: =+SUMIF(A40:A185,F40,D40:D185) -> 7.7967259e-07
A41: Togo | B41: 45429 | C41: 27736 | D41: =+B41/$B$8 -> 3.4398122e-06 | F41: Togo | G41: =+SUMIF(A41:A186,F41,D41:D186) -> 3.4398122e-06
A42: Túnez | B42: 4406479 | C42: 15120089 | D42: =+B42/$B$8 -> 0.00033365164 | F42: Túnez | G42: =+SUMIF(A42:A187,F42,D42:D187) -> 0.00033365164
A43: Uganda | B43: 392016 | C43: 1270502 | D43: =+B43/$B$8 -> 2.9682833e-05 | F43: Uganda | G43: =+SUMIF(A43:A188,F43,D43:D188) -> 2.9682833e-05
A44: Zambia | B44: - | C44: - | D44: =+B44/$B$8 -> #VALUE! | F44: Zambia | G44: =+SUMIF(A44:A189,F44,D44:D189) -> #VALUE!
A45: Territorios vinculados a Francia | B45: 7570316 | C45: 24726000 | D45: =+B45/$B$8 -> 0.00057321238 | F45: Territorios vinculados a Francia | G45: =+SUMIF(A45:A190,F45,D45:D190) -> 0.00057321238
...

Sheet 2014
A1: Evolución de las exportaciones con origen en la provincia de Santa Fe, según destino. Enero - diciembre de 2014.
B4: A Ñ O 2 0 1 4
A5: PAIS DE DESTINO | B5: VALOR F.O.B. | C5: PESO NETO
B6: (en Dólares) | C6: (en Kilos)
A8: TOTAL | B8: 16079051363 | C8: 2.6262937e+10
A10: AFRICA | B10: 1784390303 | C10: 3.548443e+09 | D10: =+B10/$B$8 -> 0.11097609 | F10: {=+_xlfn.UNIQUE(A10:A155)} -> AFRICA | G10: =+SUMIF(A10:A155,F10,D10:D155) -> 0.11097609
A11: Burkina Faso | B11: 123396 | C11: 53697.6 | D11: =+B11/$B$8 -> 7.6743333e-06 | F11: Burkina Faso | G11: =+SUMIF(A11:A156,F11,D11:D156) -> 7.6743333e-06
A12: Argelia | B12: 735216401 | C12: 1.3973032e+09 | D12: =+B12/$B$8 -> 0.045725111 | F12: Argelia | G12: =+SUMIF(A12:A157,F12,D12:D157) -> 0.045725111
A13: Camerún | B13: 10268011 | C13: 17511306 | D13: =+B13/$B$8 -> 0.00063859557 | F13: Camerún | G13: =+SUMIF(A13:A158,F13,D13:D158) -> 0.00063859557
A14: Congo | B14: 1064906 | C14: 1732307.9 | D14: =+B14/$B$8 -> 6.6229405e-05 | F14: Congo | G14: =+SUMIF(A14:A159,F14,D14:D159) -> 6.6229405e-05
A15: Rep Democrática del Congo (ex Zaire) | B15: 4136217 | C15: 8191813 | D15: =+B15/$B$8 -> 0.0002572426 | F15: Rep Democrática del Congo (ex Zaire) | G15: =+SUMIF(A15:A160,F15,D15:D160) -> 0.0002572426
A16: Costa de Marfil | B16: 21963252 | C16: 29987108 | D16: =+B16/$B$8 -> 0.0013659545 | F16: Costa de Marfil | G16: =+SUMIF(A16:A161,F16,D16:D161) -> 0.0013659545
A17: Chad | B17: 256000 | C17: 50000 | D17: =+B17/$B$8 -> 1.5921337e-05 | F17: Chad | G17: =+SUMIF(A17:A162,F17,D17:D162) -> 1.5921337e-05
A18: Benin | B18: 77822 | C18: 83840.95 | D18: =+B18/$B$8 -> 4.8399621e-06 | F18: Benin | G18: =+SUMIF(A18:A163,F18,D18:D163) -> 4.8399621e-06
A19: Egipto | B19: 342626265 | C19: 7.8376433e+08 | D19: =+B19/$B$8 -> 0.021308861 | F19: Egipto | G19: =+SUMIF(A19:A164,F19,D19:D164) -> 0.021308861
A20: Gabón | B20: 657885 | C20: 232170.94 | D20: =+B20/$B$8 -> 4.091566e-05 | F20: Gabón | G20: =+SUMIF(A20:A165,F20,D20:D165) -> 4.091566e-05
A21: Gambia | B21: 2324 | C21: 2735.24 | D21: =+B21/$B$8 -> 1.4453589e-07 | F21: Gambia | G21: =+SUMIF(A21:A166,F21,D21:D166) -> 1.4453589e-07
A22: Ghana | B22: 51760 | C22: 61491.76 | D22: =+B22/$B$8 -> 3.2190954e-06 | F22: Ghana | G22: =+SUMIF(A22:A167,F22,D22:D167) -> 3.2190954e-06
... A28: Madagascar | B28: 6827742 | C28: 8081200 | D28: =+B28/$B$8 -> 0.00042463587 | F28: Madagascar | G28: =+SUMIF(A28:A173,F28,D28:D173) -> 0.00042463587
A29: Malawi | B29: - | C29: - | D29: =+B29/$B$8 -> #VALUE! | F29: Malawi | G29: =+SUMIF(A29:A174,F29,D29:D174) -> #VALUE!
A30: Mali | B30: 47811 | C30: 51607.71 | D30: =+B30/$B$8 -> 2.9734963e-06 | F30: Mali | G30: =+SUMIF(A30:A175,F30,D30:D175) -> 2.9734963e-06
A31: Marruecos | B31: 200362614 | C31: 4.698787e+08 | D31: =+B31/$B$8 -> 0.012461097 | F31: Marruecos | G31: =+SUMIF(A31:A176,F31,D31:D176) -> 0.012461097
A32: Mauricio | B32: 24059334 | C32: 46767921 | D32: =+B32/$B$8 -> 0.0014963155 | F32: Mauricio | G32: =+SUMIF(A32:A177,F32,D32:D177) -> 0.0014963155
A33: Mauritania | B33: 206310 | C33: 34501 | D33: =+B33/$B$8 -> 1.2830981e-05 | F33: Mauritania | G33: =+SUMIF(A33:A178,F33,D33:D178) -> 1.2830981e-05
A34: Níger | B34: 15236558 | C34: 2974560 | D34: =+B34/$B$8 -> 0.00094760304 | F34: Níger | G34: =+SUMIF(A34:A179,F34,D34:D179) -> 0.00094760304
A35: Nigeria | B35: 18157286 | C35: 16341040 | D35: =+B35/$B$8 -> 0.0011292511 | F35: Nigeria | G35: =+SUMIF(A35:A180,F35,D35:D180) -> 0.0011292511
A36: Zimbabwe | B36: 77474 | C36: 25837.94 | D36: =+B36/$B$8 -> 4.8183191e-06 | F36: Zimbabwe | G36: =+SUMIF(A36:A181,F36,D36:D181) -> 4.8183191e-06
A37: Rwanda | B37: 18 | C37: 11.58 | D37: =+B37/$B$8 -> 1.119469e-09 | F37: Rwanda | G37: =+SUMIF(A37:A182,F37,D37:D182) -> 1.119469e-09
A38: Senegal | B38: 12335721 | C38: 29074652 | D38: =+B38/$B$8 -> 0.00076719209 | F38: Senegal | G38: =+SUMIF(A38:A183,F38,D38:D183) -> 0.00076719209
A39: Sierra Leona | B39: 637932 | C39: 2129868.3 | D39: =+B39/$B$8 -> 3.9674729e-05 | F39: Sierra Leona | G39: =+SUMIF(A39:A184,F39,D39:D184) -> 3.9674729e-05
A40: Tanzania | B40: 1300062 | C40: 1530348.8 | D40: =+B40/$B$8 -> 8.0854397e-05 | F40: Tanzania | G40: =+SUMIF(A40:A185,F40,D40:D185) -> 8.0854397e-05
A41: Togo | B41: 22025 | C41: 31780.35 | D41: =+B41/$B$8 -> 1.3697947e-06 | F41: Togo | G41: =+SUMIF(A41:A186,F41,D41:D186) -> 1.3697947e-06
... A47: Cabo Verde | B47: 201494 | C47: 1011569.6 | D47: =+B47/$B$8 -> 1.2531461e-05 | F47: Cabo Verde | G47: =+SUMIF(A47:A192,F47,D47:D192) -> 1.2531461e-05
A48: Mozambique | B48: 17575837 | C48: 20672282 | D48: =+B48/$B$8 -> 0.0010930892 | F48: Mozambique
A49: Djibouti | B49: 3555 | C49: 5829.2 | D49: =+B49/$B$8 -> 2.2109513e-07 | F49: Djibouti | G49: =+SUMIF(A49:A194,F49,D49:D194) -> 2.2109513e-07
A50: Namibia | B50: - | C50: - | D50: =+B50/$B$8 -> #VALUE! | F50: Namibia | G50: =+SUMIF(A50:A195,F50,D50:D195) -> #VALUE!
A51: Sudáfrica | B51: 214480531 | C51: 3.9209451e+08 | D51: =+B51/$B$8 -> 0.013339128 | F51: Sudáfrica | G51: =+SUMIF(A51:A196,F51,D51:D196) -> 0.013339128
A52: Eritrea | B52: 66495 | C52: 100901.21 | D52: =+B52/$B$8 -> 4.1355052e-06 | F52: Eritrea | G52: =+SUMIF(A52:A197,F52,D52:D197) -> 4.1355052e-06
A53: Etiopía | B53: 156773 | C53: 248581.75 | D53: =+B53/$B$8 -> 9.7501399e-06 | F53: Etiopía | G53: =+SUMIF(A53:A198,F53,D53:D198) -> 9.7501399e-06
A54: Sudán | B54: 3711694 | C54: 869105 | D54: =+B54/$B$8 -> 0.00023084036 | F54: Sudán | G54: =+SUMIF(A54:A199,F54,D54:D199) -> 0.00023084036
...

Sheet 2013
A1: Evolución de las exportaciones con origen en la provincia de Santa Fe, según destino. Enero - diciembre de 2013.
B4: A Ñ O 2 0 1 3
A5: PAIS DE DESTINO | B5: VALOR F.O.B. | C5: PESO NETO
B6: (en Dólares) | C6: (en Kilos)
A8: TOTAL | B8: 16794654401 | C8: 2.6601621e+10
A10: AFRICA | B10: 1909750581 | C10: 3.5133766e+09 | D10: =+B10/$B$8 -> 0.11371181 | F10: {=+_xlfn.UNIQUE(A10:A155)} -> AFRICA | G10: =+SUMIF(A10:A155,F10,D10:D155) -> 0.11371181
A11: Burkina Faso | B11: 25279 | C11: 30447.9 | D11: =+B11/$B$8 -> 1.5051813e-06 | F11: Burkina Faso | G11: =+SUMIF(A11:A156,F11,D11:D156) -> 1.5051813e-06
A12: Argelia | B12: 805160756 | C12: 1.5076616e+09 | D12: =+B12/$B$8 -> 0.04794149 | F12: Argelia | G12: =+SUMIF(A12:A157,F12,D12:D157) -> 0.04794149
A13: Camerún | B13: 24034203 | C13: 40158419 | D13: =+B13/$B$8 -> 0.0014310627 | F13: Camerún | G13: =+SUMIF(A13:A158,F13,D13:D158) -> 0.0014310627
A14: Congo | B14: 2114781 | C14: 3502096.1 | D14: =+B14/$B$8 -> 0.00012591989 | F14: Congo | G14: =+SUMIF(A14:A159,F14,D14:D159) -> 0.00012591989
A15: Rep Democrática del Congo (ex Zaire) | B15: 1319925 | C15: 2830576.9 | D15: =+B15/$B$8 -> 7.8591971e-05 | F15: Rep Democrática del Congo (ex Zaire) | G15: =+SUMIF(A15:A160,F15,D15:D160) -> 7.8591971e-05
A16: Costa de Marfil | B16: 2966420 | C16: 3402660.8 | D16: =+B16/$B$8 -> 0.00017662882 | F16: Costa de Marfil | G16: =+SUMIF(A16:A161,F16,D16:D161) -> 0.00017662882
A17: Chad | B17: 635370 | C17: 147800 | D17: =+B17/$B$8 -> 3.7831681e-05 | F17: Chad | G17: =+SUMIF(A17:A162,F17,D17:D162) -> 3.7831681e-05
A18: Benin | B18: 126165 | C18: 151559.1 | D18: =+B18/$B$8 -> 7.5122117e-06 | F18: Benin | G18: =+SUMIF(A18:A163,F18,D18:D163) -> 7.5122117e-06
A19: Egipto | B19: 402411934 | C19: 8.0272711e+08 | D19: =+B19/$B$8 -> 0.023960715 | F19: Egipto | G19: =+SUMIF(A19:A164,F19,D19:D164) -> 0.023960715
A20: Gabón | B20: 279262 | C20: 198110.64 | D20: =+B20/$B$8 -> 1.6628029e-05 | F20: Gabón | G20: =+SUMIF(A20:A165,F20,D20:D165) -> 1.6628029e-05
A21: Gambia | B21: 141050 | C21: 73000 | D21: =+B21/$B$8 -> 8.3985057e-06 | F21: Gambia | G21: =+SUMIF(A21:A166,F21,D21:D166) -> 8.3985057e-06
A22: Ghana | B22: 5164751 | C22: 9394332.7 | D22: =+B22/$B$8 -> 0.00030752351 | F22: Ghana | G22: =+SUMIF(A22:A167,F22,D22:D167) -> 0.00030752351
A23: Guinea | B23: 52011 | C23: 61576.2 | D23: =+B23/$B$8 -> 3.0968783e-06 | F23: Guinea | G23: =+SUMIF(A23:A168,F23,D23:D168) -> 3.0968783e-06
A24: Guinea Ecuatorial | B24: - | C24: - | D24: =+B24/$B$8 -> #VALUE! | F24: Guinea Ecuatorial | G24: =+SUMIF(A24:A169,F24,D24:D169) -> #VALUE!
A25: Kenya | B25: 2153040 | C25: 2359370 | D25: =+B25/$B$8 -> 0.00012819793 | F25: Kenya | G25: =+SUMIF(A25:A170,F25,D25:D170) -> 0.00012819793
A26: Liberia | B26: 74191 | C26: 86904.09 | D26: =+B26/$B$8 -> 4.4175366e-06 | F26: Liberia | G26: =+SUMIF(A26:A171,F26,D26:D171) -> 4.4175366e-06
A27: Libia | B27: 56931664 | C27: 1.1302132e+08 | D27: =+B27/$B$8 -> 0.0033898681 | F27: Libia | G27: =+SUMIF(A27:A172,F27,D27:D172) -> 0.0033898681
A28: Madagascar | B28: 6794775 | C28: 7133500 | D28: =+B28/$B$8 -> 0.00040457963 | F28: Madagascar | G28: =+SUMIF(A28:A173,F28,D28:D173) -> 0.00040457963
A29: Malawi | B29: 185360 | C29: 50025 | D29: =+B29/$B$8 -> 1.1036845e-05 | F29: Malawi | G29: =+SUMIF(A29:A174,F29,D29:D174) -> 1.1036845e-05
A30: Mali | B30: 1105774 | C30: 273172.32 | D30: =+B30/$B$8 -> 6.5840831e-05 | F30: Mali | G30: =+SUMIF(A30:A175,F30,D30:D175) -> 6.5840831e-05
A31: Marruecos | B31: 178864204 | C31: 3.4324709e+08 | D31: =+B31/$B$8 -> 0.010650068 | F31: Marruecos | G31: =+SUMIF(A31:A176,F31,D31:D176) -> 0.010650068
A32: Mauricio | B32: 22640155 | C32: 43558929 | D32: =+B32/$B$8 -> 0.0013480572 | F32: Mauricio | G32: =+SUMIF(A32:A177,F32,D32:D177) -> 0.0013480572
A33: Mauritania | B33: 477715 | C33: 789420 | D33: =+B33/$B$8 -> 2.8444467e-05 | F33: Mauritania | G33: =+SUMIF(A33:A178,F33,D33:D178) -> 2.8444467e-05
A34: Níger | B34: 8007382 | C34: 1878680 | D34: =+B34/$B$8 -> 0.00047678159 | F34: Níger | G34: =+SUMIF(A34:A179,F34,D34:D179) -> 0.00047678159
A35: Nigeria | B35: 28877947 | C35: 39307121 | D35: =+B35/$B$8 -> 0.0017194725 | F35: Nigeria | G35: =+SUMIF(A35:A180,F35,D35:D180) -> 0.0017194725
A36: Zimbabwe | B36: 68420 | C36: 24770.44 | D36: =+B36/$B$8 -> 4.0739153e-06 | F36: Zimbabwe | G36: =+SUMIF(A36:A181,F36,D36:D181) -> 4.0739153e-06
A37: Rwanda | B37: - | C37: - | D37: =+B37/$B$8 -> #VALUE! | F37: Rwanda | G37: =+SUMIF(A37:A182,F37,D37:D182) -> #VALUE!
A38: Senegal | B38: 15798363 | C38: 24906742 | D38: =+B38/$B$8 -> 0.00094067806 | F38: Senegal | G38: =+SUMIF(A38:A183,F38,D38:D183) -> 0.00094067806
A39: Sierra Leona | B39: 535093 | C39: 152628.94 | D39: =+B39/$B$8 -> 3.1860912e-05 | F39: Sierra Leona | G39: =+SUMIF(A39:A184,F39,D39:D184) -> 3.1860912e-05
A40: Sudán | B40: - | C40: - | D40: =+B40/$B$8 -> #VALUE! | F40: Sudán | G40: =+SUMIF(A40:A185,F40,D40:D185) -> #VALUE!
A41: Tanzania | B41: 1463543 | C41: 3813390.2 | D41: =+B41/$B$8 -> 8.7143383e-05 | F41: Tanzania | G41: =+SUMIF(A41:A186,F41,D41:D186) -> 8.7143383e-05
A42: Togo | B42: 437365 | C42: 219779.69 | D42: =+B42/$B$8 -> 2.6041917e-05 | F42: Togo | G42: =+SUMIF(A42:A187,F42,D42:D187) -> 2.6041917e-05
A43: Túnez | B43: 49563183 | C43: 1.0219804e+08 | D43: =+B43/$B$8 -> 0.0029511285 | F43: Túnez | G43: =+SUMIF(A43:A188,F43,D43:D188) -> 0.0029511285
A44: Uganda | B44: 524692 | C44: 1434240.7 | D44: =+B44/$B$8 -> 3.1241607e-05 | F44: Uganda | G44: =+SUMIF(A44:A189,F44,D44:D189) -> 3.1241607e-05
...

Sheet 2012
A1: Evolución de las exportaciones con origen en la provincia de Santa Fe, según destino. Enero - diciembre de 2012.
B4: A Ñ O 2 0 1 2
A5: PAIS DE DESTINO | B5: VALOR F.O.B. | C5: PESO NETO
B6: (en Dólares) | C6: (en Kilos)
A8: TOTAL | B8: 17931537295 | C8: 2.8561926e+10
A10: AFRICA | B10: 1602535825 | C10: 3.3890123e+09 | D10: =+B10/$B$8 -> 0.089369684 | F10: {=+_xlfn.UNIQUE(A10:A155)} -> AFRICA | G10: =+SUMIF(A10:A155,F10,D10:D155) -> 0.089369684
A11: Burkina Faso | B11: 508445 | C11: 187239.3 | D11: =+B11/$B$8 -> 2.8354791e-05 | F11: Burkina Faso | G11: =+SUMIF(A11:A156,F11,D11:D156) -> 2.8354791e-05
A12: Argelia | B12: 594729970 | C12: 1.2729916e+09 | D12: =+B12/$B$8 -> 0.033166703 | F12: Argelia | G12: =+SUMIF(A12:A157,F12,D12:D157) -> 0.033166703
A13: Burundi | B13: - | C13: - | D13: =+B13/$B$8 -> #VALUE! | F13: Burundi | G13: =+SUMIF(A13:A158,F13,D13:D158) -> #VALUE!
A14: Camerún | B14: 7752616 | C14: 11043429 | D14: =+B14/$B$8 -> 0.00043234531 | F14: Camerún | G14: =+SUMIF(A14:A159,F14,D14:D159) -> 0.00043234531
A15: Congo | B15: 3698985 | C15: 9751609.9 | D15: =+B15/$B$8 -> 0.00020628376 | F15: Congo | G15: =+SUMIF(A15:A160,F15,D15:D160) -> 0.00020628376
A16: Rep Democrática del Congo (ex Zaire) | B16: 7080364 | C16: 10378593 | D16: =+B16/$B$8 -> 0.00039485538 | F16: Rep Democrática del Congo (ex Zaire) | G16: =+SUMIF(A16:A161,F16,D16:D161) -> 0.00039485538
A17: Costa de Marfil | B17: 4445804 | C17: 8600044.5 | D17: =+B17/$B$8 -> 0.00024793212 | F17: Costa de Marfil | G17: =+SUMIF(A17:A162,F17,D17:D162) -> 0.00024793212
A18: Chad | B18: 572420 | C18: 171600 | D18: =+B18/$B$8 -> 3.1922528e-05 | F18: Chad | G18: =+SUMIF(A18:A163,F18,D18:D163) -> 3.1922528e-05
A19: Benin | B19: 795396 | C19: 468057.56 | D19: =+B19/$B$8 -> 4.4357379e-05 | F19: Benin | G19: =+SUMIF(A19:A164,F19,D19:D164) -> 4.4357379e-05
A20: Egipto | B20: 339738636 | C20: 6.6645281e+08 | D20: =+B20/$B$8 -> 0.018946431 | F20: Egipto | G20: =+SUMIF(A20:A165,F20,D20:D165) -> 0.018946431
A21: Gabón | B21: 393446 | C21: 120879.36 | D21: =+B21/$B$8 -> 2.1941565e-05 | F21: Gabón | G21: =+SUMIF(A21:A166,F21,D21:D166) -> 2.1941565e-05
A22: Gambia | B22: - | C22: - | D22: =+B22/$B$8 -> #VALUE! | F22: Gambia | G22: =+SUMIF(A22:A167,F22,D22:D167) -> #VALUE!
A23: Ghana | B23: 4583710 | C23: 13478357 | D23: =+B23/$B$8 -> 0.00025562281 | F23: Ghana | G23: =+SUMIF(A23:A168,F23,D23:D168) -> 0.00025562281
A24: Guinea | B24: 606926 | C24: 260908.35 | D24: =+B24/$B$8 -> 3.3846847e-05 | F24: Guinea | G24: =+SUMIF(A24:A169,F24,D24:D169) -> 3.3846847e-05
A25: Guinea Ecuatorial | B25: 48840 | C25: 28531.81 | D25: =+B25/$B$8 -> 2.7236929e-06 | F25: Guinea Ecuatorial | G25: =+SUMIF(A25:A170,F25,D25:D170) -> 2.7236929e-06
A26: Kenya | B26: 10812518 | C26: 41981191 | D26: =+B26/$B$8 -> 0.0006029889 | F26: Kenya | G26: =+SUMIF(A26:A171,F26,D26:D171) -> 0.0006029889
A27: Liberia | B27: 292966 | C27: 155386.95 | D27: =+B27/$B$8 -> 1.633803e-05 | F27: Liberia | G27: =+SUMIF(A27:A172,F27,D27:D172) -> 1.633803e-05
A28: Libia | B28: 51557764 | C28: 1.2004329e+08 | D28: =+B28/$B$8 -> 0.0028752562 | F28: Libia | G28: =+SUMIF(A28:A173,F28,D28:D173) -> 0.0028752562
A29: Madagascar | B29: 3843905 | C29: 3252795.3 | D29: =+B29/$B$8 -> 0.00021436561 | F29: Madagascar | G29: =+SUMIF(A29:A174,F29,D29:D174) -> 0.00021436561
A30: Malawi | B30: 171608 | C30: 83331 | D30: =+B30/$B$8 -> 9.5701778e-06 | F30: Malawi | G30: =+SUMIF(A30:A175,F30,D30:D175) -> 9.5701778e-06
A31: Mali | B31: 847034 | C31: 1310828.4 | D31: =+B31/$B$8 -> 4.723711e-05 | F31: Mali | G31: =+SUMIF(A31:A176,F31,D31:D176) -> 4.723711e-05
A32: Marruecos | B32: 95356292 | C32: 3.1272613e+08 | D32: =+B32/$B$8 -> 0.0053177979 | F32: Marruecos | G32: =+SUMIF(A32:A177,F32,D32:D177) -> 0.0053177979
A33: Mauricio | B33: 30845730 | C33: 57668766 | D33: =+B33/$B$8 -> 0.0017201944 | F33: Mauricio | G33: =+SUMIF(A33:A178,F33,D33:D178) -> 0.0017201944
A34: Mauritania | B34: 4906939 | C34: 15187666 | D34: =+B34/$B$8 -> 0.00027364854 | F34: Mauritania | G34: =+SUMIF(A34:A179,F34,D34:D179) -> 0.00027364854
... A47: Territorios vinculados a Francia | B47: 8221428 | C47: 18310144 | D47: =+B47/$B$8 -> 0.00045848986 | F47: Territorios vinculados a Francia | G47: =+SUMIF(A47:A192,F47,D47:D192) -> 0.00046285134
A48: Angola | B48: 27381089 | C48: 23649350 | D48: =+B48/$B$8 -> 0.0015269795 | F48: Angola
A49: Cabo Verde | B49: 742125 | C49: 2880467.4 | D49: =+B49/$B$8 -> 4.138658e-05 | F49: Cabo Verde | G49: =+SUMIF(A49:A194,F49,D49:D194) -> 4.138658e-05
A50: Mozambique | B50: 30424807 | C50: 32682990 | D50: =+B50/$B$8 -> 0.0016967205 | F50: Mozambique | G50: =+SUMIF(A50:A195,F50,D50:D195) -> 0.0016967205
A51: Djibouti | B51: 4018115 | C51: 17503584 | D51: =+B51/$B$8 -> 0.0002240809 | F51: Djibouti | G51: =+SUMIF(A51:A196,F51,D51:D196) -> 0.0002240809
A52: Guinea Bissau | B52: 44200 | C52: 13000 | D52: =+B52/$B$8 -> 2.4649309e-06 | F52: Guinea Bissau | G52: =+SUMIF(A52:A197,F52,D52:D197) -> 2.4649309e-06
A53: Namibia | B53: 2168946 | C53: 3059413.6 | D53: =+B53/$B$8 -> 0.00012095706 | F53: Namibia | G53: =+SUMIF(A53:A198,F53,D53:D198) -> 0.00012095706
A54: Sudáfrica | B54: 208720520 | C54: 4.2180594e+08 | D54: =+B54/$B$8 -> 0.011639856 | F54: Sudáfrica | G54: =+SUMIF(A54:A199,F54,D54:D199) -> 0.011639856
A55: Eritrea | B55: 50761 | C55: 69441.4 | D55: =+B55/$B$8 -> 2.8308225e-06 | F55: Eritrea | G55: =+SUMIF(A55:A200,F55,D55:D200) -> 2.8308225e-06
A56: Etiopía | B56: 79592 | C56: 97146 | D56: =+B56/$B$8 -> 4.4386601e-06 | F56: Etiopía | G56: =+SUMIF(A56:A201,F56,D56:D201) -> 4.4386601e-06
...

Sheet 2011
A1: Evolución de las exportaciones con origen en la provincia de Santa Fe, según destino. Enero - diciembre de 2011.
B4: A Ñ O 2 0 1 1
A5: PAIS DE DESTINO | B5: VALOR F.O.B. | C5: PESO NETO
B6: (en Dólares) | C6: (en Kilos)
A8: TOTAL | B8: 18852657175 | C8: 3.0838193e+10
A10: AFRICA | B10: 2052467955 | C10: 3.8274555e+09 | D10: =+B10/$B$8 -> 0.1088689 | F10: {=+_xlfn.UNIQUE(A10:A155)} -> AFRICA | G10: =+SUMIF(A10:A155,F10,D10:D155) -> 0.1088689
A11: Burkina Faso | B11: 1161725 | C11: 319660.8 | D11: =+B11/$B$8 -> 6.1621287e-05 | F11: Burkina Faso | G11: =+SUMIF(A11:A156,F11,D11:D156) -> 6.1621287e-05
A12: Argelia | B12: 757269769 | C12: 1.4940834e+09 | D12: =+B12/$B$8 -> 0.0401678 | F12: Argelia | G12: =+SUMIF(A12:A157,F12,D12:D157) -> 0.0401678
A13: Burundi | B13: 75275 | C13: 345300 | D13: =+B13/$B$8 -> 3.9928059e-06 | F13: Burundi | G13: =+SUMIF(A13:A158,F13,D13:D158) -> 3.9928059e-06
A14: Camerún | B14: 9871032 | C14: 19977767 | D14: =+B14/$B$8 -> 0.00052358837 | F14: Camerún | G14: =+SUMIF(A14:A159,F14,D14:D159) -> 0.00052358837
A15: Congo | B15: 4459039 | C15: 10354135 | D15: =+B15/$B$8 -> 0.00023652045 | F15: Congo | G15: =+SUMIF(A15:A160,F15,D15:D160) -> 0.00023652045
A16: Rep Democrática del Congo (ex Zaire) | B16: 4944851 | C16: 5466600.2 | D16: =+B16/$B$8 -> 0.00026228934 | F16: Rep Democrática del Congo (ex Zaire) | G16: =+SUMIF(A16:A161,F16,D16:D161) -> 0.00026228934
A17: Costa de Marfil | B17: 7607577 | C17: 13886079 | D17: =+B17/$B$8 -> 0.0004035281 | F17: Costa de Marfil | G17: =+SUMIF(A17:A162,F17,D17:D162) -> 0.0004035281
A18: Chad | B18: 431250 | C18: 100000 | D18: =+B18/$B$8 -> 2.287476e-05 | F18: Chad | G18: =+SUMIF(A18:A163,F18,D18:D163) -> 2.287476e-05
A19: Benin | B19: 395557 | C19: 259166.4 | D19: =+B19/$B$8 -> 2.0981499e-05 | F19: Benin | G19: =+SUMIF(A19:A164,F19,D19:D164) -> 2.0981499e-05
A20: Egipto | B20: 606887768 | C20: 1.0731355e+09 | D20: =+B20/$B$8 -> 0.0321911 | F20: Egipto | G20: =+SUMIF(A20:A165,F20,D20:D165) -> 0.0321911
A21: Gabón | B21: 1407376 | C21: 548684.06 | D21: =+B21/$B$8 -> 7.4651334e-05 | F21: Gabón | G21: =+SUMIF(A21:A166,F21,D21:D166) -> 7.4651334e-05
A22: Gambia | B22: 358794 | C22: 159493.5 | D22: =+B22/$B$8 -> 1.9031482e-05 | F22: Gambia | G22: =+SUMIF(A22:A167,F22,D22:D167) -> 1.9031482e-05
... A47: Territorios vinculados a Francia | B47: 3568708 | C47: 9420443.8 | D47: =+B47/$B$8 -> 0.0001892947 | F47: Territorios vinculados a Francia | G47: =+SUMIF(A47:A192,F47,D47:D192) -> 0.00019670124
A48: Angola | B48: 32260006 | C48: 28727922 | D48: =+B48/$B$8 -> 0.0017111649 | F48: Angola
A49: Cabo Verde | B49: 922276 | C49: 3318004.8 | D49: =+B49/$B$8 -> 4.8920213e-05 | F49: Cabo Verde | G49: =+SUMIF(A49:A194,F49,D49:D194) -> 4.8920213e-05
A50: Mozambique | B50: 40665760 | C50: 44477773 | D50: =+B50/$B$8 -> 0.0021570307 | F50: Mozambique | G50: =+SUMIF(A50:A195,F50,D50:D195) -> 0.0021570307
A51: Seychelles | B51: - | C51: - | D51: =+B51/$B$8 -> #VALUE! | F51: Seychelles | G51: =+SUMIF(A51:A196,F51,D51:D196) -> #VALUE!
A52: Djibouti | B52: 1214051 | C52: 5374241.6 | D52: =+B52/$B$8 -> 6.4396811e-05 | F52: Djibouti | G52: =+SUMIF(A52:A197,F52,D52:D197) -> 6.4396811e-05
A53: Guinea Bissau | B53: 15132 | C53: 38358.6 | D53: =+B53/$B$8 -> 8.0264548e-07 | F53: Guinea Bissau | G53: =+SUMIF(A53:A198,F53,D53:D198) -> 8.0264548e-07
A54: Namibia | B54: 330454 | C54: 992393 | D54: =+B54/$B$8 -> 1.7528245e-05 | F54: Namibia | G54: =+SUMIF(A54:A199,F54,D54:D199) -> 1.7528245e-05
A55: Sudáfrica | B55: 243332224 | C55: 5.7532813e+08 | D55: =+B55/$B$8 -> 0.012907052 | F55: Sudáfrica | G55: =+SUMIF(A55:A200,F55,D55:D200) -> 0.012907052
A56: Etiopía | B56: 48430 | C56: 82944 | D56: =+B56/$B$8 -> 2.5688687e-06 | F56: Etiopía | G56: =+SUMIF(A56:A201,F56,D56:D201) -> 2.5688687e-06
D57: =+B57/$B$8 -> 0 | F57: 0 | G57: =+SUMIF(A57:A202,F57,D57:D202) -> 0
A58: AMERICA | B58: 5357222496 | C58: 4.9629729e+09 | D58: =+B58/$B$8 -> 0.28416273 | F58: AMERICA | G58: =+SUMIF(A58:A203,F58,D58:D203) -> 0.28416273
A59: Barbados | B59: 1627215 | C59: 719658.99 | D59: =+B59/$B$8 -> 8.6312236e-05 | F59: Barbados | G59: =+SUMIF(A59:A204,F59,D59:D204) -> 8.6312236e-05
A60: Bolivia | B60: 112235922 | C60: 91085456 | D60: =+B60/$B$8 -> 0.0059533211 | F60: Bolivia | G60: =+SUMIF(A60:A205,F60,D60:D205) -> 0.0059533211
A61: Brasil | B61: 1979589230 | C61: 1.026317e+09 | D61: =+B61/$B$8 -> 0.10500319 | F61: Brasil | G61: =+SUMIF(A61:A206,F61,D61:D206) -> 0.10500319
A62: Canadá | B62: 6242977 | C62: 1508420.7 | D62: =+B62/$B$8 -> 0.00033114573 | F62: Canadá | G62: =+SUMIF(A62:A207,F62,D62:D207) -> 0.00033114573
A63: Colombia | B63: 464256954 | C63: 1.1281098e+09 | D63: =+B63/$B$8 -> 0.024625545 | F63: Colombia | G63: =+SUMIF(A63:A208,F63,D63:D208) -> 0.024625545
A64: Costa Rica | B64: 17072514 | C64: 6965280.7 | D64: =+B64/$B$8 -> 0.00090557601 | F64: Costa Rica | G64: =+SUMIF(A64:A209,F64,D64:D209) -> 0.00090557601
A65: Cuba | B65: 18159015 | C65: 28612780 | D65: =+B65/$B$8 -> 0.00096320719 | F65: Cuba | G65: =+SUMIF(A65:A210,F65,D65:D210) -> 0.00096320719
A66: Chile | B66: 365095958 | C66: 4.7497661e+08 | D66: =+B66/$B$8 -> 0.019365756 | F66: Chile | G66: =+SUMIF(A66:A211,F66,D66:D211) -> 0.019365756
A67: República Dominicana | B67: 124941112 | C67: 1.2696154e+08 | D67: =+B67/$B$8 -> 0.0066272415 | F67: República Dominicana | G67: =+SUMIF(A67:A212,F67,D67:D212) -> 0.0066272415
A68: Ecuador | B68: 75921925 | C68: 1.3581996e+08 | D68: =+B68/$B$8 -> 0.0040271206 | F68: Ecuador | G68: =+SUMIF(A68:A213,F68,D68:D213) -> 0.0040271206
...

Sheet 2010
A1: Evolución de las exportaciones con origen en la provincia de Santa Fe, según destino. Enero - diciembre de 2010.
B4: A Ñ O 2 0 1 0
A5: PAIS DE DESTINO | B5: VALOR F.O.B. | C5: PESO NETO
B6: (en Dólares) | C6: (en Kilos)
A8: TOTAL | B8: 15448056685 | C8: 3.1950609e+10
A10: AFRICA | B10: 1493756341 | C10: 3.6166664e+09 | D10: =+B10/$B$8 -> 0.096695421 | F10: {=+_xlfn.UNIQUE(A10:A155)} -> AFRICA | G10: =+SUMIF(A10:A155,F10,D10:D155) -> 0.096695421
A11: Burkina Faso | B11: 716895 | C11: 222810.3 | D11: =+B11/$B$8 -> 4.6406808e-05 | F11: Burkina Faso | G11: =+SUMIF(A11:A156,F11,D11:D156) -> 4.6406808e-05
A12: Argelia | B12: 480471321 | C12: 1.3059559e+09 | D12: =+B12/$B$8 -> 0.031102379 | F12: Argelia | G12: =+SUMIF(A12:A157,F12,D12:D157) -> 0.031102379
A13: Botswana | B13: - | C13: - | D13: =+B13/$B$8 -> #VALUE! | F13: Botswana | G13: =+SUMIF(A13:A158,F13,D13:D158) -> #VALUE!
A14: Camerún | B14: 7293089 | C14: 11976446 | D14: =+B14/$B$8 -> 0.00047210398 | F14: Camerún | G14: =+SUMIF(A14:A159,F14,D14:D159) -> 0.00047210398
A15: República Centroafricana | B15: - | C15: - | D15: =+B15/$B$8 -> #VALUE! | F15: República Centroafricana | G15: =+SUMIF(A15:A160,F15,D15:D160) -> #VALUE!
A16: Congo | B16: 3169256 | C16: 2900225.8 | D16: =+B16/$B$8 -> 0.00020515564 | F16: Congo | G16: =+SUMIF(A16:A161,F16,D16:D161) -> 0.00020515564
A17: Rep Democrática del Congo (ex Zaire) | B17: 4681308 | C17: 6250003.6 | D17: =+B17/$B$8 -> 0.0003030354 | F17: Rep Democrática del Congo (ex Zaire) | G17: =+SUMIF(A17:A162,F17,D17:D162) -> 0.0003030354
A18: Costa de Marfil | B18: 8833639 | C18: 17761175 | D18: =+B18/$B$8 -> 0.00057182849 | F18: Costa de Marfil | G18: =+SUMIF(A18:A163,F18,D18:D163) -> 0.00057182849
A19: Chad | B19: 669000 | C19: 200000 | D19: =+B19/$B$8 -> 4.3306418e-05 | F19: Chad | G19: =+SUMIF(A19:A164,F19,D19:D164) -> 4.3306418e-05
A20: Benin | B20: 231596 | C20: 150086.41 | D20: =+B20/$B$8 -> 1.4991918e-05 | F20: Benin | G20: =+SUMIF(A20:A165,F20,D20:D165) -> 1.4991918e-05
A21: Egipto | B21: 392887917 | C21: 9.2949735e+08 | D21: =+B21/$B$8 -> 0.025432838 | F21: Egipto | G21: =+SUMIF(A21:A166,F21,D21:D166) -> 0.025432838
A22: Gabón | B22: 896395 | C22: 434140.15 | D22: =+B22/$B$8 -> 5.8026392e-05 | F22: Gabón | G22: =+SUMIF(A22:A167,F22,D22:D167) -> 5.8026392e-05
A23: Gambia | B23: 162255 | C23: 86084 | D23: =+B23/$B$8 -> 1.0503263e-05 | F23: Gambia | G23: =+SUMIF(A23:A168,F23,D23:D168) -> 1.0503263e-05
A24: Ghana | B24: 2617253 | C24: 1338060.5 | D24: =+B24/$B$8 -> 0.0001694228 | F24: Ghana | G24: =+SUMIF(A24:A169,F24,D24:D169) -> 0.0001694228
