Workbook

Sheet participaciones
A1: Año | B1: Albania | C1: Algeria | D1: Angola | E1: Antigua and Barbuda | F1: Australia | G1: Austria | H1: Bahamas, The | I1: Bangladesh | J1: Barbados | K1: Belgium | L1: Belize | M1: Benin | N1: Bolivia | O1: Brazil | P1: Bulgaria | Q1: Burkina Faso | R1: Cambodia | S1: Cameroon | T1: Canada | U1: Chile | V1: China, People's Republic of | W1: Colombia | X1: Congo, Democratic Republic of the | Y1: Congo, Republic of | Z1: Costa Rica | AA1: Croatia, Republic of | AB1: Cuba | AC1: Cyprus | AD1: Czech Republic | AE1: Côte d'Ivoire | AF1: Denmark | AG1: Dominica | AH1: Dominican Republic | AI1: Ecuador | AJ1: Egypt, Arab Republic of | AK1: El Salvador | AL1: Equatorial Guinea, Republic of | AM1: Estonia, Republic of | AN1: Ethiopia, The Federal Democratic Republic of | AO1: Fiji, Republic of | AP1: France | AQ1: Gabon | AR1: Gambia, The | AS1: Georgia | AT1: Germany | AU1: Ghana | AV1: Greece | AW1: Grenada | AX1: Guatemala | AY1: Guinea | AZ1: Guyana | BA1: Haiti | BB1: Honduras | BC1: Hong Kong Special Administrative Region, People's Republic of China | BD1: India | BE1: Indonesia | BF1: Iran, Islamic Republic of | BG1: Ireland | BH1: Israel | BI1: Italy | BJ1: Jamaica | BK1: Japan | BL1: Jordan | BM1: Kenya | BN1: Korea, Republic of | BO1: Kuwait | BP1: Latvia, Republic of | BQ1: Lebanon | BR1: Liberia | BS1: Libya | BT1: Luxembourg | BU1: Madagascar, Republic of | BV1: Malaysia | BW1: Mali | BX1: Malta | BY1: Mauritania, Islamic Republic of | BZ1: Mauritius | CA1: Mexico | CB1: Morocco | CC1: Mozambique, Republic of | CD1: Namibia | CE1: Netherlands, The | CF1: New Zealand | CG1: Nicaragua | CH1: Niger | CI1: Nigeria | CJ1: Norway | CK1: Oman | CL1: Pakistan | CM1: Panama | CN1: Paraguay | CO1: Peru | CP1: Philippines | CQ1: Poland, Republic of | CR1: Portugal | CS1: Qatar | CT1: Romania | CU1: Russian Federation | CV1: Saudi Arabia | CW1: Senegal | CX1: Sierra Leone | CY1: Singapore | CZ1: South Africa | DA1: Spain | DB1: Sri Lanka | DC1: St. Kitts and Nevis | DD1: St. Lucia | DE1: St. Vincent and the Grenadines | DF1: Sudan | DG1: Suriname | DH1: Sweden | DI1: Switzerland | DJ1: Syrian Arab Republic | DK1: Taiwan Province of China | DL1: Tanzania, United Republic of | DM1: Thailand | DN1: Togo | DO1: Trinidad and Tobago | DP1: Tunisia | DQ1: Türkiye, Republic of | DR1: Ukraine | DS1: United Arab Emirates | DT1: United Kingdom | DU1: United States | DV1: Uruguay | DW1: Venezuela, República Bolivariana de | DX1: Vietnam | DY1: Yemen, Republic of | DZ1: Zambia | EA1: Aruba, Kingdom of the Netherlands | EB1: Azerbaijan, Republic of | EC1: Belarus, Republic of | ED1: Cabo Verde | EE1: Finland | EF1: Guinea-Bissau | EG1: Hungary | EH1: Iraq | EI1: Lithuania, Republic of | EJ1: Nepal | EK1: Netherlands Antilles | EL1: North Macedonia, Republic of | EM1: Slovenia, Republic of | EN1: Zimbabwe | EO1: Afghanistan, Islamic Republic of | EP1: Armenia, Republic of | EQ1: Bahrain, Kingdom of | ER1: Bosnia and Herzegovina | ES1: Central African Republic | ET1: Comoros, Union of the | EU1: Puerto Rico | EV1: Rwanda | EW1: Uganda | EX1: Kazakhstan, Republic of | EY1: Malawi | EZ1: Moldova, Republic of | FA1: Myanmar | FB1: Andorra, Principality of | FC1: Chad | FD1: Eritrea, The State of | FE1: Mongolia | FF1: Montenegro | FG1: Serbia, Republic of | FH1: Djibouti | FI1: Botswana | FJ1: Iceland | FK1: Macao Special Administrative Region, People's Republic of China | FL1: São Tomé and Príncipe, Democratic Republic of | FM1: Maldives | FN1: Seychelles | FO1: Papua New Guinea | FP1: Brunei Darussalam | FQ1: Slovak Republic | FR1: Uzbekistan, Republic of | FS1: Curaçao, Kingdom of the Netherlands
A2: 2002 | B2: 5.8157289e-05 | C2: 0.012074498 | D2: 0.0003305491 | E2: 5.8876703e-06 | F2: 0.0031527871 | G2: 7.4757881e-05 | H2: 1.5041729e-05 | I2: 0.018048788 | J2: 6.4657473e-05 | K2: 0.014928414 | L2: 2.9566101e-05 | M2: 0.0001740231 | N2: 0.0062873835 | O2: 0.07148379 | P2: 0.0013582504 | Q2: 1.1490515e-05 | R2: 4.7475993e-05 | S2: 0.00013127429 | T2: 0.0017153789 | U2: 0.032051665 | V2: 0.061000133 | W2: 0.0046317684 | X2: 7.770598e-05 | Y2: 0.0008296823 | Z2: 0.00051576078 | AA2: 1.863522e-05 | AB2: 0.00048424824 | AC2: 0.0024051078 | AD2: 4.0048148e-05 | AE2: 8.3854639e-05 | AF2: 0.035054573 | AG2: 4.2499257e-06 | AH2: 0.009665227 | AI2: 0.0056712913 | AJ2: 0.040079492 | AK2: 6.8717496e-05 | AL2: 2.6628622e-07 | AM2: 4.2112227e-06 | AN2: 5.6820569e-07 | AO2: 0.00019187776 | AP2: 0.010835119 | AQ2: 9.677867e-05 | AR2: 7.5352019e-05 | AS2: 9.0407303e-06 | AT2: 0.021434318 | AU2: 0.00039424374 | AV2: 0.0040254366 | AW2: 3.4734161e-05 | AX2: 0.0032553594 | AY2: 8.4884151e-06 | AZ2: 3.4790668e-05 | BA2: 6.8320955e-05 | BB2: 0.00015331465 | BC2: 0.0023733997 | BD2: 0.070733011 | BE2: 0.0063135682 | BF2: 0.019885379 | BG2: 0.0043929122 | BH2: 0.0014826056 | BI2: 0.074155671 | BJ2: 0.0005081435 | BK2: 0.0010082027 | BL2: 0.0076490089 | BM2: 0.00069854798 | BN2: 0.01228879 | BO2: 2.4391914e-06 | BP2: 8.9622409e-06 | BQ2: 0.0038588568 | BR2: 4.7729278e-06 | BS2: 1.4410756e-05 | BT2: 3.2472245e-05 | BU2: 0.00038680843 | BV2: 0.027616121 | BW2: 7.8937012e-05 | BX2: 0.000138359 | BY2: 0.00019413349 | BZ2: 0.0022962991 | CA2: 0.026826406 | CB2: 0.010703253 | CC2: 0.00047289761 | CD2: 1.0586924e-05 | CE2: 0.070653502 | CF2: 9.7704894e-06 | CG2: 5.3669675e-05 | CH2: 0.00017206111 | CI2: 0.0020178436 | CJ2: 0.00012460895 | CK2: 0.0033108512 | CL2: 0.0032302857 | CM2: 0.00040986097 | CN2: 0.0040816907 | CO2: 0.022912646 | CP2: 0.016740269 | CQ2: 0.0075924506 | CR2: 0.004654139 | CS2: 4.4421165e-06 | CT2: 0.00086862147 | CU2: 0.0030024032 | CV2: 0.0018333006 | CW2: 0.0013005323 | CX2: 4.1801881e-05 | CY2: 0.00018828842 | CZ2: 0.023556344 | DA2: 0.065322566 | DB2: 3.0497959e-05 | DC2: 3.1486059e-05 | DD2: 1.6785205e-05 | DE2: 2.779224e-05 | DF2: 0.00022422937 | DG2: 3.6929878e-06 | DH2: 0.00031387222 | DI2: 0.00013949474 | DJ2: 0.0062626668 | DK2: 0.00085602002 | DL2: 0.00013026212 | DM2: 0.021760477 | DN2: 4.0804873e-05 | DO2: 0.00016673095 | DP2: 0.0099692982 | DQ2: 0.0039045624 | DR2: 1.6574271e-05 | DS2: 0.005084676 | DT2: 0.0092677091 | DU2: 0.046494681 | DV2: 0.0059855312 | DW2: 0.0029268142 | DX2: 0.012634111 | DY2: 0.0015072144 | DZ2: 2.4222416e-05
A3: 2003 | B3: 5.744787e-06 | C3: 0.018487583 | D3: 0.00033482846 | E3: 2.2347541e-06 | F3: 0.0021351357 | G3: 8.8583191e-05 | I3: 0.018473866 | J3: 4.0058288e-05 | K3: 0.010529689 | L3: 4.5371148e-05 | M3: 8.9241004e-05 | N3: 0.0056303468 | O3: 0.043938469 | P3: 0.00078237518 | R3: 2.2617728e-05 | S3: 0.00012511734 | T3: 0.001527663 | U3: 0.038932851 | V3: 0.1301896 | W3: 0.0033448992 | Y3: 0.0010216567 | Z3: 0.00056260158 | AA3: 0.00044688383 | AB3: 0.00025663363 | AC3: 0.0017556294 | AD3: 6.7365299e-05 | AE3: 0.0002170251 | AF3: 0.033217435 | AH3: 0.0078794391 | AI3: 0.0075568251 | AJ3: 0.033071262 | AK3: 0.00056158726 | AL3: 3.3438235e-06 | AM3: 1.9984736e-05 | AO3: 0.00014061618 | AP3: 0.012769521 | AQ3: 9.9943458e-05 | AR3: 4.8285114e-05 | AT3: 0.018602233 | AU3: 0.00040127695 | AV3: 0.0055808283 | AW3: 3.6151254e-05 | AX3: 0.0035020584 | AY3: 3.9152756e-05 | AZ3: 4.3077842e-05 | BA3: 6.8233296e-05 | BB3: 0.00032013022 | BC3: 0.0022253111 | BD3: 0.057917293 | BE3: 0.0041081391 | BF3: 0.0018408768 | BG3: 0.0089415426 | BH3: 0.0027762523 | BI3: 0.055984941 | BJ3: 0.00014832306 | BK3: 0.00097191654 | BL3: 0.0051654835 | BM3: 0.00023582053 | BN3: 0.014576513 | BP3: 7.0301482e-06 | BQ3: 0.0022185107 | BR3: 9.5843687e-06 | BS3: 3.4137172e-05 | BT3: 2.9174235e-05 | BU3: 0.00055876027 | BV3: 0.018618514 | BW3: 1.6816732e-05 | BX3: 9.7250291e-05 | BY3: 3.5039343e-05 | BZ3: 0.0012978708 | CA3: 0.025709653 | CB3: 0.015438096 | CC3: 0.00049353495 | CD3: 1.4476622e-05 | CE3: 0.071051521 | CF3: 3.7498277e-05 | CG3: 0.00038722545 | CH3: 0.00016072345 | CI3: 0.0017159428 | CJ3: 9.7632472e-05 | CK3: 0.0013893145 | CL3: 0.0041899515 | CM3: 0.00065430962 | CN3: 0.0036907534 | CO3: 0.018380788 | CP3: 0.03020989 | CQ3: 0.016545412 | CR3: 0.0040366656 | CS3: 4.8146527e-06 | CT3: 0.00077474669 | CU3: 0.001687948 | CV3: 0.0016822729 | CW3: 0.0013095562 | CX3: 9.0433188e-05 | CY3: 0.00052092382 | CZ3: 0.018619815 | DA3: 0.072094031 | DC3: 1.3068667e-05 | DD3: 3.5778864e-05 | DE3: 1.0690984e-05 | DF3: 4.1458503e-05 | DG3: 9.1783424e-06 | DH3: 0.00032732074 | DI3: 0.00011073638 | DJ3: 0.0076722897 | DK3: 0.0028516016 | DL3: 1.6306568e-05 | DM3: 0.026700888 | DN3: 0.00018413252 | DO3: 0.00070767748 | DP3: 0.0081129417 | DQ3: 0.0041921084 | DR3: 6.5110909e-05 | DS3: 0.0026783248 | DT3: 0.0080177763 | DU3: 0.033331025 | DV3: 0.0057936566 | DW3: 0.0043359601 | DX3: 0.017831346 | DY3: 0.0012902227 | EA3: 0.00018420841 | EB3: 7.9300163e-06 | EC3: 1.1169994e-06 | ED3: 4.4111659e-05 | EE3: 8.6057669e-06 | EF3: 1.8880991e-09 | EG3: 9.2888812e-06 | EH3: 0.00029786395 | EI3: 7.2257553e-07 | EJ3: 0.00037988554 | EK3: 0.00033933508 | EL3: 1.2813207e-05 | EM3: 0.0002104395 | EN3: 1.6048842e-05
A4: 2004 | B4: 3.0210744e-05 | C4: 0.026138925 | D4: 0.00062929234 | E4: 4.7556812e-06 | F4: 0.0015784974 | G4: 0.00031688375 | H4: 2.4362129e-06 | I4: 0.0084433426 | J4: 4.8758281e-05 | K4: 0.0082509372 | L4: 9.1309666e-06 | M4: 5.4887513e-05 | N4: 0.0066738707 | O4: 0.045646677 | P4: 0.00073372943 | Q4: 1.4495418e-05 | R4: 0.00020275879 | S4: 0.00014014891 | T4: 0.0022526484 | U4: 0.032240453 | V4: 0.11676662 | W4: 0.0072472602 | Y4: 0.0017130802 | Z4: 0.00028817529 | AA4: 0.00025179492 | AB4: 0.0026436478 | AC4: 0.00077797824 | AD4: 5.5312549e-05 | AE4: 7.2754144e-05 | AF4: 0.02504327 | AG4: 3.2508472e-06 | AH4: 0.010872931 | AI4: 0.010206842 | AJ4: 0.030774679 | AK4: 0.0017510879 | AL4: 4.2415066e-06 | AM4: 1.839686e-05 | AP4: 0.006852845 | AQ4: 8.6746614e-05 | AR4: 1.6403572e-05 | AS4: 3.6780018e-06 | AT4: 0.016040808 | AU4: 0.00047637274 | AV4: 0.0060537382 | AW4: 2.5490233e-05 | AX4: 0.0039150856 | AY4: 2.5190907e-05 | AZ4: 2.1866976e-05 | BA4: 5.3449486e-05 | BB4: 0.0014227901 | BC4: 0.0022778605 | BD4: 0.055148106 | BE4: 0.011120199 | BG4: 0.0053744593 | BH4: 0.0050347246 | BI4: 0.055839223 | BJ4: 0.00062046256 | BK4: 0.0015577071 | BL4: 0.0058148594 | BM4: 0.0001088229 | BN4: 0.020201629 | BO4: 4.6191246e-05 | BQ4: 0.0014340923 | BR4: 0.00036294724 | BS4: 0.0024244546 | BT4: 3.469549e-05 | BU4: 0.00081443203 | BV4: 0.014750909 | BW4: 2.4099738e-05 | BX4: 0.00011477378 | BY4: 0.00011497405 | BZ4: 0.0013111167 | CA4: 0.030074543 | CB4: 0.012553327 | CC4: 0.00065510738 | CE4: 0.060476277 | CF4: 0.00010197551 | CG4: 0.0010131286 | CH4: 0.00043817165 | CI4: 0.0011854256 | CJ4: 0.0002989303 | CK4: 0.00050059606 | CL4: 0.0034199491 | CM4: 0.0018828479 | CN4: 0.004380106 | CO4: 0.021709638 | CP4: 0.020687486 | CQ4: 0.021119665 | CR4: 0.0026235349 | CT4: 0.00071247805 | CU4: 0.0067933974 | CV4: 0.0036129578 | CW4: 0.00052279974 | CX4: 0.00014404678 | CY4: 0.00033722131 | CZ4: 0.026250327 | DA4: 0.067552766 | DC4: 2.3314715e-05 | DD4: 4.9081501e-05 | DE4: 3.673708e-05 | DF4: 7.205451e-05 | DG4: 1.119242e-05 | DH4: 0.00043010441 | DI4: 0.00014108306 | DJ4: 0.0068726578 | DK4: 0.0031363278 | DL4: 5.6484466e-05 | DM4: 0.014556724 | DN4: 5.2951289e-05 | DO4: 0.00052107092 | DP4: 0.012658288 | DQ4: 0.0093907216 | DR4: 0.0008369613 | DS4: 0.0049289233 | DT4: 0.0081069988 | DU4: 0.043342183 | DV4: 0.0086479063 | DW4: 0.018960851 | DY4: 0.0010946235 | DZ4: 7.6732354e-06 | EA4: 0.00030393935 | EC4: 2.0596908e-06 | ED4: 4.2459683e-05 | EE4: 8.7576476e-05 | EG4: 2.0637544e-08 | EH4: 0.00050957203 | EI4: 1.7900236e-05 | EK4: 0.00036467661 | EL4: 5.2421841e-05 | EM4: 0.00019349138 | EO4: 3.1989831e-05 | EP4: 7.5343414e-08 | EQ4: 2.9020318e-05 | ER4: 6.8709418e-05 | ES4: 4.9137009e-06 | ET4: 1.1449955e-05 | EU4: 0.0005374356 | EV4: 1.9540806e-05 | EW4: 1.4172751e-05
A5: 2005 | B5: 1.0937436e-05 | C5: 0.030247436 | D5: 0.00086957486 | E5: 2.398031e-06 | F5: 0.0018575251 | G5: 0.0004874607 | H5: 1.1117057e-07 | I5: 0.010737208 | J5: 8.5583236e-05 | K5: 0.0083097389 | L5: 1.5658544e-06 | M5: 9.4677302e-06 | N5: 0.0063943024 | O5: 0.058943348 | P5: 0.00031311317 | Q5: 5.0914576e-05 | R5: 0.00027640239 | S5: 0.00024041114 | T5: 0.0024980993 | U5: 0.042460158 | V5: 0.092996667 | W5: 0.004460199 | Y5: 0.00099846558 | Z5: 0.0002451448 | AA5: 0.00060547861 | AB5: 0.0019225208 | AC5: 0.0013302396 | AD5: 4.1147053e-05 | AE5: 0.0005427166 | AF5: 0.02399519 | AG5: 6.6551025e-08 | AH5: 0.0078957204 | AI5: 0.0076441228 | AJ5: 0.016681751 | AK5: 0.00040872228 | AL5: 3.5439324e-06 | AM5: 4.0092234e-05 | AP5: 0.0064778242 | AQ5: 8.9274162e-05 | AR5: 2.1329957e-05 | AT5: 0.012741424 | AU5: 0.00072313433 | AV5: 0.0032463211 | AW5: 3.0370409e-05 | AX5: 0.0033500646 | AY5: 5.4176351e-05 | AZ5: 2.8548653e-05 | BA5: 7.1749171e-05 | BB5: 0.00029813326 | BC5: 0.0037487669 | BD5: 0.062732002 | BE5: 0.017123696 | BF5: 7.1129106e-06 | BG5: 0.0047345301 | BH5: 0.0052571125 | BI5: 0.044468109 | BJ5: 0.00054147306 | BK5: 0.0039484413 | BL5: 0.0036154287 | BM5: 0.000177671 | BN5: 0.025565756 | BO5: 9.1539409e-05 | BP5: 0.001254547 | BQ5: 0.0015193404 | BR5: 0.00021008854 | BS5: 0.0024933646 | BT5: 4.3787249e-05 | BU5: 0.001382128 | BV5: 0.019824502 | BW5: 4.1698613e-05 | BX5: 6.5191915e-05 | BY5: 9.0074822e-05 | BZ5: 0.0013554918 | CA5: 0.022675993 | CB5: 0.010891435 | CC5: 0.0005739863 | CE5: 0.067212715 | CF5: 0.00014819476 | CG5: 0.00098799277 | CH5: 0.00035822017 | CI5: 0.0014437193 | CJ5: 5.2219944e-05 | CK5: 0.0015646937 | CL5: 4.708185e-05 | CM5: 0.00049681171 | CN5: 0.0042459207 | CO5: 0.023634997 | CP5: 0.020641629 | CQ5: 0.028062734 | CR5: 0.0017892485 | CS5: 8.7567944e-06 | CT5: 0.0001985395 | CU5: 0.014457123 | CV5: 0.003819867 | CW5: 0.00092729054 | CX5: 0.00011804058 | CY5: 0.00023774515 | CZ5: 0.022796397 | DA5: 0.080889388 | DB5: 8.183389e-06 | DC5: 2.6005634e-05 | DD5: 2.84961e-05 | DE5: 3.3051511e-05 | DF5: 4.9359732e-05 | DG5: 4.8603726e-06 | DH5: 0.00047639818 | DI5: 6.8473626e-05 | DJ5: 0.0093616851 | DK5: 0.0020343182 | DL5: 4.199005e-07 | DM5: 0.01924458 | DN5: 0.00031933357 | DO5: 0.0006816818 | DP5: 0.0078365304 | DQ5: 0.0073180249 | DR5: 0.00056292492 | DS5: 0.0016011672 | DT5: 0.0093644154 | DU5: 0.042910234 | DV5: 0.010367059 | DW5: 0.012418975 | DY5: 0.0014480466 | EA5: 0.00027886697 | EB5: 5.6496265e-07 | EC5: 2.0915885e-05 | EE5: 0.00028759541 | EG5: 1.6887546e-05 | EH5: 5.9985785e-05 | EI5: 6.9395864e-06 | EK5: 0.00043392426 | EL5: 2.9239877e-05 | EM5: 0.00045163484 | EQ5: 9.8465856e-06 | ER5: 0.00022245353 | ES5: 5.0533353e-06 | EU5: 0.00081006287 | EW5: 1.2707241e-05 | EX5: 7.6151839e-06 | EY5: 1.6945791e-05 | EZ5: 1.9972418e-05 | FA5: 2.0639433e-06
A6: 2006 | C6: 0.03121941 | D6: 0.00083887287 | E6: 2.3487724e-06 | F6: 0.0034127456 | G6: 0.00017401275 | I6: 0.0094231938 | J6: 4.3178802e-05 | K6: 0.010226896 | L6: 1.2386205e-06 | M6: 0.0001237317 | N6: 0.0058219186 | O6: 0.064650668 | P6: 0.00022033389 | Q6: 0.00010079116 | R6: 0.00017403513 | S6: 0.00045010563 | T6: 0.0018209801 | U6: 0.034142825 | V6: 0.071218033 | W6: 0.010120842 | X6: 0.00030235851 | Y6: 0.0012459363 | Z6: 0.00059168428 | AA6: 0.00046189998 | AB6: 0.0019773214 | AC6: 0.0017049523 | AD6: 4.4536201e-05 | AE6: 0.00040832039 | AF6: 0.025599699 | AG6: 1.7351044e-05 | AH6: 0.0072822512 | AI6: 0.01105727 | AJ6: 0.016244627 | AK6: 0.00028861685 | AL6: 6.4787408e-06 | AM6: 5.8463138e-05 | AP6: 0.014799958 | AQ6: 0.00011711004 | AR6: 5.2287628e-06 | AS6: 0.00029969817 | AT6: 0.013319576 | AU6: 0.000245141 | AV6: 0.0034736573 | AW6: 2.8771572e-05 | AX6: 0.0026480822 | AY6: 6.616936e-05 | AZ6: 6.9683118e-05 | BA6: 5.7815385e-05 | BB6: 8.9254089e-05 | BC6: 0.0024178186 | BD6: 0.062859405 | BE6: 0.013946621 | BG6: 0.0074804916 | BH6: 0.0024771835 | BI6: 0.044960592 | BJ6: 0.00081349876 | BK6: 0.0057891512 | BL6: 0.0022644538 | BM6: 0.00021744796 | BN6: 0.023062079 | BO6: 7.7513793e-05 | BP6: 0.0016988455 | BQ6: 0.0014899868 | BR6: 0.00016880075 | BS6: 0.0036908163 | BT6: 3.666886e-05 | BU6: 0.0015844906 | BV6: 0.021617308 | BW6: 0.00021270383 | BX6: 0.00035973329 | BY6: 9.4344648e-05 | BZ6: 0.0013474739 | CA6: 0.020599035 | CB6: 0.013915211 | CC6: 0.00099468613 | CE6: 0.064952934 | CF6: 0.00011879958 | CG6: 0.00038246257 | CH6: 0.00076561129 | CI6: 0.00097693457 | CJ6: 3.9690018e-05 | CK6: 0.00066266556 | CL6: 8.3311238e-05 | CM6: 0.00046097553 | CN6: 0.0056075791 | CO6: 0.022371251 | CP6: 0.021001712 | CQ6: 0.024990731 | CR6: 0.0031983548 | CS6: 1.7182085e-05 | CT6: 0.000786773 | CU6: 0.014199152 | CV6: 0.0014508369 | CW6: 0.0055099053 | CX6: 3.2857852e-05 | CY6: 0.00030101617 | CZ6: 0.028072069 | DA6: 0.076702107 | DB6: 0.00019068606 | DC6: 2.2594385e-05 | DD6: 2.952325e-05 | DE6: 1.6527274e-05 | DF6: 7.4107501e-05 | DG6: 3.3603817e-06 | DH6: 0.0004182306 | DI6: 3.1558933e-05 | DJ6: 0.007450659 | DK6: 0.0014170926 | DL6: 0.00020975032 | DM6: 0.016870389 | DN6: 0.00056934263 | DO6: 0.00040509066 | DP6: 0.01086769 | DQ6: 0.014846104 | DR6: 0.00031142227 | DS6: 0.0026936699 | DT6: 0.016110583 | DU6: 0.028975101 | DV6: 0.010326564 | DW6: 0.01801056 | DY6: 0.00068917827 | EA6: 0.00021282628 | EB6: 1.3537667e-05 | EC6: 1.208991e-05 | ED6: 7.6445273e-06 | EE6: 0.0002171875 | EF6: 1.3215342e-05 | EG6: 7.857217e-06 | EH6: 0.00025369002 | EI6: 1.0924253e-05 | EK6: 0.00024357949 | EM6: 0.0015039792 | EP6: 5.2077472e-06 | EQ6: 7.9543465e-06 | ER6: 5.5107737e-05 | ET6: 1.3222356e-06 | EU6: 0.00030048573 | EW6: 4.5037761e-05 | EY6: 1.3924458e-05 | FA6: 3.8114645e-06 | FB6: 5.8792155e-07 | FC6: 2.6640195e-05 | FD6: 1.9308246e-06 | FE6: 1.4225979e-05
A7: 2007 | B7: 1.7683819e-05 | C7: 0.025080247 | D7: 0.00064252608 | E7: 1.9817811e-06 | F7: 0.0068726366 | G7: 0.00012175388 | I7: 0.01360249 | J7: 3.6207455e-05 | K7: 0.010287861 | L7: 1.1447375e-06 | M7: 1.9138669e-05 | N7: 0.0044989908 | O7: 0.097240497 | P7: 9.1271676e-06 | Q7: 2.4554109e-05 | R7: 0.00012010486 | S7: 0.00012315421 | T7: 0.0011557057 | U7: 0.02688175 | V7: 0.11718416 | W7: 0.011424899 | X7: 0.00011431581 | Y7: 0.00048357508 | Z7: 0.00024045881 | AA7: 0.00012980657 | AB7: 0.00078837797 | AC7: 0.001438989 | AD7: 0.00012238675 | AE7: 0.00020108148 | AF7: 0.023155654 | AG7: 1.6329569e-05 | AH7: 0.0092319856 | AI7: 0.010260968 | AJ7: 0.010308829 | AK7: 0.00033193095 | AL7: 1.140001e-05 | AM7: 3.6953768e-05 | AP7: 0.016285337 | AQ7: 8.6629322e-05 | AR7: 2.7194552e-05 | AS7: 3.9748684e-06 | AT7: 0.014365865 | AU7: 0.0001923074 | AV7: 0.0040512753 | AW7: 9.2418838e-06 | AX7: 0.0025954073 | AY7: 2.7860188e-05 | AZ7: 3.3685148e-05 | BA7: 9.5653892e-05 | BB7: 9.9632708e-05 | BC7: 0.0031442606 | BD7: 0.049752875 | BE7: 0.017339955 | BF7: 0.011994768 | BG7: 0.0059075027 | BH7: 0.002905233 | BI7: 0.041339329 | BJ7: 0.00020662904 | BK7: 0.0054345412 | BL7: 0.00061008266 | BM7: 0.0005713813 | BN7: 0.021401442 | BO7: 0.00015253681 | BQ7: 0.0017740719 | BR7: 2.0595434e-05 | BS7: 0.0024448514 | BT7: 4.0291999e-05 | BU7: 0.0017017797 | BV7: 0.021352559 | BW7: 3.4011834e-05 | BX7: 1.8735801e-05 | BY7: 5.6618156e-05 | BZ7: 0.00085904788 | CA7: 0.013989208 | CB7: 0.01143813 | CC7: 0.0010163874 | CD7: 1.7447391e-05 | CE7: 0.049230039 | CF7: 0.00093965023 | CG7: 0.00018522136 | CH7: 0.00026088193 | CI7: 0.00066825785 | CJ7: 6.0108635e-05 | CK7: 0.00015682538 | CL7: 0.0029612738 | CM7: 0.00074268562 | CN7: 0.0056643171 | CO7: 0.022970526 | CP7: 0.018907594 | CQ7: 0.026930617 | CR7: 0.0029930959 | CS7: 3.1759104e-06 | CT7: 0.0024406202 | CU7: 0.0099462658 | CV7: 0.0035609673 | CW7: 0.0018307388 | CX7: 2.7064836e-05 | CY7: 0.0002858282 | CZ7: 0.024967073 | DA7: 0.069792812 | DB7: 8.7028839e-05 | DC7: 7.8603007e-06 | DD7: 3.3222392e-05 | DE7: 6.3177027e-06 | DF7: 1.1556573e-05 | DG7: 9.4885325e-06 | DH7: 0.00055080966 | DI7: 3.3690489e-05 | DJ7: 0.0038274105 | DK7: 0.0013667341 | DL7: 0.00045914642 | DM7: 0.020537664 | DN7: 0.00034950427 | DO7: 0.00044985835 | DP7: 0.0088647653 | DQ7: 0.0040307316 | DR7: 0.00019601771 | DS7: 0.00037831861 | DT7: 0.019696257 | DU7: 0.018720993 | DV7: 0.009354429 | DW7: 0.019805526 | DY7: 0.0012665197 | DZ7: 9.9085509e-07 | EA7: 5.5384901e-05 | EB7: 0.00010885359 | EC7: 1.1138828e-05 | ED7: 9.1286419e-08 | EE7: 0.00026334301 | EF7: 1.4461926e-05 | EG7: 8.2352549e-06 | EH7: 3.98748e-06 | EI7: 2.8350817e-05 | EK7: 9.2629731e-05 | EL7: 2.7303041e-05 | EM7: 0.0016001723 | EO7: 5.8175276e-06 | EQ7: 4.7810111e-06 | ER7: 5.9609153e-05 | ES7: 2.6621823e-06 | ET7: 1.3711373e-06 | EU7: 0.00012876046 | EX7: 0.00020264319 | EY7: 4.4662631e-06 | FA7: 4.0399109e-06 | FC7: 2.3189102e-05 | FE7: 8.9622273e-06 | FF7: 1.3582766e-06 | FG7: 2.6798867e-06
A8: 2008 | B8: 4.598557e-05 | C8: 0.020535107 | D8: 0.00081266514 | E8: 5.7422324e-06 | F8: 0.0090615019 | G8: 0.00010279362 | H8: 4.9639425e-06 | I8: 0.006655108 | J8: 8.1211297e-05 | K8: 0.013165565 | L8: 4.233189e-07 | M8: 2.7434986e-05 | N8: 0.0056185557 | O8: 0.090180457 | P8: 7.834348e-06 | Q8: 0.00016251132 | R8: 0.00013905766 | S8: 0.00030108919 | T8: 0.0012537845 | U8: 0.025122305 | V8: 0.089166695 | W8: 0.011957454 | X8: 0.00053036603 | Y8: 0.00028486482 | Z8: 0.00032658532 | AA8: 0.000452531 | AB8: 0.00054462017 | AC8: 0.0013296271 | AD8: 0.00012610142 | AE8: 0.00092432178 | AF8: 0.019685876 | AG8: 2.0574506e-07 | AH8: 0.0068101446 | AI8: 0.013125633 | AJ8: 0.02843517 | AK8: 0.00014579056 | AL8: 1.9861253e-05 | AM8: 4.2753743e-05 | AN8: 3.8998041e-08 | AP8: 0.018181341 | AQ8: 8.2952189e-05 | AR8: 3.6558092e-06 | AT8: 0.016109295 | AU8: 0.00043215771 | AV8: 0.0015423911 | AW8: 4.474581e-06 | AX8: 0.0023182478 | AY8: 4.0661926e-05 | AZ8: 2.5847765e-05 | BA8: 8.1477628e-05 | BB8: 9.6872259e-05 | BC8: 0.0015878762 | BD8: 0.040095746 | BE8: 0.013593865 | BF8: 0.016840261 | BG8: 0.0055051079 | BH8: 0.0016979273 | BI8: 0.050897595 | BJ8: 9.8529182e-05 | BK8: 0.0019398598 | BL8: 0.00010278914 | BM8: 0.00013554502 | BN8: 0.018779721 | BO8: 0.00028423296 | BP8: 0.00067437796 | BQ8: 0.0015041153 | BR8: 6.6111947e-05 | BS8: 0.0016516489 | BT8: 4.2160921e-05 | BU8: 0.0010331662 | BV8: 0.016817181 | BW8: 1.5976416e-05 | BX8: 2.0911121e-05 | BY8: 3.035519e-05 | BZ8: 0.00049257214 | CA8: 0.0074719405 | CB8: 0.009497333 | CC8: 0.0012525798 | CD8: 8.9024641e-06 | CE8: 0.069626985 | CF8: 0.0016017202 | CG8: 0.00016267874 | CH8: 0.00066127292 | CI8: 0.0014273088 | CJ8: 0.0014051207 | CK8: 0.0006632958 | CL8: 0.00026775289 | CM8: 0.00052152892 | CN8: 0.0068793034 | CO8: 0.027673468 | CP8: 0.017505123 | CQ8: 0.024299785 | CR8: 0.0052382848 | CT8: 0.0015389148 | CU8: 0.0076706708 | CV8: 0.0027191339 | CW8: 0.0033644569 | CX8: 2.629983e-05 | CY8: 0.00036068496 | CZ8: 0.019035244 | DA8: 0.070326962 | DB8: 4.6550872e-05 | DC8: 3.7105031e-06 | DD8: 1.5070433e-05 | DE8: 2.0070834e-05 | DF8: 5.5026507e-05 | DG8: 9.7443604e-06 | DH8: 0.00043121001 | DI8: 0.00020708575 | DJ8: 0.0059299853 | DK8: 0.0009970568 | DL8: 0.00025736135 | DM8: 0.018396734 | DN8: 0.00026026022 | DO8: 0.000363815 | DP8: 0.014814794 | DQ8: 0.011550135 | DR8: 0.00094965951 | DS8: 0.0034501443 | DT8: 0.0212604 | DU8: 0.025096118 | DV8: 0.013734411 | DW8: 0.032035175 | DY8: 0.00043208391 | DZ8: 8.1854582e-06 | EA8: 7.4386396e-05 | EB8: 9.4192184e-05 | ED8: 1.2248222e-06 | EE8: 7.73406e-05 | EG8: 7.8630159e-06 | EI8: 0.00021723371 | EK8: 9.6403112e-05 | EM8: 0.00025722173 | EN8: 3.3768126e-06 | EO8: 1.9472462e-05 | EP8: 6.3110661e-07 | EQ8: 6.1462596e-06 | ER8: 3.5814503e-05 | ET8: 1.5890813e-06 | EU8: 0.00020505383 | EV8: 0.00053985105 | EX8: 0.00034413876 | EY8: 1.5976416e-05 | EZ8: 0.0001753509 | FA8: 1.8677599e-07 | FC8: 1.4028072e-05 | FE8: 8.5890193e-06 | FF8: 3.366492e-05 | FH8: 8.4364827e-06
A9: 2009 | B9: 0.00021591138 | C9: 0.021070217 | D9: 0.0012136385 | E9: 2.5359241e-06 | F9: 0.010630655 | G9: 0.00011595111 | H9: 1.1945759e-05 | I9: 0.014514728 | J9: 5.6771892e-05 | K9: 0.013450255 | L9: 3.9016877e-08 | N9: 0.0058525008 | O9: 0.066717575 | P9: 8.6788083e-06 | Q9: 1.3074079e-05 | R9: 0.00028996566 | S9: 0.00026267601 | T9: 0.00061992221 | U9: 0.018488511 | V9: 0.088680556 | W9: 0.015364342 | X9: 0.00044552092 | Y9: 0.00012997182 | Z9: 0.00034663321 | AA9: 9.4889779e-05 | AB9: 0.00039162272 | AC9: 0.0015288188 | AD9: 7.2455135e-05 | AE9: 0.00041582751 | AF9: 0.02850775 | AG9: 7.2746173e-06 | AH9: 0.0057399831 | AI9: 0.012984935 | AJ9: 0.016580927 | AK9: 3.4958128e-05 | AL9: 5.5222915e-06 | AM9: 0.00011338809 | AP9: 0.0084757401 | AQ9: 0.00012568623 | AR9: 1.8703832e-05 | AS9: 1.6692652e-05 | AT9: 0.017499635 | AU9: 0.00032865359 | AV9: 0.0031875434 | AW9: 2.3172506e-05 | AX9: 0.0013359344 | AY9: 1.8197705e-05 | AZ9: 1.8027351e-05 | BA9: 0.00068718232 | BB9: 0.00056112166 | BC9: 0.0054560146 | BD9: 0.032117325 | BE9: 0.026848306 | BF9: 0.02269403 | BG9: 0.0021851678 | BH9: 0.0025853268 | BI9: 0.06302444 | BJ9: 0.00042832482 | BK9: 0.0041273333 | BL9: 0.00059060212 | BM9: 2.1072547e-05 | BN9: 0.01364158 | BO9: 0.00016255014 | BP9: 0.00038866806 | BQ9: 0.0010380376 | BR9: 4.3284349e-05 | BS9: 0.0041876432 | BT9: 2.6594761e-05 | BU9: 5.8111739e-05 | BV9: 0.023348389 | BW9: 5.7521792e-05 | BX9: 0.00013806018 | BY9: 1.6077584e-05 | BZ9: 0.00086889145 | CA9: 0.0037213845 | CB9: 0.0019421582 | CC9: 0.00030031605 | CD9: 5.2906945e-06 | CE9: 0.095397096 | CF9: 0.0023358125 | CG9: 0.00018343289 | CH9: 0.00053940491 | CI9: 0.00093176222 | CJ9: 0.00017511577 | CK9: 0.0013488695 | CL9: 0.0010655205 | CM9: 0.00067078288 | CN9: 0.0058094507 | CO9: 0.015869148 | CP9: 0.018444386 | CQ9: 0.02835792 | CR9: 0.0026470947 | CS9: 7.8984899e-06 | CT9: 0.001579235 | CU9: 0.011420831 | CV9: 0.0053341318 | CW9: 0.0030683137 | CX9: 2.3348767e-05 | CY9: 0.00031298321 | CZ9: 0.021381264 | DA9: 0.076499798 | DC9: 2.1166619e-05 | DD9: 2.2142101e-05 | DE9: 2.6635682e-05 | DF9: 6.9942566e-05 | DG9: 4.0633889e-06 | DH9: 0.0003381256 | DI9: 0.00021640383 | DJ9: 0.010769679 | DK9: 0.00094066917 | DL9: 0.00036435185 | DM9: 0.020474863 | DN9: 0.00012260682 | DO9: 0.00042066372 | DP9: 0.0049649938 | DQ9: 0.0035698589 | DR9: 0.00011562373 | DS9: 0.0055124325 | DT9: 0.021648593 | DU9: 0.014551594 | DV9: 0.011384769 | DW9: 0.014545483 | DY9: 0.0034256051 | DZ9: 9.8523268e-06 | EA9: 9.5000891e-05 | EB9: 4.8831624e-05 | ED9: 3.4585749e-06 | EE9: 2.0415102e-06 | EG9: 2.5059431e-06 | EH9: 6.5474324e-05 | EI9: 2.6691891e-05 | EK9: 0.00013943564 | EL9: 2.3652486e-05 | EM9: 0.00052470031 | EN9: 1.4772151e-05 | EO9: 4.6644149e-05 | EP9: 9.5022159e-07 | EQ9: 1.5051855e-05 | ER9: 3.9040118e-05 | ES9: 4.3649549e-06 | ET9: 1.9980851e-06 | EU9: 0.00016218625 | EV9: 3.2425379e-08 | EX9: 0.00026275095 | EY9: 4.3233839e-05 | FA9: 2.363727e-07 | FC9: 6.2855351e-05 | FE9: 3.3162018e-06 | FG9: 5.5531473e-05 | FI9: 2.1927605e-06 | FJ9: 3.8012522e-09 | FK9: 7.6055806e-08 | FL9: 3.5493652e-06
A10: 2010 | B10: 7.9616268e-05 | C10: 0.03110377 | D10: 0.00058459692 | E10: 3.7249598e-06 | F10: 0.0088335092 | G10: 9.8671074e-05 | I10: 0.011997562 | J10: 7.0895212e-05 | K10: 0.004356131 | L10: 3.6543071e-06 | M10: 1.4198377e-05 | N10: 0.0055291802 | O10: 0.10053867 | P10: 8.5057471e-06 | Q10: 5.2417682e-05 | R10: 0.00027442521 | S10: 0.00053407534 | T10: 0.00060045584 | U10: 0.021420099 | V10: 0.024801677 | W10: 0.017503988 | X10: 0.00029524452 | Y10: 0.00021077913 | Z10: 0.001666128 | AA10: 3.6449435e-05 | AB10: 0.0007238345 | AC10: 0.00095440702 | AD10: 0.00010856107 | AE10: 0.0006276356 | AF10: 0.015470747 | AH10: 0.0072811415 | AI10: 0.0075910225 | AJ10: 0.022297125 | AK10: 9.1833226e-05 | AL10: 1.4549695e-05 | AM10: 0.00016427278 | AN10: 4.3921354e-06 | AP10: 0.01411019 | AQ10: 6.5597017e-05 | AR10: 1.1193402e-05 | AS10: 3.6595948e-07 | AT10: 0.01258491 | AU10: 0.0001921348 | AV10: 0.0046382293 | AW10: 6.9565604e-06 | AX10: 0.0029427173 | AY10: 3.4483388e-06 | AZ10: 1.5439426e-05 | BA10: 0.0010861906 | BB10: 5.2895056e-05 | BC10: 0.0054056051 | BD10: 0.06160763 | BE10: 0.032454837 | BF10: 0.045890787 | BG10: 0.003621175 | BH10: 0.0028538865 | BI10: 0.056084674 | BJ10: 0.00020507094 | BK10: 0.0023058105 | BL10: 0.0017553955 | BM10: 2.2095664e-05 | BN10: 0.016636158 | BO10: 0.00013273196 | BP10: 0.00029262807 | BQ10: 0.0015728122 | BR10: 2.9414386e-05 | BS10: 0.0044210758 | BT10: 2.5027339e-05 | BU10: 0.00029101797 | BV10: 0.025849278 | BW10: 0.00010156535 | BX10: 4.0339082e-05 | BY10: 3.4042742e-05 | BZ10: 0.001164357 | CA10: 0.0041599256 | CB10: 0.002938483 | CC10: 0.0010998052 | CD10: 3.6897507e-06 | CE10: 0.086179826 | CF10: 0.0023545324 | CG10: 0.00012843521 | CH10: 0.00084604543 | CI10: 0.0011284976 | CJ10: 3.7263294e-05 | CK10: 0.00054857974 | CL10: 0.00078782424 | CM10: 0.0007930283 | CN10: 0.0092434903 | CO10: 0.023137657 | CP10: 0.013587163 | CQ10: 0.023618802 | CR10: 0.0018732263 | CS10: 1.1840954e-05 | CT10: 0.0042271515 | CU10: 0.006381573 | CV10: 0.004813197 | CW10: 0.0028294474 | CX10: 5.0879098e-07 | CY10: 0.00027964545 | CZ10: 0.019200086 | DA10: 0.071465034 | DB10: 1.2407839e-06 | DC10: 1.3410509e-05 | DD10: 1.575381e-05 | DE10: 1.1046985e-05 | DF10: 0.00010552745 | DG10: 5.7296799e-06 | DH10: 0.00033974868 | DI10: 0.0001338689 | DJ10: 0.0050449524 | DK10: 0.0011254346 | DL10: 0.00024151153 | DM10: 0.014930286 | DN10: 0.00010362188 | DO10: 0.00052385607 | DP10: 0.0045358632 | DQ10: 0.0047542508 | DR10: 0.00036200898 | DS10: 0.0086531155 | DT10: 0.022034293 | DU10: 0.011824259 | DV10: 0.013185348 | DW10: 0.020997128 | DY10: 0.001546122 | EA10: 0.00014353256 | EB10: 0.00017207126 | EC10: 2.7697481e-05 | EE10: 6.0501997e-05 | EG10: 1.1550399e-06 | EH10: 6.4881396e-05 | EI10: 0.00021879864 | EK10: 0.0001385967 | EL10: 8.0728352e-06 | EM10: 0.00022629262 | EN10: 7.2380842e-05 | EO10: 3.9044287e-06 | EP10: 2.0182018e-07 | EQ10: 1.4042508e-05 | ER10: 4.1212261e-05 | EU10: 0.00016742465 | EX10: 0.00022850736 | EY10: 2.1390858e-05 | FC10: 4.9509988e-05 | FE10: 4.8886266e-06 | FG10: 7.768425e-06 | FK10: 3.3598706e-08 | FM10: 9.817098e-07 | FN10: 8.6817873e-07
A11: 2011 | B11: 1.3615331e-05 | C11: 0.040699895 | D11: 0.001854922 | F11: 0.016382694 | G11: 0.00016999774 | I11: 0.018727048 | J11: 9.8789835e-05 | K11: 0.0069761819 | L11: 4.8882059e-08 | M11: 1.7795908e-05 | N11: 0.0060849814 | O11: 0.10702799 | P11: 5.1944558e-06 | Q11: 6.9819154e-05 | R11: 0.00036494667 | S11: 0.000533468 | T11: 0.00034571317 | U11: 0.018192835 | V11: 0.026337246 | W11: 0.01977592 | X11: 0.00021761372 | Y11: 0.00016704108 | Z11: 0.0010142995 | AA11: 0.0001821059 | AB11: 0.00066064102 | AC11: 0.00075739957 | AD11: 0.00010841929 | AE11: 0.00039400405 | AF11: 0.015064149 | AH11: 0.0071976239 | AI11: 0.0040021283 | AJ11: 0.028577281 | AK11: 2.4389614e-05 | AL11: 1.6149123e-06 | AM11: 8.572452e-05 | AP11: 0.011861667 | AQ11: 8.3825675e-05 | AR11: 2.029538e-05 | AS11: 2.4313928e-05 | AT11: 0.01058432 | AU11: 0.0002055016 | AV11: 0.0033906886 | AX11: 0.0025588027 | AY11: 3.6412763e-05 | AZ11: 6.6376502e-05 | BA11: 0.00048583477 | BB11: 6.7795758e-05 | BC11: 0.0039051702 | BD11: 0.040975389 | BE11: 0.033314898 | BF11: 0.026651508 | BG11: 0.0047514123 | BH11: 0.0030897145 | BI11: 0.061786225 | BJ11: 0.00010997252 | BK11: 0.002078669 | BL11: 0.0029636158 | BM11: 5.6102037e-05 | BN11: 0.017944185 | BO11: 0.00010857948 | BP11: 0.0016968311 | BQ11: 0.001522046 | BR11: 1.0741596e-05 | BS11: 0.0013903554 | BT11: 2.5157052e-05 | BU11: 0.00017437064 | BV11: 0.021205285 | BW11: 0.0001138926 | BX11: 1.3549277e-05 | BY11: 0.00011318805 | BZ11: 0.0012567973 | CA11: 0.0042312618 | CB11: 0.003867441 | CC11: 0.0022853593 | CD11: 2.061648e-06 | CE11: 0.063420221 | CF11: 0.0025408801 | CG11: 0.0011076832 | CH11: 0.0010606048 | CI11: 0.0011428461 | CJ11: 5.0589677e-06 | CK11: 0.00062966791 | CL11: 0.00091767972 | CM11: 0.0028615494 | CN11: 0.011893935 | CO11: 0.036426957 | CP11: 0.017047476 | CQ11: 0.022017259 | CR11: 0.0020361818 | CT11: 0.00059311751 | CU11: 0.0052918867 | CV11: 0.005219701 | CW11: 0.001436153 | CX11: 1.6450249e-05 | CY11: 0.00014300079 | CZ11: 0.013392854 | DA11: 0.085508524 | DB11: 8.104273e-05 | DC11: 1.5265778e-05 | DD11: 4.3609334e-06 | DE11: 2.0301754e-05 | DF11: 0.00021676858 | DG11: 4.8738095e-06 | DH11: 0.00043168973 | DI11: 0.00025147272 | DJ11: 0.0079652521 | DK11: 0.001502917 | DL11: 0.00054908404 | DM11: 0.013292977 | DN11: 7.3998182e-05 | DO11: 0.00044618839 | DP11: 0.0037218515 | DQ11: 0.0044280806 | DR11: 0.00041675502 | DS11: 0.0052232287 | DT11: 0.019197651 | DU11: 0.011861754 | DV11: 0.013170804 | DW11: 0.030738661 | DY11: 0.00067179314 | DZ11: 5.8434326e-06 | EA11: 4.6137206e-05 | EB11: 0.00013920041 | EC11: 5.0177411e-05 | ED11: 2.9874286e-06 | EE11: 0.0016554309 | EG11: 4.0349057e-06 | EH11: 6.5193383e-06 | EI11: 0.00061829447 | EK11: 7.4913462e-05 | EM11: 0.00064566747 | EN11: 7.7124424e-05 | EO11: 4.6962359e-06 | EP11: 5.7068329e-08 | EQ11: 2.3324676e-06 | ER11: 6.1277518e-06 | EU11: 0.00022385841 | EX11: 0.00019408472 | EY11: 9.6075138e-06 | EZ11: 1.4334837e-05 | FA11: 8.1389515e-07 | FC11: 2.6181613e-05 | FE11: 4.0143198e-06 | FG11: 3.0082902e-07 | FM11: 8.4010772e-07 | FO11: 3.3833748e-05
A12: 2012 | C12: 0.029986779 | D12: 0.0015874775 | F12: 0.018972222 | G12: 0.00028361803 | I12: 0.014839273 | J12: 5.4449733e-05 | K12: 0.00807812 | L12: 1.2693929e-07 | M12: 3.8725342e-05 | N12: 0.0060072479 | O12: 0.10648485 | Q12: 3.0539487e-05 | R12: 0.00028131632 | S12: 0.00045240903 | T12: 0.00039884061 | U12: 0.027477648 | V12: 0.040227981 | W12: 0.022326405 | X12: 0.00033906749 | Y12: 0.00010305096 | Z12: 0.00012593096 | AA12: 0.00031839846 | AB12: 0.0015608467 | AC12: 0.00048320131 | AD12: 0.00015994897 | AE12: 0.00018406908 | AF12: 0.01889182 | AH12: 0.0071970311 | AI12: 0.0018654453 | AJ12: 0.016479248 | AK12: 0.00011451099 | AL12: 3.1073928e-06 | AM12: 4.3792891e-05 | AP12: 0.0070818693 | AQ12: 2.3765765e-05 | AT12: 0.0096767959 | AU12: 0.00027620415 | AV12: 0.0043315663 | AW12: 3.1048478e-06 | AX12: 0.0026087307 | AY12: 3.3641154e-05 | AZ12: 2.1425486e-05 | BA12: 0.00095779129 | BB12: 9.3474719e-05 | BC12: 0.0030715015 | BD12: 0.051768668 | BE12: 0.049121791 | BF12: 0.031278253 | BG12: 0.0070013049 | BH12: 0.0037084258 | BI12: 0.030645137 | BJ12: 6.6828076e-05 | BK12: 0.0033914634 | BL12: 0.0060411299 | BM12: 1.8528052e-06 | BN12: 0.017692479 | BO12: 1.946311e-05 | BP12: 0.0013656241 | BQ12: 0.00157861 | BR12: 1.3848898e-05 | BS12: 0.0032247493 | BT12: 2.4151846e-05 | BU12: 0.00024456438 | BV12: 0.030372791 | BW12: 3.4813743e-05 | BX12: 2.2042581e-05 | BY12: 5.9042791e-05 | BZ12: 0.0017486928 | CA12: 0.0041089723 | CB12: 0.0022505374 | CC12: 0.0018660499 | CD12: 9.6330906e-05 | CE12: 0.054240692 | CF12: 0.0023707668 | CG12: 0.0003901725 | CH12: 0.00069954388 | CI12: 0.0017370749 | CJ12: 1.8804053e-06 | CK12: 2.1776019e-05 | CL12: 0.0011849247 | CM12: 0.0022604449 | CN12: 0.0090309122 | CO12: 0.034644187 | CP12: 0.01404861 | CQ12: 0.028272517 | CR12: 0.00090483102 | CS12: 1.7984876e-06 | CT12: 0.0023758623 | CU12: 0.0051873748 | CV12: 0.0043237941 | CW12: 0.00079842013 | CX12: 1.0412629e-05 | CY12: 0.00013762589 | CZ12: 0.012055453 | DA12: 0.080144794 | DB12: 1.148412e-07 | DC12: 9.5810006e-06 | DD12: 2.778849e-06 | DE12: 4.9308547e-06 | DF12: 0.00023469278 | DG12: 4.4799389e-05 | DH12: 0.00021737132 | DI12: 0.00019329951 | DJ12: 0.0017874969 | DK12: 0.0014115951 | DL12: 0.0002864961 | DM12: 0.024761981 | DN12: 6.4339828e-05 | DO12: 0.00011847828 | DP12: 0.0034114021 | DQ12: 0.0042670312 | DR12: 0.00025001125 | DS12: 0.0011279756 | DT12: 0.019752359 | DU12: 0.0082887161 | DV12: 0.012217427 | DW12: 0.035641611 | DY12: 0.0012276081 | DZ12: 5.2922386e-05 | EA12: 1.0481967e-05 | EB12: 3.5068493e-05 | EC12: 1.8350546e-05 | EE12: 5.6517306e-05 | EF12: 2.8121778e-06 | EG12: 5.3907138e-06 | EH12: 5.8852136e-06 | EI12: 0.003680205 | EK12: 9.1614017e-05 | EM12: 0.00010434325 | EN12: 0.00010354162 | EP12: 1.6500867e-06 | EQ12: 2.2271557e-05 | EU12: 0.00023625898 | EW12: 1.3456461e-05 | EX12: 0.00017279504 | EY12: 1.0918385e-05 | EZ12: 3.1316358e-05 | FC12: 3.6419611e-05 | FE12: 9.8780766e-06 | FG12: 1.8912214e-07
A13: 2013 | B13: 0.00030522466 | C13: 0.048931688 | D13: 0.0013362595 | F13: 0.015676951 | G13: 0.00023766443 | I13: 0.011215692 | J13: 2.5000935e-05 | K13: 0.0060420074 | N13: 0.0067035558 | O13: 0.10604131 | P13: 3.3944452e-06 | R13: 0.00052099453 | S13: 0.0016253753 | T13: 0.00051155927 | U13: 0.022826172 | V13: 0.03518537 | W13: 0.017199296 | X13: 6.7321917e-05 | Y13: 0.00013769627 | Z13: 0.00019061114 | AA13: 1.4543909e-07 | AB13: 0.0051305648 | AC13: 0.00048478193 | AD13: 0.00010540398 | AE13: 0.00020168679 | AF13: 0.011354665 | AH13: 0.0060746861 | AI13: 0.0041073063 | AJ13: 0.01876444 | AK13: 0.00011314705 | AM13: 6.7283204e-05 | AN13: 2.0182144e-05 | AP13: 0.0093979855 | AQ13: 1.5110322e-05 | AR13: 7.089245e-06 | AS13: 0.0010243135 | AT13: 0.01022288 | AU13: 0.00034869089 | AV13: 0.0035798873 | AX13: 0.0027984043 | AZ13: 3.235321e-05 | BA13: 0.00071531449 | BB13: 6.8314593e-05 | BC13: 0.0033108409 | BD13: 0.046397267 | BE13: 0.05055488 | BF13: 0.035236415 | BG13: 0.0081729365 | BH13: 0.0038313672 | BI13: 0.026111273 | BJ13: 0.00048049151 | BK13: 0.0031894252 | BL13: 0.0062339121 | BM13: 0.00013240444 | BN13: 0.0088596383 | BO13: 1.3372722e-05 | BP13: 0.008673031 | BQ13: 0.0015649482 | BS13: 0.0038208565 | BT13: 1.8395366e-05 | BU13: 0.00046972037 | BV13: 0.03214806 | BW13: 7.3709483e-05 | BY13: 1.9442712e-05 | BZ13: 0.0013652987 | CA13: 0.0049068844 | CB13: 0.010239002 | CC13: 0.0012948509 | CD13: 1.5395172e-07 | CE13: 0.040305325 | CF13: 0.0020195919 | CG13: 0.00073725437 | CH13: 0.00055354746 | CI13: 0.0016582901 | CJ13: 2.5862782e-05 | CK13: 1.0388965e-05 | CL13: 0.0043802427 | CM13: 0.0012721896 | CN13: 0.0088733613 | CO13: 0.029043871 | CP13: 0.021706008 | CQ13: 0.026336167 | CR13: 2.6462884e-05 | CS13: 5.6054117e-06 | CT13: 0.0040436043 | CU13: 0.0055818949 | CV13: 0.010762896 | CW13: 0.00077171375 | CX13: 3.3873525e-05 | CY13: 0.00040848276 | CZ13: 0.016213186 | DA13: 0.03560045 | DB13: 3.5975067e-07 | DC13: 5.7685701e-06 | DD13: 3.0692235e-06 | DE13: 8.3387633e-06 | DF13: 0.00034285036 | DG13: 9.2779813e-05 | DH13: 0.00026845394 | DI13: 0.00026615184 | DJ13: 0.0022117585 | DK13: 0.0016954134 | DL13: 3.3919141e-05 | DM13: 0.032218299 | DN13: 2.3519218e-05 | DO13: 7.4411924e-05 | DP13: 0.0021141522 | DQ13: 0.011212417 | DR13: 0.00021108918 | DS13: 0.0020149012 | DT13: 0.012117478 | DU13: 0.0266224 | DV13: 0.013315116 | DW13: 0.037650145 | DY13: 0.0033401719 | EA13: 1.3078467e-05 | EC13: 5.5132038e-05 | EE13: 6.5297096e-05 | EG13: 4.1858338e-05 | EH13: 1.3272892e-05 | EI13: 0.0014631179 | EK13: 6.2662486e-05 | EN13: 4.7286059e-06 | EQ13: 8.6845041e-06 | EU13: 0.0020432879 | EW13: 5.3610039e-06 | EX13: 2.8785124e-05 | EY13: 1.2813871e-05 | EZ13: 1.480249e-05 | FA13: 2.3126706e-05 | FC13: 4.3922902e-05 | FE13: 1.8887574e-06 | FG13: 2.9915224e-06 | FO13: 8.7172481e-06 | FP13: 0.0001057725
A14: 2014 | C14: 0.045007725 | D14: 0.001120761 | F14: 0.0055183575 | G14: 0.0002171418 | I14: 0.013873411 | J14: 3.5651702e-05 | K14: 0.0039490318 | L14: 2.4751979e-08 | M14: 2.5237633e-06 | N14: 0.0064614253 | O14: 0.075855082 | P14: 2.7079298e-06 | Q14: 6.9915064e-06 | R14: 0.0005139928 | S14: 0.00068531848 | T14: 9.8840484e-05 | U14: 0.018115358 | V14: 0.023266392 | W14: 0.0092097674 | X14: 0.00025881429 | Y14: 5.7133793e-05 | Z14: 0.00036736899 | AA14: 0.00042380163 | AB14: 0.0066104052 | AC14: 0.00061979652 | AD14: 0.00012276376 | AE14: 0.0014960764 | AF14: 0.011069636 | AH14: 0.0028477635 | AI14: 0.0061174148 | AJ14: 0.018777274 | AK14: 0.00020903621 | AL14: 6.3886074e-06 | AM14: 5.1386156e-05 | AP14: 0.0035223953 | AQ14: 4.3781723e-05 | AS14: 7.8884656e-06 | AT14: 0.012311644 | AU14: 1.1761419e-06 | AV14: 0.0038079286 | AX14: 0.00073121794 | AZ14: 5.404812e-05 | BA14: 0.00048137375 | BB14: 0.0010461396 | BC14: 0.0031546707 | BD14: 0.068031251 | BE14: 0.04483212 | BF14: 0.039057653 | BG14: 0.0098481766 | BH14: 0.0034928312 | BI14: 0.027392143 | BJ14: 3.5611999e-05 | BK14: 0.0019933446 | BL14: 0.0071389453 | BM14: 1.9129518e-05 | BN14: 0.01099147 | BO14: 2.6004245e-05 | BP14: 0.014183975 | BQ14: 0.0023348837 | BS14: 0.0066680971 | BT14: 1.9290928e-05 | BU14: 0.00046571905 | BV14: 0.032961794 | BY14: 1.4072395e-05 | BZ14: 0.0015415067 | CA14: 0.004728903 | CB14: 0.0118167 | CC14: 0.0011988447 | CE14: 0.033251116 | CF14: 0.00029393078 | CG14: 0.0012280041 | CH14: 0.0010392829 | CI14: 0.00096723634 | CK14: 1.1116916e-05 | CL14: 0.0043839005 | CM14: 0.0012994921 | CN14: 0.0091098594 | CO14: 0.028314622 | CP14: 0.031071465 | CQ14: 0.036238295 | CR14: 0.00033654202 | CS14: 2.6565637e-06 | CT14: 0.0032957031 | CU14: 0.0092427709 | CV14: 0.011014305 | CW14: 0.00044115063 | CY14: 0.00013543405 | CZ14: 0.0145893 | DA14: 0.049755321 | DB14: 1.3267628e-06 | DD14: 2.1174074e-06 | DE14: 6.8209819e-06 | DF14: 0.00025290819 | DG14: 7.7118021e-05 | DH14: 0.00023784009 | DI14: 0.00049527626 | DJ14: 0.0030807571 | DK14: 0.0019948251 | DL14: 8.8008265e-05 | DM14: 0.022581655 | DO14: 0.00011027409 | DP14: 0.0012558823 | DQ14: 0.012359607 | DR14: 9.9555411e-05 | DS14: 0.0010491536 | DT14: 0.027179081 | DU14: 0.010869391 | DV14: 0.013196158 | DW14: 0.043054061 | DY14: 0.0029418427 | DZ14: 2.0617646e-07 | EA14: 2.0210488e-05 | EB14: 5.4506466e-07 | EC14: 4.5063414e-05 | EE14: 8.5578153e-07 | EG14: 2.8437738e-05 | EH14: 1.2399658e-05 | EI14: 0.0019249228 | EK14: 0.00011721027 | EN14: 5.2844875e-06 | EQ14: 3.4924655e-06 | EU14: 0.0016668838 | EX14: 5.2857774e-05 | EZ14: 8.2338214e-06 | FA14: 0.00014797112 | FC14: 1.7461714e-05 | FE14: 4.3275864e-05 | FG14: 2.1830853e-06 | FP14: 0.00018798329
A15: 2015 | B15: 7.272895e-05 | C15: 0.042761133 | D15: 0.00082826536 | F15: 0.012948066 | G15: 0.00021490314 | I15: 0.010001724 | J15: 1.9151703e-06 | K15: 0.005496276 | M15: 8.1876708e-06 | N15: 0.0057426158 | O15: 0.052870437 | P15: 6.6844592e-06 | Q15: 1.7460079e-05 | R15: 0.00049451612 | S15: 0.0012649007 | T15: 8.9469857e-05 | U15: 0.021588091 | V15: 0.033681952 | W15: 0.0015145607 | X15: 7.2710847e-05 | Y15: 0.00024538619 | Z15: 0.0001792779 | AA15: 0.00037303463 | AB15: 0.002607684 | AC15: 0.0015548948 | AD15: 0.00012104872 | AE15: 0.0008145179 | AF15: 0.015703405 | AH15: 0.0027461851 | AI15: 0.0035593533 | AJ15: 0.03104585 | AK15: 0.00014361012 | AM15: 3.150556e-05 | AP15: 0.0088529578 | AQ15: 1.8498448e-05 | AT15: 0.012223775 | AU15: 0.00024646758 | AV15: 0.0050052002 | AX15: 0.0012041668 | AZ15: 2.5168173e-05 | BA15: 2.689854e-05 | BB15: 6.2449118e-05 | BC15: 0.0031257537 | BD15: 0.10335819 | BE15: 0.036547953 | BF15: 0.030516748 | BG15: 0.0089872367 | BH15: 0.003253199 | BI15: 0.035047302 | BJ15: 6.9465922e-05 | BK15: 0.0014128191 | BL15: 0.0077343389 | BM15: 1.1998109e-06 | BN15: 0.025239392 | BO15: 1.7369679e-05 | BP15: 0.0096846697 | BQ15: 0.0024041812 | BS15: 0.0040359733 | BT15: 3.3070226e-05 | BU15: 0.00057435146 | BV15: 0.033502882 | BW15: 3.8783704e-06 | BY15: 5.9304592e-06 | BZ15: 0.0015812781 | CA15: 0.0052419302 | CB15: 0.0076253106 | CC15: 0.002192541 | CE15: 0.030002497 | CF15: 0.0023646427 | CG15: 0.00091201269 | CH15: 0.00082869217 | CI15: 0.0041310801 | CK15: 1.5155143e-05 | CL15: 0.012138658 | CM15: 0.0010342374 | CN15: 0.0083819262 | CO15: 0.02102648 | CP15: 0.014085366 | CQ15: 0.030284462 | CR15: 0.00039768068 | CS15: 3.1539474e-05 | CT15: 0.0032019595 | CU15: 0.0043189272 | CV15: 0.0098988918 | CW15: 0.00081462764 | CY15: 0.0035132634 | CZ15: 0.017840982 | DA15: 0.039232368 | DD15: 1.3377172e-06 | DF15: 0.00028779551 | DG15: 2.7082229e-05 | DH15: 0.0006308366 | DI15: 0.00027719851 | DJ15: 0.0013498393 | DK15: 0.0012355233 | DM15: 0.016791212 | DN15: 3.3160067e-06 | DO15: 6.8463312e-06 | DP15: 0.00028495165 | DQ15: 0.009801564 | DR15: 7.7375931e-05 | DS15: 0.0003324961 | DT15: 0.018928616 | DU15: 0.032307394 | DV15: 0.012518648 | DW15: 0.039816665 | DY15: 0.0018748437 | EA15: 9.5430052e-06 | EC15: 1.4964821e-05 | EG15: 5.4700363e-05 | EH15: 9.6901764e-06 | EI15: 0.00091268934 | EJ15: 4.4816724e-06 | EK15: 6.2322964e-05 | EM15: 0.00055423165 | EN15: 2.8182825e-07 | EQ15: 4.0218721e-05 | EU15: 8.8924795e-05 | EX15: 3.6875611e-05 | EZ15: 1.4346309e-05 | FA15: 8.7506464e-06 | FC15: 1.2576262e-05 | FE15: 6.8112961e-05 | FG15: 3.8650908e-06 | FP15: 0.00044829544 | FQ15: 0.00018824793 | FR15: 0.0027834607
A16: 2016 | B16: 5.8664071e-05 | C16: 0.037599371 | D16: 0.00014193101 | F16: 0.017264406 | G16: 0.00021338513 | H16: 1.8189108e-05 | I16: 0.020296622 | J16: 1.5067374e-07 | K16: 0.0047969689 | N16: 0.0055003496 | O16: 0.06321037 | P16: 6.1185088e-06 | Q16: 1.6710359e-05 | R16: 0.0004934157 | S16: 0.00069490825 | T16: 0.00016227373 | U16: 0.017966777 | V16: 0.013403539 | W16: 0.0026281172 | X16: 5.0169731e-05 | Y16: 2.9765365e-05 | Z16: 0.00013101504 | AA16: 6.4912652e-07 | AB16: 0.0026413736 | AC16: 0.0012755992 | AD16: 0.00011070327 | AE16: 0.0007097731 | AF16: 0.011020287 | AH16: 0.0024132099 | AI16: 0.0044941261 | AJ16: 0.052458195 | AK16: 9.6037114e-05 | AM16: 8.7877599e-05 | AP16: 0.0054853201 | AQ16: 2.5300686e-06 | AT16: 0.01339574 | AU16: 0.0003783663 | AV16: 0.0039730361 | AX16: 0.0013785741 | AY16: 5.9653978e-06 | AZ16: 3.0260416e-06 | BB16: 6.2332837e-05 | BC16: 0.0029283147 | BD16: 0.10256038 | BE16: 0.038061466 | BF16: 0.017999776 | BG16: 0.0094281245 | BH16: 0.0058532801 | BI16: 0.026327644 | BJ16: 4.4721248e-05 | BK16: 0.0047736601 | BL16: 0.0069096808 | BM16: 3.8504567e-05 | BN16: 0.021175616 | BO16: 1.0820159e-05 | BP16: 0.0041731318 | BQ16: 0.0038904137 | BS16: 0.0031935708 | BT16: 5.9560304e-06 | BU16: 0.00082714735 | BV16: 0.034643233 | BW16: 4.4080084e-06 | BZ16: 0.0020152258 | CA16: 0.0041161766 | CB16: 0.0083794731 | CC16: 0.0012942837 | CE16: 0.017753896 | CF16: 0.0033084434 | CG16: 0.00033927859 | CH16: 0.00031873308 | CI16: 0.00038591967 | CK16: 2.1812792e-05 | CL16: 0.010848688 | CM16: 0.00077093403 | CN16: 0.0075592802 | CO16: 0.027168222 | CP16: 0.015968685 | CQ16: 0.02860016 | CR16: 0.0021821684 | CS16: 5.3944914e-05 | CT16: 0.0015637207 | CU16: 0.0042615464 | CV16: 0.0092547359 | CW16: 0.00068729887 | CY16: 7.3701045e-05 | CZ16: 0.016859337 | DA16: 0.040254176 | DE16: 5.1161749e-06 | DF16: 0.00033979213 | DH16: 0.00029870119 | DI16: 0.00024159033 | DJ16: 0.00074773589 | DK16: 0.00095161873 | DL16: 0.00035113393 | DM16: 0.016000148 | DO16: 1.5099731e-05 | DP16: 0.004471492 | DQ16: 0.018325311 | DR16: 5.4505504e-05 | DS16: 0.001810639 | DT16: 0.013273847 | DU16: 0.075539477 | DV16: 0.0088958868 | DW16: 0.014953699 | DY16: 0.0017001868 | EA16: 2.0768363e-05 | EC16: 0.00076845355 | EG16: 3.0287538e-05 | EH16: 0.0025601276 | EI16: 1.1199824e-05 | EJ16: 8.9763079e-06 | EK16: 0.00010198254 | EL16: 2.0432537e-06 | EM16: 2.5235688e-07 | EN16: 4.0767666e-06 | EQ16: 3.3992369e-05 | EU16: 6.5716668e-05 | EX16: 1.406899e-05 | EZ16: 5.3610117e-07 | FA16: 5.2484785e-06 | FE16: 2.9883687e-05 | FG16: 3.225524e-06 | FI16: 7.5836979e-06 | FP16: 0.0001344515 | FQ16: 0.0013030486 | FR16: 0.00018496071
A17: 2017 | B17: 9.9149904e-06 | C17: 0.032639659 | D17: 0.00035056608 | F17: 0.0089868281 | G17: 0.0001443185 | I17: 0.022786847 | J17: 1.4503622e-06 | K17: 0.0054838907 | M17: 6.1734212e-06 | N17: 0.0061021011 | O17: 0.080404168 | P17: 5.61784e-05 | R17: 0.00014116889 | S17: 0.00054983242 | T17: 0.00010361611 | U17: 0.022103112 | V17: 0.018833957 | W17: 0.003286681 | X17: 0.00023417562 | Y17: 9.7058625e-05 | Z17: 0.0001278978 | AA17: 7.3662987e-05 | AB17: 0.00078250516 | AC17: 0.00084152513 | AD17: 0.00010273925 | AE17: 0.0011751002 | AF17: 0.012330217 | AH17: 0.00055986821 | AI17: 0.0074120861 | AJ17: 0.035875494 | AK17: 0.00014407325 | AM17: 3.5540983e-07 | AN17: 3.7896465e-07 | AP17: 0.0023422293 | AQ17: 4.6881588e-05 | AT17: 0.0087791298 | AU17: 0.0010865864 | AV17: 0.0051201996 | AW17: 7.0307403e-06 | AX17: 0.0020919896 | AZ17: 9.8574028e-06 | BA17: 0.00017888649 | BB17: 7.5875574e-05 | BC17: 0.0030180181 | BD17: 0.10562379 | BE17: 0.049538909 | BF17: 0.022891066 | BG17: 0.0078983636 | BH17: 0.0034531438 | BI17: 0.036653608 | BK17: 0.003549456 | BL17: 0.0089071762 | BM17: 9.8192256e-06 | BN17: 0.0024298893 | BO17: 9.5138861e-05 | BP17: 0.0029381512 | BQ17: 0.0036853734 | BS17: 0.00048122511 | BU17: 0.0010076592 | BV17: 0.031394743 | BX17: 0.013039589 | BY17: 4.7054197e-06 | BZ17: 0.00167319 | CA17: 0.0039637777 | CB17: 0.0099778562 | CC17: 0.0020450167 | CD17: 8.8232734e-05 | CE17: 0.033842194 | CF17: 0.002127984 | CG17: 0.00041397701 | CH17: 0.00024202877 | CI17: 0.00020876841 | CK17: 0.00054499263 | CL17: 0.0029933957 | CM17: 0.00032054582 | CN17: 0.0074817188 | CO17: 0.025880849 | CP17: 0.010223782 | CQ17: 0.03103904 | CR17: 0.0019741183 | CS17: 2.8674831e-05 | CT17: 0.0042171472 | CU17: 0.0053827168 | CV17: 0.011449167 | CW17: 0.00089395567 | CY17: 4.3244274e-05 | CZ17: 0.017921128 | DA17: 0.042549263 | DB17: 5.15514e-05 | DE17: 6.6231611e-06 | DF17: 0.0006485411 | DG17: 2.1635687e-07 | DH17: 0.00041007853 | DI17: 0.00025437922 | DJ17: 1.1685702e-05 | DK17: 0.0011699521 | DL17: 0.00019753568 | DM17: 0.017244414 | DN17: 6.6639191e-06 | DO17: 1.4000055e-05 | DP17: 0.0028462007 | DQ17: 0.014700833 | DR17: 0.00023793133 | DS17: 0.0020791941 | DT17: 0.020476204 | DU17: 0.051915857 | DV17: 0.010411986 | DW17: 0.010000742 | DY17: 0.0029520195 | DZ17: 3.7003866e-07 | EA17: 2.8961687e-05 | EC17: 0.0021441678 | EE17: 4.0139943e-07 | EG17: 8.2549654e-06 | EH17: 0.0043031585 | EI17: 0.0015287893 | EJ17: 1.1292551e-07 | EK17: 0.00012537137 | EL17: 3.3366874e-07 | EM17: 2.2502608e-07 | EO17: 7.6487566e-06 | EQ17: 1.3097963e-05 | EU17: 0.00011965463 | EW17: 6.524162e-05 | EX17: 6.2805253e-05 | EZ17: 5.0218479e-06 | FA17: 1.3380701e-05 | FE17: 9.5729827e-05 | FG17: 1.6450734e-06 | FP17: 0.00020386632 | FQ17: 0.0017582927
A18: 2018 | C18: 0.04778759 | D18: 0.00015696887 | F18: 0.019014381 | I18: 0.021194454 | K18: 0.0075213856 | N18: 0.0064868061 | O18: 0.084030271 | P18: 3.9859779e-05 | S18: 0.0016818254 | T18: 0.0022687739 | U18: 0.026230633 | V18: 0.038280998 | W18: 0.0033934644 | X18: 9.3623369e-05 | Y18: 5.7990128e-05 | Z18: 8.7914593e-05 | AB18: 0.0032949153 | AC18: 0.0010839516 | AD18: 0.00011060806 | AE18: 0.002231736 | AF18: 0.014685101 | AH18: 0.00063817998 | AI18: 0.0085515223 | AJ18: 0.02643676 | AK18: 3.9707283e-05 | AP18: 0.0026237609 | AQ18: 4.4064569e-05 | AT18: 0.0085573888 | AU18: 0.0016958801 | AV18: 0.0057428173 | AX18: 0.0010052316 | AZ18: 0.00016247811 | BB18: 5.3203968e-05 | BC18: 0.0032137525 | BD18: 0.080263069 | BE18: 0.045264289 | BF18: 0.017480335 | BG18: 0.012159889 | BH18: 0.0053840932 | BI18: 0.030888416 | BK18: 0.0025088161 | BL18: 0.0075291604 | BN18: 9.7207673e-05 | BO18: 2.3283021e-05 | BQ18: 0.0029216238 | BS18: 0.0020728885 | BU18: 0.00056047633 | BV18: 0.027517078 | BX18: 0.0185233 | BZ18: 0.0017804659 | CA18: 0.0055078279 | CB18: 0.0097486027 | CC18: 0.0038349344 | CE18: 0.049180509 | CF18: 0.0019487108 | CG18: 0.00020944145 | CI18: 0.00011720631 | CK18: 0.00057269462 | CL18: 0.0013142659 | CM18: 0.00045667224 | CN18: 0.0094822559 | CO18: 0.024309745 | CP18: 0.017779395 | CQ18: 0.030881965 | CR18: 0.00012694062 | CS18: 3.224668e-05 | CT18: 1.878626e-05 | CU18: 0.0097816955 | CV18: 0.01279102 | CW18: 0.0009733997 | CY18: 5.4154922e-05 | CZ18: 0.013851707 | DA18: 0.034913851 | DB18: 9.4477918e-06 | DF18: 0.00017854073 | DH18: 0.00063098619 | DI18: 0.00023059899 | DK18: 0.0011616307 | DM18: 0.015203898 | DP18: 0.001839322 | DQ18: 0.019033284 | DR18: 4.8379024e-05 | DS18: 0.0026354119 | DT18: 0.025677044 | DU18: 0.010024376 | DV18: 0.0097420991 | DW18: 0.014133367 | DY18: 0.0052743699 | EC18: 0.0027129881 | EH18: 0.0082336307 | EI18: 0.0017800649 | EQ18: 1.4081448e-05 | EU18: 0.00012800356 | EX18: 3.6022206e-05 | FG18: 1.8883029e-06
A19: 2019 | C19: 0.039839414 | D19: 0.00020059154 | F19: 0.013070659 | G19: 2.7853515e-05 | I19: 0.026654031 | J19: 2.0867857e-05 | K19: 0.0027368411 | N19: 0.0066103267 | O19: 0.072611829 | P19: 9.3617757e-05 | R19: 0.00042332752 | S19: 0.00089949999 | T19: 0.00095524112 | U19: 0.027511189 | V19: 0.075413467 | W19: 0.0038709155 | X19: 8.1726496e-05 | Y19: 3.7039788e-05 | Z19: 9.1341817e-05 | AB19: 0.0034866833 | AC19: 0.0023004227 | AD19: 0.00015573879 | AE19: 0.0025025706 | AF19: 0.012099299 | AH19: 0.0038297916 | AI19: 0.0061030511 | AJ19: 0.017685498 | AK19: 6.530907e-05 | AP19: 0.0023343268 | AT19: 0.0088180557 | AU19: 0.0021028311 | AV19: 0.0054312753 | AX19: 0.00068696756 | AZ19: 0.00016386488 | BB19: 0.00013826984 | BC19: 0.0026687796 | BD19: 0.092178914 | BE19: 0.050390881 | BF19: 0.017613132 | BG19: 0.011512462 | BH19: 0.0037420603 | BI19: 0.029859476 | BK19: 0.0024518428 | BL19: 0.0043468995 | BM19: 2.8377393e-06 | BN19: 0.0061402246 | BO19: 2.4468471e-05 | BQ19: 0.0010396367 | BS19: 0.0029067456 | BU19: 0.0005946647 | BV19: 0.021165595 | BX19: 0.0059019849 | BZ19: 0.0012245829 | CA19: 0.0037040603 | CB19: 0.012656391 | CC19: 0.0037144798 | CE19: 0.055255964 | CF19: 0.0036755776 | CG19: 0.00014467137 | CI19: 5.9585549e-05 | CK19: 0.0016146271 | CL19: 0.0010352625 | CM19: 0.00056359325 | CN19: 0.008769268 | CO19: 0.026259213 | CP19: 0.016404387 | CQ19: 0.026220711 | CR19: 0.0020631372 | CS19: 2.3634032e-05 | CT19: 2.6350546e-05 | CU19: 0.0062727641 | CV19: 0.015764921 | CW19: 0.0012123997 | CZ19: 0.013392796 | DA19: 0.040590875 | DI19: 0.00012766297 | DK19: 0.0010721368 | DM19: 0.020596865 | DP19: 0.0023135306 | DQ19: 0.015006586 | DR19: 3.021278e-05 | DS19: 0.0016481114 | DT19: 0.016783326 | DU19: 0.010449047 | DV19: 0.0081154798 | DW19: 0.0025637735 | DY19: 0.0028479213 | EA19: 2.2477826e-05 | EC19: 0.00092541952 | EG19: 4.9560036e-07 | EH19: 0.0035919328 | EI19: 0.00071178982 | EQ19: 9.7421032e-06 | EU19: 7.0358131e-05 | EX19: 2.588113e-05
A20: 2020 | C20: 0.02753875 | D20: 7.1782017e-05 | F20: 0.0089900991 | G20: 5.7117546e-05 | I20: 0.016609293 | K20: 0.00084548697 | N20: 0.0070374151 | O20: 0.074881817 | P20: 0.000138381 | S20: 0.00072253192 | T20: 0.00017546984 | U20: 0.038633205 | V20: 0.075920581 | W20: 0.0046332232 | X20: 0.00017958979 | Y20: 4.3367181e-05 | Z20: 0.00062042617 | AB20: 0.0027922291 | AC20: 0.0014410514 | AD20: 0.00013662262 | AE20: 0.0019364146 | AF20: 0.013656894 | AH20: 0.001508001 | AI20: 0.0058151604 | AJ20: 0.014325431 | AK20: 0.00010171156 | AP20: 0.0065726176 | AT20: 0.0097013858 | AU20: 0.0018465491 | AV20: 0.0084873821 | AX20: 0.00044536598 | AZ20: 7.9137362e-05 | BB20: 0.00010388185 | BC20: 0.0013796407 | BD20: 0.11714928 | BE20: 0.041335038 | BF20: 0.0099343009 | BG20: 0.010826634 | BH20: 0.0082707406 | BI20: 0.030502734 | BK20: 0.0029594283 | BL20: 0.0063378554 | BN20: 0.0012029926 | BO20: 5.7477049e-05 | BP20: 0.0026258576 | BQ20: 0.0027469593 | BS20: 0.0009388642 | BU20: 0.0010072172 | BV20: 0.029856754 | BW20: 5.0066933e-05 | BZ20: 0.0010459406 | CA20: 0.0037877245 | CB20: 0.013259251 | CC20: 0.0062393941 | CE20: 0.050089939 | CF20: 0.00090709053 | CG20: 0.00023576103 | CI20: 4.9333678e-05 | CK20: 0.0011426055 | CL20: 0.0026725153 | CM20: 0.00039209889 | CN20: 0.0078564959 | CO20: 0.028629191 | CP20: 0.0096611813 | CQ20: 0.025802929 | CR20: 0.00063478807 | CS20: 3.5987952e-05 | CU20: 0.0083950234 | CV20: 0.015402377 | CW20: 0.0014574427 | CY20: 8.0555961e-06 | CZ20: 0.016018582 | DA20: 0.028916679 | DH20: 0.00059396813 | DI20: 9.4639846e-05 | DK20: 0.0013016077 | DM20: 0.011590469 | DP20: 0.0024831987 | DQ20: 0.01962561 | DR20: 4.5489985e-05 | DS20: 0.0013543693 | DT20: 0.0098312292 | DU20: 0.012546928 | DV20: 0.011516959 | DW20: 0.0014869445 | DY20: 0.0065071757 | EA20: 2.377717e-05 | EC20: 0.0067601246 | EH20: 0.008917712 | EI20: 0.001796247 | EU20: 7.7356663e-05 | EX20: 2.1468378e-05 | FS20: 0.00020447906
A21: 2021 | C21: 0.023121799 | D21: 0.00014051614 | F21: 0.0043596941 | G21: 8.916607e-05 | I21: 0.02353847 | K21: 0.0013041604 | N21: 0.0049293039 | O21: 0.061382038 | P21: 8.0963856e-05 | S21: 0.00031975353 | T21: 0.0001325037 | U21: 0.038812968 | V21: 0.057256357 | W21: 0.010845228 | Y21: 0.00016124979 | Z21: 0.0002461436 | AB21: 0.002660912 | AC21: 0.0013387636 | AD21: 0.00013444454 | AE21: 0.0020870092 | AF21: 0.0077868096 | AH21: 0.0071977668 | AI21: 0.014174131 | AJ21: 0.015931586 | AK21: 0.00020368425 | AP21: 0.0094659621 | AT21: 0.0062406719 | AU21: 0.0014846017 | AV21: 0.0053106172 | AX21: 0.0035230701 | AZ21: 0.00010397317 | BB21: 7.2486374e-05 | BC21: 0.00094593061 | BD21: 0.12616301 | BE21: 0.05240759 | BF21: 0.0051477093 | BG21: 0.0078683214 | BH21: 0.0067381967 | BI21: 0.019611604 | BK21: 0.0059419647 | BL21: 0.0066817704 | BM21: 3.5574621e-06 | BN21: 0.009742866 | BO21: 3.0239809e-05 | BP21: 0.0023750188 | BQ21: 0.00062019472 | BS21: 0.0036143371 | BV21: 0.024661549 | BZ21: 0.0013910302 | CA21: 0.0053963365 | CB21: 0.0075799645 | CC21: 0.0067269896 | CE21: 0.078352662 | CF21: 0.00092596205 | CG21: 0.00039265076 | CI21: 0.0015776662 | CK21: 0.0018065204 | CL21: 0.000351614 | CM21: 0.00051989187 | CN21: 0.0068984101 | CO21: 0.024176023 | CP21: 0.012973484 | CQ21: 0.02267704 | CR21: 0.0015900814 | CS21: 9.7553188e-05 | CT21: 0.0020730349 | CU21: 0.0055462117 | CV21: 0.013124787 | CW21: 0.0011749422 | CY21: 5.0483089e-05 | CZ21: 0.014922493 | DA21: 0.040671901 | DB21: 5.513677e-06 | DI21: 0.00017688022 | DK21: 0.0011488161 | DM21: 0.0098904486 | DP21: 0.0025409222 | DQ21: 0.014105089 | DR21: 1.5159697e-05 | DS21: 0.0024698542 | DT21: 0.013553551 | DU21: 0.010185931 | DV21: 0.0098054324 | DW21: 0.0045127909 | DY21: 0.003932154 | EC21: 0.004760237 | EH21: 0.010747488 | EI21: 0.00087646116 | EM21: 2.6420887e-06 | EU21: 2.5119783e-05 | EX21: 1.039035e-05 | FA21: 0.0010193971 | FS21: 9.4429028e-05
A22: 2022 | C22: 0.016763125 | D22: 0.0012006352 | F22: 0.0047484045 | G22: 0.00011799381 | I22: 0.022151166 | K22: 0.0022420424 | N22: 0.00427977 | O22: 0.07480632 | P22: 0.00015368988 | S22: 0.0019775051 | T22: 0.0022166932 | U22: 0.038215693 | V22: 0.04719342 | W22: 0.0094508494 | X22: 0.00022519106 | Y22: 6.5334021e-05 | Z22: 0.00089299262 | AB22: 0.0020474479 | AD22: 5.9685794e-05 | AE22: 0.0023790199 | AF22: 0.0044755491 | AH22: 0.011247579 | AI22: 0.019319043 | AJ22: 0.0080902051 | AK22: 0.00021799238 | AL22: 7.5765919e-06 | AP22: 0.0076785942 | AQ22: 2.8898933e-05 | AT22: 0.0081726243 | AU22: 0.0021806244 | AV22: 0.0063039448 | AX22: 0.0029465135 | AZ22: 0.0001379231 | BB22: 0.00010662056 | BC22: 0.00044418993 | BD22: 0.11620199 | BE22: 0.043650974 | BG22: 0.011453609 | BH22: 0.0058841333 | BI22: 0.026393768 | BJ22: 0.00061808338 | BK22: 0.0036185487 | BL22: 0.0064057356 | BM22: 1.3253853e-06 | BN22: 0.009079439 | BO22: 4.1607386e-05 | BP22: 0.0036993234 | BQ22: 0.00093705269 | BS22: 0.0033643728 | BU22: 0.00080281238 | BV22: 0.026275064 | BW22: 0.00018122134 | BZ22: 0.0018474914 | CA22: 0.011401849 | CB22: 0.013048665 | CC22: 0.0051313731 | CE22: 0.091656803 | CF22: 9.0986934e-05 | CG22: 0.00038606901 | CI22: 0.00092048037 | CK22: 0.0034196758 | CL22: 0.0054837524 | CM22: 0.00038902235 | CN22: 0.004928324 | CO22: 0.025648888 | CP22: 0.017886943 | CQ22: 0.027897006 | CR22: 0.0016779446 | CS22: 9.610148e-05 | CT22: 0.0026126044 | CU22: 0.0033848341 | CV22: 0.012860459 | CW22: 0.0023549892 | CY22: 0.00016965767 | CZ22: 0.0088872335 | DA22: 0.035624203 | DG22: 3.85094e-05 | DI22: 0.00018345132 | DK22: 0.0014941656 | DM22: 0.0060214352 | DP22: 0.0037392437 | DQ22: 0.020834632 | DR22: 2.823921e-05 | DS22: 0.0026343311 | DT22: 0.0074247639 | DU22: 0.011478976 | DV22: 0.01177405 | DW22: 0.0046079522 | DY22: 0.0023624875 | EH22: 0.0056764981 | EP22: 0.00033811458 | EU22: 0.0019973509 | EX22: 4.3645167e-05 | FA22: 0.0016927017 | FG22: 8.5100033e-07
