Workbook

Sheet Particip
A1: fecha | B1: Argelia | C1: Angola | D1: Australia | E1: Bangladesh | F1: Bielorrusia | G1: Bélgica | H1: Brasil | I1: Canadá | J1: Chile | K1: China | L1: Colombia | M1: Chipre | N1: Dinamarca | O1: República Dominicana | P1: Ecuador | Q1: Egipto | R1: Francia | S1: Georgia | T1: República Federal de Alemania | U1: Grecia | V1: India | W1: Indonesia | X1: Irán | Y1: Iraq | Z1: Irlanda | AA1: Israel | AB1: Italia | AC1: Japón | AD1: Jordania | AE1: Corea Republicana | AF1: Letonia | AG1: Líbano | AH1: Libia | AI1: Lituania | AJ1: Malasia | AK1: Malta | AL1: México | AM1: Marruecos | AN1: Mozambique | AO1: Países Bajos | AP1: Nigeria | AQ1: Omán | AR1: Paquistán | AS1: Paraguay | AT1: Perú | AU1: Filipinas | AV1: Polonia | AW1: Rumania | AX1: Arabia Saudita | AY1: Sudáfrica | AZ1: España | BA1: Tailandia | BB1: Túnez | BC1: Turquía | BD1: Reino Unido | BE1: Estados Unidos | BF1: Uruguay | BG1: Venezuela | BH1: Vietnam | BI1: República de Yemen | BJ1: Confidencial | BK1: Cuba
B2: Algeria | C2: Angola | D2: Australia | E2: Bangladesh | F2: Belarus, Republic of | G2: Belgium | H2: Brazil | I2: Canada | J2: Chile | K2: China, People's Republic of | L2: Colombia | M2: Cyprus | N2: Denmark | O2: Dominican Republic | P2: Ecuador | Q2: Egypt, Arab Republic of | R2: France | S2: Georgia | T2: Germany | U2: Greece | V2: India | W2: Indonesia | X2: Iran, Islamic Republic of | Y2: Iraq | Z2: Ireland | AA2: Israel | AB2: Italy | AC2: Japan | AD2: Jordan | AE2: Korea, Republic of | AF2: Latvia, Republic of | AG2: Lebanon | AH2: Libya | AI2: Lithuania, Republic of | AJ2: Malaysia | AK2: Malta | AL2: Mexico | AM2: Morocco | AN2: Mozambique, Republic of | AO2: Netherlands, The | AP2: Niger | AQ2: Oman | AR2: Pakistan | AS2: Paraguay | AT2: Peru | AU2: Philippines | AV2: Poland, Republic of | AW2: Romania | AX2: Saudi Arabia | AY2: South Africa | AZ2: Spain | BA2: Thailand | BB2: Tunisia | BC2: Türkiye, Republic of | BD2: United Kingdom | BE2: United States | BF2: Uruguay | BG2: Venezuela, República Bolivariana de | BH2: Vietnam | BI2: Yemen, Republic of
A3: 36892 | B3: 0.010150497 | E3: 0.014674798 | G3: 0.013212699 | H3: 0.10023499 | J3: 0.02942526 | K3: 0.074810125 | N3: 0.04001595 | Q3: 0.038657437 | T3: 0.017698975 | V3: 0.057864148 | X3: 0.02475185 | AB3: 0.05925471 | AD3: 0.011902904 | AJ3: 0.036667342 | AL3: 0.012018495 | AM3: 0.012906051 | AO3: 0.046847079 | AT3: 0.02509234 | AY3: 0.025665513 | AZ3: 0.061249656 | BA3: 0.026646618 | BB3: 0.011426168 | BE3: 0.049060324
A4: 36923 | B4: 0.010150497 | E4: 0.014674798 | G4: 0.013212699 | H4: 0.10023499 | J4: 0.02942526 | K4: 0.074810125 | N4: 0.04001595 | Q4: 0.038657437 | T4: 0.017698975 | V4: 0.057864148 | X4: 0.02475185 | AB4: 0.05925471 | AD4: 0.011902904 | AJ4: 0.036667342 | AL4: 0.012018495 | AM4: 0.012906051 | AO4: 0.046847079 | AT4: 0.02509234 | AY4: 0.025665513 | AZ4: 0.061249656 | BA4: 0.026646618 | BB4: 0.011426168 | BE4: 0.049060324
A5: 36951 | B5: 0.010150497 | E5: 0.014674798 | G5: 0.013212699 | H5: 0.10023499 | J5: 0.02942526 | K5: 0.074810125 | N5: 0.04001595 | Q5: 0.038657437 | T5: 0.017698975 | V5: 0.057864148 | X5: 0.02475185 | AB5: 0.05925471 | AD5: 0.011902904 | AJ5: 0.036667342 | AL5: 0.012018495 | AM5: 0.012906051 | AO5: 0.046847079 | AT5: 0.02509234 | AY5: 0.025665513 | AZ5: 0.061249656 | BA5: 0.026646618 | BB5: 0.011426168 | BE5: 0.049060324
A6: 36982 | B6: 0.010150497 | E6: 0.014674798 | G6: 0.013212699 | H6: 0.10023499 | J6: 0.02942526 | K6: 0.074810125 | N6: 0.04001595 | Q6: 0.038657437 | T6: 0.017698975 | V6: 0.057864148 | X6: 0.02475185 | AB6: 0.05925471 | AD6: 0.011902904 | AJ6: 0.036667342 | AL6: 0.012018495 | AM6: 0.012906051 | AO6: 0.046847079 | AT6: 0.02509234 | AY6: 0.025665513 | AZ6: 0.061249656 | BA6: 0.026646618 | BB6: 0.011426168 | BE6: 0.049060324
A7: 37012 | B7: 0.010150497 | E7: 0.014674798 | G7: 0.013212699 | H7: 0.10023499 | J7: 0.02942526 | K7: 0.074810125 | N7: 0.04001595 | Q7: 0.038657437 | T7: 0.017698975 | V7: 0.057864148 | X7: 0.02475185 | AB7: 0.05925471 | AD7: 0.011902904 | AJ7: 0.036667342 | AL7: 0.012018495 | AM7: 0.012906051 | AO7: 0.046847079 | AT7: 0.02509234 | AY7: 0.025665513 | AZ7: 0.061249656 | BA7: 0.026646618 | BB7: 0.011426168 | BE7: 0.049060324
A8: 37043 | B8: 0.010150497 | E8: 0.014674798 | G8: 0.013212699 | H8: 0.10023499 | J8: 0.02942526 | K8: 0.074810125 | N8: 0.04001595 | Q8: 0.038657437 | T8: 0.017698975 | V8: 0.057864148 | X8: 0.02475185 | AB8: 0.05925471 | AD8: 0.011902904 | AJ8: 0.036667342 | AL8: 0.012018495 | AM8: 0.012906051 | AO8: 0.046847079 | AT8: 0.02509234 | AY8: 0.025665513 | AZ8: 0.061249656 | BA8: 0.026646618 | BB8: 0.011426168 | BE8: 0.049060324
A9: 37073 | B9: 0.010150497 | E9: 0.014674798 | G9: 0.013212699 | H9: 0.10023499 | J9: 0.02942526 | K9: 0.074810125 | N9: 0.04001595 | Q9: 0.038657437 | T9: 0.017698975 | V9: 0.057864148 | X9: 0.02475185 | AB9: 0.05925471 | AD9: 0.011902904 | AJ9: 0.036667342 | AL9: 0.012018495 | AM9: 0.012906051 | AO9: 0.046847079 | AT9: 0.02509234 | AY9: 0.025665513 | AZ9: 0.061249656 | BA9: 0.026646618 | BB9: 0.011426168 | BE9: 0.049060324
A10: 37104 | B10: 0.010150497 | E10: 0.014674798 | G10: 0.013212699 | H10: 0.10023499 | J10: 0.02942526 | K10: 0.074810125 | N10: 0.04001595 | Q10: 0.038657437 | T10: 0.017698975 | V10: 0.057864148 | X10: 0.02475185 | AB10: 0.05925471 | AD10: 0.011902904 | AJ10: 0.036667342 | AL10: 0.012018495 | AM10: 0.012906051 | AO10: 0.046847079 | AT10: 0.02509234 | AY10: 0.025665513 | AZ10: 0.061249656 | BA10: 0.026646618 | BB10: 0.011426168 | BE10: 0.049060324
A11: 37135 | B11: 0.010150497 | E11: 0.014674798 | G11: 0.013212699 | H11: 0.10023499 | J11: 0.02942526 | K11: 0.074810125 | N11: 0.04001595 | Q11: 0.038657437 | T11: 0.017698975 | V11: 0.057864148 | X11: 0.02475185 | AB11: 0.05925471 | AD11: 0.011902904 | AJ11: 0.036667342 | AL11: 0.012018495 | AM11: 0.012906051 | AO11: 0.046847079 | AT11: 0.02509234 | AY11: 0.025665513 | AZ11: 0.061249656 | BA11: 0.026646618 | BB11: 0.011426168 | BE11: 0.049060324
A12: 37165 | B12: 0.010150497 | E12: 0.014674798 | G12: 0.013212699 | H12: 0.10023499 | J12: 0.02942526 | K12: 0.074810125 | N12: 0.04001595 | Q12: 0.038657437 | T12: 0.017698975 | V12: 0.057864148 | X12: 0.02475185 | AB12: 0.05925471 | AD12: 0.011902904 | AJ12: 0.036667342 | AL12: 0.012018495 | AM12: 0.012906051 | AO12: 0.046847079 | AT12: 0.02509234 | AY12: 0.025665513 | AZ12: 0.061249656 | BA12: 0.026646618 | BB12: 0.011426168 | BE12: 0.049060324
A13: 37196 | B13: 0.010150497 | E13: 0.014674798 | G13: 0.013212699 | H13: 0.10023499 | J13: 0.02942526 | K13: 0.074810125 | N13: 0.04001595 | Q13: 0.038657437 | T13: 0.017698975 | V13: 0.057864148 | X13: 0.02475185 | AB13: 0.05925471 | AD13: 0.011902904 | AJ13: 0.036667342 | AL13: 0.012018495 | AM13: 0.012906051 | AO13: 0.046847079 | AT13: 0.02509234 | AY13: 0.025665513 | AZ13: 0.061249656 | BA13: 0.026646618 | BB13: 0.011426168 | BE13: 0.049060324
A14: 37226 | B14: 0.010150497 | E14: 0.014674798 | G14: 0.013212699 | H14: 0.10023499 | J14: 0.02942526 | K14: 0.074810125 | N14: 0.04001595 | Q14: 0.038657437 | T14: 0.017698975 | V14: 0.057864148 | X14: 0.02475185 | AB14: 0.05925471 | AD14: 0.011902904 | AJ14: 0.036667342 | AL14: 0.012018495 | AM14: 0.012906051 | AO14: 0.046847079 | AT14: 0.02509234 | AY14: 0.025665513 | AZ14: 0.061249656 | BA14: 0.026646618 | BB14: 0.011426168 | BE14: 0.049060324
A15: 37257 | B15: 0.010615883 | E15: 0.015337155 | G15: 0.013143843 | H15: 0.083766652 | J15: 0.032359423 | K15: 0.082744799 | N15: 0.028932943 | Q15: 0.038970495 | T15: 0.020157052 | V15: 0.060109724 | X15: 0.021678065 | AB15: 0.065343247 | AE15: 0.012668567 | AJ15: 0.026027686 | AL15: 0.023208526 | AO15: 0.063730978 | AT15: 0.02383252 | AU15: 0.015142059 | AY15: 0.021850538 | AZ15: 0.06260458 | BA15: 0.02754049 | BE15: 0.047537382 | BH15: 0.010810951
A16: 37288 | B16: 0.010615883 | E16: 0.015337155 | G16: 0.013143843 | H16: 0.083766652 | J16: 0.032359423 | K16: 0.082744799 | N16: 0.028932943 | Q16: 0.038970495 | T16: 0.020157052 | V16: 0.060109724 | X16: 0.021678065 | AB16: 0.065343247 | AE16: 0.012668567 | AJ16: 0.026027686 | AL16: 0.023208526 | AO16: 0.063730978 | AT16: 0.02383252 | AU16: 0.015142059 | AY16: 0.021850538 | AZ16: 0.06260458 | BA16: 0.02754049 | BE16: 0.047537382 | BH16: 0.010810951
A17: 37316 | B17: 0.010615883 | E17: 0.015337155 | G17: 0.013143843 | H17: 0.083766652 | J17: 0.032359423 | K17: 0.082744799 | N17: 0.028932943 | Q17: 0.038970495 | T17: 0.020157052 | V17: 0.060109724 | X17: 0.021678065 | AB17: 0.065343247 | AE17: 0.012668567 | AJ17: 0.026027686 | AL17: 0.023208526 | AO17: 0.063730978 | AT17: 0.02383252 | AU17: 0.015142059 | AY17: 0.021850538 | AZ17: 0.06260458 | BA17: 0.02754049 | BE17: 0.047537382 | BH17: 0.010810951
A18: 37347 | B18: 0.010615883 | E18: 0.015337155 | G18: 0.013143843 | H18: 0.083766652 | J18: 0.032359423 | K18: 0.082744799 | N18: 0.028932943 | Q18: 0.038970495 | T18: 0.020157052 | V18: 0.060109724 | X18: 0.021678065 | AB18: 0.065343247 | AE18: 0.012668567 | AJ18: 0.026027686 | AL18: 0.023208526 | AO18: 0.063730978 | AT18: 0.02383252 | AU18: 0.015142059 | AY18: 0.021850538 | AZ18: 0.06260458 | BA18: 0.02754049 | BE18: 0.047537382 | BH18: 0.010810951
A19: 37377 | B19: 0.010615883 | E19: 0.015337155 | G19: 0.013143843 | H19: 0.083766652 | J19: 0.032359423 | K19: 0.082744799 | N19: 0.028932943 | Q19: 0.038970495 | T19: 0.020157052 | V19: 0.060109724 | X19: 0.021678065 | AB19: 0.065343247 | AE19: 0.012668567 | AJ19: 0.026027686 | AL19: 0.023208526 | AO19: 0.063730978 | AT19: 0.02383252 | AU19: 0.015142059 | AY19: 0.021850538 | AZ19: 0.06260458 | BA19: 0.02754049 | BE19: 0.047537382 | BH19: 0.010810951
A20: 37408 | B20: 0.010615883 | E20: 0.015337155 | G20: 0.013143843 | H20: 0.083766652 | J20: 0.032359423 | K20: 0.082744799 | N20: 0.028932943 | Q20: 0.038970495 | T20: 0.020157052 | V20: 0.060109724 | X20: 0.021678065 | AB20: 0.065343247 | AE20: 0.012668567 | AJ20: 0.026027686 | AL20: 0.023208526 | AO20: 0.063730978 | AT20: 0.02383252 | AU20: 0.015142059 | AY20: 0.021850538 | AZ20: 0.06260458 | BA20: 0.02754049 | BE20: 0.047537382 | BH20: 0.010810951
A21: 37438 | B21: 0.010615883 | E21: 0.015337155 | G21: 0.013143843 | H21: 0.083766652 | J21: 0.032359423 | K21: 0.082744799 | N21: 0.028932943 | Q21: 0.038970495 | T21: 0.020157052 | V21: 0.060109724 | X21: 0.021678065 | AB21: 0.065343247 | AE21: 0.012668567 | AJ21: 0.026027686 | AL21: 0.023208526 | AO21: 0.063730978 | AT21: 0.02383252 | AU21: 0.015142059 | AY21: 0.021850538 | AZ21: 0.06260458 | BA21: 0.02754049 | BE21: 0.047537382 | BH21: 0.010810951
A22: 37469 | B22: 0.010615883 | E22: 0.015337155 | G22: 0.013143843 | H22: 0.083766652 | J22: 0.032359423 | K22: 0.082744799 | N22: 0.028932943 | Q22: 0.038970495 | T22: 0.020157052 | V22: 0.060109724 | X22: 0.021678065 | AB22: 0.065343247 | AE22: 0.012668567 | AJ22: 0.026027686 | AL22: 0.023208526 | AO22: 0.063730978 | AT22: 0.02383252 | AU22: 0.015142059 | AY22: 0.021850538 | AZ22: 0.06260458 | BA22: 0.02754049 | BE22: 0.047537382 | BH22: 0.010810951
A23: 37500 | B23: 0.010615883 | E23: 0.015337155 | G23: 0.013143843 | H23: 0.083766652 | J23: 0.032359423 | K23: 0.082744799 | N23: 0.028932943 | Q23: 0.038970495 | T23: 0.020157052 | V23: 0.060109724 | X23: 0.021678065 | AB23: 0.065343247 | AE23: 0.012668567 | AJ23: 0.026027686 | AL23: 0.023208526 | AO23: 0.063730978 | AT23: 0.02383252 | AU23: 0.015142059 | AY23: 0.021850538 | AZ23: 0.06260458 | BA23: 0.02754049 | BE23: 0.047537382 | BH23: 0.010810951
A24: 37530 | B24: 0.010615883 | E24: 0.015337155 | G24: 0.013143843 | H24: 0.083766652 | J24: 0.032359423 | K24: 0.082744799 | N24: 0.028932943 | Q24: 0.038970495 | T24: 0.020157052 | V24: 0.060109724 | X24: 0.021678065 | AB24: 0.065343247 | AE24: 0.012668567 | AJ24: 0.026027686 | AL24: 0.023208526 | AO24: 0.063730978 | AT24: 0.02383252 | AU24: 0.015142059 | AY24: 0.021850538 | AZ24: 0.06260458 | BA24: 0.02754049 | BE24: 0.047537382 | BH24: 0.010810951
A25: 37561 | B25: 0.010615883 | E25: 0.015337155 | G25: 0.013143843 | H25: 0.083766652 | J25: 0.032359423 | K25: 0.082744799 | N25: 0.028932943 | Q25: 0.038970495 | T25: 0.020157052 | V25: 0.060109724 | X25: 0.021678065 | AB25: 0.065343247 | AE25: 0.012668567 | AJ25: 0.026027686 | AL25: 0.023208526 | AO25: 0.063730978 | AT25: 0.02383252 | AU25: 0.015142059 | AY25: 0.021850538 | AZ25: 0.06260458 | BA25: 0.02754049 | BE25: 0.047537382 | BH25: 0.010810951
A26: 37591 | B26: 0.010615883 | E26: 0.015337155 | G26: 0.013143843 | H26: 0.083766652 | J26: 0.032359423 | K26: 0.082744799 | N26: 0.028932943 | Q26: 0.038970495 | T26: 0.020157052 | V26: 0.060109724 | X26: 0.021678065 | AB26: 0.065343247 | AE26: 0.012668567 | AJ26: 0.026027686 | AL26: 0.023208526 | AO26: 0.063730978 | AT26: 0.02383252 | AU26: 0.015142059 | AY26: 0.021850538 | AZ26: 0.06260458 | BA26: 0.02754049 | BE26: 0.047537382 | BH26: 0.010810951
A27: 37622 | B27: 0.016397838 | E27: 0.01561558 | H27: 0.060222895 | J27: 0.037088992 | K27: 0.16740587 | N27: 0.028133457 | Q27: 0.032864411 | T27: 0.017756507 | V27: 0.048958203 | AB27: 0.048473837 | AJ27: 0.017050007 | AL27: 0.022234945 | AM27: 0.014318196 | AO27: 0.060627486 | AT27: 0.018292608 | AU27: 0.025515784 | AV27: 0.013988594 | AY27: 0.016605419 | AZ27: 0.063862722 | BA27: 0.031324459 | BE27: 0.034184623 | BH27: 0.015072471
A28: 37653 | B28: 0.016397838 | E28: 0.01561558 | H28: 0.060222895 | J28: 0.037088992 | K28: 0.16740587 | N28: 0.028133457 | Q28: 0.032864411 | T28: 0.017756507 | V28: 0.048958203 | AB28: 0.048473837 | AJ28: 0.017050007 | AL28: 0.022234945 | AM28: 0.014318196 | AO28: 0.060627486 | AT28: 0.018292608 | AU28: 0.025515784 | AV28: 0.013988594 | AY28: 0.016605419 | AZ28: 0.063862722 | BA28: 0.031324459 | BE28: 0.034184623 | BH28: 0.015072471
A29: 37681 | B29: 0.016397838 | E29: 0.01561558 | H29: 0.060222895 | J29: 0.037088992 | K29: 0.16740587 | N29: 0.028133457 | Q29: 0.032864411 | T29: 0.017756507 | V29: 0.048958203 | AB29: 0.048473837 | AJ29: 0.017050007 | AL29: 0.022234945 | AM29: 0.014318196 | AO29: 0.060627486 | AT29: 0.018292608 | AU29: 0.025515784 | AV29: 0.013988594 | AY29: 0.016605419 | AZ29: 0.063862722 | BA29: 0.031324459 | BE29: 0.034184623 | BH29: 0.015072471
A30: 37712 | B30: 0.016397838 | E30: 0.01561558 | H30: 0.060222895 | J30: 0.037088992 | K30: 0.16740587 | N30: 0.028133457 | Q30: 0.032864411 | T30: 0.017756507 | V30: 0.048958203 | AB30: 0.048473837 | AJ30: 0.017050007 | AL30: 0.022234945 | AM30: 0.014318196 | AO30: 0.060627486 | AT30: 0.018292608 | AU30: 0.025515784 | AV30: 0.013988594 | AY30: 0.016605419 | AZ30: 0.063862722 | BA30: 0.031324459 | BE30: 0.034184623 | BH30: 0.015072471
A31: 37742 | B31: 0.016397838 | E31: 0.01561558 | H31: 0.060222895 | J31: 0.037088992 | K31: 0.16740587 | N31: 0.028133457 | Q31: 0.032864411 | T31: 0.017756507 | V31: 0.048958203 | AB31: 0.048473837 | AJ31: 0.017050007 | AL31: 0.022234945 | AM31: 0.014318196 | AO31: 0.060627486 | AT31: 0.018292608 | AU31: 0.025515784 | AV31: 0.013988594 | AY31: 0.016605419 | AZ31: 0.063862722 | BA31: 0.031324459 | BE31: 0.034184623 | BH31: 0.015072471
A32: 37773 | B32: 0.016397838 | E32: 0.01561558 | H32: 0.060222895 | J32: 0.037088992 | K32: 0.16740587 | N32: 0.028133457 | Q32: 0.032864411 | T32: 0.017756507 | V32: 0.048958203 | AB32: 0.048473837 | AJ32: 0.017050007 | AL32: 0.022234945 | AM32: 0.014318196 | AO32: 0.060627486 | AT32: 0.018292608 | AU32: 0.025515784 | AV32: 0.013988594 | AY32: 0.016605419 | AZ32: 0.063862722 | BA32: 0.031324459 | BE32: 0.034184623 | BH32: 0.015072471
A33: 37803 | B33: 0.016397838 | E33: 0.01561558 | H33: 0.060222895 | J33: 0.037088992 | K33: 0.16740587 | N33: 0.028133457 | Q33: 0.032864411 | T33: 0.017756507 | V33: 0.048958203 | AB33: 0.048473837 | AJ33: 0.017050007 | AL33: 0.022234945 | AM33: 0.014318196 | AO33: 0.060627486 | AT33: 0.018292608 | AU33: 0.025515784 | AV33: 0.013988594 | AY33: 0.016605419 | AZ33: 0.063862722 | BA33: 0.031324459 | BE33: 0.034184623 | BH33: 0.015072471
A34: 37834 | B34: 0.016397838 | E34: 0.01561558 | H34: 0.060222895 | J34: 0.037088992 | K34: 0.16740587 | N34: 0.028133457 | Q34: 0.032864411 | T34: 0.017756507 | V34: 0.048958203 | AB34: 0.048473837 | AJ34: 0.017050007 | AL34: 0.022234945 | AM34: 0.014318196 | AO34: 0.060627486 | AT34: 0.018292608 | AU34: 0.025515784 | AV34: 0.013988594 | AY34: 0.016605419 | AZ34: 0.063862722 | BA34: 0.031324459 | BE34: 0.034184623 | BH34: 0.015072471
A35: 37865 | B35: 0.016397838 | E35: 0.01561558 | H35: 0.060222895 | J35: 0.037088992 | K35: 0.16740587 | N35: 0.028133457 | Q35: 0.032864411 | T35: 0.017756507 | V35: 0.048958203 | AB35: 0.048473837 | AJ35: 0.017050007 | AL35: 0.022234945 | AM35: 0.014318196 | AO35: 0.060627486 | AT35: 0.018292608 | AU35: 0.025515784 | AV35: 0.013988594 | AY35: 0.016605419 | AZ35: 0.063862722 | BA35: 0.031324459 | BE35: 0.034184623 | BH35: 0.015072471
A36: 37895 | B36: 0.016397838 | E36: 0.01561558 | H36: 0.060222895 | J36: 0.037088992 | K36: 0.16740587 | N36: 0.028133457 | Q36: 0.032864411 | T36: 0.017756507 | V36: 0.048958203 | AB36: 0.048473837 | AJ36: 0.017050007 | AL36: 0.022234945 | AM36: 0.014318196 | AO36: 0.060627486 | AT36: 0.018292608 | AU36: 0.025515784 | AV36: 0.013988594 | AY36: 0.016605419 | AZ36: 0.063862722 | BA36: 0.031324459 | BE36: 0.034184623 | BH36: 0.015072471
A37: 37926 | B37: 0.016397838 | E37: 0.01561558 | H37: 0.060222895 | J37: 0.037088992 | K37: 0.16740587 | N37: 0.028133457 | Q37: 0.032864411 | T37: 0.017756507 | V37: 0.048958203 | AB37: 0.048473837 | AJ37: 0.017050007 | AL37: 0.022234945 | AM37: 0.014318196 | AO37: 0.060627486 | AT37: 0.018292608 | AU37: 0.025515784 | AV37: 0.013988594 | AY37: 0.016605419 | AZ37: 0.063862722 | BA37: 0.031324459 | BE37: 0.034184623 | BH37: 0.015072471
A38: 37956 | B38: 0.016397838 | E38: 0.01561558 | H38: 0.060222895 | J38: 0.037088992 | K38: 0.16740587 | N38: 0.028133457 | Q38: 0.032864411 | T38: 0.017756507 | V38: 0.048958203 | AB38: 0.048473837 | AJ38: 0.017050007 | AL38: 0.022234945 | AM38: 0.014318196 | AO38: 0.060627486 | AT38: 0.018292608 | AU38: 0.025515784 | AV38: 0.013988594 | AY38: 0.016605419 | AZ38: 0.063862722 | BA38: 0.031324459 | BE38: 0.034184623 | BH38: 0.015072471
A39: 37987 | B39: 0.025097683 | H39: 0.062496532 | J39: 0.032251612 | K39: 0.1462587 | N39: 0.021379281 | Q39: 0.031804824 | T39: 0.014824322 | V39: 0.046154871 | W39: 0.013363519 | AB39: 0.048140963 | AE39: 0.017883498 | AJ39: 0.015485531 | AL39: 0.025902314 | AM39: 0.012591285 | AO39: 0.052492344 | AT39: 0.021424428 | AU39: 0.018266039 | AV39: 0.017794801 | AY39: 0.025354325 | AZ39: 0.059827202 | BA39: 0.018252979 | BB39: 0.011368222 | BC39: 0.012067375 | BE39: 0.041347158 | BG39: 0.016233063
A40: 38018 | B40: 0.025097683 | H40: 0.062496532 | J40: 0.032251612 | K40: 0.1462587 | N40: 0.021379281 | Q40: 0.031804824 | T40: 0.014824322 | V40: 0.046154871 | W40: 0.013363519 | AB40: 0.048140963 | AE40: 0.017883498 | AJ40: 0.015485531 | AL40: 0.025902314 | AM40: 0.012591285 | AO40: 0.052492344 | AT40: 0.021424428 | AU40: 0.018266039 | AV40: 0.017794801 | AY40: 0.025354325 | AZ40: 0.059827202 | BA40: 0.018252979 | BB40: 0.011368222 | BC40: 0.012067375 | BE40: 0.041347158 | BG40: 0.016233063
...

Sheet CPI
A1: fecha | B1: Argelia | C1: Angola | D1: Australia | E1: Bangladesh | F1: Bielorrusia | G1: Bélgica | H1: Brasil | I1: Canadá | J1: Chile | K1: China | L1: Colombia | M1: Chipre | N1: Dinamarca | O1: República Dominicana | P1: Ecuador | Q1: Egipto | R1: Francia | S1: Georgia | T1: República Federal de Alemania | U1: Grecia | V1: India | W1: Indonesia | X1: Irán | Y1: Iraq | Z1: Irlanda | AA1: Israel | AB1: Italia | AC1: Japón | AD1: Jordania | AE1: Corea Republicana | AF1: Letonia | AG1: Líbano | AH1: Libia | AI1: Lituania | AJ1: Malasia | AK1: Malta | AL1: México | AM1: Marruecos | AN1: Mozambique | AO1: Países Bajos | AP1: Nigeria | AQ1: Omán | AR1: Paquistán | AS1: Paraguay | AT1: Perú | AU1: Filipinas | AV1: Polonia | AW1: Rumania | AX1: Arabia Saudita | AY1: Sudáfrica | AZ1: España | BA1: Tailandia | BB1: Túnez | BC1: Turquía | BD1: Reino Unido | BE1: Estados Unidos | BF1: Uruguay | BG1: Venezuela | BH1: Vietnam | BI1: República de Yemen | BJ1: Confidencial | BK1: Cuba
B2: Algeria | C2: Angola | D2: Australia | E2: Bangladesh | F2: Belarus, Republic of | G2: Belgium | H2: Brazil | I2: Canada | J2: Chile | K2: China, People's Republic of | L2: Colombia | M2: Cyprus | N2: Denmark | O2: Dominican Republic | P2: Ecuador | Q2: Egypt, Arab Republic of | R2: France | S2: Georgia | T2: Germany | U2: Greece | V2: India | W2: Indonesia | X2: Iran, Islamic Republic of | Y2: Iraq | Z2: Ireland | AA2: Israel | AB2: Italy | AC2: Japan | AD2: Jordan | AE2: Korea, Republic of | AF2: Latvia, Republic of | AG2: Lebanon | AH2: Libya | AI2: Lithuania, Republic of | AJ2: Malaysia | AK2: Malta | AL2: Mexico | AM2: Morocco | AN2: Mozambique, Republic of | AO2: Netherlands, The | AP2: Niger | AQ2: Oman | AR2: Pakistan | AS2: Paraguay | AT2: Peru | AU2: Philippines | AV2: Poland, Republic of | AW2: Romania | AX2: Saudi Arabia | AY2: South Africa | AZ2: Spain | BA2: Thailand | BB2: Tunisia | BC2: Türkiye, Republic of | BD2: United Kingdom | BE2: United States | BF2: Uruguay | BG2: Venezuela, República Bolivariana de | BH2: Vietnam | BI2: Yemen, Republic of
A3: 36892 | G3: 76.14 | H3: 1693.07 | I3: 96.3 | J3: 43.991852 | K3: 64.357 | L3: 43.72165 | M3: 76.278682 | N3: 76.7 | O3: 25.307374 | P3: 49.468445 | R3: 80.13 | T3: 76.45412 | U3: 72.38197 | V3: 45.985098 | W3: 28.55481 | Z3: 63 | AA3: 65.7 | AB3: 76.25511 | AC3: 97.15772 | AE3: 64.604 | AF3: 55.66002 | AI3: 69.1432 | AJ3: 81.505876 | AL3: 48.57548 | AO3: 76.31 | AQ3: 65.678269 | AV3: 89.51325 | AW3: 33.59 | AX3: 62.98494 | AY3: 30.41352 | AZ3: 67.81409 | BC3: 43.30509 | BD3: 73.5 | BE3: 80.300657
A4: 36923 | G4: 76.47 | H4: 1700.86 | I4: 96.8 | J4: 43.856581 | K4: 64.42136 | L4: 44.55224 | M4: 76.113109 | N4: 77.3 | O4: 25.341669 | P4: 50.909274 | R4: 80.35 | T4: 76.89655 | U4: 72.31022 | V4: 45.778426 | W4: 28.79852 | Z4: 63.6 | AA4: 65.7 | AB4: 76.52128 | AC4: 96.863005 | AE4: 64.919 | AF4: 55.54844 | AI4: 69.2547 | AJ4: 81.666955 | AL4: 48.54333 | AO4: 76.98 | AQ4: 65.414501 | AV4: 89.59966 | AW4: 34.34 | AX4: 62.85666 | AY4: 30.50142 | AZ4: 68.03672 | BC4: 44.08434 | BD4: 73.7 | BE4: 80.621677
A5: 36951 | G5: 76.64 | H5: 1707.32 | I5: 97.1 | J5: 44.06537 | K5: 64.03484 | L5: 45.20835 | M5: 76.832991 | N5: 77.7 | O5: 25.234498 | P5: 52.026321 | R5: 80.71 | T5: 76.89655 | U5: 73.72794 | V5: 45.985098 | W5: 29.05746 | Z5: 64.1 | AA5: 65.8 | AB5: 76.58781 | AC5: 96.666528 | AE5: 65.488 | AF5: 55.81809 | AI5: 69.6317 | AJ5: 81.505876 | AL5: 48.85089 | AO5: 77.7 | AQ5: 65.282617 | AV5: 90.03167 | AW5: 35.04 | AX5: 62.85666 | AY5: 30.70652 | AZ5: 68.3234 | BC5: 46.76098 | BD5: 73.9 | BE5: 80.805116
A6: 36982 | G6: 77.3 | H6: 1717.22 | I6: 97.8 | J6: 44.266505 | K6: 64.1629 | L6: 45.72485 | M6: 77.380101 | N6: 78 | O6: 25.390967 | P6: 52.922117 | R6: 81.1 | T6: 77.25051 | U6: 74.42166 | V6: 46.295113 | W6: 29.19455 | Z6: 64.6 | AA6: 66.5 | AB6: 76.92052 | AC6: 96.863005 | AE6: 65.74 | AF6: 56.01336 | AI6: 69.768 | AJ6: 81.586416 | AL6: 49.09731 | AO6: 78.13 | AQ6: 65.282617 | AV6: 90.72289 | AW6: 35.97 | AX6: 62.85666 | AY6: 30.85302 | AZ6: 68.6782 | BC6: 51.59355 | BD6: 74.4 | BE6: 81.126135
A7: 37012 | G7: 77.79 | H7: 1724.26 | I7: 98.6 | J7: 44.458819 | K7: 63.84209 | L7: 45.92029 | M7: 77.646457 | N7: 78.4 | O7: 25.457414 | P7: 53.008458 | R7: 81.6 | T7: 77.51598 | U7: 74.73617 | V7: 46.605123 | W7: 29.52457 | Z7: 65 | AA7: 66.7 | AB7: 77.12014 | AC7: 96.961244 | AE7: 65.677 | AF7: 56.60845 | AI7: 70.1704 | AJ7: 81.666955 | AL7: 49.20997 | AO7: 78.39 | AQ7: 65.216675 | AV7: 91.75973 | AW7: 36.6 | AX7: 62.72838 | AY7: 30.97022 | AZ7: 68.93794 | BC7: 54.20094 | BD7: 74.9 | BE7: 81.493014
A8: 37043 | G8: 77.93 | H8: 1733.23 | I8: 98.7 | J8: 44.483526 | K8: 63.07598 | L8: 45.94123 | M8: 78.229562 | N8: 78.3 | O8: 25.313804 | P8: 53.262087 | R8: 81.65 | T8: 77.60446 | U8: 74.65639 | V8: 47.225149 | W8: 30.01707 | Z8: 65.4 | AA8: 66.9 | AB8: 77.31976 | AC8: 96.666528 | AE8: 65.866 | AF8: 56.8781 | AI8: 70.5567 | AJ8: 81.586416 | AL8: 49.32636 | AO8: 78.09 | AQ8: 65.612327 | AV8: 91.67332 | AW8: 37.18 | AX8: 62.72838 | AY8: 31.11672 | AZ8: 69.17023 | BC8: 55.8992 | BD8: 75 | BE8: 81.630594
A9: 37073 | G9: 77.87 | H9: 1756.28 | I9: 98.4 | J9: 44.397654 | K9: 62.7606 | L9: 45.99009 | M9: 76.696213 | N9: 78.1 | O9: 25.253789 | P9: 53.3916 | R9: 81.48 | T9: 77.69296 | U9: 73.3528 | V9: 47.845155 | W9: 30.65174 | Z9: 65.2 | AA9: 67.2 | AB9: 77.3863 | AC9: 96.371813 | AE9: 65.992 | AF9: 56.63634 | AI9: 69.9924 | AJ9: 81.586416 | AL9: 49.1982 | AO9: 77.98 | AQ9: 65.546385 | AV9: 91.41412 | AW9: 37.67 | AX9: 62.6001 | AY9: 31.08743 | AZ9: 69.34 | BC9: 57.23752 | BD9: 74.5 | BE9: 81.401295
A10: 37104 | G10: 77.86 | H10: 1768.57 | I10: 98.4 | J10: 44.754066 | K10: 62.82336 | L10: 46.10875 | M10: 77.120943 | N10: 78.1 | O10: 25.440266 | P10: 53.623644 | R10: 81.48 | T10: 77.51598 | U10: 73.37089 | V10: 48.15518 | W10: 30.59081 | Z10: 65.4 | AA10: 67.4 | AB10: 77.3863 | AC10: 96.764767 | AE10: 66.245 | AF10: 56.26441 | AI10: 70.426 | AJ10: 81.505876 | AL10: 49.48969 | AO10: 78.27 | AQ10: 65.216675 | AV10: 91.15491 | AW10: 38.51 | AX10: 62.53596 | AY10: 31.02882 | AZ10: 69.50774 | BC10: 58.9197 | BD10: 74.8 | BE10: 81.401295
A11: 37135 | G11: 78.08 | H11: 1773.52 | I11: 98.6 | J11: 45.082238 | K11: 63.38877 | L11: 46.27626 | M11: 78.251158 | N11: 78.4 | O11: 25.671756 | P11: 54.719105 | R11: 81.63 | T11: 77.51598 | U11: 74.77231 | V11: 48.05187 | W11: 30.78375 | Z11: 65.7 | AA11: 67.6 | AB11: 77.3863 | AC11: 96.56829 | AE11: 66.182 | AF11: 56.63634 | AI11: 70.2956 | AJ11: 81.586416 | AL11: 49.95038 | AO11: 79.23 | AQ11: 65.348559 | AV11: 91.41412 | AW11: 39.26 | AX11: 62.53596 | AY11: 31.11672 | AZ11: 69.4986 | BC11: 62.38921 | BD11: 75 | BE11: 81.768174
A12: 37165 | G12: 77.96 | H12: 1788.24 | I12: 98.1 | J12: 45.143403 | K12: 63.57894 | L12: 46.367 | M12: 79.237396 | N12: 78.5 | O12: 25.736058 | P12: 55.361272 | R12: 81.68 | T12: 77.42749 | U12: 75.00918 | V12: 48.361847 | W12: 30.99192 | Z12: 65.9 | AA12: 67.6 | AB12: 77.51938 | AC12: 96.56829 | AE12: 66.182 | AF12: 56.71073 | AI12: 70.5044 | AJ12: 81.505876 | AL12: 50.17614 | AO12: 79.15 | AQ12: 65.348559 | AV12: 91.75973 | AW12: 40.22 | AX12: 62.6001 | AY12: 31.08743 | AZ12: 69.42591 | BC12: 66.17783 | BD12: 74.9 | BE12: 81.493014
A13: 37196 | G13: 78.05 | H13: 1800.94 | I13: 97.2 | J13: 45.139282 | K13: 63.45178 | L13: 46.41586 | M13: 79.09342 | N13: 78.3 | O13: 25.710337 | P13: 56.246275 | R13: 81.46 | T13: 77.25051 | U13: 75.08886 | V13: 48.775229 | W13: 31.52503 | Z13: 65.9 | AA13: 67.2 | AB13: 77.65246 | AC13: 96.077098 | AE13: 65.804 | AF13: 56.84091 | AI13: 70.4774 | AJ13: 82.150191 | AL13: 50.36515 | AO13: 79.05 | AQ13: 65.348559 | AV13: 91.84613 | AW13: 41.32 | AX13: 62.53596 | AY13: 31.23392 | AZ13: 69.37406 | BC13: 68.97446 | BD13: 74.9 | BE13: 81.355435
A14: 37226 | G14: 77.88 | H14: 1812.65 | I14: 97.4 | J14: 44.9999 | K14: 63.51524 | L14: 46.57639 | M14: 79.496554 | N14: 78.5 | O14: 25.772496 | P14: 56.624021 | R14: 81.56 | T14: 77.95842 | U14: 75.79599 | V14: 48.465205 | W14: 32.03276 | Z14: 66.2 | AA14: 67.1 | AB14: 77.719 | AC14: 95.97886 | AE14: 65.93 | AF14: 57.06407 | AI14: 70.7189 | AJ14: 82.230731 | AL14: 50.4349 | AO14: 78.81 | AQ14: 65.468516 | AV14: 92.01894 | AW14: 42.21 | AX14: 62.66424 | AY14: 31.40973 | AZ14: 69.62567 | BC14: 71.19841 | BD14: 75 | BE14: 81.034416 | BH14: 29.486905
A15: 37257 | C15: 2.1417484 | G15: 78.35 | H15: 1822.08 | I15: 97.6 | J15: 44.963434 | K15: 63.70578 | L15: 46.94632 | M15: 78.337544 | N15: 78.6 | O15: 25.918249 | P15: 57.646091 | R15: 81.94 | T15: 78.04691 | U15: 75.59269 | V15: 48.258538 | W15: 32.71313 | Z15: 66.1 | AA15: 67.9 | AB15: 78.0517 | AC15: 95.782383 | AE15: 66.308 | AF15: 57.56618 | AI15: 71.392 | AJ15: 82.39181 | AL15: 50.90047 | AO15: 79.38 | AQ15: 65.216675 | AV15: 92.79655 | AW15: 43.19 | AX15: 62.79252 | AY15: 31.93713 | AZ15: 69.53 | BC15: 74.98579 | BD15: 74.8 | BE15: 81.217855 | BH15: 29.794797
A16: 37288 | C16: 2.2748309 | G16: 78.48 | H16: 1828.64 | I16: 98.2 | J16: 44.967555 | K16: 64.40655 | L16: 47.53961 | M16: 78.164772 | N16: 79.2 | O16: 25.928966 | P16: 58.261277 | R16: 82.04 | T16: 78.31237 | U16: 74.79243 | V16: 48.15518 | W16: 33.08377 | Z16: 66.5 | AA16: 68.5 | AB16: 78.31786 | AC16: 95.291192 | AE16: 66.624 | AF16: 57.38021 | AI16: 71.2302 | AJ16: 82.633428 | AL16: 50.86775 | AO16: 79.81 | AQ16: 65.282617 | AV16: 92.88296 | AW16: 43.69 | AX16: 62.85666 | AY16: 32.3227 | AZ16: 69.59 | BC16: 76.30061 | BD16: 75 | BE16: 81.538874 | BH16: 30.450282
A17: 37316 | C17: 2.4026547 | G17: 78.69 | H17: 1839.61 | I17: 98.9 | J17: 45.205155 | K17: 63.56926 | L17: 47.87464 | M17: 78.647093 | N17: 79.7 | O17: 26.224758 | P17: 58.915316 | R17: 82.4 | T17: 78.48935 | U17: 76.6844 | V17: 48.361847 | W17: 33.18532 | Z17: 67.1 | AA17: 68.7 | AB17: 78.51749 | AC17: 95.487668 | AE17: 67.003 | AF17: 57.60337 | AI17: 70.7634 | AJ17: 83.197204 | AL17: 51.12795 | AO17: 80.52 | AQ17: 65.216675 | AV17: 93.05576 | AW17: 43.84 | AX17: 62.79252 | AY17: 32.64694 | AZ17: 70.165 | BC17: 77.2085 | BD17: 75.2 | BE17: 81.997473 | BH17: 30.20668
A18: 37347 | C18: 2.5021207 | G18: 78.71 | H18: 1854.33 | I18: 99.5 | J18: 45.373357 | K18: 63.37855 | L18: 48.31437 | M18: 79.431764 | N18: 80 | O18: 26.402662 | P18: 59.796541 | R18: 82.71 | T18: 78.40086 | U18: 77.27505 | V18: 48.465205 | W18: 33.11931 | Z18: 67.7 | AA18: 69.8 | AB18: 78.7171 | AC18: 95.782383 | AE18: 67.382 | AF18: 57.64987 | AI18: 70.7315 | AJ18: 83.116664 | AL18: 51.40723 | AO18: 80.9 | AQ18: 65.084791 | AV18: 93.48778 | AW18: 44.74 | AX18: 62.72838 | AY18: 33.2034 | AZ18: 71.118 | BC18: 78.79544 | BD18: 75.6 | BE18: 82.456072 | BH18: 30.20668
A19: 37377 | C19: 2.6767441 | G19: 78.83 | H19: 1858.22 | I19: 99.7 | J19: 45.414531 | K19: 63.18842 | L19: 48.60054 | M19: 79.474957 | N19: 80 | O19: 26.308352 | P19: 60.089024 | R19: 82.81 | T19: 78.48935 | U19: 77.26619 | V19: 48.775229 | W19: 33.38841 | Z19: 68.1 | AA19: 70.5 | AB19: 78.91673 | AC19: 96.077098 | AE19: 67.634 | AF19: 57.75215 | AI19: 70.484 | AJ19: 83.197204 | AL19: 51.51143 | AO19: 80.92 | AQ19: 65.252742 | AV19: 93.31497 | AW19: 45.57 | AX19: 62.72838 | AY19: 33.36551 | AZ19: 71.374 | BC19: 79.25186 | BD19: 75.8 | BE19: 82.456072 | BH19: 30.2973
A20: 37408 | C20: 2.8115711 | G20: 78.61 | H20: 1866.02 | I20: 99.9 | J20: 45.356891 | K20: 62.61972 | L20: 48.80994 | M20: 79.8205 | N20: 80 | O20: 26.33836 | P20: 60.31837 | R20: 82.8 | T20: 78.48935 | U20: 77.12772 | V20: 49.188564 | W20: 33.48996 | Z20: 68.2 | AA20: 71.4 | AB20: 78.98327 | AC20: 95.97886 | AE20: 67.571 | AF20: 57.436 | AI20: 70.242 | AJ20: 83.277743 | AL20: 51.76258 | AO20: 80.65 | AQ20: 65.018849 | AV20: 92.96936 | AW20: 46.11 | AX20: 62.6001 | AY20: 33.65031 | AZ20: 71.377 | BC20: 79.71446 | BD20: 75.8 | BE20: 82.501932 | BH20: 30.327597
A21: 37438 | C21: 3.0167556 | G21: 78.87 | H21: 1888.23 | I21: 100.5 | J21: 45.558034 | K21: 62.18138 | L21: 48.81692 | M21: 79.244595 | N21: 79.8 | O21: 26.443387 | P21: 60.278437 | R21: 82.8 | T21: 78.57784 | U21: 75.80174 | V21: 49.705256 | W21: 33.72351 | Z21: 67.9 | AA21: 71.9 | AB21: 79.11635 | AC21: 95.585907 | AE21: 67.382 | AF21: 57.20354 | AI21: 70.0484 | AJ21: 83.277743 | AL21: 51.91118 | AO21: 80.54 | AQ21: 65.282617 | AV21: 92.53735 | AW21: 46.35 | AX21: 62.79252 | AY21: 34.18486 | AZ21: 70.882 | BC21: 80.86354 | BD21: 75.6 | BE21: 82.593652 | BH21: 30.29727
A22: 37469 | C22: 3.2396571 | G22: 78.84 | H22: 1900.5 | I22: 100.9 | J22: 45.729762 | K22: 62.36793 | L22: 48.86578 | M22: 80.029266 | N22: 79.9 | O22: 26.679164 | P22: 60.541779 | R22: 82.99 | T22: 78.48935 | U22: 75.97141 | V22: 50.015233 | W22: 33.82506 | Z22: 68.3 | AA22: 71.7 | AB22: 79.24943 | AC22: 95.880622 | AE22: 67.824 | AF22: 56.76652 | AI22: 69.6518 | AJ22: 83.197204 | AL22: 52.10856 | AO22: 80.81 | AQ22: 65.282617 | AV22: 92.19174 | AW22: 46.73 | AX22: 62.9208 | AY22: 34.36889 | AZ22: 71.085 | BC22: 82.62983 | BD22: 75.8 | BE22: 82.868811 | BH22: 30.327567
A23: 37500 | C23: 3.4081967 | G23: 79.06 | H23: 1914.18 | I23: 100.9 | J23: 46.115573 | K23: 62.99161 | L23: 49.04027 | M23: 80.92192 | N23: 80.3 | O23: 27.054262 | P23: 60.890924 | R23: 83.14 | T23: 78.48935 | U23: 77.40582 | V23: 50.11859 | W23: 34.02815 | Z23: 68.7 | AA23: 71.9 | AB23: 79.38251 | AC23: 95.880622 | AE23: 68.204 | AF23: 57.20354 | AI23: 69.2545 | AJ23: 83.277743 | AL23: 52.42198 | AO23: 81.69 | AQ23: 65.150733 | AV23: 92.45094 | AW23: 47.01 | AX23: 62.98494 | AY23: 34.67122 | AZ23: 71.351 | BC23: 85.50315 | BD23: 76 | BE23: 83.006391 | BH23: 30.388222
A24: 37530 | C24: 3.5445202 | G24: 78.97 | H24: 1939.26 | I24: 101.2 | J24: 46.517263 | K24: 63.11759 | L24: 49.31947 | M24: 81.231469 | N24: 80.5 | O24: 27.840898 | P24: 61.283779 | R24: 83.27 | T24: 78.40086 | U24: 77.80714 | V24: 50.325258 | W24: 34.1957 | Z24: 69 | AA24: 72.3 | AB24: 79.58213 | AC24: 95.684145 | AE24: 68.013 | AF24: 57.64057 | AI24: 69.7004 | AJ24: 83.197204 | AL24: 52.65303 | AO24: 81.49 | AQ24: 65.018849 | AV24: 92.71015 | AW24: 47.79 | AX24: 62.98494 | AY24: 35.18824 | AZ24: 72.058 | BC24: 88.31339 | BD24: 76.1 | BE24: 83.14397 | BH24: 30.479387
A25: 37561 | C25: 3.7629613 | G25: 78.91 | H25: 1997.83 | I25: 101.5 | J25: 46.476097 | K25: 63.05447 | L25: 49.69638 | M25: 81.353849 | N25: 80.5 | O25: 27.97379 | P25: 61.709552 | R25: 83.27 | T25: 78.1354 | U25: 77.82386 | V25: 50.531925 | W25: 34.80498 | Z25: 69 | AA25: 71.7 | AB25: 79.84829 | AC25: 95.684145 | AE25: 68.077 | AF25: 57.74285 | AI25: 69.7805 | AJ25: 83.438822 | AL25: 53.07888 | AO25: 81.25 | AQ25: 65.348559 | AV25: 92.62375 | AW25: 49.01 | AX25: 63.04908 | AY25: 35.60887 | AZ25: 72.169 | BC25: 90.8849 | BD25: 76.1 | BE25: 83.14397 | BH25: 30.570825
A26: 37591 | C26: 4.0911462 | G26: 78.95 | H26: 2039.78 | I26: 101.1 | J26: 46.270842 | K26: 63.24364 | L26: 49.83598 | M26: 81.83617 | N26: 80.5 | O26: 28.481781 | P26: 61.921629 | R26: 83.41 | T26: 78.84331 | U26: 78.36359 | V26: 50.015233 | W26: 35.21116 | Z26: 69.5 | AA26: 71.6 | AB26: 79.91483 | AC26: 95.684145 | AE26: 68.391 | AF26: 57.85443 | AI26: 70.028 | AJ26: 83.599901 | AL26: 53.30993 | AO26: 80.97 | AQ26: 65.414501 | AV26: 92.71015 | AW26: 49.74 | AX26: 63.11322 | AY26: 35.65268 | AZ26: 72.409 | BC26: 92.37907 | BD26: 76.3 | BE26: 82.960531 | BH26: 30.662537
... A38: 37956 | C38: 7.2238287 | G38: 80.32 | H38: 2229.49 | I38: 103.2 | J38: 46.767217 | K38: 65.27184 | L38: 53.06763 | M38: 83.873435 | N38: 81.6 | O38: 40.630692 | P38: 65.680194 | R38: 85.23 | T38: 79.72819 | U38: 80.77365 | V38: 51.875333 | W38: 37.02884 | Z38: 70.9 | AA38: 70.2 | AB38: 81.91103 | AC38: 95.291192 | AE38: 70.73 | AF38: 59.94656 | AI38: 69.0985 | AJ38: 84.566374 | AL38: 55.42981 | AO38: 82.34 | AQ38: 65.414501 | AV38: 94.179 | AW38: 56.77 | AX38: 63.49805 | AY38: 35.06994 | AZ38: 74.294 | BC38: 104.12 | BD38: 77.3 | BE38: 84.519767 | BH38: 31.585006
A39: 37987 | C39: 7.4457445 | G39: 80.56 | H39: 2246.43 | I39: 103.3 | J39: 46.681353 | K39: 65.98983 | L39: 53.53528 | M39: 83.023975 | N39: 81.6 | O39: 44.381679 | P39: 65.949473 | R39: 85.23 | T39: 79.72819 | U39: 80.2452 | V39: 52.082 | W39: 37.26748 | Z39: 70.5 | AA39: 70.1 | AB39: 82.04411 | AC39: 95.094715 | AE39: 71.172 | AF39: 60.66254 | AI39: 69.085 | AJ39: 84.566374 | AL39: 55.77432 | AN39: 23.258309 | AO39: 82.35 | AQ39: 65.275569 | AV39: 94.52461 | AW39: 57.39 | AX39: 63.69047 | AY39: 35.22329 | AZ39: 73.773 | BC39: 104.81 | BD39: 77 | BE39: 84.932506 | BH39: 31.932441
A40: 38018 | C40: 7.6639234 | G40: 80.86 | H40: 2260.13 | I40: 103.5 | J40: 46.685466 | K40: 65.85785 | L40: 54.17743 | M40: 83.153553 | N40: 82.2 | O40: 49.375851 | P40: 66.401688 | R40: 85.59 | T40: 79.90517 | U40: 79.99671 | V40: 52.082 | W40: 37.23193 | Z40: 71.1 | AA40: 70.2 | AB40: 82.24374 | AC40: 95.094715 | AE40: 71.487 | AF40: 61.09026 | AI40: 68.9236 | AJ40: 84.646913 | AL40: 56.10794 | AN40: 23.365087 | AO40: 82.72 | AQ40: 65.145642 | AV40: 94.61102 | AW40: 57.76 | AX40: 63.75461 | AY40: 35.33283 | AZ40: 73.807 | BC40: 105.35 | BD40: 77.2 | BE40: 85.391105 | BH40: 32.890414
A41: 38047 | C41: 7.829777 | G41: 80.97 | H41: 2270.75 | I41: 103.9 | J41: 46.881908 | K41: 66.05542 | L41: 54.71487 | M41: 83.679067 | N41: 82.5 | O41: 50.533298 | P41: 66.865775 | R41: 85.93 | T41: 80.17063 | U41: 81.97674 | V41: 52.082 | W41: 37.36902 | Z41: 71.4 | AA41: 70.1 | AB41: 82.5099 | AC41: 95.291192 | AE41: 72.181 | AF41: 61.70395 | AI41: 69.2734 | AJ41: 84.566374 | AL41: 56.29807 | AN41: 23.597934 | AO41: 83.44 | AQ41: 65.410044 | AV41: 94.87022 | AW41: 58.04 | AX41: 63.62634 | AY41: 35.49933 | AZ41: 74.322 | BC41: 106.36 | BD41: 77.3 | BE41: 85.941423 | BH41: 33.153537
A42: 38078 | C42: 8.0158543 | G42: 81.41 | H42: 2279.15 | I42: 104.1 | J42: 47.054223 | K42: 66.3857 | L42: 54.95917 | M42: 84.26937 | N42: 82.6 | O42: 50.884819 | P42: 67.302341 | R42: 86.15 | T42: 80.4361 | U42: 82.21053 | V42: 52.082 | W42: 37.73967 | X42: 3.8268156 | Z42: 71.6 | AA42: 70.9 | AB42: 82.70952 | AC42: 95.291192 | AE42: 72.181 | AF42: 62.05729 | AI42: 69.5732 | AJ42: 84.727452 | AL42: 56.38303 | AN42: 23.91453 | AO42: 83.71 | AQ42: 65.426031 | AV42: 95.64785 | AW42: 58.38 | AX42: 63.36978 | AY42: 35.53876 | AZ42: 75.34 | BC42: 106.89 | BD42: 77.6 | BE42: 86.216582 | BH42: 33.319305
A43: 38108 | C43: 8.3758435 | G43: 81.72 | H43: 2290.77 | I43: 105 | J43: 47.300064 | K43: 66.31931 | L43: 55.16856 | M43: 84.780486 | N43: 82.9 | O43: 52.222314 | P43: 66.982336 | R43: 86.47 | T43: 80.61308 | U43: 82.57018 | V43: 52.495335 | W43: 38.07477 | X43: 3.8826816 | Z43: 71.8 | AA43: 71.2 | AB43: 82.90914 | AC43: 95.38943 | AE43: 72.119 | AF43: 62.84765 | AI43: 70.647 | AJ43: 84.969071 | AL43: 56.2416 | AN43: 24.064951 | AO43: 83.85 | AQ43: 65.637744 | AV43: 96.59828 | AW43: 58.55 | AX43: 63.30564 | AY43: 35.54314 | AZ43: 75.784 | BC43: 107.35 | BD43: 77.9 | BE43: 86.721041 | BH43: 33.619179
A44: 38139 | C44: 8.5402668 | G44: 81.68 | H44: 2307.03 | I44: 105.1 | J44: 47.505319 | K44: 65.85508 | L44: 55.50359 | M44: 85.356392 | N44: 82.7 | O44: 53.261873 | P44: 66.776195 | R44: 86.5 | T44: 80.61308 | U44: 82.32673 | V44: 52.908717 | W44: 38.24232 | X44: 3.9385475 | Z44: 72.1 | AA44: 71.2 | AB44: 83.04222 | AC44: 95.585907 | AE44: 72.119 | AF44: 63.22889 | AI44: 70.7213 | AJ44: 85.04961 | AL44: 56.33175 | AN44: 24.047127 | AO44: 83.31 | AQ44: 65.493526 | AV44: 97.4623 | AW44: 58.9 | AX44: 63.2415 | AY44: 35.57381 | AZ44: 75.904 | BC44: 107.21 | BD44: 77.9 | BE44: 86.996201 | BH44: 33.888132
A45: 38169 | C45: 8.6639991 | G45: 81.96 | H45: 2328.02 | I45: 105 | J45: 47.61589 | K45: 65.72337 | L45: 55.48964 | M45: 84.586118 | N45: 82.4 | O45: 53.589817 | P45: 66.364993 | R45: 86.36 | T45: 80.79005 | U45: 80.8301 | V45: 53.425409 | W45: 38.41495 | X45: 3.9944134 | Z45: 71.9 | AA45: 71.1 | AB45: 83.10876 | AC45: 95.291192 | AE45: 72.561 | AF45: 63.33117 | AI45: 70.7185 | AJ45: 85.210689 | AL45: 56.47939 | AN45: 24.050019 | AO45: 83.19 | AQ45: 65.773951 | AV45: 97.3759 | AW45: 59.64 | AX45: 63.62634 | AY45: 35.64392 | AZ45: 75.328 | BC45: 107.72 | BD45: 77.7 | BE45: 86.858621 | BH45: 34.057573
A46: 38200 | C46: 8.8026121 | G46: 82.06 | H46: 2344.08 | I46: 104.8 | J46: 47.796439 | K46: 66.18343 | L46: 55.50359 | M46: 85.018047 | N46: 82.2 | O46: 53.881322 | P46: 66.382801 | R46: 86.55 | T46: 80.87854 | U46: 80.63053 | V46: 53.942053 | W46: 38.44541 | X46: 4.0223464 | Z46: 72.4 | AA46: 71.2 | AB46: 83.30838 | AC46: 95.38943 | AE46: 73.191 | AF46: 63.28468 | AI46: 70.4392 | AJ46: 85.210689 | AL46: 56.82804 | AN46: 23.93183 | AO46: 83.47 | AQ46: 66.021977 | AV46: 96.94389 | AW46: 59.97 | AX46: 63.62634 | AY46: 35.57381 | AZ46: 75.661 | BC46: 108.54 | BD46: 77.9 | BE46: 86.904481 | BH46: 34.261918
A47: 38231 | C47: 8.9391237 | G47: 82.12 | H47: 2351.82 | I47: 105 | J47: 47.821138 | K47: 66.91145 | L47: 55.67111 | M47: 85.85311 | N47: 82.7 | O47: 53.270447 | P47: 66.534978 | R47: 86.63 | T47: 80.70156 | U47: 82.24439 | V47: 54.045411 | W47: 38.44541 | X47: 4.0223464 | Z47: 72.4 | AA47: 71.1 | AB47: 83.30838 | AC47: 95.684145 | AE47: 73.191 | AF47: 63.55433 | AI47: 70.8566 | AJ47: 85.532846 | AL47: 57.29792 | AN47: 23.89353 | AO47: 84.2 | AQ47: 66.121224 | AV47: 97.20309 | AW47: 60.54 | AX47: 63.49805 | AY47: 35.58258 | AZ47: 75.796 | BC47: 109.57 | BD47: 77.9 | BE47: 87.08792 | BH47: 34.364704
A48: 38261 | C48: 9.0788285 | G48: 82.52 | H48: 2362.17 | I48: 105.2 | J48: 47.960529 | K48: 66.91145 | L48: 55.66413 | M48: 86.695372 | N48: 83 | O48: 53.988493 | P48: 66.721692 | R48: 86.85 | T48: 80.79005 | U48: 82.87289 | V48: 54.355435 | W48: 38.64851 | X48: 4.0782123 | Z48: 72.5 | AA48: 71.1 | AB48: 83.30838 | AC48: 96.175337 | AE48: 73.191 | AF48: 63.83328 | AI48: 70.9616 | AJ48: 86.016083 | AL48: 57.69475 | AN48: 24.040184 | AO48: 84.23 | AQ48: 65.864969 | AV48: 97.80791 | AW48: 61.28 | AX48: 63.62634 | AY48: 35.68335 | AZ48: 76.575 | BC48: 112.03 | BD48: 78.1 | BE48: 87.546519 | BH48: 34.364704
A49: 38292 | C49: 9.2502934 | G49: 82.42 | H49: 2378.47 | I49: 105.6 | J49: 48.083445 | K49: 66.71072 | L49: 55.81769 | M49: 87.177693 | N49: 82.8 | O49: 53.09683 | P49: 67.001224 | R49: 86.9 | T49: 80.61308 | U49: 82.95445 | V49: 54.252078 | W49: 39.01915 | X49: 4.1061453 | Z49: 72.6 | AA49: 71 | AB49: 83.37492 | AC49: 95.97886 | AE49: 72.75 | AF49: 64.14013 | AI49: 71.1462 | AJ49: 86.177162 | AL49: 58.1869 | AN49: 24.297629 | AO49: 83.98 | AQ49: 66.427496 | AV49: 98.06712 | AW49: 61.67 | AX49: 63.75461 | AY49: 35.89367 | AZ49: 76.767 | BC49: 113.5 | BD49: 78.3 | BE49: 87.592379 | BH49: 34.433434
A50: 38322 | C50: 9.464749 | G50: 82.15 | H50: 2398.92 | I50: 105.4 | J50: 47.902889 | K50: 66.77743 | L50: 55.9852 | M50: 87.393658 | N50: 82.6 | O50: 52.308051 | P50: 66.958053 | R50: 87 | T50: 81.49796 | U50: 83.27147 | V50: 53.838743 | W50: 39.42533 | X50: 4.1340782 | Z50: 72.7 | AA50: 71.1 | AB50: 83.57454 | AC50: 95.487668 | AE50: 72.877 | AF50: 64.3354 | AI50: 71.101 | AJ50: 86.33824 | AL50: 58.30709 | AN50: 24.656048 | AO50: 83.25 | AQ50: 66.684494 | AV50: 98.15353 | AW50: 62.03 | AX50: 63.75461 | AY50: 35.84109 | AZ50: 76.692 | BC50: 113.86 | BD50: 78.6 | BE50: 87.27136 | BH50: 34.640034
A51: 38353 | B51: 111.8 | C51: 9.6479253 | F51: 7.7882096 | G51: 82.38 | H51: 2412.83 | I51: 105.3 | J51: 47.751153 | K51: 67.17809 | L51: 56.44587 | M51: 85.464374 | N51: 82.4 | O51: 52.719588 | P51: 67.121918 | R51: 86.52 | S51: 69.9027 | T51: 80.87854 | U51: 83.48018 | V51: 54.355435 | W51: 39.96353 | X51: 4.1899441 | Z51: 72.1 | AA51: 70.7 | AB51: 83.57454 | AC51: 95.291192 | AE51: 73.594 | AF51: 64.68873 | AI51: 71.0819 | AJ51: 86.579859 | AK51: 79 | AL51: 58.30916 | AN51: 25.016304 | AO51: 83.58 | AQ51: 66.436971 | AS51: 49.580916 | AV51: 98.23993 | AW51: 62.53 | AX51: 63.69047 | AY51: 35.95063 | AZ51: 76.046 | BB51: 66.680709 | BC51: 114.49 | BD51: 78.3 | BE51: 87.454799 | BF51: 25.675986 | BH51: 35.021074
...

Sheet PPI
B1: Algeria | C1: Angola | D1: Australia | E1: Bangladesh | F1: Belarus, Republic of | G1: Belgium | H1: Brazil | I1: Canada | J1: Chile | K1: China, People's Republic of | L1: Colombia | M1: Cyprus | N1: Denmark | O1: Dominican Republic | P1: Ecuador | Q1: Egypt, Arab Republic of | R1: France | S1: Georgia | T1: Germany | U1: Greece | V1: India | W1: Indonesia | X1: Iran, Islamic Republic of | Y1: Iraq | Z1: Ireland | AA1: Israel | AB1: Italy | AC1: Japan | AD1: Jordan | AE1: Korea, Republic of | AF1: Latvia, Republic of | AG1: Lebanon | AH1: Libya | AI1: Lithuania, Republic of | AJ1: Malaysia | AK1: Malta | AL1: Mexico | AM1: Morocco | AN1: Mozambique, Republic of | AO1: Netherlands, The | AP1: Niger | AQ1: Oman | AR1: Pakistan | AS1: Paraguay | AT1: Peru | AU1: Philippines | AV1: Poland, Republic of | AW1: Romania | AX1: Saudi Arabia | AY1: South Africa | AZ1: Spain | BA1: Thailand | BB1: Tunisia | BC1: Türkiye, Republic of | BD1: United Kingdom | BE1: United States | BF1: Uruguay | BG1: Venezuela, República Bolivariana de | BH1: Vietnam | BI1: Yemen, Republic of
A2: COUNTRY | F2: Belarus, Republic of | G2: Belgium | H2: Brazil | I2: Canada | J2: Chile | K2: China, People's Republic of | L2: Colombia | M2: Cyprus | N2: Denmark | P2: Ecuador | R2: France | S2: Georgia | T2: Germany | U2: Greece | V2: India | X2: Iran, Islamic Republic of | AA2: Israel | AB2: Italy | AC2: Japan | AD2: Jordan | AE2: Korea, Republic of | AF2: Latvia, Republic of | AI2: Lithuania, Republic of | AJ2: Malaysia | AK2: Malta | AL2: Mexico | AM2: Morocco | AO2: Netherlands, The | AS2: Paraguay | AU2: Philippines | AV2: Poland, Republic of | AW2: Romania | AY2: South Africa | AZ2: Spain | BA2: Thailand | BB2: Tunisia | BC2: Türkiye, Republic of | BD2: United Kingdom | BE2: United States | BF2: Uruguay
A3: 2001-M01 | F3: 75.167555 | G3: 75.223485 | H3: 42.64832 | I3: 90.784869 | L3: 67.641437 | M3: 70.214484 | N3: 73.293861 | P3: 75.167555 | R3: 87.301038 | S3: 54.733795 | T3: 86.968239 | U3: 71.453984 | V3: 75.167555 | AA3: 70.235975 | AB3: 84.34907 | AC3: 98.722022 | AE3: 79.427278 | AF3: 58.169717 | AI3: 68.607841 | AJ3: 70.021873 | AK3: 112.6193 | AL3: 59.920573 | AO3: 80.2 | AS3: 42.036914 | AU3: 67.545639 | AV3: 78.808835 | AW3: 32.277346 | AY3: 75.167555 | AZ3: 79.282219 | BA3: 61.203543 | BB3: 66.777741 | BC3: 22.026765 | BD3: 72.377586 | BE3: 75.784915 | BF3: 31.430542
A4: 2001-M02 | F4: 75.167555 | G4: 75.223485 | H4: 42.780036 | I4: 91.184802 | L4: 68.839031 | M4: 70.645248 | N4: 73.917108 | P4: 75.167555 | R4: 87.404844 | S4: 54.788195 | T4: 87.314726 | U4: 72.128078 | V4: 75.167555 | AA4: 70.140285 | AB4: 84.463519 | AC4: 98.722022 | AE4: 79.265759 | AF4: 58.302829 | AI4: 69.032658 | AJ4: 70.287393 | AK4: 112.08908 | AL4: 59.923157 | AO4: 80.5 | AS4: 42.036914 | AU4: 67.484787 | AV4: 78.707668 | AW4: 33.28153 | AY4: 75.167555 | AZ4: 79.526917 | BA4: 61.324619 | BB4: 66.977674 | BC4: 22.607193 | BD4: 72.377586 | BE4: 74.377481 | BF4: 31.487443
A5: 2001-M03 | F5: 75.270665 | G5: 75.223485 | H5: 43.213627 | I5: 91.684719 | L5: 69.494318 | M5: 70.322175 | N5: 74.291056 | P5: 75.270665 | R5: 87.404844 | S5: 55.707495 | T5: 87.661213 | U5: 72.128078 | V5: 75.270665 | AA5: 70.523043 | AB5: 84.463519 | AC5: 98.526727 | AE5: 79.447468 | AF5: 58.302829 | AI5: 69.138862 | AJ5: 70.817287 | AK5: 111.45281 | AL5: 60.409438 | AO5: 80.5 | AS5: 41.604936 | AU5: 67.667343 | AV5: 78.859418 | AW5: 33.85535 | AY5: 75.270665 | AZ5: 79.771615 | BA5: 61.324619 | BB5: 66.777741 | BC5: 24.881358 | BD5: 71.867166 | BE5: 73.5655 | BF5: 31.843914
A6: 2001-M04 | F6: 75.476886 | G6: 75.488357 | H6: 43.813664 | I6: 91.984669 | L6: 70.499845 | M6: 70.429866 | N6: 74.914304 | P6: 75.476886 | R6: 87.612457 | S6: 55.854295 | T6: 88.585178 | U6: 72.689823 | V6: 75.476886 | AA6: 71.145023 | AB6: 84.692418 | AC6: 98.233783 | AE6: 79.396993 | AF6: 58.302829 | AI6: 69.457474 | AJ6: 70.295146 | AK6: 112.08908 | AL6: 60.459839 | AO6: 80.8 | AS6: 41.415945 | AU6: 67.728195 | AV6: 79.011168 | AW6: 34.429169 | AY6: 75.476886 | AZ6: 79.649266 | BA6: 62.293221 | BB6: 67.277574 | BC6: 28.454107 | BD6: 71.96925 | BE6: 73.83616 | BF6: 32.189525
A7: 2001-M05 | F7: 75.683107 | G7: 75.753228 | H7: 43.892737 | I7: 92.484585 | L7: 71.076045 | M7: 70.429866 | N7: 75.288252 | P7: 75.683107 | R7: 87.923875 | S7: 56.093695 | T7: 89.047161 | U7: 73.02687 | V7: 75.683107 | AA7: 71.432091 | AB7: 84.577969 | AC7: 98.038487 | AE7: 79.326329 | AF7: 58.835275 | AI7: 70.307107 | AJ7: 71.243734 | AK7: 112.08908 | AL7: 60.322115 | AO7: 81.2 | AS7: 41.604936 | AU7: 68.093306 | AV7: 79.011168 | AW7: 35.289898 | AY7: 75.683107 | AZ7: 80.016313 | BA7: 62.656446 | BB7: 67.377541 | BC7: 30.247861 | BD7: 71.96925 | BE7: 74.052689 | BF7: 32.181956
A8: 2001-M06 | F8: 75.579997 | G8: 75.620792 | H8: 44.754895 | I8: 91.284785 | L8: 70.906575 | M8: 70.537557 | N8: 76.036148 | P8: 75.579997 | R8: 88.027682 | S8: 56.430895 | T8: 89.047161 | U8: 73.02687 | V8: 75.579997 | AA8: 71.384247 | AB8: 84.577969 | AC8: 97.843191 | AE8: 79.003289 | AF8: 58.569052 | AI8: 67.758209 | AJ8: 69.997733 | AK8: 112.6193 | AL8: 60.271899 | AO8: 80.9 | AS8: 41.820925 | AU8: 68.580122 | AV8: 78.707668 | AW8: 35.863718 | AY8: 75.579997 | AZ8: 80.016313 | BA8: 62.595909 | BB8: 67.577474 | BC8: 31.116863 | BD8: 71.96925 | BE8: 73.348971 | BF8: 32.102211
A9: 2001-M07 | F9: 74.548892 | G9: 74.561307 | H9: 45.616835 | I9: 90.584902 | L9: 70.951767 | M9: 70.537557 | N9: 75.786849 | P9: 74.548892 | R9: 87.923875 | S9: 56.137195 | T9: 88.354187 | U9: 72.914521 | V9: 74.548892 | AA9: 70.523043 | AB9: 84.34907 | AC9: 97.745543 | AE9: 78.952814 | AF9: 58.702163 | AI9: 66.589964 | AJ9: 70.639492 | AK9: 114.20997 | AL9: 60.138975 | AO9: 79.9 | AS9: 42.792877 | AU9: 69.249493 | AV9: 78.960585 | AW9: 36.724447 | AY9: 74.548892 | AZ9: 80.138662 | BA9: 62.595909 | BB9: 67.977341 | BC9: 32.141631 | BD9: 71.356745 | BE9: 72.212198 | BF9: 32.660989
A10: 2001-M08 | F10: 74.13645 | G10: 74.164 | H10: 46.130154 | I10: 90.584902 | L10: 71.16643 | M10: 70.429866 | N10: 75.786849 | P10: 74.13645 | R10: 87.716263 | S10: 55.609495 | T10: 88.0077 | U10: 72.802172 | V10: 74.13645 | AA10: 70.140285 | AB10: 84.234621 | AC10: 97.550248 | AE10: 78.569205 | AF10: 58.835275 | AI10: 67.227188 | AJ10: 71.265625 | AK10: 113.5737 | AL10: 60.374177 | AO10: 79.5 | AS10: 43.899822 | AU10: 69.432049 | AV10: 79.567585 | AW10: 37.441721 | AY10: 74.13645 | AZ10: 79.771615 | BA10: 62.656446 | BB10: 68.177274 | BC10: 33.280353 | BD10: 71.254661 | BE10: 72.212198 | BF10: 32.090228
A11: 2001-M09 | F11: 74.652002 | G11: 74.693742 | H11: 46.350991 | I11: 91.284785 | L11: 71.22292 | M11: 70.429866 | N11: 75.786849 | P11: 74.652002 | R11: 87.612457 | S11: 55.821695 | T11: 88.354187 | U11: 73.139219 | V11: 74.652002 | AA11: 70.379509 | AB11: 84.234621 | AC11: 97.354952 | AE11: 78.357211 | AF11: 58.835275 | AI11: 67.970617 | AJ11: 70.409609 | AK11: 112.08908 | AL11: 60.773134 | AO11: 79.6 | AS11: 44.250804 | AU11: 69.492901 | AV11: 79.972252 | AW11: 38.015541 | AY11: 74.652002 | AZ11: 79.649266 | BA11: 62.656446 | BB11: 68.177274 | BC11: 35.060989 | BD11: 71.152577 | BE11: 72.158066 | BF11: 32.157618
A12: 2001-M10 | F12: 73.620897 | G12: 73.634257 | H12: 47.22276 | I12: 89.885019 | L12: 70.940469 | M12: 70.322175 | N12: 75.412901 | P12: 73.620897 | R12: 87.301038 | S12: 59.868795 | T12: 86.621752 | U12: 72.577474 | V12: 73.620897 | AA12: 70.762266 | AB12: 84.005722 | AC12: 96.671417 | AE12: 77.983697 | AF12: 58.702163 | AI12: 66.271351 | AJ12: 68.95628 | AK12: 113.25557 | AL12: 60.944828 | AO12: 78.7 | AS12: 44.3318 | AU12: 69.492901 | AV12: 79.517002 | AW12: 38.445906 | AY12: 73.620897 | AZ12: 79.526917 | BA12: 62.111608 | BB12: 68.177274 | BC12: 37.420414 | BD12: 71.254661 | BE12: 70.534103 | BF12: 32.513819
A13: 2001-M11 | F13: 72.796013 | G13: 72.839642 | H13: 47.565701 | I13: 89.785035 | L13: 70.850084 | M13: 70.429866 | N13: 75.163602 | P13: 72.796013 | R13: 87.093426 | S13: 59.607695 | T13: 86.044273 | U13: 72.240427 | V13: 72.796013 | AA13: 70.475198 | AB13: 83.776824 | AC13: 96.476121 | AE13: 77.670752 | AF13: 58.835275 | AI13: 64.465882 | AJ13: 68.426554 | AK13: 114.31601 | AL13: 60.954243 | AO13: 78 | AS13: 44.439795 | AU13: 69.249493 | AV13: 79.061752 | AW13: 39.019725 | AY13: 72.796013 | AZ13: 79.282219 | BA13: 61.869457 | BB13: 68.677108 | BC13: 38.986259 | BD13: 71.254661 | BE13: 70.263443 | BF13: 32.295606
A14: 2001-M12 | F14: 72.17735 | G14: 72.177464 | H14: 47.521359 | I14: 88.885185 | L14: 71.053449 | M14: 70.537557 | N14: 75.288252 | P14: 72.17735 | R14: 87.197232 | S14: 59.254095 | T14: 85.813282 | U14: 72.465125 | V14: 72.17735 | AA14: 69.901062 | AB14: 83.662375 | AC14: 96.378473 | AE14: 77.196288 | AF14: 58.702163 | AI14: 64.14727 | AJ14: 68.898152 | AK14: 114.42206 | AL14: 60.759657 | AO14: 77.4 | AS14: 45.006767 | AU14: 68.823529 | AV14: 78.808835 | AW14: 39.593545 | AY14: 72.17735 | AZ14: 79.404568 | BA14: 61.566769 | BB14: 68.877041 | BC14: 40.594734 | BD14: 71.662998 | BE14: 69.343197 | BF14: 32.119109
A15: 2002-M01 | F15: 72.796013 | G15: 72.839642 | H15: 47.458887 | I15: 89.785035 | L15: 71.358497 | M15: 70.645248 | N15: 75.786849 | P15: 72.796013 | R15: 87.301038 | S15: 58.969695 | T15: 86.159769 | U15: 73.02687 | V15: 72.796013 | AA15: 70.044596 | AB15: 83.891273 | AC15: 96.085529 | AD15: 52.439903 | AE15: 77.377998 | AF15: 58.968386 | AI15: 64.572086 | AJ15: 68.439567 | AK15: 113.67975 | AL15: 60.919904 | AO15: 77.1 | AS15: 45.14176 | AU15: 67.545639 | AV15: 78.910002 | AW15: 40.454274 | AY15: 72.796013 | AZ15: 79.282219 | BA15: 61.687844 | BB15: 69.776741 | BC15: 42.281092 | BD15: 71.867166 | BE15: 69.559726 | BF15: 32.334114
A16: 2002-M02 | F16: 72.692903 | G16: 72.707207 | H16: 47.524636 | I16: 90.184969 | L16: 71.57316 | M16: 71.183703 | N16: 76.784045 | P16: 72.692903 | R16: 87.404844 | S16: 59.811095 | T16: 86.275265 | U16: 73.02687 | V16: 72.692903 | AA16: 70.570887 | AB16: 83.891273 | AC16: 96.085529 | AD16: 51.919802 | AE16: 77.771702 | AF16: 58.569052 | AI16: 64.253474 | AJ16: 68.819731 | AK16: 111.55885 | AL16: 60.958674 | AO16: 77.1 | AS16: 45.789728 | AU16: 67.484787 | AV16: 79.061752 | AW16: 41.028093 | AY16: 72.692903 | AZ16: 79.282219 | BA16: 61.990533 | BB16: 69.876708 | BC16: 43.364066 | BD16: 71.560914 | BE16: 69.505594 | BF16: 33.075398
A17: 2002-M03 | F17: 73.311566 | G17: 73.369385 | H17: 47.473085 | I17: 90.784869 | L17: 71.968591 | M17: 71.076012 | N17: 76.784045 | P17: 73.311566 | R17: 87.716263 | S17: 59.633295 | T17: 86.852743 | U17: 73.700964 | V17: 73.311566 | AA17: 71.192868 | AB17: 84.120172 | AC17: 96.085529 | AD17: 51.951645 | AE17: 78.175501 | AF17: 58.569052 | AI17: 65.527923 | AJ17: 69.191423 | AK17: 111.6649 | AL17: 61.916836 | AO17: 77.8 | AS17: 46.140711 | AU17: 67.789047 | AV17: 79.213502 | AW17: 41.745368 | AY17: 73.311566 | AZ17: 79.893964 | BA17: 62.474834 | BB17: 69.676774 | BC17: 44.170763 | BD17: 71.356745 | BE17: 70.263443 | BF17: 34.246692
A18: 2002-M04 | F18: 74.548892 | G18: 74.561307 | H18: 47.831317 | I18: 90.984835 | L18: 72.239745 | M18: 71.076012 | N18: 76.784045 | P18: 74.548892 | R18: 88.027682 | S18: 60.616995 | T18: 86.275265 | U18: 74.15036 | V18: 74.548892 | AA18: 72.628208 | AB18: 84.234621 | AC18: 95.890233 | AD18: 51.627909 | AE18: 78.7812 | AF18: 58.702163 | AI18: 67.120984 | AJ18: 69.244823 | AK18: 111.02863 | AL18: 62.50761 | AO18: 78.9 | AS18: 46.113712 | AU18: 68.154158 | AV18: 79.466418 | AW18: 42.893007 | AY18: 74.548892 | AZ18: 79.893964 | BA18: 63.019672 | BB18: 69.776741 | BC18: 44.970902 | BD18: 71.254661 | BE18: 70.804764 | BF18: 35.206189
A19: 2002-M05 | F19: 74.652002 | G19: 74.693742 | H19: 48.437689 | I19: 90.484919 | L19: 72.736859 | M19: 71.614466 | N19: 76.534746 | P19: 74.652002 | R19: 88.027682 | S19: 60.468795 | T19: 86.159769 | U19: 73.925662 | V19: 74.652002 | AA19: 73.537257 | AB19: 84.234621 | AC19: 95.890233 | AD19: 51.755281 | AE19: 79.114334 | AF19: 58.835275 | AI19: 66.589964 | AJ19: 68.988314 | AK19: 111.24072 | AL19: 63.092846 | AO19: 78.8 | AS19: 47.112662 | AU19: 68.336714 | AV19: 79.567585 | AW19: 43.753736 | AY19: 74.652002 | AZ19: 80.016313 | BA19: 63.140747 | BB19: 69.676774 | BC19: 45.158639 | BD19: 70.948409 | BE19: 70.804764 | BF19: 36.708012
A20: 2002-M06 | F20: 74.342671 | G20: 74.296435 | H20: 49.649123 | I20: 90.184969 | L20: 72.996714 | M20: 71.614466 | N20: 76.784045 | P20: 74.342671 | R20: 87.923875 | S20: 60.492495 | T20: 86.044273 | U20: 73.588615 | V20: 74.342671 | AA20: 73.87217 | AB20: 84.120172 | AC20: 95.792585 | AD20: 52.047174 | AE20: 78.609585 | AF20: 58.569052 | AI20: 65.846535 | AJ20: 69.195656 | AK20: 110.39236 | AL20: 63.578388 | AO20: 78.4 | AS20: 49.299554 | AU20: 70.831643 | AV20: 79.719335 | AW20: 44.1841 | AY20: 74.342671 | AZ20: 79.649266 | BA20: 63.201285 | BB20: 69.276908 | BC20: 45.680041 | BD20: 70.846325 | BE20: 70.858896 | BF20: 36.724057
A21: 2002-M07 | F21: 74.342671 | G21: 74.296435 | H21: 51.047972 | I21: 90.484919 | L21: 73.674597 | M21: 72.04523 | N21: 75.911499 | P21: 74.342671 | R21: 88.131488 | S21: 60.605095 | T21: 85.697786 | U21: 73.700964 | V21: 74.342671 | AA21: 74.207082 | AB21: 84.234621 | AC21: 95.694938 | AD21: 52.179852 | AE21: 78.387496 | AF21: 58.702163 | AI21: 65.315515 | AJ21: 69.866779 | AK21: 109.33192 | AL21: 63.932853 | AO21: 78.8 | AS21: 52.674387 | AU21: 70.283976 | AV21: 80.376918 | AW21: 44.901375 | AY21: 74.342671 | AZ21: 80.138662 | BA21: 62.838059 | BB21: 69.276908 | BC21: 46.899104 | BD21: 70.846325 | BE21: 71.021292 | BF21: 40.526749
A22: 2002-M08 | F22: 74.652002 | G22: 74.693742 | H22: 52.743674 | I22: 91.084819 | L22: 74.567143 | M22: 72.475994 | N22: 76.410097 | P22: 74.652002 | R22: 88.131488 | S22: 60.741395 | T22: 85.351299 | U22: 74.15036 | V22: 74.652002 | AA22: 73.920014 | AB22: 84.463519 | AC22: 95.59729 | AD22: 52.726488 | AE22: 78.488445 | AF22: 58.835275 | AI22: 65.740331 | AJ22: 70.073639 | AK22: 109.54401 | AL22: 64.316856 | AO22: 79.4 | AS22: 53.052368 | AU22: 71.196755 | AV22: 80.680418 | AW22: 45.475194 | AY22: 74.652002 | AZ22: 80.016313 | BA22: 63.019672 | BB22: 69.876708 | BC22: 47.900097 | BD22: 70.948409 | BE22: 71.183688 | BF22: 46.363962
A23: 2002-M09 | F23: 75.992439 | G23: 76.0181 | H23: 54.768118 | I23: 91.784702 | L23: 76.03589 | M23: 72.799067 | N23: 77.157993 | P23: 75.992439 | R23: 88.235294 | S23: 60.225895 | T23: 85.697786 | U23: 74.824455 | V23: 75.992439 | AA23: 74.58984 | AB23: 84.692418 | AC23: 95.401994 | AD23: 52.40806 | AE23: 78.649965 | AF23: 58.968386 | AI23: 66.802372 | AJ23: 69.680608 | AK23: 108.90774 | AL23: 64.857784 | AO23: 80 | AS23: 54.942274 | AU23: 71.622718 | AV23: 80.933335 | AW23: 46.049014 | AY23: 75.992439 | AZ23: 80.261011 | BA23: 63.746124 | BB23: 70.076641 | BC23: 49.390519 | BD23: 71.765082 | BE23: 71.616745 | BF23: 54.736302
A24: 2002-M10 | F24: 76.817323 | G24: 76.812714 | H24: 58.066686 | I24: 92.084652 | L24: 77.278676 | M24: 72.799067 | N24: 77.531941 | P24: 76.817323 | R24: 88.3391 | S24: 60.219895 | T24: 86.044273 | U24: 74.824455 | V24: 76.817323 | AA24: 75.498888 | AB24: 84.806867 | AC24: 95.10905 | AD24: 53.00246 | AE24: 78.750915 | AF24: 58.968386 | AI24: 66.908576 | AJ24: 69.566662 | AK24: 109.11983 | AL24: 64.815322 | AO24: 79.9 | AS24: 56.778183 | AU24: 72.109533 | AV24: 80.933335 | AW24: 46.622833 | AY24: 76.817323 | AZ24: 80.383361 | BA24: 64.230425 | BB24: 70.176608 | BC24: 50.937509 | BD24: 71.96925 | BE24: 72.103934 | BF24: 52.570212
A25: 2002-M11 | F25: 75.786218 | G25: 75.753228 | H25: 62.392986 | I25: 91.784702 | L25: 77.233484 | M25: 73.337521 | N25: 75.537551 | P25: 75.786218 | R25: 88.027682 | S25: 60.569495 | T25: 85.813282 | U25: 74.262709 | V25: 75.786218 | AA25: 75.068286 | AB25: 84.463519 | AC25: 95.206698 | AD25: 52.77956 | AE25: 78.912434 | AF25: 59.234609 | AI25: 64.572086 | AJ25: 70.004634 | AK25: 109.01379 | AL25: 65.260249 | AO25: 78.9 | AS25: 59.073069 | AU25: 72.170385 | AV25: 80.528668 | AW25: 46.909743 | AY25: 75.786218 | AZ25: 80.138662 | BA25: 63.867199 | BB25: 70.276574 | BC25: 51.765521 | BD25: 71.96925 | BE25: 72.049802 | BF25: 52.653646
A26: 2002-M12 | F26: 76.30177 | G26: 76.282971 | H26: 64.350808 | I26: 91.484752 | L26: 77.651512 | M26: 73.445212 | N26: 76.160798 | P26: 76.30177 | R26: 88.235294 | S26: 60.545795 | T26: 86.044273 | U26: 74.487408 | V26: 76.30177 | AA26: 74.733374 | AB26: 84.806867 | AC26: 95.011402 | AD26: 53.241282 | AE26: 78.922529 | AF26: 59.234609 | AI26: 65.421719 | AJ26: 71.816516 | AK26: 108.16543 | AL26: 66.109487 | AO26: 79.3 | AS26: 61.583944 | AU26: 71.98783 | AV26: 80.629835 | AW26: 47.770472 | AY26: 76.30177 | AZ26: 80.138662 | BA26: 64.048812 | BB26: 70.176608 | BC26: 53.114115 | BD26: 71.662998 | BE26: 71.941537 | BF26: 52.865442
