Workbook

Sheet TCNB_NOS
A1: mes | B1: Afghanistan, Islamic Republic of | C1: Albania | D1: Algeria | E1: Angola | F1: Antigua and Barbuda | G1: Armenia, Republic of | H1: Aruba, Kingdom of the Netherlands | I1: Austria | J1: Azerbaijan, Republic of | K1: Bahamas, The | L1: Bahrain, Kingdom of | M1: Bangladesh | N1: Barbados | O1: Belarus, Republic of | P1: Belgium | Q1: Belize | R1: Benin | S1: Bolivia | T1: Bosnia and Herzegovina | U1: Botswana | V1: Brazil | W1: Brunei Darussalam | X1: Bulgaria | Y1: Burkina Faso | Z1: Burundi | AA1: Cabo Verde | AB1: Cambodia | AC1: Cameroon | AD1: Canada | AE1: Central African Republic | AF1: Chad | AG1: Chile | AH1: China, People's Republic of | AI1: Colombia | AJ1: Comoros, Union of the | AK1: Congo, Democratic Republic of the | AL1: Congo, Republic of | AM1: Costa Rica | AN1: Croatia, Republic of | AO1: Curaçao, Kingdom of the Netherlands | AP1: Czech Republic | AQ1: Côte d'Ivoire | AR1: Denmark | AS1: Djibouti | AT1: Dominica | AU1: Dominican Republic | AV1: Ecuador | AW1: Egypt, Arab Republic of | AX1: El Salvador | AY1: Equatorial Guinea, Republic of | AZ1: Estonia, Republic of | BA1: Ethiopia, The Federal Democratic Republic of | BB1: Fiji, Republic of | BC1: Finland | BD1: France | BE1: Gabon | BF1: Gambia, The | BG1: Georgia | BH1: Germany | BI1: Ghana | BJ1: Greece | BK1: Grenada | BL1: Guatemala | BM1: Guinea | BN1: Guinea-Bissau | BO1: Guyana | BP1: Haiti | BQ1: Honduras | BR1: Hong Kong Special Administrative Region, People's Republic of China | BS1: Hungary | BT1: Iceland | BU1: India | BV1: Indonesia | BW1: Iran, Islamic Republic of | BX1: Iraq | BY1: Ireland | BZ1: Israel | CA1: Italy | CB1: Jamaica | CC1: Japan | CD1: Jordan | CE1: Kazakhstan, Republic of | CF1: Kenya | CG1: Korea, Republic of | CH1: Kuwait | CI1: Latvia, Republic of | CJ1: Lebanon | CK1: Lesotho, Kingdom of | CL1: Liberia | CM1: Libya | CN1: Lithuania, Republic of | CO1: Luxembourg | CP1: Macao Special Administrative Region, People's Republic of China | CQ1: Madagascar, Republic of | CR1: Malawi | CS1: Malaysia | CT1: Maldives | CU1: Mali | CV1: Malta | CW1: Mauritania, Islamic Republic of | CX1: Mauritius | CY1: Mexico | CZ1: Moldova, Republic of | DA1: Mongolia | DB1: Montenegro | DC1: Morocco | DD1: Mozambique, Republic of | DE1: Myanmar | DF1: Namibia | DG1: Nepal | DH1: Netherlands, The | DI1: Nicaragua | DJ1: Niger | DK1: Nigeria | DL1: North Macedonia, Republic of | DM1: Norway | DN1: Oman | DO1: Pakistan | DP1: Panama | DQ1: Paraguay | DR1: Peru | DS1: Philippines | DT1: Poland, Republic of | DU1: Portugal | DV1: Qatar | DW1: Romania | DX1: Russian Federation | DY1: Rwanda | DZ1: Saudi Arabia | EA1: Senegal | EB1: Serbia, Republic of | EC1: Seychelles | ED1: Sierra Leone | EE1: Singapore | EF1: Slovak Republic | EG1: Slovenia, Republic of | EH1: South Africa | EI1: South Sudan, Republic of | EJ1: Spain | EK1: Sri Lanka | EL1: St. Kitts and Nevis | EM1: St. Lucia | EN1: St. Vincent and the Grenadines | EO1: Sudan | EP1: Suriname | EQ1: Sweden | ER1: Switzerland | ES1: Syrian Arab Republic | ET1: São Tomé and Príncipe, Democratic Republic of | EU1: Tanzania, United Republic of | EV1: Thailand | EW1: Togo | EX1: Trinidad and Tobago | EY1: Tunisia | EZ1: Türkiye, Republic of | FA1: Uganda | FB1: Ukraine | FC1: United Arab Emirates | FD1: United Kingdom | FE1: United States | FF1: Uruguay | FG1: Uzbekistan, Republic of | FH1: Vietnam | FI1: Zambia | FJ1: Zimbabwe
A2: 36892 | B2: 0.021039979 | C2: 0.0070516439 | D2: 0.013360031 | E2: 0.055804288 | F2: 0.37018519 | G2: 0.0018060098 | H2: 0.55837989 | I2: 0.93781268 | J2: 1.0916339 | K2: 0.9995 | L2: 2.6582447 | M2: 0.018509259 | N2: 0.49975 | O2: 8.3153078 | P2: 0.93781268 | Q2: 0.49975 | R2: 0.0014296862 | S2: 0.15599881 | T2: 0.47942308 | U2: 0.18305526 | V2: 0.51159101 | W2: 0.57558307 | X2: 0.47942249 | Y2: 0.0014296862 | Z2: 0.0012775449 | AA2: 0.0085027648 | AB2: 0.00025569199 | AC2: 0.0014296862 | AD2: 0.66493495 | AE2: 0.0014296862 | AF2: 0.0014296862 | AG2: 0.00175007 | AH2: 0.12074741 | AI2: 0.00044592665 | AJ2: 0.0019062483 | AK2: 0.01999 | AL2: 0.0014296862 | AM2: 0.00313372 | AN2: 0.123412 | AP2: 0.026706747 | AQ2: 0.0014296862 | AR2: 0.12571347 | AS2: 0.0056239837 | AT2: 0.37018519 | AU2: 0.060141677 | AV2: 0.9995 | AW2: 0.27013514 | AX2: 0.9995 | AY2: 0.0014296862 | AZ2: 0.93781268 | BA2: 0.12001537 | BB2: 0.45819103 | BC2: 0.93781268 | BD2: 0.93781268 | BE2: 0.0014296862 | BF2: 0.06753059 | BG2: 0.49524329 | BH2: 0.93781268 | BI2: 1.4311274 | BJ2: 0.93781268 | BK2: 0.37018519 | BL2: 0.12810883 | BM2: 0.00052329843 | BN2: 0.0014296862 | BO2: 0.0053840767 | BP2: 0.042675923 | BQ2: 0.065972291 | BR2: 0.12815746 | BS2: 0.0035413124 | BT2: 0.011785167 | BU2: 0.02147615 | BV2: 0.0001053547 | BW2: 0.00056947158 | BX2: 0.00049914979 | BY2: 0.93781268 | BZ2: 0.24265598 | CA2: 0.93781268 | CB2: 0.021939741 | CC2: 0.0085357853 | CD2: 1.409732 | CE2: 0.0068888276 | CF2: 0.012715379 | CG2: 0.00078526422 | CH2: 3.2698876 | CI2: 0.93781268 | CJ2: 0.00066301824 | CK2: 0.12841976 | CL2: 0.022152374 | CM2: 1.8484823 | CN2: 0.93781268 | CO2: 0.93781268 | CP2: 0.12441496 | CQ2: 0.00076777481 | CR2: 0.012477109 | CS2: 0.26302632 | CT2: 0.084919286 | CU2: 0.0014296862 | CV2: 0.93781268 | CW2: 0.040187367 | CX2: 0.035824758 | CY2: 0.10230192 | CZ2: 0.079164555 | DA2: 0.00091045728 | DB2: 0.93781268 | DC2: 0.094381492 | DD2: 0.057697858 | DE2: 0.15150367 | DF2: 0.12841976 | DG2: 0.013452221 | DH2: 0.93781268 | DI2: 0.076350164 | DJ2: 0.0014296862 | DK2: 0.0090859506 | DL2: 0.015434529 | DM2: 0.11385967 | DN2: 2.5994798 | DO2: 0.01691773 | DP2: 0.9995 | DQ2: 0.00027997199 | DR2: 0.28370707 | DS2: 0.019609959 | DT2: 0.24300997 | DU2: 0.93781268 | DV2: 0.27458791 | DW2: 0.38086347 | DX2: 0.035244295 | DY2: 0.0023123508 | DZ2: 0.26653333 | EA2: 0.0014296862 | EB2: 0.016059372 | EC2: 0.15673023 | ED2: 0.60451557 | EE2: 0.57558307 | EF2: 0.93781268 | EG2: 0.93781268 | EH2: 0.12841976 | EJ2: 0.93781268 | EK2: 0.011946853 | EL2: 0.37018519 | EM2: 0.37018519 | EN2: 0.37018519 | EO2: 0.3882458 | EP2: 0.4587705 | EQ2: 0.10557838 | ER2: 0.61309239 | ES2: 0.089042316 | ET2: 0.116606 | EU2: 0.0012411061 | EV2: 0.023202152 | EW2: 0.0014296862 | EX2: 0.15872638 | EY2: 0.72675053 | EZ2: 1.4871432 | FA2: 0.00054604357 | FB2: 0.18396496 | FC2: 0.27215793 | FD2: 1.4774575 | FE2: 0.9995 | FF2: 0.07957169 | FG2: 0.0030621936 | FH2: 6.8769781e-05 | FI2: 0.24835198 | FJ2: 18.129406
A3: 36923 | B3: 0.021039979 | C3: 0.0069973397 | D3: 0.01319559 | E3: 0.051121607 | F3: 0.37018519 | G3: 0.0018101965 | H3: 0.55837989 | I3: 0.92124415 | J3: 1.0904429 | K3: 0.9995 | L3: 2.6582447 | M3: 0.018509259 | N3: 0.49975 | O3: 8.1326282 | P3: 0.92124415 | Q3: 0.49975 | R3: 0.0014044276 | S3: 0.15542631 | T3: 0.47094905 | U3: 0.18214787 | V3: 0.49948638 | W3: 0.57341686 | X3: 0.47095133 | Y3: 0.0014044276 | Z3: 0.001339184 | AA3: 0.0083556261 | AB3: 0.00025556124 | AC3: 0.0014044276 | AD3: 0.65678154 | AE3: 0.0014044276 | AF3: 0.0014044276 | AG3: 0.001774901 | AH3: 0.12075544 | AI3: 0.00044552514 | AJ3: 0.0018725702 | AK3: 0.01999 | AL3: 0.0014044276 | AM3: 0.0031173975 | AN3: 0.11977294 | AP3: 0.026617134 | AQ3: 0.0014044276 | AR3: 0.12347235 | AS3: 0.0056239837 | AT3: 0.37018519 | AU3: 0.059993998 | AV3: 0.9995 | AW3: 0.26028646 | AX3: 0.9995 | AY3: 0.0014044276 | AZ3: 0.92124415 | BA3: 0.11962181 | BB3: 0.45018467 | BC3: 0.92124415 | BD3: 0.92124415 | BE3: 0.0014044276 | BF3: 0.066570313 | BG3: 0.48458257 | BH3: 0.92124415 | BI3: 1.4208564 | BJ3: 0.92124415 | BK3: 0.37018519 | BL3: 0.12919245 | BM3: 0.00051787565 | BN3: 0.0014044276 | BO3: 0.0053655787 | BP3: 0.042630782 | BQ3: 0.065741009 | BR3: 0.12815746 | BS3: 0.0034689203 | BT3: 0.011657336 | BU3: 0.021485895 | BV3: 0.00010332565 | BW3: 0.00056934532 | BX3: 0.00049914979 | BY3: 0.92124415 | BZ3: 0.24247938 | CA3: 0.92124415 | CB3: 0.021897251 | CC3: 0.0086136044 | CD3: 1.409732 | CE3: 0.0068821869 | CF3: 0.012773114 | CG3: 0.00079804222 | CH3: 3.2632899 | CI3: 0.92124415 | CJ3: 0.00066301824 | CK3: 0.12788607 | CL3: 0.022752106 | CM3: 1.8364074 | CN3: 0.92124415 | CO3: 0.92124415 | CP3: 0.12441496 | CQ3: 0.00075792504 | CR3: 0.012507884 | CS3: 0.26302632 | CT3: 0.084919286 | CU3: 0.0014044276 | CV3: 0.92124415 | CW3: 0.039862008 | CX3: 0.035592828 | CY3: 0.10301256 | CZ3: 0.07913071 | DA3: 0.00090953763 | DB3: 0.92124415 | DC3: 0.093464498 | DD3: 0.055934859 | DE3: 0.15057019 | DF3: 0.12788607 | DG3: 0.013501283 | DH3: 0.92124415 | DI3: 0.075990268 | DJ3: 0.0014044276 | DK3: 0.0090694615 | DL3: 0.015137311 | DM3: 0.11209467 | DN3: 2.5994798 | DO3: 0.016756069 | DP3: 0.9995 | DQ3: 0.00027058855 | DR3: 0.28314448 | DS3: 0.020697867 | DT3: 0.24437055 | DU3: 0.92124415 | DV3: 0.27458791 | DW3: 0.37273914 | DX3: 0.034954641 | DY3: 0.0023016611 | DZ3: 0.26653333 | EA3: 0.0014044276 | EB3: 0.015655323 | EC3: 0.15496364 | ED3: 0.56000672 | EE3: 0.57341686 | EF3: 0.92124415 | EG3: 0.92124415 | EH3: 0.12788607 | EJ3: 0.92124415 | EK3: 0.011491705 | EL3: 0.37018519 | EM3: 0.37018519 | EN3: 0.37018519 | EO3: 0.38229107 | EP3: 0.4587705 | EQ3: 0.10266329 | ER3: 0.59962325 | ES3: 0.089042316 | ET3: 0.11631561 | EU3: 0.001225358 | EV3: 0.023468501 | EW3: 0.0014044276 | EX3: 0.15883484 | EY3: 0.71942705 | EZ3: 1.3151074 | FA3: 0.00057344647 | FB3: 0.18408354 | FC3: 0.27215793 | FD3: 1.4530362 | FE3: 0.9995 | FF3: 0.079404802 | FG3: 0.003015083 | FH3: 6.8661125e-05 | FI3: 0.2774339 | FJ3: 18.128825
A4: 36951 | B4: 0.021039979 | C4: 0.0069251022 | D4: 0.013073289 | E4: 0.050972376 | F4: 0.37018519 | G4: 0.0018306867 | H4: 0.55837989 | I4: 0.90906797 | J4: 1.087122 | K4: 0.9995 | L4: 2.6582447 | M4: 0.018509259 | N4: 0.49975 | O4: 7.8392157 | P4: 0.90906797 | Q4: 0.49975 | R4: 0.0013858652 | S4: 0.1545754 | T4: 0.46460796 | U4: 0.18030125 | V4: 0.47863043 | W4: 0.56443415 | X4: 0.4646028 | Y4: 0.0013858652 | Z4: 0.0013081947 | AA4: 0.0082453391 | AB4: 0.0002556266 | AC4: 0.0013858652 | AD4: 0.64132178 | AE4: 0.0013858652 | AF4: 0.0013858652 | AG4: 0.0017004372 | AH4: 0.12074858 | AI4: 0.00043861189 | AJ4: 0.0018478202 | AK4: 0.01999 | AL4: 0.0013858652 | AM4: 0.0031009556 | AN4: 0.11841737 | AP4: 0.026333816 | AQ4: 0.0013858652 | AR4: 0.12178969 | AS4: 0.0056239837 | AT4: 0.37018519 | AU4: 0.059993998 | AV4: 0.9995 | AW4: 0.26028646 | AX4: 0.9995 | AY4: 0.0013858652 | AZ4: 0.90906797 | BA4: 0.11914696 | BB4: 0.4365868 | BC4: 0.90906797 | BD4: 0.90906797 | BE4: 0.0013858652 | BF4: 0.066409754 | BG4: 0.48425388 | BH4: 0.90906797 | BI4: 1.3990894 | BJ4: 0.90906797 | BK4: 0.37018519 | BL4: 0.12981497 | BM4: 0.00051787565 | BN4: 0.0013858652 | BO4: 0.0053650027 | BP4: 0.042238581 | BQ4: 0.065525086 | BR4: 0.12815746 | BS4: 0.003415576 | BT4: 0.011390931 | BU4: 0.021439067 | BV4: 9.8194286e-05 | BW4: 0.00056893593 | BX4: 0.00049914979 | BY4: 0.90906797 | BZ4: 0.23999904 | CA4: 0.90906797 | CB4: 0.021919677 | CC4: 0.0082518544 | CD4: 1.409732 | CE4: 0.0068731949 | CF4: 0.012854892 | CG4: 0.00077575033 | CH4: 3.2505334 | CI4: 0.90906797 | CJ4: 0.00066301824 | CK4: 0.12686119 | CL4: 0.022275462 | CM4: 1.8170402 | CN4: 0.90906797 | CO4: 0.90906797 | CP4: 0.12441651 | CQ4: 0.00075376847 | CR4: 0.012605959 | CS4: 0.26302632 | CT4: 0.084919286 | CU4: 0.0013858652 | CV4: 0.90906797 | CW4: 0.039599842 | CX4: 0.035351124 | CY4: 0.10392081 | CZ4: 0.078035946 | DA4: 0.00091029144 | DB4: 0.90906797 | DC4: 0.092468383 | DD4: 0.054049991 | DE4: 0.14892571 | DF4: 0.12686119 | DG4: 0.013506757 | DH4: 0.90906797 | DI4: 0.07563375 | DJ4: 0.0013858652 | DK4: 0.0090735781 | DL4: 0.014960022 | DM4: 0.11137533 | DN4: 2.5994798 | DO4: 0.01650577 | DP4: 0.9995 | DQ4: 0.00026636286 | DR4: 0.28394886 | DS4: 0.020622279 | DT4: 0.24600655 | DU4: 0.90906797 | DV4: 0.27458791 | DW4: 0.36613063 | DX4: 0.034853837 | DY4: 0.0023024177 | DZ4: 0.26653333 | EA4: 0.0013858652 | EB4: 0.01547046 | EC4: 0.15504537 | ED4: 0.52386343 | EE4: 0.56443415 | EF4: 0.90906797 | EG4: 0.90906797 | EH4: 0.12686119 | EJ4: 0.90906797 | EK4: 0.011647704 | EL4: 0.37018519 | EM4: 0.37018519 | EN4: 0.37018519 | EO4: 0.38851745 | EP4: 0.4587705 | EQ4: 0.099803887 | ER4: 0.59200862 | ES4: 0.089042316 | ET4: 0.11601453 | EU4: 0.0011970347 | EV4: 0.022796734 | EW4: 0.0013858652 | EX4: 0.15894345 | EY4: 0.7105787 | EZ4: 1.0426272 | FA4: 0.0005699086 | FB4: 0.18436197 | FC4: 0.27215793 | FD4: 1.4442598 | FE4: 0.9995 | FF4: 0.078154323 | FH4: 6.8684717e-05 | FI4: 0.29839473 | FJ4: 18.127147
A5: 36982 | B5: 0.021039979 | C5: 0.0068703602 | D5: 0.012917225 | E5: 0.051455398 | F5: 0.37018519 | G5: 0.0018245377 | H5: 0.55837989 | I5: 0.891554 | J5: 1.08171 | K5: 0.9995 | L5: 2.6582447 | M5: 0.018509259 | N5: 0.49975 | O5: 7.5662377 | P5: 0.891554 | Q5: 0.49975 | R5: 0.0013591653 | S5: 0.15377633 | T5: 0.45572084 | U5: 0.1769653 | V5: 0.45604806 | W5: 0.55175269 | X5: 0.45599708 | Y5: 0.0013591653 | Z5: 0.0012507508 | AA5: 0.008082646 | AB5: 0.00025556124 | AC5: 0.0013591653 | AD5: 0.64173973 | AE5: 0.0013591653 | AF5: 0.0013591653 | AG5: 0.0016696457 | AH5: 0.12075485 | AI5: 0.00043024407 | AJ5: 0.0018122204 | AK5: 0.01999 | AL5: 0.0013591653 | AM5: 0.003085829 | AN5: 0.11698281 | AP5: 0.025811533 | AQ5: 0.0013591653 | AR5: 0.11956857 | AS5: 0.0056239837 | AT5: 0.37018519 | AU5: 0.059993998 | AV5: 0.9995 | AW5: 0.26028646 | AX5: 0.9995 | AY5: 0.0013591653 | AZ5: 0.891554 | BA5: 0.11881553 | BB5: 0.43064409 | BC5: 0.891554 | BD5: 0.891554 | BE5: 0.0013591653 | BF5: 0.065644724 | BG5: 0.48687223 | BH5: 0.891554 | BI5: 1.3863495 | BJ5: 0.891554 | BK5: 0.37018519 | BL5: 0.12900619 | BM5: 0.00051388175 | BN5: 0.0013591653 | BO5: 0.0053532216 | BP5: 0.042721891 | BQ5: 0.065268781 | BR5: 0.12817389 | BS5: 0.0033429212 | BT5: 0.010731157 | BU5: 0.021363228 | BV5: 8.9384725e-05 | BW5: 0.0005706777 | BX5: 0.00049914979 | BY5: 0.891554 | BZ5: 0.23934387 | CA5: 0.891554 | CB5: 0.021925206 | CC5: 0.0080717127 | CD5: 1.409732 | CE5: 0.0068684717 | CF5: 0.012896857 | CG5: 0.00075402663 | CH5: 3.2518553 | CI5: 0.891554 | CJ5: 0.00066301824 | CK5: 0.12366789 | CL5: 0.021531667 | CM5: 1.79965 | CN5: 0.891554 | CO5: 0.891554 | CP5: 0.1244196 | CQ5: 0.00074019272 | CR5: 0.012693176 | CS5: 0.26302632 | CT5: 0.084919286 | CU5: 0.0013591653 | CV5: 0.891554 | CW5: 0.039519987 | CX5: 0.035262449 | CY5: 0.10688925 | CZ5: 0.077625642 | DA5: 0.00091397899 | DB5: 0.891554 | DC5: 0.09053196 | DD5: 0.052315874 | DE5: 0.1474254 | DF5: 0.12366789 | DG5: 0.013473982 | DH5: 0.891554 | DI5: 0.075269222 | DJ5: 0.0013591653 | DK5: 0.0088295053 | DL5: 0.014650313 | DM5: 0.10990497 | DN5: 2.5994798 | DO5: 0.016365897 | DP5: 0.9995 | DQ5: 0.00026390136 | DR5: 0.28083731 | DS5: 0.01991631 | DT5: 0.24878656 | DU5: 0.891554 | DV5: 0.27458791 | DW5: 0.35852644 | DX5: 0.034649038 | DY5: 0.0022898231 | DZ5: 0.26653333 | EA5: 0.0013591653 | EB5: 0.015052552 | EC5: 0.1653843 | ED5: 0.52466916 | EE5: 0.55175269 | EF5: 0.891554 | EG5: 0.891554 | EH5: 0.12366789 | EJ5: 0.891554 | EK5: 0.011373024 | EL5: 0.37018519 | EM5: 0.37018519 | EN5: 0.37018519 | EO5: 0.38844196 | EP5: 0.4587705 | EQ5: 0.098002879 | ER5: 0.5829994 | ES5: 0.089042316 | ET5: 0.11322956 | EU5: 0.0011301192 | EV5: 0.022009116 | EW5: 0.0013591653 | EX5: 0.15933873 | EY5: 0.69958704 | EZ5: 0.82998543 | FA5: 0.00056347318 | FB5: 0.18447086 | FC5: 0.27215793 | FD5: 1.434044 | FE5: 0.9995 | FF5: 0.077465607 | FH5: 6.8661125e-05 | FI5: 0.32195408 | FJ5: 18.122559
A6: 37012 | B6: 0.021039979 | C6: 0.0068211288 | D6: 0.01275888 | E6: 0.051155568 | F6: 0.37018519 | G6: 0.001804901 | H6: 0.55837989 | I6: 0.87372655 | J6: 1.080307 | K6: 0.9995 | L6: 2.6582447 | M6: 0.018279078 | N6: 0.49975 | O6: 7.370944 | P6: 0.87372655 | Q6: 0.49975 | R6: 0.0013319875 | S6: 0.1531003 | T6: 0.4466202 | U6: 0.17836748 | V6: 0.43524044 | W6: 0.5511442 | X6: 0.44742379 | Y6: 0.0013319875 | Z6: 0.0011743212 | AA6: 0.0079388403 | AB6: 0.00025477951 | AC6: 0.0013319875 | AD6: 0.64841354 | AE6: 0.0013319875 | AF6: 0.0013319875 | AG6: 0.0016534873 | AH6: 0.12075267 | AI6: 0.00042587551 | AJ6: 0.0017759834 | AK6: 0.0095719211 | AL6: 0.0013319875 | AM6: 0.0030707549 | AN6: 0.1189615 | AP6: 0.025451999 | AQ6: 0.0013319875 | AR6: 0.11724065 | AS6: 0.0056239837 | AT6: 0.37018519 | AU6: 0.059993998 | AV6: 0.9995 | AW6: 0.26021869 | AX6: 0.9995 | AY6: 0.0013319875 | AZ6: 0.87372655 | BA6: 0.11855481 | BB6: 0.43886453 | BC6: 0.87372655 | BD6: 0.87372655 | BE6: 0.0013319875 | BF6: 0.065495459 | BG6: 0.48404281 | BH6: 0.87372655 | BI6: 1.383325 | BJ6: 0.87372655 | BK6: 0.37018519 | BL6: 0.12865018 | BM6: 0.00051388175 | BN6: 0.0013319875 | BO6: 0.0053532216 | BP6: 0.042778757 | BQ6: 0.065030547 | BR6: 0.12817389 | BS6: 0.0033835477 | BT6: 0.0099472532 | BU6: 0.021303456 | BV6: 8.9002671e-05 | BW6: 0.00056969667 | BX6: 0.00049914979 | BY6: 0.87372655 | BZ6: 0.24142512 | CA6: 0.87372655 | CB6: 0.021875588 | CC6: 0.0081973263 | CD6: 1.409732 | CE6: 0.0068482357 | CF6: 0.012726032 | CG6: 0.00076975802 | CH6: 3.2493287 | CI6: 0.87372655 | CJ6: 0.00066301824 | CK6: 0.12536389 | CL6: 0.020625258 | CM6: 1.7918816 | CN6: 0.87372655 | CO6: 0.87372655 | CP6: 0.12441651 | CQ6: 0.00073497187 | CR6: 0.013013137 | CS6: 0.26302632 | CT6: 0.084919286 | CU6: 0.0013319875 | CV6: 0.87372655 | CW6: 0.039282346 | CX6: 0.034875728 | CY6: 0.10927438 | CZ6: 0.076648185 | DA6: 0.00091459788 | DB6: 0.87372655 | DC6: 0.085679997 | DD6: 0.049773145 | DE6: 0.14683846 | DF6: 0.12536389 | DG6: 0.013376606 | DH6: 0.87372655 | DI6: 0.074902578 | DJ6: 0.0013319875 | DK6: 0.0088396568 | DL6: 0.014400959 | DM6: 0.1093088 | DN6: 2.5994798 | DO6: 0.016157092 | DP6: 0.9995 | DQ6: 0.00026151914 | DR6: 0.27763889 | DS6: 0.019776806 | DT6: 0.2510928 | DU6: 0.87372655 | DV6: 0.27458791 | DW6: 0.35078791 | DX6: 0.034443782 | DY6: 0.0022762308 | DZ6: 0.26653333 | EA6: 0.0013319875 | EB6: 0.014742127 | EC6: 0.17370827 | ED6: 0.52627976 | EE6: 0.5511442 | EF6: 0.87372655 | EG6: 0.87372655 | EH6: 0.12536389 | EJ6: 0.87372655 | EK6: 0.011022085 | EL6: 0.37018519 | EM6: 0.37018519 | EN6: 0.37018519 | EO6: 0.38836649 | EP6: 0.4587705 | EQ6: 0.096910593 | ER6: 0.57003536 | ES6: 0.089042316 | ET6: 0.11256011 | EU6: 0.0011247777 | EV6: 0.021998217 | EW6: 0.0013319875 | EX6: 0.15970025 | EY6: 0.68581035 | EZ6: 0.88243292 | FA6: 0.00056067144 | FB6: 0.18462419 | FC6: 0.27215793 | FD6: 1.4244791 | FE6: 0.9995 | FF6: 0.076520261 | FH6: 6.8440153e-05 | FI6: 0.3007788 | FJ6: 18.127947
A7: 37043 | B7: 0.021039979 | C7: 0.0067279214 | D7: 0.012624484 | E7: 0.050466875 | F7: 0.37018519 | G7: 0.0018005343 | H7: 0.55837989 | I7: 0.85274008 | J7: 1.0765834 | K7: 0.9995 | L7: 2.6582447 | M7: 0.017535088 | N7: 0.49975 | O7: 7.2322721 | P7: 0.85274008 | Q7: 0.49975 | R7: 0.0012999939 | S7: 0.1521008 | T7: 0.43597822 | U7: 0.17661507 | V7: 0.42083768 | W7: 0.55048853 | X7: 0.43598691 | Y7: 0.0012999939 | Z7: 0.0010973026 | AA7: 0.0077342722 | AB7: 0.00025523493 | AC7: 0.0012999939 | AD7: 0.65566985 | AE7: 0.0012999939 | AF7: 0.0012999939 | AG7: 0.0016223806 | AH7: 0.12075573 | AI7: 0.00043349843 | AJ7: 0.0017333252 | AK7: 0.0029010536 | AL7: 0.0012999939 | AM7: 0.0030544266 | AN7: 0.11695352 | AP7: 0.025127586 | AQ7: 0.0012999939 | AR7: 0.11459672 | AS7: 0.0056239837 | AT7: 0.37018519 | AU7: 0.059993998 | AV7: 0.9995 | AW7: 0.25961039 | AX7: 0.9995 | AY7: 0.0012999939 | AZ7: 0.85274008 | BA7: 0.11827703 | BB7: 0.4351617 | BC7: 0.85274008 | BD7: 0.85274008 | BE7: 0.0012999939 | BF7: 0.063800995 | BG7: 0.48524129 | BH7: 0.85274008 | BI7: 1.3834934 | BJ7: 0.85274008 | BK7: 0.37018519 | BL7: 0.12816929 | BM7: 0.00051388175 | BN7: 0.0012999939 | BO7: 0.005352075 | BP7: 0.041959833 | BQ7: 0.064759622 | BR7: 0.12817389 | BS7: 0.0034545329 | BT7: 0.0095783421 | BU7: 0.021263578 | BV7: 8.8349686e-05 | BW7: 0.00056982812 | BX7: 0.00049914979 | BY7: 0.85274008 | BZ7: 0.24009128 | CA7: 0.85274008 | CB7: 0.0218686 | CC7: 0.0081823394 | CD7: 1.409732 | CE7: 0.0068271858 | CF7: 0.012713034 | CG7: 0.00077251262 | CH7: 3.2453722 | CI7: 0.85274008 | CJ7: 0.00066301824 | CK7: 0.12410676 | CL7: 0.018872186 | CM7: 1.52958 | CN7: 0.85274008 | CO7: 0.85274008 | CP7: 0.12441805 | CQ7: 0.00072864087 | CR7: 0.013344335 | CS7: 0.26302632 | CT7: 0.084919286 | CU7: 0.0012999939 | CV7: 0.85274008 | CW7: 0.039148486 | CX7: 0.034432865 | CY7: 0.10988709 | CZ7: 0.077349905 | DA7: 0.000912119 | DB7: 0.85274008 | DC7: 0.084127331 | DD7: 0.046926072 | DE7: 0.14553635 | DF7: 0.12410676 | DG7: 0.013371237 | DH7: 0.85274008 | DI7: 0.074539488 | DJ7: 0.0012999939 | DK7: 0.008925701 | DL7: 0.01399225 | DM7: 0.10748814 | DN7: 2.5994798 | DO7: 0.015757126 | DP7: 0.9995 | DQ7: 0.0002557247 | DR7: 0.28306429 | DS7: 0.01941229 | DT7: 0.25173152 | DU7: 0.85274008 | DV7: 0.27458791 | DW7: 0.34522658 | DX7: 0.034330091 | DY7: 0.0022693273 | DZ7: 0.26653333 | EA7: 0.0012999939 | EB7: 0.014339041 | EC7: 0.17677125 | ED7: 0.51433394 | EE7: 0.55048853 | EF7: 0.85274008 | EG7: 0.85274008 | EH7: 0.12410676 | EJ7: 0.85274008 | EK7: 0.011022082 | EL7: 0.37018519 | EM7: 0.37018519 | EN7: 0.37018519 | EO7: 0.38830614 | EP7: 0.45880048 | EQ7: 0.092688161 | ER7: 0.56023587 | ES7: 0.089042316 | ET7: 0.11138737 | EU7: 0.0011241452 | EV7: 0.022112049 | EW7: 0.0012999939 | EX7: 0.16029188 | EY7: 0.66887506 | EZ7: 0.82390656 | FA7: 0.00056544383 | FB7: 0.18505147 | FC7: 0.27215793 | FD7: 1.4003503 | FE7: 0.9995 | FF7: 0.074788243 | FH7: 6.7675537e-05 | FI7: 0.27729535 | FJ7: 18.129849
A8: 37073 | B8: 0.021039979 | C8: 0.0067616019 | D8: 0.012594808 | E8: 0.048443366 | F8: 0.37018519 | G8: 0.0018039888 | H8: 0.55837989 | I8: 0.8602333 | J8: 1.0728854 | K8: 0.9995 | L8: 2.6582447 | M8: 0.017535088 | N8: 0.49975 | O8: 7.1443888 | P8: 0.8602333 | Q8: 0.49975 | R8: 0.0013114172 | S8: 0.15091576 | T8: 0.43972967 | U8: 0.17460955 | V8: 0.40544004 | W8: 0.54805863 | X8: 0.43972723 | Y8: 0.0013114172 | Z8: 0.0011882683 | AA8: 0.0077958038 | AB8: 0.00025503955 | AC8: 0.0013114172 | AD8: 0.65311145 | AE8: 0.0013114172 | AF8: 0.0013114172 | AG8: 0.0015225604 | AH8: 0.12075792 | AI8: 0.00043375805 | AJ8: 0.0017485563 | AK8: 0.0038039962 | AL8: 0.0013114172 | AM8: 0.0030365172 | AN8: 0.11915265 | AP8: 0.02540994 | AQ8: 0.0013114172 | AR8: 0.1154549 | AS8: 0.0056239837 | AT8: 0.37018519 | AU8: 0.059993998 | AV8: 0.9995 | AW8: 0.25961039 | AX8: 0.9995 | AY8: 0.0013114172 | AZ8: 0.8602333 | BA8: 0.1179699 | BB8: 0.43126776 | BC8: 0.8602333 | BD8: 0.8602333 | BE8: 0.0013114172 | BF8: 0.063585065 | BG8: 0.48345748 | BH8: 0.8602333 | BI8: 1.391929 | BJ8: 0.8602333 | BK8: 0.37018519 | BL8: 0.12815828 | BM8: 0.00051388175 | BN8: 0.0013114172 | BO8: 0.005352075 | BP8: 0.041490417 | BQ8: 0.064520918 | BR8: 0.12817389 | BS8: 0.0034526236 | BT8: 0.0099660983 | BU8: 0.021201982 | BV8: 9.3350145e-05 | BW8: 0.00057033675 | BX8: 0.00049914979 | BY8: 0.8602333 | BZ8: 0.23808957 | CA8: 0.8602333 | CB8: 0.021863338 | CC8: 0.0080185102 | CD8: 1.409732 | CE8: 0.0068136887 | CF8: 0.012648953 | CG8: 0.00076731153 | CH8: 3.2500789 | CI8: 0.8602333 | CJ8: 0.00066301824 | CK8: 0.12263774 | CL8: 0.017637198 | CM8: 1.5307666 | CN8: 0.8602333 | CO8: 0.8602333 | CP8: 0.12441341 | CQ8: 0.00074632549 | CR8: 0.013852911 | CS8: 0.26302632 | CT8: 0.081359381 | CU8: 0.0013114172 | CV8: 0.8602333 | CW8: 0.039082662 | CX8: 0.034062987 | CY8: 0.10916339 | CZ8: 0.077475815 | DA8: 0.00091139541 | DB8: 0.8602333 | DC8: 0.084608027 | DD8: 0.045854661 | DE8: 0.1454474 | DF8: 0.12263774 | DG8: 0.013491078 | DH8: 0.8602333 | DI8: 0.076654651 | DJ8: 0.0013114172 | DK8: 0.0089762012 | DL8: 0.014083376 | DM8: 0.10789588 | DN8: 2.5994798 | DO8: 0.015589426 | DP8: 0.9995 | DQ8: 0.00023923502 | DR8: 0.28532686 | DS8: 0.018779122 | DT8: 0.2387778 | DU8: 0.8602333 | DV8: 0.27458791 | DW8: 0.34038278 | DX8: 0.034209184 | DY8: 0.0022539873 | DZ8: 0.26653333 | EA8: 0.0013114172 | EB8: 0.014429567 | EC8: 0.17723517 | ED8: 0.49158236 | EE8: 0.54805863 | EF8: 0.8602333 | EG8: 0.8602333 | EH8: 0.12263774 | EJ8: 0.8602333 | EK8: 0.011073075 | EL8: 0.37018519 | EM8: 0.37018519 | EN8: 0.37018519 | EO8: 0.38830614 | EP8: 0.45880048 | EQ8: 0.092833478 | ER8: 0.56810108 | ES8: 0.089042316 | ET8: 0.11160864 | EU8: 0.0011246891 | EV8: 0.021933867 | EW8: 0.0013114172 | EX8: 0.16200665 | EY8: 0.67306397 | EZ8: 0.75630659 | FA8: 0.00057917116 | FB8: 0.18608851 | FC8: 0.27215793 | FD8: 1.4130804 | FE8: 0.9995 | FF8: 0.073467798 | FH8: 6.7094046e-05 | FI8: 0.27121266 | FJ8: 18.145008
A9: 37104 | B9: 0.021039979 | C9: 0.0069773124 | D9: 0.012987131 | E9: 0.045982014 | F9: 0.37018519 | G9: 0.0018022648 | H9: 0.55837989 | I9: 0.90003237 | J9: 1.0685268 | K9: 0.9995 | L9: 2.6582447 | M9: 0.017535088 | N9: 0.49975 | O9: 6.9073946 | P9: 0.90003237 | Q9: 0.49975 | R9: 0.0013720905 | S9: 0.14974231 | T9: 0.46005315 | U9: 0.17433241 | V9: 0.39823407 | W9: 0.56731108 | X9: 0.46004787 | Y9: 0.0013720905 | Z9: 0.0011801448 | AA9: 0.0081392508 | AB9: 0.00025464968 | AC9: 0.0013720905 | AD9: 0.64895855 | AE9: 0.0013720905 | AF9: 0.0013720905 | AG9: 0.001483598 | AH9: 0.12075675 | AI9: 0.00043667264 | AJ9: 0.001829454 | AK9: 0.0033776021 | AL9: 0.0013720905 | AM9: 0.0030181785 | AN9: 0.12167515 | AP9: 0.026392923 | AQ9: 0.0013720905 | AR9: 0.12089185 | AS9: 0.0056239837 | AT9: 0.37018519 | AU9: 0.059993998 | AV9: 0.9995 | AW9: 0.24142512 | AX9: 0.9995 | AY9: 0.0013720905 | AZ9: 0.90003237 | BA9: 0.11768792 | BB9: 0.44334496 | BC9: 0.90003237 | BD9: 0.90003237 | BE9: 0.0013720905 | BF9: 0.063981103 | BG9: 0.48413659 | BH9: 0.90003237 | BI9: 1.3983972 | BJ9: 0.90003237 | BK9: 0.37018519 | BL9: 0.12733019 | BM9: 0.00050684584 | BN9: 0.0013720905 | BO9: 0.005352075 | BP9: 0.040693272 | BQ9: 0.064369667 | BR9: 0.12817389 | BS9: 0.0035815387 | BT9: 0.010155456 | BU9: 0.021208955 | BV9: 0.00011320904 | BW9: 0.00057095232 | BX9: 0.00049914979 | BY9: 0.90003237 | BZ9: 0.23610422 | CA9: 0.90003237 | CB9: 0.02187353 | CC9: 0.0082190729 | CD9: 1.409732 | CE9: 0.0067965456 | CF9: 0.012665708 | CG9: 0.00077758501 | CH9: 3.2689465 | CI9: 0.90003237 | CJ9: 0.00066301824 | CK9: 0.12022064 | CL9: 0.01865542 | CM9: 1.5597484 | CN9: 0.90003237 | CO9: 0.90003237 | CP9: 0.12441496 | CQ9: 0.00077590811 | CR9: 0.014745911 | CS9: 0.26302632 | CT9: 0.078085937 | CU9: 0.0013720905 | CV9: 0.90003237 | CW9: 0.039071967 | CX9: 0.033880782 | CY9: 0.10952104 | CZ9: 0.077570217 | DA9: 0.00090993509 | DB9: 0.90003237 | DC9: 0.087491246 | DD9: 0.045805004 | DE9: 0.14817945 | DF9: 0.12022064 | DG9: 0.013322226 | DH9: 0.90003237 | DI9: 0.07627442 | DJ9: 0.0013720905 | DK9: 0.0089883094 | DL9: 0.014742084 | DM9: 0.11171455 | DN9: 2.5994798 | DO9: 0.015585712 | DP9: 0.9995 | DQ9: 0.00023339716 | DR9: 0.28630765 | DS9: 0.019225591 | DT9: 0.23540357 | DU9: 0.90003237 | DV9: 0.27458791 | DW9: 0.33530142 | DX9: 0.034060085 | DY9: 0.0022618024 | DZ9: 0.26653333 | EA9: 0.0013720905 | EB9: 0.015064281 | EC9: 0.18114432 | ED9: 0.48533082 | EE9: 0.56731108 | EF9: 0.90003237 | EG9: 0.90003237 | EH9: 0.12022064 | EJ9: 0.90003237 | EK9: 0.01111467 | EL9: 0.37018519 | EM9: 0.37018519 | EN9: 0.37018519 | EO9: 0.38744988 | EP9: 0.45880048 | EQ9: 0.096631669 | ER9: 0.59468915 | ES9: 0.089042316 | ET9: 0.11275948 | EU9: 0.0011219622 | EV9: 0.022277697 | EW9: 0.0013720905 | EX9: 0.16270287 | EY9: 0.69448305 | EZ9: 0.71396274 | FA9: 0.00057094384 | FB9: 0.18693774 | FC9: 0.27215793 | FD9: 1.4361664 | FE9: 0.9995 | FF9: 0.074654736 | FH9: 6.6726751e-05 | FI9: 0.27807918 | FJ9: 18.147115
A10: 37135 | B10: 0.021042105 | C10: 0.0070056283 | D10: 0.013073101 | E10: 0.042720211 | F10: 0.37018519 | G10: 0.0018039237 | H10: 0.55837989 | I10: 0.91063945 | J10: 1.0660196 | K10: 0.9995 | L10: 2.6582447 | M10: 0.017535088 | N10: 0.49975 | O10: 6.7946975 | P10: 0.91063945 | Q10: 0.49975 | R10: 0.0013882609 | S10: 0.1489124 | T10: 0.46550941 | U10: 0.1708956 | V10: 0.37422359 | W10: 0.57165898 | X10: 0.46677252 | Y10: 0.0013882609 | Z10: 0.0011805769 | AA10: 0.0082610133 | AB10: 0.00025445519 | AC10: 0.0013882609 | AD10: 0.63756677 | AE10: 0.0013882609 | AF10: 0.0013882609 | AG10: 0.0014671775 | AH10: 0.12075908 | AI10: 0.00042929607 | AJ10: 0.0018510145 | AK10: 0.0032085647 | AL10: 0.0013882609 | AM10: 0.0029988899 | AN10: 0.12117923 | AP10: 0.026611465 | AQ10: 0.0013882609 | AR10: 0.12233033 | AS10: 0.0056239837 | AT10: 0.37018519 | AU10: 0.059993998 | AV10: 0.9995 | AW10: 0.24142512 | AX10: 0.9995 | AY10: 0.0013882609 | AZ10: 0.91063945 | BA10: 0.11741143 | BB10: 0.43795844 | BC10: 0.91063945 | BD10: 0.91063945 | BE10: 0.0013882609 | BF10: 0.061695246 | BG10: 0.48177962 | BH10: 0.91063945 | BI10: 1.3977253 | BJ10: 0.91063945 | BK10: 0.37018519 | BL10: 0.12567016 | BM10: 0.00050787602 | BN10: 0.0013882609 | BO10: 0.0053318041 | BP10: 0.039981119 | BQ10: 0.064091466 | BR10: 0.12814103 | BS10: 0.0035579524 | BT10: 0.01001503 | BU10: 0.020977627 | BV10: 0.00010739806 | BW10: 0.00056991876 | BX10: 0.00049914979 | BY10: 0.91063945 | BZ10: 0.23123193 | CA10: 0.91063945 | CB10: 0.021827195 | CC10: 0.0084009062 | CD10: 1.409732 | CE10: 0.0067753525 | CF10: 0.012660561 | CG10: 0.00077259025 | CH10: 3.2769203 | CI10: 0.91063945 | CJ10: 0.00066301824 | CK10: 0.11572895 | CL10: 0.020034075 | CM10: 1.5731868 | CN10: 0.91063945 | CO10: 0.91063945 | CP10: 0.12441341 | CQ10: 0.00078436943 | CR10: 0.016024588 | CS10: 0.26302632 | CT10: 0.078085937 | CU10: 0.0013882609 | CV10: 0.91063945 | CW10: 0.039044494 | CX10: 0.033642098 | CY10: 0.10650995 | CZ10: 0.07768658 | DA10: 0.00090904957 | DB10: 0.91063945 | DC10: 0.088312216 | DD10: 0.045297224 | DE10: 0.14962351 | DF10: 0.11572895 | DG10: 0.013309808 | DH10: 0.91063945 | DI10: 0.073454839 | DJ10: 0.0013882609 | DK10: 0.0090772864 | DL10: 0.014953553 | DM10: 0.11383179 | DN10: 2.5994798 | DO10: 0.015569045 | DP10: 0.9995 | DQ10: 0.0002268652 | DR10: 0.28638968 | DS10: 0.019502439 | DT10: 0.23693256 | DU10: 0.91063945 | DV10: 0.27458791 | DW10: 0.33056621 | DX10: 0.033963328 | DY10: 0.0022416295 | DZ10: 0.26653333 | EA10: 0.0013882609 | EB10: 0.015254442 | EC10: 0.18199862 | ED10: 0.4829389 | EE10: 0.57165898 | EF10: 0.91063945 | EG10: 0.91063945 | EH10: 0.11572895 | EJ10: 0.91063945 | EK10: 0.011083958 | EL10: 0.37018519 | EM10: 0.37018519 | EN10: 0.37018519 | EO10: 0.38693818 | EP10: 0.45880048 | EQ10: 0.094103624 | ER10: 0.61076212 | ES10: 0.089042316 | ET10: 0.11271243 | EU10: 0.0011205911 | EV10: 0.022570381 | EW10: 0.0013882609 | EX10: 0.16267904 | EY10: 0.69851143 | EZ10: 0.67891868 | FA10: 0.00057019893 | FB10: 0.18720734 | FC10: 0.27215793 | FD10: 1.4618557 | FE10: 0.9995 | FF10: 0.073583544 | FH10: 7.0891553e-05 | FI10: 0.27173691 | FJ10: 18.140309
A11: 37165 | B11: 0.021042105 | C11: 0.0070689497 | D11: 0.013030968 | E11: 0.039786225 | F11: 0.37018519 | G11: 0.0017823236 | H11: 0.55837989 | I11: 0.90541228 | J11: 1.0614911 | K11: 0.9995 | L11: 2.6582447 | M11: 0.017535088 | N11: 0.49975 | O11: 6.6811497 | P11: 0.90541228 | Q11: 0.49975 | R11: 0.0013802921 | S11: 0.14797542 | T11: 0.46287418 | U11: 0.16317835 | V11: 0.36486455 | W11: 0.55254269 | X11: 0.46288149 | Y11: 0.0013802921 | Z11: 0.0011730257 | AA11: 0.0082134933 | AB11: 0.0002536802 | AC11: 0.0013802921 | AD11: 0.63614719 | AE11: 0.0013802921 | AF11: 0.0013802921 | AG11: 0.0014115238 | AH11: 0.12075908 | AI11: 0.0004306983 | AJ11: 0.0018403895 | AK11: 0.0031366703 | AL11: 0.0013802921 | AM11: 0.0029786917 | AN11: 0.12114689 | AP11: 0.027006944 | AQ11: 0.0013802921 | AR11: 0.12177337 | AS11: 0.0056239837 | AT11: 0.37018519 | AU11: 0.059993998 | AV11: 0.9995 | AW11: 0.24142512 | AX11: 0.9995 | AY11: 0.0013802921 | AZ11: 0.90541228 | BA11: 0.11713211 | BB11: 0.43447763 | BC11: 0.90541228 | BD11: 0.90541228 | BE11: 0.0013802921 | BF11: 0.061514885 | BG11: 0.4803441 | BH11: 0.90541228 | BI11: 1.3944236 | BJ11: 0.90541228 | BK11: 0.37018519 | BL11: 0.12330312 | BM11: 0.00050787602 | BN11: 0.0013802921 | BO11: 0.0052744063 | BP11: 0.038895742 | BQ11: 0.063681079 | BR11: 0.12814103 | BS11: 0.0035503694 | BT11: 0.0097731495 | BU11: 0.020814036 | BV11: 9.8808759e-05 | BW11: 0.00056948763 | BX11: 0.00049914979 | BY11: 0.90541228 | BZ11: 0.23164457 | CA11: 0.90541228 | CB11: 0.021526474 | CC11: 0.0082411675 | CD11: 1.409732 | CE11: 0.0067565741 | CF11: 0.012657263 | CG11: 0.00076731153 | CH11: 3.2738612 | CI11: 0.90541228 | CJ11: 0.00066301824 | CK11: 0.10776164 | CL11: 0.019923588 | CM11: 1.5644957 | CN11: 0.90541228 | CO11: 0.90541228 | CP11: 0.12441186 | CQ11: 0.00078244137 | CR11: 0.016061824 | CS11: 0.26302632 | CT11: 0.078085937 | CU11: 0.0013802921 | CV11: 0.90541228 | CW11: 0.039119374 | CX11: 0.033286044 | CY11: 0.1066873 | CZ11: 0.077734311 | DA11: 0.0009089917 | DB11: 0.90541228 | DC11: 0.087991901 | DD11: 0.044618604 | DE11: 0.14869087 | DF11: 0.10776164 | DG11: 0.013107337 | DH11: 0.90541228 | DI11: 0.073094925 | DJ11: 0.0013802921 | DK11: 0.0090772864 | DL11: 0.0148663 | DM11: 0.11321122 | DN11: 2.5994798 | DO11: 0.015949126 | DP11: 0.9995 | DQ11: 0.00021944365 | DR11: 0.28887283 | DS11: 0.019320356 | DT11: 0.24182232 | DU11: 0.90541228 | DV11: 0.27458791 | DW11: 0.32466056 | DX11: 0.033841893 | DY11: 0.0022081366 | DZ11: 0.26653333 | EA11: 0.0013802921 | EB11: 0.015141186 | EC11: 0.17975649 | ED11: 0.4728138 | EE11: 0.55254269 | EF11: 0.90541228 | EG11: 0.90541228 | EH11: 0.10776164 | EJ11: 0.90541228 | EK11: 0.011001696 | EL11: 0.37018519 | EM11: 0.37018519 | EN11: 0.37018519 | EO11: 0.38540081 | EP11: 0.45977 | EQ11: 0.09466513 | ER11: 0.61183139 | ES11: 0.089042316 | ET11: 0.11174815 | EU11: 0.0011139221 | EV11: 0.022373844 | EW11: 0.0013802921 | EX11: 0.16218804 | EY11: 0.69414543 | EZ11: 0.62372579 | FA11: 0.00057518989 | FB11: 0.18821912 | FC11: 0.27215793 | FD11: 1.450611 | FE11: 0.9995 | FF11: 0.071583576 | FH11: 6.6535748e-05 | FI11: 0.26699684 | FJ11: 18.140309
A12: 37196 | B12: 0.021042105 | C12: 0.0071309323 | D12: 0.012864505 | E12: 0.036393481 | F12: 0.37018519 | G12: 0.0017700877 | H12: 0.55837989 | I12: 0.88786494 | J12: 1.0545474 | K12: 0.9995 | L12: 2.6582447 | M12: 0.017535088 | N12: 0.49975 | O12: 6.5284128 | P12: 0.88786494 | Q12: 0.49975 | R12: 0.0013535414 | S12: 0.14699178 | T12: 0.45391148 | U12: 0.1585778 | V12: 0.39315335 | W12: 0.54635997 | X12: 0.45390554 | Y12: 0.0013535414 | Z12: 0.0011610078 | AA12: 0.008048152 | AB12: 0.00025634778 | AC12: 0.0013535414 | AD12: 0.62765954 | AE12: 0.0013535414 | AF12: 0.0013535414 | AG12: 0.0014498114 | AH12: 0.12075806 | AI12: 0.00043259597 | AJ12: 0.0018047218 | AK12: 0.0031083813 | AL12: 0.0013535414 | AM12: 0.0029561385 | AN12: 0.11984263 | AP12: 0.026671114 | AQ12: 0.0013535414 | AR12: 0.11925158 | AS12: 0.0056239837 | AT12: 0.37018519 | AU12: 0.059639784 | AV12: 0.9995 | AW12: 0.24142512 | AX12: 0.9995 | AY12: 0.0013535414 | AZ12: 0.88786494 | BA12: 0.1168268 | BB12: 0.43762165 | BC12: 0.88786494 | BD12: 0.88786494 | BE12: 0.0013535414 | BF12: 0.059659888 | BG12: 0.46980024 | BH12: 0.88786494 | BI12: 1.3864802 | BJ12: 0.88786494 | BK12: 0.37018519 | BL12: 0.12365351 | BM12: 0.00050624256 | BN12: 0.0013535414 | BO12: 0.0052744063 | BP12: 0.037687258 | BQ12: 0.063239481 | BR12: 0.12814103 | BS12: 0.0035299311 | BT12: 0.0093150047 | BU12: 0.020824058 | BV12: 9.450643e-05 | BW12: 0.00056990418 | BX12: 0.00049914979 | BY12: 0.88786494 | BZ12: 0.2357923 | CA12: 0.88786494 | CB12: 0.021147308 | CC12: 0.0081719853 | CD12: 1.4099347 | CE12: 0.0067338139 | CF12: 0.01265842 | CG12: 0.00077842679 | CH12: 3.2587787 | CI12: 0.88786494 | CJ12: 0.00066301824 | CK12: 0.10247257 | CL12: 0.022211111 | CM12: 1.5515983 | CN12: 0.88786494 | CO12: 0.88786494 | CP12: 0.12441651 | CQ12: 0.00076972838 | CR12: 0.015431932 | CS12: 0.26302632 | CT12: 0.078085937 | CU12: 0.0013535414 | CV12: 0.88786494 | CW12: 0.03778828 | CX12: 0.032951346 | CY12: 0.1083786 | CZ12: 0.077634083 | DA12: 0.00090863636 | DB12: 0.88786494 | DC12: 0.086649328 | DD12: 0.043387291 | DE12: 0.14762355 | DF12: 0.10247257 | DG12: 0.013069631 | DH12: 0.88786494 | DI12: 0.072740637 | DJ12: 0.0013535414 | DK12: 0.0089649296 | DL12: 0.014582194 | DM12: 0.11206124 | DN12: 2.5994798 | DO12: 0.016251187 | DP12: 0.9995 | DQ12: 0.00021496935 | DR12: 0.29055233 | DS12: 0.019224888 | DT12: 0.24411987 | DU12: 0.88786494 | DV12: 0.27458791 | DW12: 0.31934438 | DX12: 0.033545221 | DY12: 0.0021847291 | DZ12: 0.26653333 | EA12: 0.0013535414 | EB12: 0.014809821 | EC12: 0.17716291 | ED12: 0.44410577 | EE12: 0.54635997 | EF12: 0.88786494 | EG12: 0.88786494 | EH12: 0.10247257 | EJ12: 0.88786494 | EK12: 0.010799123 | EL12: 0.37018519 | EM12: 0.37018519 | EN12: 0.37018519 | EO12: 0.38182957 | EP12: 0.45880188 | EQ12: 0.094323775 | ER12: 0.60517074 | ES12: 0.089042316 | ET12: 0.11099512 | EU12: 0.0010944909 | EV12: 0.02252572 | EW12: 0.0013535414 | EX12: 0.15989697 | EY12: 0.68514748 | EZ12: 0.65786053 | FA12: 0.00057567755 | FB12: 0.18903788 | FC12: 0.27215793 | FD12: 1.4356713 | FE12: 0.9995 | FF12: 0.071628207 | FH12: 6.6354644e-05 | FI12: 0.26296749 | FJ12: 18.140309
A13: 37226 | B13: 0.021059053 | C13: 0.007293491 | D13: 0.012894678 | E13: 0.032765808 | F13: 0.37018519 | G13: 0.0017704366 | H13: 0.55837989 | I13: 0.89192604 | J13: 1.0492337 | K13: 0.9995 | L13: 2.6582447 | M13: 0.017535088 | N13: 0.49975 | O13: 6.3621897 | P13: 0.89192604 | Q13: 0.49975 | R13: 0.0013597325 | S13: 0.14664456 | T13: 0.45600549 | U13: 0.14358363 | V13: 0.42317626 | W13: 0.54397222 | X13: 0.4560595 | Y13: 0.0013597325 | Z13: 0.0011585316 | AA13: 0.0080931174 | AB13: 0.00025595391 | AC13: 0.0013597325 | AD13: 0.63361015 | AE13: 0.0013597325 | AF13: 0.0013597325 | AG13: 0.0014937083 | AH13: 0.12075821 | AI13: 0.00043326542 | AJ13: 0.0018129766 | AK13: 0.0031226568 | AL13: 0.0013597325 | AM13: 0.0029339243 | AN13: 0.12070182 | AP13: 0.027402375 | AQ13: 0.0013597325 | AR13: 0.1199795 | AS13: 0.0056239837 | AT13: 0.37018519 | AU13: 0.05888591 | AV13: 0.9995 | AW13: 0.22950631 | AX13: 0.9995 | AY13: 0.0013597325 | AZ13: 0.89192604 | BA13: 0.11679813 | BB13: 0.43562487 | BC13: 0.89192604 | BD13: 0.89192604 | BE13: 0.0013597325 | BF13: 0.059903387 | BG13: 0.46727443 | BH13: 0.89192604 | BI13: 1.3731269 | BJ13: 0.89192604 | BK13: 0.37018519 | BL13: 0.12558079 | BM13: 0.00050624256 | BN13: 0.0013597325 | BO13: 0.0052744063 | BP13: 0.038191857 | BQ13: 0.062928522 | BR13: 0.12817389 | BS13: 0.003608173 | BT13: 0.0095417661 | BU13: 0.020858959 | BV13: 9.489855e-05 | BW13: 0.00056959155 | BX13: 0.00049914979 | BY13: 0.89192604 | BZ13: 0.23376289 | CA13: 0.89192604 | CB13: 0.021141537 | CC13: 0.0078479303 | CD13: 1.4099309 | CE13: 0.0066815964 | CF13: 0.012702306 | CG13: 0.00077501047 | CH13: 3.2505122 | CI13: 0.89192604 | CJ13: 0.00066301824 | CK13: 0.086200949 | CL13: 0.021710109 | CM13: 1.5448973 | CN13: 0.89192604 | CO13: 0.89192604 | CP13: 0.12442735 | CQ13: 0.00076515341 | CR13: 0.014848963 | CS13: 0.26302632 | CT13: 0.078085937 | CU13: 0.0013597325 | CV13: 0.89192604 | CW13: 0.037645951 | CX13: 0.032930068 | CY13: 0.10903002 | CZ13: 0.076326842 | DA13: 0.00090757203 | DB13: 0.89192604 | DC13: 0.086860172 | DD13: 0.043169445 | DE13: 0.14706748 | DF13: 0.086200949 | DG13: 0.013069631 | DH13: 0.89192604 | DI13: 0.072387146 | DJ13: 0.0013597325 | DK13: 0.0089320822 | DL13: 0.014612167 | DM13: 0.11161113 | DN13: 2.5994798 | DO13: 0.016421899 | DP13: 0.9995 | DQ13: 0.00021416786 | DR13: 0.29097525 | DS13: 0.019299502 | DT13: 0.24897868 | DU13: 0.89192604 | DV13: 0.27458791 | DW13: 0.3167385 | DX13: 0.033215249 | DY13: 0.002182791 | DZ13: 0.26653333 | EA13: 0.0013597325 | EB13: 0.01486933 | EC13: 0.174909 | ED13: 0.45155956 | EE13: 0.54397222 | EF13: 0.89192604 | EG13: 0.89192604 | EH13: 0.086200949 | EJ13: 0.89192604 | EK13: 0.010732114 | EL13: 0.37018519 | EM13: 0.37018519 | EN13: 0.37018519 | EO13: 0.38233494 | EP13: 0.45880188 | EQ13: 0.094734039 | ER13: 0.60492901 | ES13: 0.089042316 | ET13: 0.11094338 | EU13: 0.0010901813 | EV13: 0.022788626 | EW13: 0.0013597325 | EX13: 0.1590674 | EY13: 0.68499253 | EZ13: 0.68892027 | FA13: 0.00058333898 | FB13: 0.18878794 | FC13: 0.27215793 | FD13: 1.43844 | FE13: 0.9995 | FF13: 0.07103464 | FH13: 6.6328224e-05 | FI13: 0.26162661 | FJ13: 18.140309
A14: 37257 | B14: 0.02962148 | C14: 0.0099873731 | D14: 0.017974228 | E14: 0.042589904 | F14: 0.51851852 | G14: 0.0024819175 | H14: 0.78212291 | I14: 1.2366009 | J14: 1.4601585 | K14: 1.4 | L14: 3.7234043 | M14: 0.024239906 | N14: 0.7 | O14: 8.583691 | P14: 1.2366009 | Q14: 0.7 | R14: 0.0018851859 | S14: 0.20404297 | T14: 0.63212758 | U14: 0.20496603 | V14: 0.58895293 | W14: 0.76136611 | X14: 0.63213979 | Y14: 0.0018851859 | Z14: 0.0016182352 | AA14: 0.011222445 | AB14: 0.00035943517 | AC14: 0.0018851859 | AD14: 0.87484342 | AE14: 0.0018851859 | AF14: 0.0018851859 | AG14: 0.0020980698 | AH14: 0.16915036 | AI14: 0.00061539544 | AJ14: 0.0025135812 | AK14: 0.004276768 | AL14: 0.0018851859 | AM14: 0.0040806809 | AN14: 0.16557858 | AP14: 0.03854095 | AQ14: 0.0018851859 | AR14: 0.16630989 | AS14: 0.0078775159 | AT14: 0.51851852 | AU14: 0.082134376 | AV14: 1.4 | AW14: 0.3113879 | AX14: 1.4 | AY14: 0.0018851859 | AZ14: 1.2366009 | BA14: 0.1635686 | BB14: 0.61043769 | BC14: 1.2366009 | BD14: 1.2366009 | BE14: 0.0018851859 | BF14: 0.080490301 | BG14: 0.63961988 | BH14: 1.2366009 | BI14: 1.914012 | BJ14: 1.2366009 | BK14: 0.51851852 | BL14: 0.17464002 | BM14: 0.0007079109 | BN14: 0.0018851859 | BO14: 0.0073843557 | BP14: 0.052566562 | BQ14: 0.08762322 | BR14: 0.17953321 | BS14: 0.0050739345 | BT14: 0.013667871 | BU14: 0.028964093 | BV14: 0.00013490985 | BW14: 0.00079829312 | BX14: 0.00069915929 | BY14: 1.2366009 | BZ14: 0.30856715 | CA14: 1.2366009 | CB14: 0.029547958 | CC14: 0.010552917 | CD14: 1.9746177 | CE14: 0.009262935 | CF14: 0.017812407 | CG14: 0.0010625379 | CH14: 4.55294 | CI14: 1.2366009 | CJ14: 0.00092868988 | CK14: 0.1208161 | CL14: 0.02686109 | CM14: 1.0663465 | CN14: 1.2366009 | CO14: 1.2366009 | CP14: 0.17428543 | CQ14: 0.0010569787 | CR14: 0.020682768 | CS14: 0.36842105 | CT14: 0.109375 | CU14: 0.0018851859 | CV14: 1.2366009 | CW14: 0.052728711 | CX14: 0.046136862 | CY14: 0.15281507 | CZ14: 0.10692982 | DA14: 0.0012704174 | DB14: 1.2366009 | DC14: 0.12085635 | DD14: 0.060049292 | DE14: 0.20413817 | DF14: 0.1208161 | DG14: 0.018280342 | DH14: 1.2366009 | DI14: 0.10089218 | DJ14: 0.0018851859 | DK14: 0.012334802 | DL14: 0.020302036 | DM14: 0.15610365 | DN14: 3.6410923 | DO14: 0.023057067 | DP14: 1.4 | DQ14: 0.00029270332 | DR14: 0.40462428 | DS14: 0.027232215 | DT14: 0.34441192 | DU14: 1.2366009 | DV14: 0.38461538 | DW14: 0.43679022 | DX14: 0.045951508 | DY14: 0.0030647389 | DZ14: 0.37333333 | EA14: 0.0018851859 | EB14: 0.020663383 | EC14: 0.24365624 | ED14: 0.67270499 | EE14: 0.76136611 | EF14: 1.2366009 | EG14: 1.2366009 | EH14: 0.1208161 | EJ14: 1.2366009 | EK14: 0.014991984 | EL14: 0.51851852 | EM14: 0.51851852 | EN14: 0.51851852 | EO14: 0.53549572 | EP14: 0.64264402 | EQ14: 0.13412428 | ER14: 0.83995296 | ES14: 0.1247216 | ET14: 0.15482102 | EU14: 0.0015140045 | EV14: 0.031831421 | EW14: 0.0018851859 | EX14: 0.22270298 | EY14: 0.95225139 | EZ14: 1.0249772 | FA14: 0.00080518076 | FB14: 0.26352445 | FC14: 0.38121171 | FD14: 2.0051561 | FE14: 1.4 | FF14: 0.097680098 | FH14: 9.2709092e-05 | FI14: 0.36376392 | FJ14: 25.409137
A15: 37288 | B15: 0.041281129 | C15: 0.013781663 | D15: 0.02472156 | E15: 0.0563538 | F15: 0.72261852 | G15: 0.0034515108 | H15: 1.0899832 | I15: 1.6974992 | J15: 2.029405 | K15: 1.95107 | L15: 5.189016 | M15: 0.033697237 | N15: 0.975535 | O15: 11.72518 | P15: 1.6974992 | Q15: 0.975535 | R15: 0.0025878208 | S15: 0.28120694 | T15: 0.86789418 | U15: 0.2873277 | V15: 0.80662725 | W15: 1.0653493 | X15: 0.8679137 | Y15: 0.0025878208 | Z15: 0.0022527596 | AA15: 0.015384561 | AB15: 0.00050078799 | AC15: 0.0025878208 | AD15: 1.2225937 | AE15: 0.0025878208 | AF15: 0.0025878208 | AG15: 0.0028741235 | AH15: 0.23573128 | AI15: 0.00085322517 | AJ15: 0.0034504278 | AK15: 0.0058141967 | AL15: 0.0025878208 | AM15: 0.0056397456 | AN15: 0.22633109 | AP15: 0.053396918 | AQ15: 0.0025878208 | AR15: 0.2284636 | AS15: 0.010978275 | AT15: 0.72261852 | AU15: 0.11378247 | AV15: 1.95107 | AW15: 0.43357111 | AX15: 1.95107 | AY15: 0.0025878208 | AZ15: 1.6974992 | BA15: 0.22791809 | BB15: 0.8437698 | BC15: 1.6974992 | BD15: 1.6974992 | BE15: 0.0025878208 | BF15: 0.11124624 | BG15: 0.88092379 | BH15: 1.6974992 | BI15: 2.6211202 | BJ15: 1.6974992 | BK15: 0.72261852 | BL15: 0.24575703 | BM15: 0.0009863977 | BN15: 0.0025878208 | BO15: 0.010255296 | BP15: 0.072930653 | BQ15: 0.12135029 | BR15: 0.25013718 | BS15: 0.0069703476 | BT15: 0.019258415 | BU15: 0.040070033 | BV15: 0.00019073348 | BW15: 0.0011126385 | BX15: 0.00097436337 | BY15: 1.6974992 | BZ15: 0.41850493 | CA15: 1.6974992 | CB15: 0.041115668 | CC15: 0.01461274 | CD15: 2.7518618 | CE15: 0.012856286 | CF15: 0.024933738 | CG15: 0.001479518 | CH15: 6.3409777 | CI15: 1.6974992 | CJ15: 0.0012942421 | CK15: 0.16997456 | CL15: 0.03579945 | CM15: 1.4764468 | CN15: 1.6974992 | CO15: 1.6974992 | CP15: 0.24286977 | CQ15: 0.0013911035 | CR15: 0.027277354 | CS15: 0.51343947 | CT15: 0.15242734 | CU15: 0.0025878208 | CV15: 1.6974992 | CW15: 0.071793862 | CX15: 0.064212886 | CY15: 0.21425732 | CZ15: 0.1488185 | DA15: 0.0017682345 | DB15: 1.6974992 | DC15: 0.16658726 | DD15: 0.083325824 | DE15: 0.28253037 | DF15: 0.16997456 | DG15: 0.025381423 | DH15: 1.6974992 | DI15: 0.13994491 | DJ15: 0.0025878208 | DK15: 0.017069729 | DL15: 0.027852772 | DM15: 0.21803563 | DN15: 5.0743043 | DO15: 0.032410425 | DP15: 1.95107 | DQ15: 0.00039769869 | DR15: 0.56113604 | DS15: 0.038046126 | DT15: 0.46597167 | DU15: 1.6974992 | DV15: 0.53600824 | DW15: 0.60530202 | DX15: 0.063344989 | DY15: 0.0042441894 | DZ15: 0.52028533 | EA15: 0.0025878208 | EB15: 0.028242936 | EC15: 0.33738609 | ED15: 0.93428626 | EE15: 1.0653493 | EF15: 1.6974992 | EG15: 1.6974992 | EH15: 0.16997456 | EJ15: 1.6974992 | EK15: 0.020858388 | EL15: 0.72261852 | EM15: 0.72261852 | EN15: 0.72261852 | EO15: 0.74550839 | EP15: 0.89560248 | EQ15: 0.18475482 | ER15: 1.1485936 | ES15: 0.1738147 | ET15: 0.21618504 | EU15: 0.0020416797 | EV15: 0.044568279 | EW15: 0.0025878208 | EX15: 0.31026493 | EY15: 1.3134096 | EZ15: 1.4407951 | FA15: 0.0011203787 | FB15: 0.36667356 | FC15: 0.53126481 | FD15: 2.7753485 | FE15: 1.95107 | FF15: 0.13319066 | FH15: 0.000128775 | FI15: 0.49972978 | FJ15: 35.410718
... A31: 37773 | B31: 0.057634623 | C31: 0.023604202 | D31: 0.035421989 | E31: 0.036749665 | F31: 1.0403333 | G31: 0.0047998975 | H31: 1.5692179 | I31: 3.2759666 | J31: 2.8550722 | K31: 2.8089 | L31: 7.4704787 | M31: 0.048512953 | N31: 1.40445 | O31: 13.692133 | P31: 3.2759666 | Q31: 1.40445 | R31: 0.0049941788 | S31: 0.36784966 | T31: 1.6747726 | U31: 0.55282425 | V31: 0.97449873 | W31: 1.6197094 | X31: 1.6747555 | Y31: 0.0049941788 | Z31: 0.002617142 | AA31: 0.029755297 | AB31: 0.00070047382 | AC31: 0.0049941788 | AD31: 2.0771717 | AE31: 0.0049941788 | AF31: 0.0049941788 | AG31: 0.0039607716 | AH31: 0.33935922 | AI31: 0.00099361503 | AJ31: 0.0066589051 | AK31: 0.0066453192 | AL31: 0.0049941788 | AM31: 0.007078227 | AN31: 0.43590481 | AP31: 0.10428052 | AQ31: 0.0049941788 | AR31: 0.44080053 | AS31: 0.01580511 | AT31: 1.0403333 | AU31: 0.096558955 | AV31: 2.8089 | AW31: 0.4691822 | AX31: 2.8089 | AY31: 0.0049941788 | AZ31: 3.2759666 | BA31: 0.32674546 | BB31: 1.5016595 | BC31: 3.2759666 | BD31: 3.2759666 | BE31: 0.0049941788 | BF31: 0.10204311 | BG31: 1.3076816 | BH31: 3.2759666 | BI31: 3.2353305 | BJ31: 3.2759666 | BK31: 1.0403333 | BL31: 0.35466133 | BM31: 0.0014186364 | BN31: 0.0049941788 | BO31: 0.014520031 | BP31: 0.06753722 | BQ31: 0.1623773 | BR31: 0.36020775 | BS31: 0.012556549 | BT31: 0.037937601 | BU31: 0.060125221 | BV31: 0.00034105976 | BW31: 0.00034370093 | BX31: 0.0019252228 | BY31: 3.2759666 | BZ31: 0.64159434 | CA31: 3.2759666 | CB31: 0.047653624 | CC31: 0.023751041 | CD31: 3.9617772 | CE31: 0.018832719 | CF31: 0.03810109 | CG31: 0.0023524732 | CH31: 9.3878779 | CI31: 3.2759666 | CJ31: 0.0018632836 | CK31: 0.35544448 | CL31: 0.039684939 | CM31: 2.0565723 | CN31: 3.2759666 | CO31: 3.2759666 | CP31: 0.34968317 | CQ31: 0.0023435975 | CR31: 0.030807922 | CS31: 0.73918421 | CT31: 0.21944531 | CU31: 0.0049941788 | CV31: 3.2759666 | CW31: 0.10766607 | CX31: 0.1009176 | CY31: 0.26763408 | CZ31: 0.19832803 | DA31: 0.0024777052 | DB31: 3.2759666 | DC31: 0.30106432 | DD31: 0.11813582 | DE31: 0.46268263 | DF31: 0.35544448 | DG31: 0.036626679 | DH31: 3.2759666 | DI31: 0.18643472 | DJ31: 0.0049941788 | DK31: 0.022047708 | DL31: 0.05349002 | DM31: 0.40118317 | DN31: 7.3053316 | DO31: 0.048666121 | DP31: 2.8089 | DQ31: 0.00045121442 | DR31: 0.80738718 | DS31: 0.052601912 | DT31: 0.73984618 | DU31: 3.2759666 | DV31: 0.77167582 | DW31: 0.86119174 | DX31: 0.092151581 | DY31: 0.005278894 | DZ31: 0.74904 | EA31: 0.0049941788 | EB31: 0.050409084 | EC31: 0.50594402 | ED31: 1.210305 | EE31: 1.6197094 | EF31: 3.2759666 | EG31: 3.2759666 | EH31: 0.35544448 | EJ31: 3.2759666 | EK31: 0.028889143 | EL31: 1.0403333 | EM31: 1.0403333 | EN31: 1.0403333 | EO31: 1.0772387 | EP31: 1.0700571 | EQ31: 0.35922285 | ER31: 2.126231 | ES31: 0.25023608 | ET31: 0.30158151 | EU31: 0.0027025025 | EV31: 0.067518551 | EW31: 0.0049941788 | EX31: 0.44665829 | EY31: 2.2246951 | EZ31: 1.9763199 | FA31: 0.0014056933 | FB31: 0.52670167 | FC31: 0.76484683 | FD31: 4.6640874 | FE31: 2.8089 | FF31: 0.10515262 | FH31: 0.00018138318 | FI31: 0.57950832 | FJ31: 3.3949125
A32: 37803 | B32: 0.057756262 | C32: 0.023284016 | D32: 0.035982423 | E32: 0.034633164 | F32: 1.0375185 | G32: 0.0048335778 | H32: 1.5649721 | I32: 3.1855896 | J32: 2.8473762 | K32: 2.8013 | L32: 7.450266 | M32: 0.048188539 | N32: 1.40065 | O32: 13.562925 | P32: 3.1855896 | Q32: 1.40065 | R32: 0.0048564001 | S32: 0.36529008 | T32: 1.6286295 | U32: 0.56653723 | V32: 0.97301146 | W32: 1.5959459 | X32: 1.6286628 | Y32: 0.0048564001 | Z32: 0.0025968981 | AA32: 0.028900237 | AB32: 0.00070313755 | AC32: 0.0048564001 | AD32: 2.0276968 | AE32: 0.0048564001 | AF32: 0.0048564001 | AG32: 0.0039953504 | AH32: 0.33843489 | AI32: 0.00097987981 | AJ32: 0.0064752001 | AK32: 0.0064858795 | AL32: 0.0048564001 | AM32: 0.0069975109 | AN32: 0.42500065 | AP32: 0.099921527 | AQ32: 0.0048564001 | AR32: 0.42836739 | AS32: 0.015762347 | AT32: 1.0375185 | AU32: 0.08038665 | AV32: 2.8013 | AW32: 0.45968165 | AX32: 2.8013 | AY32: 0.0048564001 | AZ32: 3.1855896 | BA32: 0.32564925 | BB32: 1.4937237 | BC32: 3.1855896 | BD32: 3.1855896 | BE32: 0.0048564001 | BF32: 0.096709936 | BG32: 1.3129453 | BH32: 3.1855896 | BI32: 3.2202187 | BJ32: 3.1855896 | BK32: 1.0375185 | BL32: 0.35375577 | BM32: 0.0014130139 | BN32: 0.0048564001 | BO32: 0.014444158 | BP32: 0.06484896 | BQ32: 0.16116839 | BR32: 0.35923314 | BS32: 0.012068847 | BT32: 0.036314493 | BU32: 0.060595415 | BV32: 0.00033474338 | BW32: 0.00034074096 | BY32: 3.1855896 | BZ32: 0.64088309 | CA32: 3.1855896 | CB32: 0.047528962 | CC32: 0.023601458 | CD32: 3.9510578 | CE32: 0.019064244 | CF32: 0.037476939 | CG32: 0.0023707885 | CH32: 9.3405311 | CI32: 3.1855896 | CJ32: 0.0018582421 | CK32: 0.37113978 | CL32: 0.038580085 | CM32: 2.0270892 | CN32: 3.1855896 | CO32: 3.1855896 | CP32: 0.34872835 | CQ32: 0.0022898299 | CR32: 0.030751278 | CS32: 0.73718421 | CT32: 0.21885156 | CU32: 0.0048564001 | CV32: 3.1855896 | CW32: 0.10716936 | CX32: 0.096083664 | CY32: 0.2682364 | CZ32: 0.19870335 | DA32: 0.0024431575 | DB32: 3.1855896 | DC32: 0.29410591 | DD32: 0.11835597 | DE32: 0.45591849 | DF32: 0.37113978 | DG32: 0.03699551 | DH32: 3.1855896 | DI32: 0.18502666 | DJ32: 0.0048564001 | DK32: 0.022001524 | DL32: 0.052023615 | DM32: 0.38426612 | DN32: 7.2855657 | DO32: 0.048502614 | DP32: 2.8013 | DQ32: 0.00046605996 | DR32: 0.80705755 | DS32: 0.052152333 | DT32: 0.71710526 | DU32: 3.1855896 | DV32: 0.76958791 | DW32: 0.85727987 | DX32: 0.092270345 | DY32: 0.0051936461 | DZ32: 0.74701333 | EA32: 0.0048564001 | EB32: 0.048972663 | EC32: 0.50588724 | ED32: 1.2042438 | EE32: 1.5959459 | EF32: 3.1855896 | EG32: 3.1855896 | EH32: 0.37113978 | EJ32: 3.1855896 | EK32: 0.028837701 | EL32: 1.0375185 | EM32: 1.0375185 | EN32: 1.0375185 | EO32: 1.0741593 | EP32: 1.0671619 | EQ32: 0.3467728 | ER32: 2.0581904 | ES32: 0.24955902 | ET32: 0.30004391 | EU32: 0.0026901267 | EV32: 0.067125142 | EW32: 0.0048564001 | EX32: 0.44536479 | EY32: 2.1794912 | EZ32: 1.9794075 | FA32: 0.0014039655 | FB32: 0.52536524 | FC32: 0.7627774 | FD32: 4.5511852 | FE32: 2.8013 | FF32: 0.10407951 | FH32: 0.00018061251 | FI32: 0.58612946 | FJ32: 3.3857269
A33: 37834 | B33: 0.060153789 | C33: 0.024419429 | D33: 0.037642453 | E33: 0.034198029 | F33: 1.0846296 | G33: 0.0050653821 | H33: 1.6360335 | I33: 3.2619585 | J33: 2.9796911 | K33: 2.9285 | L33: 7.7885638 | M33: 0.050128981 | N33: 1.46425 | O33: 14.06587 | P33: 3.2619585 | Q33: 1.46425 | R33: 0.0049728237 | S33: 0.38024566 | T33: 1.667318 | U33: 0.59861818 | V33: 0.97561382 | W33: 1.670136 | X33: 1.6673309 | Y33: 0.0049728237 | Z33: 0.0026637499 | AA33: 0.029610718 | AB33: 0.00073157632 | AC33: 0.0049728237 | AD33: 2.0983054 | AE33: 0.0049728237 | AF33: 0.0049728237 | AG33: 0.0041611606 | AH33: 0.35381134 | AI33: 0.0010213477 | AJ33: 0.0066304316 | AK33: 0.0069124658 | AL33: 0.0049728237 | AM33: 0.0072555869 | AN33: 0.43469581 | AP33: 0.10098624 | AQ33: 0.0049728237 | AR33: 0.43876735 | AS33: 0.016478075 | AT33: 1.0846296 | AU33: 0.085797095 | AV33: 2.9285 | AW33: 0.47689226 | AX33: 2.9285 | AY33: 0.0049728237 | AZ33: 3.2619585 | BA33: 0.34029771 | BB33: 1.5461941 | BC33: 3.2619585 | BD33: 3.2619585 | BE33: 0.0049728237 | BF33: 0.096559342 | BG33: 1.3800009 | BH33: 3.2619585 | BI33: 3.3628726 | BJ33: 3.2619585 | BK33: 1.0846296 | BL33: 0.36969428 | BM33: 0.0014753149 | BN33: 0.0049728237 | BO33: 0.015022571 | BP33: 0.070498315 | BQ33: 0.16773296 | BR33: 0.37554501 | BS33: 0.012577306 | BT33: 0.036684204 | BU33: 0.063755905 | BV33: 0.0003438821 | BW33: 0.00035275957 | BY33: 3.2619585 | BZ33: 0.64761168 | CA33: 3.2619585 | CB33: 0.049636519 | CC33: 0.024645141 | CD33: 4.1304654 | CE33: 0.019954347 | CF33: 0.038553084 | CG33: 0.0024851072 | CH33: 9.7724045 | CI33: 3.2619585 | CJ33: 0.0019426202 | CK33: 0.39592141 | CL33: 0.052062222 | CM33: 2.0988836 | CN33: 3.2619585 | CO33: 3.2619585 | CP33: 0.36454962 | CQ33: 0.0023685432 | CR33: 0.028316601 | CS33: 0.77065789 | CT33: 0.22878906 | CU33: 0.0049728237 | CV33: 3.2619585 | CW33: 0.11149819 | CX33: 0.10158385 | CY33: 0.27285772 | CZ33: 0.20909045 | DA33: 0.0025416815 | DB33: 3.2619585 | DC33: 0.30250599 | DD33: 0.12333777 | DE33: 0.47219401 | DF33: 0.39592141 | DG33: 0.039062292 | DH33: 3.2619585 | DI33: 0.19247327 | DJ33: 0.0049728237 | DK33: 0.022949728 | DL33: 0.053306418 | DM33: 0.39520918 | DN33: 7.6163849 | DO33: 0.050674463 | DP33: 2.9285 | DQ33: 0.00047024536 | DR33: 0.84137792 | DS33: 0.053253782 | DT33: 0.74737138 | DU33: 3.2619585 | DV33: 0.80453297 | DW33: 0.87787035 | DX33: 0.096497934 | DY33: 0.0053442843 | DZ33: 0.78093333 | EA33: 0.0049728237 | EB33: 0.050171923 | EC33: 0.52506544 | ED33: 1.238633 | EE33: 1.670136 | EF33: 3.2619585 | EG33: 3.2619585 | EH33: 0.39592141 | EJ33: 3.2619585 | EK33: 0.030200703 | EL33: 1.0846296 | EM33: 1.0846296 | EN33: 1.0846296 | EO33: 1.1220307 | EP33: 1.115619 | EQ33: 0.35299932 | ER33: 2.113952 | ES33: 0.26089087 | ET33: 0.31192084 | EU33: 0.0028020679 | EV33: 0.07036585 | EW33: 0.0049728237 | EX33: 0.46570615 | EY33: 2.2551209 | EZ33: 2.0912181 | FA33: 0.0014653556 | FB33: 0.54926196 | FC33: 0.79741321 | FD33: 4.6681225 | FE33: 2.9285 | FF33: 0.10533074 | FH33: 0.00018870417 | FI33: 0.62327465 | FJ33: 3.5394643
A34: 37865 | B34: 0.059392428 | C34: 0.02421612 | D34: 0.037607557 | E34: 0.036299695 | F34: 1.0818148 | G34: 0.0050818588 | H34: 1.6317877 | I34: 3.2777543 | J34: 2.9733681 | K34: 2.9209 | L34: 7.7683511 | M34: 0.049991956 | N34: 1.46045 | O34: 13.913619 | P34: 3.2777543 | Q34: 1.46045 | R34: 0.0049969042 | S34: 0.37778238 | T34: 1.6751343 | U34: 0.60156524 | V34: 0.99962355 | W34: 1.6727275 | X34: 1.6733887 | Y34: 0.0049969042 | Z34: 0.0026239243 | AA34: 0.029626737 | AB34: 0.00072876747 | AC34: 0.0049969042 | AD34: 2.1426416 | AE34: 0.0049969042 | AF34: 0.0049969042 | AG34: 0.0043244404 | AH34: 0.35288844 | AI34: 0.0010284569 | AJ34: 0.006662539 | AK34: 0.0076269741 | AL34: 0.0049969042 | AM34: 0.0071780694 | AN34: 0.43574633 | AP34: 0.10124788 | AQ34: 0.0049969042 | AR34: 0.44111362 | AS34: 0.016435312 | AT34: 1.0818148 | AU34: 0.09057188 | AV34: 2.9209 | AW34: 0.47573986 | AX34: 2.9209 | AY34: 0.0049969042 | AZ34: 3.2777543 | BA34: 0.33927659 | BB34: 1.5549908 | BC34: 3.2777543 | BD34: 3.2777543 | BE34: 0.0049969042 | BF34: 0.08982465 | BG34: 1.372926 | BH34: 3.2777543 | BI34: 3.3541453 | BJ34: 3.2777543 | BK34: 1.0818148 | BL34: 0.36582678 | BM34: 0.0014677889 | BN34: 0.0049969042 | BO34: 0.015008992 | BP34: 0.070217318 | BQ34: 0.16655642 | BR34: 0.37519589 | BS34: 0.012822775 | BT34: 0.036888732 | BU34: 0.06370973 | BV34: 0.0003461069 | BW34: 0.00035106396 | BY34: 3.2777543 | BZ34: 0.65420624 | CA34: 3.2777543 | CB34: 0.049161317 | CC34: 0.025357236 | CD34: 4.1197461 | CE34: 0.019749155 | CF34: 0.037493486 | CG34: 0.0025046949 | CH34: 9.8188975 | CI34: 3.2777543 | CJ34: 0.0019375788 | CK34: 0.39954859 | CL34: 0.051198948 | CM34: 2.1105653 | CN34: 3.2777543 | CO34: 3.2777543 | CP34: 0.36413389 | CQ34: 0.0023873509 | CR34: 0.027024401 | CS34: 0.76865789 | CT34: 0.22819531 | CU34: 0.0049969042 | CV34: 3.2777543 | CW34: 0.11168081 | CX34: 0.10172957 | CY34: 0.26734703 | CZ34: 0.21397437 | DA34: 0.002525332 | DB34: 3.2777543 | DC34: 0.30355213 | DD34: 0.12306195 | DE34: 0.47348798 | DF34: 0.39954859 | DG34: 0.03919093 | DH34: 3.2777543 | DI34: 0.19104148 | DJ34: 0.0049969042 | DK34: 0.022788553 | DL34: 0.053405079 | DM34: 0.39957592 | DN34: 7.596619 | DO34: 0.050550196 | DP34: 2.9209 | DQ34: 0.00046974156 | DR34: 0.83909796 | DS34: 0.053084591 | DT34: 0.73361798 | DU34: 3.2777543 | DV34: 0.80244505 | DW34: 0.86418898 | DX34: 0.095468912 | DY34: 0.0052912463 | DZ34: 0.77890667 | EA34: 0.0049969042 | EB34: 0.049711608 | EC34: 0.52545513 | ED34: 1.2100987 | EE34: 1.6727275 | EF34: 3.2777543 | EG34: 3.2777543 | EH34: 0.39954859 | EJ34: 3.2777543 | EK34: 0.030599422 | EL34: 1.0818148 | EM34: 1.0818148 | EN34: 1.0818148 | EO34: 1.1186473 | EP34: 1.1127238 | EQ34: 0.3612342 | ER34: 2.1185592 | ES34: 0.26021381 | ET34: 0.30917501 | EU34: 0.0027874314 | EV34: 0.072198891 | EW34: 0.0049969042 | EX34: 0.4641654 | EY34: 2.2551729 | EZ34: 2.1249771 | FA34: 0.0014648673 | FB34: 0.5478468 | FC34: 0.79534377 | FD34: 4.7029368 | FE34: 2.9209 | FF34: 0.10484545 | FH34: 0.0001879964 | FI34: 0.61548944 | FJ34: 3.5302787
