Workbook

Sheet TCRB_NOS
A1: mes | B1: Afghanistan, Islamic Republic of | C1: Albania | D1: Algeria | E1: Angola | F1: Antigua and Barbuda | G1: Armenia, Republic of | H1: Aruba, Kingdom of the Netherlands | I1: Austria | J1: Azerbaijan, Republic of | K1: Bahamas, The | L1: Bahrain, Kingdom of | M1: Bangladesh | N1: Barbados | O1: Belarus, Republic of | P1: Belgium | Q1: Belize | R1: Benin | S1: Bolivia | T1: Bosnia and Herzegovina | U1: Botswana | V1: Brazil | W1: Brunei Darussalam | X1: Bulgaria | Y1: Burkina Faso | Z1: Burundi | AA1: Cabo Verde | AB1: Cambodia | AC1: Cameroon | AD1: Canada | AE1: Central African Republic | AF1: Chad | AG1: Chile | AH1: China, People's Republic of | AI1: Colombia | AJ1: Comoros, Union of the | AK1: Congo, Democratic Republic of the | AL1: Congo, Republic of | AM1: Costa Rica | AN1: Croatia, Republic of | AO1: Curaçao, Kingdom of the Netherlands | AP1: Czech Republic | AQ1: Côte d'Ivoire | AR1: Denmark | AS1: Djibouti | AT1: Dominica | AU1: Dominican Republic | AV1: Ecuador | AW1: Egypt, Arab Republic of | AX1: El Salvador | AY1: Equatorial Guinea, Republic of | AZ1: Estonia, Republic of | BA1: Ethiopia, The Federal Democratic Republic of | BB1: Fiji, Republic of | BC1: Finland | BD1: France | BE1: Gabon | BF1: Gambia, The | BG1: Georgia | BH1: Germany | BI1: Ghana | BJ1: Greece | BK1: Grenada | BL1: Guatemala | BM1: Guinea | BN1: Guinea-Bissau | BO1: Guyana | BP1: Haiti | BQ1: Honduras | BR1: Hong Kong Special Administrative Region, People's Republic of China | BS1: Hungary | BT1: Iceland | BU1: India | BV1: Indonesia | BW1: Iran, Islamic Republic of | BX1: Iraq | BY1: Ireland | BZ1: Israel | CA1: Italy | CB1: Jamaica | CC1: Japan | CD1: Jordan | CE1: Kazakhstan, Republic of | CF1: Kenya | CG1: Korea, Republic of | CH1: Kuwait | CI1: Latvia, Republic of | CJ1: Lebanon | CK1: Lesotho, Kingdom of | CL1: Liberia | CM1: Libya | CN1: Lithuania, Republic of | CO1: Luxembourg | CP1: Macao Special Administrative Region, People's Republic of China | CQ1: Madagascar, Republic of | CR1: Malawi | CS1: Malaysia | CT1: Maldives | CU1: Mali | CV1: Malta | CW1: Mauritania, Islamic Republic of | CX1: Mauritius | CY1: Mexico | CZ1: Moldova, Republic of | DA1: Mongolia | DB1: Montenegro | DC1: Morocco | DD1: Mozambique, Republic of | DE1: Myanmar | DF1: Namibia | DG1: Nepal | DH1: Netherlands, The | DI1: Nicaragua | DJ1: Niger | DK1: Nigeria | DL1: North Macedonia, Republic of | DM1: Norway | DN1: Oman | DO1: Pakistan | DP1: Panama | DQ1: Paraguay | DR1: Peru | DS1: Philippines | DT1: Poland, Republic of | DU1: Portugal | DV1: Qatar | DW1: Romania | DX1: Russian Federation | DY1: Rwanda | DZ1: Saudi Arabia | EA1: Senegal | EB1: Serbia, Republic of | EC1: Seychelles | ED1: Sierra Leone | EE1: Singapore | EF1: Slovak Republic | EG1: Slovenia, Republic of | EH1: South Africa | EI1: South Sudan, Republic of | EJ1: Spain | EK1: Sri Lanka | EL1: St. Kitts and Nevis | EM1: St. Lucia | EN1: St. Vincent and the Grenadines | EO1: Sudan | EP1: Suriname | EQ1: Sweden | ER1: Switzerland | ES1: Syrian Arab Republic | ET1: São Tomé and Príncipe, Democratic Republic of | EU1: Tanzania, United Republic of | EV1: Thailand | EW1: Togo | EX1: Trinidad and Tobago | EY1: Tunisia | EZ1: Türkiye, Republic of | FA1: Uganda | FB1: Ukraine | FC1: United Arab Emirates | FD1: United Kingdom | FE1: United States | FF1: Uruguay | FG1: Uzbekistan, Republic of | FH1: Vietnam | FI1: Zambia | FJ1: Zimbabwe
A2: 36892 | F2: 2.8325085 | H2: 3.9603221 | I2: 7.0038242 | P2: 7.6203674 | V2: 92.436768 | X2: 187.12947 | Z2: 0.0036350527 | AB2: 0.0022350389 | AD2: 6.8336446 | AG2: 0.0082162682 | AH2: 0.829317 | AI2: 0.0020806878 | AM2: 0.010104512 | AP2: 0.21262129 | AQ2: 0.008793717 | AR2: 1.0290207 | AT2: 3.198111 | AU2: 0.16243124 | AV2: 5.2766465 | AZ2: 12.070085 | BA2: 0.20548106 | BC2: 7.9899742 | BD2: 8.0197011 | BH2: 7.6518057 | BI2: 1.1436823 | BJ2: 7.2442501 | BK2: 3.1040072 | BP2: 0.093466308 | BQ2: 0.78216657 | BS2: 0.027929014 | BT2: 0.090154887 | BU2: 0.10539511 | BV2: 0.0003210555 | BY2: 6.3052685 | BZ2: 1.7013878 | CA2: 7.631888 | CB2: 0.050106285 | CC2: 0.088504986 | CG2: 0.0054140486 | CI2: 5.5706567 | CN2: 6.9201023 | CO2: 7.3648669 | CP2: 0.75177763 | CQ2: 0.0022496324 | CS2: 2.2878896 | CT2: 0.44195866 | CX2: 0.13649112 | CY2: 0.53033199 | CZ2: 0.12225848 | DH2: 7.6373816 | DM2: 0.93442228 | DN2: 18.220282 | DT2: 2.3214448 | DU2: 7.5632196 | DW2: 1.3652942 | DX2: 0.12949514 | DZ2: 1.6205116 | EA2: 0.0093885453 | EF2: 10.191105 | EG2: 6.5434676 | EH2: 0.41681706 | EJ2: 6.7870801 | EM2: 2.9359468 | EN2: 2.9956222 | EO2: 2.0878315 | EQ2: 2.9486666 | ER2: 6.1356737 | EW2: 0.0083078653 | EX2: 0.68073319 | EZ2: 6.8728785 | FD2: 11.589088 | FE2: 8.5654234
A3: 36923 | F3: 2.8392366 | H3: 3.9789848 | I3: 6.9298711 | P3: 7.5428277 | Q3: 3.9714306 | V3: 90.96212 | X3: 185.03577 | Z3: 0.003989467 | AB3: 0.0022695947 | AD3: 6.8071395 | AG3: 0.0083344561 | AH3: 0.83292316 | AI3: 0.0021252504 | AM3: 0.010201324 | AP3: 0.21260255 | AQ3: 0.0087138448 | AR3: 1.0219215 | AT3: 3.2134082 | AU3: 0.16278387 | AV3: 5.4481374 | AZ3: 11.935166 | BA3: 0.20459422 | BC3: 7.9229361 | BD3: 7.9255421 | BH3: 7.5849016 | BI3: 1.1719954 | BJ3: 7.1325164 | BK3: 3.1082377 | BP3: 0.094407901 | BQ3: 0.79213641 | BS3: 0.027819191 | BT3: 0.089627139 | BU3: 0.10531316 | BV3: 0.00031860065 | BY3: 6.27336 | BZ3: 1.7057231 | CA3: 7.5478858 | CB3: 0.050642098 | CC3: 0.089332855 | CG3: 0.0055471006 | CI3: 5.4791724 | CN3: 6.8311268 | CO3: 7.3506814 | CP3: 0.74824767 | CQ3: 0.0022779806 | CS3: 2.2999263 | CT3: 0.45313864 | CX3: 0.13670042 | CY3: 0.53541202 | CZ3: 0.12297466 | DH3: 7.5931329 | DM3: 0.93015437 | DN3: 18.206599 | DT3: 2.3443561 | DU3: 7.4631284 | DW3: 1.370483 | DX3: 0.13178976 | DZ3: 1.622513 | EA3: 0.00924137 | EF3: 10.279492 | EG3: 6.5229135 | EH3: 0.41764921 | EJ3: 6.710988 | EM3: 2.948971 | EN3: 2.9838035 | EO3: 2.0341081 | EQ3: 2.887094 | ER3: 6.0124097 | EW3: 0.0082893983 | EX3: 0.68636261 | EZ3: 6.2074596 | FD3: 11.466009 | FE3: 8.6278578
A4: 36951 | F4: 2.8406787 | H4: 3.9805925 | I4: 6.8449168 | P4: 7.4522806 | V4: 87.408282 | X4: 182.45158 | Z4: 0.0039758446 | AB4: 0.0022965239 | AD4: 6.6608947 | AG4: 0.0080148494 | AH4: 0.82705751 | AI4: 0.0021209792 | AM4: 0.010310596 | AP4: 0.2104126 | AQ4: 0.0086390734 | AR4: 1.012206 | AT4: 3.2236834 | AU4: 0.16193466 | AV4: 5.5621572 | AZ4: 11.814354 | BA4: 0.19929119 | BC4: 7.8527803 | BD4: 7.8480371 | BH4: 7.4772268 | BI4: 1.2007294 | BJ4: 7.1691192 | BK4: 3.099611 | BP4: 0.093965142 | BQ4: 0.79551875 | BS4: 0.027619963 | BT4: 0.087954117 | BU4: 0.10545334 | BV4: 0.00030519767 | BY4: 6.2329225 | BZ4: 1.6891676 | CA4: 7.4472057 | CB4: 0.05087814 | CC4: 0.085322785 | CG4: 0.0054340176 | CI4: 5.4276105 | CN4: 6.7708111 | CO4: 7.2663849 | CP4: 0.74551854 | CQ4: 0.0022425717 | CS4: 2.2931131 | CT4: 0.44966127 | CX4: 0.13542299 | CY4: 0.54301568 | CZ4: 0.12151648 | DH4: 7.5553523 | DM4: 0.92565117 | DN4: 18.151869 | DT4: 2.3690778 | DU4: 7.3894651 | DW4: 1.3722635 | DX4: 0.1337211 | DZ4: 1.6209036 | EA4: 0.0090937806 | EF4: 10.213203 | EG4: 6.4993532 | EH4: 0.41667432 | EJ4: 6.6435953 | EM4: 2.9562339 | EN4: 2.9796428 | EO4: 2.0770616 | EQ4: 2.8246083 | ER4: 5.939681 | EW4: 0.0082838469 | EX4: 0.68370883 | EZ4: 5.2149484 | FD4: 11.416346 | FE4: 8.6389111
A5: 36982 | F5: 2.8327027 | H5: 3.9857989 | I5: 6.7398066 | P5: 7.3649332 | V5: 83.690895 | X5: 178.5861 | Z5: 0.0038318606 | AB5: 0.0022336798 | AD5: 6.707172 | AG5: 0.007898438 | AH5: 0.82799983 | AI5: 0.0021023685 | AM5: 0.010379567 | AP5: 0.20660331 | AQ5: 0.008498356 | AR5: 0.99667442 | AT5: 3.2072972 | AU5: 0.16279037 | AV5: 5.6527746 | AZ5: 11.65241 | BA5: 0.19621021 | BC5: 7.7299109 | BD5: 7.7269868 | BH5: 7.3602179 | BI5: 1.2156265 | BJ5: 7.0906928 | BK5: 3.0987663 | BP5: 0.09542412 | BQ5: 0.79654653 | BS5: 0.027222172 | BT5: 0.083799144 | BU5: 0.10569238 | BV5: 0.00027887319 | BY5: 6.1549118 | BZ5: 1.7009268 | CA5: 7.3287774 | CB5: 0.051078937 | CC5: 0.083553625 | CG5: 0.0052973424 | CI5: 5.3368002 | CN5: 6.6473048 | CO5: 7.1421692 | CP5: 0.74565594 | CQ5: 0.0021575924 | CS5: 2.2932886 | CT5: 0.45876974 | CX5: 0.13517399 | CY5: 0.56083278 | CZ5: 0.12257899 | DH5: 7.4440133 | DM5: 0.91612263 | DN5: 18.135339 | DT5: 2.4120453 | DU5: 7.281375 | DW5: 1.3781716 | DX5: 0.1351917 | DZ5: 1.6194275 | EA5: 0.0088921004 | EF5: 10.052829 | EG5: 6.4102549 | EH5: 0.4077522 | EJ5: 6.5434716 | EM5: 2.9891674 | EN5: 2.9856285 | EO5: 2.0643846 | EQ5: 2.7951994 | ER5: 5.860119 | EW5: 0.0082172875 | EX5: 0.68625237 | EZ5: 4.5762269 | FD5: 11.401896 | FE5: 8.6653329
A6: 37012 | F6: 2.8635542 | H6: 3.9756977 | I6: 6.5799746 | P6: 7.2217637 | Q6: 3.9647971 | V6: 79.739951 | X6: 174.32544 | Z6: 0.0035365436 | AB6: 0.002219735 | AD6: 6.7931774 | AG6: 0.0078109301 | AH6: 0.81912049 | AI6: 0.0020779316 | AM6: 0.010340108 | AP6: 0.20390938 | AQ6: 0.0083816725 | AR6: 0.97664843 | AT6: 3.2003674 | AU6: 0.16228039 | AV6: 5.6295275 | AZ6: 11.428193 | BA6: 0.19372721 | BC6: 7.5818549 | BD6: 7.5754714 | BH6: 7.1963246 | BI6: 1.2270353 | BJ6: 6.9382564 | BK6: 3.0829626 | BP6: 0.095315493 | BQ6: 0.79847427 | BS6: 0.027646657 | BT6: 0.078367984 | BU6: 0.10549398 | BV6: 0.00027920976 | BY6: 6.0343829 | BZ6: 1.7110089 | CA6: 7.1595762 | CB6: 0.051135957 | CC6: 0.084452862 | CG6: 0.0053716969 | CI6: 5.2553394 | CN6: 6.5143855 | CO6: 6.9981444 | CP6: 0.74030383 | CQ6: 0.0021180765 | CS6: 2.2823883 | CT6: 0.46870362 | CX6: 0.13324011 | CY6: 0.57136737 | CZ6: 0.1209431 | DH6: 7.2774657 | DM6: 0.91057383 | DN6: 18.013125 | DT6: 2.4481068 | DU6: 7.1541786 | DW6: 1.3641737 | DX6: 0.13599861 | DZ6: 1.6068545 | EA6: 0.0086386656 | EF6: 9.8270018 | EG6: 6.318463 | EH6: 0.41253494 | EJ6: 6.3999681 | EM6: 2.9652787 | EN6: 2.9595594 | EO6: 2.1261969 | EQ6: 2.7668326 | ER6: 5.7278704 | EW6: 0.0080990294 | EX6: 0.68483991 | EZ6: 5.0819746 | FD6: 11.336575 | FE6: 8.654603
A7: 37043 | F7: 2.8342721 | H7: 4.0036754 | I7: 6.4673591 | P7: 7.0971183 | V7: 77.898932 | X7: 170.60199 | Z7: 0.0032936735 | AB7: 0.0022298212 | AD7: 6.9113528 | AG7: 0.007707484 | AH7: 0.81345296 | AI7: 0.0021269185 | AM7: 0.010366463 | AP7: 0.20448735 | AQ7: 0.0082724257 | AR7: 0.95828491 | AT7: 3.2237854 | AU7: 0.16219069 | AV7: 5.6854085 | AZ7: 11.238091 | BA7: 0.1934487 | BC7: 7.4368884 | BD7: 7.4359003 | BH7: 7.0674713 | BI7: 1.2400306 | BJ7: 6.7989893 | BK7: 3.1038784 | BP7: 0.094787567 | BQ7: 0.80438171 | BS7: 0.028444899 | BT7: 0.077011631 | BU7: 0.10724335 | BV7: 0.00028322658 | BY7: 5.9560059 | BZ7: 1.7153913 | CA7: 7.0415435 | CB7: 0.052081867 | CC7: 0.084472297 | CG7: 0.0054340992 | CI7: 5.1799128 | CN7: 6.4256288 | CO7: 6.8856628 | CP7: 0.74529729 | CQ7: 0.0020966128 | CS7: 2.2918055 | CT7: 0.48763018 | CX7: 0.1332641 | CY7: 0.57887718 | CZ7: 0.12206153 | DH7: 7.1116896 | DM7: 0.89998924 | DN7: 18.215143 | DT7: 2.4645705 | DU7: 7.0363744 | DW7: 1.3708007 | DX7: 0.13845047 | DZ7: 1.6150772 | EA7: 0.008600815 | EF7: 9.6649037 | EG7: 6.2228422 | EH7: 0.41242971 | EJ7: 6.2993623 | EM7: 3.01436 | EN7: 2.951921 | EO7: 2.2245162 | EQ7: 2.6559617 | ER7: 5.6689313 | EW7: 0.0079796689 | EX7: 0.7002375 | EZ7: 4.9186311 | FD7: 11.216533 | FE7: 8.7135765
A8: 37073 | F8: 2.8491348 | H8: 4.0196416 | I8: 6.5444858 | P8: 7.1692581 | V8: 76.209336 | X8: 172.10828 | Z8: 0.003533774 | AB8: 0.0022609358 | AD8: 6.8781269 | AG8: 0.0072347303 | AH8: 0.81113005 | AI8: 0.0021350084 | AM8: 0.010390426 | AP8: 0.20940264 | AQ8: 0.0083353991 | AR8: 0.96505306 | AT8: 3.2303539 | AU8: 0.16215193 | AV8: 5.7114124 | AZ8: 11.407103 | BA8: 0.18991085 | BC8: 7.4621748 | BD8: 7.50162 | BH8: 7.1529585 | BI8: 1.2532818 | BJ8: 6.753373 | BK8: 3.1176429 | BP8: 0.094002663 | BQ8: 0.80744157 | BS8: 0.028526883 | BT8: 0.080927621 | BU8: 0.10856809 | BV8: 0.00030623718 | BY8: 6.0027691 | BZ8: 1.7123693 | CA8: 7.1247253 | CB8: 0.052882588 | CC8: 0.08270495 | CG8: 0.005419395 | CI8: 5.2143385 | CN8: 6.443991 | CO8: 6.8926621 | CP8: 0.74606316 | CQ8: 0.0021602789 | CS8: 2.296703 | CT8: 0.44148812 | CX8: 0.13407844 | CY8: 0.57479637 | CZ8: 0.12043862 | DH8: 7.1793855 | DM8: 0.89378616 | DN8: 18.235723 | DT8: 2.3361193 | DU8: 7.1213832 | DW8: 1.3723061 | DX8: 0.13887985 | DZ8: 1.6152187 | EA8: 0.0088066161 | EF8: 9.7769457 | EG8: 6.3047489 | EH8: 0.40803436 | EJ8: 6.3839265 | EM8: 3.0191027 | EN8: 2.9927774 | EO8: 2.3223066 | EQ8: 2.6521988 | ER8: 5.7520837 | EW8: 0.0082114361 | EX8: 0.71073509 | EZ8: 4.6330446 | FD8: 11.267068 | FE8: 8.7076687
A9: 37104 | F9: 2.8566545 | H9: 4.0275229 | I9: 6.8417791 | P9: 7.5085491 | Q9: 3.9852351 | V9: 75.464755 | X9: 180.82617 | Z9: 0.0034684945 | AB9: 0.0022674793 | AD9: 6.8421967 | AG9: 0.0071143012 | AH9: 0.8128606 | AI9: 0.002157361 | AM9: 0.01042161 | AP9: 0.21746899 | AQ9: 0.0087264587 | AR9: 1.011653 | AT9: 3.2385384 | AU9: 0.16353584 | AV9: 5.7427857 | AZ9: 11.938844 | BA9: 0.18921865 | BC9: 7.8407508 | BD9: 7.8576493 | BH9: 7.475373 | BI9: 1.2369691 | BJ9: 7.0756348 | BK9: 3.1188236 | BP9: 0.092294602 | BQ9: 0.81211454 | BS9: 0.029549073 | BT9: 0.082821205 | BU9: 0.10943236 | BV9: 0.00037106978 | BY9: 6.3069498 | BZ9: 1.7050894 | CA9: 7.4628671 | CB9: 0.053436402 | CC9: 0.085216478 | CG9: 0.0055193061 | CI9: 5.4259451 | CN9: 6.7916398 | CO9: 7.3033167 | CP9: 0.74265866 | CQ9: 0.0022591286 | CS9: 2.2970562 | CT9: 0.424468 | CX9: 0.13371944 | CY9: 0.58075881 | CZ9: 0.12011947 | DH9: 7.548088 | DM9: 0.92527903 | DN9: 18.164715 | DT9: 2.2991992 | DU9: 7.4449974 | DW9: 1.3835422 | DX9: 0.13844633 | DZ9: 1.6154067 | EA9: 0.0093766148 | EF9: 10.227799 | EG9: 6.6010812 | EH9: 0.39969416 | EJ9: 6.703086 | EM9: 3.0038405 | EN9: 2.9847664 | EO9: 2.3657717 | EQ9: 2.7706973 | ER9: 5.9947273 | EW9: 0.0085605353 | EX9: 0.72011318 | EZ9: 4.5073322 | FD9: 11.510385 | FE9: 8.7176134
A10: 37135 | F10: 2.8605017 | H10: 4.0479838 | I10: 6.9595828 | P10: 7.6371286 | V10: 71.287123 | X10: 186.24927 | Z10: 0.0035697073 | AB10: 0.002296294 | AD10: 6.7522175 | AG10: 0.0071044745 | AH10: 0.82219716 | AI10: 0.002133826 | AM10: 0.010443454 | AP10: 0.21780487 | AQ10: 0.0088007498 | AR10: 1.0301348 | AT10: 3.2232799 | AU10: 0.16542731 | AV10: 5.8744285 | AZ10: 12.118855 | BA10: 0.19220662 | BC10: 8.009823 | BD10: 7.9843597 | BH10: 7.5819609 | BI10: 1.2255403 | BJ10: 7.3135982 | BK10: 3.1312189 | BP10: 0.091499787 | BQ10: 0.81666873 | BS10: 0.029579099 | BT10: 0.082415518 | BU10: 0.10827059 | BV10: 0.00035510908 | BY10: 6.4262211 | BZ10: 1.6789522 | CA10: 7.5692767 | CB10: 0.053688002 | CC10: 0.087137383 | CG10: 0.0054920305 | CI10: 5.5396902 | CN10: 6.8757241 | CO10: 7.4161927 | CP10: 0.74112402 | CQ10: 0.0023131045 | CS10: 2.3049467 | CT10: 0.43564411 | CX10: 0.13330691 | CY10: 0.57144285 | CZ10: 0.12167908 | DH10: 7.7496119 | DM10: 0.9500105 | DN10: 18.245943 | DT10: 2.3263865 | DU10: 7.5485113 | DW10: 1.3939673 | DX10: 0.13922083 | DZ10: 1.6193556 | EA10: 0.0095130912 | EF10: 10.393655 | EG10: 6.7538899 | EH10: 0.38679393 | EJ10: 6.7977682 | EM10: 3.0162987 | EN10: 3.014072 | EO10: 2.2322617 | EQ10: 2.7275493 | ER10: 6.1796658 | EW10: 0.0084201034 | EX10: 0.71976006 | EZ10: 4.5495776 | FD10: 11.77632 | FE10: 8.7783104
A11: 37165 | F11: 2.8599573 | H11: 4.0533867 | I11: 6.9146912 | P11: 7.5688629 | V11: 69.963238 | X11: 187.55218 | Z11: 0.0035047983 | AB11: 0.0022627888 | AD11: 6.6917398 | AG11: 0.0068327404 | AH11: 0.82327613 | AI11: 0.0021413841 | AM11: 0.010354702 | AP11: 0.22066977 | AQ11: 0.0087524826 | AR11: 1.0250249 | AT11: 3.2361722 | AU11: 0.16556261 | AV11: 5.933368 | AZ11: 12.029016 | BA11: 0.1905266 | BC11: 7.9327752 | BD11: 7.9300247 | BH11: 7.5171634 | BI11: 1.2570808 | BJ11: 7.2823782 | BK11: 3.1211866 | BP11: 0.089510021 | BQ11: 0.81124698 | BS11: 0.029542531 | BT11: 0.080807433 | BU11: 0.10793732 | BV11: 0.00032836462 | BY11: 6.3979998 | BZ11: 1.6791181 | CA11: 7.5260847 | CB11: 0.053320879 | CC11: 0.085336674 | CG11: 0.0054453279 | CI11: 5.5058459 | CN11: 6.8450249 | CO11: 7.3738948 | CP11: 0.73626576 | CQ11: 0.0023293459 | CS11: 2.2987966 | CT11: 0.43455313 | CX11: 0.13207894 | CY11: 0.57401391 | CZ11: 0.1231291 | DH11: 7.6843959 | DM11: 0.94324156 | DN11: 18.21524 | DT11: 2.3793643 | DU11: 7.5215818 | DW11: 1.4001805 | DX11: 0.13999917 | DZ11: 1.6182886 | EA11: 0.0095638863 | EF11: 10.323236 | EG11: 6.73489 | EH11: 0.35922078 | EJ11: 6.7403181 | EM11: 2.9907965 | EN11: 2.9822121 | EO11: 2.1406038 | EQ11: 2.7317971 | ER11: 6.1706993 | EW11: 0.0082794006 | EX11: 0.71787889 | EZ11: 4.4260738 | FD11: 11.650517 | FE11: 8.7340487
A12: 37196 | F12: 2.8849173 | H12: 4.0812226 | I12: 6.8155962 | P12: 7.4762505 | Q12: 4.027401 | V12: 76.388021 | X12: 185.44743 | Z12: 0.0034842396 | AB12: 0.0022767747 | AD12: 6.5819478 | AG12: 0.0070604146 | AH12: 0.8266544 | AI12: 0.0021662716 | AM12: 0.010431405 | AP12: 0.21926038 | AQ12: 0.0086440772 | AR12: 1.0073722 | AT12: 3.2430591 | AU12: 0.16542756 | AV12: 6.0651368 | AZ12: 11.868129 | BA12: 0.19276344 | BC12: 7.7918086 | BD12: 7.8028875 | BH12: 7.399669 | BI12: 1.2541074 | BJ12: 7.192609 | BK12: 3.1438959 | BP12: 0.08767722 | BQ12: 0.81462298 | BS12: 0.029590431 | BT12: 0.077757627 | BU12: 0.10957935 | BV12: 0.00032142592 | BY12: 6.3124268 | BZ12: 1.7094757 | CA12: 7.438171 | CB12: 0.052702485 | CC12: 0.084705477 | CG12: 0.0055262955 | CI12: 5.444675 | CN12: 6.7508866 | CO12: 7.2858049 | CP12: 0.73825216 | CQ12: 0.0023225634 | CS12: 2.3311586 | CT12: 0.4392873 | CX12: 0.13215645 | CY12: 0.5888948 | CZ12: 0.1250844 | DH12: 7.5720385 | DM12: 0.93937822 | DN12: 18.326794 | DT12: 2.4189564 | DU12: 7.4703117 | DW12: 1.4235857 | DX12: 0.1415206 | DZ12: 1.6265313 | EA12: 0.0093346527 | EF12: 10.178621 | EG12: 6.6725895 | EH12: 0.34530124 | EJ12: 6.6451999 | EM12: 3.0502162 | EN12: 3.0077438 | EO12: 2.1739612 | EQ12: 2.7396339 | ER12: 6.1491283 | EW12: 0.0082509707 | EX12: 0.71306356 | EZ12: 4.8953773 | FD12: 11.601145 | FE12: 8.7727025
A13: 37226 | F13: 2.8779338 | H13: 4.0849857 | I13: 6.840731 | P13: 7.4729808 | V13: 82.522872 | X13: 186.94666 | Z13: 0.0034687737 | AB13: 0.0022643128 | AD13: 6.6392675 | AG13: 0.0072313009 | AH13: 0.8251515 | AI13: 0.0021709956 | AM13: 0.010436539 | AP13: 0.22463751 | AQ13: 0.0086823145 | AR13: 1.0132481 | AT13: 3.2445637 | AU13: 0.16327022 | AV13: 6.0886721 | AZ13: 11.908024 | BA13: 0.18889841 | BC13: 7.8023639 | BD13: 7.8260955 | BH13: 7.4805056 | BI13: 1.2460256 | BJ13: 7.2730095 | BK13: 3.1354391 | BP13: 0.088964679 | BQ13: 0.81104216 | BS13: 0.030161119 | BT13: 0.079793984 | BU13: 0.10875814 | BV13: 0.00032703409 | BY13: 6.3522256 | BZ13: 1.6874743 | CA13: 7.4575321 | CB13: 0.052767149 | CC13: 0.081034472 | CG13: 0.0054970505 | CI13: 5.4755868 | CN13: 6.785837 | CO13: 7.2846633 | CP13: 0.73382746 | CQ13: 0.0023254686 | CS13: 2.3268717 | CT13: 0.44589868 | CX13: 0.13240232 | CY13: 0.59158389 | CZ13: 0.12496179 | DH13: 7.5622191 | DM13: 0.93537132 | DN13: 18.308722 | DT13: 2.4647817 | DU13: 7.4980251 | DW13: 1.4383192 | DX13: 0.14196957 | DZ13: 1.625277 | EA13: 0.0093212989 | EF13: 10.222573 | EG13: 6.690947 | EH13: 0.29128313 | EJ13: 6.680936 | EM13: 3.0313782 | EN13: 2.9778316 | EO13: 2.209623 | EQ13: 2.746246 | ER13: 6.1270947 | EW13: 0.0083381716 | EX13: 0.71228175 | EZ13: 5.2768937 | FD13: 11.606254 | FE13: 8.7134749 | FH13: 0.00021041013
A14: 37257 | E14: 0.009848486 | F14: 4.1057931 | H14: 5.7557106 | I14: 9.5459233 | P14: 10.460753 | V14: 115.86237 | X14: 267.0576 | Z14: 0.0047805047 | AB14: 0.0031749915 | AD14: 9.2188026 | AG14: 0.010185299 | AH14: 1.1634457 | AI14: 0.0031192501 | AM14: 0.014730868 | AP14: 0.32249165 | AQ14: 0.012254677 | AR14: 1.4113509 | AT14: 4.5514488 | AU14: 0.22983967 | AV14: 8.7134926 | AZ14: 16.782599 | BA14: 0.26376047 | BC14: 10.901738 | BD14: 10.940065 | BH14: 10.420286 | BI14: 1.8506149 | BJ14: 10.092615 | BK14: 4.4047675 | BP14: 0.12386242 | BQ14: 1.1371508 | BS14: 0.043113567 | BT14: 0.11579152 | BU14: 0.15091363 | BV14: 0.00047649695 | BY14: 8.8252169 | BZ14: 2.2621105 | CA14: 10.420926 | CB14: 0.074332333 | CC14: 0.1091321 | CG14: 0.0076068481 | CI14: 7.68584 | CN14: 9.5317683 | CO14: 10.052456 | CP14: 1.0291137 | CQ14: 0.003273648 | CS14: 3.2773502 | CT14: 0.64064748 | CX14: 0.18856981 | CY14: 0.83981253 | CZ14: 0.17797684 | DH14: 10.598271 | DL14: 0.18837762 | DM14: 1.3146254 | DN14: 25.638033 | DT14: 3.4506774 | DU14: 10.449537 | DW14: 2.0368098 | DX14: 0.20320265 | DZ14: 2.2893703 | EA14: 0.012869749 | EF14: 14.406065 | EG14: 9.4594042 | EH14: 0.41659595 | EJ14: 9.2831669 | EM14: 4.1556537 | EN14: 4.325675 | EO14: 3.5721083 | EQ14: 3.8925217 | ER14: 8.5486493 | EW14: 0.01181592 | EX14: 1.0166966 | EZ14: 8.2982699 | FD14: 16.193628 | FE14: 12.276482 | FH14: 0.00029823398
A15: 37288 | E15: 0.013482398 | F15: 5.5290028 | H15: 7.7958212 | I15: 12.776662 | P15: 14.010815 | Q15: 7.6805366 | V15: 155.13005 | X15: 362.98327 | Z15: 0.0064060405 | AB15: 0.0043029417 | AD15: 12.626659 | AG15: 0.013592505 | AH15: 1.5967689 | AI15: 0.0042659336 | AM15: 0.019920475 | AP15: 0.43522388 | AQ15: 0.016390737 | AR15: 1.9029922 | AT15: 6.1798994 | AU15: 0.31028115 | AV15: 11.954947 | AZ15: 22.565838 | BA15: 0.35481471 | BC15: 14.599872 | BD15: 14.646372 | BH15: 13.980888 | BI15: 2.4402009 | BJ15: 13.352483 | BK15: 5.9590271 | BP15: 0.16800391 | BQ15: 1.5501792 | BS15: 0.058279576 | BT15: 0.15850009 | BU15: 0.20293527 | BV15: 0.00066364641 | BY15: 11.872059 | BZ15: 3.0149907 | CA15: 13.981868 | CB15: 0.10075302 | CC15: 0.14644658 | CG15: 0.010366825 | CI15: 10.243928 | CN15: 12.716528 | CO15: 13.606099 | CP15: 1.4017881 | CQ15: 0.004275633 | CS15: 4.4621056 | CT15: 0.86455493 | CX15: 0.25794854 | CY15: 1.1462333 | CZ15: 0.24031528 | DH15: 14.248256 | DL15: 0.25197804 | DM15: 1.7909082 | DN15: 34.839257 | DT15: 4.5518756 | DU15: 13.948509 | DW15: 2.7813074 | DX15: 0.27602674 | DZ15: 3.1110336 | EA15: 0.017340595 | EF15: 19.334496 | EG15: 12.764695 | EH15: 0.57781177 | EJ15: 12.423708 | EM15: 5.6576655 | EN15: 5.8664145 | EO15: 4.8265825 | EQ15: 5.235628 | ER15: 11.386651 | EW15: 0.015670237 | EX15: 1.37412 | EZ15: 11.56179 | FD15: 21.891404 | FE15: 16.731404 | FH15: 0.00041239909
A16: 37316 | E16: 0.016584899 | F16: 6.8237297 | H16: 9.5559412 | I16: 15.770015 | P16: 17.306205 | V16: 196.92634 | X16: 450.54359 | Z16: 0.0079633363 | AB16: 0.0053302343 | AD16: 15.649119 | AG16: 0.017115182 | AH16: 1.9286231 | AI16: 0.0052674988 | AM16: 0.024359707 | AP16: 0.54295921 | AQ16: 0.020194251 | AR16: 2.358791 | AT16: 7.5945698 | AU16: 0.38399426 | AV16: 14.79468 | AZ16: 27.864992 | BA16: 0.43698351 | BC16: 18.0814 | BD16: 18.122141 | BH16: 17.262077 | BI16: 2.9243923 | BJ16: 16.865116 | BK16: 7.2963649 | BP16: 0.20523914 | BQ16: 1.8991286 | BS16: 0.071971267 | BT16: 0.19475549 | BU16: 0.24917227 | BV16: 0.00084459217 | BY16: 14.757229 | BZ16: 3.6986081 | CA16: 17.268265 | CB16: 0.12350078 | CC16: 0.18277034 | CG16: 0.012722506 | CI16: 12.668646 | CN16: 15.562917 | CO16: 16.775053 | CP16: 1.7023553 | CQ16: 0.0056364236 | CS16: 5.4979717 | CT16: 1.0496637 | CX16: 0.31727351 | CY16: 1.4138614 | CZ16: 0.28845458 | DH16: 17.708675 | DL16: 0.33587583 | DM16: 2.2342347 | DN16: 42.593141 | DT16: 5.6407537 | DU16: 17.257381 | DW16: 3.3599163 | DX16: 0.33860952 | DZ16: 3.8033913 | EA16: 0.021402071 | EF16: 23.840293 | EG16: 15.828283 | EH16: 0.71220976 | EJ16: 15.431311 | EM16: 7.0036067 | EN16: 7.1652009 | EO16: 5.9038235 | EQ16: 6.5991017 | ER16: 14.122608 | EW16: 0.019532226 | EX16: 1.6739639 | EZ16: 14.317284 | FD16: 26.860185 | FE16: 20.591019 | FH16: 0.00049766649
A17: 37347 | E17: 0.018987607 | F17: 7.857417 | H17: 11.041724 | I17: 18.418067 | P17: 20.139809 | V17: 230.90997 | X17: 523.29004 | Z17: 0.0097242009 | AB17: 0.0060623864 | AD17: 18.174442 | AG17: 0.02013765 | AH17: 2.211707 | AI17: 0.0061665096 | AM17: 0.02784272 | AP17: 0.65324351 | AQ17: 0.023567087 | AR17: 2.7515518 | AT17: 8.7512253 | AU17: 0.43095973 | AV17: 17.272087 | AZ17: 32.72623 | BA17: 0.49991215 | BC17: 21.123646 | BD17: 21.163304 | BH17: 20.060708 | BI17: 3.2945471 | BJ17: 19.772643 | BK17: 8.3787198 | BP17: 0.2397683 | BQ17: 2.1903826 | BS17: 0.085299826 | BT17: 0.23327339 | BU17: 0.28616518 | BV17: 0.0010173809 | BY17: 17.322641 | BZ17: 4.194907 | CA17: 20.141626 | CB17: 0.14231063 | CC17: 0.21107811 | CG17: 0.014756756 | CI17: 14.751078 | CN17: 18.098322 | CO17: 19.592363 | CP17: 1.9541509 | CQ17: 0.0069478836 | CS17: 6.3179075 | CT17: 1.1804232 | CX17: 0.3661228 | CY17: 1.6260778 | CZ17: 0.33675468 | DH17: 20.700172 | DL17: 0.36479314 | DM17: 2.6349501 | DN17: 48.893589 | DT17: 6.6528012 | DU17: 20.240879 | DW17: 3.9040416 | DX17: 0.39257835 | DZ17: 4.3703734 | EA17: 0.02489851 | EF17: 27.839045 | EG17: 18.668536 | EH17: 0.86721271 | EJ17: 18.197217 | EM17: 8.1109344 | EN17: 8.2174202 | EO17: 6.7718235 | EQ17: 7.6464007 | ER17: 16.596619 | EW17: 0.023160916 | EX17: 1.9299214 | EZ17: 17.288194 | FD17: 31.501101 | FE17: 23.817238 | FH17: 0.00057349328
A18: 37377 | E18: 0.021067605 | F18: 8.6478949 | H18: 12.217691 | I18: 20.895405 | P18: 22.817936 | Q18: 12.007486 | V18: 236.55438 | X18: 580.60231 | Z18: 0.010111826 | AB18: 0.0066391581 | AD18: 20.308402 | AG18: 0.021922614 | AH18: 2.4097975 | AI18: 0.0066404802 | AM18: 0.030353145 | AP18: 0.73340194 | AQ18: 0.026702112 | AR18: 3.1125819 | AT18: 9.5265623 | AU18: 0.46765087 | AV18: 18.967524 | AZ18: 37.108453 | BA18: 0.54770277 | BC18: 23.948846 | BD18: 23.969977 | BH18: 22.719332 | BI18: 3.5219234 | BJ18: 22.365279 | BK18: 9.1563926 | BP18: 0.26137608 | BQ18: 2.3938189 | BS18: 0.096430972 | BT18: 0.2699056 | BU18: 0.31420908 | BV18: 0.0011609701 | BY18: 19.712057 | BZ18: 4.5471643 | CA18: 22.843041 | CB18: 0.15429164 | CC18: 0.23977218 | CG18: 0.016862668 | CI18: 16.716794 | CN18: 20.402123 | CO18: 22.229564 | CP18: 2.1304975 | CQ18: 0.0077196836 | CS18: 6.9109957 | CT18: 1.3264779 | CX18: 0.40192289 | CY18: 1.7133949 | CZ18: 0.37154622 | DH18: 23.422902 | DL18: 0.41315476 | DM18: 3.0324963 | DN18: 53.56954 | DT18: 7.28124 | DU18: 23.048633 | DW18: 4.2950448 | DX18: 0.43520631 | DZ18: 4.7760107 | EA18: 0.028119887 | EF18: 31.550869 | EG18: 21.182501 | EH18: 1.0348609 | EJ18: 20.659741 | EM18: 8.8537258 | EN18: 8.9092029 | EO18: 7.4711648 | EQ18: 8.5727779 | ER18: 18.90996 | EW18: 0.026573469 | EX18: 2.1323726 | EZ18: 17.960461 | FD18: 34.915879 | FE18: 26.02784 | FH18: 0.00062740644
A19: 37408 | E19: 0.02347688 | F19: 9.6444173 | H19: 13.658295 | I19: 24.317454 | P19: 26.455437 | V19: 242.2547 | X19: 662.88247 | Z19: 0.011050038 | AB19: 0.0074580497 | AD19: 22.973637 | AG19: 0.023711845 | AH19: 2.6648285 | AI19: 0.0072719118 | AM19: 0.03377755 | AP19: 0.85599942 | AQ19: 0.031383229 | AR19: 3.6242652 | AT19: 10.566098 | AU19: 0.52237152 | AV19: 21.246301 | AZ19: 43.110819 | BA19: 0.62209472 | BC19: 27.785754 | BD19: 27.865541 | BH19: 26.414834 | BI19: 3.8535829 | BJ19: 25.95659 | BK19: 10.36487 | BP19: 0.28941395 | BQ19: 2.6868152 | BS19: 0.11201019 | BT19: 0.31151839 | BU19: 0.35387234 | BV19: 0.0013483414 | BY19: 22.952052 | BZ19: 5.0916406 | CA19: 26.581058 | CB19: 0.17257939 | CC19: 0.27352664 | CG19: 0.019453634 | CI19: 19.329532 | CN19: 23.639268 | CO19: 25.884725 | CP19: 2.3793982 | CQ19: 0.0085369973 | CS19: 7.7193206 | CT19: 1.4825492 | CX19: 0.45051699 | CY19: 1.8723576 | CZ19: 0.39429424 | DH19: 27.14198 | DL19: 0.4760065 | DM19: 3.5753819 | DN19: 59.563013 | DT19: 8.1365455 | DU19: 26.88419 | DW19: 4.8638835 | DX19: 0.48581065 | DZ19: 5.3185649 | EA19: 0.032427058 | EF19: 36.548282 | EG19: 24.570811 | EH19: 1.1702658 | EJ19: 24.021241 | EM19: 9.874118 | EN19: 9.9020497 | EO19: 8.6308819 | EQ19: 10.070351 | ER19: 21.75495 | EW19: 0.030746387 | EX19: 2.4170528 | EZ19: 18.403566 | FD19: 39.676472 | FE19: 29.06015 | FH19: 0.00069806386
A20: 37438 | E20: 0.022353032 | F20: 9.0418576 | H20: 12.823782 | I20: 23.643106 | P20: 25.831546 | V20: 212.45463 | X20: 645.95473 | Z20: 0.010149589 | AB20: 0.0070449699 | AD20: 21.459589 | AG20: 0.021597169 | AH20: 2.479961 | AI20: 0.0064285274 | AM20: 0.031830621 | AP20: 0.85391791 | AQ20: 0.030205316 | AR20: 3.5193659 | AT20: 9.8981533 | AU20: 0.49149723 | AV20: 19.897977 | AZ20: 41.824375 | BA20: 0.59277001 | BC20: 26.991811 | BD20: 27.118702 | BH20: 25.735858 | BI20: 3.5743821 | BJ20: 24.826628 | BK20: 9.7245334 | BP20: 0.26442177 | BQ20: 2.5274291 | BS20: 0.10716102 | BT20: 0.30469449 | BU20: 0.33647341 | BV20: 0.0012392483 | BY20: 22.238646 | BZ20: 5.0273815 | CA20: 25.912231 | CB20: 0.16409525 | CC20: 0.26724972 | CG20: 0.018768455 | CI20: 18.735335 | CN20: 22.942291 | CO20: 25.013115 | CP20: 2.230285 | CQ20: 0.0078916045 | CS20: 7.2342298 | CT20: 1.3878584 | CX20: 0.42925496 | CY20: 1.7489576 | CZ20: 0.36571111 | DH20: 26.378506 | DL20: 0.45652621 | DM20: 3.4751671 | DN20: 56.046457 | DT20: 7.418384 | DU20: 26.208522 | DW20: 4.6393665 | DX20: 0.45692579 | DZ20: 4.9996614 | EA20: 0.031871769 | EF20: 35.470476 | EG20: 24.040009 | EH20: 1.1138489 | EJ20: 23.215312 | EM20: 9.2431317 | EN20: 9.335417 | EO20: 8.1149412 | EQ20: 9.621374 | ER20: 21.173373 | EW20: 0.029353957 | EX20: 2.2744733 | EZ20: 16.155348 | FD20: 38.765444 | FE20: 27.264254 | FH20: 0.00065354255
A21: 37469 | E21: 0.023842895 | F21: 9.3203747 | H21: 13.305163 | I21: 24.135551 | P21: 26.30924 | Q21: 13.053802 | V21: 208.60936 | X21: 653.85156 | Z21: 0.010078839 | AB21: 0.007301915 | AD21: 21.963021 | AG21: 0.022223174 | AH21: 2.5717807 | AI21: 0.0063000591 | AM21: 0.033025911 | AP21: 0.8387459 | AQ21: 0.030755111 | AR21: 3.5899296 | AT21: 10.298269 | AU21: 0.51269499 | AV21: 20.662602 | AZ21: 42.413805 | BA21: 0.63209736 | BC21: 27.501422 | BD21: 27.694112 | BH21: 26.192227 | BI21: 3.7288203 | BJ21: 25.351979 | BK21: 10.05556 | BP21: 0.27002519 | BQ21: 2.6164006 | BS21: 0.10950275 | BT21: 0.31137982 | BU21: 0.3513303 | BV21: 0.0012941629 | BY21: 22.791998 | BZ21: 5.2330623 | CA21: 26.445868 | CB21: 0.16970253 | CC21: 0.27497434 | CG21: 0.019348518 | CI21: 18.943227 | CN21: 23.243099 | CO21: 25.737698 | CP21: 2.3054899 | CQ21: 0.0081040305 | CS21: 7.4723113 | CT21: 1.423883 | CX21: 0.44825973 | CY21: 1.8099683 | CZ21: 0.37912918 | DH21: 26.966637 | DL21: 0.4648649 | DM21: 3.5173003 | DN21: 57.94701 | DT21: 7.5293911 | DU21: 26.723033 | DW21: 4.8192591 | DX21: 0.47221763 | DZ21: 5.1797619 | EA21: 0.032801811 | EF21: 36.340389 | EG21: 24.513911 | EH21: 1.1082489 | EJ21: 23.721364 | EM21: 9.5294661 | EN21: 9.8149271 | EO21: 8.7625115 | EQ21: 9.8244902 | ER21: 21.537261 | EW21: 0.02948753 | EX21: 2.3704807 | EZ21: 17.233901 | FD21: 39.739101 | FE21: 28.282704 | FH21: 0.00067523286
A22: 37500 | E22: 0.023923263 | F22: 8.8625674 | H22: 12.768582 | I22: 23.108938 | P22: 25.260461 | V22: 186.62974 | X22: 630.61947 | Z22: 0.0085282301 | AB22: 0.0069334929 | AD22: 20.858534 | AG22: 0.020664802 | AH22: 2.4792365 | AI22: 0.0058067358 | AM22: 0.031374583 | AP22: 0.81475956 | AQ22: 0.029473875 | AR22: 3.4544502 | AT22: 9.8511939 | AU22: 0.49624809 | AV22: 19.836209 | AZ22: 40.641672 | BA22: 0.61188739 | BC22: 26.427714 | BD22: 26.564062 | BH22: 25.078132 | BI22: 3.608586 | BJ22: 24.731934 | BK22: 9.7078347 | BP22: 0.25854547 | BQ22: 2.4875722 | BS22: 0.10611706 | BT22: 0.29390327 | BU22: 0.33702637 | BV22: 0.0012366656 | BY22: 21.950337 | BZ22: 4.9052554 | CA22: 25.363506 | CB22: 0.16387617 | CC22: 0.25949602 | CG22: 0.01838524 | CI22: 18.277103 | CN22: 22.127505 | CO22: 24.715418 | CP22: 2.1921312 | CQ22: 0.0077703574 | CS22: 7.1392314 | CT22: 1.3322295 | CX22: 0.43079349 | CY22: 1.7005041 | CZ22: 0.36530132 | DH22: 26.100772 | DL22: 0.44772544 | DM22: 3.419362 | DN22: 55.198728 | DT22: 7.2573791 | DU22: 25.571344 | DW22: 4.6244134 | DX22: 0.45155048 | DZ22: 4.949126 | EA22: 0.031730055 | EF22: 34.890492 | EG22: 23.65013 | EH22: 1.0659594 | EJ22: 22.797358 | EM22: 9.0907088 | EN22: 9.350058 | EO22: 8.2257698 | EQ22: 9.562406 | ER22: 20.645421 | EW22: 0.027863372 | EX22: 2.2481284 | EZ22: 16.910036 | FD22: 38.488094 | FE22: 27.040682 | FH22: 0.00064537829
A23: 37530 | E23: 0.023805007 | F23: 9.3430452 | H23: 13.345133 | I23: 24.147369 | P23: 26.315305 | V23: 173.09943 | X23: 664.57234 | Z23: 0.0088310508 | AB23: 0.0072107309 | AD23: 21.784818 | AG23: 0.021283945 | AH23: 2.5900407 | AI23: 0.0059236533 | AM23: 0.032640003 | AP23: 0.83400583 | AQ23: 0.03092506 | AR23: 3.6090467 | AT23: 10.265889 | AU23: 0.53243846 | AV23: 20.814917 | AZ23: 42.62033 | BA23: 0.64174207 | BC23: 27.633872 | BD23: 27.748201 | BH23: 26.125649 | BI23: 3.7995676 | BJ23: 25.927803 | BK23: 10.12277 | BP23: 0.25326917 | BQ23: 2.5944069 | BS23: 0.1114004 | BT23: 0.30744198 | BU23: 0.35338172 | BV23: 0.0012634073 | BY23: 22.992985 | BZ23: 5.1177614 | CA23: 26.519286 | CB23: 0.16898394 | CC23: 0.26237768 | CG23: 0.018612461 | CI23: 19.207663 | CN23: 23.22638 | CO23: 25.87076 | CP23: 2.2898572 | CQ23: 0.0081123316 | CS23: 7.436255 | CT23: 1.4104689 | CX23: 0.45345883 | CY23: 1.7713275 | CZ23: 0.38423227 | DH23: 27.155048 | DL23: 0.46886624 | DM23: 3.5906643 | DN23: 57.434397 | DP23: 22.934344 | DT23: 7.6373569 | DU23: 26.841477 | DW23: 4.8828811 | DX23: 0.47481636 | DZ23: 5.1600219 | EA23: 0.032700675 | EF23: 36.388898 | EG23: 24.779107 | EH23: 1.1571382 | EJ23: 24.012007 | EM23: 9.4996668 | EN23: 9.5481782 | EO23: 8.3583972 | EQ23: 10.079982 | ER23: 21.643651 | EW23: 0.02921006 | EX23: 2.3199412 | EZ23: 18.165224 | FD23: 40.248552 | FE23: 28.239688 | FH23: 0.00067410722
A24: 37561 | E24: 0.022274437 | F24: 8.6281883 | H24: 12.444568 | I24: 22.804508 | P24: 24.856671 | Q24: 12.129268 | V24: 175.76381 | X24: 629.23103 | Z24: 0.0085229589 | AB24: 0.0066886771 | AD24: 20.318722 | AG24: 0.020606743 | AH24: 2.3963786 | AI24: 0.0057334183 | AM24: 0.030273788 | AP24: 0.78448864 | AQ24: 0.029439861 | AR24: 3.3795814 | AT24: 9.4985268 | AU24: 0.49548237 | AV24: 19.412088 | AZ24: 40.225534 | BA24: 0.59913101 | BC24: 26.039746 | BD24: 26.230072 | BH24: 24.612672 | BI24: 3.5060596 | BJ24: 24.514537 | BK24: 9.3812317 | BP24: 0.20496039 | BQ24: 2.4073851 | BS24: 0.10775638 | BT24: 0.2895097 | BU24: 0.32859785 | BV24: 0.0012085955 | BY24: 21.735019 | BZ24: 4.8126151 | CA24: 25.152233 | CB24: 0.15717185 | CC24: 0.24561027 | CG24: 0.017670543 | CI24: 18.189013 | CN24: 21.980876 | CO24: 24.477001 | CP24: 2.1122349 | CQ24: 0.007627467 | CS24: 6.9072381 | CT24: 1.3045962 | CX24: 0.42155636 | CY24: 1.6364593 | CZ24: 0.3531801 | DH24: 25.593772 | DL24: 0.44397865 | DM24: 3.416827 | DN24: 53.463764 | DP24: 21.262343 | DT24: 7.3657822 | DU24: 25.556917 | DW24: 4.5960108 | DX24: 0.44521545 | DZ24: 4.7839251 | EA24: 0.031044245 | EF24: 34.398029 | EG24: 23.42342 | EH24: 1.1248228 | EJ24: 22.733254 | EM24: 8.7633332 | EN24: 8.8432364 | EO24: 7.8041396 | EQ24: 9.413854 | ER24: 20.246822 | EW24: 0.027571111 | EX24: 2.1517355 | EZ24: 17.824751 | FD24: 37.382947 | FE24: 26.154753 | FH24: 0.00062543711
A25: 37591 | E25: 0.023144988 | F25: 8.8643933 | H25: 12.778756 | I25: 23.875999 | P25: 25.963529 | V25: 181.72559 | X25: 663.82305 | Z25: 0.0086828907 | AB25: 0.0068556819 | AD25: 20.939791 | AG25: 0.021289049 | AH25: 2.4676658 | AI25: 0.0057179007 | AM25: 0.031039194 | AP25: 0.80809654 | AQ25: 0.031068155 | AR25: 3.5687391 | AT25: 9.7800304 | AU25: 0.51793972 | AV25: 19.998499 | AZ25: 41.929702 | BA25: 0.62096306 | BC25: 27.182904 | BD25: 27.430246 | BH25: 25.928443 | BI25: 3.6404547 | BJ25: 25.770682 | BK25: 9.6327208 | BP25: 0.20800132 | BQ25: 2.4770751 | BS25: 0.11351888 | BT25: 0.30653416 | BU25: 0.33556279 | BV25: 0.001276028 | BY25: 22.855798 | BZ25: 4.9266616 | CA25: 26.280823 | CB25: 0.16053076 | CC25: 0.25273652 | CG25: 0.018270903 | CI25: 19.026031 | CN25: 23.029436 | CO25: 25.524612 | CP25: 2.1695559 | CQ25: 0.0078722715 | CS25: 7.1052146 | CT25: 1.339986 | CX25: 0.43442696 | CY25: 1.6882611 | CZ25: 0.36829428 | DH25: 26.627827 | DL25: 0.46203448 | DM25: 3.6071485 | DN25: 54.945575 | DP25: 21.786011 | DT25: 7.6550863 | DU25: 26.718264 | DW25: 4.773382 | DX25: 0.46371332 | DZ25: 4.9165569 | EA25: 0.032426684 | EF25: 36.174645 | EG25: 24.59547 | EH25: 1.2867583 | EJ25: 23.812453 | EM25: 9.043306 | EN25: 9.1608065 | EO25: 8.1143277 | EQ25: 9.930338 | ER25: 21.276233 | EW25: 0.029020404 | EX25: 2.225168 | EZ25: 18.807152 | FD25: 39.087933 | FE25: 26.793322 | FH25: 0.00064321361
A26: 37622 | E26: 0.020944079 | F26: 7.9704362 | H26: 11.510012 | I26: 22.41959 | P26: 24.441396 | V26: 176.05573 | X26: 627.27507 | Z26: 0.0081314454 | AB26: 0.00615616 | AD26: 19.206335 | AG26: 0.018601952 | AH26: 2.2415949 | AI26: 0.0050219683 | AM26: 0.027850042 | AP26: 0.75446281 | AQ26: 0.029203039 | AR26: 3.3417129 | AT26: 8.787802 | AU26: 0.48065007 | AV26: 18.414522 | AZ26: 39.728826 | BA26: 0.56706811 | BC26: 25.508046 | BD26: 25.757471 | BH26: 24.300638 | BI26: 3.4761949 | BJ26: 24.029316 | BK26: 8.6685518 | BP26: 0.18039858 | BQ26: 2.2334692 | BS26: 0.10589199 | BT26: 0.29040719 | BU26: 0.30216835 | BV26: 0.0011602307 | BY26: 21.359253 | BZ26: 4.3019663 | CA26: 24.733438 | CB26: 0.13993274 | CC26: 0.2332745 | CG26: 0.016937455 | CI26: 17.994921 | CN26: 21.574849 | CO26: 23.74207 | CP26: 1.9509121 | CQ26: 0.0073101763 | CS26: 6.3960264 | CT26: 1.1968657 | CX26: 0.40341786 | CY26: 1.4685254 | CZ26: 0.3361296 | DH26: 25.042414 | DL26: 0.4342696 | DM26: 3.439682 | DN26: 49.216917 | DP26: 19.61297 | DT26: 7.0462577 | DU26: 25.077858 | DW26: 4.3705904 | DX26: 0.42691893 | DZ26: 4.4173126 | EA26: 0.030210377 | EF26: 35.691219 | EG26: 23.276346 | EH26: 1.1998913 | EJ26: 22.225643 | EM26: 8.1480603 | EN26: 8.2387353 | EO26: 7.4412645 | EQ26: 9.2707785 | ER26: 20.041187 | EW26: 0.027225676 | EX26: 1.9966021 | EZ26: 16.581867 | FD26: 35.594153 | FE26: 24.179092 | FH26: 0.00058170259
A27: 37653 | E27: 0.021027412 | F27: 8.0604542 | H27: 11.607265 | I27: 22.660041 | P27: 24.851286 | Q27: 11.207164 | V27: 170.47646 | X27: 634.32817 | Z27: 0.0078595002 | AB27: 0.0061636716 | AD27: 19.637225 | AG27: 0.018100087 | AH27: 2.2517069 | AI27: 0.0049894088 | AM27: 0.027708785 | AP27: 0.76024874 | AQ27: 0.029683189 | AR27: 3.4088096 | AT27: 8.7474501 | AU27: 0.48113477 | AV27: 18.473748 | AZ27: 40.272466 | BA27: 0.56984302 | BC27: 25.927106 | BD27: 26.189552 | BH27: 24.675675 | BI27: 3.7610874 | BJ27: 24.28736 | BK27: 8.6325963 | BP27: 0.16589157 | BQ27: 2.2428304 | BS27: 0.10551195 | BT27: 0.29551996 | BU27: 0.30268959 | BV27: 0.0011563662 | BY27: 21.754601 | BZ27: 4.2747293 | CA27: 25.016425 | CB27: 0.13480973 | CC27: 0.23033333 | CG27: 0.016785951 | CI27: 18.228551 | CN27: 21.729703 | CO27: 24.301284 | CP27: 1.9325968 | CQ27: 0.0073835502 | CS27: 6.3801639 | CT27: 1.1827769 | CX27: 0.41712355 | CY27: 1.4197699 | CZ27: 0.33571332 | DH27: 25.442613 | DL27: 0.43436389 | DM27: 3.384193 | DN27: 48.851987 | DP27: 19.526777 | DT27: 6.9663601 | DU27: 25.318746 | DW27: 4.4620408 | DX27: 0.43351611 | DZ27: 4.393431 | EA27: 0.030438421 | EF27: 36.257669 | EG27: 23.621949 | EH27: 1.250846 | EJ27: 22.490336 | EM27: 8.1535476 | EN27: 8.1619623 | EO27: 7.3356449 | EQ27: 9.4739487 | ER27: 20.183038 | EW27: 0.027419239 | EX27: 1.9956505 | EZ27: 17.092164 | FD27: 35.383 | FE27: 24.258313 | FH27: 0.00059246325
A28: 37681 | E28: 0.020082485 | F28: 7.5674234 | H28: 10.952907 | I28: 21.484823 | P28: 23.560346 | V28: 169.44287 | X28: 601.84285 | Z28: 0.0075674861 | AB28: 0.0057983573 | AD28: 19.020618 | AG28: 0.017303552 | AH28: 2.1095356 | AI28: 0.0047400232 | AM28: 0.026055437 | AP28: 0.7151534 | AQ28: 0.028108357 | AR28: 3.2477702 | AT28: 8.2592644 | AU28: 0.3698401 | AV28: 17.509868 | AZ28: 38.163818 | BA28: 0.54424199 | BC28: 24.580265 | BD28: 24.860917 | BH28: 23.355621 | BI28: 3.6131907 | BJ28: 23.483966 | BK28: 8.1453949 | BP28: 0.16851379 | BQ28: 2.1128557 | BS28: 0.10040745 | BT28: 0.28010915 | BU28: 0.28758024 | BV28: 0.0010839087 | BY28: 20.714979 | BZ28: 4.1063071 | CA28: 23.730059 | CB28: 0.12363621 | CC28: 0.21911594 | CG28: 0.015473304 | CI28: 17.327183 | CN28: 20.596015 | CO28: 23.040338 | CP28: 1.8185188 | CQ28: 0.0069024748 | CS28: 6.0018339 | CT28: 1.1202983 | CX28: 0.39822569 | CY28: 1.3439994 | CZ28: 0.31523119 | DH28: 24.284193 | DL28: 0.4108722 | DM28: 3.0522009 | DN28: 46.13694 | DP28: 18.422592 | DT28: 6.3527379 | DU28: 23.954343 | DW28: 4.218098 | DX28: 0.41613949 | DZ28: 4.1408579 | EA28: 0.028667083 | EF28: 34.426883 | EG28: 22.49223 | EH28: 1.2233533 | EJ28: 21.410873 | EM28: 7.7021083 | EN28: 7.6239191 | EO28: 6.8683691 | EQ28: 8.9223763 | ER28: 19.102531 | EW28: 0.025879685 | EX28: 1.8895398 | EZ28: 16.079849 | FD28: 32.925002 | FE28: 23.001089 | FH28: 0.00055472901
A29: 37712 | E29: 0.019994365 | F29: 7.2696891 | H29: 10.550164 | I29: 20.797746 | P29: 22.771452 | V29: 182.52707 | X29: 584.53632 | Z29: 0.0073097898 | AB29: 0.0055662036 | AD29: 18.45325 | AG29: 0.017268041 | AH29: 2.032215 | AI29: 0.0046793078 | AM29: 0.025181514 | AP29: 0.69770448 | AQ29: 0.027451923 | AR29: 3.1429427 | AT29: 7.921964 | AU29: 0.34213937 | AV29: 17.066085 | AZ29: 36.921286 | BA29: 0.53243416 | BC29: 23.787381 | BD29: 24.054431 | BH29: 22.554421 | BI29: 3.4688936 | BJ29: 22.775367 | BK29: 7.8576155 | BP29: 0.17087493 | BQ29: 2.0413819 | BS29: 0.097460259 | BT29: 0.27420076 | BU29: 0.28262165 | BV29: 0.0010651994 | BY29: 20.128516 | BZ29: 4.0973676 | CA29: 23.049828 | CB29: 0.11709274 | CC29: 0.20993969 | CG29: 0.014903923 | CI29: 16.841957 | CN29: 19.965093 | CO29: 22.3109 | CP29: 1.7559235 | CQ29: 0.0065016979 | CS29: 5.8045147 | CT29: 1.0724379 | CX29: 0.38894589 | CY29: 1.3374594 | CZ29: 0.30283638 | DH29: 23.552644 | DL29: 0.40438316 | DM29: 2.9399224 | DN29: 44.4894 | DP29: 17.782724 | DT29: 6.2090416 | DU29: 23.388708 | DW29: 4.0458432 | DX29: 0.40892402 | DZ29: 3.9929676 | EA29: 0.027595067 | EF29: 33.414476 | EG29: 21.901878 | EH29: 1.2316353 | EJ29: 20.914554 | EM29: 7.4137207 | EN29: 7.351738 | EO29: 5.6958812 | EQ29: 8.6803724 | ER29: 18.233091 | EW29: 0.025317027 | EX29: 1.8350774 | EZ29: 16.044813 | FD29: 31.77432 | FE29: 22.153984 | FH29: 0.00053459541
A30: 37742 | E30: 0.01926858 | F30: 6.9560175 | H30: 10.056127 | I30: 21.204554 | P30: 23.152916 | Q30: 9.7581365 | V30: 185.03419 | X30: 594.56875 | Z30: 0.0071427785 | AB30: 0.0052659609 | AD30: 18.581292 | AG30: 0.016769127 | AH30: 1.9270838 | AI30: 0.0045962363 | AM30: 0.023982649 | AP30: 0.71696063 | AQ30: 0.028165343 | AR30: 3.194603 | AT30: 7.5581238 | AU30: 0.30731284 | AV30: 16.325711 | AZ30: 37.5272 | BA30: 0.50982979 | BC30: 24.222767 | BD30: 24.495873 | BH30: 22.944145 | BI30: 3.3366078 | BJ30: 23.317583 | BK30: 7.5285465 | BP30: 0.17126885 | BQ30: 1.9467749 | BS30: 0.099484523 | BT30: 0.27622722 | BU30: 0.27212089 | BV30: 0.0010673501 | BY30: 20.493165 | BZ30: 4.0187248 | CA30: 23.558713 | CB30: 0.10608007 | CC30: 0.20521392 | CG30: 0.014597729 | CI30: 17.20112 | CN30: 20.325005 | CO30: 22.755299 | CP30: 1.6752998 | CQ30: 0.0064719815 | CS30: 5.5482066 | CT30: 1.0451431 | CX30: 0.37284093 | CY30: 1.3204718 | CZ30: 0.29851939 | DH30: 23.995898 | DL30: 0.41233802 | DM30: 2.9638085 | DN30: 42.742386 | DP30: 16.947307 | DT30: 6.2658036 | DU30: 23.980491 | DW30: 4.0255481 | DX30: 0.39734391 | DZ30: 3.8168756 | EA30: 0.027967545 | EF30: 34.097138 | EG30: 22.437836 | EH30: 1.1810237 | EJ30: 21.303881 | EM30: 7.1234098 | EN30: 7.0697122 | EO30: 6.4726495 | EQ30: 8.840223 | ER30: 18.299309 | EW30: 0.026386934 | EX30: 1.7569815 | EZ30: 16.79353 | FD30: 31.27965 | FE30: 21.120905 | FH30: 0.00050913234
A31: 37773 | E31: 0.019843168 | F31: 7.0884152 | H31: 10.270787 | I31: 21.823447 | P31: 23.852351 | V31: 193.21469 | X31: 595.64514 | Z31: 0.0072802699 | AB31: 0.005331223 | AD31: 19.406622 | AG31: 0.016971253 | AH31: 1.9422073 | AI31: 0.0047391892 | AM31: 0.024414748 | AP31: 0.73569501 | AQ31: 0.029027367 | AR31: 3.2866169 | AT31: 7.7062696 | AU31: 0.29234885 | AV31: 16.619321 | AZ31: 38.370394 | BA31: 0.53061039 | BC31: 24.854314 | BD31: 25.210991 | BH31: 23.648483 | BI31: 3.4172189 | BJ31: 23.90882 | BK31: 7.6761427 | BP31: 0.17867418 | BQ31: 1.984759 | BS31: 0.096483165 | BT31: 0.27760085 | BU31: 0.28146467 | BV31: 0.0011134058 | BY31: 21.081322 | BZ31: 4.1638415 | CA31: 24.220396 | CB31: 0.11380226 | CC31: 0.20693321 | CG31: 0.014922365 | CI31: 17.791898 | CN31: 20.897114 | CO31: 23.375223 | CP31: 1.7055457 | CQ31: 0.0066480867 | CS31: 5.6543473 | CT31: 1.0626323 | CX31: 0.37043184 | CY31: 1.3167054 | CZ31: 0.30985853 | DH31: 24.53615 | DL31: 0.42271292 | DM31: 2.9290642 | DN31: 43.60188 | DP31: 17.305383 | DT31: 6.3044899 | DU31: 24.632599 | DW31: 4.1273767 | DX31: 0.41444901 | DZ31: 3.8975885 | EA31: 0.02868414 | EF31: 35.17535 | EG31: 23.108831 | EH31: 1.170568 | EJ31: 21.898895 | EM31: 7.2503867 | EN31: 7.2837779 | EO31: 6.784904 | EQ31: 9.0940233 | ER31: 18.52338 | EW31: 0.027153674 | EX31: 1.7989917 | EZ31: 18.035648 | FD31: 32.607366 | FE31: 21.569102 | FH31: 0.00051754472
A32: 37803 | E32: 0.018895337 | F32: 6.9223349 | H32: 9.9759255 | I32: 20.604649 | P32: 22.583856 | V32: 187.86515 | X32: 567.93919 | Z32: 0.0069929148 | AB32: 0.0052164539 | AD32: 18.429172 | AG32: 0.016623242 | AH32: 1.8729921 | AI32: 0.0045354759 | AM32: 0.023644855 | AP32: 0.68598752 | AQ32: 0.027112621 | AR32: 3.0850514 | AT32: 7.6610726 | AU32: 0.24518878 | AV32: 16.113237 | AZ32: 36.318159 | BA32: 0.52008744 | BC32: 23.365616 | BD32: 23.800105 | BH32: 22.398806 | BI32: 3.3182899 | BJ32: 22.159044 | BK32: 7.4472708 | BP32: 0.17091749 | BQ32: 1.9216769 | BS32: 0.090339551 | BT32: 0.25804211 | BU32: 0.2779009 | BV32: 0.00106203 | BY32: 19.781686 | BZ32: 4.0194583 | CA32: 22.9269 | CB32: 0.11199417 | CC32: 0.19943186 | CG32: 0.014602274 | CI32: 16.756403 | CN32: 19.591545 | CO32: 21.900519 | CP32: 1.6378813 | CQ32: 0.0062659511 | CS32: 5.4908601 | CT32: 1.03295 | CX32: 0.34468589 | CY32: 1.2843864 | CZ32: 0.30562986 | DH32: 23.207501 | DL32: 0.39881627 | DM32: 2.7163794 | DN32: 42.132408 | DP32: 16.789586 | DT32: 5.9167703 | DU32: 23.210605 | DW32: 4.040837 | DX32: 0.40616721 | DZ32: 3.800679 | EA32: 0.027406115 | EF32: 33.214043 | EG32: 21.943279 | EH32: 1.181807 | EJ32: 20.565616 | EM32: 7.0114993 | EN32: 7.0875041 | EO32: 6.9057301 | EQ32: 8.5022755 | ER32: 17.28628 | EW32: 0.025214573 | EX32: 1.7515275 | EZ32: 17.522116 | FD32: 30.882235 | FE32: 20.928098 | FH32: 0.00049933915
A33: 37834 | E33: 0.02007762 | F33: 7.4274219 | H33: 10.675609 | I33: 21.674914 | P33: 23.754876 | Q33: 10.399175 | V33: 193.6217 | X33: 600.09333 | Z33: 0.0073267979 | AB33: 0.0055643681 | AD33: 19.593561 | AG33: 0.017765048 | AH33: 2.0199278 | AI33: 0.0048583362 | AM33: 0.025219393 | AP33: 0.70838766 | AQ33: 0.028534063 | AR33: 3.2370852 | AT33: 8.2514515 | AU33: 0.27628977 | AV33: 17.266696 | AZ33: 38.096604 | BA33: 0.56260143 | BC33: 24.542587 | BD33: 25.024762 | BH33: 23.495641 | BI33: 3.6294136 | BJ33: 23.234622 | BK33: 7.992208 | BP33: 0.19139942 | BQ33: 2.0670332 | BS33: 0.09621538 | BT33: 0.26682172 | BU33: 0.29833714 | BV33: 0.0011251031 | BY33: 20.868769 | BZ33: 4.1608036 | CA33: 24.108683 | CB33: 0.12161702 | CC33: 0.21377379 | CG33: 0.015751058 | CI33: 17.387024 | CN33: 20.402404 | CO33: 23.278174 | CP33: 1.7543149 | CQ33: 0.0066340445 | CS33: 5.8746721 | CT33: 1.1028023 | CX33: 0.37296518 | CY33: 1.3424215 | CZ33: 0.33077475 | DH33: 24.4209 | DL33: 0.41901248 | DM33: 2.869104 | DN33: 45.166265 | DP33: 17.998348 | DT33: 6.2935774 | DU33: 24.359034 | DW33: 4.2500505 | DX33: 0.43336145 | DZ33: 4.0620235 | EA33: 0.029039386 | EF33: 35.195697 | EG33: 22.934925 | EH33: 1.2943261 | EJ33: 21.671847 | EM33: 7.4708094 | EN33: 7.612582 | EO33: 7.4013183 | EQ33: 8.8636441 | ER33: 18.230339 | EW33: 0.025875868 | EX33: 1.8738679 | EZ33: 18.994125 | FD33: 32.533647 | FE33: 22.497754 | FH33: 0.00053391068
A34: 37865 | E34: 0.021370974 | F34: 7.2216187 | H34: 10.435005 | I34: 21.295786 | P34: 23.362219 | V34: 195.12263 | X34: 593.32246 | Z34: 0.0070435645 | AB34: 0.0054108967 | AD34: 19.564012 | AG34: 0.018052283 | AH34: 1.9897683 | AI34: 0.0047845909 | AM34: 0.024381292 | AP34: 0.69044068 | AQ34: 0.027624338 | AR34: 3.1956079 | AT34: 8.0304219 | AU34: 0.28892767 | AV34: 16.940317 | AZ34: 37.446896 | BA34: 0.54682182 | BC34: 24.1667 | BD34: 24.633672 | BH34: 23.015542 | BI34: 3.4853276 | BJ34: 23.219331 | BK34: 7.7987868 | BP34: 0.1913826 | BQ34: 2.0119884 | BS34: 0.096300293 | BT34: 0.26371075 | BU34: 0.29094648 | BV34: 0.0011091766 | BY34: 20.494193 | BZ34: 4.0846375 | CA34: 23.681049 | CB34: 0.11929543 | CC34: 0.21487783 | CG34: 0.015633347 | CI34: 17.129032 | CN34: 19.934376 | CO34: 22.929739 | CP34: 1.7194952 | CQ34: 0.0065482176 | CS34: 5.7293785 | CT34: 1.0637387 | CX34: 0.36620847 | CY34: 1.2912972 | CZ34: 0.33564026 | DH34: 24.183728 | DL34: 0.41063131 | DM34: 2.8451494 | DN34: 44.142356 | DP34: 17.484679 | DT34: 6.0571554 | DU34: 23.933211 | DW34: 4.1703764 | DX34: 0.41984478 | DZ34: 3.9619823 | EA34: 0.028868147 | EF34: 34.718208 | EG34: 22.555224 | EH34: 1.2660668 | EJ34: 21.315993 | EM34: 7.247444 | EN34: 7.3810376 | EO34: 6.8455039 | EQ34: 8.9164326 | ER34: 17.856218 | EW34: 0.025109068 | EX34: 1.8225891 | EZ34: 19.09032 | FD34: 32.070785 | FE34: 21.970521 | FH34: 0.00051962633
A35: 37895 | E35: 0.022252219 | F35: 7.2554202 | H35: 10.460071 | I35: 22.203518 | P35: 24.325109 | V35: 200.39781 | X35: 624.98108 | Z35: 0.0074273055 | AB35: 0.0054308226 | AD35: 20.169679 | AG35: 0.018892161 | AH35: 2.0129437 | AI35: 0.0047398531 | AM35: 0.024523081 | AP35: 0.73005644 | AQ35: 0.028665263 | AR35: 3.3300669 | AT35: 8.0426074 | AU35: 0.27202011 | AV35: 16.984486 | AZ35: 39.177313 | BA35: 0.5452489 | BC35: 25.217909 | BD35: 25.786677 | BH35: 24.041813 | BI35: 3.6361821 | BJ35: 24.341868 | BK35: 7.824691 | BP35: 0.19460032 | BQ35: 2.018771 | BS35: 0.10138472 | BT35: 0.27595472 | BU35: 0.29701611 | BV35: 0.0011174878 | BY35: 21.408036 | BZ35: 4.1106537 | CA35: 24.757172 | CB35: 0.12025076 | CC35: 0.22646288 | CG35: 0.015686164 | CI35: 18.047896 | CN35: 20.854278 | CO35: 23.937593 | CP35: 1.7337103 | CQ35: 0.0066427861 | CS35: 5.7496717 | CT35: 1.0831651 | CX35: 0.37348692 | CY35: 1.2708913 | CZ35: 0.35199011 | DH35: 25.192346 | DL35: 0.43032222 | DM35: 2.9618969 | DN35: 44.256356 | DP35: 17.477298 | DT35: 6.1990512 | DU35: 25.136249 | DW35: 4.3270436 | DX35: 0.43120435 | DZ35: 3.9641901 | EA35: 0.030043618 | EF35: 36.296628 | EG35: 23.636776 | EH35: 1.3244251 | EJ35: 22.416579 | EM35: 7.299114 | EN35: 7.4438008 | EO35: 6.894804 | EQ35: 9.3855648 | ER35: 18.743148 | EW35: 0.026216593 | EX35: 1.8361193 | EZ35: 18.56749 | FD35: 33.516424 | FE35: 22.003473 | FH35: 0.00051872445
A36: 37926 | E36: 0.022363764 | F36: 7.1544324 | H36: 10.253226 | I36: 21.797324 | P36: 23.87974 | Q36: 10.020076 | V36: 193.32616 | X36: 623.54423 | Z36: 0.0073981608 | AB36: 0.005311335 | AD36: 19.943925 | AG36: 0.01904668 | AH36: 1.9903849 | AI36: 0.0047082332 | AM36: 0.024141806 | AP36: 0.71874062 | AQ36: 0.028052976 | AR36: 3.2598468 | AT36: 7.8563511 | AU36: 0.24722024 | AV36: 16.683616 | AZ36: 38.328811 | BA36: 0.52261233 | BC36: 24.686479 | BD36: 25.297015 | BH36: 23.505 | BI36: 3.5710324 | BJ36: 23.896676 | BK36: 7.6661586 | BP36: 0.18999526 | BQ36: 1.9808217 | BS36: 0.098388433 | BT36: 0.27208516 | BU36: 0.29049838 | BV36: 0.0010950624 | BY36: 20.976853 | BZ36: 3.9779163 | CA36: 24.317848 | CB36: 0.11880459 | CC36: 0.22134771 | CG36: 0.015088968 | CI36: 17.778323 | CN36: 20.531139 | CO36: 23.512648 | CP36: 1.6907765 | CQ36: 0.0064518293 | CS36: 5.6344157 | CT36: 1.0289864 | CX36: 0.37009803 | CY36: 1.2608628 | CZ36: 0.34617667 | DH36: 24.622547 | DL36: 0.42360608 | DM36: 2.9171067 | DN36: 43.371331 | DP36: 17.12774 | DT36: 6.0446165 | DU36: 24.698313 | DW36: 4.1776169 | DX36: 0.43122891 | DZ36: 3.8810149 | EA36: 0.029134094 | EF36: 35.624995 | EG36: 23.217157 | EH36: 1.3245312 | EJ36: 22.036689 | EM36: 7.1258031 | EN36: 7.337533 | EO36: 7.0459135 | EQ36: 9.1922654 | ER36: 18.203439 | EW36: 0.025591224 | EX36: 1.8032655 | EZ36: 17.853178 | FD36: 33.061461 | FE36: 21.483583 | FH36: 0.00050873175
A37: 37956 | E37: 0.024658656 | F37: 7.4859729 | H37: 10.842329 | I37: 24.190681 | P37: 26.435526 | V37: 204.23391 | X37: 702.67441 | Z37: 0.0078059693 | AB37: 0.0056335694 | AD37: 21.058979 | AG37: 0.020780857 | AH37: 2.1126138 | AI37: 0.005064348 | AM37: 0.025579564 | AP37: 0.78882928 | AQ37: 0.031061364 | AR37: 3.6011997 | AT37: 8.3421754 | AU37: 0.28783717 | AV37: 17.595501 | AZ37: 42.39163 | BA37: 0.54137362 | BC37: 27.36906 | BD37: 28.051542 | BH37: 26.240745 | BI37: 3.7671611 | BJ37: 26.584834 | BK37: 8.1212359 | BP37: 0.20144799 | BQ37: 2.0897902 | BS37: 0.10687563 | BT37: 0.29872704 | BU37: 0.30484394 | BV37: 0.001169 | BY37: 23.335144 | BZ37: 4.2811741 | CA37: 26.959177 | CB37: 0.12537019 | CC37: 0.23651335 | CG37: 0.015883588 | CI37: 19.730065 | CN37: 22.742221 | CO37: 26.072498 | CP37: 1.7831451 | CQ37: 0.0070778373 | CS37: 5.9618537 | CT37: 1.0800738 | CX37: 0.41256782 | CY37: 1.31844 | CZ37: 0.37304 | DH37: 27.100363 | DL37: 0.47136776 | DM37: 3.2139607 | DN37: 45.576911 | DP37: 18.035141 | DT37: 6.6607445 | DU37: 27.374526 | DW37: 4.6068813 | DX37: 0.46584521 | DZ37: 4.1031116 | EA37: 0.031969387 | EF37: 39.52822 | EG37: 25.75094 | EH37: 1.4452715 | EJ37: 24.452203 | EM37: 7.5396433 | EN37: 7.7643338 | EO37: 7.3446545 | EQ37: 10.160237 | ER37: 20.210419 | EW37: 0.028540735 | EX37: 1.9002376 | EZ37: 19.507221 | FD37: 36.243428 | FE37: 22.642558 | FH37: 0.00054091387
A38: 37987 | E38: 0.02375629 | F38: 7.0398259 | H38: 10.311069 | I38: 23.583645 | P38: 25.824915 | V38: 200.25579 | X38: 694.5943 | Z38: 0.007197752 | AB38: 0.0053551388 | AD38: 20.257841 | AG38: 0.020682284 | AH38: 2.0262782 | AI38: 0.0049492309 | AM38: 0.024520924 | AP38: 0.7727711 | AQ38: 0.030462237 | AR38: 3.5117676 | AT38: 7.9370526 | AU38: 0.24184067 | AV38: 16.761228 | AZ38: 41.513487 | BA38: 0.50970454 | BC38: 26.58367 | BD38: 27.321965 | BH38: 25.558264 | BI38: 3.762879 | BJ38: 25.724001 | BK38: 7.7130597 | BP38: 0.19064181 | BQ38: 1.9945637 | BS38: 0.10650272 | BT38: 0.29825914 | BU38: 0.29120163 | BV38: 0.0011299285 | BY38: 22.600007 | BZ38: 4.0276014 | CA38: 26.300673 | CB38: 0.11998203 | CC38: 0.22690932 | CG38: 0.01527336 | CI38: 19.446437 | CN38: 22.146404 | CO38: 25.213699 | CP38: 1.7005959 | CQ38: 0.0063155078 | CS38: 5.6559896 | CT38: 1.0243825 | CX38: 0.40886587 | CY38: 1.2968114 | CZ38: 0.35967545 | DD38: 0.24953823 | DH38: 26.398731 | DL38: 0.46017779 | DM38: 3.0005677 | DN38: 43.146822 | DP38: 17.178521 | DT38: 6.4121262 | DU38: 26.664161 | DW38: 4.4780365 | DX38: 0.45769746 | DY38: 0.020273617 | DZ38: 3.9044036 | EA38: 0.031198697 | EF38: 40.199161 | EG38: 25.174163 | EH38: 1.2834077 | EJ38: 23.649224 | EM38: 7.1407233 | EN38: 7.4587849 | EO38: 6.9672918 | EQ38: 9.751297 | ER38: 19.490774 | EW38: 0.02809061 | EX38: 1.8072648 | EZ38: 19.762452 | FD38: 35.647469 | FE38: 21.585814 | FH38: 0.00051791396
A39: 38018 | E39: 0.025306839 | F39: 7.451123 | H39: 10.751019 | I39: 24.671839 | P39: 27.015762 | Q39: 10.518956 | V39: 203.82297 | X39: 726.04511 | Z39: 0.0074752778 | AB39: 0.0055732792 | AD39: 20.575163 | AG39: 0.021108298 | AH39: 2.1020505 | AI39: 0.0052661519 | AM39: 0.025625447 | AP39: 0.80420841 | AQ39: 0.031722145 | AR39: 3.685427 | AT39: 8.2283088 | AU39: 0.25860189 | AV39: 17.5426 | AZ39: 43.4337 | BA39: 0.53388654 | BC39: 27.862308 | BD39: 28.59608 | BH39: 26.696748 | BI39: 3.9148246 | BJ39: 26.727332 | BK39: 8.0156921 | BP39: 0.19786503 | BQ39: 2.0884979 | BS39: 0.11307506 | BT39: 0.31322582 | BU39: 0.30394089 | BV39: 0.0011665404 | BY39: 23.754893 | BZ39: 4.1548654 | CA39: 27.478077 | CB39: 0.12486704 | CC39: 0.23578937 | CG39: 0.016187748 | CI39: 20.410585 | CN39: 23.027746 | CO39: 26.618407 | CP39: 1.7661058 | CQ39: 0.0062036661 | CS39: 5.8849445 | CT39: 1.0632348 | CX39: 0.43316341 | CY39: 1.3459887 | CZ39: 0.38592737 | DD39: 0.25893012 | DH39: 27.637198 | DL39: 0.47429882 | DM39: 3.0644409 | DN39: 44.761421 | DP39: 17.856902 | DT39: 6.4995183 | DU39: 27.748121 | DW39: 4.7578333 | DX39: 0.48735691 | DY39: 0.021337048 | DZ39: 4.0626761 | EA39: 0.032627557 | EF39: 42.230921 | EG39: 26.270707 | EH39: 1.3794728 | EJ39: 24.659316 | EM39: 7.4017311 | EN39: 7.65688 | EO39: 7.4181523 | EQ39: 10.094749 | ER39: 20.215335 | EW39: 0.02920488 | EX39: 1.8790344 | EZ39: 20.957219 | FD39: 38.080241 | FE39: 22.559397 | FH39: 0.00055247253
A40: 38047 | E40: 0.024819147 | F40: 7.2173066 | H40: 10.380455 | I40: 23.113485 | P40: 25.249396 | V40: 198.81649 | X40: 677.48795 | Z40: 0.0075558279 | AB40: 0.0054180472 | AD40: 19.892014 | AG40: 0.019742899 | AH40: 2.0295818 | AI40: 0.0052100498 | AM40: 0.024594475 | AP40: 0.74777301 | AQ40: 0.029870258 | AR40: 3.4533492 | AT40: 7.9285081 | AU40: 0.27238649 | AV40: 17.0052 | AZ40: 40.601104 | BA40: 0.52112511 | BC40: 25.916386 | BD40: 26.796105 | BH40: 25.000124 | BI40: 3.7328774 | BJ40: 25.563335 | BK40: 7.7736673 | BP40: 0.20803909 | BQ40: 2.0079301 | BS40: 0.1101825 | BT40: 0.29255388 | BU40: 0.29422484 | BV40: 0.0011058063 | BY40: 22.265122 | BZ40: 3.958989 | CA40: 25.729593 | CB40: 0.12069316 | CC40: 0.22310468 | CG40: 0.015738944 | CI40: 19.24154 | CN40: 21.60197 | CO40: 24.854942 | CP40: 1.6930348 | CQ40: 0.0056116531 | CS40: 5.6596813 | CT40: 1.0232004 | CX40: 0.40770423 | CY40: 1.3017928 | CZ40: 0.38186446 | DD40: 0.25169509 | DH40: 26.019632 | DL40: 0.44278071 | DM40: 2.9518454 | DN40: 43.26393 | DP40: 17.155388 | DT40: 6.2018989 | DU40: 25.958512 | DW40: 4.5214842 | DX40: 0.47236871 | DY40: 0.020752902 | DZ40: 3.9030174 | EA40: 0.030422399 | EF40: 39.478493 | EG40: 24.672499 | EH40: 1.3595053 | EJ40: 23.176308 | EM40: 7.1575017 | EN40: 7.4136575 | EO40: 7.0512748 | EQ40: 9.4335336 | ER40: 19.01144 | EW40: 0.027089639 | EX40: 1.8128788 | EZ40: 20.50907 | FD40: 35.927512 | FE40: 21.85649 | FH40: 0.00053520098
...

Sheet TCRB_BCRA
A1: Índices con base 17-12-15=100
A2: Período | B2: ITCRM | C2: ITCRB Brasil | D2: ITCRB Canadá | E2: ITCRB Chile | F2: ITCRB Estados Unidos | G2: ITCRB México | H2: ITCRB Uruguay | I2: ITCRB China | J2: ITCRB India | K2: ITCRB Japón | L2: ITCRB Reino Unido | M2: ITCRB Suiza | N2: ITCRB Zona Euro | O2: ITCRB Vietnam | P2: ITCRB Sudamérica*
A3: 36922 | B3: 73.369179 | C3: 80.477883 | D3: 76.012322 | E3: 82.569152 | F3: 78.726615 | G3: 102.64086 | H3: 73.16585 | I3: 60.001077 | J3: 55.232127 | K3: 43.53173 | L3: 77.791222 | M3: 62.296217 | N3: 71.775635 | O3: 54.979042 | P3: 78.737628
A4: 36950 | B4: 72.750626 | C4: 79.435857 | D4: 74.940576 | E4: 84.011726 | F4: 79.097566 | G4: 102.46157 | H4: 73.294738 | I4: 61.134165 | J4: 55.113111 | K4: 44.353009 | L4: 75.818457 | M4: 60.574744 | N4: 69.993861 | O4: 55.120785 | P4: 78.914107
A5: 36981 | B5: 72.289194 | C5: 78.745391 | D5: 73.468119 | E5: 84.04338 | F5: 79.213931 | G5: 103.72442 | H5: 73.092045 | I5: 60.915662 | J5: 55.001875 | K5: 42.944849 | L5: 75.532053 | M5: 59.681365 | N5: 69.274842 | O5: 55.035305 | P5: 78.626939
A6: 37011 | B6: 70.040533 | C6: 73.027059 | D6: 73.548658 | E6: 79.320084 | F6: 78.960897 | G6: 108.67703 | H6: 72.255249 | I6: 60.073607 | J6: 54.913929 | K6: 42.503089 | L6: 75.092397 | M6: 58.847176 | N6: 68.196897 | O6: 54.440679 | P6: 74.867464
A7: 37042 | B7: 69.381512 | C7: 72.000576 | D7: 74.648311 | E7: 78.846198 | F7: 78.955633 | G7: 108.38985 | H7: 71.719525 | I7: 59.910031 | J7: 54.880478 | K7: 43.049516 | L7: 74.825755 | M7: 57.46068 | N7: 66.946496 | O7: 53.907692 | P7: 74.188767
A8: 37072 | B8: 68.096584 | C8: 68.777478 | D8: 76.033512 | E8: 78.019123 | F8: 79.51632 | G8: 110.33 | H8: 70.965552 | I8: 59.961263 | J8: 55.515191 | K8: 42.792396 | L8: 74.263315 | M8: 56.780777 | N8: 65.652842 | O8: 53.444115 | P8: 72.587384
A9: 37103 | B9: 67.914579 | C9: 67.900351 | D9: 76.077911 | E9: 74.056248 | F9: 79.945073 | G9: 111.26327 | H9: 69.491267 | I9: 60.585355 | J9: 56.391438 | K9: 42.20591 | L9: 75.008852 | M9: 57.963533 | N9: 66.537503 | O9: 53.20336 | P9: 70.482622
A10: 37134 | B10: 68.522013 | C10: 66.892834 | D10: 75.766458 | E10: 71.386015 | F10: 80.151363 | G10: 111.89635 | H10: 71.080039 | I10: 61.47292 | J10: 57.134603 | K10: 43.731881 | L10: 76.359078 | M10: 60.653568 | N10: 69.854734 | O10: 53.045637 | P10: 69.786296
A11: 37164 | B11: 67.500462 | C11: 62.988602 | D11: 74.699268 | E11: 71.582336 | F11: 80.486372 | G11: 110.42267 | H11: 70.119538 | I11: 61.12019 | J11: 56.748975 | K11: 45.158859 | L11: 78.101852 | M11: 62.309574 | N11: 70.819056 | O11: 53.243151 | P11: 68.230159
