Workbook

Sheet TC_u$d
A1: Tipo de cambio de socios comerciales (domestic currency per dollar US)
A2: fecha | B2: tipo_frecuencia | C2: Algeria | D2: Australia | E2: Bangladesh | F2: Belgium | G2: Brazil | H2: Chile | I2: China, People's Republic of | J2: Colombia | K2: Denmark | L2: Dominican Republic | M2: Ecuador | N2: Egypt, Arab Republic of | O2: Euro Area (EA) | P2: France | Q2: Germany | R2: Greece | S2: India | T2: Indonesia | U2: Iran, Islamic Republic of | V2: Ireland | W2: Italy | X2: Jordan | Y2: Korea, Republic of | Z2: Latvia, Republic of | AA2: Malaysia | AB2: Malta | AC2: Mexico | AD2: Morocco | AE2: Netherlands, The | AF2: Pakistan | AG2: Paraguay | AH2: Peru | AI2: Philippines | AJ2: Poland, Republic of | AK2: Russian Federation | AL2: Saudi Arabia | AM2: South Africa | AN2: Spain | AO2: Thailand | AP2: Tunisia | AQ2: Türkiye, Republic of | AR2: United Kingdom | AS2: United States | AT2: Uruguay | AU2: Venezuela, República Bolivariana de | AV2: Vietnam
A3: 2001.M01 | B3: mensual | C3: 74.8127 | D3: 1.79966 | E3: 54 | F3: #NUM! | G3: 1.9537091 | H3: 571.12 | I3: 8.27761 | J3: 2241.4 | K3: 7.95062 | L3: 16.619091 | M3: 1 | N3: 3.7 | O3: 1.0657779 | P3: #NUM! | Q3: #NUM! | R3: #NUM! | S3: 46.54 | T3: 9487 | U3: 1755.1359 | V3: #NUM! | W3: #NUM! | X3: 0.709 | Y3: 1272.82 | Z3: 0.614 | AA3: 3.8 | AB3: 0.4367 | AC3: 9.7701 | AD3: 10.59 | AE3: #NUM! | AF3: 59.08003 | AG3: 3570 | AH3: 3.523 | AI3: 50.969 | AJ3: 4.113 | AK3: 28.3592 | AL3: 3.75 | AM3: 7.78307 | AN3: #NUM! | AO3: 43.0779 | AP3: 1.3753 | AQ3: 0.672094 | AR3: 0.6765 | AS3: 1 | AT3: 12.561 | AU3: 0.6997 | AV3: 14534
A4: 2001.M02 | B4: mensual | C4: 75.745 | D4: 1.8695 | E4: 54 | F4: #NUM! | G4: 2.0010556 | H4: 563.13 | I4: 8.27706 | J4: 2243.42 | K4: 8.09493 | L4: 16.66 | M4: 1 | N4: 3.84 | O4: 1.0849458 | P4: #NUM! | Q4: #NUM! | R4: #NUM! | S4: 46.51889 | T4: 9673.3 | U4: 1755.5251 | V4: #NUM! | W4: #NUM! | X4: 0.709 | Y4: 1252.44 | Z4: 0.618 | AA4: 3.8 | AB4: 0.44244 | AC4: 9.7027 | AD4: 10.6939 | AE4: #NUM! | AF4: 59.65003 | AG4: 3693.8 | AH4: 3.53 | AI4: 48.29 | AJ4: 4.0901 | AK4: 28.5942 | AL4: 3.75 | AM4: 7.81555 | AN4: #NUM! | AO4: 42.589 | AP4: 1.3893 | AQ4: 0.760014 | AR4: 0.68787 | AS4: 1 | AT4: 12.5874 | AU4: 0.7026 | AV4: 14557
A5: 2001.M03 | B5: mensual | C5: 76.4536 | D5: 1.98089 | E5: 54 | F5: #NUM! | G5: 2.08825 | H5: 587.79 | I5: 8.27753 | J5: 2278.78 | K5: 8.20677 | L5: 16.66 | M5: 1 | N5: 3.84 | O5: 1.0994777 | P5: #NUM! | Q5: #NUM! | R5: #NUM! | S5: 46.6205 | T5: 10178.8 | U5: 1756.7883 | V5: #NUM! | W5: #NUM! | X5: 0.709 | Y5: 1288.43 | Z5: 0.624 | AA5: 3.8 | AB5: 0.4457321 | AC5: 9.6179 | AD5: 10.8091 | AE5: #NUM! | AF5: 60.55458 | AG5: 3752.4 | AH5: 3.52 | AI5: 48.467 | AJ5: 4.0629 | AK5: 28.6769 | AL5: 3.75 | AM5: 7.87869 | AN5: #NUM! | AO5: 43.844 | AP5: 1.4066 | AQ5: 0.958636 | AR5: 0.69205 | AS5: 1 | AT5: 12.7888 | AU5: 0.7055 | AV5: 14552
A6: 2001.M04 | B6: mensual | C6: 77.3773 | D6: 1.99608 | E6: 54 | F6: #NUM! | G6: 2.191655 | H6: 598.63 | I6: 8.2771 | J6: 2323.1 | K6: 8.35922 | L6: 16.66 | M6: 1 | N6: 3.84 | O6: 1.1210762 | P6: #NUM! | Q6: #NUM! | R6: #NUM! | S6: 46.786 | T6: 11182 | U6: 1751.4264 | V6: #NUM! | W6: #NUM! | X6: 0.709 | Y6: 1325.55 | Z6: 0.63 | AA6: 3.8 | AB6: 0.4511414 | AC6: 9.3508 | AD6: 11.0403 | AE6: #NUM! | AF6: 61.07212 | AG6: 3787.4 | AH6: 3.559 | AI6: 50.185 | AJ6: 4.0175 | AK6: 28.8464 | AL6: 3.75 | AM6: 8.08213 | AN6: #NUM! | AO6: 45.413 | AP6: 1.4287 | AQ6: 1.204238 | AR6: 0.69698 | AS6: 1 | AT6: 12.9025 | AU6: 0.7096 | AV6: 14557
A7: 2001.M05 | B7: mensual | C7: 78.3376 | D7: 1.92324 | E7: 54.68 | F7: #NUM! | G7: 2.2964318 | H7: 604.48 | I7: 8.27725 | J7: 2346.93 | K7: 8.5252 | L7: 16.66 | M7: 1 | N7: 3.841 | O7: 1.1439506 | P7: #NUM! | Q7: #NUM! | R7: #NUM! | S7: 46.91727 | T7: 11230 | U7: 1754.4424 | V7: #NUM! | W7: #NUM! | X7: 0.709 | Y7: 1298.46 | Z7: 0.633 | AA7: 3.8 | AB7: 0.4565376 | AC7: 9.1467 | AD7: 11.6655 | AE7: #NUM! | AF7: 61.86138 | AG7: 3821.9 | AH7: 3.6 | AI7: 50.539 | AJ7: 3.9806 | AK7: 29.0183 | AL7: 3.75 | AM7: 7.97279 | AN7: #NUM! | AO7: 45.4355 | AP7: 1.4574 | AQ7: 1.132664 | AR7: 0.70166 | AS7: 1 | AT7: 13.0619 | AU7: 0.7144 | AV7: 14604
A8: 2001.M06 | B8: mensual | C8: 79.17155 | D8: 1.93008 | E8: 57 | F8: #NUM! | G8: 2.375025 | H8: 616.07 | I8: 8.27704 | J8: 2305.66 | K8: 8.72189 | L8: 16.66 | M8: 1 | N8: 3.85 | O8: 1.1721039 | P8: #NUM! | Q8: #NUM! | R8: #NUM! | S8: 47.00526 | T8: 11313 | U8: 1754.0377 | V8: #NUM! | W8: #NUM! | X8: 0.709 | Y8: 1293.83 | Z8: 0.639 | AA8: 3.8 | AB8: 0.4638864 | AC8: 9.0957 | AD8: 11.8808 | AE8: #NUM! | AF8: 63.43162 | AG8: 3908.5 | AH8: 3.531 | AI8: 51.488 | AJ8: 3.9705 | AK8: 29.1144 | AL8: 3.75 | AM8: 8.05355 | AN8: #NUM! | AO8: 45.2016 | AP8: 1.4943 | AQ8: 1.213123 | AR8: 0.71375 | AS8: 1 | AT8: 13.3644 | AU8: 0.7167 | AV8: 14769
A9: 2001.M07 | B9: mensual | C9: 79.3581 | D9: 1.96028 | E9: 57 | F9: #NUM! | G9: 2.4652227 | H9: 656.46 | I9: 8.27689 | J9: 2304.28 | K9: 8.65706 | L9: 16.66 | M9: 1 | N9: 3.85 | O9: 1.1618941 | P9: #NUM! | Q9: #NUM! | R9: #NUM! | S9: 47.14182 | T9: 10707 | U9: 1752.4734 | V9: #NUM! | W9: #NUM! | X9: 0.709 | Y9: 1302.6 | Z9: 0.639 | AA9: 3.8 | AB9: 0.4612 | AC9: 9.156 | AD9: 11.8133 | AE9: #NUM! | AF9: 64.11397 | AG9: 4177.9 | AH9: 3.503 | AI9: 53.224 | AJ9: 4.1859 | AK9: 29.2173 | AL9: 3.75 | AM9: 8.15002 | AN9: #NUM! | AO9: 45.5688 | AP9: 1.485 | AQ9: 1.321554 | AR9: 0.70732 | AS9: 1 | AT9: 13.6046 | AU9: 0.722 | AV9: 14897
A10: 2001.M08 | B10: mensual | C10: 76.9608 | D10: 1.90554 | E10: 57 | F10: #NUM! | G10: 2.5098304 | H10: 673.7 | I10: 8.27697 | J10: 2288.9 | K10: 8.26772 | L10: 16.66 | M10: 1 | N10: 4.14 | O10: 1.1105156 | P10: #NUM! | Q10: #NUM! | R10: #NUM! | S10: 47.12632 | T10: 8828.8 | U10: 1750.584 | V10: #NUM! | W10: #NUM! | X10: 0.709 | Y10: 1285.39 | Z10: 0.628 | AA10: 3.8 | AB10: 0.44891363 | AC10: 9.1261 | AD10: 11.424 | AE10: #NUM! | AF10: 64.12925 | AG10: 4282.4 | AH10: 3.491 | AI10: 51.988 | AJ10: 4.2459 | AK10: 29.3452 | AL10: 3.75 | AM10: 8.31388 | AN10: #NUM! | AO10: 44.8655 | AP10: 1.4392 | AQ10: 1.399933 | AR10: 0.69595 | AS10: 1 | AT10: 13.3883 | AU10: 0.7308 | AV10: 14979
A11: 2001.M09 | B11: mensual | C11: 76.4547 | D11: 1.97529 | E11: 57 | F11: #NUM! | G11: 2.6708632 | H11: 681.24 | I11: 8.27681 | J11: 2328.23 | K11: 8.1705 | L11: 16.66 | M11: 1 | N11: 4.14 | O11: 1.0975804 | P11: #NUM! | Q11: #NUM! | R11: #NUM! | S11: 47.646 | T11: 9306.5 | U11: 1753.7587 | V11: #NUM! | W11: #NUM! | X11: 0.709 | Y11: 1293.7 | Z11: 0.622 | AA11: 3.8 | AB11: 0.4445828 | AC11: 9.3841 | AD11: 11.3178 | AE11: #NUM! | AF11: 64.1979 | AG11: 4405.7 | AH11: 3.49 | AI11: 51.25 | AJ11: 4.2185 | AK11: 29.4288 | AL11: 3.75 | AM11: 8.63656 | AN11: #NUM! | AO11: 44.2837 | AP11: 1.4309 | AQ11: 1.472194 | AR11: 0.68372 | AS11: 1 | AT11: 13.5832 | AU11: 0.7429 | AV11: 14099
A12: 2001.M10 | B12: mensual | C12: 76.7019 | D12: 1.98078 | E12: 57 | F12: #NUM! | G12: 2.7393727 | H12: 708.1 | I12: 8.27681 | J12: 2320.65 | K12: 8.20787 | L12: 16.66 | M12: 1 | N12: 4.14 | O12: 1.103917 | P12: #NUM! | Q12: #NUM! | R12: #NUM! | S12: 48.02048 | T12: 10115.5 | U12: 1755.0864 | V12: #NUM! | W12: #NUM! | X12: 0.709 | Y12: 1302.6 | Z12: 0.625 | AA12: 3.8 | AB12: 0.44642857 | AC12: 9.3685 | AD12: 11.359 | AE12: #NUM! | AF12: 62.66801 | AG12: 4554.7 | AH12: 3.46 | AI12: 51.733 | AJ12: 4.1332 | AK12: 29.5344 | AL12: 3.75 | AM12: 9.2751 | AN12: #NUM! | AO12: 44.6727 | AP12: 1.4399 | AQ12: 1.602467 | AR12: 0.68902 | AS12: 1 | AT12: 13.9627 | AU12: 0.7431 | AV12: 15022
A13: 2001.M11 | B13: mensual | C13: 77.6944 | D13: 1.93481 | E13: 57 | F13: #NUM! | G13: 2.542265 | H13: 689.4 | I13: 8.27688 | J13: 2310.47 | K13: 8.38144 | L13: 16.758947 | M13: 1 | N13: 4.14 | O13: 1.1257343 | P13: #NUM! | Q13: #NUM! | R13: #NUM! | S13: 47.99737 | T13: 10576 | U13: 1753.8036 | V13: #NUM! | W13: #NUM! | X13: 0.70889809 | Y13: 1284 | Z13: 0.63 | AA13: 3.8 | AB13: 0.4521 | AC13: 9.2223 | AD13: 11.535 | AE13: #NUM! | AF13: 61.5032 | AG13: 4649.5 | AH13: 3.44 | AI13: 51.9899 | AJ13: 4.0943 | AK13: 29.7956 | AL13: 3.75 | AM13: 9.75383 | AN13: #NUM! | AO13: 44.3715 | AP13: 1.45881 | AQ13: 1.519319 | AR13: 0.69619 | AS13: 1 | AT13: 13.954 | AU13: 0.7447 | AV13: 15063
A14: 2001.M12 | B14: mensual | C14: 77.5126 | D14: 1.94516 | E14: 57 | F14: #NUM! | G14: 2.3619 | H14: 669.14 | I14: 8.27687 | J14: 2306.9 | K14: 8.33059 | L14: 16.9735 | M14: 1 | N14: 4.355 | O14: 1.1206086 | P14: #NUM! | Q14: #NUM! | R14: #NUM! | S14: 47.91706 | T14: 10532.3 | U14: 1754.7662 | V14: #NUM! | W14: #NUM! | X14: 0.7089 | Y14: 1289.66 | Z14: 0.633 | AA14: 3.8 | AB14: 0.4508363 | AC14: 9.1672 | AD14: 11.507 | AE14: #NUM! | AF14: 60.86385 | AG14: 4666.9 | AH14: 3.435 | AI14: 51.7889 | AJ14: 4.0144 | AK14: 30.0916 | AL14: 3.75 | AM14: 11.595 | AN14: #NUM! | AO14: 43.8596 | AP14: 1.45914 | AQ14: 1.450821 | AR14: 0.69485 | AS14: 1 | AT14: 14.0706 | AU14: 0.7519 | AV14: 15069
... A86: 2007.M12 | B86: mensual | C86: 67.0718 | D86: 1.14585 | E86: 68.5871 | F86: #NUM! | G86: 1.7852 | H86: 499.28 | I86: 7.37196 | J86: 2014.2015 | K86: 5.1199 | L86: 33.658685 | M86: 1 | N86: 5.52 | O86: 0.68632444 | P86: #NUM! | Q86: #NUM! | R86: #NUM! | S86: 39.4395 | T86: 9351.8 | U86: 9368.125 | V86: #NUM! | W86: #NUM! | X86: 0.7089986 | Y86: 930.24 | Z86: 0.4824 | AA86: 3.3341842 | AB86: 0.2916 | AC86: 10.8494 | AD86: 7.7751 | AE86: #NUM! | AF86: 61.2207 | AG86: 4731.7 | AH86: 2.9808 | AI86: 41.742889 | AJ86: 2.4754 | AK86: 24.565915 | AL86: 3.75 | AM86: 6.80615 | AN86: #NUM! | AO86: 33.658632 | AP86: 1.2275 | AQ86: 1.1716081 | AR86: 0.4942 | AS86: 1 | AT86: 21.6921 | AU86: 2.147 | AV86: 16117
A87: 2008.M01 | B87: mensual | C87: 66.8474 | D87: 1.13423 | E87: 68.5798 | F87: #NUM! | G87: 1.7735 | H87: 480.9 | I87: 7.24781 | J87: 1980.59 | K87: 5.0624 | L87: 33.894138 | M87: 1 | N87: 5.5 | O87: 0.67944434 | P87: #NUM! | Q87: #NUM! | R87: #NUM! | S87: 39.3737 | T87: 9394.8 | U87: 9280.7778 | V87: #NUM! | W87: #NUM! | X87: 0.7089986 | Y87: 942.39 | Z87: 0.4785 | AA87: 3.2679 | AB87: #NUM! | AC87: 10.9171 | AD87: 7.7176 | AE87: #NUM! | AF87: 61.2207 | AG87: 4712.9 | AH87: 2.9503 | AI87: 40.938091 | AJ87: 2.4537 | AK87: 24.5011 | AL87: 3.75 | AM87: 7.0131 | AN87: #NUM! | AO87: 33.144091 | AP87: 1.2163 | AQ87: 1.1716081 | AR87: 0.50771 | AS87: 1 | AT87: 21.1998 | AU87: 2.147 | AV87: 16104
A88: 2008.M02 | B88: mensual | C88: 66.7689 | D88: 1.09521 | E88: 68.5799 | F88: #NUM! | G88: 1.7269 | H88: 467.22 | I88: 7.16504 | J88: 1903.27 | K88: 5.0549 | L88: 33.95613 | M88: 1 | N88: 5.5 | O88: 0.67804053 | P88: #NUM! | Q88: #NUM! | R88: #NUM! | S88: 39.7326 | T88: 9164 | U88: 9322.8667 | V88: #NUM! | W88: #NUM! | X88: 0.709 | Y88: 944.69 | Z88: 0.4772 | AA88: 3.2223 | AB88: #NUM! | AC88: 10.7794 | AD88: 7.7073 | AE88: #NUM! | AF88: 61.2207 | AG88: 4682.7 | AH88: 2.9055 | AI88: 40.6711 | AJ88: 2.4305 | AK88: 24.5347 | AL88: 3.75 | AM88: 7.66325 | AN88: #NUM! | AO88: 32.567253 | AP88: 1.2164 | AQ88: 1.1915017 | AR88: 0.50925 | AS88: 1 | AT88: 20.9366 | AU88: 2.147 | AV88: 16070
A89: 2008.M03 | B89: mensual | C89: 65.6725 | D89: 1.0811 | E89: 68.5802 | F89: #NUM! | G89: 1.7068 | H89: 442.94 | I89: 7.07521 | J89: 1846.9 | K89: 4.8012 | L89: 34.04004 | M89: 1 | N89: 5.46 | O89: 0.64405906 | P89: #NUM! | Q89: #NUM! | R89: #NUM! | S89: 40.3561 | T89: 9185.8 | U89: 9048.8571 | V89: #NUM! | W89: #NUM! | X89: 0.709 | Y89: 979.86 | Z89: 0.4534 | AA89: 3.1868 | AB89: #NUM! | AC89: 10.7346 | AD89: 7.3758 | AE89: #NUM! | AF89: 61.3358 | AG89: 4526.7 | AH89: 2.8109 | AI89: 41.252368 | AJ89: 2.2816 | AK89: 23.7607 | AL89: 3.75 | AM89: 7.97056 | AN89: #NUM! | AO89: 31.411564 | AP89: 1.1664 | AQ89: 1.2394565 | AR89: 0.49913 | AS89: 1 | AT89: 20.6261 | AU89: 2.147 | AV89: 16004
A90: 2008.M04 | B90: mensual | C90: 64.9695 | D90: 1.07458 | E90: 68.6278 | F90: #NUM! | G90: 1.6881 | H90: 446.43 | I90: 7.00076 | J90: 1796.13 | K90: 4.7373 | L90: 34.136155 | M90: 1 | N90: 5.42 | O90: 0.63490048 | P90: #NUM! | Q90: #NUM! | R90: #NUM! | S90: 40.0224 | T90: 9212 | U90: 9031.7812 | V90: #NUM! | W90: #NUM! | X90: 0.709 | Y90: 986.66 | Z90: 0.4454 | AA90: 3.1621 | AB90: #NUM! | AC90: 10.5295 | AD90: 7.2907 | AE90: #NUM! | AF90: 63.7746 | AG90: 4279.5455 | AH90: 2.743 | AI90: 41.819571 | AJ90: 2.1852 | AK90: 23.5127 | AL90: 3.75 | AM90: 7.785 | AN90: #NUM! | AO90: 31.5429 | AP90: 1.1576 | AQ90: 1.2993333 | AR90: 0.5048 | AS90: 1 | AT90: 19.9325 | AU90: 2.147 | AV90: 15960
A91: 2008.M05 | B91: mensual | C91: 63.4761 | D91: 1.05372 | E91: 68.5758 | F91: #NUM! | G91: 1.6597 | H91: 470.1 | I91: 6.97413 | J91: 1778.01 | K91: 4.7942 | L91: 34.131268 | M91: 1 | N91: 5.34 | O91: 0.64279745 | P91: #NUM! | Q91: #NUM! | R91: #NUM! | S91: 42.125 | T91: 9300.3 | U91: 9202.25 | V91: #NUM! | W91: #NUM! | X91: 0.71 | Y91: 1036.73 | Z91: 0.4513 | AA91: 3.218 | AB91: #NUM! | AC91: 10.4542 | AD91: 7.3679 | AE91: #NUM! | AF91: 67.8047 | AG91: 4082.25 | AH91: 2.8046 | AI91: 42.901952 | AJ91: 2.1904 | AK91: 23.7294 | AL91: 3.75 | AM91: 7.621 | AN91: #NUM! | AO91: 32.057 | AP91: 1.1742 | AQ91: 1.2453 | AR91: 0.50881 | AS91: 1 | AT91: 19.8739 | AU91: 2.147 | AV91: 16022
A92: 2008.M06 | B92: mensual | C92: 62.3983 | D92: 1.05175 | E92: 68.5296 | F92: #NUM! | G92: 1.6181 | H92: 493.61238 | I92: 6.89837 | J92: 1712.28 | K92: 4.7936 | L92: 34.268229 | M92: 1 | N92: 5.34 | O92: 0.64297262 | P92: #NUM! | Q92: #NUM! | R92: #NUM! | S92: 42.8202 | T92: 9283.5 | U92: 9252.9333 | V92: #NUM! | W92: #NUM! | X92: 0.71 | Y92: 1029.27 | Z92: 0.4519 | AA92: 3.2584 | AB92: #NUM! | AC92: 10.3305 | AD92: 7.3679 | AE92: #NUM! | AF92: 67.3662 | AG92: 3978.75 | AH92: 2.8916 | AI92: 44.28055 | AJ92: 2.1694 | AK92: 23.6376 | AL92: 3.75 | AM92: 7.92 | AN92: #NUM! | AO92: 33.1482 | AP92: 1.1774 | AQ92: 1.231195 | AR92: 0.5092 | AS92: 1 | AT92: 19.494 | AU92: 2.147 | AV92: 16347
A93: 2008.M07 | B93: mensual | C93: 61.4996 | D93: 1.03893 | E93: 68.5151 | F93: #NUM! | G93: 1.5906 | H93: 502.24 | I93: 6.83763 | J93: 1783.09 | K93: 4.7307 | L93: 34.385522 | M93: 1 | N93: 5.31 | O93: 0.63412765 | P93: #NUM! | Q93: #NUM! | R93: #NUM! | S93: 42.838 | T93: 9145.3 | U93: 9192.6875 | V93: #NUM! | W93: #NUM! | X93: 0.71 | Y93: 1019.12 | Z93: 0.4453 | AA93: 3.2499 | AB93: #NUM! | AC93: 10.239 | AD93: 7.2801 | AE93: #NUM! | AF93: 70.8502 | AG93: 3977.1739 | AH93: 2.848 | AI93: 44.956261 | AJ93: 2.0674 | AK93: 23.3505 | AL93: 3.75 | AM93: 7.62568 | AN93: #NUM! | AO93: 33.4504 | AP93: 1.1647 | AQ93: 1.2105726 | AR93: 0.50284 | AS93: 1 | AT93: 19.2522 | AU93: 2.147 | AV93: 16507
A94: 2008.M08 | B94: mensual | C94: 61.0767 | D94: 1.09746 | E94: 68.5199 | F94: #NUM! | G94: 1.6115 | H94: 516.7 | I94: 6.8515 | J94: 1844.29 | K94: 4.9834 | L94: 34.796581 | M94: 1 | N94: 5.33 | O94: 0.66776265 | P94: #NUM! | Q94: #NUM! | R94: #NUM! | S94: 42.9374 | T94: 9149.25 | U94: 9492.5 | V94: #NUM! | W94: #NUM! | X94: 0.71 | Y94: 1041.54 | Z94: 0.4793 | AA94: 3.3273 | AB94: #NUM! | AC94: 10.0906 | AD94: 7.6001 | AE94: #NUM! | AF94: 74.556 | AG94: 3985.5 | AH94: 2.8923 | AI94: 44.876947 | AJ94: 2.1926 | AK94: 24.1314 | AL94: 3.75 | AM94: 7.6614 | AN94: #NUM! | AO94: 33.8043 | AP94: 1.2112 | AQ94: 1.1761258 | AR94: 0.51293 | AS94: 1 | AT94: 19.2173 | AU94: 2.147 | AV94: 16495
A95: 2008.M09 | B95: mensual | C95: 60.9788 | D95: 1.21875 | E95: 68.5187 | F95: #NUM! | G95: 1.7988 | H95: 530.17 | I95: 6.83061 | J95: 2066.04 | K95: 5.19167 | L95: 34.94999 | M95: 1 | N95: 5.42 | O95: 0.69591844 | P95: #NUM! | Q95: #NUM! | R95: #NUM! | S95: 45.5635 | T95: 9372.8 | U95: 9679.7222 | V95: #NUM! | W95: #NUM! | X95: 0.71 | Y95: 1130.4 | Z95: 0.4881 | AA95: 3.4416 | AB95: #NUM! | AC95: 10.5744 | AD95: 7.8739 | AE95: #NUM! | AF95: 77.3388 | AG95: 3995.79 | AH95: 2.9658 | AI95: 44.876947 | AJ95: 2.3497 | AK95: 25.2837 | AL95: 3.75 | AM95: 8.05714 | AN95: #NUM! | AO95: 34.241 | AP95: 1.2492 | AQ95: 1.23723 | AR95: 0.55668 | AS95: 1 | AT95: 20.4459 | AU95: 2.147 | AV95: 16508
A96: 2008.M10 | B96: mensual | C96: 62.2584 | D96: 1.44219 | E96: 68.5458 | F96: #NUM! | G96: 2.1721 | H96: 618.39455 | I96: 6.83155 | J96: 2289.17 | K96: 5.6029 | L96: 35.087748 | M96: 1 | N96: 5.55 | O96: 0.75063314 | P96: #NUM! | Q96: #NUM! | R96: #NUM! | S96: 48.6555 | T96: 10100 | U96: 9887 | V96: #NUM! | W96: #NUM! | X96: 0.71 | Y96: 1326.92 | Z96: 0.5247 | AA96: 3.5264 | AB96: #NUM! | AC96: 12.4738 | AD96: 8.4273 | AE96: #NUM! | AF96: 80.339 | AG96: 4409.3478 | AH96: 3.0752 | AI96: 48.025227 | AJ96: 2.698 | AK96: 26.3512 | AL96: 3.75 | AM96: 9.7448 | AN96: #NUM! | AO96: 34.3764 | AP96: 1.3228 | AQ96: 1.4803016 | AR96: 0.59215 | AS96: 1 | AT96: 22.3731 | AU96: 2.147 | AV96: 16517
A97: 2008.M11 | B97: mensual | C97: 68.133 | D97: 1.52513 | E97: 68.7166 | F97: #NUM! | G97: 2.2655 | H97: 651.5055 | I97: 6.82856 | J97: 2329.16 | K97: 5.8507 | L97: 35.316926 | M97: 1 | N97: 5.52 | O97: 0.7854133 | P97: #NUM! | Q97: #NUM! | R97: #NUM! | S97: 49.0033 | T97: 11836 | U97: 9854.5882 | V97: #NUM! | W97: #NUM! | X97: 0.71 | Y97: 1390.09 | Z97: 0.5523 | AA97: 3.6175 | AB97: #NUM! | AC97: 13.0609 | AD97: 8.6866 | AE97: #NUM! | AF97: 80.00246 | AG97: 4837 | AH97: 3.0919 | AI97: 49.1862 | AJ97: 2.9209 | AK97: 27.3101 | AL97: 3.75 | AM97: 10.0985 | AN97: #NUM! | AO97: 35.0382 | AP97: 1.3871 | AQ97: 1.5929117 | AR97: 0.65164 | AS97: 1 | AT97: 23.687 | AU97: 2.147 | AV97: 16493
A98: 2008.M12 | B98: mensual | C98: 70.9144 | D98: 1.49309 | E98: 68.8901 | F98: #NUM! | G98: 2.3936 | H98: 649.32 | I98: 6.84269 | J98: 2252.72 | K98: 5.5746 | L98: 35.389605 | M98: 1 | N98: 5.5 | O98: 0.74352601 | P98: #NUM! | Q98: #NUM! | R98: #NUM! | S98: 48.6345 | T98: 11243.8 | U98: 9896.375 | V98: #NUM! | W98: #NUM! | X98: 0.71 | Y98: 1373.84 | Z98: 0.5224 | AA98: 3.5518 | AB98: #NUM! | AC98: 13.3726 | AD98: 8.3087 | AE98: #NUM! | AF98: 79.08724 | AG98: 4891.8421 | AH98: 3.1138 | AI98: 48.094235 | AJ98: 2.9715 | AK98: 28.1314 | AL98: 3.75 | AM98: 9.97425 | AN98: #NUM! | AO98: 34.9783 | AP98: 1.3424 | AQ98: 1.5427242 | AR98: 0.672455 | AS98: 1 | AT98: 24.3534 | AU98: 2.147 | AV98: 16600
... A158: 2013.M12 | B158: mensual | C158: 78.6569 | D158: 1.1132645 | E158: 77.7505 | F158: #NUM! | G158: 2.3459158 | H158: 529.45 | I158: 6.1172 | J158: 1934.08 | K158: 5.4457 | L158: 42.6996 | M158: 1 | N158: 6.8986 | O158: 0.72973525 | P158: #NUM! | Q158: #NUM! | R158: #NUM! | S158: 61.9103 | T158: 12087.1 | U158: 24790.929 | V158: #NUM! | W158: #NUM! | X158: 0.71 | Y158: 1056.67 | Z158: 0.5138 | AA158: 3.2492976 | AB158: #NUM! | AC158: 13.0098 | AD158: 8.1879857 | AE158: #NUM! | AF158: 107.0777 | AG158: 4524.0048 | AH158: 2.78525 | AI158: 44.104278 | AJ158: 3.0481 | AK158: 32.894 | AL158: 3.75 | AM158: 10.382465 | AN158: #NUM! | AO158: 32.344 | AP158: 1.6605 | AQ158: 2.0590242 | AR158: 0.61068151 | AS158: 1 | AT158: 21.363 | AU158: 6.2842 | AV158: 21036
A159: 2014.M01 | B159: mensual | C159: 78.1073 | D159: 1.128419 | E159: 77.7503 | F159: #NUM! | G159: 2.381565 | H159: 537.02955 | I159: 6.1039158 | J159: 1960.41 | K159: 5.4822 | L159: 42.9692 | M159: 1 | N159: 6.943 | O159: 0.73474159 | P159: #NUM! | Q159: #NUM! | R159: #NUM! | S159: 62.076 | T159: 12179.65 | U159: 24820.867 | V159: #NUM! | W159: #NUM! | X159: 0.71 | Y159: 1064.75 | Z159: #NUM! | AA159: 3.3044342 | AB159: #NUM! | AC159: 13.1981 | AD159: 8.232535 | AE159: #NUM! | AF159: 105.50709 | AG159: 4635.2175 | AH159: 2.8089318 | AI159: 44.926571 | AJ159: 3.065 | AK159: 33.457 | AL159: 3.75 | AM159: 10.893577 | AN159: #NUM! | AO159: 32.9394 | AP159: 1.6391 | AQ159: 2.21605 | AR159: 0.60702574 | AS159: 1 | AT159: 21.6559 | AU159: 6.2842 | AV159: 21036
A160: 2014.M02 | B160: mensual | C160: 77.9306 | D160: 1.1153121 | E160: 77.7501 | F160: #NUM! | G160: 2.3881105 | H160: 554.41 | I160: 6.1132667 | J160: 2040.51 | K160: 5.4025 | L160: 43.1817 | M160: 1 | N160: 6.9562 | O160: 0.73214482 | P160: #NUM! | Q160: #NUM! | R160: #NUM! | S160: 62.254 | T160: 11935.1 | U160: 24882.5 | V160: #NUM! | W160: #NUM! | X160: 0.71 | Y160: 1071.3 | Z160: #NUM! | AA160: 3.3082132 | AB160: #NUM! | AC160: 13.2888 | AD160: 8.208395 | AE160: #NUM! | AF160: 105.16126 | AG160: 4512.6452 | AH160: 2.81265 | AI160: 44.895 | AJ160: 3.0613 | AK160: 35.2237 | AL160: 3.75 | AM160: 10.981045 | AN160: #NUM! | AO160: 32.6518 | AP160: 1.5909 | AQ160: 2.2159804 | AR160: 0.61295656 | AS160: 1 | AT160: 22.3739 | AU160: 6.2842 | AV160: 21036
A161: 2014.M03 | B161: mensual | C161: 77.644 | D161: 1.1024027 | E161: 77.7094 | F161: #NUM! | G161: 2.3281947 | H161: 563.64737 | I161: 6.1369053 | J161: 2022.19 | K161: 5.3999 | L161: 43.2189 | M161: 1 | N161: 6.9583027 | O161: 0.72345688 | P161: #NUM! | Q161: #NUM! | R161: #NUM! | S161: 61.014 | T161: 11427.05 | U161: 25085.2 | V161: #NUM! | W161: #NUM! | X161: 0.71 | Y161: 1070.89 | Z161: #NUM! | AA161: 3.282981 | AB161: #NUM! | AC161: 13.2154 | AD161: 8.1266286 | AE161: #NUM! | AF161: 100.07966 | AG161: 4423.7776 | AH161: 2.806381 | AI161: 44.791571 | AJ161: 3.0378 | AK161: 36.211 | AL161: 3.75 | AM161: 10.745828 | AN161: #NUM! | AO161: 32.3941 | AP161: 1.5778 | AQ161: 2.2177355 | AR161: 0.60156857 | AS161: 1 | AT161: 22.6345 | AU161: 6.2842 | AV161: 21036
A162: 2014.M04 | B162: mensual | C162: 78.5992 | D162: 1.0737226 | E162: 77.6623 | F162: #NUM! | G162: 2.2347905 | H162: 554.64095 | I162: 6.15511 | J162: 1939.27 | K162: 5.4059 | L162: 43.2036 | M162: 1 | N162: 6.9781 | O162: 0.7239819 | P162: #NUM! | Q162: #NUM! | R162: #NUM! | S162: 60.356624 | T162: 11435.75 | U162: 25498.467 | V162: #NUM! | W162: #NUM! | X162: 0.71 | Y162: 1044.55 | Z162: #NUM! | AA162: 3.2578659 | AB162: #NUM! | AC162: 13.0681 | AD162: 8.1328727 | AE162: #NUM! | AF162: 97.685677 | AG162: 4433.204 | AH162: 2.794375 | AI162: 44.641579 | AJ162: 3.0293 | AK162: 35.6618 | AL162: 3.75 | AM162: 10.550126 | AN162: #NUM! | AO162: 32.3176 | AP162: 1.5884 | AQ162: 2.1300783 | AR162: 0.59744738 | AS162: 1 | AT162: 22.853 | AU162: 6.2842 | AV162: 21036
A163: 2014.M05 | B163: mensual | C163: 78.7997 | D163: 1.0742083 | E163: 77.6404 | F163: #NUM! | G163: 2.220281 | H163: 556.1045 | I163: 6.1628833 | J163: 1915.46 | K163: 5.427 | L163: 43.283305 | M163: 1 | N163: 7.0808 | O163: 0.72821847 | P163: #NUM! | Q163: #NUM! | R163: #NUM! | S163: 59.305 | T163: 11525.94 | U163: 25533.571 | V163: #NUM! | W163: #NUM! | X163: 0.71 | Y163: 1024.99 | Z163: #NUM! | AA163: 3.22846 | AB163: #NUM! | AC163: 12.9479 | AD163: 8.1754857 | AE163: #NUM! | AF163: 98.734455 | AG163: 4421.6337 | AH163: 2.7947381 | AI163: 43.923619 | AJ163: 3.0415 | AK163: 34.9269 | AL163: 3.75 | AM163: 10.409786 | AN163: #NUM! | AO163: 32.5269 | AP163: 1.6201 | AQ163: 2.0939597 | AR163: 0.5934588 | AS163: 1 | AT163: 23.022 | AU163: 6.2842 | AV163: 21036
A164: 2014.M06 | B164: mensual | C164: 79.294 | D164: 1.0676319 | E164: 77.63 | F164: #NUM! | G164: 2.23486 | H164: 553.06 | I164: 6.1563619 | J164: 1888.1 | K164: 5.4871 | L164: 43.4811 | M164: 1 | N164: 7.1429 | O164: 0.73570628 | P164: #NUM! | Q164: #NUM! | R164: #NUM! | S164: 59.7307 | T164: 11892.62 | U164: 25611 | V164: #NUM! | W164: #NUM! | X164: 0.71 | Y164: 1019.36 | Z164: #NUM! | AA164: 3.2184167 | AB164: #NUM! | AC164: 12.9832 | AD164: 8.2420571 | AE164: #NUM! | AF164: 98.581719 | AG164: 4404.765 | AH164: 2.7942381 | AI164: 43.8175 | AJ164: 3.0425 | AK164: 34.4065 | AL164: 3.75 | AM164: 10.671188 | AN164: #NUM! | AO164: 32.5111 | AP164: 1.6594 | AQ164: 2.1173083 | AR164: 0.59157923 | AS164: 1 | AT164: 22.9559 | AU164: 6.2842 | AV164: 21120
A165: 2014.M07 | B165: mensual | C165: 79.8322 | D165: 1.0647359 | E165: 77.5932 | F165: #NUM! | G165: 2.2215409 | H165: 558.21 | I165: 6.1675 | J165: 1858.4 | K165: 5.5075 | L165: 43.5749 | M165: 1 | N165: 7.1453 | O165: 0.7385975 | P165: #NUM! | Q165: #NUM! | R165: #NUM! | S165: 60.0586 | T165: 11689.056 | U165: 26303 | V165: #NUM! | W165: #NUM! | X165: 0.71 | Y165: 1019.93 | Z165: #NUM! | AA165: 3.18424 | AB165: #NUM! | AC165: 12.9734 | AD165: 8.25856 | AE165: #NUM! | AF165: 98.778392 | AG165: 4267.307 | AH165: 2.7860952 | AI165: 43.466524 | AJ165: 3.0598 | AK165: 34.6352 | AL165: 3.75 | AM165: 10.7041 | AN165: #NUM! | AO165: 32.0998 | AP165: 1.7083 | AQ165: 2.1176032 | AR165: 0.59231179 | AS165: 1 | AT165: 23.003 | AU165: 6.2842 | AV165: 21246
A166: 2014.M08 | B166: mensual | C166: 80.3249 | D166: 1.0748726 | E166: 77.4558 | F166: #NUM! | G166: 2.2693524 | H166: 579.05 | I166: 6.1606143 | J166: 1899.07 | K166: 5.5988 | L166: 43.6016 | M166: 1 | N166: 7.145 | O166: 0.7509709 | P166: #NUM! | Q166: #NUM! | R166: #NUM! | S166: 60.8952 | T166: 11706.05 | U166: 26504.75 | V166: #NUM! | W166: #NUM! | X166: 0.71 | Y166: 1025.36 | Z166: #NUM! | AA166: 3.1784452 | AB166: #NUM! | AC166: 13.149 | AD166: 8.3804333 | AE166: #NUM! | AF166: 100.35615 | AG166: 4267.8545 | AH166: 2.8145 | AI166: 43.767316 | AJ166: 3.1482 | AK166: 36.109973 | AL166: 3.75 | AM166: 10.662886 | AN166: #NUM! | AO166: 32.0055 | AP166: 1.7252 | AQ166: 2.1610403 | AR166: 0.59873605 | AS166: 1 | AT166: 23.7194 | AU166: 6.2842 | AV166: 21246
A167: 2014.M09 | B167: mensual | C167: 81.1859 | D167: 1.1035368 | E167: 77.4 | F167: #NUM! | G167: 2.3272429 | H167: 593.47 | I167: 6.152075 | J167: 1971.34 | K167: 5.7712 | L167: 43.765167 | M167: 1 | N167: 7.145 | O167: 0.77511186 | P167: #NUM! | Q167: #NUM! | R167: #NUM! | S167: 60.8649 | T167: 11849.86 | U167: 26637.647 | V167: #NUM! | W167: #NUM! | X167: 0.71 | Y167: 1033.24 | Z167: #NUM! | AA167: 3.21815 | AB167: #NUM! | AC167: 13.2002 | AD167: 8.6176818 | AE167: #NUM! | AF167: 102.5476 | AG167: 4334.3786 | AH167: 2.864 | AI167: 44.075143 | AJ167: 3.2475 | AK167: 37.869515 | AL167: 3.75 | AM167: 10.97778 | AN167: #NUM! | AO167: 32.1803 | AP167: 1.7713 | AQ167: 2.2075367 | AR167: 0.61363553 | AS167: 1 | AT167: 24.3193 | AU167: 6.2842 | AV167: 21246
A168: 2014.M10 | B168: mensual | C168: 83.4736 | D168: 1.1383828 | E168: 77.401 | F168: #NUM! | G168: 2.450419 | H168: 589.17773 | I168: 6.1440412 | J168: 2047.03 | K168: 5.8749 | L168: 43.9085 | M168: 1 | N168: 7.1463 | O168: 0.78909539 | P168: #NUM! | Q168: #NUM! | R168: #NUM! | S168: 61.342 | T168: 12144.87 | U168: 26687.824 | V168: #NUM! | W168: #NUM! | X168: 0.71 | Y168: 1060.28 | Z168: #NUM! | AA168: 3.2687881 | AB168: #NUM! | AC168: 13.4768 | AD168: 8.7263864 | AE168: #NUM! | AF168: 102.90656 | AG168: 4574.2663 | AH168: 2.9060455 | AI168: 44.797864 | AJ168: 3.3152 | AK168: 40.7589 | AL168: 3.75 | AM168: 11.0701 | AN168: #NUM! | AO168: 32.4485 | AP168: 1.8016 | AQ168: 2.2610419 | AR168: 0.62245663 | AS168: 1 | AT168: 24.3157 | AU168: 6.2842 | AV168: 21246
A169: 2014.M11 | B169: mensual | C169: 84.7706 | D169: 1.1560226 | E169: 77.8522 | F169: #NUM! | G169: 2.5463667 | H169: 592.4595 | I169: 6.1443167 | J169: 2127.25 | K169: 5.9666 | L169: 44.1474 | M169: 1 | N169: 7.1454 | O169: 0.80178317 | P169: #NUM! | Q169: #NUM! | R169: #NUM! | S169: 61.7042 | T169: 12158.3 | U169: 26776.909 | V169: #NUM! | W169: #NUM! | X169: 0.71 | Y169: 1095.1 | Z169: #NUM! | AA169: 3.34405 | AB169: #NUM! | AC169: 13.5819 | AD169: 8.8435611 | AE169: #NUM! | AF169: 101.9233 | AG169: 4641.8835 | AH169: 2.925075 | AI169: 44.9514 | AJ169: 3.3777 | AK169: 45.864897 | AL169: 3.75 | AM169: 11.104922 | AN169: #NUM! | AO169: 32.7814 | AP169: 1.8338 | AQ169: 2.234215 | AR169: 0.62496094 | AS169: 1 | AT169: 23.9929 | AU169: 6.2842 | AV169: 21246
A170: 2014.M12 | B170: mensual | C170: 86.9862 | D170: 1.2131122 | E170: 77.8522 | F170: #NUM! | G170: 2.6327 | H170: 612.919 | I170: 6.124219 | J170: 2344.23 | K170: 6.026 | L170: 44.2607 | M170: 1 | N170: 7.145 | O170: 0.81094231 | P170: #NUM! | Q170: #NUM! | R170: #NUM! | S170: 62.75295 | T170: 12438.29 | U170: 26958.235 | V170: #NUM! | W170: #NUM! | X170: 0.71 | Y170: 1104.33 | Z170: #NUM! | AA170: 3.4802727 | AB170: #NUM! | AC170: 14.4266 | AD170: 8.9314435 | AE170: #NUM! | AF170: 100.9392 | AG170: 4629.2905 | AH170: 2.9615 | AI170: 44.687765 | AJ170: 3.4287 | AK170: 55.4131 | AL170: 3.75 | AM170: 11.460529 | AN170: #NUM! | AO170: 32.9016 | AP170: 1.8562 | AQ170: 2.2899597 | AR170: 0.63661828 | AS170: 1 | AT170: 24.1068 | AU170: 6.2842 | AV170: 21246
...

Sheet TC_$
A1: Tipo de cambio de socios comerciales (expresado en pesos S$C 1 = ARS x) | H1: En este color TC de países eurozona | L1: Falta VENEZUELA desde 2018.m6 | O1: Falta IRAN desde 2024.m6 | R1: Desde 2025.m7 hacia atrás están todos los demas
A2: fecha | B2: ARS / USD | C2: Algeria | D2: Australia | E2: Bangladesh | F2: Belgium | G2: Brazil | H2: Chile | I2: China, People's Republic of | J2: Colombia | K2: Denmark | L2: Dominican Republic | M2: Ecuador | N2: Egypt, Arab Republic of | O2: Euro Area (EA) | P2: France | Q2: Germany | R2: Greece | S2: India | T2: Indonesia | U2: Iran, Islamic Republic of | V2: Ireland | W2: Italy | X2: Jordan | Y2: Korea, Republic of | Z2: Latvia, Republic of | AA2: Malaysia | AB2: Malta | AC2: Mexico | AD2: Morocco | AE2: Netherlands, The | AF2: Pakistan | AG2: Paraguay | AH2: Peru | AI2: Philippines | AJ2: Poland, Republic of | AK2: Russian Federation | AL2: Saudi Arabia | AM2: South Africa | AN2: Spain | AO2: Thailand | AP2: Tunisia | AQ2: Türkiye, Republic of | AR2: United Kingdom | AS2: United States | AT2: Uruguay | AU2: Venezuela, República Bolivariana de | AV2: Vietnam
A3: 2001.M01 | B3: 1 | C3: =$B3/'TC_u$d'!C3 -> 0.013366714 | D3: =$B3/'TC_u$d'!D3 -> 0.55566051 | E3: =$B3/'TC_u$d'!E3 -> 0.018518519 | F3: =O3 -> 0.93828182 | G3: =$B3/'TC_u$d'!G3 -> 0.51184693 | H3: =$B3/'TC_u$d'!H3 -> 0.0017509455 | I3: =$B3/'TC_u$d'!I3 -> 0.12080782 | J3: =$B3/'TC_u$d'!J3 -> 0.00044614973 | K3: =$B3/'TC_u$d'!K3 -> 0.12577635 | L3: =$B3/'TC_u$d'!L3 -> 0.060171763 | M3: =$B3/'TC_u$d'!M3 -> 1 | N3: =$B3/'TC_u$d'!N3 -> 0.27027027 | O3: =$B3/'TC_u$d'!O3 -> 0.93828182 | P3: =O3 -> 0.93828182 | Q3: =O3 -> 0.93828182 | R3: =O3 -> 0.93828182 | S3: =$B3/'TC_u$d'!S3 -> 0.021486893 | T3: =$B3/'TC_u$d'!T3 -> 0.0001054074 | U3: =$B3/'TC_u$d'!U3 -> 0.00056975646 | V3: =O3 -> 0.93828182 | W3: =O3 -> 0.93828182 | X3: =$B3/'TC_u$d'!X3 -> 1.4104372 | Y3: =$B3/'TC_u$d'!Y3 -> 0.00078565704 | Z3: =$B3/'TC_u$d'!Z3 -> 1.6286645 | AA3: =$B3/'TC_u$d'!AA3 -> 0.26315789 | AB3: =$B3/'TC_u$d'!AB3 -> 2.2899015 | AC3: =$B3/'TC_u$d'!AC3 -> 0.1023531 | AD3: =$B3/'TC_u$d'!AD3 -> 0.094428706 | AE3: =O3 -> 0.93828182 | AF3: =$B3/'TC_u$d'!AF3 -> 0.016926193 | AG3: =$B3/'TC_u$d'!AG3 -> 0.00028011204 | AH3: =$B3/'TC_u$d'!AH3 -> 0.28384899 | AI3: =$B3/'TC_u$d'!AI3 -> 0.019619769 | AJ3: =$B3/'TC_u$d'!AJ3 -> 0.24313153 | AK3: =$B3/'TC_u$d'!AK3 -> 0.035261926 | AL3: =$B3/'TC_u$d'!AL3 -> 0.26666667 | AM3: =$B3/'TC_u$d'!AM3 -> 0.128484 | AN3: =O3 -> 0.93828182 | AO3: =$B3/'TC_u$d'!AO3 -> 0.023213759 | AP3: =$B3/'TC_u$d'!AP3 -> 0.72711408 | AQ3: =$B3/'TC_u$d'!AQ3 -> 1.4878871 | AR3: =$B3/'TC_u$d'!AR3 -> 1.4781966 | AS3: =$B3/'TC_u$d'!AS3 -> 1 | AT3: =$B3/'TC_u$d'!AT3 -> 0.079611496 | AU3: =$B3/'TC_u$d'!AU3 -> 1.4291839 | AV3: =$B3/'TC_u$d'!AV3 -> 6.8804183e-05
A4: 2001.M02 | B4: 1 | C4: =$B4/'TC_u$d'!C4 -> 0.013202192 | D4: =$B4/'TC_u$d'!D4 -> 0.53490238 | E4: =$B4/'TC_u$d'!E4 -> 0.018518519 | F4: =O4 -> 0.921705 | G4: =$B4/'TC_u$d'!G4 -> 0.49973625 | H4: =$B4/'TC_u$d'!H4 -> 0.0017757889 | I4: =$B4/'TC_u$d'!I4 -> 0.12081585 | J4: =$B4/'TC_u$d'!J4 -> 0.00044574801 | K4: =$B4/'TC_u$d'!K4 -> 0.12353411 | L4: =$B4/'TC_u$d'!L4 -> 0.06002401 | M4: =$B4/'TC_u$d'!M4 -> 1 | N4: =$B4/'TC_u$d'!N4 -> 0.26041667 | O4: =$B4/'TC_u$d'!O4 -> 0.921705 | P4: =O4 -> 0.921705 | Q4: =O4 -> 0.921705 | R4: =O4 -> 0.921705 | S4: =$B4/'TC_u$d'!S4 -> 0.021496644 | T4: =$B4/'TC_u$d'!T4 -> 0.00010337734 | U4: =$B4/'TC_u$d'!U4 -> 0.00056963013 | V4: =O4 -> 0.921705 | W4: =O4 -> 0.921705 | X4: =$B4/'TC_u$d'!X4 -> 1.4104372 | Y4: =$B4/'TC_u$d'!Y4 -> 0.00079844144 | Z4: =$B4/'TC_u$d'!Z4 -> 1.618123 | AA4: =$B4/'TC_u$d'!AA4 -> 0.26315789 | AB4: =$B4/'TC_u$d'!AB4 -> 2.2601935 | AC4: =$B4/'TC_u$d'!AC4 -> 0.1030641 | AD4: =$B4/'TC_u$d'!AD4 -> 0.093511254 | AE4: =O4 -> 0.921705 | AF4: =$B4/'TC_u$d'!AF4 -> 0.016764451 | AG4: =$B4/'TC_u$d'!AG4 -> 0.00027072392 | AH4: =$B4/'TC_u$d'!AH4 -> 0.28328612 | AI4: =$B4/'TC_u$d'!AI4 -> 0.020708221 | AJ4: =$B4/'TC_u$d'!AJ4 -> 0.2444928 | AK4: =$B4/'TC_u$d'!AK4 -> 0.034972127 | AL4: =$B4/'TC_u$d'!AL4 -> 0.26666667 | AM4: =$B4/'TC_u$d'!AM4 -> 0.12795005 | AN4: =O4 -> 0.921705 | AO4: =$B4/'TC_u$d'!AO4 -> 0.023480241 | AP4: =$B4/'TC_u$d'!AP4 -> 0.71978694 | AQ4: =$B4/'TC_u$d'!AQ4 -> 1.3157652 | AR4: =$B4/'TC_u$d'!AR4 -> 1.4537631 | AS4: =$B4/'TC_u$d'!AS4 -> 1 | AT4: =$B4/'TC_u$d'!AT4 -> 0.079444524 | AU4: =$B4/'TC_u$d'!AU4 -> 1.4232849 | AV4: =$B4/'TC_u$d'!AV4 -> 6.8695473e-05
A5: 2001.M03 | B5: 1 | C5: =$B5/'TC_u$d'!C5 -> 0.013079829 | D5: =$B5/'TC_u$d'!D5 -> 0.50482359 | E5: =$B5/'TC_u$d'!E5 -> 0.018518519 | F5: =O5 -> 0.90952273 | G5: =$B5/'TC_u$d'!G5 -> 0.47886987 | H5: =$B5/'TC_u$d'!H5 -> 0.0017012879 | I5: =$B5/'TC_u$d'!I5 -> 0.12080899 | J5: =$B5/'TC_u$d'!J5 -> 0.0004388313 | K5: =$B5/'TC_u$d'!K5 -> 0.12185062 | L5: =$B5/'TC_u$d'!L5 -> 0.06002401 | M5: =$B5/'TC_u$d'!M5 -> 1 | N5: =$B5/'TC_u$d'!N5 -> 0.26041667 | O5: =$B5/'TC_u$d'!O5 -> 0.90952273 | P5: =O5 -> 0.90952273 | Q5: =O5 -> 0.90952273 | R5: =O5 -> 0.90952273 | S5: =$B5/'TC_u$d'!S5 -> 0.021449791 | T5: =$B5/'TC_u$d'!T5 -> 9.8243408e-05 | U5: =$B5/'TC_u$d'!U5 -> 0.00056922054 | V5: =O5 -> 0.90952273 | W5: =O5 -> 0.90952273 | X5: =$B5/'TC_u$d'!X5 -> 1.4104372 | Y5: =$B5/'TC_u$d'!Y5 -> 0.0007761384 | Z5: =$B5/'TC_u$d'!Z5 -> 1.6025641 | AA5: =$B5/'TC_u$d'!AA5 -> 0.26315789 | AB5: =$B5/'TC_u$d'!AB5 -> 2.2435001 | AC5: =$B5/'TC_u$d'!AC5 -> 0.1039728 | AD5: =$B5/'TC_u$d'!AD5 -> 0.09251464 | AE5: =O5 -> 0.90952273 | AF5: =$B5/'TC_u$d'!AF5 -> 0.016514028 | AG5: =$B5/'TC_u$d'!AG5 -> 0.00026649611 | AH5: =$B5/'TC_u$d'!AH5 -> 0.28409091 | AI5: =$B5/'TC_u$d'!AI5 -> 0.020632595 | AJ5: =$B5/'TC_u$d'!AJ5 -> 0.24612961 | AK5: =$B5/'TC_u$d'!AK5 -> 0.034871273 | AL5: =$B5/'TC_u$d'!AL5 -> 0.26666667 | AM5: =$B5/'TC_u$d'!AM5 -> 0.12692465 | AN5: =O5 -> 0.90952273 | AO5: =$B5/'TC_u$d'!AO5 -> 0.022808138 | AP5: =$B5/'TC_u$d'!AP5 -> 0.71093417 | AQ5: =$B5/'TC_u$d'!AQ5 -> 1.0431488 | AR5: =$B5/'TC_u$d'!AR5 -> 1.4449823 | AS5: =$B5/'TC_u$d'!AS5 -> 1 | AT5: =$B5/'TC_u$d'!AT5 -> 0.078193419 | AU5: =$B5/'TC_u$d'!AU5 -> 1.4174344 | AV5: =$B5/'TC_u$d'!AV5 -> 6.8719076e-05
A6: 2001.M04 | B6: 1 | C6: =$B6/'TC_u$d'!C6 -> 0.012923687 | D6: =$B6/'TC_u$d'!D6 -> 0.50098192 | E6: =$B6/'TC_u$d'!E6 -> 0.018518519 | F6: =O6 -> 0.892 | G6: =$B6/'TC_u$d'!G6 -> 0.45627619 | H6: =$B6/'TC_u$d'!H6 -> 0.0016704809 | I6: =$B6/'TC_u$d'!I6 -> 0.12081526 | J6: =$B6/'TC_u$d'!J6 -> 0.0004304593 | K6: =$B6/'TC_u$d'!K6 -> 0.11962839 | L6: =$B6/'TC_u$d'!L6 -> 0.06002401 | M6: =$B6/'TC_u$d'!M6 -> 1 | N6: =$B6/'TC_u$d'!N6 -> 0.26041667 | O6: =$B6/'TC_u$d'!O6 -> 0.892 | P6: =O6 -> 0.892 | Q6: =O6 -> 0.892 | R6: =O6 -> 0.892 | S6: =$B6/'TC_u$d'!S6 -> 0.021373915 | T6: =$B6/'TC_u$d'!T6 -> 8.942944e-05 | U6: =$B6/'TC_u$d'!U6 -> 0.00057096318 | V6: =O6 -> 0.892 | W6: =O6 -> 0.892 | X6: =$B6/'TC_u$d'!X6 -> 1.4104372 | Y6: =$B6/'TC_u$d'!Y6 -> 0.00075440383 | Z6: =$B6/'TC_u$d'!Z6 -> 1.5873016 | AA6: =$B6/'TC_u$d'!AA6 -> 0.26315789 | AB6: =$B6/'TC_u$d'!AB6 -> 2.2165999 | AC6: =$B6/'TC_u$d'!AC6 -> 0.10694272 | AD6: =$B6/'TC_u$d'!AD6 -> 0.090577249 | AE6: =O6 -> 0.892 | AF6: =$B6/'TC_u$d'!AF6 -> 0.016374084 | AG6: =$B6/'TC_u$d'!AG6 -> 0.00026403337 | AH6: =$B6/'TC_u$d'!AH6 -> 0.2809778 | AI6: =$B6/'TC_u$d'!AI6 -> 0.019926273 | AJ6: =$B6/'TC_u$d'!AJ6 -> 0.24891101 | AK6: =$B6/'TC_u$d'!AK6 -> 0.034666371 | AL6: =$B6/'TC_u$d'!AL6 -> 0.26666667 | AM6: =$B6/'TC_u$d'!AM6 -> 0.12372976 | AN6: =O6 -> 0.892 | AO6: =$B6/'TC_u$d'!AO6 -> 0.022020126 | AP6: =$B6/'TC_u$d'!AP6 -> 0.69993701 | AQ6: =$B6/'TC_u$d'!AQ6 -> 0.83040064 | AR6: =$B6/'TC_u$d'!AR6 -> 1.4347614 | AS6: =$B6/'TC_u$d'!AS6 -> 1 | AT6: =$B6/'TC_u$d'!AT6 -> 0.07750436 | AU6: =$B6/'TC_u$d'!AU6 -> 1.4092446 | AV6: =$B6/'TC_u$d'!AV6 -> 6.8695473e-05
A7: 2001.M05 | B7: 1 | C7: =$B7/'TC_u$d'!C7 -> 0.012765262 | D7: =$B7/'TC_u$d'!D7 -> 0.51995591 | E7: =$B7/'TC_u$d'!E7 -> 0.018288222 | F7: =O7 -> 0.87416364 | G7: =$B7/'TC_u$d'!G7 -> 0.43545817 | H7: =$B7/'TC_u$d'!H7 -> 0.0016543145 | I7: =$B7/'TC_u$d'!I7 -> 0.12081307 | J7: =$B7/'TC_u$d'!J7 -> 0.00042608855 | K7: =$B7/'TC_u$d'!K7 -> 0.1172993 | L7: =$B7/'TC_u$d'!L7 -> 0.06002401 | M7: =$B7/'TC_u$d'!M7 -> 1 | N7: =$B7/'TC_u$d'!N7 -> 0.26034887 | O7: =$B7/'TC_u$d'!O7 -> 0.87416364 | P7: =O7 -> 0.87416364 | Q7: =O7 -> 0.87416364 | R7: =O7 -> 0.87416364 | S7: =$B7/'TC_u$d'!S7 -> 0.021314113 | T7: =$B7/'TC_u$d'!T7 -> 8.9047195e-05 | U7: =$B7/'TC_u$d'!U7 -> 0.00056998166 | V7: =O7 -> 0.87416364 | W7: =O7 -> 0.87416364 | X7: =$B7/'TC_u$d'!X7 -> 1.4104372 | Y7: =$B7/'TC_u$d'!Y7 -> 0.00077014309 | Z7: =$B7/'TC_u$d'!Z7 -> 1.5797788 | AA7: =$B7/'TC_u$d'!AA7 -> 0.26315789 | AB7: =$B7/'TC_u$d'!AB7 -> 2.1904001 | AC7: =$B7/'TC_u$d'!AC7 -> 0.10932905 | AD7: =$B7/'TC_u$d'!AD7 -> 0.085722858 | AE7: =O7 -> 0.87416364 | AF7: =$B7/'TC_u$d'!AF7 -> 0.016165174 | AG7: =$B7/'TC_u$d'!AG7 -> 0.00026164996 | AH7: =$B7/'TC_u$d'!AH7 -> 0.27777778 | AI7: =$B7/'TC_u$d'!AI7 -> 0.019786699 | AJ7: =$B7/'TC_u$d'!AJ7 -> 0.25121841 | AK7: =$B7/'TC_u$d'!AK7 -> 0.034461013 | AL7: =$B7/'TC_u$d'!AL7 -> 0.26666667 | AM7: =$B7/'TC_u$d'!AM7 -> 0.12542661 | AN7: =O7 -> 0.87416364 | AO7: =$B7/'TC_u$d'!AO7 -> 0.022009222 | AP7: =$B7/'TC_u$d'!AP7 -> 0.68615342 | AQ7: =$B7/'TC_u$d'!AQ7 -> 0.88287436 | AR7: =$B7/'TC_u$d'!AR7 -> 1.4251917 | AS7: =$B7/'TC_u$d'!AS7 -> 1 | AT7: =$B7/'TC_u$d'!AT7 -> 0.07655854 | AU7: =$B7/'TC_u$d'!AU7 -> 1.399776 | AV7: =$B7/'TC_u$d'!AV7 -> 6.8474391e-05
A8: 2001.M06 | B8: 1 | C8: =$B8/'TC_u$d'!C8 -> 0.0126308 | D8: =$B8/'TC_u$d'!D8 -> 0.51811324 | E8: =$B8/'TC_u$d'!E8 -> 0.01754386 | F8: =O8 -> 0.85316667 | G8: =$B8/'TC_u$d'!G8 -> 0.4210482 | H8: =$B8/'TC_u$d'!H8 -> 0.0016231922 | I8: =$B8/'TC_u$d'!I8 -> 0.12081614 | J8: =$B8/'TC_u$d'!J8 -> 0.00043371529 | K8: =$B8/'TC_u$d'!K8 -> 0.11465405 | L8: =$B8/'TC_u$d'!L8 -> 0.06002401 | M8: =$B8/'TC_u$d'!M8 -> 1 | N8: =$B8/'TC_u$d'!N8 -> 0.25974026 | O8: =$B8/'TC_u$d'!O8 -> 0.85316667 | P8: =O8 -> 0.85316667 | Q8: =O8 -> 0.85316667 | R8: =O8 -> 0.85316667 | S8: =$B8/'TC_u$d'!S8 -> 0.021274215 | T8: =$B8/'TC_u$d'!T8 -> 8.8393883e-05 | U8: =$B8/'TC_u$d'!U8 -> 0.00057011318 | V8: =O8 -> 0.85316667 | W8: =O8 -> 0.85316667 | X8: =$B8/'TC_u$d'!X8 -> 1.4104372 | Y8: =$B8/'TC_u$d'!Y8 -> 0.00077289907 | Z8: =$B8/'TC_u$d'!Z8 -> 1.5649452 | AA8: =$B8/'TC_u$d'!AA8 -> 0.26315789 | AB8: =$B8/'TC_u$d'!AB8 -> 2.1557002 | AC8: =$B8/'TC_u$d'!AC8 -> 0.10994206 | AD8: =$B8/'TC_u$d'!AD8 -> 0.084169416 | AE8: =O8 -> 0.85316667 | AF8: =$B8/'TC_u$d'!AF8 -> 0.015765008 | AG8: =$B8/'TC_u$d'!AG8 -> 0.00025585263 | AH8: =$B8/'TC_u$d'!AH8 -> 0.28320589 | AI8: =$B8/'TC_u$d'!AI8 -> 0.019422001 | AJ8: =$B8/'TC_u$d'!AJ8 -> 0.25185745 | AK8: =$B8/'TC_u$d'!AK8 -> 0.034347265 | AL8: =$B8/'TC_u$d'!AL8 -> 0.26666667 | AM8: =$B8/'TC_u$d'!AM8 -> 0.12416884 | AN8: =O8 -> 0.85316667 | AO8: =$B8/'TC_u$d'!AO8 -> 0.022123111 | AP8: =$B8/'TC_u$d'!AP8 -> 0.66920966 | AQ8: =$B8/'TC_u$d'!AQ8 -> 0.82431872 | AR8: =$B8/'TC_u$d'!AR8 -> 1.4010508 | AS8: =$B8/'TC_u$d'!AS8 -> 1 | AT8: =$B8/'TC_u$d'!AT8 -> 0.074825656 | AU8: =$B8/'TC_u$d'!AU8 -> 1.3952839 | AV8: =$B8/'TC_u$d'!AV8 -> 6.7709391e-05
A9: 2001.M07 | B9: 1 | C9: =$B9/'TC_u$d'!C9 -> 0.012601108 | D9: =$B9/'TC_u$d'!D9 -> 0.51013121 | E9: =$B9/'TC_u$d'!E9 -> 0.01754386 | F9: =O9 -> 0.86066364 | G9: =$B9/'TC_u$d'!G9 -> 0.40564286 | H9: =$B9/'TC_u$d'!H9 -> 0.0015233221 | I9: =$B9/'TC_u$d'!I9 -> 0.12081833 | J9: =$B9/'TC_u$d'!J9 -> 0.00043397504 | K9: =$B9/'TC_u$d'!K9 -> 0.11551266 | L9: =$B9/'TC_u$d'!L9 -> 0.06002401 | M9: =$B9/'TC_u$d'!M9 -> 1 | N9: =$B9/'TC_u$d'!N9 -> 0.25974026 | O9: =$B9/'TC_u$d'!O9 -> 0.86066364 | P9: =O9 -> 0.86066364 | Q9: =O9 -> 0.86066364 | R9: =O9 -> 0.86066364 | S9: =$B9/'TC_u$d'!S9 -> 0.021212588 | T9: =$B9/'TC_u$d'!T9 -> 9.3396843e-05 | U9: =$B9/'TC_u$d'!U9 -> 0.00057062206 | V9: =O9 -> 0.86066364 | W9: =O9 -> 0.86066364 | X9: =$B9/'TC_u$d'!X9 -> 1.4104372 | Y9: =$B9/'TC_u$d'!Y9 -> 0.00076769538 | Z9: =$B9/'TC_u$d'!Z9 -> 1.5649452 | AA9: =$B9/'TC_u$d'!AA9 -> 0.26315789 | AB9: =$B9/'TC_u$d'!AB9 -> 2.1682567 | AC9: =$B9/'TC_u$d'!AC9 -> 0.109218 | AD9: =$B9/'TC_u$d'!AD9 -> 0.084650352 | AE9: =O9 -> 0.86066364 | AF9: =$B9/'TC_u$d'!AF9 -> 0.015597225 | AG9: =$B9/'TC_u$d'!AG9 -> 0.0002393547 | AH9: =$B9/'TC_u$d'!AH9 -> 0.2854696 | AI9: =$B9/'TC_u$d'!AI9 -> 0.018788516 | AJ9: =$B9/'TC_u$d'!AJ9 -> 0.23889725 | AK9: =$B9/'TC_u$d'!AK9 -> 0.034226297 | AL9: =$B9/'TC_u$d'!AL9 -> 0.26666667 | AM9: =$B9/'TC_u$d'!AM9 -> 0.12269909 | AN9: =O9 -> 0.86066364 | AO9: =$B9/'TC_u$d'!AO9 -> 0.021944839 | AP9: =$B9/'TC_u$d'!AP9 -> 0.67340067 | AQ9: =$B9/'TC_u$d'!AQ9 -> 0.75668493 | AR9: =$B9/'TC_u$d'!AR9 -> 1.4137873 | AS9: =$B9/'TC_u$d'!AS9 -> 1 | AT9: =$B9/'TC_u$d'!AT9 -> 0.07350455 | AU9: =$B9/'TC_u$d'!AU9 -> 1.3850416 | AV9: =$B9/'TC_u$d'!AV9 -> 6.712761e-05
A10: 2001.M08 | B10: 1 | C10: =$B10/'TC_u$d'!C10 -> 0.012993628 | D10: =$B10/'TC_u$d'!D10 -> 0.52478563 | E10: =$B10/'TC_u$d'!E10 -> 0.01754386 | F10: =O10 -> 0.90048261 | G10: =$B10/'TC_u$d'!G10 -> 0.39843329 | H10: =$B10/'TC_u$d'!H10 -> 0.0014843402 | I10: =$B10/'TC_u$d'!I10 -> 0.12081716 | J10: =$B10/'TC_u$d'!J10 -> 0.00043689108 | K10: =$B10/'TC_u$d'!K10 -> 0.12095233 | L10: =$B10/'TC_u$d'!L10 -> 0.06002401 | M10: =$B10/'TC_u$d'!M10 -> 1 | N10: =$B10/'TC_u$d'!N10 -> 0.24154589 | O10: =$B10/'TC_u$d'!O10 -> 0.90048261 | P10: =O10 -> 0.90048261 | Q10: =O10 -> 0.90048261 | R10: =O10 -> 0.90048261 | S10: =$B10/'TC_u$d'!S10 -> 0.021219565 | T10: =$B10/'TC_u$d'!T10 -> 0.00011326568 | U10: =$B10/'TC_u$d'!U10 -> 0.00057123794 | V10: =O10 -> 0.90048261 | W10: =O10 -> 0.90048261 | X10: =$B10/'TC_u$d'!X10 -> 1.4104372 | Y10: =$B10/'TC_u$d'!Y10 -> 0.000777974 | Z10: =$B10/'TC_u$d'!Z10 -> 1.5923567 | AA10: =$B10/'TC_u$d'!AA10 -> 0.26315789 | AB10: =$B10/'TC_u$d'!AB10 -> 2.2276 | AC10: =$B10/'TC_u$d'!AC10 -> 0.10957583 | AD10: =$B10/'TC_u$d'!AD10 -> 0.087535014 | AE10: =O10 -> 0.90048261 | AF10: =$B10/'TC_u$d'!AF10 -> 0.015593508 | AG10: =$B10/'TC_u$d'!AG10 -> 0.00023351392 | AH10: =$B10/'TC_u$d'!AH10 -> 0.28645087 | AI10: =$B10/'TC_u$d'!AI10 -> 0.019235208 | AJ10: =$B10/'TC_u$d'!AJ10 -> 0.23552133 | AK10: =$B10/'TC_u$d'!AK10 -> 0.034077123 | AL10: =$B10/'TC_u$d'!AL10 -> 0.26666667 | AM10: =$B10/'TC_u$d'!AM10 -> 0.12028078 | AN10: =O10 -> 0.90048261 | AO10: =$B10/'TC_u$d'!AO10 -> 0.022288841 | AP10: =$B10/'TC_u$d'!AP10 -> 0.69483046 | AQ10: =$B10/'TC_u$d'!AQ10 -> 0.7143199 | AR10: =$B10/'TC_u$d'!AR10 -> 1.4368848 | AS10: =$B10/'TC_u$d'!AS10 -> 1 | AT10: =$B10/'TC_u$d'!AT10 -> 0.074692082 | AU10: =$B10/'TC_u$d'!AU10 -> 1.3683634 | AV10: =$B10/'TC_u$d'!AV10 -> 6.6760131e-05
A11: 2001.M09 | B11: 1 | C11: =$B11/'TC_u$d'!C11 -> 0.013079641 | D11: =$B11/'TC_u$d'!D11 -> 0.50625478 | E11: =$B11/'TC_u$d'!E11 -> 0.01754386 | F11: =O11 -> 0.911095 | G11: =$B11/'TC_u$d'!G11 -> 0.3744108 | H11: =$B11/'TC_u$d'!H11 -> 0.0014679115 | I11: =$B11/'TC_u$d'!I11 -> 0.12081949 | J11: =$B11/'TC_u$d'!J11 -> 0.00042951083 | K11: =$B11/'TC_u$d'!K11 -> 0.12239153 | L11: =$B11/'TC_u$d'!L11 -> 0.06002401 | M11: =$B11/'TC_u$d'!M11 -> 1 | N11: =$B11/'TC_u$d'!N11 -> 0.24154589 | O11: =$B11/'TC_u$d'!O11 -> 0.911095 | P11: =O11 -> 0.911095 | Q11: =O11 -> 0.911095 | R11: =O11 -> 0.911095 | S11: =$B11/'TC_u$d'!S11 -> 0.020988121 | T11: =$B11/'TC_u$d'!T11 -> 0.00010745178 | U11: =$B11/'TC_u$d'!U11 -> 0.00057020386 | V11: =O11 -> 0.911095 | W11: =O11 -> 0.911095 | X11: =$B11/'TC_u$d'!X11 -> 1.4104372 | Y11: =$B11/'TC_u$d'!Y11 -> 0.00077297673 | Z11: =$B11/'TC_u$d'!Z11 -> 1.607717 | AA11: =$B11/'TC_u$d'!AA11 -> 0.26315789 | AB11: =$B11/'TC_u$d'!AB11 -> 2.2492998 | AC11: =$B11/'TC_u$d'!AC11 -> 0.10656323 | AD11: =$B11/'TC_u$d'!AD11 -> 0.088356394 | AE11: =O11 -> 0.911095 | AF11: =$B11/'TC_u$d'!AF11 -> 0.015576834 | AG11: =$B11/'TC_u$d'!AG11 -> 0.00022697869 | AH11: =$B11/'TC_u$d'!AH11 -> 0.28653295 | AI11: =$B11/'TC_u$d'!AI11 -> 0.019512195 | AJ11: =$B11/'TC_u$d'!AJ11 -> 0.23705108 | AK11: =$B11/'TC_u$d'!AK11 -> 0.033980319 | AL11: =$B11/'TC_u$d'!AL11 -> 0.26666667 | AM11: =$B11/'TC_u$d'!AM11 -> 0.11578684 | AN11: =O11 -> 0.911095 | AO11: =$B11/'TC_u$d'!AO11 -> 0.022581672 | AP11: =$B11/'TC_u$d'!AP11 -> 0.69886086 | AQ11: =$B11/'TC_u$d'!AQ11 -> 0.6792583 | AR11: =$B11/'TC_u$d'!AR11 -> 1.462587 | AS11: =$B11/'TC_u$d'!AS11 -> 1 | AT11: =$B11/'TC_u$d'!AT11 -> 0.073620355 | AU11: =$B11/'TC_u$d'!AU11 -> 1.3460762 | AV11: =$B11/'TC_u$d'!AV11 -> 7.0927016e-05
A12: 2001.M10 | B12: 1 | C12: =$B12/'TC_u$d'!C12 -> 0.013037487 | D12: =$B12/'TC_u$d'!D12 -> 0.50485162 | E12: =$B12/'TC_u$d'!E12 -> 0.01754386 | F12: =O12 -> 0.90586522 | G12: =$B12/'TC_u$d'!G12 -> 0.36504707 | H12: =$B12/'TC_u$d'!H12 -> 0.0014122299 | I12: =$B12/'TC_u$d'!I12 -> 0.12081949 | J12: =$B12/'TC_u$d'!J12 -> 0.00043091375 | K12: =$B12/'TC_u$d'!K12 -> 0.12183429 | L12: =$B12/'TC_u$d'!L12 -> 0.06002401 | M12: =$B12/'TC_u$d'!M12 -> 1 | N12: =$B12/'TC_u$d'!N12 -> 0.24154589 | O12: =$B12/'TC_u$d'!O12 -> 0.90586522 | P12: =O12 -> 0.90586522 | Q12: =O12 -> 0.90586522 | R12: =O12 -> 0.90586522 | S12: =$B12/'TC_u$d'!S12 -> 0.020824448 | T12: =$B12/'TC_u$d'!T12 -> 9.8858188e-05 | U12: =$B12/'TC_u$d'!U12 -> 0.00056977252 | V12: =O12 -> 0.90586522 | W12: =O12 -> 0.90586522 | X12: =$B12/'TC_u$d'!X12 -> 1.4104372 | Y12: =$B12/'TC_u$d'!Y12 -> 0.00076769538 | Z12: =$B12/'TC_u$d'!Z12 -> 1.6 | AA12: =$B12/'TC_u$d'!AA12 -> 0.26315789 | AB12: =$B12/'TC_u$d'!AB12 -> 2.24 | AC12: =$B12/'TC_u$d'!AC12 -> 0.10674067 | AD12: =$B12/'TC_u$d'!AD12 -> 0.088035919 | AE12: =O12 -> 0.90586522 | AF12: =$B12/'TC_u$d'!AF12 -> 0.015957105 | AG12: =$B12/'TC_u$d'!AG12 -> 0.00021955343 | AH12: =$B12/'TC_u$d'!AH12 -> 0.28901734 | AI12: =$B12/'TC_u$d'!AI12 -> 0.019330021 | AJ12: =$B12/'TC_u$d'!AJ12 -> 0.24194329 | AK12: =$B12/'TC_u$d'!AK12 -> 0.033858822 | AL12: =$B12/'TC_u$d'!AL12 -> 0.26666667 | AM12: =$B12/'TC_u$d'!AM12 -> 0.10781555 | AN12: =O12 -> 0.90586522 | AO12: =$B12/'TC_u$d'!AO12 -> 0.022385036 | AP12: =$B12/'TC_u$d'!AP12 -> 0.69449267 | AQ12: =$B12/'TC_u$d'!AQ12 -> 0.62403781 | AR12: =$B12/'TC_u$d'!AR12 -> 1.4513367 | AS12: =$B12/'TC_u$d'!AS12 -> 1 | AT12: =$B12/'TC_u$d'!AT12 -> 0.071619386 | AU12: =$B12/'TC_u$d'!AU12 -> 1.3457139 | AV12: =$B12/'TC_u$d'!AV12 -> 6.6569032e-05
A13: 2001.M11 | B13: 1 | C13: =$B13/'TC_u$d'!C13 -> 0.012870941 | D13: =$B13/'TC_u$d'!D13 -> 0.51684662 | E13: =$B13/'TC_u$d'!E13 -> 0.01754386 | F13: =O13 -> 0.88830909 | G13: =$B13/'TC_u$d'!G13 -> 0.39335002 | H13: =$B13/'TC_u$d'!H13 -> 0.0014505367 | I13: =$B13/'TC_u$d'!I13 -> 0.12081847 | J13: =$B13/'TC_u$d'!J13 -> 0.00043281237 | K13: =$B13/'TC_u$d'!K13 -> 0.11931124 | L13: =$B13/'TC_u$d'!L13 -> 0.059669619 | M13: =$B13/'TC_u$d'!M13 -> 1 | N13: =$B13/'TC_u$d'!N13 -> 0.24154589 | O13: =$B13/'TC_u$d'!O13 -> 0.88830909 | P13: =O13 -> 0.88830909 | Q13: =O13 -> 0.88830909 | R13: =O13 -> 0.88830909 | S13: =$B13/'TC_u$d'!S13 -> 0.020834475 | T13: =$B13/'TC_u$d'!T13 -> 9.4553707e-05 | U13: =$B13/'TC_u$d'!U13 -> 0.00057018927 | V13: =O13 -> 0.88830909 | W13: =O13 -> 0.88830909 | X13: =$B13/'TC_u$d'!X13 -> 1.41064 | Y13: =$B13/'TC_u$d'!Y13 -> 0.0007788162 | Z13: =$B13/'TC_u$d'!Z13 -> 1.5873016 | AA13: =$B13/'TC_u$d'!AA13 -> 0.26315789 | AB13: =$B13/'TC_u$d'!AB13 -> 2.2119 | AC13: =$B13/'TC_u$d'!AC13 -> 0.10843282 | AD13: =$B13/'TC_u$d'!AD13 -> 0.086692674 | AE13: =O13 -> 0.88830909 | AF13: =$B13/'TC_u$d'!AF13 -> 0.016259317 | AG13: =$B13/'TC_u$d'!AG13 -> 0.00021507689 | AH13: =$B13/'TC_u$d'!AH13 -> 0.29069767 | AI13: =$B13/'TC_u$d'!AI13 -> 0.019234505 | AJ13: =$B13/'TC_u$d'!AJ13 -> 0.24424199 | AK13: =$B13/'TC_u$d'!AK13 -> 0.033562002 | AL13: =$B13/'TC_u$d'!AL13 -> 0.26666667 | AM13: =$B13/'TC_u$d'!AM13 -> 0.10252383 | AN13: =O13 -> 0.88830909 | AO13: =$B13/'TC_u$d'!AO13 -> 0.022536989 | AP13: =$B13/'TC_u$d'!AP13 -> 0.68549023 | AQ13: =$B13/'TC_u$d'!AQ13 -> 0.65818962 | AR13: =$B13/'TC_u$d'!AR13 -> 1.4363895 | AS13: =$B13/'TC_u$d'!AS13 -> 1 | AT13: =$B13/'TC_u$d'!AT13 -> 0.071664039 | AU13: =$B13/'TC_u$d'!AU13 -> 1.3428226 | AV13: =$B13/'TC_u$d'!AV13 -> 6.6387838e-05
A14: 2001.M12 | B14: 1 | C14: =$B14/'TC_u$d'!C14 -> 0.012901128 | D14: =$B14/'TC_u$d'!D14 -> 0.51409653 | E14: =$B14/'TC_u$d'!E14 -> 0.01754386 | F14: =O14 -> 0.89237222 | G14: =$B14/'TC_u$d'!G14 -> 0.42338795 | H14: =$B14/'TC_u$d'!H14 -> 0.0014944556 | I14: =$B14/'TC_u$d'!I14 -> 0.12081862 | J14: =$B14/'TC_u$d'!J14 -> 0.00043348216 | K14: =$B14/'TC_u$d'!K14 -> 0.12003952 | L14: =$B14/'TC_u$d'!L14 -> 0.058915368 | M14: =$B14/'TC_u$d'!M14 -> 1 | N14: =$B14/'TC_u$d'!N14 -> 0.22962113 | O14: =$B14/'TC_u$d'!O14 -> 0.89237222 | P14: =O14 -> 0.89237222 | Q14: =O14 -> 0.89237222 | R14: =O14 -> 0.89237222 | S14: =$B14/'TC_u$d'!S14 -> 0.020869394 | T14: =$B14/'TC_u$d'!T14 -> 9.4946023e-05 | U14: =$B14/'TC_u$d'!U14 -> 0.00056987649 | V14: =O14 -> 0.89237222 | W14: =O14 -> 0.89237222 | X14: =$B14/'TC_u$d'!X14 -> 1.4106362 | Y14: =$B14/'TC_u$d'!Y14 -> 0.00077539817 | Z14: =$B14/'TC_u$d'!Z14 -> 1.5797788 | AA14: =$B14/'TC_u$d'!AA14 -> 0.26315789 | AB14: =$B14/'TC_u$d'!AB14 -> 2.2181 | AC14: =$B14/'TC_u$d'!AC14 -> 0.10908456 | AD14: =$B14/'TC_u$d'!AD14 -> 0.086903624 | AE14: =O14 -> 0.89237222 | AF14: =$B14/'TC_u$d'!AF14 -> 0.016430114 | AG14: =$B14/'TC_u$d'!AG14 -> 0.000214275 | AH14: =$B14/'TC_u$d'!AH14 -> 0.29112082 | AI14: =$B14/'TC_u$d'!AI14 -> 0.019309157 | AJ14: =$B14/'TC_u$d'!AJ14 -> 0.24910323 | AK14: =$B14/'TC_u$d'!AK14 -> 0.033231865 | AL14: =$B14/'TC_u$d'!AL14 -> 0.26666667 | AM14: =$B14/'TC_u$d'!AM14 -> 0.086244071 | AN14: =O14 -> 0.89237222 | AO14: =$B14/'TC_u$d'!AO14 -> 0.022800026 | AP14: =$B14/'TC_u$d'!AP14 -> 0.6853352 | AQ14: =$B14/'TC_u$d'!AQ14 -> 0.68926491 | AR14: =$B14/'TC_u$d'!AR14 -> 1.4391595 | AS14: =$B14/'TC_u$d'!AS14 -> 1 | AT14: =$B14/'TC_u$d'!AT14 -> 0.071070175 | AU14: =$B14/'TC_u$d'!AU14 -> 1.3299641 | AV14: =$B14/'TC_u$d'!AV14 -> 6.6361404e-05
... A86: 2007.M12 | B86: 3.1397 | C86: =$B86/'TC_u$d'!C86 -> 0.046811029 | D86: =$B86/'TC_u$d'!D86 -> 2.740062 | E86: =$B86/'TC_u$d'!E86 -> 0.04577683 | F86: =O86 -> 4.5746586 | G86: =$B86/'TC_u$d'!G86 -> 1.7587385 | H86: =$B86/'TC_u$d'!H86 -> 0.0062884554 | I86: =$B86/'TC_u$d'!I86 -> 0.42589759 | J86: =$B86/'TC_u$d'!J86 -> 0.0015587815 | K86: =$B86/'TC_u$d'!K86 -> 0.61323463 | L86: =$B86/'TC_u$d'!L86 -> 0.093280531 | M86: =$B86/'TC_u$d'!M86 -> 3.1397 | N86: =$B86/'TC_u$d'!N86 -> 0.56878623 | O86: =$B86/'TC_u$d'!O86 -> 4.5746586 | P86: =O86 -> 4.5746586 | Q86: =O86 -> 4.5746586 | R86: =O86 -> 4.5746586 | S86: =$B86/'TC_u$d'!S86 -> 0.079608007 | T86: =$B86/'TC_u$d'!T86 -> 0.00033573216 | U86: =$B86/'TC_u$d'!U86 -> 0.00033514711 | V86: =O86 -> 4.5746586 | W86: =O86 -> 4.5746586 | X86: =$B86/'TC_u$d'!X86 -> 4.4283585 | Y86: =$B86/'TC_u$d'!Y86 -> 0.0033751505 | Z86: =$B86/'TC_u$d'!Z86 -> 6.5084992 | AA86: =$B86/'TC_u$d'!AA86 -> 0.94166963 | AB86: =$B86/'TC_u$d'!AB86 -> 10.767147 | AC86: =$B86/'TC_u$d'!AC86 -> 0.28938927 | AD86: =$B86/'TC_u$d'!AD86 -> 0.40381474 | AE86: =O86 -> 4.5746586 | AF86: =$B86/'TC_u$d'!AF86 -> 0.051284941 | AG86: =$B86/'TC_u$d'!AG86 -> 0.00066354587 | AH86: =$B86/'TC_u$d'!AH86 -> 1.0533078 | AI86: =$B86/'TC_u$d'!AI86 -> 0.075215206 | AJ86: =$B86/'TC_u$d'!AJ86 -> 1.2683607 | AK86: =$B86/'TC_u$d'!AK86 -> 0.12780717 | AL86: =$B86/'TC_u$d'!AL86 -> 0.83725333 | AM86: =$B86/'TC_u$d'!AM86 -> 0.46130338 | AN86: =O86 -> 4.5746586 | AO86: =$B86/'TC_u$d'!AO86 -> 0.093280677 | AP86: =$B86/'TC_u$d'!AP86 -> 2.5578004 | AQ86: =$B86/'TC_u$d'!AQ86 -> 2.6798211 | AR86: =$B86/'TC_u$d'!AR86 -> 6.3530959 | AS86: =$B86/'TC_u$d'!AS86 -> 3.1397 | AT86: =$B86/'TC_u$d'!AT86 -> 0.14473933 | AU86: =$B86/'TC_u$d'!AU86 -> 1.4623661 | AV86: =$B86/'TC_u$d'!AV86 -> 0.00019480673
A87: 2008.M01 | B87: 3.1444 | C87: =$B87/'TC_u$d'!C87 -> 0.047038479 | D87: =$B87/'TC_u$d'!D87 -> 2.7722772 | E87: =$B87/'TC_u$d'!E87 -> 0.045850236 | F87: =O87 -> 4.6278993 | G87: =$B87/'TC_u$d'!G87 -> 1.7729913 | H87: =$B87/'TC_u$d'!H87 -> 0.0065385735 | I87: =$B87/'TC_u$d'!I87 -> 0.43384139 | J87: =$B87/'TC_u$d'!J87 -> 0.0015876077 | K87: =$B87/'TC_u$d'!K87 -> 0.62112832 | L87: =$B87/'TC_u$d'!L87 -> 0.092771204 | M87: =$B87/'TC_u$d'!M87 -> 3.1444 | N87: =$B87/'TC_u$d'!N87 -> 0.57170909 | O87: =$B87/'TC_u$d'!O87 -> 4.6278993 | P87: =O87 -> 4.6278993 | Q87: =O87 -> 4.6278993 | R87: =O87 -> 4.6278993 | S87: =$B87/'TC_u$d'!S87 -> 0.079860414 | T87: =$B87/'TC_u$d'!T87 -> 0.00033469579 | U87: =$B87/'TC_u$d'!U87 -> 0.00033880781 | V87: =O87 -> 4.6278993 | W87: =O87 -> 4.6278993 | X87: =$B87/'TC_u$d'!X87 -> 4.4349876 | Y87: =$B87/'TC_u$d'!Y87 -> 0.0033366228 | Z87: =$B87/'TC_u$d'!Z87 -> 6.5713689 | AA87: =$B87/'TC_u$d'!AA87 -> 0.96220815 | AB87: =O87 -> 4.6278993 | AC87: =$B87/'TC_u$d'!AC87 -> 0.28802521 | AD87: =$B87/'TC_u$d'!AD87 -> 0.40743236 | AE87: =O87 -> 4.6278993 | AF87: =$B87/'TC_u$d'!AF87 -> 0.051361713 | AG87: =$B87/'TC_u$d'!AG87 -> 0.00066719005 | AH87: =$B87/'TC_u$d'!AH87 -> 1.0657899 | AI87: =$B87/'TC_u$d'!AI87 -> 0.076808662 | AJ87: =$B87/'TC_u$d'!AJ87 -> 1.2814933 | AK87: =$B87/'TC_u$d'!AK87 -> 0.1283371 | AL87: =$B87/'TC_u$d'!AL87 -> 0.83850667 | AM87: =$B87/'TC_u$d'!AM87 -> 0.44836092 | AN87: =O87 -> 4.6278993 | AO87: =$B87/'TC_u$d'!AO87 -> 0.094870606 | AP87: =$B87/'TC_u$d'!AP87 -> 2.5852175 | AQ87: =$B87/'TC_u$d'!AQ87 -> 2.6838327 | AR87: =$B87/'TC_u$d'!AR87 -> 6.1932993 | AS87: =$B87/'TC_u$d'!AS87 -> 3.1444 | AT87: =$B87/'TC_u$d'!AT87 -> 0.14832215 | AU87: =$B87/'TC_u$d'!AU87 -> 1.4645552 | AV87: =$B87/'TC_u$d'!AV87 -> 0.00019525584
A88: 2008.M02 | B88: 3.1583 | C88: =$B88/'TC_u$d'!C88 -> 0.047301962 | D88: =$B88/'TC_u$d'!D88 -> 2.8837392 | E88: =$B88/'TC_u$d'!E88 -> 0.046052852 | F88: =O88 -> 4.6579812 | G88: =$B88/'TC_u$d'!G88 -> 1.8288841 | H88: =$B88/'TC_u$d'!H88 -> 0.0067597706 | I88: =$B88/'TC_u$d'!I88 -> 0.44079307 | J88: =$B88/'TC_u$d'!J88 -> 0.0016594072 | K88: =$B88/'TC_u$d'!K88 -> 0.6247997 | L88: =$B88/'TC_u$d'!L88 -> 0.093011188 | M88: =$B88/'TC_u$d'!M88 -> 3.1583 | N88: =$B88/'TC_u$d'!N88 -> 0.57423636 | O88: =$B88/'TC_u$d'!O88 -> 4.6579812 | P88: =O88 -> 4.6579812 | Q88: =O88 -> 4.6579812 | R88: =O88 -> 4.6579812 | S88: =$B88/'TC_u$d'!S88 -> 0.079488883 | T88: =$B88/'TC_u$d'!T88 -> 0.00034464208 | U88: =$B88/'TC_u$d'!U88 -> 0.00033876919 | V88: =O88 -> 4.6579812 | W88: =O88 -> 4.6579812 | X88: =$B88/'TC_u$d'!X88 -> 4.4545839 | Y88: =$B88/'TC_u$d'!Y88 -> 0.0033432131 | Z88: =$B88/'TC_u$d'!Z88 -> 6.618399 | AA88: =$B88/'TC_u$d'!AA88 -> 0.98013841 | AB88: =O88 -> 4.6579812 | AC88: =$B88/'TC_u$d'!AC88 -> 0.29299404 | AD88: =$B88/'TC_u$d'!AD88 -> 0.40978034 | AE88: =O88 -> 4.6579812 | AF88: =$B88/'TC_u$d'!AF88 -> 0.05158876 | AG88: =$B88/'TC_u$d'!AG88 -> 0.00067446132 | AH88: =$B88/'TC_u$d'!AH88 -> 1.0870074 | AI88: =$B88/'TC_u$d'!AI88 -> 0.077654649 | AJ88: =$B88/'TC_u$d'!AJ88 -> 1.2994446 | AK88: =$B88/'TC_u$d'!AK88 -> 0.12872788 | AL88: =$B88/'TC_u$d'!AL88 -> 0.84221333 | AM88: =$B88/'TC_u$d'!AM88 -> 0.41213584 | AN88: =O88 -> 4.6579812 | AO88: =$B88/'TC_u$d'!AO88 -> 0.096977785 | AP88: =$B88/'TC_u$d'!AP88 -> 2.5964321 | AQ88: =$B88/'TC_u$d'!AQ88 -> 2.6506886 | AR88: =$B88/'TC_u$d'!AR88 -> 6.2018655 | AS88: =$B88/'TC_u$d'!AS88 -> 3.1583 | AT88: =$B88/'TC_u$d'!AT88 -> 0.15085066 | AU88: =$B88/'TC_u$d'!AU88 -> 1.4710293 | AV88: =$B88/'TC_u$d'!AV88 -> 0.00019653391
A89: 2008.M03 | B89: 3.1558 | C89: =$B89/'TC_u$d'!C89 -> 0.048053599 | D89: =$B89/'TC_u$d'!D89 -> 2.9190639 | E89: =$B89/'TC_u$d'!E89 -> 0.046016197 | F89: =O89 -> 4.8998612 | G89: =$B89/'TC_u$d'!G89 -> 1.8489571 | H89: =$B89/'TC_u$d'!H89 -> 0.007124667 | I89: =$B89/'TC_u$d'!I89 -> 0.44603623 | J89: =$B89/'TC_u$d'!J89 -> 0.0017087011 | K89: =$B89/'TC_u$d'!K89 -> 0.65729401 | L89: =$B89/'TC_u$d'!L89 -> 0.092708469 | M89: =$B89/'TC_u$d'!M89 -> 3.1558 | N89: =$B89/'TC_u$d'!N89 -> 0.57798535 | O89: =$B89/'TC_u$d'!O89 -> 4.8998612 | P89: =O89 -> 4.8998612 | Q89: =O89 -> 4.8998612 | R89: =O89 -> 4.8998612 | S89: =$B89/'TC_u$d'!S89 -> 0.078198835 | T89: =$B89/'TC_u$d'!T89 -> 0.000343552 | U89: =$B89/'TC_u$d'!U89 -> 0.00034875122 | V89: =O89 -> 4.8998612 | W89: =O89 -> 4.8998612 | X89: =$B89/'TC_u$d'!X89 -> 4.4510578 | Y89: =$B89/'TC_u$d'!Y89 -> 0.0032206642 | Z89: =$B89/'TC_u$d'!Z89 -> 6.9603 | AA89: =$B89/'TC_u$d'!AA89 -> 0.99027237 | AB89: =O89 -> 4.8998612 | AC89: =$B89/'TC_u$d'!AC89 -> 0.29398394 | AD89: =$B89/'TC_u$d'!AD89 -> 0.42785867 | AE89: =O89 -> 4.8998612 | AF89: =$B89/'TC_u$d'!AF89 -> 0.051451192 | AG89: =$B89/'TC_u$d'!AG89 -> 0.00069715245 | AH89: =$B89/'TC_u$d'!AH89 -> 1.1227009 | AI89: =$B89/'TC_u$d'!AI89 -> 0.07649985 | AJ89: =$B89/'TC_u$d'!AJ89 -> 1.3831522 | AK89: =$B89/'TC_u$d'!AK89 -> 0.13281595 | AL89: =$B89/'TC_u$d'!AL89 -> 0.84154667 | AM89: =$B89/'TC_u$d'!AM89 -> 0.39593203 | AN89: =O89 -> 4.8998612 | AO89: =$B89/'TC_u$d'!AO89 -> 0.10046618 | AP89: =$B89/'TC_u$d'!AP89 -> 2.7055898 | AQ89: =$B89/'TC_u$d'!AQ89 -> 2.5461161 | AR89: =$B89/'TC_u$d'!AR89 -> 6.3226013 | AS89: =$B89/'TC_u$d'!AS89 -> 3.1558 | AT89: =$B89/'TC_u$d'!AT89 -> 0.15300032 | AU89: =$B89/'TC_u$d'!AU89 -> 1.4698649 | AV89: =$B89/'TC_u$d'!AV89 -> 0.0001971882
A90: 2008.M04 | B90: 3.1665 | C90: =$B90/'TC_u$d'!C90 -> 0.048738254 | D90: =$B90/'TC_u$d'!D90 -> 2.9467327 | E90: =$B90/'TC_u$d'!E90 -> 0.046140194 | F90: =O90 -> 4.9873958 | G90: =$B90/'TC_u$d'!G90 -> 1.8757775 | H90: =$B90/'TC_u$d'!H90 -> 0.0070929373 | I90: =$B90/'TC_u$d'!I90 -> 0.45230804 | J90: =$B90/'TC_u$d'!J90 -> 0.001762957 | K90: =$B90/'TC_u$d'!K90 -> 0.66841872 | L90: =$B90/'TC_u$d'!L90 -> 0.092760888 | M90: =$B90/'TC_u$d'!M90 -> 3.1665 | N90: =$B90/'TC_u$d'!N90 -> 0.58422509 | O90: =$B90/'TC_u$d'!O90 -> 4.9873958 | P90: =O90 -> 4.9873958 | Q90: =O90 -> 4.9873958 | R90: =O90 -> 4.9873958 | S90: =$B90/'TC_u$d'!S90 -> 0.079118194 | T90: =$B90/'TC_u$d'!T90 -> 0.00034373643 | U90: =$B90/'TC_u$d'!U90 -> 0.00035059529 | V90: =O90 -> 4.9873958 | W90: =O90 -> 4.9873958 | X90: =$B90/'TC_u$d'!X90 -> 4.4661495 | Y90: =$B90/'TC_u$d'!Y90 -> 0.0032093122 | Z90: =$B90/'TC_u$d'!Z90 -> 7.1093399 | AA90: =$B90/'TC_u$d'!AA90 -> 1.0013915 | AB90: =O90 -> 4.9873958 | AC90: =$B90/'TC_u$d'!AC90 -> 0.30072653 | AD90: =$B90/'TC_u$d'!AD90 -> 0.43432044 | AE90: =O90 -> 4.9873958 | AF90: =$B90/'TC_u$d'!AF90 -> 0.049651429 | AG90: =$B90/'TC_u$d'!AG90 -> 0.00073991503 | AH90: =$B90/'TC_u$d'!AH90 -> 1.154393 | AI90: =$B90/'TC_u$d'!AI90 -> 0.075718136 | AJ90: =$B90/'TC_u$d'!AJ90 -> 1.4490664 | AK90: =$B90/'TC_u$d'!AK90 -> 0.1346719 | AL90: =$B90/'TC_u$d'!AL90 -> 0.8444 | AM90: =$B90/'TC_u$d'!AM90 -> 0.40674374 | AN90: =O90 -> 4.9873958 | AO90: =$B90/'TC_u$d'!AO90 -> 0.10038709 | AP90: =$B90/'TC_u$d'!AP90 -> 2.7354008 | AQ90: =$B90/'TC_u$d'!AQ90 -> 2.437019 | AR90: =$B90/'TC_u$d'!AR90 -> 6.2727813 | AS90: =$B90/'TC_u$d'!AS90 -> 3.1665 | AT90: =$B90/'TC_u$d'!AT90 -> 0.15886116 | AU90: =$B90/'TC_u$d'!AU90 -> 1.4748486 | AV90: =$B90/'TC_u$d'!AV90 -> 0.00019840226
