Workbook

Sheet CPI_socios_expo
A1: DATASET | B1: SERIES_CODE | C1: OBS_MEASURE | D1: COUNTRY | E1: INDEX_TYPE | F1: COICOP_1999 | G1: TYPE_OF_TRANSFORMATION | H1: FREQUENCY | I1: SCALE | J1: X2001.M01 | K1: X2001.M02 | L1: X2001.M03 | M1: X2001.M04 | N1: X2001.M05 | O1: X2001.M06 | P1: X2001.M07 | Q1: X2001.M08 | R1: X2001.M09 | S1: X2001.M10 | T1: X2001.M11 | U1: X2001.M12 | V1: X2002.M01 | W1: X2002.M02 | X1: X2002.M03 | Y1: X2002.M04 | Z1: X2002.M05 | AA1: X2002.M06 | AB1: X2002.M07 | AC1: X2002.M08 | AD1: X2002.M09 | AE1: X2002.M10 | AF1: X2002.M11 | AG1: X2002.M12 | AH1: X2003.M01 | AI1: X2003.M02 | AJ1: X2003.M03 | AK1: X2003.M04 | AL1: X2003.M05 | AM1: X2003.M06 | AN1: X2003.M07 | AO1: X2003.M08 | AP1: X2003.M09 | AQ1: X2003.M10 | AR1: X2003.M11 | AS1: X2003.M12 | AT1: X2004.M01 | AU1: X2004.M02 | AV1: X2004.M03 | AW1: X2004.M04 | AX1: X2004.M05 | AY1: X2004.M06 | AZ1: X2004.M07 | BA1: X2004.M08 | BB1: X2004.M09 | BC1: X2004.M10 | BD1: X2004.M11 | BE1: X2004.M12 | BF1: X2005.M01 | BG1: X2005.M02 | BH1: X2005.M03 | BI1: X2005.M04 | BJ1: X2005.M05 | BK1: X2005.M06 | BL1: X2005.M07 | BM1: X2005.M08 | BN1: X2005.M09 | BO1: X2005.M10 | BP1: X2005.M11 | BQ1: X2005.M12 | BR1: X2006.M01 | BS1: X2006.M02 | BT1: X2006.M03 | BU1: X2006.M04 | BV1: X2006.M05 | BW1: X2006.M06 | BX1: X2006.M07 | BY1: X2006.M08 | BZ1: X2006.M09 | CA1: X2006.M10 | CB1: X2006.M11 | CC1: X2006.M12 | CD1: X2007.M01 | CE1: X2007.M02 | CF1: X2007.M03 | CG1: X2007.M04 | CH1: X2007.M05 | CI1: X2007.M06 | CJ1: X2007.M07 | CK1: X2007.M08 | CL1: X2007.M09 | CM1: X2007.M10 | CN1: X2007.M11 | CO1: X2007.M12 | CP1: X2008.M01 | CQ1: X2008.M02 | CR1: X2008.M03 | CS1: X2008.M04 | CT1: X2008.M05 | CU1: X2008.M06 | CV1: X2008.M07 | CW1: X2008.M08 | CX1: X2008.M09 | CY1: X2008.M10 | CZ1: X2008.M11 | DA1: X2008.M12 | DB1: X2009.M01 | DC1: X2009.M02 | DD1: X2009.M03 | DE1: X2009.M04 | DF1: X2009.M05 | DG1: X2009.M06 | DH1: X2009.M07 | DI1: X2009.M08 | DJ1: X2009.M09 | DK1: X2009.M10 | DL1: X2009.M11 | DM1: X2009.M12 | DN1: X2010.M01 | DO1: X2010.M02 | DP1: X2010.M03 | DQ1: X2010.M04 | DR1: X2010.M05 | DS1: X2010.M06 | DT1: X2010.M07 | DU1: X2010.M08 | DV1: X2010.M09 | DW1: X2010.M10 | DX1: X2010.M11 | DY1: X2010.M12 | DZ1: X2011.M01 | EA1: X2011.M02 | EB1: X2011.M03 | EC1: X2011.M04 | ED1: X2011.M05 | EE1: X2011.M06 | EF1: X2011.M07 | EG1: X2011.M08 | EH1: X2011.M09 | EI1: X2011.M10 | EJ1: X2011.M11 | EK1: X2011.M12 | EL1: X2012.M01 | EM1: X2012.M02 | EN1: X2012.M03 | EO1: X2012.M04 | EP1: X2012.M05 | EQ1: X2012.M06 | ER1: X2012.M07 | ES1: X2012.M08 | ET1: X2012.M09 | EU1: X2012.M10 | EV1: X2012.M11 | EW1: X2012.M12 | EX1: X2013.M01 | EY1: X2013.M02 | EZ1: X2013.M03 | FA1: X2013.M04 | FB1: X2013.M05 | FC1: X2013.M06 | FD1: X2013.M07 | FE1: X2013.M08 | FF1: X2013.M09 | FG1: X2013.M10 | FH1: X2013.M11 | FI1: X2013.M12 | FJ1: X2014.M01 | FK1: X2014.M02 | FL1: X2014.M03 | FM1: X2014.M04 | FN1: X2014.M05 | FO1: X2014.M06 | FP1: X2014.M07 | FQ1: X2014.M08 | FR1: X2014.M09 | FS1: X2014.M10 | FT1: X2014.M11 | FU1: X2014.M12 | FV1: X2015.M01 | FW1: X2015.M02 | FX1: X2015.M03 | FY1: X2015.M04 | FZ1: X2015.M05 | GA1: X2015.M06 | GB1: X2015.M07 | GC1: X2015.M08 | GD1: X2015.M09 | GE1: X2015.M10 | GF1: X2015.M11 | GG1: X2015.M12 | GH1: X2016.M01 | GI1: X2016.M02 | GJ1: X2016.M03 | GK1: X2016.M04 | GL1: X2016.M05 | GM1: X2016.M06 | GN1: X2016.M07 | GO1: X2016.M08 | GP1: X2016.M09 | GQ1: X2016.M10 | GR1: X2016.M11 | GS1: X2016.M12 | GT1: X2017.M01 | GU1: X2017.M02 | GV1: X2017.M03 | GW1: X2017.M04 | GX1: X2017.M05 | GY1: X2017.M06 | GZ1: X2017.M07 | HA1: X2017.M08 | HB1: X2017.M09 | HC1: X2017.M10 | HD1: X2017.M11 | HE1: X2017.M12 | HF1: X2018.M01 | HG1: X2018.M02 | HH1: X2018.M03 | HI1: X2018.M04 | HJ1: X2018.M05 | HK1: X2018.M06 | HL1: X2018.M07 | HM1: X2018.M08 | HN1: X2018.M09 | HO1: X2018.M10 | HP1: X2018.M11 | HQ1: X2018.M12 | HR1: X2019.M01 | HS1: X2019.M02 | HT1: X2019.M03 | HU1: X2019.M04 | HV1: X2019.M05 | HW1: X2019.M06 | HX1: X2019.M07 | HY1: X2019.M08 | HZ1: X2019.M09 | IA1: X2019.M10 | IB1: X2019.M11 | IC1: X2019.M12 | ID1: X2020.M01 | IE1: X2020.M02 | IF1: X2020.M03 | IG1: X2020.M04 | IH1: X2020.M05 | II1: X2020.M06 | IJ1: X2020.M07 | IK1: X2020.M08 | IL1: X2020.M09 | IM1: X2020.M10 | IN1: X2020.M11 | IO1: X2020.M12 | IP1: X2021.M01 | IQ1: X2021.M02 | IR1: X2021.M03 | IS1: X2021.M04 | IT1: X2021.M05 | IU1: X2021.M06 | IV1: X2021.M07 | IW1: X2021.M08 | IX1: X2021.M09 | IY1: X2021.M10 | IZ1: X2021.M11 | JA1: X2021.M12 | JB1: X2022.M01 | JC1: X2022.M02 | JD1: X2022.M03 | JE1: X2022.M04 | JF1: X2022.M05 | JG1: X2022.M06 | JH1: X2022.M07 | JI1: X2022.M08 | JJ1: X2022.M09 | JK1: X2022.M10 | JL1: X2022.M11 | JM1: X2022.M12 | JN1: X2023.M01 | JO1: X2023.M02 | JP1: X2023.M03 | JQ1: X2023.M04 | JR1: X2023.M05 | JS1: X2023.M06 | JT1: X2023.M07 | JU1: X2023.M08 | JV1: X2023.M09 | JW1: X2023.M10 | JX1: X2023.M11 | JY1: X2023.M12 | JZ1: X2024.M01 | KA1: X2024.M02 | KB1: X2024.M03 | KC1: X2024.M04 | KD1: X2024.M05 | KE1: X2024.M06 | KF1: X2024.M07 | KG1: X2024.M08 | KH1: X2024.M09 | KI1: X2024.M10 | KJ1: X2024.M11 | KK1: X2024.M12
A2: IMF.STA:CPI(5.0.0) | B2: DZA.CPI._T.IX.M | C2: OBS_VALUE | D2: Algeria | E2: Consumer price index (CPI) | F2: All Items | G2: Index | H2: Monthly | I2: Units | BF2: 111.8 | BG2: 112.42 | BH2: 112.94 | BI2: 113.31 | BJ2: 111.77 | BK2: 111.42 | BL2: 110.67 | BM2: 110.29 | BN2: 110.19 | BO2: 110.72 | BP2: 110.64 | BQ2: 111.49 | BR2: 112.5 | BS2: 112.15 | BT2: 113.26 | BU2: 114.41 | BV2: 114.19 | BW2: 113.73 | BX2: 112.89 | BY2: 113.9 | BZ2: 114.75 | CA2: 115.86 | CB2: 115.17 | CC2: 115.77 | CD2: 115.17 | CE2: 115.86 | CF2: 116.73 | CG2: 116.24 | CH2: 115.71 | CI2: 117.46 | CJ2: 118.31 | CK2: 118.88 | CL2: 120.95 | CM2: 121.57 | CN2: 120.72 | CO2: 121.33 | CP2: 120.39 | CQ2: 121.42 | CR2: 123.58 | CS2: 123.61 | CT2: 123.42 | CU2: 122.29 | CV2: 121.39 | CW2: 124.32 | CX2: 126.6 | CY2: 126.61 | CZ2: 127.01 | DA2: 127.23 | DB2: 126.98 | DC2: 128.91 | DD2: 130.5 | DE2: 130.81 | DF2: 127.84 | DG2: 128.25 | DH2: 130.24 | DI2: 132.4 | DJ2: 133.96 | DK2: 134.23 | DL2: 134.56 | DM2: 134.55 | DN2: 133.52 | DO2: 134.26 | DP2: 135.29 | DQ2: 134.03 | DR2: 135.86 | DS2: 136.08 | DT2: 135.4 | DU2: 137.64 | DV2: 137.28 | DW2: 138.01 | DX2: 139.17 | DY2: 138.22 | DZ2: 138.29 | EA2: 138.93 | EB2: 139.94 | EC2: 140.11 | ED2: 141.13 | EE2: 141.1 | EF2: 142.47 | EG2: 145.51 | EH2: 144.32 | EI2: 145.55 | EJ2: 146.02 | EK2: 145.35 | EL2: 148.71 | EM2: 151.91 | EN2: 154.11 | EO2: 155.49 | EP2: 153.8 | EQ2: 153.34 | ER2: 154.16 | ES2: 155.97 | ET2: 156.9 | EU2: 159.95 | EV2: 157.83 | EW2: 158.48 | EX2: 160.33 | EY2: 160.09 | EZ2: 160.91 | FA2: 160.25 | FB2: 159.11 | FC2: 160.22 | FD2: 159.58 | FE2: 161.08 | FF2: 160.31 | FG2: 160.15 | FH2: 158.87 | FI2: 160.3 | FJ2: 161.4 | FK2: 160.99 | FL2: 162.3 | FM2: 161.34 | FN2: 161.83 | FO2: 164.7 | FP2: 164.88 | FQ2: 165.47 | FR2: 166.63 | FS2: 169.96 | FT2: 169.02 | FU2: 168.72 | FV2: 168.91 | FW2: 170 | FX2: 171.21 | FY2: 170.64 | FZ2: 171.36 | GA2: 172.14 | GB2: 170.98 | GC2: 172.85 | GD2: 176.8 | GE2: 176.07 | GF2: 174.8 | GG2: 176.08 | GH2: 177.42 | GI2: 177.06 | GJ2: 180.36 | GK2: 182.07 | GL2: 183.31 | GM2: 185.79 | GN2: 184.9 | GO2: 185.67 | GP2: 186.37 | GQ2: 185.14 | GR2: 187.97 | GS2: 188.33 | GT2: 191.74 | GU2: 190.63 | GV2: 192.84 | GW2: 193.54 | GX2: 192.82 | GY2: 193.37 | GZ2: 190.62 | HA2: 194.03 | HB2: 196.14 | HC2: 197.18 | HD2: 197.11 | HE2: 197.62 | HF2: 198.59 | HG2: 197.44 | HH2: 198.92 | HI2: 200.07 | HJ2: 203.71 | HK2: 205.92 | HL2: 201.97 | HM2: 202.89 | HN2: 203.54 | HO2: 205.97 | HP2: 205.05 | HQ2: 202.96 | HR2: 203.74 | HS2: 202.75 | HT2: 204.65 | HU2: 204.68 | HV2: 206.7 | HW2: 206.12 | HX2: 204.68 | HY2: 206.83 | HZ2: 209.36 | IA2: 209.14 | IB2: 207.85 | IC2: 207.9 | ID2: 207.66 | IE2: 206.45 | IF2: 209.01 | IG2: 209.6 | IH2: 211.63 | II2: 211.97 | IJ2: 209.65 | IK2: 209.89 | IL2: 212.27 | IM2: 215.83 | IN2: 214.99 | IO2: 215.21 | IP2: 216.45 | IQ2: 217.36 | IR2: 221.28 | IS2: 224.64 | IT2: 224.39 | IU2: 223.35 | IV2: 224.94 | IW2: 228.14 | IX2: 232.69 | IY2: 235.59 | IZ2: 234.98 | JA2: 233.47 | JB2: 236 | JC2: 237.36 | JD2: 241.87 | JE2: 247.09 | JF2: 245.78 | JG2: 247.52 | JH2: 246.04 | JI2: 250.6 | JJ2: 252.81 | JK2: 254.63 | JL2: 254.18 | JM2: 255.17 | JN2: 257.98 | JO2: 260.79 | JP2: 266.28 | JQ2: 271.55 | JR2: 270.69 | JS2: 270.13 | JT2: 269.1 | JU2: 274.96 | JV2: 276.84 | JW2: 275.47 | JX2: 276.87 | JY2: 275.17 | JZ2: 274.32 | KA2: 272.73 | KB2: 277.1 | KC2: 277.86 | KD2: 278.26 | KE2: 281.96 | KF2: 284.3 | KG2: 287.21 | KH2: 287.43 | KI2: 287.16 | KJ2: 285.45 | KK2: 283.38
A3: IMF.STA:CPI(5.0.0) | B3: BGD.CPI._T.IX.M | C3: OBS_VALUE | D3: Bangladesh | E3: Consumer price index (CPI) | F3: All Items | G3: Index | H3: Monthly | I3: Units | DN3: 46.346617 | DO3: 46.371626 | DP3: 46.394551 | DQ3: 46.369542 | DR3: 46.598795 | DS3: 47.123993 | DT3: 47.842222 | DU3: 48.753034 | DV3: 49.323498 | DW3: 50.143056 | DX3: 50.466265 | DY3: 51.427056 | DZ3: 51.754874 | EA3: 52.079406 | EB3: 52.291101 | EC3: 52.265909 | ED3: 51.938721 | EE3: 52.451929 | EF3: 53.509195 | EG3: 54.62395 | EH3: 55.567655 | EI3: 55.653419 | EJ3: 55.449708 | EK3: 55.342751 | EL3: 56.195182 | EM3: 55.693458 | EN3: 55.825972 | EO3: 55.525942 | EP3: 55.058456 | EQ3: 55.361278 | ER3: 56.294375 | ES3: 57.337583 | ET3: 58.323465 | EU3: 58.914742 | EV3: 59.080507 | EW3: 59.291775 | EX3: 59.912581 | EY3: 60.062094 | EZ3: 60.1336 | FA3: 60.172604 | FB3: 59.451039 | FC3: 59.818322 | FD3: 60.712152 | FE3: 61.573478 | FF3: 62.483559 | FG3: 63.05886 | FH3: 63.302632 | FI3: 63.647163 | FJ3: 64.40448 | FK3: 64.531241 | FL3: 64.62875 | FM3: 64.658003 | FN3: 63.900685 | FO3: 63.985193 | FP3: 64.986282 | FQ3: 65.828107 | FR3: 66.75769 | FS3: 67.219231 | FT3: 67.235482 | FU3: 67.534509 | FV3: 68.295076 | FW3: 68.496594 | FX3: 68.681861 | FY3: 68.746867 | FZ3: 67.856287 | GA3: 67.986299 | GB3: 69.1174 | GC3: 69.890968 | GD3: 70.92456 | GE3: 71.382851 | GF3: 71.304844 | GG3: 71.652625 | GH3: 72.439195 | GI3: 72.344937 | GJ3: 72.562706 | GK3: 72.60171 | GL3: 71.555116 | GM3: 71.746883 | GN3: 72.848732 | GO3: 73.641802 | GP3: 74.844409 | GQ3: 75.357955 | GR3: 75.140185 | GS3: 75.253946 | GT3: 76.167277 | GU3: 76.186778 | GV3: 76.476054 | GW3: 76.570313 | GX3: 75.676483 | GY3: 76.011263 | GZ3: 76.905092 | HA3: 77.980938 | HB3: 79.424067 | HC3: 79.91161 | HD3: 79.583331 | HE3: 79.641836 | HF3: 80.649426 | HG3: 80.545416 | HH3: 80.818441 | HI3: 80.883446 | HJ3: 79.892108 | HK3: 80.223638 | HL3: 81.14347 | HM3: 82.255068 | HN3: 83.727449 | HO3: 84.224744 | HP3: 83.857461 | HQ3: 83.899715 | HR3: 85.021065 | HS3: 84.949558 | HT3: 85.30384 | HU3: 85.394848 | HV3: 84.387258 | HW3: 84.650532 | HX3: 85.706876 | HY3: 86.76972 | HZ3: 88.375363 | IA3: 88.830403 | IB3: 88.927912 | IC3: 88.723144 | ID3: 89.759986 | IE3: 89.587721 | IF3: 89.977756 | IG3: 90.484801 | IH3: 88.90516 | II3: 89.746985 | IJ3: 90.445797 | IK3: 91.693908 | IL3: 93.647332 | IM3: 94.554163 | IN3: 93.839099 | IO3: 93.416561 | IP3: 94.268137 | IQ3: 94.355895 | IR3: 94.895443 | IS3: 95.519499 | IT3: 93.582326 | IU3: 94.810936 | IV3: 95.295229 | IW3: 96.77086 | IX3: 98.880298 | IY3: 99.943142 | IZ3: 99.449098 | JA3: 99.072065 | JB3: 99.790379 | JC3: 100.17716 | JD3: 100.79797 | JE3: 101.53253 | JF3: 100.52494 | JG3: 101.98107 | JH3: 102.42636 | JI3: 105.97893 | JJ3: 107.8706 | JK3: 108.84893 | JL3: 108.25738 | JM3: 107.69833 | JN3: 108.34514 | JO3: 108.97895 | JP3: 110.20756 | JQ3: 111.45 | JR3: 111.06 | JS3: 112.46 | JT3: 112.89 | JU3: 117.06 | JV3: 118.83 | JW3: 120.24 | JX3: 119.1 | JY3: 118.4 | JZ3: 119.6 | KA3: 120.09 | KB3: 121.6 | KC3: 122.3 | KD3: 122.04 | KE3: 123.38 | KF3: 126.06 | KG3: 129.34 | KH3: 130.61 | KI3: 133.32 | KJ3: 132.66 | KK3: 131.3
A4: IMF.STA:CPI(5.0.0) | B4: BEL.HICP._T.IX.M | C4: OBS_VALUE | D4: Belgium | E4: Harmonised index of consumer prices (HICP) | F4: All Items | G4: Index | H4: Monthly | I4: Units | J4: 74.64 | K4: 75.98 | L4: 76.12 | M4: 76.8 | N4: 77.2 | O4: 77.34 | P4: 76.37 | Q4: 77.38 | R4: 77.49 | S4: 77.4 | T4: 77.4 | U4: 77.29 | V4: 76.61 | W4: 77.86 | X4: 78.04 | Y4: 78.09 | Z4: 78.2 | AA4: 77.99 | AB4: 77.25 | AC4: 78.33 | AD4: 78.41 | AE4: 78.34 | AF4: 78.23 | AG4: 78.32 | AH4: 77.51 | AI4: 79.16 | AJ4: 79.38 | AK4: 79.24 | AL4: 78.93 | AM4: 79.18 | AN4: 78.32 | AO4: 79.64 | AP4: 79.75 | AQ4: 79.51 | AR4: 79.64 | AS4: 79.6 | AT4: 78.59 | AU4: 80.05 | AV4: 80.11 | AW4: 80.57 | AX4: 80.82 | AY4: 80.75 | AZ4: 79.92 | BA4: 81.27 | BB4: 81.19 | BC4: 81.58 | BD4: 81.45 | BE4: 81.2 | BF4: 80.14 | BG4: 81.86 | BH4: 82.39 | BI4: 82.55 | BJ4: 82.65 | BK4: 82.93 | BL4: 82.1 | BM4: 83.59 | BN4: 83.56 | BO4: 83.44 | BP4: 83.4 | BQ4: 83.44 | BR4: 82.33 | BS4: 84.22 | BT4: 84.16 | BU4: 84.63 | BV4: 84.93 | BW4: 85 | BX4: 84.09 | BY4: 85.54 | BZ4: 85.13 | CA4: 84.88 | CB4: 85.06 | CC4: 85.17 | CD4: 83.73 | CE4: 85.71 | CF4: 85.71 | CG4: 86.14 | CH4: 86.04 | CI4: 86.1 | CJ4: 85.19 | CK4: 86.52 | CL4: 86.36 | CM4: 86.76 | CN4: 87.5 | CO4: 87.82 | CP4: 86.68 | CQ4: 88.82 | CR4: 89.47 | CS4: 89.65 | CT4: 90.43 | CU4: 91.06 | CV4: 90.21 | CW4: 91.16 | CX4: 91.07 | CY4: 90.92 | CZ4: 90.32 | DA4: 90.19 | DB4: 88.5 | DC4: 90.54 | DD4: 90.04 | DE4: 90.31 | DF4: 90.21 | DG4: 90.1 | DH4: 88.65 | DI4: 90.51 | DJ4: 90.14 | DK4: 90.12 | DL4: 90.3 | DM4: 90.49 | DN4: 89.2 | DO4: 91.28 | DP4: 91.75 | DQ4: 92.16 | DR4: 92.48 | DS4: 92.5 | DT4: 90.81 | DU4: 92.67 | DV4: 92.78 | DW4: 92.91 | DX4: 93.02 | DY4: 93.55 | DZ4: 92.31 | EA4: 94.48 | EB4: 94.8 | EC4: 95.05 | ED4: 95.2 | EE4: 95.52 | EF4: 94.46 | EG4: 95.86 | EH4: 95.77 | EI4: 95.9 | EJ4: 96.28 | EK4: 96.53 | EL4: 95.34 | EM4: 97.65 | EN4: 97.75 | EO4: 97.8 | EP4: 97.71 | EQ4: 97.59 | ER4: 96.33 | ES4: 98.35 | ET4: 98.27 | EU4: 98.45 | EV4: 98.37 | EW4: 98.54 | EX4: 96.74 | EY4: 99.14 | EZ4: 99.14 | FA4: 98.98 | FB4: 98.9 | FC4: 99.19 | FD4: 97.91 | FE4: 99.43 | FF4: 99.26 | FG4: 99.15 | FH4: 99.25 | FI4: 99.69 | FJ4: 97.82 | FK4: 99.97 | FL4: 99.94 | FM4: 99.74 | FN4: 99.59 | FO4: 99.74 | FP4: 98.43 | FQ4: 99.83 | FR4: 99.46 | FS4: 99.47 | FT4: 99.31 | FU4: 99.3 | FV4: 97.2 | FW4: 99.56 | FX4: 99.82 | FY4: 100.11 | FZ4: 100.43 | GA4: 100.6 | GB4: 99.27 | GC4: 100.58 | GD4: 100.36 | GE4: 100.62 | GF4: 100.7 | GG4: 100.74 | GH4: 98.99 | GI4: 100.67 | GJ4: 101.46 | GK4: 101.65 | GL4: 102.04 | GM4: 102.4 | GN4: 101.3 | GO4: 102.59 | GP4: 102.15 | GQ4: 102.56 | GR4: 102.46 | GS4: 102.96 | GT4: 102.03 | GU4: 104 | GV4: 103.99 | GW4: 104.35 | GX4: 104.02 | GY4: 103.95 | GZ4: 103.13 | HA4: 104.64 | HB4: 104.15 | HC4: 104.44 | HD4: 104.61 | HE4: 105.08 | HF4: 103.82 | HG4: 105.53 | HH4: 105.56 | HI4: 106.01 | HJ4: 106.38 | HK4: 106.68 | HL4: 105.93 | HM4: 107.41 | HN4: 107.1 | HO4: 107.8 | HP4: 107.63 | HQ4: 107.39 | HR4: 105.69 | HS4: 107.62 | HT4: 107.86 | HU4: 108.11 | HV4: 108.16 | HW4: 108.09 | HX4: 107.21 | HY4: 108.34 | HZ4: 107.7 | IA4: 108.01 | IB4: 108.02 | IC4: 108.38 | ID4: 107.17 | IE4: 108.74 | IF4: 108.32 | IG4: 108.1 | IH4: 107.92 | II4: 108.33 | IJ4: 109.05 | IK4: 107.38 | IL4: 108.21 | IM4: 108.47 | IN4: 108.27 | IO4: 108.76 | IP4: 107.82 | IQ4: 109.08 | IR4: 110.07 | IS4: 110.32 | IT4: 110.62 | IU4: 111.11 | IV4: 110.58 | IW4: 112.41 | IX4: 112.35 | IY4: 114.33 | IZ4: 115.95 | JA4: 115.93 | JB4: 116.99 | JC4: 119.49 | JD4: 120.28 | JE4: 120.61 | JF4: 121.61 | JG4: 122.82 | JH4: 122.03 | JI4: 124.24 | JJ4: 125.9 | JK4: 129.3 | JL4: 128.07 | JM4: 127.77 | JN4: 125.66 | JO4: 125.99 | JP4: 126.23 | JQ4: 124.65 | JR4: 124.91 | JS4: 124.79 | JT4: 124.05 | JU4: 127.2 | JV4: 126.73 | JW4: 127.15 | JX4: 127.05 | JY4: 128.45 | JZ4: 127.51 | KA4: 130.54 | KB4: 131.05 | KC4: 130.72 | KD4: 130.98 | KE4: 131.56 | KF4: 130.76 | KG4: 132.73 | KH4: 132.21 | KI4: 132.9 | KJ4: 133.13 | KK4: 134.12
A5: IMF.STA:CPI(5.0.0) | B5: BEL.CPI._T.IX.M | C5: OBS_VALUE | D5: Belgium | E5: Consumer price index (CPI) | F5: All Items | G5: Index | H5: Monthly | I5: Units | J5: 76.14 | K5: 76.47 | L5: 76.64 | M5: 77.3 | N5: 77.79 | O5: 77.93 | P5: 77.87 | Q5: 77.86 | R5: 78.08 | S5: 77.96 | T5: 78.05 | U5: 77.88 | V5: 78.35 | W5: 78.48 | X5: 78.69 | Y5: 78.71 | Z5: 78.83 | AA5: 78.61 | AB5: 78.87 | AC5: 78.84 | AD5: 79.06 | AE5: 78.97 | AF5: 78.91 | AG5: 78.95 | AH5: 79.3 | AI5: 79.85 | AJ5: 80.07 | AK5: 79.87 | AL5: 79.65 | AM5: 79.88 | AN5: 80.03 | AO5: 80.25 | AP5: 80.48 | AQ5: 80.22 | AR5: 80.37 | AS5: 80.32 | AT5: 80.56 | AU5: 80.86 | AV5: 80.97 | AW5: 81.41 | AX5: 81.72 | AY5: 81.68 | AZ5: 81.96 | BA5: 82.06 | BB5: 82.12 | BC5: 82.52 | BD5: 82.42 | BE5: 82.15 | BF5: 82.38 | BG5: 82.93 | BH5: 83.46 | BI5: 83.65 | BJ5: 83.78 | BK5: 84.03 | BL5: 84.53 | BM5: 84.62 | BN5: 84.71 | BO5: 84.56 | BP5: 84.53 | BQ5: 84.52 | BR5: 84.54 | BS5: 84.91 | BT5: 84.88 | BU5: 85.29 | BV5: 85.61 | BW5: 85.6 | BX5: 85.89 | BY5: 86 | BZ5: 85.75 | CA5: 85.58 | CB5: 85.79 | CC5: 85.91 | CD5: 85.95 | CE5: 86.41 | CF5: 86.42 | CG5: 86.81 | CH5: 86.71 | CI5: 86.7 | CJ5: 87.07 | CK5: 86.96 | CL5: 87.04 | CM5: 87.5 | CN5: 88.32 | CO5: 88.56 | CP5: 88.92 | CQ5: 89.56 | CR5: 90.21 | CS5: 90.42 | CT5: 91.23 | CU5: 91.73 | CV5: 92.21 | CW5: 91.65 | CX5: 91.8 | CY5: 91.63 | CZ5: 91.09 | DA5: 90.89 | DB5: 90.98 | DC5: 91.29 | DD5: 90.77 | DE5: 90.96 | DF5: 90.89 | DG5: 90.72 | DH5: 90.66 | DI5: 90.94 | DJ5: 90.7 | DK5: 90.74 | DL5: 90.98 | DM5: 91.13 | DN5: 91.54 | DO5: 91.93 | DP5: 92.27 | DQ5: 92.59 | DR5: 92.96 | DS5: 92.95 | DT5: 92.99 | DU5: 93.05 | DV5: 93.34 | DW5: 93.47 | DX5: 93.59 | DY5: 93.96 | DZ5: 94.49 | EA5: 95.04 | EB5: 95.52 | EC5: 95.75 | ED5: 96.07 | EE5: 96.37 | EF5: 96.48 | EG5: 96.4 | EH5: 96.66 | EI5: 96.81 | EJ5: 97.19 | EK5: 97.23 | EL5: 97.94 | EM5: 98.52 | EN5: 98.73 | EO5: 98.8 | EP5: 98.77 | EQ5: 98.54 | ER5: 98.72 | ES5: 99.15 | ET5: 99.32 | EU5: 99.5 | EV5: 99.39 | EW5: 99.4 | EX5: 99.37 | EY5: 99.69 | EZ5: 99.83 | FA5: 99.79 | FB5: 99.94 | FC5: 100.11 | FD5: 100.21 | FE5: 100.15 | FF5: 100.21 | FG5: 100.13 | FH5: 100.2 | FI5: 100.36 | FJ5: 100.5 | FK5: 100.66 | FL5: 100.72 | FM5: 100.41 | FN5: 100.3 | FO5: 100.38 | FP5: 100.55 | FQ5: 100.17 | FR5: 100.09 | FS5: 100.22 | FT5: 100.09 | FU5: 99.98 | FV5: 99.85 | FW5: 100.26 | FX5: 100.32 | FY5: 100.7 | FZ5: 100.86 | GA5: 101.01 | GB5: 101.01 | GC5: 101.08 | GD5: 101.15 | GE5: 101.5 | GF5: 101.61 | GG5: 101.48 | GH5: 101.59 | GI5: 101.65 | GJ5: 102.57 | GK5: 102.75 | GL5: 103.08 | GM5: 103.19 | GN5: 103.31 | GO5: 103.26 | GP5: 103.04 | GQ5: 103.34 | GR5: 103.41 | GS5: 103.54 | GT5: 104.28 | GU5: 104.67 | GV5: 104.91 | GW5: 105.09 | GX5: 105 | GY5: 104.84 | GZ5: 105.15 | HA5: 105.22 | HB5: 105.11 | HC5: 105.41 | HD5: 105.55 | HE5: 105.75 | HF5: 106.06 | HG5: 106.22 | HH5: 106.37 | HI5: 106.69 | HJ5: 106.91 | HK5: 107.02 | HL5: 107.43 | HM5: 107.58 | HN5: 107.58 | HO5: 108.31 | HP5: 108.48 | HQ5: 108.22 | HR5: 108.17 | HS5: 108.52 | HT5: 108.85 | HU5: 108.91 | HV5: 108.93 | HW5: 108.87 | HX5: 108.96 | HY5: 108.94 | HZ5: 108.44 | IA5: 108.83 | IB5: 108.9 | IC5: 109.04 | ID5: 109.69 | IE5: 109.71 | IF5: 109.53 | IG5: 109.53 | IH5: 109.45 | II5: 109.52 | IJ5: 109.76 | IK5: 109.83 | IL5: 109.42 | IM5: 109.64 | IN5: 109.46 | IO5: 109.49 | IP5: 109.97 | IQ5: 110.21 | IR5: 110.51 | IS5: 110.88 | IT5: 111.05 | IU5: 111.3 | IV5: 112.25 | IW5: 112.83 | IX5: 112.55 | IY5: 114.2 | IZ5: 115.63 | JA5: 115.74 | JB5: 118.32 | JC5: 119.07 | JD5: 119.69 | JE5: 120.09 | JF5: 121.01 | JG5: 122.04 | JH5: 123.05 | JI5: 124.05 | JJ5: 125.24 | JK5: 128.21 | JL5: 127.92 | JM5: 127.72 | JN5: 127.84 | JO5: 126.95 | JP5: 127.67 | JQ5: 126.82 | JR5: 127.3 | JS5: 127.11 | JT5: 128.14 | JU5: 129.12 | JV5: 128.23 | JW5: 128.67 | JX5: 128.89 | JY5: 129.45 | JZ5: 130.08 | KA5: 131.01 | KB5: 131.73 | KC5: 131.1 | KD5: 131.58 | KE5: 131.87 | KF5: 132.81 | KG5: 132.81 | KH5: 132.15 | KI5: 132.79 | KJ5: 133.01 | KK5: 133.54
A6: IMF.STA:CPI(5.0.0) | B6: BRA.CPI._T.IX.M | C6: OBS_VALUE | D6: Brazil | E6: Consumer price index (CPI) | F6: All Items | G6: Index | H6: Monthly | I6: Units | J6: 1693.07 | K6: 1700.86 | L6: 1707.32 | M6: 1717.22 | N6: 1724.26 | O6: 1733.23 | P6: 1756.28 | Q6: 1768.57 | R6: 1773.52 | S6: 1788.24 | T6: 1800.94 | U6: 1812.65 | V6: 1822.08 | W6: 1828.64 | X6: 1839.61 | Y6: 1854.33 | Z6: 1858.22 | AA6: 1866.02 | AB6: 1888.23 | AC6: 1900.5 | AD6: 1914.18 | AE6: 1939.26 | AF6: 1997.83 | AG6: 2039.78 | AH6: 2085.68 | AI6: 2118.43 | AJ6: 2144.49 | AK6: 2165.29 | AL6: 2178.5 | AM6: 2175.23 | AN6: 2179.58 | AO6: 2186.99 | AP6: 2204.05 | AQ6: 2210.44 | AR6: 2217.96 | AS6: 2229.49 | AT6: 2246.43 | AU6: 2260.13 | AV6: 2270.75 | AW6: 2279.15 | AX6: 2290.77 | AY6: 2307.03 | AZ6: 2328.02 | BA6: 2344.08 | BB6: 2351.82 | BC6: 2362.17 | BD6: 2378.47 | BE6: 2398.92 | BF6: 2412.83 | BG6: 2427.07 | BH6: 2441.87 | BI6: 2463.11 | BJ6: 2475.18 | BK6: 2474.68 | BL6: 2480.87 | BM6: 2485.09 | BN6: 2493.79 | BO6: 2512.49 | BP6: 2526.31 | BQ6: 2535.4 | BR6: 2550.36 | BS6: 2560.82 | BT6: 2571.83 | BU6: 2577.23 | BV6: 2579.81 | BW6: 2574.39 | BX6: 2579.28 | BY6: 2580.57 | BZ6: 2585.99 | CA6: 2594.52 | CB6: 2602.56 | CC6: 2615.05 | CD6: 2626.56 | CE6: 2638.12 | CF6: 2647.88 | CG6: 2654.5 | CH6: 2661.93 | CI6: 2669.38 | CJ6: 2675.79 | CK6: 2688.37 | CL6: 2693.21 | CM6: 2701.29 | CN6: 2711.55 | CO6: 2731.62 | CP6: 2746.37 | CQ6: 2759.83 | CR6: 2773.08 | CS6: 2788.33 | CT6: 2810.36 | CU6: 2831.16 | CV6: 2846.16 | CW6: 2854.13 | CX6: 2861.55 | CY6: 2874.43 | CZ6: 2884.78 | DA6: 2892.86 | DB6: 2906.74 | DC6: 2922.73 | DD6: 2928.57 | DE6: 2942.63 | DF6: 2956.46 | DG6: 2967.1 | DH6: 2974.22 | DI6: 2978.68 | DJ6: 2985.83 | DK6: 2994.19 | DL6: 3006.47 | DM6: 3017.59 | DN6: 3040.22 | DO6: 3063.93 | DP6: 3079.86 | DQ6: 3097.42 | DR6: 3110.74 | DS6: 3110.74 | DT6: 3111.05 | DU6: 3112.29 | DV6: 3126.29 | DW6: 3149.74 | DX6: 3175.88 | DY6: 3195.89 | DZ6: 3222.42 | EA6: 3248.2 | EB6: 3273.86 | EC6: 3299.07 | ED6: 3314.58 | EE6: 3319.55 | EF6: 3324.86 | EG6: 3337.16 | EH6: 3354.85 | EI6: 3369.28 | EJ6: 3386.8 | EK6: 3403.73 | EL6: 3422.79 | EM6: 3438.19 | EN6: 3445.41 | EO6: 3467.46 | EP6: 3479.94 | EQ6: 3482.72 | ER6: 3497.7 | ES6: 3512.04 | ET6: 3532.06 | EU6: 3552.9 | EV6: 3574.22 | EW6: 3602.46 | EX6: 3633.44 | EY6: 3655.24 | EZ6: 3672.42 | FA6: 3692.62 | FB6: 3706.28 | FC6: 3715.92 | FD6: 3717.03 | FE6: 3725.95 | FF6: 3738.99 | FG6: 3760.3 | FH6: 3780.61 | FI6: 3815.39 | FJ6: 3836.37 | FK6: 3862.84 | FL6: 3898.38 | FM6: 3924.5 | FN6: 3942.55 | FO6: 3958.32 | FP6: 3958.72 | FQ6: 3968.62 | FR6: 3991.24 | FS6: 4008 | FT6: 4028.44 | FU6: 4059.86 | FV6: 4110.2 | FW6: 4160.34 | FX6: 4215.26 | FY6: 4245.19 | FZ6: 4276.6 | GA6: 4310.39 | GB6: 4337.11 | GC6: 4346.65 | GD6: 4370.12 | GE6: 4405.95 | GF6: 4450.45 | GG6: 4493.17 | GH6: 4550.23 | GI6: 4591.18 | GJ6: 4610.92 | GK6: 4639.05 | GL6: 4675.23 | GM6: 4691.59 | GN6: 4715.99 | GO6: 4736.74 | GP6: 4740.53 | GQ6: 4752.86 | GR6: 4761.42 | GS6: 4775.7 | GT6: 4793.85 | GU6: 4809.67 | GV6: 4821.69 | GW6: 4828.44 | GX6: 4843.41 | GY6: 4832.27 | GZ6: 4843.87 | HA6: 4853.07 | HB6: 4860.83 | HC6: 4881.25 | HD6: 4894.92 | HE6: 4916.46 | HF6: 4930.72 | HG6: 4946.5 | HH6: 4950.95 | HI6: 4961.84 | HJ6: 4981.69 | HK6: 5044.46 | HL6: 5061.11 | HM6: 5056.56 | HN6: 5080.83 | HO6: 5103.69 | HP6: 5092.97 | HQ6: 5100.61 | HR6: 5116.93 | HS6: 5138.93 | HT6: 5177.47 | HU6: 5206.98 | HV6: 5213.75 | HW6: 5214.27 | HX6: 5224.18 | HY6: 5229.93 | HZ6: 5227.84 | IA6: 5233.07 | IB6: 5259.76 | IC6: 5320.25 | ID6: 5331.42 | IE6: 5344.75 | IF6: 5348.49 | IG6: 5331.91 | IH6: 5311.65 | II6: 5325.46 | IJ6: 5344.63 | IK6: 5357.46 | IL6: 5391.75 | IM6: 5438.12 | IN6: 5486.52 | IO6: 5560.59 | IP6: 5574.49 | IQ6: 5622.43 | IR6: 5674.72 | IS6: 5692.31 | IT6: 5739.56 | IU6: 5769.98 | IV6: 5825.37 | IW6: 5876.05 | IX6: 5944.21 | IY6: 6018.51 | IZ6: 6075.69 | JA6: 6120.04 | JB6: 6153.09 | JC6: 6215.24 | JD6: 6315.93 | JE6: 6382.88 | JF6: 6412.88 | JG6: 6455.85 | JH6: 6411.95 | JI6: 6388.87 | JJ6: 6370.34 | JK6: 6407.93 | JL6: 6434.2 | JM6: 6474.09 | JN6: 6508.4 | JO6: 6563.07 | JP6: 6609.67 | JQ6: 6649.99 | JR6: 6665.28 | JS6: 6659.95 | JT6: 6667.94 | JU6: 6683.28 | JV6: 6700.66 | JW6: 6716.74 | JX6: 6735.55 | JY6: 6773.27 | JZ6: 6801.72 | KA6: 6858.17 | KB6: 6869.14 | KC6: 6895.24 | KD6: 6926.96 | KE6: 6941.51 | KF6: 6967.89 | KG6: 6966.5 | KH6: 6997.15 | KI6: 7036.33 | KJ6: 7063.77 | KK6: 7100.5
A7: IMF.STA:CPI(5.0.0) | B7: CHL.CPI._T.IX.M | C7: OBS_VALUE | D7: Chile | E7: Consumer price index (CPI) | F7: All Items | G7: Index | H7: Monthly | I7: Units | J7: 43.991852 | K7: 43.856581 | L7: 44.06537 | M7: 44.266505 | N7: 44.458819 | O7: 44.483526 | P7: 44.397654 | Q7: 44.754066 | R7: 45.082238 | S7: 45.143403 | T7: 45.139282 | U7: 44.9999 | V7: 44.963434 | W7: 44.967555 | X7: 45.205155 | Y7: 45.373357 | Z7: 45.414531 | AA7: 45.356891 | AB7: 45.558034 | AC7: 45.729762 | AD7: 46.115573 | AE7: 46.517263 | AF7: 46.476097 | AG7: 46.270842 | AH7: 46.316128 | AI7: 46.689586 | AJ7: 47.234779 | AK7: 47.189493 | AL7: 47.008937 | AM7: 47.008937 | AN7: 46.968359 | AO7: 47.04599 | AP7: 47.135974 | AQ7: 47.062464 | AR7: 46.918961 | AS7: 46.767217 | AT7: 46.681353 | AU7: 46.685466 | AV7: 46.881908 | AW7: 47.054223 | AX7: 47.300064 | AY7: 47.505319 | AZ7: 47.61589 | BA7: 47.796439 | BB7: 47.821138 | BC7: 47.960529 | BD7: 48.083445 | BE7: 47.902889 | BF7: 47.751153 | BG7: 47.705867 | BH7: 48.009347 | BI7: 48.439849 | BJ7: 48.571007 | BK7: 48.772142 | BL7: 49.071502 | BM7: 49.215005 | BN7: 49.702559 | BO7: 49.944867 | BP7: 49.825476 | BQ7: 49.657861 | BR7: 49.698439 | BS7: 49.653748 | BT7: 49.944867 | BU7: 50.264218 | BV7: 50.387135 | BW7: 50.682375 | BX7: 50.957035 | BY7: 51.092298 | BZ7: 51.100531 | CA7: 50.969381 | CB7: 50.883517 | CC7: 50.932923 | CD7: 51.088773 | CE7: 51.002321 | CF7: 51.21993 | CG7: 51.514574 | CH7: 51.834521 | CI7: 52.318542 | CJ7: 52.909021 | CK7: 53.483034 | CL7: 54.089392 | CM7: 54.257595 | CN7: 54.667525 | CO7: 54.917472 | CP7: 54.89748 | CQ7: 55.118614 | CR7: 55.577943 | CS7: 55.790844 | CT7: 56.434843 | CU7: 57.275275 | CV7: 57.922799 | CW7: 58.459759 | CX7: 59.083178 | CY7: 59.603665 | CZ7: 59.526034 | DA7: 58.81263 | DB7: 58.365655 | DC7: 57.605647 | DD7: 57.628674 | DE7: 57.542306 | DF7: 57.415645 | DG7: 57.611402 | DH7: 57.363821 | DI7: 57.098968 | DJ7: 57.749587 | DK7: 57.743832 | DL7: 57.513524 | DM7: 57.294732 | DN7: 57.59413 | DO7: 57.752314 | DP7: 57.805042 | DQ7: 58.068682 | DR7: 58.279595 | DS7: 58.279595 | DT7: 58.656224 | DU7: 58.595963 | DV7: 58.829473 | DW7: 58.889734 | DX7: 58.927397 | DY7: 59.002723 | DZ7: 59.160907 | EA7: 59.296493 | EB7: 59.748448 | EC7: 59.936763 | ED7: 60.177806 | EE7: 60.283262 | EF7: 60.358588 | EG7: 60.456511 | EH7: 60.757815 | EI7: 61.051585 | EJ7: 61.247432 | EK7: 61.616529 | EL7: 61.669257 | EM7: 61.9103 | EN7: 62.015756 | EO7: 62.045886 | EP7: 62.060951 | EQ7: 61.880169 | ER7: 61.872637 | ES7: 62.008223 | ET7: 62.482776 | EU7: 62.836808 | EV7: 62.550569 | EW7: 62.535504 | EX7: 62.648493 | EY7: 62.716286 | EZ7: 62.957329 | FA7: 62.656026 | FB7: 62.648493 | FC7: 63.04772 | FD7: 63.213437 | FE7: 63.364088 | FF7: 63.710587 | FG7: 63.800978 | FH7: 64.034488 | FI7: 64.41865 | FJ7: 64.531639 | FK7: 64.848007 | FL7: 65.390353 | FM7: 65.797113 | FN7: 66.02309 | FO7: 66.05322 | FP7: 66.211405 | FQ7: 66.422317 | FR7: 66.979728 | FS7: 67.672726 | FT7: 67.695324 | FU7: 67.416618 | FV7: 67.461813 | FW7: 67.702856 | FX7: 68.124681 | FY7: 68.523908 | FZ7: 68.644429 | GA7: 68.975863 | GB7: 69.262101 | GC7: 69.736654 | GD7: 70.090685 | GE7: 70.376923 | GF7: 70.354325 | GG7: 70.361858 | GH7: 70.693292 | GI7: 70.889139 | GJ7: 71.160312 | GK7: 71.393822 | GL7: 71.552006 | GM7: 71.875907 | GN7: 72.049157 | GO7: 72.086819 | GP7: 72.260069 | GQ7: 72.38059 | GR7: 72.418253 | GS7: 72.267601 | GT7: 72.659296 | GU7: 72.832545 | GV7: 73.111251 | GW7: 73.292033 | GX7: 73.382424 | GY7: 73.096186 | GZ7: 73.269435 | HA7: 73.420087 | HB7: 73.307098 | HC7: 73.736455 | HD7: 73.804248 | HE7: 73.909705 | HF7: 74.248671 | HG7: 74.286334 | HH7: 74.436985 | HI7: 74.670495 | HJ7: 74.881408 | HK7: 74.956734 | HL7: 75.220374 | HM7: 75.35596 | HN7: 75.612068 | HO7: 75.883241 | HP7: 75.883241 | HQ7: 75.807915 | HR7: 75.890774 | HS7: 75.920904 | HT7: 76.282468 | HU7: 76.485848 | HV7: 76.945335 | HW7: 76.982998 | HX7: 77.156248 | HY7: 77.299367 | HZ7: 77.306899 | IA7: 77.939636 | IB7: 77.999897 | IC7: 78.082756 | ID7: 78.519645 | IE7: 78.873677 | IF7: 79.137317 | IG7: 79.099654 | IH7: 79.061991 | II7: 79.009263 | IJ7: 79.084589 | IK7: 79.190045 | IL7: 79.694728 | IM7: 80.237074 | IN7: 80.131618 | IO7: 80.402791 | IP7: 80.967735 | IQ7: 81.118386 | IR7: 81.41969 | IS7: 81.728526 | IT7: 81.946971 | IU7: 82.014764 | IV7: 82.677631 | IW7: 82.971402 | IX7: 83.950638 | IY7: 85.072993 | IZ7: 85.50235 | JA7: 86.165217 | JB7: 87.204714 | JC7: 87.453289 | JD7: 89.080327 | JE7: 90.323203 | JF7: 91.407895 | JG7: 92.259077 | JH7: 93.524551 | JI7: 94.661971 | JJ7: 95.47549 | JK7: 95.97264 | JL7: 96.90668 | JM7: 97.185386 | JN7: 97.961242 | JO7: 97.900981 | JP7: 98.963076 | JQ7: 99.271912 | JR7: 99.3849 | JS7: 99.234249 | JT7: 99.580747 | JU7: 99.693736 | JV7: 100.36414 | JW7: 100.80103 | JX7: 101.55428 | JY7: 101.01194 | JZ7: 101.72002 | KA7: 102.32004 | KB7: 102.7 | KC7: 103.24 | KD7: 103.52 | KE7: 103.42 | KF7: 104.19 | KG7: 104.45 | KH7: 104.54 | KI7: 105.56 | KJ7: 105.83 | KK7: 105.62
A8: IMF.STA:CPI(5.0.0) | B8: CHN.CPI._T.IX.M | C8: OBS_VALUE | D8: China, People's Republic of | E8: Consumer price index (CPI) | F8: All Items | G8: Index | H8: Monthly | I8: Units | J8: 64.357 | K8: 64.42136 | L8: 64.03484 | M8: 64.1629 | N8: 63.84209 | O8: 63.07598 | P8: 62.7606 | Q8: 62.82336 | R8: 63.38877 | S8: 63.57894 | T8: 63.45178 | U8: 63.51524 | V8: 63.70578 | W8: 64.40655 | X8: 63.56926 | Y8: 63.37855 | Z8: 63.18842 | AA8: 62.61972 | AB8: 62.18138 | AC8: 62.36793 | AD8: 62.99161 | AE8: 63.11759 | AF8: 63.05447 | AG8: 63.24364 | AH8: 63.93932 | AI8: 64.51477 | AJ8: 64.12768 | AK8: 63.99942 | AL8: 63.55143 | AM8: 62.78881 | AN8: 62.47487 | AO8: 62.91219 | AP8: 63.66714 | AQ8: 64.24014 | AR8: 64.88255 | AS8: 65.27184 | AT8: 65.98983 | AU8: 65.85785 | AV8: 66.05542 | AW8: 66.3857 | AX8: 66.31931 | AY8: 65.85508 | AZ8: 65.72337 | BA8: 66.18343 | BB8: 66.91145 | BC8: 66.91145 | BD8: 66.71072 | BE8: 66.77743 | BF8: 67.17809 | BG8: 68.3873 | BH8: 67.77181 | BI8: 67.5685 | BJ8: 67.43336 | BK8: 66.89389 | BL8: 66.89389 | BM8: 67.02768 | BN8: 67.49687 | BO8: 67.76686 | BP8: 67.56356 | BQ8: 67.83382 | BR8: 68.71565 | BS8: 69.05923 | BT8: 68.4377 | BU8: 68.57458 | BV8: 68.506 | BW8: 68.16347 | BX8: 67.95898 | BY8: 68.16286 | BZ8: 68.50367 | CA8: 68.57217 | CB8: 68.77789 | CC8: 69.74078 | CD8: 70.22897 | CE8: 70.93126 | CF8: 70.71846 | CG8: 70.64774 | CH8: 70.85969 | CI8: 71.14313 | CJ8: 71.78342 | CK8: 72.64481 | CL8: 72.86275 | CM8: 73.08134 | CN8: 73.59291 | CO8: 74.32883 | CP8: 75.22079 | CQ8: 77.17652 | CR8: 76.63628 | CS8: 76.71292 | CT8: 76.40607 | CU8: 76.25326 | CV8: 76.32951 | CW8: 76.25318 | CX8: 76.25318 | CY8: 76.02442 | CZ8: 75.41623 | DA8: 75.2654 | DB8: 75.94279 | DC8: 75.94279 | DD8: 75.71496 | DE8: 75.56353 | DF8: 75.33684 | DG8: 74.96015 | DH8: 74.96015 | DI8: 75.33495 | DJ8: 75.63628 | DK8: 75.56251 | DL8: 75.7899 | DM8: 76.54786 | DN8: 77.00264 | DO8: 77.93114 | DP8: 77.38162 | DQ8: 77.53953 | DR8: 77.46373 | DS8: 76.99632 | DT8: 77.30582 | DU8: 77.76691 | DV8: 78.23433 | DW8: 78.78385 | DX8: 79.64919 | DY8: 80.04712 | DZ8: 80.8493 | EA8: 81.8829 | EB8: 81.71854 | EC8: 81.80072 | ED8: 81.8829 | EE8: 82.12944 | EF8: 82.48972 | EG8: 82.72406 | EH8: 83.11464 | EI8: 83.19276 | EJ8: 83.03652 | EK8: 83.27087 | EL8: 84.52071 | EM8: 84.4426 | EN8: 84.59883 | EO8: 84.52071 | EP8: 84.28637 | EQ8: 83.81767 | ER8: 83.89579 | ES8: 84.44312 | ET8: 84.70231 | EU8: 84.61381 | EV8: 84.75506 | EW8: 85.37871 | EX8: 86.23212 | EY8: 87.18035 | EZ8: 86.39648 | FA8: 86.56728 | FB8: 86.04879 | FC8: 86.04879 | FD8: 86.13388 | FE8: 86.56716 | FF8: 87.2571 | FG8: 87.34471 | FH8: 87.25703 | FI8: 87.51881 | FJ8: 88.39396 | FK8: 88.8422 | FL8: 88.39396 | FM8: 88.03536 | FN8: 88.12501 | FO8: 88.03536 | FP8: 88.03536 | FQ8: 88.21466 | FR8: 88.6629 | FS8: 88.6629 | FT8: 88.39396 | FU8: 88.75256 | FV8: 89.0215 | FW8: 90.09729 | FX8: 89.55939 | FY8: 89.3801 | FZ8: 89.2008 | GA8: 89.2008 | GB8: 89.55939 | GC8: 90.00764 | GD8: 90.09729 | GE8: 89.73869 | GF8: 89.73869 | GG8: 90.18694 | GH8: 90.63519 | GI8: 92.06957 | GJ8: 91.62132 | GK8: 91.44202 | GL8: 91.08343 | GM8: 90.90413 | GN8: 91.08343 | GO8: 91.17308 | GP8: 91.80062 | GQ8: 91.71098 | GR8: 91.80062 | GS8: 91.97992 | GT8: 92.96606 | GU8: 92.78676 | GV8: 92.51781 | GW8: 92.51781 | GX8: 92.60746 | GY8: 92.42816 | GZ8: 92.33852 | HA8: 92.78676 | HB8: 93.32465 | HC8: 93.41431 | HD8: 93.41431 | HE8: 93.68325 | HF8: 94.3108 | HG8: 95.47623 | HH8: 94.40044 | HI8: 94.22115 | HJ8: 94.04185 | HK8: 94.04185 | HL8: 94.3108 | HM8: 94.93834 | HN8: 95.56588 | HO8: 95.74518 | HP8: 95.38658 | HQ8: 95.47623 | HR8: 95.92448 | HS8: 96.91061 | HT8: 96.55202 | HU8: 96.64167 | HV8: 96.64167 | HW8: 96.55202 | HX8: 96.91061 | HY8: 97.62781 | HZ8: 98.43465 | IA8: 99.33114 | IB8: 99.68974 | IC8: 99.68974 | ID8: 101.1241 | IE8: 101.931 | IF8: 100.6759 | IG8: 99.77939 | IH8: 98.97254 | II8: 98.97254 | IJ8: 98.61395 | IK8: 99.95869 | IL8: 100.138 | IM8: 99.86903 | IN8: 99.24149 | IO8: 99.95869 | IP8: 100.9 | IQ8: 101.5 | IR8: 101 | IS8: 100.7 | IT8: 100.6 | IU8: 100.2 | IV8: 100.5 | IW8: 100.6 | IX8: 100.6 | IY8: 101.3 | IZ8: 101.7 | JA8: 101.4 | JB8: 101.9 | JC8: 102.5 | JD8: 102.5 | JE8: 102.9 | JF8: 102.7 | JG8: 102.7 | JH8: 103.2 | JI8: 103.1 | JJ8: 103.4 | JK8: 103.5 | JL8: 103.3 | JM8: 103.2 | JN8: 104 | JO8: 103.5 | JP8: 103.2 | JQ8: 103 | JR8: 102.9 | JS8: 102.7 | JT8: 102.9 | JU8: 103.2 | JV8: 103.4 | JW8: 103.3 | JX8: 102.8 | JY8: 102.9 | JZ8: 103.1 | KA8: 104.2 | KB8: 103.3 | KC8: 103.2 | KD8: 103.2 | KE8: 102.9 | KF8: 103.4 | KG8: 103.8 | KH8: 103.8 | KI8: 103.6 | KJ8: 103 | KK8: 103
A9: IMF.STA:CPI(5.0.0) | B9: COL.CPI._T.IX.M | C9: OBS_VALUE | D9: Colombia | E9: Consumer price index (CPI) | F9: All Items | G9: Index | H9: Monthly | I9: Units | J9: 43.72165 | K9: 44.55224 | L9: 45.20835 | M9: 45.72485 | N9: 45.92029 | O9: 45.94123 | P9: 45.99009 | Q9: 46.10875 | R9: 46.27626 | S9: 46.367 | T9: 46.41586 | U9: 46.57639 | V9: 46.94632 | W9: 47.53961 | X9: 47.87464 | Y9: 48.31437 | Z9: 48.60054 | AA9: 48.80994 | AB9: 48.81692 | AC9: 48.86578 | AD9: 49.04027 | AE9: 49.31947 | AF9: 49.69638 | AG9: 49.83598 | AH9: 50.4153 | AI9: 50.98067 | AJ9: 51.51113 | AK9: 52.10442 | AL9: 52.35569 | AM9: 52.32777 | AN9: 52.251 | AO9: 52.41851 | AP9: 52.53019 | AQ9: 52.56509 | AR9: 52.74656 | AS9: 53.06763 | AT9: 53.53528 | AU9: 54.17743 | AV9: 54.71487 | AW9: 54.95917 | AX9: 55.16856 | AY9: 55.50359 | AZ9: 55.48964 | BA9: 55.50359 | BB9: 55.67111 | BC9: 55.66413 | BD9: 55.81769 | BE9: 55.9852 | BF9: 56.44587 | BG9: 57.0252 | BH9: 57.46493 | BI9: 57.7162 | BJ9: 57.95351 | BK9: 58.18385 | BL9: 58.21177 | BM9: 58.21177 | BN9: 58.46304 | BO9: 58.59566 | BP9: 58.66546 | BQ9: 58.70036 | BR9: 59.02143 | BS9: 59.40532 | BT9: 59.82411 | BU9: 60.09632 | BV9: 60.29176 | BW9: 60.47323 | BX9: 60.72451 | BY9: 60.96182 | BZ9: 61.13631 | CA9: 61.04558 | CB9: 61.19215 | CC9: 61.33175 | CD9: 61.7994 | CE9: 62.5253 | CF9: 63.2861 | CG9: 63.85147 | CH9: 64.04691 | CI9: 64.12368 | CJ9: 64.22838 | CK9: 64.14462 | CL9: 64.19348 | CM9: 64.20046 | CN9: 64.50758 | CO9: 64.82166 | CP9: 65.50569 | CQ9: 66.49683 | CR9: 67.03427 | CS9: 67.5089 | CT9: 68.13708 | CU9: 68.73037 | CV9: 69.05842 | CW9: 69.19104 | CX9: 69.05842 | CY9: 69.29574 | CZ9: 69.49117 | DA9: 69.79829 | DB9: 70.21009 | DC9: 70.7964 | DD9: 71.15237 | DE9: 71.37572 | DF9: 71.38969 | DG9: 71.3478 | DH9: 71.31989 | DI9: 71.35478 | DJ9: 71.27801 | DK9: 71.18029 | DL9: 71.13841 | DM9: 71.19425 | DN9: 71.68284 | DO9: 72.27612 | DP9: 72.4576 | DQ9: 72.79263 | DR9: 72.86941 | DS9: 72.95316 | DT9: 72.91827 | DU9: 73.00202 | DV9: 72.9043 | DW9: 72.84149 | DX9: 72.98109 | DY9: 73.45571 | DZ9: 74.1188 | EA9: 74.56551 | EB9: 74.76792 | EC9: 74.85866 | ED9: 75.06805 | EE9: 75.31235 | EF9: 75.41705 | EG9: 75.38912 | EH9: 75.62644 | EI9: 75.76604 | EJ9: 75.87074 | EK9: 76.1918 | EL9: 76.75019 | EM9: 77.21784 | EN9: 77.30858 | EO9: 77.42026 | EP9: 77.65059 | EQ9: 77.72039 | ER9: 77.69945 | ES9: 77.73434 | ET9: 77.9577 | EU9: 78.08334 | EV9: 77.97865 | EW9: 78.04844 | EX9: 78.27878 | EY9: 78.62777 | EZ9: 78.7883 | FA9: 78.98373 | FB9: 79.20709 | FC9: 79.39555 | FD9: 79.43044 | FE9: 79.49326 | FF9: 79.73058 | FG9: 79.52119 | FH9: 79.34669 | FI9: 79.55608 | FJ9: 79.94695 | FK9: 80.4495 | FL9: 80.7636 | FM9: 81.13352 | FN9: 81.53137 | FO9: 81.60117 | FP9: 81.72681 | FQ9: 81.89433 | FR9: 82.006 | FS9: 82.13862 | FT9: 82.2503 | FU9: 82.46667 | FV9: 82.99714 | FW9: 83.95338 | FX9: 84.44196 | FY9: 84.89565 | FZ9: 85.119 | GA9: 85.20975 | GB9: 85.37028 | GC9: 85.78209 | GD9: 86.39632 | GE9: 86.98262 | GF9: 87.50611 | GG9: 88.05054 | GH9: 89.18825 | GI9: 90.32596 | GJ9: 91.1775 | GK9: 91.63119 | GL9: 92.09883 | GM9: 92.53857 | GN9: 93.02017 | GO9: 92.72702 | GP9: 92.67816 | GQ9: 92.62232 | GR9: 92.72702 | GS9: 93.11091 | GT9: 94.06715 | GU9: 95.00942 | GV9: 95.45613 | GW9: 95.90284 | GX9: 96.11922 | GY9: 96.2309 | GZ9: 96.18204 | HA9: 96.31465 | HB9: 96.35653 | HC9: 96.37049 | HD9: 96.54498 | HE9: 96.91492 | HF9: 97.52216 | HG9: 98.21317 | HH9: 98.45048 | HI9: 98.90417 | HJ9: 99.15544 | HK9: 99.309 | HL9: 99.18336 | HM9: 99.30202 | HN9: 99.46255 | HO9: 99.58121 | HP9: 99.69987 | HQ9: 100 | HR9: 100.5985 | HS9: 101.1768 | HT9: 101.6162 | HU9: 102.1201 | HV9: 102.4414 | HW9: 102.7153 | HX9: 102.9402 | HY9: 103.0274 | HZ9: 103.2627 | IA9: 103.4265 | IB9: 103.5351 | IC9: 103.8043 | ID9: 104.2425 | IE9: 104.9406 | IF9: 105.534 | IG9: 105.6996 | IH9: 105.363 | II9: 104.9666 | IJ9: 104.9681 | IK9: 104.9623 | IL9: 105.2944 | IM9: 105.2346 | IN9: 105.0772 | IO9: 105.476 | IP9: 105.9075 | IQ9: 106.5809 | IR9: 107.1239 | IS9: 107.7584 | IT9: 108.8354 | IU9: 108.7819 | IV9: 109.1354 | IW9: 109.6237 | IX9: 110.0433 | IY9: 110.058 | IZ9: 110.6031 | JA9: 111.4066 | JB9: 113.2623 | JC9: 115.1129 | JD9: 116.2593 | JE9: 117.7089 | JF9: 118.7032 | JG9: 119.3053 | JH9: 120.2736 | JI9: 121.5025 | JJ9: 122.6321 | JK9: 123.509 | JL9: 124.4633 | JM9: 126.0259 | JN9: 128.2718 | JO9: 130.3988 | JP9: 131.7733 | JQ9: 132.8026 | JR9: 133.3753 | JS9: 133.7765 | JT9: 134.4477 | JU9: 135.387 | JV9: 136.1147 | JW9: 136.4511 | JX9: 137.0947 | JY9: 137.7161 | JZ9: 138.9781 | KA9: 140.4882 | KB9: 141.4753 | KC9: 142.3156 | KD9: 142.9208 | KE9: 143.385 | KF9: 143.6709 | KG9: 143.6733 | KH9: 144.0213 | KI9: 143.8278 | KJ9: 144.22 | KK9: 144.8816
A10: IMF.STA:CPI(5.0.0) | B10: DNK.CPI._T.IX.M | C10: OBS_VALUE | D10: Denmark | E10: Consumer price index (CPI) | F10: All Items | G10: Index | H10: Monthly | I10: Units | J10: 76.7 | K10: 77.3 | L10: 77.7 | M10: 78 | N10: 78.4 | O10: 78.3 | P10: 78.1 | Q10: 78.1 | R10: 78.4 | S10: 78.5 | T10: 78.3 | U10: 78.5 | V10: 78.6 | W10: 79.2 | X10: 79.7 | Y10: 80 | Z10: 80 | AA10: 80 | AB10: 79.8 | AC10: 79.9 | AD10: 80.3 | AE10: 80.5 | AF10: 80.5 | AG10: 80.5 | AH10: 80.6 | AI10: 81.4 | AJ10: 82 | AK10: 81.9 | AL10: 81.8 | AM10: 81.8 | AN10: 81.3 | AO10: 81.3 | AP10: 81.8 | AQ10: 81.6 | AR10: 81.8 | AS10: 81.6 | AT10: 81.6 | AU10: 82.2 | AV10: 82.5 | AW10: 82.6 | AX10: 82.9 | AY10: 82.7 | AZ10: 82.4 | BA10: 82.2 | BB10: 82.7 | BC10: 83 | BD10: 82.8 | BE10: 82.6 | BF10: 82.4 | BG10: 83.2 | BH10: 83.7 | BI10: 84.1 | BJ10: 84.1 | BK10: 84.2 | BL10: 84.1 | BM10: 84.1 | BN10: 84.7 | BO10: 84.7 | BP10: 84.4 | BQ10: 84.5 | BR10: 84.2 | BS10: 85 | BT10: 85.3 | BU10: 85.7 | BV10: 85.8 | BW10: 86 | BX10: 85.8 | BY10: 85.8 | BZ10: 86.1 | CA10: 86 | CB10: 85.9 | CC10: 86 | CD10: 85.7 | CE10: 86.6 | CF10: 87 | CG10: 87.1 | CH10: 87.3 | CI10: 87.2 | CJ10: 86.8 | CK10: 86.6 | CL10: 87.2 | CM10: 87.5 | CN10: 88 | CO10: 88 | CP10: 88.2 | CQ10: 89.3 | CR10: 89.7 | CS10: 90 | CT10: 90.3 | CU10: 90.5 | CV10: 90.3 | CW10: 90.4 | CX10: 90.8 | CY10: 90.7 | CZ10: 90.4 | DA10: 90.1 | DB10: 89.8 | DC10: 90.9 | DD10: 91.2 | DE10: 91.1 | DF10: 91.4 | DG10: 91.6 | DH10: 91.2 | DI10: 91.4 | DJ10: 91.6 | DK10: 91.6 | DL10: 91.6 | DM10: 91.4 | DN10: 91.6 | DO10: 92.7 | DP10: 93.3 | DQ10: 93.4 | DR10: 93.4 | DS10: 93.3 | DT10: 93.2 | DU10: 93.6 | DV10: 93.9 | DW10: 93.8 | DX10: 93.9 | DY10: 94 | DZ10: 94.1 | EA10: 95.2 | EB10: 95.8 | EC10: 96.2 | ED10: 96.3 | EE10: 96.1 | EF10: 96 | EG10: 96 | EH10: 96.3 | EI10: 96.4 | EJ10: 96.3 | EK10: 96.3 | EL10: 96.7 | EM10: 97.8 | EN10: 98.3 | EO10: 98.3 | EP10: 98.4 | EQ10: 98.2 | ER10: 98.2 | ES10: 98.5 | ET10: 98.7 | EU10: 98.7 | EV10: 98.5 | EW10: 98.3 | EX10: 97.9 | EY10: 99 | EZ10: 99.3 | FA10: 99.1 | FB10: 99.2 | FC10: 99.1 | FD10: 98.8 | FE10: 98.9 | FF10: 99.2 | FG10: 99.3 | FH10: 99.1 | FI10: 99 | FJ10: 98.9 | FK10: 99.5 | FL10: 99.6 | FM10: 99.8 | FN10: 99.7 | FO10: 99.7 | FP10: 99.5 | FQ10: 99.4 | FR10: 99.7 | FS10: 99.8 | FT10: 99.6 | FU10: 99.4 | FV10: 98.8 | FW10: 99.8 | FX10: 100.2 | FY10: 100.3 | FZ10: 100.4 | GA10: 100.3 | GB10: 100.2 | GC10: 100 | GD10: 100.2 | GE10: 100.1 | GF10: 99.9 | GG10: 99.8 | GH10: 99.4 | GI10: 100.1 | GJ10: 100.2 | GK10: 100.3 | GL10: 100.5 | GM10: 100.6 | GN10: 100.5 | GO10: 100.2 | GP10: 100.2 | GQ10: 100.4 | GR10: 100.3 | GS10: 100.3 | GT10: 100.3 | GU10: 101.1 | GV10: 101.2 | GW10: 101.4 | GX10: 101.3 | GY10: 101.2 | GZ10: 102 | HA10: 101.7 | HB10: 101.8 | HC10: 101.9 | HD10: 101.6 | HE10: 101.3 | HF10: 101 | HG10: 101.7 | HH10: 101.7 | HI10: 102.2 | HJ10: 102.4 | HK10: 102.3 | HL10: 103.1 | HM10: 102.7 | HN10: 102.4 | HO10: 102.7 | HP10: 102.4 | HQ10: 102.1 | HR10: 102.3 | HS10: 102.8 | HT10: 102.9 | HU10: 103.2 | HV10: 103.1 | HW10: 102.9 | HX10: 103.5 | HY10: 103.1 | HZ10: 102.9 | IA10: 103.3 | IB10: 103.1 | IC10: 102.9 | ID10: 103 | IE10: 103.6 | IF10: 103.3 | IG10: 103.2 | IH10: 103.1 | II10: 103.2 | IJ10: 104 | IK10: 103.6 | IL10: 103.5 | IM10: 103.7 | IN10: 103.6 | IO10: 103.4 | IP10: 103.6 | IQ10: 104.2 | IR10: 104.3 | IS10: 104.7 | IT10: 104.9 | IU10: 105 | IV10: 105.7 | IW10: 105.5 | IX10: 105.8 | IY10: 106.8 | IZ10: 107.1 | JA10: 106.6 | JB10: 108.1 | JC10: 109.2 | JD10: 109.9 | JE10: 111.7 | JF10: 112.7 | JG10: 113.6 | JH10: 114.9 | JI10: 114.9 | JJ10: 116.4 | JK10: 117.6 | JL10: 116.6 | JM10: 115.9 | JN10: 116.4 | JO10: 117.5 | JP10: 117.3 | JQ10: 117.6 | JR10: 116 | JS10: 116.4 | JT10: 118.5 | JU10: 117.7 | JV10: 117.4 | JW10: 117.7 | JX10: 117.3 | JY10: 116.7 | JZ10: 117.8 | KA10: 118.4 | KB10: 118.4 | KC10: 118.5 | KD10: 118.5 | KE10: 118.5 | KF10: 119.8 | KG10: 119.3 | KH10: 118.9 | KI10: 119.6 | KJ10: 119.2 | KK10: 118.9
A11: IMF.STA:CPI(5.0.0) | B11: DNK.HICP._T.IX.M | C11: OBS_VALUE | D11: Denmark | E11: Harmonised index of consumer prices (HICP) | F11: All Items | G11: Index | H11: Monthly | I11: Units | J11: 78 | K11: 78.4 | L11: 78.8 | M11: 79.3 | N11: 79.7 | O11: 79.6 | P11: 79.3 | Q11: 79.2 | R11: 79.7 | S11: 79.7 | T11: 79.6 | U11: 79.7 | V11: 79.8 | W11: 80.3 | X11: 80.8 | Y11: 81.2 | Z11: 81.3 | AA11: 81.3 | AB11: 81 | AC11: 81.1 | AD11: 81.6 | AE11: 81.8 | AF11: 81.8 | AG11: 81.8 | AH11: 81.9 | AI11: 82.5 | AJ11: 83.2 | AK11: 83.1 | AL11: 83 | AM11: 82.9 | AN11: 82.4 | AO11: 82.4 | AP11: 83 | AQ11: 82.8 | AR11: 82.9 | AS11: 82.8 | AT11: 82.7 | AU11: 83.1 | AV11: 83.5 | AW11: 83.6 | AX11: 83.9 | AY11: 83.7 | AZ11: 83.4 | BA11: 83.1 | BB11: 83.7 | BC11: 84.1 | BD11: 83.8 | BE11: 83.6 | BF11: 83.4 | BG11: 84 | BH11: 84.6 | BI11: 85 | BJ11: 85 | BK11: 85.1 | BL11: 85 | BM11: 85 | BN11: 85.8 | BO11: 85.7 | BP11: 85.4 | BQ11: 85.5 | BR11: 85.1 | BS11: 85.8 | BT11: 86.1 | BU11: 86.6 | BV11: 86.7 | BW11: 86.9 | BX11: 86.7 | BY11: 86.7 | BZ11: 87 | CA11: 86.9 | CB11: 86.9 | CC11: 86.9 | CD11: 86.6 | CE11: 87.4 | CF11: 87.8 | CG11: 88 | CH11: 88.2 | CI11: 88 | CJ11: 87.6 | CK11: 87.4 | CL11: 88 | CM11: 88.4 | CN11: 89.1 | CO11: 89 | CP11: 89.3 | CQ11: 90.2 | CR11: 90.7 | CS11: 91 | CT11: 91.4 | CU11: 91.7 | CV11: 91.4 | CW11: 91.6 | CX11: 92 | CY11: 91.8 | CZ11: 91.6 | DA11: 91.2 | DB11: 90.8 | DC11: 91.7 | DD11: 92.1 | DE11: 92 | DF11: 92.3 | DG11: 92.5 | DH11: 92 | DI11: 92.3 | DJ11: 92.4 | DK11: 92.5 | DL11: 92.5 | DM11: 92.2 | DN11: 92.5 | DO11: 93.4 | DP11: 94 | DQ11: 94.2 | DR11: 94.2 | DS11: 94 | DT11: 94 | DU11: 94.4 | DV11: 94.8 | DW11: 94.6 | DX11: 94.7 | DY11: 94.8 | DZ11: 94.9 | EA11: 95.8 | EB11: 96.4 | EC11: 96.9 | ED11: 97 | EE11: 96.8 | EF11: 96.7 | EG11: 96.7 | EH11: 97 | EI11: 97.2 | EJ11: 97.1 | EK11: 97.1 | EL11: 97.5 | EM11: 98.4 | EN11: 99 | EO11: 99 | EP11: 99 | EQ11: 98.9 | ER11: 98.8 | ES11: 99.2 | ET11: 99.5 | EU11: 99.4 | EV11: 99.3 | EW11: 98.9 | EX11: 98.4 | EY11: 99.5 | EZ11: 99.7 | FA11: 99.5 | FB11: 99.7 | FC11: 99.5 | FD11: 99.2 | FE11: 99.3 | FF11: 99.6 | FG11: 99.8 | FH11: 99.5 | FI11: 99.4 | FJ11: 99.2 | FK11: 99.8 | FL11: 99.9 | FM11: 100 | FN11: 100 | FO11: 99.9 | FP11: 99.7 | FQ11: 99.6 | FR11: 99.9 | FS11: 100 | FT11: 99.8 | FU11: 99.5 | FV11: 98.9 | FW11: 99.7 | FX11: 100.2 | FY11: 100.4 | FZ11: 100.4 | GA11: 100.3 | GB11: 100.2 | GC11: 99.9 | GD11: 100.2 | GE11: 100.1 | GF11: 99.9 | GG11: 99.8 | GH11: 99.3 | GI11: 99.8 | GJ11: 99.9 | GK11: 100.1 | GL11: 100.3 | GM11: 100.4 | GN11: 100.3 | GO11: 99.9 | GP11: 99.9 | GQ11: 100.2 | GR11: 100 | GS11: 100.1 | GT11: 100 | GU11: 100.7 | GV11: 100.8 | GW11: 101.1 | GX11: 101 | GY11: 100.8 | GZ11: 101.8 | HA11: 101.4 | HB11: 101.5 | HC11: 101.6 | HD11: 101.3 | HE11: 100.9 | HF11: 100.6 | HG11: 101.2 | HH11: 101.2 | HI11: 101.8 | HJ11: 102 | HK11: 101.9 | HL11: 102.7 | HM11: 102.2 | HN11: 102 | HO11: 102.3 | HP11: 102 | HQ11: 101.6 | HR11: 101.8 | HS11: 102.3 | HT11: 102.4 | HU11: 102.7 | HV11: 102.7 | HW11: 102.4 | HX11: 103.1 | HY11: 102.7 | HZ11: 102.4 | IA11: 102.9 | IB11: 102.6 | IC11: 102.4 | ID11: 102.6 | IE11: 103 | IF11: 102.7 | IG11: 102.6 | IH11: 102.5 | II11: 102.6 | IJ11: 103.5 | IK11: 103.1 | IL11: 102.9 | IM11: 103.2 | IN11: 103 | IO11: 102.8 | IP11: 103 | IQ11: 103.5 | IR11: 103.6 | IS11: 104.1 | IT11: 104.4 | IU11: 104.5 | IV11: 105.3 | IW11: 105 | IX11: 105.4 | IY11: 106.5 | IZ11: 106.9 | JA11: 106.3 | JB11: 108 | JC11: 109 | JD11: 109.8 | JE11: 111.8 | JF11: 113 | JG11: 114 | JH11: 115.4 | JI11: 115.4 | JJ11: 117.1 | JK11: 118.6 | JL11: 117.3 | JM11: 116.5 | JN11: 117.1 | JO11: 118 | JP11: 117.8 | JQ11: 118.1 | JR11: 116.3 | JS11: 116.7 | JT11: 119.1 | JU11: 118.1 | JV11: 117.8 | JW11: 118.1 | JX11: 117.6 | JY11: 117 | JZ11: 118.2 | KA11: 118.7 | KB11: 118.7 | KC11: 118.7 | KD11: 118.7 | KE11: 118.8 | KF11: 120.3 | KG11: 119.7 | KH11: 119.2 | KI11: 120 | KJ11: 119.5 | KK11: 119.1
A12: IMF.STA:CPI(5.0.0) | B12: DOM.CPI._T.IX.M | C12: OBS_VALUE | D12: Dominican Republic | E12: Consumer price index (CPI) | F12: All Items | G12: Index | H12: Monthly | I12: Units | J12: 25.307374 | K12: 25.341669 | L12: 25.234498 | M12: 25.390967 | N12: 25.457414 | O12: 25.313804 | P12: 25.253789 | Q12: 25.440266 | R12: 25.671756 | S12: 25.736058 | T12: 25.710337 | U12: 25.772496 | V12: 25.918249 | W12: 25.928966 | X12: 26.224758 | Y12: 26.402662 | Z12: 26.308352 | AA12: 26.33836 | AB12: 26.443387 | AC12: 26.679164 | AD12: 27.054262 | AE12: 27.840898 | AF12: 27.97379 | AG12: 28.481781 | AH12: 29.418456 | AI12: 30.588764 | AJ12: 31.131049 | AK12: 31.221073 | AL12: 31.594028 | AM12: 33.216598 | AN12: 34.431918 | AO12: 35.486481 | AP12: 36.020193 | AQ12: 36.954725 | AR12: 39.177453 | AS12: 40.630692 | AT12: 44.381679 | AU12: 49.375851 | AV12: 50.533298 | AW12: 50.884819 | AX12: 52.222314 | AY12: 53.261873 | AZ12: 53.589817 | BA12: 53.881322 | BB12: 53.270447 | BC12: 53.988493 | BD12: 53.09683 | BE12: 52.308051 | BF12: 52.719588 | BG12: 52.741022 | BH12: 52.70244 | BI12: 52.867484 | BJ12: 52.708871 | BK12: 52.738879 | BL12: 53.053961 | BM12: 53.763434 | BN12: 55.516752 | BO12: 56.134058 | BP12: 55.662505 | BQ12: 56.19836 | BR12: 57.068589 | BS12: 57 | BT12: 57.053585 | BU12: 57.392246 | BV12: 57.720189 | BW12: 58.157447 | BX12: 58.678299 | BY12: 58.789757 | BZ12: 58.142443 | CA12: 58.202459 | CB12: 58.575414 | CC12: 59.008386 | CD12: 59.559245 | CE12: 59.741436 | CF12: 60.212988 | CG12: 60.701688 | CH12: 61.346858 | CI12: 61.593352 | CJ12: 61.751965 | CK12: 61.355432 | CL12: 62.103486 | CM12: 62.399278 | CN12: 63.522431 | CO12: 64.246907 | CP12: 64.947806 | CQ12: 64.926371 | CR12: 66.036664 | CS12: 67.277705 | CT12: 67.502764 | CU12: 69.11033 | CV12: 70.229196 | CW12: 70.293498 | CX12: 71.157297 | CY12: 70.41353 | CZ12: 68.105065 | DA12: 67.149099 | DB12: 67.33772 | DC12: 67.543489 | DD12: 67.648516 | DE12: 67.74497 | DF12: 67.822134 | DG12: 69.288234 | DH12: 69.371827 | DI12: 69.963411 | DJ12: 70.040574 | DK12: 70.201331 | DL12: 70.951528 | DM12: 71.020118 | DN12: 71.952506 | DO12: 72.053247 | DP12: 72.672696 | DQ12: 72.93205 | DR12: 73.180686 | DS12: 73.056368 | DT12: 73.307148 | DU12: 73.467905 | DV12: 74.033768 | DW12: 74.533185 | DX12: 74.764675 | DY12: 75.45057 | DZ12: 74.513841 | EA12: 75.409532 | EB12: 76.280936 | EC12: 76.947736 | ED12: 77.11554 | EE12: 77.903778 | EF12: 78.566192 | EG12: 78.956233 | EH12: 79.124773 | EI12: 79.149281 | EJ12: 79.220451 | EK12: 79.309505 | EL12: 79.655417 | EM12: 79.93509 | EN12: 80.052847 | EO12: 80.060207 | EP12: 79.846772 | EQ12: 80.016048 | ER12: 79.854132 | ES12: 80.663713 | ET12: 81.186261 | EU12: 81.377616 | EV12: 81.892804 | EW12: 82.407992 | EX12: 83.445728 | EY12: 83.718042 | EZ12: 84.034514 | FA12: 83.982995 | FB12: 83.828439 | FC12: 83.857878 | FD12: 84.380426 | FE12: 84.939773 | FF12: 85.351923 | FG12: 85.234166 | FH12: 85.285685 | FI12: 85.602158 | FJ12: 85.800873 | FK12: 86.095266 | FL12: 86.544215 | FM12: 86.912207 | FN12: 86.926927 | FO12: 86.941646 | FP12: 87.258119 | FQ12: 87.596671 | FR12: 87.765947 | FS12: 87.692349 | FT12: 87.567232 | FU12: 86.956366 | FV12: 86.79445 | FW12: 86.971085 | FX12: 87.096203 | FY12: 86.875408 | FZ12: 87.125642 | GA12: 87.478914 | GB12: 87.692349 | GC12: 87.972022 | GD12: 88.111859 | GE12: 88.766883 | GF12: 88.91408 | GG12: 88.995038 | GH12: 88.987678 | GI12: 88.48721 | GJ12: 88.47985 | GK12: 88.398892 | GL12: 88.619687 | GM12: 89.149595 | GN12: 89.318871 | GO12: 89.267352 | GP12: 89.304151 | GQ12: 89.576465 | GR12: 89.694222 | GS12: 90.503803 | GT12: 91.06315 | GU12: 91.445861 | GV12: 91.261865 | GW12: 91.504739 | GX12: 91.372263 | GY12: 91.423781 | GZ12: 91.585698 | HA12: 92.108245 | HB12: 92.697032 | HC12: 92.697032 | HD12: 93.403575 | HE12: 94.308834 | HF12: 94.581147 | HG12: 94.47811 | HH12: 94.831382 | HI12: 95.206733 | HJ12: 95.456967 | HK12: 95.655682 | HL12: 95.640963 | HM12: 95.670402 | HN12: 95.744 | HO12: 95.957435 | HP12: 95.618883 | HQ12: 95.412808 | HR12: 95.250892 | HS12: 95.604164 | HT12: 96.229749 | HU12: 96.737577 | HV12: 96.708138 | HW12: 96.531502 | HX12: 96.980451 | HY12: 97.311644 | HZ12: 97.679635 | IA12: 98.33466 | IB12: 98.702651 | IC12: 98.901366 | ID12: 99.225199 | IE12: 99.100082 | IF12: 98.584894 | IG12: 97.775313 | IH12: 97.664915 | II12: 99.328236 | IJ12: 101.19763 | IK12: 101.98513 | IL12: 102.596 | IM12: 103.276 | IN12: 103.893 | IO12: 104.394 | IP12: 105.404 | IQ12: 106.124 | IR12: 106.764 | IS12: 107.206 | IT12: 107.901 | IU12: 108.585 | IV12: 109.168 | IW12: 110.04 | IX12: 110.535 | IY12: 111.244 | IZ12: 112.446 | JA12: 113.263 | JB12: 114.602 | JC12: 115.658 | JD12: 116.431 | JE12: 117.544 | JF12: 118.122 | JG12: 118.877 | JH12: 119.468 | JI12: 119.718 | JJ12: 120.07 | JK12: 120.405 | JL12: 120.966 | JM12: 122.128 | JN12: 122.903 | JO12: 123.035 | JP12: 123.299 | JQ12: 123.6 | JR12: 123.356 | JS12: 123.627 | JT12: 124.1884 | JU12: 124.8282 | JV12: 125.3654 | JW12: 125.6376 | JX12: 125.8094 | JY12: 126.4866 | JZ12: 126.9796 | KA12: 127.0946 | KB12: 127.4728 | KC12: 127.3478 | KD12: 127.2987 | KE12: 127.9079 | KF12: 128.5831 | KG12: 129.1021 | KH12: 129.4854 | KI12: 129.6056 | KJ12: 129.8098 | KK12: 130.722
A13: IMF.STA:CPI(5.0.0) | B13: ECU.CPI._T.IX.M | C13: OBS_VALUE | D13: Ecuador | E13: Consumer price index (CPI) | F13: All Items | G13: Index | H13: Monthly | I13: Units | J13: 49.468445 | K13: 50.909274 | L13: 52.026321 | M13: 52.922117 | N13: 53.008458 | O13: 53.262087 | P13: 53.3916 | Q13: 53.623644 | R13: 54.719105 | S13: 55.361272 | T13: 56.246275 | U13: 56.624021 | V13: 57.646091 | W13: 58.261277 | X13: 58.915316 | Y13: 59.796541 | Z13: 60.089024 | AA13: 60.31837 | AB13: 60.278437 | AC13: 60.541779 | AD13: 60.890924 | AE13: 61.283779 | AF13: 61.709552 | AG13: 61.921629 | AH13: 63.46121 | AI13: 63.946343 | AJ13: 64.30682 | AK13: 64.932259 | AL13: 65.047201 | AM13: 64.911752 | AN13: 64.933338 | AO13: 64.973271 | AP13: 65.487005 | AQ13: 65.488623 | AR13: 65.707176 | AS13: 65.680194 | AT13: 65.949473 | AU13: 66.401688 | AV13: 66.865775 | AW13: 67.302341 | AX13: 66.982336 | AY13: 66.776195 | AZ13: 66.364993 | BA13: 66.382801 | BB13: 66.534978 | BC13: 66.721692 | BD13: 67.001224 | BE13: 66.958053 | BF13: 67.121918 | BG13: 67.304613 | BH13: 67.481874 | BI13: 68.04696 | BJ13: 68.166119 | BK13: 68.214567 | BL13: 68.108353 | BM13: 68.008712 | BN13: 68.49608 | BO13: 68.735777 | BP13: 68.851363 | BQ13: 69.056665 | BR13: 69.386835 | BS13: 69.87796 | BT13: 70.333289 | BU13: 70.38145 | BV13: 70.284315 | BW13: 70.122692 | BX13: 70.143546 | BY13: 70.294099 | BZ13: 70.696813 | CA13: 70.943382 | CB13: 71.060782 | CC13: 71.038173 | CD13: 71.249075 | CE13: 71.297216 | CF13: 71.365551 | CG13: 71.358784 | CH13: 71.380284 | CI13: 71.656888 | CJ13: 71.956441 | CK13: 72.008932 | CL13: 72.520302 | CM13: 72.617999 | CN13: 72.979256 | CO13: 73.396432 | CP13: 74.234712 | CQ13: 74.935165 | CR13: 76.04391 | CS13: 77.198497 | CT13: 78.008168 | CU13: 78.598522 | CV13: 79.05926 | CW13: 79.225183 | CX13: 79.747573 | CY13: 79.772782 | CZ13: 79.644603 | DA13: 79.877734 | DB13: 80.442804 | DC13: 80.817792 | DD13: 81.699662 | DE13: 82.23477 | DF13: 82.227597 | DG13: 82.165439 | DH13: 82.105065 | DI13: 81.860631 | DJ13: 82.372647 | DK13: 82.567888 | DL13: 82.84512 | DM13: 83.321857 | DN13: 84.01399 | DO13: 84.300315 | DP13: 84.437662 | DQ13: 84.874474 | DR13: 84.888697 | DS13: 84.880883 | DT13: 84.897489 | DU13: 84.987929 | DV13: 85.206307 | DW13: 85.423004 | DX13: 85.65426 | DY13: 86.094838 | DZ13: 86.679584 | EA13: 87.160621 | EB13: 87.454201 | EC13: 88.171396 | ED13: 88.476337 | EE13: 88.511526 | EF13: 88.667149 | EG13: 89.098049 | EH13: 89.802691 | EI13: 90.11894 | EJ13: 90.392332 | EK13: 90.752037 | EL13: 91.266739 | EM13: 91.976326 | EN13: 92.804957 | EO13: 92.951585 | EP13: 92.771207 | EQ13: 92.933645 | ER13: 93.176413 | ES13: 93.445382 | ET13: 94.493759 | EU13: 94.575031 | EV13: 94.706818 | EW13: 94.53087 | EX13: 95.006193 | EY13: 95.181664 | EZ13: 95.598925 | FA13: 95.770053 | FB13: 95.561372 | FC13: 95.423009 | FD13: 95.405203 | FE13: 95.570817 | FF13: 96.113546 | FG13: 96.505951 | FH13: 96.886366 | FI13: 97.083526 | FJ13: 97.784188 | FK13: 97.891656 | FL13: 98.573258 | FM13: 98.864518 | FN13: 98.823861 | FO13: 98.926698 | FP13: 99.325737 | FQ13: 99.53375 | FR13: 100.14362 | FS13: 100.34671 | FT13: 100.52857 | FU13: 100.64393 | FV13: 101.23809 | FW13: 101.85807 | FX13: 102.27995 | FY13: 103.13628 | FZ13: 103.31886 | GA13: 103.73993 | GB13: 103.65746 | GC13: 103.6561 | GD13: 103.93019 | GE13: 103.83616 | GF13: 103.94768 | GG13: 104.04582 | GH13: 104.36644 | GI13: 104.51051 | GJ13: 104.65371 | GK13: 104.97455 | GL13: 105.00793 | GM13: 105.38476 | GN13: 105.29497 | GO13: 105.12332 | GP13: 105.2835 | GQ13: 105.1969 | GR13: 105.04411 | GS13: 105.21091 | GT13: 105.30329 | GU13: 105.51204 | GV13: 105.66 | GW13: 106.12 | GX13: 106.17 | GY13: 105.55 | GZ13: 105.4 | HA13: 105.42 | HB13: 105.25558 | HC13: 105.10349 | HD13: 104.81586 | HE13: 105 | HF13: 105.20405 | HG13: 105.36518 | HH13: 105.4323 | HI13: 105.28586 | HJ13: 105.09361 | HK13: 104.80541 | HL13: 104.8011 | HM13: 105.08353 | HN13: 105.49532 | HO13: 105.44573 | HP13: 105.17914 | HQ13: 105.28345 | HR13: 105.7735 | HS13: 105.53091 | HT13: 105.30776 | HU13: 105.48843 | HV13: 105.48399 | HW13: 105.44625 | HX13: 105.54256 | HY13: 105.43264 | HZ13: 105.42003 | IA13: 105.96898 | IB13: 105.22328 | IC13: 105.21467 | ID13: 105.45352 | IE13: 105.29068 | IF13: 105.49856 | IG13: 106.55632 | IH13: 106.27929 | II13: 105.62055 | IJ13: 104.97347 | IK13: 104.63351 | IL13: 104.4697 | IM13: 104.27197 | IN13: 104.26286 | IO13: 104.23303 | IP13: 104.3541 | IQ13: 104.44211 | IR13: 104.6253 | IS13: 104.99064 | IT13: 105.07814 | IU13: 104.89361 | IV13: 105.44557 | IW13: 105.56735 | IX13: 105.58391 | IY13: 105.80374 | IZ13: 106.18414 | JA13: 106.25585 | JB13: 107.02231 | JC13: 107.27113 | JD13: 107.39174 | JE13: 108.02927 | JF13: 108.63144 | JG13: 109.33561 | JH13: 109.51081 | JI13: 109.54213 | JJ13: 109.93309 | JK13: 110.06144 | JL13: 110.05371 | JM13: 110.22732 | JN13: 110.36024 | JO13: 110.38041 | JP13: 110.45214 | JQ13: 110.66887 | JR13: 110.76759 | JS13: 111.18154 | JT13: 111.78086 | JU13: 112.34308 | JV13: 112.38561 | JW13: 112.18891 | JX13: 111.74 | JY13: 111.72 | JZ13: 111.86 | KA13: 111.96 | KB13: 112.28144 | KC13: 113.71089 | KD13: 113.57536 | KE13: 112.49404 | KF13: 113.54068 | KG13: 113.78626 | KH13: 113.98681 | KI13: 113.7152 | KJ13: 113.42409 | KK13: 112.30626
