Workbook

Sheet PPI_socios_expo
A1: COUNTRY | B1: INDICATOR | C1: TYPE_OF_TRANSFORMATION | D1: FREQUENCY | E1: SCALE | F1: 2001-M01 | G1: 2001-M02 | H1: 2001-M03 | I1: 2001-M04 | J1: 2001-M05 | K1: 2001-M06 | L1: 2001-M07 | M1: 2001-M08 | N1: 2001-M09 | O1: 2001-M10 | P1: 2001-M11 | Q1: 2001-M12 | R1: 2002-M01 | S1: 2002-M02 | T1: 2002-M03 | U1: 2002-M04 | V1: 2002-M05 | W1: 2002-M06 | X1: 2002-M07 | Y1: 2002-M08 | Z1: 2002-M09 | AA1: 2002-M10 | AB1: 2002-M11 | AC1: 2002-M12 | AD1: 2003-M01 | AE1: 2003-M02 | AF1: 2003-M03 | AG1: 2003-M04 | AH1: 2003-M05 | AI1: 2003-M06 | AJ1: 2003-M07 | AK1: 2003-M08 | AL1: 2003-M09 | AM1: 2003-M10 | AN1: 2003-M11 | AO1: 2003-M12 | AP1: 2004-M01 | AQ1: 2004-M02 | AR1: 2004-M03 | AS1: 2004-M04 | AT1: 2004-M05 | AU1: 2004-M06 | AV1: 2004-M07 | AW1: 2004-M08 | AX1: 2004-M09 | AY1: 2004-M10 | AZ1: 2004-M11 | BA1: 2004-M12 | BB1: 2005-M01 | BC1: 2005-M02 | BD1: 2005-M03 | BE1: 2005-M04 | BF1: 2005-M05 | BG1: 2005-M06 | BH1: 2005-M07 | BI1: 2005-M08 | BJ1: 2005-M09 | BK1: 2005-M10 | BL1: 2005-M11 | BM1: 2005-M12 | BN1: 2006-M01 | BO1: 2006-M02 | BP1: 2006-M03 | BQ1: 2006-M04 | BR1: 2006-M05 | BS1: 2006-M06 | BT1: 2006-M07 | BU1: 2006-M08 | BV1: 2006-M09 | BW1: 2006-M10 | BX1: 2006-M11 | BY1: 2006-M12 | BZ1: 2007-M01 | CA1: 2007-M02 | CB1: 2007-M03 | CC1: 2007-M04 | CD1: 2007-M05 | CE1: 2007-M06 | CF1: 2007-M07 | CG1: 2007-M08 | CH1: 2007-M09 | CI1: 2007-M10 | CJ1: 2007-M11 | CK1: 2007-M12 | CL1: 2008-M01 | CM1: 2008-M02 | CN1: 2008-M03 | CO1: 2008-M04 | CP1: 2008-M05 | CQ1: 2008-M06 | CR1: 2008-M07 | CS1: 2008-M08 | CT1: 2008-M09 | CU1: 2008-M10 | CV1: 2008-M11 | CW1: 2008-M12 | CX1: 2009-M01 | CY1: 2009-M02 | CZ1: 2009-M03 | DA1: 2009-M04 | DB1: 2009-M05 | DC1: 2009-M06 | DD1: 2009-M07 | DE1: 2009-M08 | DF1: 2009-M09 | DG1: 2009-M10 | DH1: 2009-M11 | DI1: 2009-M12 | DJ1: 2010-M01 | DK1: 2010-M02 | DL1: 2010-M03 | DM1: 2010-M04 | DN1: 2010-M05 | DO1: 2010-M06 | DP1: 2010-M07 | DQ1: 2010-M08 | DR1: 2010-M09 | DS1: 2010-M10 | DT1: 2010-M11 | DU1: 2010-M12 | DV1: 2011-M01 | DW1: 2011-M02 | DX1: 2011-M03 | DY1: 2011-M04 | DZ1: 2011-M05 | EA1: 2011-M06 | EB1: 2011-M07 | EC1: 2011-M08 | ED1: 2011-M09 | EE1: 2011-M10 | EF1: 2011-M11 | EG1: 2011-M12 | EH1: 2012-M01 | EI1: 2012-M02 | EJ1: 2012-M03 | EK1: 2012-M04 | EL1: 2012-M05 | EM1: 2012-M06 | EN1: 2012-M07 | EO1: 2012-M08 | EP1: 2012-M09 | EQ1: 2012-M10 | ER1: 2012-M11 | ES1: 2012-M12 | ET1: 2013-M01 | EU1: 2013-M02 | EV1: 2013-M03 | EW1: 2013-M04 | EX1: 2013-M05 | EY1: 2013-M06 | EZ1: 2013-M07 | FA1: 2013-M08 | FB1: 2013-M09 | FC1: 2013-M10 | FD1: 2013-M11 | FE1: 2013-M12 | FF1: 2014-M01 | FG1: 2014-M02 | FH1: 2014-M03 | FI1: 2014-M04 | FJ1: 2014-M05 | FK1: 2014-M06 | FL1: 2014-M07 | FM1: 2014-M08 | FN1: 2014-M09 | FO1: 2014-M10 | FP1: 2014-M11 | FQ1: 2014-M12 | FR1: 2015-M01 | FS1: 2015-M02 | FT1: 2015-M03 | FU1: 2015-M04 | FV1: 2015-M05 | FW1: 2015-M06 | FX1: 2015-M07 | FY1: 2015-M08 | FZ1: 2015-M09 | GA1: 2015-M10 | GB1: 2015-M11 | GC1: 2015-M12 | GD1: 2016-M01 | GE1: 2016-M02 | GF1: 2016-M03 | GG1: 2016-M04 | GH1: 2016-M05 | GI1: 2016-M06 | GJ1: 2016-M07 | GK1: 2016-M08 | GL1: 2016-M09 | GM1: 2016-M10 | GN1: 2016-M11 | GO1: 2016-M12 | GP1: 2017-M01 | GQ1: 2017-M02 | GR1: 2017-M03 | GS1: 2017-M04 | GT1: 2017-M05 | GU1: 2017-M06 | GV1: 2017-M07 | GW1: 2017-M08 | GX1: 2017-M09 | GY1: 2017-M10 | GZ1: 2017-M11 | HA1: 2017-M12 | HB1: 2018-M01 | HC1: 2018-M02 | HD1: 2018-M03 | HE1: 2018-M04 | HF1: 2018-M05 | HG1: 2018-M06 | HH1: 2018-M07 | HI1: 2018-M08 | HJ1: 2018-M09 | HK1: 2018-M10 | HL1: 2018-M11 | HM1: 2018-M12 | HN1: 2019-M01 | HO1: 2019-M02 | HP1: 2019-M03 | HQ1: 2019-M04 | HR1: 2019-M05 | HS1: 2019-M06 | HT1: 2019-M07 | HU1: 2019-M08 | HV1: 2019-M09 | HW1: 2019-M10 | HX1: 2019-M11 | HY1: 2019-M12 | HZ1: 2020-M01 | IA1: 2020-M02 | IB1: 2020-M03 | IC1: 2020-M04 | ID1: 2020-M05 | IE1: 2020-M06 | IF1: 2020-M07 | IG1: 2020-M08 | IH1: 2020-M09 | II1: 2020-M10 | IJ1: 2020-M11 | IK1: 2020-M12 | IL1: 2021-M01 | IM1: 2021-M02 | IN1: 2021-M03 | IO1: 2021-M04 | IP1: 2021-M05 | IQ1: 2021-M06 | IR1: 2021-M07 | IS1: 2021-M08 | IT1: 2021-M09 | IU1: 2021-M10 | IV1: 2021-M11 | IW1: 2021-M12 | IX1: 2022-M01 | IY1: 2022-M02 | IZ1: 2022-M03 | JA1: 2022-M04 | JB1: 2022-M05 | JC1: 2022-M06 | JD1: 2022-M07 | JE1: 2022-M08 | JF1: 2022-M09 | JG1: 2022-M10 | JH1: 2022-M11 | JI1: 2022-M12 | JJ1: 2023-M01 | JK1: 2023-M02 | JL1: 2023-M03 | JM1: 2023-M04 | JN1: 2023-M05 | JO1: 2023-M06 | JP1: 2023-M07 | JQ1: 2023-M08 | JR1: 2023-M09 | JS1: 2023-M10 | JT1: 2023-M11 | JU1: 2023-M12 | JV1: 2024-M01 | JW1: 2024-M02 | JX1: 2024-M03 | JY1: 2024-M04 | JZ1: 2024-M05 | KA1: 2024-M06 | KB1: 2024-M07 | KC1: 2024-M08 | KD1: 2024-M09 | KE1: 2024-M10 | KF1: 2024-M11 | KG1: 2024-M12
A2: Australia | B2: Producer price index (PPI) | C2: Year-over-year (YOY) percent change | D2: Monthly | R2: -3.1550069 | S2: -3.2921811 | T2: -2.6027397 | U2: -1.2295082 | V2: -1.3623978 | W2: -1.6371078 | X2: -0.27662517 | Y2: 0.69541029 | Z2: 1.7955801 | AA2: 4.3417367 | AB2: 4.1076487 | AC2: 5.7142857 | AD2: 1.4164306 | AE2: 2.8368794 | AF2: 2.2503516 | AG2: -0.69156293 | AH2: -2.3480663 | AI2: -1.9417476 | AJ2: -1.8030513 | AK2: -1.7955801 | AL2: -3.1207598 | AM2: -3.8926174 | AN2: -2.1768707 | AO2: -3.1081081 | AP2: 1.396648 | AQ2: 0.13793103 | AR2: 1.2379642 | AS2: 3.8997214 | AT2: 7.9207921 | AU2: 8.6280057 | AV2: 8.8983051 | AW2: 10.548523 | AX2: 11.204482 | AY2: 13.407821 | AZ2: 12.378303 | BA2: 12.552301 | BB2: 9.3663912 | BC2: 9.5041322 | BD2: 9.6467391 | BE2: 8.310992 | BF2: 5.3735256 | BG2: 5.46875 | BH2: 5.9662776 | BI2: 4.3256997 | BJ2: 5.163728 | BK2: 3.6945813 | BL2: 2.970297 | BM2: 3.7174721 | BN2: 7.6826196 | BO2: 7.672956 | BP2: 6.6914498 | BQ2: 7.549505 | BR2: 8.3333333 | BS2: 8.0246914 | BT2: 7.7111383 | BU2: 6.8292683 | BV2: 4.3113772 | BW2: 2.6128266 | BX2: 3.7259615 | BY2: 2.9868578 | BZ2: 1.0526316 | CA2: 1.0514019 | CB2: 1.2775842 | CC2: 0.69044879 | CD2: 1.1481056 | CE2: 0.8 | CF2: 0.56818182 | CG2: 1.2557078 | CH2: 2.4110218 | CI2: 4.2824074 | CJ2: 6.1413673 | CK2: 6.8445476 | CL2: 7.8703704 | CM2: 8.7861272 | CN2: 8.7155963 | CO2: 9.2571429 | CP2: 9.307605 | CQ2: 10.884354 | CR2: 12.20339 | CS2: 11.273957 | CT2: 10.538117 | CU2: 7.8801332 | CV2: 2.7292576 | CW2: -1.8458198 | CX2: -3.3261803 | CY2: -4.9946865 | CZ2: -6.9620253 | DA2: -7.0083682 | DB2: -6.2305296 | DC2: -6.6462168 | DD2: -8.7613293 | DE2: -7.0921986 | DF2: -7.505071 | DG2: -6.3786008 | DH2: -2.1253985 | DI2: 1.880531 | DJ2: 3.7735849 | DK2: 5.1454139 | DL2: 7.8231293 | DM2: 8.2114736 | DN2: 7.4197121 | DO2: 6.5717415 | DP2: 7.2847682 | DQ2: 6.5430752 | DR2: 7.7850877 | DS2: 8.1318681 | DT2: 7.2747014 | DU2: 8.9033659 | DV2: 9.5187166 | DW2: 10.851064 | DX2: 11.146162 | DY2: 11.330561 | DZ2: 9.7938144 | EA2: 9.2497431 | EB2: 9.3621399 | EC2: 7.9836233 | ED2: 7.9348932 | EE2: 7.5203252 | EF2: 6.9838057 | EG2: 5.5832502 | EH2: 4.6875 | EI2: 4.4145873 | EJ2: 3.8789026 | EK2: 2.8944911 | EL2: 3.0985915 | EM2: 2.3518344 | EN2: 2.3518344 | EO2: 3.9810427 | EP2: 4.0527804 | EQ2: 4.3478261 | ER2: 4.3519395 | ES2: 4.3437205 | ET2: 3.1716418 | EU2: 1.9301471 | EV2: 0.91074681 | EW2: -0.81669691 | EX2: -0.81967213 | EY2: 0 | EZ2: 0.36764706 | FA2: -1.0938924 | FB2: -1.9021739 | FC2: -2.5362319 | FD2: -2.5385313 | FE2: -2.5339367 | FF2: -3.074141 | FG2: -3.4265104 | FH2: -3.8808664 | FI2: -3.2936871 | FJ2: -2.9384757 | FK2: -2.5735294 | FL2: -3.3882784 | FM2: -3.1336406 | FN2: -3.0470914 | FO2: -2.5092937 | FP2: -3.627907 | FQ2: -6.7780873 | FR2: -8.2089552 | FS2: -6.9094304 | FT2: -4.7887324 | FU2: -3.7842952 | FV2: -2.9328288 | FW2: -3.6792453 | FX2: -4.1706161 | FY2: -5.4234063 | FZ2: -5.2380952 | GA2: -5.4337464 | GB2: -4.7297297 | GC2: -3.8844622 | GD2: -4.2682927 | GE2: -6.218656 | GF2: -6.6074951 | GG2: -6.8829892 | GH2: -5.3606238 | GI2: -3.4280118 | GJ2: -2.1760633 | GK2: -0.60362173 | GL2: 0.8040201 | GM2: 3.5282258 | GN2: 5.3698075 | GO2: 9.4300518 | GP2: 13.800425 | GQ2: 15.080214 | GR2: 12.671595 | GS2: 12.671595 | GT2: 8.9598352 | GU2: 6.1866126 | GV2: 5.7633974 | GW2: 6.7813765 | GX2: 6.2811565 | GY2: 5.5501461 | GZ2: 5.6730769 | HA2: 4.0719697 | HB2: 2.891791 | HC2: 1.9516729 | HD2: 2.5304592 | HE2: 2.8116214 | HF2: 4.9149338 | HG2: 7.0678128 | HH2: 7.8393881 | HI2: 7.4881517 | HJ2: 6.84803 | HK2: 7.4723247 | HL2: 6.3694268 | HM2: 4.4585987 | HN2: 3.1731641 | HO2: 4.1932543 | HP2: 4.9360146 | HQ2: 4.0109389 | HR2: 2.7027027 | HS2: 1.0704728 | HT2: -0.17730496 | HU2: -1.2345679 | HV2: -1.1413521 | HW2: -2.1459227 | HX2: -2.3952096 | HY2: -0.17421603 | HZ2: 0.26362039 | IA2: -1.1373578 | IB2: -4.1811847 | IC2: -5.8720421 | ID2: -8.8596491 | IE2: -6.266549 | IF2: -4.1740675 | IG2: -3.3035714 | IH2: -3.6412078 | II2: -2.7192982 | IJ2: -2.5416301 | IK2: -2.0942408 | IL2: 0.26292726 | IM2: 3.6283186
A3: Australia | B3: Producer price index (PPI) | C3: Period-over-preceding period percent change | D3: Monthly | G3: 0 | H3: 0.13717421 | I3: 0.2739726 | J3: 0.27322404 | K3: -0.13623978 | L3: -1.3642565 | M3: -0.55325035 | N3: 0.69541029 | O3: -1.3812155 | P3: -1.1204482 | Q3: -0.84985836 | R3: 0.85714286 | S3: -0.14164306 | T3: 0.85106383 | U3: 1.6877637 | V3: 0.13831259 | W3: -0.41436464 | X3: 0 | Y3: 0.41608877 | Z3: 1.7955801 | AA3: 1.0854817 | AB3: -1.3422819 | AC3: 0.68027211 | AD3: -3.2432432 | AE3: 1.2569832 | AF3: 0.27586207 | AG3: -1.2379642 | AH3: -1.5320334 | AI3: 0 | AJ3: 0.14144272 | AK3: 0.42372881 | AL3: 0.42194093 | AM3: 0.28011204 | AN3: 0.41899441 | AO3: -0.27816412 | AP3: 1.2552301 | AQ3: 0 | AR3: 1.3774105 | AS3: 1.3586957 | AT3: 2.2788204 | AU3: 0.65530799 | AV3: 0.390625 | AW3: 1.9455253 | AX3: 1.0178117 | AY3: 2.2670025 | AZ3: -0.49261084 | BA3: -0.12376238 | BB3: -1.6109046 | BC3: 0.12594458 | BD3: 1.509434 | BE3: 0.12391574 | BF3: -0.4950495 | BG3: 0.74626866 | BH3: 0.86419753 | BI3: 0.36719706 | BJ3: 1.8292683 | BK3: 0.83832335 | BL3: -1.1876485 | BM3: 0.60096154 | BN3: 2.1505376 | BO3: 0.11695906 | BP3: 0.58411215 | BQ3: 0.92915215 | BR3: 0.2301496 | BS3: 0.45924225 | BT3: 0.57142857 | BU3: -0.45454545 | BV3: -0.57077626 | BW3: -0.80367394 | BX3: -0.11574074 | BY3: -0.11587486 | BZ3: 0.23201856 | CA3: 0.11574074 | CB3: 0.80924855 | CC3: 0.3440367 | CD3: 0.68571429 | CE3: 0.11350738 | CF3: 0.34013605 | CG3: 0.2259887 | CH3: 0.56369786 | CI3: 1.0089686 | CJ3: 1.6648169 | CK3: 0.54585153 | CL3: 1.194354 | CM3: 0.96566524 | CN3: 0.74388948 | CO3: 0.84388186 | CP3: 0.73221757 | CQ3: 1.5576324 | CR3: 1.5337423 | CS3: -0.60422961 | CT3: -0.10131712 | CU3: -1.4198783 | CV3: -3.1893004 | CW3: -3.9319872 | CX3: -0.33185841 | CY3: -0.77691454 | CZ3: -1.3422819 | DA3: 0.79365079 | DB3: 1.5748031 | DC3: 1.1074197 | DD3: -0.76670318 | DE3: 1.214128 | DF3: -0.54525627 | DG3: -0.21929825 | DH3: 1.2087912 | DI3: 0 | DJ3: 1.5200869 | DK3: 0.53475936 | DL3: 1.1702128 | DM3: 1.1566772 | DN3: 0.83160083 | DO3: 0.30927835 | DP3: -0.10277492 | DQ3: 0.51440329 | DR3: 0.61412487 | DS3: 0.1017294 | DT3: 0.40650407 | DU3: 1.5182186 | DV3: 2.0937188 | DW3: 1.7578125 | DX3: 1.4395393 | DY3: 1.3245033 | DZ3: -0.56022409 | EA3: -0.18779343 | EB3: 0 | EC3: -0.75258702 | ED3: 0.56872038 | EE3: -0.28275212 | EF3: -0.094517958 | EG3: 0.18921476 | EH3: 1.2275732 | EI3: 1.4925373 | EJ3: 0.91911765 | EK3: 0.36429872 | EL3: -0.36297641 | EM3: -0.91074681 | EN3: 0 | EO3: 0.82720588 | EP3: 0.63810392 | EQ3: 0 | ER3: -0.09057971 | ES3: 0.18132366 | ET3: 0.090497738 | EU3: 0.27124774 | EV3: -0.090171326 | EW3: -1.3537906 | EX3: -0.36596523 | EY3: -0.091827365 | EZ3: 0.36764706 | FA3: -0.64102564 | FB3: -0.1843318 | FC3: -0.64635272 | FD3: -0.092936803 | FE3: 0.18604651 | FF3: -0.46425255 | FG3: -0.093283582 | FH3: -0.56022409 | FI3: -0.75117371 | FJ3: 0 | FK3: 0.28382214 | FL3: -0.47169811 | FM3: -0.37914692 | FN3: -0.095147479 | FO3: -0.095238095 | FP3: -1.2392755 | FQ3: -3.0888031 | FR3: -1.9920319 | FS3: 1.3211382 | FT3: 1.7051153 | FU3: 0.29585799 | FV3: 0.88495575 | FW3: -0.48732943 | FX3: -0.97943193 | FY3: -1.6815035 | FZ3: 0.10060362 | GA3: -0.30150754 | GB3: -0.50403226 | GC3: -2.2289767 | GD3: -2.3834197 | GE3: -0.74309979 | GF3: 1.2834225 | GG3: 0 | GH3: 2.5343189 | GI3: 1.5447992 | GJ3: 0.30425963 | GK3: -0.10111223 | GL3: 1.5182186 | GM3: 2.3928215 | GN3: 1.2658228 | GO3: 1.5384615 | GP3: 1.5151515 | GQ3: 0.37313433 | GR3: -0.83643123 | GS3: 0 | GT3: -0.84348641 | GU3: -1.0396975 | GV3: -0.095510984 | GW3: 0.86042065 | GX3: 1.042654 | GY3: 1.6885553 | GZ3: 1.3837638 | HA3: 0 | HB3: 0.36396724 | HC3: -0.54397099 | HD3: -0.27347311 | HE3: 0.27422303 | HF3: 1.1850501 | HG3: 0.99099099 | HH3: 0.62444246 | HI3: 0.53191489 | HJ3: 0.44091711 | HK3: 2.2827041 | HL3: 0.34334764 | HM3: -1.7964072 | HN3: -0.87108014 | HO3: 0.43936731 | HP3: 0.43744532 | HQ3: -0.6097561 | HR3: -0.087642419 | HS3: -0.61403509 | HT3: -0.61782877 | HU3: -0.53285968 | HV3: 0.53571429 | HW3: 1.2433393 | HX3: 0.087719298 | HY3: 0.43821209 | HZ3: -0.43630017 | IA3: -0.96406661 | IB3: -2.6548673 | IC3: -2.3636364 | ID3: -3.2588454 | IE3: 2.213667 | IF3: 1.6007533 | IG3: 0.37071362 | IH3: 0.18467221 | II3: 2.2119816 | IJ3: 0.27051398 | IK3: 0.89928058 | IL3: 1.9607843 | IM3: 2.3601399
A4: Australia | B4: Producer price index (PPI) | C4: Index | D4: Monthly | E4: Units | F4: 75.167555 | G4: 75.167555 | H4: 75.270665 | I4: 75.476886 | J4: 75.683107 | K4: 75.579997 | L4: 74.548892 | M4: 74.13645 | N4: 74.652002 | O4: 73.620897 | P4: 72.796013 | Q4: 72.17735 | R4: 72.796013 | S4: 72.692903 | T4: 73.311566 | U4: 74.548892 | V4: 74.652002 | W4: 74.342671 | X4: 74.342671 | Y4: 74.652002 | Z4: 75.992439 | AA4: 76.817323 | AB4: 75.786218 | AC4: 76.30177 | AD4: 73.827118 | AE4: 74.755113 | AF4: 74.961334 | AG4: 74.033339 | AH4: 72.899124 | AI4: 72.899124 | AJ4: 73.002234 | AK4: 73.311566 | AL4: 73.620897 | AM4: 73.827118 | AN4: 74.13645 | AO4: 73.930229 | AP4: 74.858223 | AQ4: 74.858223 | AR4: 75.889328 | AS4: 76.920433 | AT4: 78.673312 | AU4: 79.188864 | AV4: 79.498196 | AW4: 81.044853 | AX4: 81.869737 | AY4: 83.725726 | AZ4: 83.313284 | BA4: 83.210174 | BB4: 81.869737 | BC4: 81.972848 | BD4: 83.210174 | BE4: 83.313284 | BF4: 82.900842 | BG4: 83.519505 | BH4: 84.241279 | BI4: 84.55061 | BJ4: 86.097268 | BK4: 86.819041 | BL4: 85.787936 | BM4: 86.303489 | BN4: 88.159478 | BO4: 88.262588 | BP4: 88.778141 | BQ4: 89.603025 | BR4: 89.809246 | BS4: 90.221688 | BT4: 90.73724 | BU4: 90.324798 | BV4: 89.809246 | BW4: 89.087472 | BX4: 88.984362 | BY4: 88.881251 | BZ4: 89.087472 | CA4: 89.190583 | CB4: 89.912356 | CC4: 90.221688 | CD4: 90.840351 | CE4: 90.943461 | CF4: 91.252793 | CG4: 91.459014 | CH4: 91.974566 | CI4: 92.902561 | CJ4: 94.449218 | CK4: 94.964771 | CL4: 96.098986 | CM4: 97.026981 | CN4: 97.748754 | CO4: 98.573638 | CP4: 99.295412 | CQ4: 100.84207 | CR4: 102.38873 | CS4: 101.77006 | CT4: 101.66695 | CU4: 100.22341 | CV4: 97.026981 | CW4: 93.211892 | CX4: 92.902561 | CY4: 92.180787 | CZ4: 90.943461 | DA4: 91.665235 | DB4: 93.108782 | DC4: 94.139887 | DD4: 93.418113 | DE4: 94.552329 | DF4: 94.036776 | DG4: 93.830555 | DH4: 94.964771 | DI4: 94.964771 | DJ4: 96.408318 | DK4: 96.92387 | DL4: 98.058086 | DM4: 99.192301 | DN4: 100.01719 | DO4: 100.32652 | DP4: 100.22341 | DQ4: 100.73896 | DR4: 101.35762 | DS4: 101.46073 | DT4: 101.87317 | DU4: 103.41983 | DV4: 105.58515 | DW4: 107.44114 | DX4: 108.9878 | DY4: 110.43135 | DZ4: 109.81268 | EA4: 109.60646 | EB4: 109.60646 | EC4: 108.78158 | ED4: 109.40024 | EE4: 109.09091 | EF4: 108.9878 | EG4: 109.19402 | EH4: 110.53446 | EI4: 112.18422 | EJ4: 113.21533 | EK4: 113.62777 | EL4: 113.21533 | EM4: 112.18422 | EN4: 112.18422 | EO4: 113.11222 | EP4: 113.83399 | EQ4: 113.83399 | ER4: 113.73088 | ES4: 113.9371 | ET4: 114.04021 | EU4: 114.34954 | EV4: 114.24643 | EW4: 112.69978 | EX4: 112.28733 | EY4: 112.18422 | EZ4: 112.59667 | FA4: 111.87489 | FB4: 111.66867 | FC4: 110.9469 | FD4: 110.84379 | FE4: 111.05001 | FF4: 110.53446 | FG4: 110.43135 | FH4: 109.81268 | FI4: 108.9878 | FJ4: 108.9878 | FK4: 109.29713 | FL4: 108.78158 | FM4: 108.36914 | FN4: 108.26603 | FO4: 108.16291 | FP4: 106.82248 | FQ4: 103.52294 | FR4: 101.46073 | FS4: 102.80117 | FT4: 104.55405 | FU4: 104.86338 | FV4: 105.79137 | FW4: 105.27582 | FX4: 104.24472 | FY4: 102.49184 | FZ4: 102.59495 | GA4: 102.28562 | GB4: 101.77006 | GC4: 99.501633 | GD4: 97.130091 | GE4: 96.408318 | GF4: 97.645644 | GG4: 97.645644 | GH4: 100.1203 | GI4: 101.66695 | GJ4: 101.97628 | GK4: 101.87317 | GL4: 103.41983 | GM4: 105.89448 | GN4: 107.23492 | GO4: 108.88469 | GP4: 110.53446 | GQ4: 110.9469 | GR4: 110.0189 | GS4: 110.0189 | GT4: 109.09091 | GU4: 107.95669 | GV4: 107.85358 | GW4: 108.78158 | GX4: 109.91579 | GY4: 111.77178 | GZ4: 113.31844 | HA4: 113.31844 | HB4: 113.73088 | HC4: 113.11222 | HD4: 112.80289 | HE4: 113.11222 | HF4: 114.45266 | HG4: 115.58687 | HH4: 116.30864 | HI4: 116.92731 | HJ4: 117.44286 | HK4: 120.12373 | HL4: 120.53617 | HM4: 118.37085 | HN4: 117.33975 | HO4: 117.8553 | HP4: 118.37085 | HQ4: 117.64908 | HR4: 117.54597 | HS4: 116.8242 | HT4: 116.10242 | HU4: 115.48376 | HV4: 116.10242 | HW4: 117.54597 | HX4: 117.64908 | HY4: 118.16463 | HZ4: 117.64908 | IA4: 116.51487 | IB4: 113.42155 | IC4: 110.74068 | ID4: 107.13181 | IE4: 109.50335 | IF4: 111.25623 | IG4: 111.66867 | IH4: 111.87489 | II4: 114.34954 | IJ4: 114.65888 | IK4: 115.68998 | IL4: 117.95841 | IM4: 120.7424
A5: Belgium | B5: Producer price index (PPI) | C5: Period-over-preceding period percent change | D5: Monthly | F5: -1.3552759 | G5: 0 | H5: 0 | I5: 0.35211268 | J5: 0.35087719 | K5: -0.17482517 | L5: -1.4010508 | M5: -0.53285968 | N5: 0.71428571 | O5: -1.4184397 | P5: -1.0791367 | Q5: -0.90909091 | R5: 0.91743119 | S5: -0.18181818 | T5: 0.91074681 | U5: 1.6245487 | V5: 0.17761989 | W5: -0.53191489 | X5: 0 | Y5: 0.53475936 | Z5: 1.7730496 | AA5: 1.0452962 | AB5: -1.3793103 | AC5: 0.6993007 | AD5: -3.125 | AE5: 1.0752688 | AF5: 0.35460993 | AG5: -1.2367491 | AH5: -1.6100179 | AI5: 0.18181818 | AJ5: 0.1814882 | AK5: 0.36231884 | AL5: 0.36101083 | AM5: 0.17985612 | AN5: 0.53859964 | AO5: -0.35714286 | AP5: 1.2544803 | AQ5: 0 | AR5: 1.4159292 | AS5: 1.3961606 | AT5: 2.2375215 | AU5: 0.67340067 | AV5: 0.33444816 | AW5: 2 | AX5: 0.98039216 | AY5: 2.2653722 | AZ5: -0.47468354 | BA5: 0 | BB5: -1.7488076 | BC5: 0.1618123 | BD5: 1.453958 | BE5: 0.15923567 | BF5: -0.47694754 | BG5: 0.63897764 | BH5: 0.95238095 | BI5: 0.31446541 | BJ5: 1.8808777 | BK5: 0.92307692 | BL5: -1.2195122 | BM5: 0.61728395 | BN5: 2.1472393 | BO5: 0.15015015 | BP5: 0.44977511 | BQ5: 0.89552239 | BR5: 0.29585799 | BS5: 0.44247788 | BT5: 0.58737151 | BU5: -0.4379562 | BV5: -0.58651026 | BW5: -0.88495575 | BX5: 0 | BY5: -0.14880952 | BZ5: 0.29806259 | CA5: 0 | CB5: 0.89153046 | CC5: 0.29455081 | CD5: 0.73421439 | CE5: 0.14577259 | CF5: 0.29112082 | CG5: 0.29027576 | CH5: 0.5788712 | CI5: 0.86330935 | CJ5: 1.7118402 | CK5: 0.56100982 | CL5: 1.1157601 | CM5: 1.1034483 | CN5: 0.68212824 | CO5: 0.81300813 | CP5: 0.80645161 | CQ5: 1.4666667 | CR5: 1.5768725 | CS5: -0.64683053 | CT5: -0.13020833 | CU5: -1.303781 | CV5: -3.3025099 | CW5: -3.8251366 | CX5: -0.42613636 | CY5: -0.71326676 | CZ5: -1.4367816 | DA5: 0.87463557 | DB5: 1.5895954 | DC5: 1.1379801 | DD5: -0.84388186 | DE5: 1.2765957 | DF5: -0.56022409 | DG5: -0.28169014 | DH5: 1.2711864 | DI5: 0 | DJ5: 1.5341702 | DK5: 0.54945055 | DL5: 1.0928962 | DM5: 1.2162162 | DN5: 0.80106809 | DO5: 0.39735099 | DP5: -0.13192612 | DQ5: 0.52840159 | DR5: 0.52562418 | DS5: 0.13071895 | DT5: 0.39164491 | DU5: 1.5604681 | DV5: 2.0486556 | DW5: 1.7565872 | DX5: 1.4796547 | DY5: 1.3365735 | DZ5: -0.59952038 | EA5: -0.12062726 | EB5: -0.12077295 | EC5: -0.60459492 | ED5: 0.486618 | EE5: -0.24213075 | EF5: -0.12135922 | EG5: 0.24301337 | EH5: 1.2121212 | EI5: 1.4371257 | EJ5: 0.94451004 | EK5: 0.35087719 | EL5: -0.34965035 | EM5: -0.93567251 | EN5: 0 | EO5: 0.82644628 | EP5: 0.58548009 | EQ5: 0 | ER5: 0 | ES5: 0.11641444 | ET5: 0.11627907 | EU5: 0.23228804 | EV5: 0 | EW5: -1.3904983 | EX5: -0.35252644 | EY5: -0.11792453 | EZ5: 0.35419126 | FA5: -0.70588235 | FB5: -0.11848341 | FC5: -0.59311981 | FD5: -0.11933174 | FE5: 0.23894863 | FF5: -0.59594756 | FG5: 0 | FH5: -0.59952038 | FI5: -0.72376357 | FJ5: 0 | FK5: 0.36452005 | FL5: -0.60532688 | FM5: -0.36540804 | FN5: 0 | FO5: -0.12224939 | FP5: -1.3463892 | FQ5: -2.9776675 | FR5: -2.0460358 | FS5: 1.305483 | FT5: 1.6752577 | FU5: 0.25348542 | FV5: 1.011378 | FW5: -0.50062578 | FX5: -1.0062893 | FY5: -1.6518424 | FZ5: 0.12919897 | GA5: -0.38709677 | GB5: -0.51813472 | GC5: -2.2135417 | GD5: -2.3968043 | GE5: -0.68212824 | GF5: 1.3736264 | GG5: -0.13550136 | GH5: 2.578019 | GI5: 1.5873016 | GJ5: 0.26041667 | GK5: -0.12987013 | GL5: 1.5604681 | GM5: 2.3047375 | GN5: 1.3767209 | GO5: 1.4814815 | GP5: 1.5815085 | GQ5: 0.23952096 | GR5: -0.83632019 | GS5: 0 | GT5: -0.72289157 | GU5: -1.092233 | GV5: 0 | GW5: 0.73619632 | GX5: 1.0962241 | GY5: 1.686747 | GZ5: 1.4218009 | HA5: 0 | HB5: 0.35046729 | HC5: -0.58207218 | HD5: -0.23419204 | HE5: 0.23474178 | HF5: 1.1709602 | HG5: 0.92592593 | HH5: 0.68807339 | HI5: 0.56947608 | HJ5: 0.45300113 | HK5: 2.2547914 | HL5: 0.33076075 | HM5: -1.7582418 | HN5: -0.89485459 | HO5: 0.45146727 | HP5: 0.4494382 | HQ5: -0.67114094 | HR5: -0.11261261 | HS5: -0.56369786 | HT5: -0.68027211 | HU5: -0.456621 | HV5: 0.5733945 | HW5: 1.2542759 | HX5: 0.11261261 | HY5: 0.33745782 | HZ5: -0.44843049 | IA5: -0.9009009 | IB5: -2.7272727 | IC5: -2.3364486 | ID5: -3.2296651 | IE5: 2.2249691 | IF5: 1.5719468 | IG5: 0.35714286 | IH5: 0.23724792 | II5: 2.1301775 | IJ5: 0.34762457 | IK5: 0.92378753 | IL5: 3.0892449 | IM5: 2.108768 | IN5: 1.6304348 | IO5: 1.1764706 | IP5: 1.6913319 | IQ5: 2.3908524 | IR5: 1.7258883 | IS5: 0.499002 | IT5: 2.2840119 | IU5: 5.1456311 | IV5: 1.9390582 | IW5: 1.9021739 | IX5: 5.2444444 | IY5: 0.92905405 | IZ5: 5.6066946 | JA5: 1.9809826 | JB5: 0.077700078 | JC5: 2.0962733 | JD5: 0.53231939 | JE5: 1.1346445 | JF5: 0.89753179 | JG5: 3.1134173 | JH5: -3.3788641 | JI5: -0.5952381 | JJ5: -1.3473054 | JK5: -1.4415781 | JL5: -0.84680523 | JM5: -5.5124224 | JN5: -1.3968776 | JO5: -0.75 | JP5: -0.83963056 | JQ5: 1.1854361 | JR5: 0.58577406 | JS5: -0.083194676 | JT5: -0.99916736 | JU5: -0.58873003 | JV5: -2.1996616 | JW5: 1.384083 | JX5: 0.34129693 | JY5: 0.68027211 | JZ5: -1.0135135 | KA5: 0.42662116 | KB5: 0.33984707 | KC5: -0.33869602 | KD5: -0.33984707 | KE5: 0.59676044 | KF5: 1.2711864 | KG5: 0.75313808
A6: Belgium | B6: Producer price index (PPI) | C6: Year-over-year (YOY) percent change | D6: Monthly | F6: 7.4894515 | G6: 6.1458333 | H6: 4.7276465 | I6: 4.6661237 | J6: 3.7589541 | K6: 3.1603265 | L6: 1.002993 | M6: -1.0199126 | N6: -1.3816819 | O6: -3.811781 | P6: -5.9382511 | Q6: -5.3496925 | R6: -3.1690141 | S6: -3.3450704 | T6: -2.4647887 | U6: -1.2280702 | V6: -1.3986014 | W6: -1.7513135 | X6: -0.35523979 | Y6: 0.71428571 | Z6: 1.7730496 | AA6: 4.3165468 | AB6: 4 | AC6: 5.6880734 | AD6: 1.4545455 | AE6: 2.7322404 | AF6: 2.166065 | AG6: -0.71047957 | AH6: -2.4822695 | AI6: -1.7825312 | AJ6: -1.6042781 | AK6: -1.7730496 | AL6: -3.1358885 | AM6: -3.9655172 | AN6: -2.0979021 | AO6: -3.125 | AP6: 1.2544803 | AQ6: 0.17730496 | AR6: 1.2367491 | AS6: 3.9355993 | AT6: 8 | AU6: 8.5299456 | AV6: 8.6956522 | AW6: 10.469314 | AX6: 11.151079 | AY6: 13.464991 | AZ6: 12.321429 | BA6: 12.724014 | BB6: 9.380531 | BC6: 9.5575221 | BD6: 9.5986038 | BE6: 8.2616179 | BF6: 5.3872054 | BG6: 5.3511706 | BH6: 6 | BI6: 4.248366 | BJ6: 5.1779935 | BK6: 3.7974684 | BL6: 3.0206677 | BM6: 3.6565978 | BN6: 7.7669903 | BO6: 7.7544426 | BP6: 6.6878981 | BQ6: 7.4721781 | BR6: 8.3067093 | BS6: 8.0952381 | BT6: 7.7044025 | BU6: 6.8965517 | BV6: 4.3076923 | BW6: 2.4390244 | BX6: 3.7037037 | BY6: 2.9141104 | BZ6: 1.0510511 | CA6: 0.89955022 | CB6: 1.3432836 | CC6: 0.73964497 | CD6: 1.179941 | CE6: 0.88105727 | CF6: 0.58394161 | CG6: 1.3196481 | CH6: 2.5073746 | CI6: 4.3154762 | CJ6: 6.1011905 | CK6: 6.8554396 | CL6: 7.7265973 | CM6: 8.9153046 | CN6: 8.6892489 | CO6: 9.2511013 | CP6: 9.3294461 | CQ6: 10.77147 | CR6: 12.191582 | CS6: 11.143271 | CT6: 10.359712 | CU6: 7.9885877 | CV6: 2.6647966 | CW6: -1.8131102 | CX6: -3.3103448 | CY6: -5.047749 | CZ6: -7.0460705 | DA6: -6.9892473 | DB6: -6.2666667 | DC6: -6.5703022 | DD6: -8.7968952 | DE6: -7.03125 | DF6: -7.4315515 | DG6: -6.4729194 | DH6: -2.0491803 | DI6: 1.8465909 | DJ6: 3.8516405 | DK6: 5.1724138 | DL6: 7.8717201 | DM6: 8.2369942 | DN6: 7.3968706 | DO6: 6.6104079 | DP6: 7.3758865 | DQ6: 6.5826331 | DR6: 7.7464789 | DS6: 8.1920904 | DT6: 7.2524407 | DU6: 8.9260809 | DV6: 9.478022 | DW6: 10.79235 | DX6: 11.216216 | DY6: 11.348465 | DZ6: 9.8013245 | EA6: 9.2348285 | EB6: 9.2470277 | EC6: 8.0157687 | ED6: 7.9738562 | EE6: 7.5718016 | EF6: 7.0221066 | EG6: 5.6338028 | EH6: 4.7678795 | EI6: 4.4389642 | EJ6: 3.8882139 | EK6: 2.8776978 | EL6: 3.1363088 | EM6: 2.294686 | EN6: 2.4183797 | EO6: 3.892944 | EP6: 3.9951574 | EQ6: 4.2475728 | ER6: 4.3742406 | ES6: 4.2424242 | ET6: 3.1137725 | EU6: 1.8890201 | EV6: 0.93567251 | EW6: -0.81585082 | EX6: -0.81871345 | EY6: 0 | EZ6: 0.35419126 | FA6: -1.1709602 | FB6: -1.862631 | FC6: -2.4447031 | FD6: -2.5611176 | FE6: -2.4418605 | FF6: -3.1358885 | FG6: -3.3603708 | FH6: -3.9397451 | FI6: -3.2902468 | FJ6: -2.9481132 | FK6: -2.4793388 | FL6: -3.4117647 | FM6: -3.0805687 | FN6: -2.9655991 | FO6: -2.5059666 | FP6: -3.7037037 | FQ6: -6.7938021 | FR6: -8.1534772 | FS6: -6.9544365 | FT6: -4.8250905 | FU6: -3.8882139 | FV6: -2.9161604 | FW6: -3.7530266 | FX6: -4.1412911 | FY6: -5.3789731 | FZ6: -5.2567237 | GA6: -5.5079559 | GB6: -4.7146402 | GC6: -3.9641944 | GD6: -4.308094 | GE6: -6.185567 | GF6: -6.4638783 | GG6: -6.8268015 | GH6: -5.3817272 | GI6: -3.3962264 | GJ6: -2.1601017 | GK6: -0.64599483 | GL6: 0.77419355 | GM6: 3.4974093 | GN6: 5.46875 | GO6: 9.4540613 | GP6: 13.915416 | GQ6: 14.972527 | GR6: 12.466125 | GS6: 12.618725 | GT6: 8.994709 | GU6: 6.1197917 | GV6: 5.8441558 | GW6: 6.7620286 | GX6: 6.2740077 | GY6: 5.6320401 | GZ6: 5.6790123 | HA6: 4.136253 | HB6: 2.8742515 | HC6: 2.0310633 | HD6: 2.6506024 | HE6: 2.8915663 | HF6: 4.8543689 | HG6: 6.993865 | HH6: 7.7300613 | HI6: 7.5517661 | HJ6: 6.8674699 | HK6: 7.464455 | HL6: 6.3084112 | HM6: 4.4392523 | HN6: 3.1431898 | HO6: 4.2154567 | HP6: 4.9295775 | HQ6: 3.9812646 | HR6: 2.662037 | HS6: 1.146789 | HT6: -0.22779043 | HU6: -1.2457531 | HV6: -1.1273957 | HW6: -2.0948181 | HX6: -2.3076923 | HY6: -0.22371365 | HZ6: 0.22573363 | IA6: -1.1235955 | IB6: -4.2505593 | IC6: -5.8558559 | ID6: -8.7936866 | IE6: -6.2358277 | IF6: -4.109589 | IG6: -3.3256881 | IH6: -3.6488027 | II6: -2.8153153 | IJ6: -2.5871766 | IK6: -2.0179372 | IL6: 1.463964 | IM6: 4.5454545 | IN6: 9.228972 | IO6: 13.157895 | IP6: 18.912237 | IQ6: 19.1052 | IR6: 19.285714 | IS6: 19.45433 | IT6: 21.893491 | IU6: 25.492468 | IV6: 27.482679 | IW6: 28.718535 | IX6: 31.409545 | IY6: 29.891304 | IZ6: 34.973262 | JA6: 36.046512 | JB6: 33.887734 | JC6: 33.502538 | JD6: 31.936128 | JE6: 32.770606 | JF6: 30.970874 | JG6: 28.43952 | JH6: 21.73913 | JI6: 18.755556 | JJ6: 11.317568 | JK6: 8.7029289 | JL6: 2.0602219 | JM6: -5.4390054 | JN6: -6.8322981 | JO6: -9.4296578 | JP6: -10.665658 | JQ6: -10.620793 | JR6: -10.896961 | JS6: -13.659238 | JT6: -11.532738 | JU6: -11.526946 | JV6: -12.291351 | JW6: -9.7767513 | JX6: -8.6956522 | JY6: -2.7115859 | JZ6: -2.3333333 | KA6: -1.1754828 | KB6: 0 | KC6: -1.5062762 | KD6: -2.4126456 | KE6: -1.7485429 | KF6: 0.50462574 | KG6: 1.8612521
A7: Belgium | B7: Producer price index (PPI) | C7: Index | D7: Monthly | E7: Units | F7: 75.223485 | G7: 75.223485 | H7: 75.223485 | I7: 75.488357 | J7: 75.753228 | K7: 75.620792 | L7: 74.561307 | M7: 74.164 | N7: 74.693742 | O7: 73.634257 | P7: 72.839642 | Q7: 72.177464 | R7: 72.839642 | S7: 72.707207 | T7: 73.369385 | U7: 74.561307 | V7: 74.693742 | W7: 74.296435 | X7: 74.296435 | Y7: 74.693742 | Z7: 76.0181 | AA7: 76.812714 | AB7: 75.753228 | AC7: 76.282971 | AD7: 73.899128 | AE7: 74.693742 | AF7: 74.958614 | AG7: 74.031564 | AH7: 72.839642 | AI7: 72.972078 | AJ7: 73.104514 | AK7: 73.369385 | AL7: 73.634257 | AM7: 73.766692 | AN7: 74.164 | AO7: 73.899128 | AP7: 74.826178 | AQ7: 74.826178 | AR7: 75.885664 | AS7: 76.94515 | AT7: 78.666814 | AU7: 79.196557 | AV7: 79.461428 | AW7: 81.050657 | AX7: 81.845271 | AY7: 83.699371 | AZ7: 83.302064 | BA7: 83.302064 | BB7: 81.845271 | BC7: 81.977707 | BD7: 83.169628 | BE7: 83.302064 | BF7: 82.904757 | BG7: 83.4345 | BH7: 84.229114 | BI7: 84.493985 | BJ7: 86.083214 | BK7: 86.877828 | BL7: 85.818342 | BM7: 86.348085 | BN7: 88.202185 | BO7: 88.334621 | BP7: 88.731928 | BQ7: 89.526542 | BR7: 89.791414 | BS7: 90.188721 | BT7: 90.718464 | BU7: 90.321157 | BV7: 89.791414 | BW7: 88.996799 | BX7: 88.996799 | BY7: 88.864364 | BZ7: 89.129235 | CA7: 89.129235 | CB7: 89.923849 | CC7: 90.188721 | CD7: 90.850899 | CE7: 90.983335 | CF7: 91.248207 | CG7: 91.513078 | CH7: 92.042821 | CI7: 92.837435 | CJ7: 94.426664 | CK7: 94.956407 | CL7: 96.015892 | CM7: 97.075378 | CN7: 97.737557 | CO7: 98.532171 | CP7: 99.326785 | CQ7: 100.78358 | CR7: 102.37281 | CS7: 101.71063 | CT7: 101.57819 | CU7: 100.25384 | CV7: 96.942942 | CW7: 93.234742 | CX7: 92.837435 | CY7: 92.175257 | CZ7: 90.850899 | DA7: 91.645514 | DB7: 93.102307 | DC7: 94.161792 | DD7: 93.367178 | DE7: 94.559099 | DF7: 94.029357 | DG7: 93.764485 | DH7: 94.956407 | DI7: 94.956407 | DJ7: 96.413199 | DK7: 96.942942 | DL7: 98.002428 | DM7: 99.194349 | DN7: 99.988964 | DO7: 100.38627 | DP7: 100.25384 | DQ7: 100.78358 | DR7: 101.31332 | DS7: 101.44576 | DT7: 101.84306 | DU7: 103.43229 | DV7: 105.55126 | DW7: 107.40536 | DX7: 108.99459 | DY7: 110.45139 | DZ7: 109.78921 | EA7: 109.65677 | EB7: 109.52434 | EC7: 108.86216 | ED7: 109.3919 | EE7: 109.12703 | EF7: 108.99459 | EG7: 109.25946 | EH7: 110.58382 | EI7: 112.17305 | EJ7: 113.23254 | EK7: 113.62984 | EL7: 113.23254 | EM7: 112.17305 | EN7: 112.17305 | EO7: 113.1001 | EP7: 113.76228 | EQ7: 113.76228 | ER7: 113.76228 | ES7: 113.89471 | ET7: 114.02715 | EU7: 114.29202 | EV7: 114.29202 | EW7: 112.70279 | EX7: 112.30549 | EY7: 112.17305 | EZ7: 112.57036 | FA7: 111.77574 | FB7: 111.64331 | FC7: 110.98113 | FD7: 110.84869 | FE7: 111.11356 | FF7: 110.45139 | FG7: 110.45139 | FH7: 109.78921 | FI7: 108.99459 | FJ7: 108.99459 | FK7: 109.3919 | FL7: 108.72972 | FM7: 108.33241 | FN7: 108.33241 | FO7: 108.19998 | FP7: 106.74319 | FQ7: 103.56473 | FR7: 101.44576 | FS7: 102.77011 | FT7: 104.49178 | FU7: 104.75665 | FV7: 105.81614 | FW7: 105.28639 | FX7: 104.22691 | FY7: 102.50524 | FZ7: 102.63768 | GA7: 102.24037 | GB7: 101.71063 | GC7: 99.459221 | GD7: 97.075378 | GE7: 96.413199 | GF7: 97.737557 | GG7: 97.605121 | GH7: 100.1214 | GI7: 101.71063 | GJ7: 101.9755 | GK7: 101.84306 | GL7: 103.43229 | GM7: 105.81614 | GN7: 107.27293 | GO7: 108.86216 | GP7: 110.58382 | GQ7: 110.84869 | GR7: 109.92164 | GS7: 109.92164 | GT7: 109.12703 | GU7: 107.93511 | GV7: 107.93511 | GW7: 108.72972 | GX7: 109.92164 | GY7: 111.77574 | GZ7: 113.36497 | HA7: 113.36497 | HB7: 113.76228 | HC7: 113.1001 | HD7: 112.83523 | HE7: 113.1001 | HF7: 114.42446 | HG7: 115.48394 | HH7: 116.27856 | HI7: 116.94074 | HJ7: 117.47048 | HK7: 120.11919 | HL7: 120.5165 | HM7: 118.39753 | HN7: 117.33804 | HO7: 117.86779 | HP7: 118.39753 | HQ7: 117.60291 | HR7: 117.47048 | HS7: 116.8083 | HT7: 116.01369 | HU7: 115.48394 | HV7: 116.14612 | HW7: 117.60291 | HX7: 117.73535 | HY7: 118.13266 | HZ7: 117.60291 | IA7: 116.54343 | IB7: 113.36497 | IC7: 110.71626 | ID7: 107.14049 | IE7: 109.52434 | IF7: 111.246 | IG7: 111.64331 | IH7: 111.90818 | II7: 114.29202 | IJ7: 114.68933 | IK7: 115.74881 | IL7: 119.32458 | IM7: 121.84086 | IN7: 123.82739 | IO7: 125.28418 | IP7: 127.40316 | IQ7: 130.44918 | IR7: 132.70058 | IS7: 133.36276 | IT7: 136.40878 | IU7: 143.42788 | IV7: 146.20903 | IW7: 148.99018 | IX7: 156.80388 | IY7: 158.26068 | IZ7: 167.13387 | JA7: 170.44476 | JB7: 170.5772 | JC7: 174.15296 | JD7: 175.08001 | JE7: 177.06655 | JF7: 178.65578 | JG7: 184.21808 | JH7: 177.9936 | JI7: 176.93411 | JJ7: 174.55027 | JK7: 172.03399 | JL7: 170.5772 | JM7: 161.17426 | JN7: 158.92286 | JO7: 157.73093 | JP7: 156.40658 | JQ7: 158.26068 | JR7: 159.18773 | JS7: 159.05529 | JT7: 157.46606 | JU7: 156.53901 | JV7: 153.09568 | JW7: 155.21466 | JX7: 155.7444 | JY7: 156.80388 | JZ7: 155.21466 | KA7: 155.87683 | KB7: 156.40658 | KC7: 155.87683 | KD7: 155.34709 | KE7: 156.27414 | KF7: 158.26068 | KG7: 159.4526
A8: Brazil | B8: Wholesale price index (WPI) | C8: Period-over-preceding period percent change | D8: Monthly | F8: 0.40006582 | G8: 0.30884115 | H8: 1.0135359 | I8: 1.3885379 | J8: 0.18047572 | K8: 1.9642386 | L8: 1.9259115 | M8: 1.1252849 | N8: 0.47872492 | O8: 1.8807994 | P8: 0.72621977 | Q8: -0.093222752 | R8: -0.13146101 | S8: 0.13853794 | T8: -0.10847084 | U8: 0.75459891 | V8: 1.2677304 | W8: 2.5010147 | X8: 2.8174715 | Y8: 3.3217801 | Z8: 3.8382692 | AA8: 6.0227894 | AB8: 7.4505703 | AC8: 3.1378878 | AD8: 2.2067135 | AE8: 1.7097196 | AF8: 1.9294694 | AG8: 0.069195506 | AH8: -1.6784314 | AI8: -1.1620411 | AJ8: -0.59262822 | AK8: 0.70220437 | AL8: 1.2883248 | AM8: 0.49707925 | AN8: 0.45615011 | AO8: 0.73824013 | AP8: 0.75455303 | AQ8: 1.4220263 | AR8: 1.0882206 | AS8: 1.5651238 | AT8: 1.7054278 | AU8: 1.5714487 | AV8: 1.3478861 | AW8: 1.5850165 | AX8: 0.65188451 | AY8: 0.61239234 | AZ8: 0.9987985 | BA8: 0.4792055 | BB8: 0.075215199 | BC8: 0.38943325 | BD8: 1.1393665 | BE8: 0.33338085 | BF8: -0.98479632 | BG8: -0.78099128 | BH8: -0.6881206 | BI8: -1.0429737 | BJ8: -0.27764256 | BK8: 0.78756694 | BL8: 0.24442029 | BM8: -0.13848548 | BN8: 0.8061862 | BO8: -0.12222108 | BP8: -0.8149661 | BQ8: -0.15464266 | BR8: 0.4575936 | BS8: 1.0573318 | BT8: 0.16645825 | BU8: 0.53405614 | BV8: 0.27706182 | BW8: 1.1640771 | BX8: 0.75107179 | BY8: 0.10638039 | BZ8: 0.32149918 | CA8: 0.1946472 | CB8: 0.1075993 | CC8: 0.018226654 | CD8: -0.035106714 | CE8: 0.093829504 | CF8: 0.42183696 | CG8: 1.9555025 | CH8: 1.6375689 | CI8: 1.0192158 | CJ8: 1.4535254 | CK8: 1.9005573 | CL8: 1.0814088 | CM8: 0.51517109 | CN8: 0.8028758 | CO8: 1.2969888 | CP8: 2.2217841 | CQ8: 2.2917775 | CR8: 1.2828755 | CS8: -0.79761344 | CT8: 0.43977263 | CU8: 1.3601399 | CV8: -0.17101192 | CW8: -0.87632455 | CX8: -0.32768341 | CY8: -0.30894499 | CZ8: -1.4569028 | DA8: -0.10177184 | DB8: -0.097286532 | DC8: -0.63986844 | DD8: -1.1633874 | DE8: 0.073436035 | DF8: 0.28651755 | DG8: -0.078998329 | DH8: -0.038714131 | DI8: -0.28533566 | DJ8: 0.95836404 | DK8: 1.3763902 | DL8: 0.52442677 | DM8: 0.68156389 | DN8: 2.058407 | DO8: 0.43245971 | DP8: 0.34178956 | DQ8: 1.704664 | DR8: 1.4731128 | DS8: 1.3227699 | DT8: 1.9817742 | DU8: 0.20923647 | DV8: 0.96097133 | DW8: 1.2290669 | DX8: 0.60264827 | DY8: 0.24445235 | DZ8: -0.62748617 | EA8: -0.19322683 | EB8: -0.13389222 | EC8: 0.76779218 | ED8: 0.94293825 | EE8: 0.4761688 | EF8: 0.34272951 | EG8: -0.55238316 | EH8: 0.013225033 | EI8: -0.031577992 | EJ8: 0.54943319 | EK8: 1.2467971 | EL8: 0.90525642 | EM8: 0.89425222 | EN8: 2.1303831 | EO8: 1.7655178 | EP8: 1.1051526 | EQ8: -0.67977145 | ER8: 0.16444427 | ES8: 0.7386932 | ET8: 0.0018087729 | EU8: 0.085372537 | EV8: 0.12325086 | EW8: -0.39402554 | EX8: 0.0088793531 | EY8: 0.85125505 | EZ8: 0.1974527 | FA8: 0.58473555 | FB8: 1.900351 | FC8: 0.71377463 | FD8: 0.12020379 | FE8: 0.78316253 | FF8: 0.11516711 | FG8: 0.9990302 | FH8: 1.9113887 | FI8: 0.26561934 | FJ8: -1.2112811 | FK8: -1.2052196 | FL8: -1.0135291 | FM8: 0.039838714 | FN8: -0.18256449 | FO8: 0.73021191 | FP8: 0.70468659 | FQ8: 1.0317563 | FR8: 0.22514021 | FS8: 0.40757032 | FT8: 1.2376752 | FU8: 1.1137044 | FV8: 0.18665384 | FW8: 0.43270039 | FX8: 0.61081187 | FY8: 0.43872406 | FZ8: 2.0204165 | GA8: 2.3760749 | GB8: 1.4091623 | GC8: 0.33387612 | GD8: 1.6253713 | GE8: 0.8399105 | GF8: 0.37361501 | GG8: 0.28862471 | GH8: 1.4890151 | GI8: 2.099963 | GJ8: -0.80729912 | GK8: 0.49945885 | GL8: -0.029835648 | GM8: 0.041213906 | GN8: -0.0066767433 | GO8: 1.0963376 | GP8: 0.33923267 | GQ8: -0.12380606 | GR8: -0.7827399 | GS8: -1.9595678 | GT8: -1.1020789 | GU8: -1.5340124 | GV8: -0.66718972 | GW8: 0.25960749 | GX8: 0.97375716 | GY8: -0.030030649 | GZ8: 1.0647885 | HA8: 1.0669748 | HB8: 0.57968215 | HC8: 0.15307943 | HD8: 0.77081052 | HE8: 1.2646794 | HF8: 2.3545796 | HG8: 1.6719076 | HH8: 0.5201967 | HI8: 0.99049856 | HJ8: 2.5436925 | HK8: 0.17231201 | HL8: -1.7018043 | HM8: -0.81935422 | HN8: -0.18850241 | HO8: 1.7872487 | HP8: 0.049712814 | HQ8: 2.4083737 | HR8: 0.52480102 | HS8: 0.83192821 | HT8: -0.21659979 | HU8: -0.90353482 | HV8: 0.69501091 | HW8: 0.84314606 | HX8: 1.1145034 | HY8: 2.3398181 | HZ8: -0.12732692 | IA8: -0.031236682 | IB8: 2.3333099 | IC8: 0.10533043 | ID8: 1.7706449 | IE8: 2.2222816 | IF8: 3.1387897 | IG8: 5.4351311 | IH8: 4.3767145 | II8: 4.86 | IJ8: 3.3070856 | IK8: 0.67728749 | IL8: 3.9221842 | IM8: 3.4039302 | IN8: 2.591863 | IO8: 2.9042699 | IP8: 4.2029061 | IQ8: -0.26038633 | IR8: 1.6495516 | IS8: -0.41921511 | IT8: -1.1704057 | IU8: 1.8999164 | IV8: -1.1568393 | IW8: 1.5421397
A9: Brazil | B9: Wholesale price index (WPI) | C9: Year-over-year (YOY) percent change | D9: Monthly | F9: 11.368679 | G9: 11.5237 | H9: 12.715008 | I9: 14.300937 | J9: 13.71729 | K9: 14.291292 | L9: 13.33337 | M9: 11.743354 | N9: 11.070574 | O9: 12.53403 | P9: 12.926278 | Q9: 11.871876 | R9: 11.279616 | S9: 11.090687 | T9: 9.8567486 | U9: 9.1698616 | V9: 10.354678 | W9: 10.935624 | X9: 11.905993 | Y9: 14.336651 | Z9: 18.15954 | AA9: 22.963347 | AB9: 31.172219 | AC9: 35.414493 | AD9: 38.584888 | AE9: 40.759296 | AF9: 43.631001 | AG9: 42.653922 | AH9: 38.50372 | AI9: 33.554044 | AJ9: 29.124519 | AK9: 25.850751 | AL9: 22.760249 | AM9: 16.362214 | AN9: 8.7876963 | AO9: 6.2565979 | AP9: 4.7468964 | AQ9: 4.4506122 | AR9: 3.5885558 | AS9: 5.1370948 | AT9: 8.7555188 | AU9: 11.763291 | AV9: 13.945003 | AW9: 14.943909 | AX9: 14.221665 | AY9: 14.352726 | AZ9: 14.970441 | BA9: 14.674811 | BB9: 13.901615 | BC9: 12.741966 | BD9: 12.799008 | BE9: 11.431025 | BF9: 8.4835475 | BG9: 5.9710203 | BH9: 3.8421382 | BI9: 1.1557566 | BJ9: 0.22157623 | BK9: 0.39607039 | BL9: -0.35380593 | BM9: -0.96637602 | BN9: -0.24301303 | BO9: -0.75144396 | BP9: -2.6692401 | BQ9: -3.1426588 | BR9: -1.7317033 | BS9: 0.08900509 | BT9: 0.95027111 | BU9: 2.5590663 | BV9: 3.1295498 | BW9: 3.5148088 | BX9: 4.0379894 | BY9: 4.2930962 | BZ9: 3.7916438 | CA9: 4.120929 | CB9: 5.0894054 | CC9: 5.2713541 | CD9: 4.7550444 | CE9: 3.7562873 | CF9: 4.0208185 | CG9: 5.491564 | CH9: 6.9228187 | CI9: 6.7697112 | CJ9: 7.5141278 | CK9: 9.4410715 | CL9: 10.27006 | CM9: 10.622815 | CN9: 11.391123 | CO9: 12.81529 | CP9: 15.362303 | CQ9: 17.895529 | CR9: 18.906391 | CS9: 15.695548 | CT9: 14.332079 | CU9: 14.717932 | CV9: 12.880997 | CW9: 9.804888 | CX9: 8.274189 | CY9: 7.3864574 | CZ9: 4.9790894 | DA9: 3.5294844 | DB9: 1.1807465 | DC9: -1.7190578 | DD9: -4.0928156 | DE9: -3.2506998 | DF9: -3.3983238 | DG9: -4.7699001 | DH9: -4.643697 | DI9: -4.0751697 | DJ9: -2.8374751 | DK9: -1.1948862 | DL9: 0.79171155 | DM9: 1.5820534 | DN9: 3.7739836 | DO9: 4.8939475 | DP9: 6.4913713 | DQ9: 8.2272136 | DR9: 9.5077635 | DS9: 11.044022 | DT9: 13.288523 | DU9: 13.850419 | DV9: 13.85336 | DW9: 13.687904 | DX9: 13.776369 | DY9: 13.282406 | DZ9: 10.301128 | EA9: 9.6139607 | EB9: 9.0943231 | EC9: 8.0893801 | ED9: 7.524637 | EE9: 6.6262163 | EF9: 4.9125264 | EG9: 4.1151604 | EH9: 3.1378049 | EI9: 1.8533898 | EJ9: 1.7995131 | EK9: 2.8174069 | EL9: 4.4032843 | EM9: 5.5408462 | EN9: 7.9337855 | EO9: 9.0024632 | EP9: 9.1776292 | EQ9: 7.9215819 | ER9: 7.7298308 | ES9: 9.1284309 | ET9: 9.1159741 | EU9: 9.2436261 | EV9: 8.7805932 | EW9: 7.0176765 | EX9: 6.0670007 | EY9: 6.0217991 | EZ9: 4.0152193 | FA9: 2.8083339 | FB9: 3.6169279 | FC9: 5.0707603 | FD9: 5.0243528 | FE9: 5.070714 | FF9: 5.1898182 | FG9: 6.1500733 | FH9: 8.0458463 | FI9: 8.7613846 | FJ9: 7.434439 | FK9: 5.2437256 | FL9: 3.9717548 | FM9: 3.4085095 | FN9: 1.2947662 | FO9: 1.3112983 | FP9: 1.9027345 | FQ9: 2.1540898 | FR9: 2.2663026 | FS9: 1.6674214 | FT9: 0.99532076 | FU9: 1.8495779 | FV9: 3.2908263 | FW9: 5.0032862 | FX9: 6.7263615 | FY9: 7.1519078 | FZ9: 9.5167614 | GA9: 11.306191 | GB9: 12.084829 | GC9: 11.310599 | GD9: 12.865704 | GE9: 13.351687 | GF9: 12.384234 | GG9: 11.467188 | GH9: 12.916188 | GI9: 14.790687 | GJ9: 13.17271 | GK9: 13.241145 | GL9: 10.965396 | GM9: 8.4346406 | GN9: 6.9207143 | GO9: 7.7332308 | GP9: 6.369793 | GQ9: 5.353228 | GR9: 4.1395054 | GS9: 1.8049869 | GT9: -0.79417413 | GU9: -4.3251404 | GV9: -4.19 | GW9: -4.4186595 | GX9: -3.4591258 | GY9: -3.5278775 | GZ9: -2.4941433 | HA9: -2.5224633 | HB9: -2.2888715 | HC9: -2.0179882 | HD9: -0.48377933 | HE9: 2.789002 | HF9: 6.3816607 | HG9: 9.8453044 | HH9: 11.158353 | HI9: 11.968696 | HJ9: 13.70958 | HK9: 13.939732 | HL9: 10.820695 | HM9: 8.752321 | HN9: 7.9217174 | HO9: 9.6826453 | HP9: 8.8977761 | HQ9: 10.127679 | HR9: 8.1589422 | HS9: 7.265369 | HT9: 6.4791316 | HU9: 4.4821612 | HV9: 2.5985324 | HW9: 3.2856144 | HX9: 6.2448149 | HY9: 9.6290002 | HZ9: 9.6961929 | IA9: 7.7364099 | IB9: 10.195453 | IC9: 7.7172875 | ID9: 9.0522707 | IE9: 10.555973 | IF9: 14.273609 | IG9: 21.583075 | IH9: 26.028507 | II9: 31.048562 | IJ9: 33.890238 | IK9: 31.715165 | IL9: 37.055785 | IM9: 41.765351 | IN9: 42.123532 | IO9: 46.097299 | IP9: 49.588942 | IQ9: 45.955882 | IR9: 43.848401 | IS9: 35.861136 | IT9: 28.64077 | IU9: 25.009381 | IV9: 19.607695 | IW9: 20.635165
A10: Brazil | B10: Wholesale price index (WPI) | C10: Index | D10: Monthly | E10: Units | F10: 42.64832 | G10: 42.780036 | H10: 43.213627 | I10: 43.813664 | J10: 43.892737 | K10: 44.754895 | L10: 45.616835 | M10: 46.130154 | N10: 46.350991 | O10: 47.22276 | P10: 47.565701 | Q10: 47.521359 | R10: 47.458887 | S10: 47.524636 | T10: 47.473085 | U10: 47.831317 | V10: 48.437689 | W10: 49.649123 | X10: 51.047972 | Y10: 52.743674 | Z10: 54.768118 | AA10: 58.066686 | AB10: 62.392986 | AC10: 64.350808 | AD10: 65.770845 | AE10: 66.895343 | AF10: 68.186068 | AG10: 68.233249 | AH10: 67.088001 | AI10: 66.308411 | AJ10: 65.915449 | AK10: 66.37831 | AL10: 67.233478 | AM10: 67.567682 | AN10: 67.875892 | AO10: 68.376979 | AP10: 68.892919 | AQ10: 69.872595 | AR10: 70.632963 | AS10: 71.738456 | AT10: 72.961904 | AU10: 74.108463 | AV10: 75.10736 | AW10: 76.297824 | AX10: 76.795198 | AY10: 77.265486 | AZ10: 78.037212 | BA10: 78.411171 | BB10: 78.470148 | BC10: 78.775737 | BD10: 79.673281 | BE10: 79.938897 | BF10: 79.151661 | BG10: 78.533494 | BH10: 77.993089 | BI10: 77.179641 | BJ10: 76.965358 | BK10: 77.571512 | BL10: 77.761112 | BM10: 77.653424 | BN10: 78.279455 | BO10: 78.183781 | BP10: 77.54661 | BQ10: 77.42669 | BR10: 77.78099 | BS10: 78.603393 | BT10: 78.734235 | BU10: 79.15472 | BV10: 79.374027 | BW10: 80.298002 | BX10: 80.901098 | BY10: 80.98716 | BZ10: 81.247534 | CA10: 81.40568 | CB10: 81.493272 | CC10: 81.508125 | CD10: 81.47951 | CE10: 81.555962 | CF10: 81.899995 | CG10: 83.501552 | CH10: 84.868947 | CI10: 85.733945 | CJ10: 86.980109 | CK10: 88.633216 | CL10: 89.591704 | CM10: 90.053254 | CN10: 90.77627 | CO10: 91.953628 | CP10: 93.996639 | CQ10: 96.150833 | CR10: 97.384328 | CS10: 96.607578 | CT10: 97.032432 | CU10: 98.352208 | CV10: 98.184014 | CW10: 97.323604 | CX10: 97.004691 | CY10: 96.704999 | CZ10: 95.296102 | DA10: 95.199117 | DB10: 95.106501 | DC10: 94.497945 | DD10: 93.398567 | DE10: 93.467156 | DF10: 93.734955 | DG10: 93.660906 | DH10: 93.624646 | DI10: 93.357502 | DJ10: 94.252207 | DK10: 95.549485 | DL10: 96.050572 | DM10: 96.705218 | DN10: 98.695805 | DO10: 99.122624 | DP10: 99.461415 | DQ10: 101.1569 | DR10: 102.64705 | DS10: 104.00484 | DT10: 106.06598 | DU10: 106.28791 | DV10: 107.3093 | DW10: 108.62821 | DX10: 109.28285 | DY10: 109.55 | DZ10: 108.86259 | EA10: 108.65223 | EB10: 108.50676 | EC10: 109.33986 | ED10: 110.37087 | EE10: 110.89642 | EF10: 111.2765 | EG10: 110.66183 | EH10: 110.67646 | EI10: 110.64151 | EJ10: 111.24941 | EK10: 112.63647 | EL10: 113.65612 | EM10: 114.67249 | EN10: 117.11545 | EO10: 119.18315 | EP10: 120.5003 | EQ10: 119.68117 | ER10: 119.87798 | ES10: 120.76351 | ET10: 120.7657 | EU10: 120.8688 | EV10: 121.01777 | EW10: 120.54093 | EX10: 120.55163 | EY10: 121.57783 | EZ10: 121.81789 | FA10: 122.53021 | FB10: 124.85871 | FC10: 125.74992 | FD10: 125.90108 | FE10: 126.88709 | FF10: 127.03322 | FG10: 128.30232 | FH10: 130.75467 | FI10: 131.10198 | FJ10: 129.51397 | FK10: 127.95304 | FL10: 126.6562 | FM10: 126.70666 | FN10: 126.47534 | FO10: 127.39888 | FP10: 128.29664 | FQ10: 129.62035 | FR10: 129.91218 | FS10: 130.44166 | FT10: 132.0561 | FU10: 133.52682 | FV10: 133.77605 | FW10: 134.3549 | FX10: 135.17556 | FY10: 135.7686 | FZ10: 138.51169 | GA10: 141.80284 | GB10: 143.80107 | GC10: 144.28119 | GD10: 146.62629 | GE10: 147.85782 | GF10: 148.41024 | GG10: 148.83859 | GH10: 151.05482 | GI10: 154.22691 | GJ10: 152.98184 | GK10: 153.74592 | GL10: 153.70005 | GM10: 153.7634 | GN10: 153.75313 | GO10: 155.43878 | GP10: 155.96608 | GQ10: 155.77299 | GR10: 154.55369 | GS10: 151.5251 | GT10: 149.85518 | GU10: 147.55638 | GV10: 146.5719 | GW10: 146.95241 | GX10: 148.38337 | GY10: 148.33881 | GZ10: 149.91831 | HA10: 151.5179 | HB10: 152.39622 | HC10: 152.62951 | HD10: 153.80599 | HE10: 155.75114 | HF10: 159.41843 | HG10: 162.08376 | HH10: 162.92691 | HI10: 164.5407 | HJ10: 168.72611 | HK10: 169.01684 | HL10: 166.14051 | HM10: 164.77923 | HN10: 164.46862 | HO10: 167.40808 | HP10: 167.4913 | HQ10: 171.52512 | HR10: 172.42528 | HS10: 173.85974 | HT10: 173.48316 | HU10: 171.91568 | HV10: 173.11051 | HW10: 174.57009 | HX10: 176.51568 | HY10: 180.64582 | HZ10: 180.41581 | IA10: 180.35945 | IB10: 184.5678 | IC10: 184.76221 | ID10: 188.03369 | IE10: 192.21233 | IF10: 198.24547 | IG10: 209.02037 | IH10: 218.16859 | II10: 228.77159 | IJ10: 236.33726 | IK10: 237.93794 | IL10: 247.27031 | IM10: 255.68721 | IN10: 262.31428 | IO10: 269.93259 | IP10: 281.2776 | IQ10: 280.5452 | IR10: 285.17293 | IS10: 283.97745 | IT10: 280.65376 | IU10: 285.98594 | IV10: 282.67755 | IW10: 287.03683
A11: Brazil | B11: Producer price index (PPI) | C11: Period-over-preceding period percent change | D11: Monthly | F11: 0.40006582 | G11: 0.30884115 | H11: 1.0135359 | I11: 1.3885379 | J11: 0.18047572 | K11: 1.9642386 | L11: 1.9259115 | M11: 1.1252849 | N11: 0.47872492 | O11: 1.8807994 | P11: 0.72621977 | Q11: -0.093222752 | R11: -0.13146101 | S11: 0.13853794 | T11: -0.10847084 | U11: 0.75459891 | V11: 1.2677304 | W11: 2.5010147 | X11: 2.8174715 | Y11: 3.3217801 | Z11: 3.8382692 | AA11: 6.0227894 | AB11: 7.4505703 | AC11: 3.1378878 | AD11: 2.2067135 | AE11: 1.7097196 | AF11: 1.9294694 | AG11: 0.069195506 | AH11: -1.6784314 | AI11: -1.1620411 | AJ11: -0.59262822 | AK11: 0.70220437 | AL11: 1.2883248 | AM11: 0.49707925 | AN11: 0.45615011 | AO11: 0.73824013 | AP11: 0.75455303 | AQ11: 1.4220263 | AR11: 1.0882206 | AS11: 1.5651238 | AT11: 1.7054278 | AU11: 1.5714487 | AV11: 1.3478861 | AW11: 1.5850165 | AX11: 0.65188451 | AY11: 0.61239234 | AZ11: 0.9987985 | BA11: 0.4792055 | BB11: 0.075215199 | BC11: 0.38943325 | BD11: 1.1393665 | BE11: 0.33338085 | BF11: -0.98479632 | BG11: -0.78099128 | BH11: -0.6881206 | BI11: -1.0429737 | BJ11: -0.27764256 | BK11: 0.78756694 | BL11: 0.24442029 | BM11: -0.13848548 | BN11: 0.8061862 | BO11: -0.12222108 | BP11: -0.8149661 | BQ11: -0.15464266 | BR11: 0.4575936 | BS11: 1.0573318 | BT11: 0.16645825 | BU11: 0.53405614 | BV11: 0.27706182 | BW11: 1.1640771 | BX11: 0.75107179 | BY11: 0.10638039 | BZ11: 0.32149918 | CA11: 0.1946472 | CB11: 0.1075993 | CC11: 0.018226654 | CD11: -0.035106714 | CE11: 0.093829504 | CF11: 0.42183696 | CG11: 1.9555025 | CH11: 1.6375689 | CI11: 1.0192158 | CJ11: 1.4535254 | CK11: 1.9005573 | CL11: 1.0814088 | CM11: 0.51517109 | CN11: 0.8028758 | CO11: 1.2969888 | CP11: 2.2217841 | CQ11: 2.2917775 | CR11: 1.2828755 | CS11: -0.79761344 | CT11: 0.43977263 | CU11: 1.3601399 | CV11: -0.17101192 | CW11: -0.87632455 | CX11: -0.32768341 | CY11: -0.30894499 | CZ11: -1.4569028 | DA11: -0.10177184 | DB11: -0.097286532 | DC11: -0.63986844 | DD11: -1.1633874 | DE11: 0.073436035 | DF11: 0.28651755 | DG11: -0.078998329 | DH11: -0.038714131 | DI11: -0.28533566 | DJ11: 0.95836404 | DK11: 1.3763902 | DL11: 0.52442677 | DM11: 0.68156389 | DN11: 2.058407 | DO11: 0.43245971 | DP11: 0.34178956 | DQ11: 1.704664 | DR11: 1.4731128 | DS11: 1.3227699 | DT11: 1.9817742 | DU11: 0.20923647 | DV11: 0.96097133 | DW11: 1.2290669 | DX11: 0.60264827 | DY11: 0.24445235 | DZ11: -0.62748617 | EA11: -0.19322683 | EB11: -0.13389222 | EC11: 0.76779218 | ED11: 0.94293825 | EE11: 0.4761688 | EF11: 0.34272951 | EG11: -0.55238316 | EH11: 0.013225033 | EI11: -0.031577992 | EJ11: 0.54943319 | EK11: 1.2467971 | EL11: 0.90525642 | EM11: 0.89425222 | EN11: 2.1303831 | EO11: 1.7655178 | EP11: 1.1051526 | EQ11: -0.67977145 | ER11: 0.16444427 | ES11: 0.7386932 | ET11: 0.0018087729 | EU11: 0.085372537 | EV11: 0.12325086 | EW11: -0.39402554 | EX11: 0.0088793531 | EY11: 0.85125505 | EZ11: 0.1974527 | FA11: 0.58473555 | FB11: 1.900351 | FC11: 0.71377463 | FD11: 0.12020379 | FE11: 0.78316253 | FF11: 1.5071789 | FG11: 0.32273767 | FH11: -0.1315823 | FI11: -0.97183042 | FJ11: -0.14027636 | FK11: -0.30177012 | FL11: -0.56821424 | FM11: 0.44071594 | FN11: 0.98458088 | FO11: 0.39638252 | FP11: 0.93497576 | FQ11: 0.18552636 | FR11: -0.39410115 | FS11: 0.71056972 | FT11: 1.8646844 | FU11: 0.22263451 | FV11: 0 | FW11: 0.46896211 | FX11: 0.71244319 | FY11: 0.96353214 | FZ11: 2.9958927 | GA11: 1.7593244 | GB11: -0.41493776 | GC11: -0.3587963 | GD11: 0.68532931 | GE11: -0.63451777 | GF11: -1.1958667 | GG11: -0.34077556 | GH11: 0.9079118 | GI11: 0.49076887 | GJ11: -0.56976744 | GK11: -0.25727985 | GL11: 0.48071286 | GM11: 0.08168028 | GN11: 0.80447709 | GO11: 1.2838307 | GP11: 0.30832477 | GQ11: -0.45537341 | GR11: 0.068618481 | GS11: -0.10285714 | GT11: 0.10296305 | GU11: -0.20571429 | GV11: -1.0077874 | GW11: 0.28921795 | GX11: 1.4880609 | GY11: 1.7958627 | GZ11: 1.4068781 | HA11: 0.41841004 | HB11: 0.48245614 | HC11: 0.38192929 | HD11: 1.0653332 | HE11: 1.5919114 | HF11: 2.5516146 | HG11: 2.2609953 | HH11: 1.130742 | HI11: 0.85854048 | HJ11: 2.9100267 | HK11: -0.68288929 | HL11: -1.6269611 | HM11: -1.5554243 | HN11: 20.83 | HO11: 1.7876355 | HP11: 1.3497032 | HQ11: 1.091055 | HR11: 0.51583208 | HS11: 0.83688615 | HT11: -0.22705919 | HU11: -0.8946088 | HV11: 0.68889065 | HW11: 0.84145958 | HX11: 1.1073852 | HY11: 2.3370613 | HZ11: -0.12812783 | IA11: -0.030186401 | IB11: 2.3326036 | IC11: 0.11065211 | ID11: 1.7684769 | IE11: 2.2228658 | IF11: 3.1378382 | IG11: 5.4391869 | IH11: 4.3769947 | II11: 4.8611544 | IJ11: 3.314687 | IK11: 0.67968435 | IL11: 3.9189885 | IM11: 3.4023343 | IN11: 2.5875839 | IO11: 2.9011833 | IP11: 4.2013416 | IQ11: -0.26137464 | IR11: 1.6500049 | IS11: -0.42012795 | IT11: -1.1698149 | IU11: 1.9016203 | IV11: -1.1615729 | IW11: 1.5412773 | IX11: 2.5709136 | IY11: 1.9422863 | IZ11: 2.7989476 | JA11: 0.18092758 | JB11: 0.54620738 | JC11: 0.43371594 | JD11: -0.32279171 | JE11: -0.63892171 | JF11: -1.6824488 | JG11: -1.0482462 | JH11: -0.43007832 | JI11: 0.31826862 | JJ11: -0.19035533 | JK11: -0.040868223 | JL11: -0.70867215 | JM11: -1.5601409 | JN11: -3.3695854 | JO11: -2.1307296 | JP11: -0.6093965 | JQ11: 0.098892405 | JR11: 1.0225252 | JS11: 0.57209916 | JT11: 0.62718786 | JU11: 0.79238537 | JV11: -0.58961699 | JW11: -0.76188639 | JX11: -0.50048591 | JY11: 0.83996679 | JZ11: 0.96856991 | KA11: 0.55158521 | KB11: 0.930166 | KC11: 0.10870079 | KD11: 1.1991313 | KE11: 2.0106363 | KF11: 1.6600357 | KG11: 1.0796221
A12: Brazil | B12: Producer price index (PPI) | C12: Year-over-year (YOY) percent change | D12: Monthly | F12: 11.368679 | G12: 11.5237 | H12: 12.715008 | I12: 14.300937 | J12: 13.71729 | K12: 14.291292 | L12: 13.33337 | M12: 11.743354 | N12: 11.070574 | O12: 12.53403 | P12: 12.926278 | Q12: 11.871876 | R12: 11.279616 | S12: 11.090687 | T12: 9.8567486 | U12: 9.1698616 | V12: 10.354678 | W12: 10.935624 | X12: 11.905993 | Y12: 14.336651 | Z12: 18.15954 | AA12: 22.963347 | AB12: 31.172219 | AC12: 35.414493 | AD12: 38.584888 | AE12: 40.759296 | AF12: 43.631001 | AG12: 42.653922 | AH12: 38.50372 | AI12: 33.554044 | AJ12: 29.124519 | AK12: 25.850751 | AL12: 22.760249 | AM12: 16.362214 | AN12: 8.7876963 | AO12: 6.2565979 | AP12: 4.7468964 | AQ12: 4.4506122 | AR12: 3.5885558 | AS12: 5.1370948 | AT12: 8.7555188 | AU12: 11.763291 | AV12: 13.945003 | AW12: 14.943909 | AX12: 14.221665 | AY12: 14.352726 | AZ12: 14.970441 | BA12: 14.674811 | BB12: 13.901615 | BC12: 12.741966 | BD12: 12.799008 | BE12: 11.431025 | BF12: 8.4835475 | BG12: 5.9710203 | BH12: 3.8421382 | BI12: 1.1557566 | BJ12: 0.22157623 | BK12: 0.39607039 | BL12: -0.35380593 | BM12: -0.96637602 | BN12: -0.24301303 | BO12: -0.75144396 | BP12: -2.6692401 | BQ12: -3.1426588 | BR12: -1.7317033 | BS12: 0.08900509 | BT12: 0.95027111 | BU12: 2.5590663 | BV12: 3.1295498 | BW12: 3.5148088 | BX12: 4.0379894 | BY12: 4.2930962 | BZ12: 3.7916438 | CA12: 4.120929 | CB12: 5.0894054 | CC12: 5.2713541 | CD12: 4.7550444 | CE12: 3.7562873 | CF12: 4.0208185 | CG12: 5.491564 | CH12: 6.9228187 | CI12: 6.7697112 | CJ12: 7.5141278 | CK12: 9.4410715 | CL12: 10.27006 | CM12: 10.622815 | CN12: 11.391123 | CO12: 12.81529 | CP12: 15.362303 | CQ12: 17.895529 | CR12: 18.906391 | CS12: 15.695548 | CT12: 14.332079 | CU12: 14.717932 | CV12: 12.880997 | CW12: 9.804888 | CX12: 8.274189 | CY12: 7.3864574 | CZ12: 4.9790894 | DA12: 3.5294844 | DB12: 1.1807465 | DC12: -1.7190578 | DD12: -4.0928156 | DE12: -3.2506998 | DF12: -3.3983238 | DG12: -4.7699001 | DH12: -4.643697 | DI12: -4.0751697 | DJ12: -2.8374751 | DK12: -1.1948862 | DL12: 0.79171155 | DM12: 1.5820534 | DN12: 3.7739836 | DO12: 4.8939475 | DP12: 6.4913713 | DQ12: 8.2272136 | DR12: 9.5077635 | DS12: 11.044022 | DT12: 13.288523 | DU12: 13.850419 | DV12: 13.85336 | DW12: 13.687904 | DX12: 13.776369 | DY12: 13.282406 | DZ12: 10.301128 | EA12: 9.6139607 | EB12: 9.0943231 | EC12: 8.0893801 | ED12: 7.524637 | EE12: 6.6262163 | EF12: 4.9125264 | EG12: 4.1151604 | EH12: 3.1378049 | EI12: 1.8533898 | EJ12: 1.7995131 | EK12: 2.8174069 | EL12: 4.4032843 | EM12: 5.5408462 | EN12: 7.9337855 | EO12: 9.0024632 | EP12: 9.1776292 | EQ12: 7.9215819 | ER12: 7.7298308 | ES12: 9.1284309 | ET12: 9.1159741 | EU12: 9.2436261 | EV12: 8.7805932 | EW12: 7.0176765 | EX12: 6.0670007 | EY12: 6.0217991 | EZ12: 4.0152193 | FA12: 2.8083339 | FB12: 3.6169279 | FC12: 5.0707603 | FD12: 5.0243528 | FE12: 5.070714 | FF12: 6.6523886 | FG12: 6.9053282 | FH12: 6.6332333 | FI12: 6.014664 | FJ12: 5.8565511 | FK12: 4.6463007 | FL12: 3.8466376 | FM12: 3.6979475 | FN12: 2.7660225 | FO12: 2.4421629 | FP12: 3.2758308 | FQ12: 2.6634133 | FR12: 0.74047638 | FS12: 1.1299233 | FT12: 3.1514062 | FU12: 4.3956051 | FV12: 4.5422532 | FW12: 5.3504329 | FX12: 6.707321 | FY12: 7.2627563 | FZ12: 9.3991107 | GA12: 10.88427 | GB12: 9.4012938 | GC12: 8.8069005 | GD12: 9.9860424 | GE12: 8.5170719 | GF12: 5.2566481 | GG12: 4.6649389 | GH12: 5.6152042 | GI12: 5.638128 | GJ12: 4.2932065 | GK12: 3.0321334 | GL12: 0.5160685 | GM12: -1.1410788 | GN12: 0.069444444 | GO12: 1.7191311 | GP12: 1.3382557 | GQ12: 1.5209567 | GR12: 2.8202115 | GS12: 3.0656762 | GT12: 2.2435148 | GU12: 1.5348837 | GV12: 1.0875921 | GW12: 1.6414586 | GX12: 2.6604434 | GY12: 4.4187945 | GZ12: 5.0427944 | HA12: 4.1452552 | HB12: 4.3260474 | HC12: 5.2035682 | HD12: 6.2514286 | HE12: 8.0539984 | HF12: 10.697143 | HG12: 13.433349 | HH12: 15.88385 | HI12: 16.5417 | HJ12: 18.174585 | HK12: 15.297008 | HL12: 11.847611 | HM12: 9.6491228 | HN12: 31.852903 | HO12: 33.699315 | HP12: 34.075508 | HQ12: 33.414505 | HR12: 30.766054 | HS12: 28.944977 | HT12: 27.213737 | HU12: 25.002475 | HV12: 22.304511 | HW12: 24.181677 | HX12: 27.633392 | HY12: 32.68 | HZ12: 9.6664736 | IA12: 7.7079437 | IB12: 8.752507 | IC12: 7.6978018 | ID12: 9.0399495 | IE12: 10.538678 | IF12: 14.266656 | IG12: 21.569404 | IH12: 26.022334 | II12: 31.045777 | IJ12: 33.906672 | IK12: 31.738016 | IL12: 37.076447 | IM12: 41.783045 | IN12: 42.136323 | IO12: 46.098298 | IP12: 49.590906 | IQ12: 45.955518 | IR12: 43.85001 | IS12: 35.856184 | IT12: 28.636505 | IU12: 25.005951 | IV12: 19.589885 | IW12: 20.613307 | IX12: 19.048668 | IY12: 17.367692 | IZ12: 17.609508 | JA12: 14.500429 | JB12: 10.484027 | JC12: 11.254004 | JD12: 9.0948152 | JE12: 8.8551155 | JF12: 8.2904822 | JG12: 5.1556698 | JH12: 5.9339177 | JI12: 4.6580021 | JJ12: 1.8405475 | JK12: -0.14062784 | JL12: -3.5479458 | JM12: -5.2242093 | JN12: -8.9152721 | JO12: -11.241003 | JP12: -11.496215 | JQ12: -10.839022 | JR12: -8.3859696 | JS12: -6.8857803 | JT12: -5.8970628 | JU12: -5.4523205 | JV12: -5.8305331 | JW12: -6.5097897 | JX12: -6.3137668 | JY12: -4.0295594 | JZ12: 0.27896686 | KA12: 3.0273246 | KB12: 4.6232199 | KC12: 4.6334716 | KD12: 4.8163904 | KE12: 6.3156359 | KF12: 7.4068706 | KG12: 7.7129572
