Workbook

Sheet Ene 2021_Destino
A1: Evolución de las exportaciones con origen en la provincia de Santa Fe, según destino. Mes enero de 2021
B4: Enero 2021
A5: País de destino | B5: Valor F.O.B. | C5: Peso Neto
B6: (en Dólares) | C6: (en Kilos)
A8: TOTAL | B8: 1.3120647e+09 | C8: 2.3849468e+09
A10: AFRICA | B10: 1.3778579e+08 | C10: 2.8535746e+08
A11: Argelia | B11: 39493430 | C11: 65613147
A12: Camerún | B12: - | C12: -
A13: Congo | B13: - | C13: -
A14: Costa de Marfil | B14: 88038.63 | C14: 98825.8
A15: Benin | B15: 22252.17 | C15: 39429.5
A16: Egipto | B16: 19838185 | C16: 47701389
A17: Gambia | B17: 438983.23 | C17: 1735768.4
A18: Ghana | B18: 185985.28 | C18: 695419.15
A19: Kenya | B19: 4106388.3 | C19: 17638531
A20: Libia | B20: 15664.79 | C20: 27380.55
A21: Mali | B21: 125725.09 | C21: 566860.36
A22: Marruecos | B22: 762941.2 | C22: 4429704.4
A23: Mauricio | B23: 459906.43 | C23: 2211423.6
A24: Nigeria | B24: 2358764.7 | C24: 10624533
A25: Senegal | B25: 532793.71 | C25: 2457053
... A41: Ecuador | B41: 15499777 | C41: 42019176
A42: El Salvador | B42: - | C42: -
A43: Estados Unidos | B43: 7956281.6 | C43: 2373998.3
A44: Guatemala | B44: 232774.27 | C44: 66791.19
A45: Honduras | B45: - | C45: -
A46: México | B46: 4310931.1 | C46: 6748288.3
A47: Nicaragua | B47: 235381.82 | C47: 4772.23
A48: Panamá | B48: 280064.88 | C48: 432087.06
A49: Paraguay | B49: 8229270.2 | C49: 8997356.4
A50: Perú | B50: 11858317 | C50: 33745879
A51: Trinidad y Tobago | B51: 6165.84 | C51: 9031.07
A52: Uruguay | B52: 9585265 | C52: 21152551
A53: Venezuela | B53: 698622.27 | C53: 377903.57
A55: ASIA | B55: 5.9755132e+08 | C55: 9.9175742e+08
A56: Arabia Saudita | B56: 4209328.2 | C56: 12277219
A57: Corea Republicana | B57: 2922078.4 | C57: 16570901
A58: China | B58: 65680887 | C58: 46524832
... A85: España | B85: 52856511 | C85: 1.2305716e+08
A86: Finlandia | B86: - | C86: -
...

Sheet Ene-Feb 2021_Destino
A1: Evolución de las exportaciones con origen en la provincia de Santa Fe, según destino. Período enero - febrero 2021
B4: Enero - febrero 2021
A5: País de destino | B5: Valor F.O.B. | C5: Peso Neto
B6: (en Dólares) | C6: (en Kilos)
A8: TOTAL | B8: 2.5912505e+09 | C8: 4.5732915e+09
A10: AFRICA | B10: 2.8372282e+08 | C10: 5.8273408e+08
A11: Argelia | B11: 95465460 | C11: 1.8237429e+08
A12: Camerún | B12: 331472.63 | C12: 1719067.4
A13: Congo | B13: - | C13: -
A14: Rep. Democrática del Congo (ex Zaire) | B14: - | C14: -
A15: Costa de Marfil | B15: 103706.63 | C15: 123925.8
A16: Benin | B16: 29100.75 | C16: 51434.9
A17: Egipto | B17: 74316732 | C17: 1.2393344e+08
A18: Gambia | B18: 983087.35 | C18: 4225517.6
A19: Ghana | B19: 745497.2 | C19: 4004131.7
A20: Guinea | B20: 2373151.3 | C20: 10780772
A21: Kenya | B21: 5234350.2 | C21: 22094971
A22: Liberia | B22: 235725.81 | C22: 1034167.2
A23: Libia | B23: 15664.79 | C23: 27380.55
A24: Mali | B24: 125725.09 | C24: 566860.36
A25: Marruecos | B25: 4394167.3 | C25: 19998549
A26: Mauricio | B26: 459906.43 | C26: 2211423.6
A27: Mauritania | B27: - | C27: -
A28: Nigeria | B28: 4011346.5 | C28: 17604613
A29: Senegal | B29: 915090.11 | C29: 4848998.5
A30: Sierra Leona | B30: 12183.72 | C30: 21433.17
A31: Tanzania | B31: 2877068.4 | C31: 12478407
A32: Túnez | B32: - | C32: -
A33: Uganda | B33: 4673629.3 | C33: 20097847
A34: Angola | B34: 510963.24 | C34: 242933.88
A35: Mozambique | B35: 24335397 | C35: 26155626
A36: Djibouti | B36: 51331.32 | C36: 91099.8
A37: Sudáfrica | B37: 61522068 | C37: 1.2804719e+08
A38: Etiopía | B38: - | C38: -
A40: AMERICA | B40: 4.5069828e+08 | C40: 7.2239705e+08
A41: Bolivia | B41: 14968438 | C41: 25693195
A42: Brasil | B42: 2.1286176e+08 | C42: 3.3379145e+08
A43: Canadá | B43: 346595.41 | C43: 99583.31
A44: Colombia | B44: 6867744 | C44: 6624495.2
A45: Costa Rica | B45: 833827.75 | C45: 883694.46
...

Sheet Ene-Mar 2021_Destino
A1: Evolución de las exportaciones con origen en la provincia de Santa Fe, según destino. Período enero - marzo 2021
B4: Enero - marzo 2021
A5: País de destino | B5: Valor F.O.B. | C5: Peso Neto
B6: (en Dólares) | C6: (en Kilos)
A8: TOTAL | B8: 4.0383981e+09 | C8: 7.1463921e+09
A10: AFRICA | B10: 4.0728613e+08 | C10: 9.4833756e+08
A11: Argelia | B11: 1.2101019e+08 | C11: 2.5431282e+08
A12: Camerún | B12: 342950.07 | C12: 1742640.3
A13: Congo | B13: 511153.4 | C13: 1803418.8
A14: Rep. Democrática del Congo (ex Zaire) | B14: - | C14: -
A15: Costa de Marfil | B15: 1944006 | C15: 8803726.2
A16: Benin | B16: 30841.53 | C16: 54436.25
A17: Egipto | B17: 1.0485478e+08 | C17: 2.1385243e+08
A18: Gambia | B18: 1392242 | C18: 6047367.2
A19: Ghana | B19: 819474.2 | C19: 4061851.7
A20: Guinea | B20: 2539434.7 | C20: 11416702
A21: Kenya | B21: 6432595 | C21: 26959926
A22: Liberia | B22: 240550.64 | C22: 1047168.2
A23: Libia | B23: 27201.22 | C23: 44706.87
A24: Mali | B24: 313806.64 | C24: 1436205.4
A25: Marruecos | B25: 28297338 | C25: 1.0640038e+08
A26: Mauricio | B26: 461815.06 | C26: 2216394
... A38: Sudáfrica | B38: 85242241 | C38: 1.7446403e+08
A39: Etiopía | B39: - | C39: -
A41: AMERICA | B41: 7.363823e+08 | C41: 1.1567856e+09
A42: Bolivia | B42: 23223519 | C42: 38495978
A43: Brasil | B43: 2.8191114e+08 | C43: 422061801
A44: Canadá | B44: 631595.21 | C44: 185339.2
A45: Colombia | B45: 15134444 | C45: 20711923
A46: Costa Rica | B46: 1106268.1 | C46: 1075805.3
A47: Cuba | B47: 24160916 | C47: 65656906
A48: Chile | B48: 1.0944713e+08 | C48: 1.7339681e+08
A49: República Dominicana | B49: 12933188 | C49: 13474076
A50: Ecuador | B50: 65610875 | C50: 1.4837976e+08
A51: El Salvador | B51: 19481.53 | C51: 32807.77
A52: Estados Unidos | B52: 34225435 | C52: 13292691
... A69: Arabia Saudita | B69: 32521623 | C69: 84711244
A70: Bahrein | B70: - | C70: -
A71: Corea Republicana | B71: 10756195 | C71: 40767813
A72: China | B72: 2.2002353e+08 | C72: 1.5216032e+08
...

Sheet Ene-Abr 2021_Destino
A1: Evolución de las exportaciones con origen en la provincia de Santa Fe, según destino. Período enero - abril 2021
B4: Enero - abril 2021
A5: País de destino | B5: Valor F.O.B. | C5: Peso Neto
B6: (en Dólares) | C6: (en Kilos)
A8: TOTAL | B8: 5.6716869e+09 | C8: 1.0285642e+10
A10: AFRICA | B10: 6.0909675e+08 | C10: 1.408069e+09
A16: Albania | B16: 8054.82 | C16: 13016.78
A17: Angola | B17: 2917516.9 | C17: 9211850.4
A18: Arabia Saudita | B18: 57869067 | C18: 1.5477614e+08
A19: Argelia | B19: 1.6643135e+08 | C19: 3.5346558e+08
A20: Australia | B20: 20483281 | C20: 38203649
A21: Austria | B21: 579673.3 | C21: 17853.83
A22: Azerbaiján | B22: 27866.27 | C22: 38990.64
A23: Bahrein | B23: 7882.77 | C23: 14485.38
A24: Bangladesh | B24: 1.7224132e+08 | C24: 2.186924e+08
A25: Bélgica | B25: 19717744 | C25: 28520084
... A28: Bolivia | B28: 30179755 | C28: 49741746
A29: Bosnia Herzegovina | B29: - | C29: -
A30: Brasil | B30: 3.6064981e+08 | C30: 5.3207825e+08
A31: Bulgaria | B31: 620912.11 | C31: 464093.56
A32: Camerún | B32: 342950.07 | C32: 1742640.3
A33: Canadá | B33: 793302.25 | C33: 209926.09
A34: Chile | B34: 1.6742016e+08 | C34: 2.693584e+08
A35: China | B35: 3.6380529e+08 | C35: 2.9273292e+08
A36: Chipre | B36: 7661.35 | C36: 10405.91
A37: Colombia | B37: 44130364 | C37: 91834378
A38: Congo | B38: 567330.96 | C38: 1873219.8
A39: Corea Republicana | B39: 26789891 | C39: 84472172
A40: Costa de Marfil | B40: 8273150.6 | C40: 25530355
A41: Costa Rica | B41: 1175657.1 | C41: 1172182
... A55: Estados Unidos | B55: 47037596 | C55: 17359574
A56: Estonia | B56: - | C56: -
A57: Etiopía | B57: - | C57: -
A58: Filipinas | B58: 73994653 | C58: 1.7155778e+08
A59: Finlandia | B59: 5312.01 | C59: 4854.65
A60: Francia | B60: 65869266 | C60: 1.3753199e+08
A61: Gabón | B61: 7070.46 | C61: 12240.8
A62: Gambia | B62: 1845691.6 | C62: 7711187.6
A63: Ghana | B63: 5772003 | C63: 15724539
A64: Grecia | B64: 36369606 | C64: 79641934
...

Sheet Ene-May 2021_Destino
A1: Evolución de las exportaciones con origen en la provincia de Santa Fe, según destino. Período enero - mayo 2021
B4: Enero - mayo 2021
A5: País de destino | B5: Valor F.O.B. | C5: Peso Neto | H5: País de destino
B6: (en Dólares) | C6: (en Kilos)
A8: TOTAL | B8: 7.3535633e+09 | C8: 1.3224774e+10 | E8: =+B8-'Ene-Abr 2021_Destino'!B8 -> 1.6818764e+09 | H8: TOTAL
A15: Bosnia Herzegovina | B15: - | C15: - | D15: =+A15='Ene-Abr 2021_Destino'!A29 -> TRUE | E15: =+B15-'Ene-Abr 2021_Destino'!B29 -> #VALUE! | F15: =+E15/$E$8 -> #VALUE! | H15: Bosnia Herzegovina
A16: Estonia | B16: - | C16: - | D16: =+A16='Ene-Abr 2021_Destino'!A56 -> TRUE | E16: =+B16-'Ene-Abr 2021_Destino'!B56 -> #VALUE! | F16: =+E16/$E$8 -> #VALUE! | H16: Estonia
A17: Etiopía | B17: - | C17: - | D17: =+A17='Ene-Abr 2021_Destino'!A57 -> TRUE | E17: =+B17-'Ene-Abr 2021_Destino'!B57 -> #VALUE! | F17: =+E17/$E$8 -> #VALUE! | H17: Etiopía
A18: Malawi | B18: - | C18: - | D18: =+A18='Ene-Abr 2021_Destino'!A91 -> TRUE | E18: =+B18-'Ene-Abr 2021_Destino'!B91 -> #VALUE! | F18: =+E18/$E$8 -> #VALUE! | H18: Malawi
A19: Myanmar (ex Birmania) Unión de | B19: - | C19: - | D19: =+A19='Ene-Abr 2021_Destino'!A101 -> TRUE | E19: =+B19-'Ene-Abr 2021_Destino'!B101 -> #VALUE! | F19: =+E19/$E$8 -> #VALUE! | H19: Myanmar (ex Birmania) Unión de
A20: Rep. Democrática del Congo (ex Zaire) | B20: - | C20: - | D20: =+A20='Ene-Abr 2021_Destino'!A119 -> TRUE | E20: =+B20-'Ene-Abr 2021_Destino'!B119 -> #VALUE! | F20: =+E20/$E$8 -> #VALUE! | H20: Rep. Democrática del Congo (ex Zaire)
A21: Siria | B21: - | C21: - | D21: =+A21='Ene-Abr 2021_Destino'!A131 -> TRUE | E21: =+B21-'Ene-Abr 2021_Destino'!B131 -> #VALUE! | F21: =+E21/$E$8 -> #VALUE! | H21: Siria
A22: China | B22: 5.7455051e+08 | C22: 5.6364213e+08 | D22: =+A22='Ene-Abr 2021_Destino'!A35 -> TRUE | E22: =+B22-'Ene-Abr 2021_Destino'!B35 -> 2.1074522e+08 | F22: =+E22/$E$8 -> 0.12530363 | H22: China | I22: China | J22: 0.122728 | K22: =I22=H22 -> TRUE
A23: India | B23: 7.6511492e+08 | C23: 7.7367726e+08 | D23: =+A23='Ene-Abr 2021_Destino'!A72 -> TRUE | E23: =+B23-'Ene-Abr 2021_Destino'!B72 -> 1.4731554e+08 | F23: =+E23/$E$8 -> 0.087589992 | H23: India | I23: India | J23: 0.08578957 | K23: =I23=H23 -> TRUE
A24: Países Bajos | B24: 3.6212041e+08 | C24: 4.3736411e+08 | D24: =+A24='Ene-Abr 2021_Destino'!A109 -> TRUE | E24: =+B24-'Ene-Abr 2021_Destino'!B109 -> 1.3603708e+08 | F24: =+E24/$E$8 -> 0.080884116 | H24: Países Bajos | I24: Países Bajos | J24: 0.079221535 | K24: =I24=H24 -> TRUE
A25: Indonesia | B25: 4.5725239e+08 | C25: 1.0483871e+09 | D25: =+A25='Ene-Abr 2021_Destino'!A73 -> TRUE | E25: =+B25-'Ene-Abr 2021_Destino'!B73 -> 1.2033321e+08 | F25: =+E25/$E$8 -> 0.071547001 | H25: Indonesia | I25: Indonesia | J25: 0.070076345 | K25: =I25=H25 -> TRUE
A26: Vietnam | B26: 5.9982555e+08 | C26: 1.4822025e+09 | D26: =+A26='Ene-Abr 2021_Destino'!A146 -> TRUE | E26: =+B26-'Ene-Abr 2021_Destino'!B146 -> 83125589 | F26: =+E26/$E$8 -> 0.049424317 | H26: Vietnam | I26: Vietnam | J26: 0.048408394 | K26: =I26=H26 -> TRUE
A27: Brasil | B27: 4.400744e+08 | C27: 6.4908684e+08 | D27: =+A27='Ene-Abr 2021_Destino'!A30 -> TRUE | E27: =+B27-'Ene-Abr 2021_Destino'!B30 -> 79424597 | F27: =+E27/$E$8 -> 0.047223803 | H27: Brasil | I27: Brasil | J27: 0.046253113 | K27: =I27=H27 -> TRUE
A28: Chile | B28: 2.4377991e+08 | C28: 4.0899213e+08 | D28: =+A28='Ene-Abr 2021_Destino'!A34 -> TRUE | E28: =+B28-'Ene-Abr 2021_Destino'!B34 -> 76359742 | F28: =+E28/$E$8 -> 0.045401519 | H28: Chile | I28: Chile | J28: 0.044468286 | K28: =I28=H28 -> TRUE
A29: Arabia Saudita | B29: 1.1848074e+08 | C29: 3.2115698e+08 | D29: =+A29='Ene-Abr 2021_Destino'!A18 -> TRUE | E29: =+B29-'Ene-Abr 2021_Destino'!B18 -> 60611673 | F29: =+E29/$E$8 -> 0.036038127 | H29: Arabia Saudita | I29: Arabia Saudita | J29: 0.035297359 | K29: =I29=H29 -> TRUE
A30: Bangladesh | B30: 2.2451707e+08 | C30: 3.1165051e+08 | D30: =+A30='Ene-Abr 2021_Destino'!A24 -> TRUE | E30: =+B30-'Ene-Abr 2021_Destino'!B24 -> 52275748 | F30: =+E30/$E$8 -> 0.031081802 | H30: Bangladesh | I30: Bangladesh | J30: 0.030442913 | K30: =I30=H30 -> TRUE
A31: Perú | B31: 1.6380192e+08 | C31: 2.5965088e+08 | D31: =+A31='Ene-Abr 2021_Destino'!A113 -> TRUE | E31: =+B31-'Ene-Abr 2021_Destino'!B113 -> 47109702 | F31: =+E31/$E$8 -> 0.028010205 | H31: Perú | I31: Perú | J31: 0.027434452 | K31: =I31=H31 -> TRUE
A32: Egipto | B32: 2.3639224e+08 | C32: 4.6930367e+08 | D32: =+A32='Ene-Abr 2021_Destino'!A49 -> TRUE | E32: =+B32-'Ene-Abr 2021_Destino'!B49 -> 42131308 | F32: =+E32/$E$8 -> 0.025050181 | H32: Egipto | I32: Egipto | J32: 0.024535272 | K32: =I32=H32 -> TRUE
A33: Malasia | B33: 2.1725008e+08 | C33: 5.6188767e+08 | D33: =+A33='Ene-Abr 2021_Destino'!A90 -> TRUE | E33: =+B33-'Ene-Abr 2021_Destino'!B90 -> 41709828 | F33: =+E33/$E$8 -> 0.02479958 | H33: Malasia | I33: Malasia | J33: 0.024289822 | K33: =I33=H33 -> TRUE
A34: Polonia | B34: 1.9503038e+08 | C34: 4.2098737e+08 | D34: =+A34='Ene-Abr 2021_Destino'!A114 -> TRUE | E34: =+B34-'Ene-Abr 2021_Destino'!B114 -> 41495804 | F34: =+E34/$E$8 -> 0.024672327 | H34: Polonia | I34: Polonia | J34: 0.024165185 | K34: =I34=H34 -> TRUE
A35: Iraq | B35: 1.1637257e+08 | C35: 1.7867237e+08 | D35: =+A35='Ene-Abr 2021_Destino'!A75 -> TRUE | E35: =+B35-'Ene-Abr 2021_Destino'!B75 -> 41122271 | F35: =+E35/$E$8 -> 0.024450234 | H35: Iraq | I35: Iraq | J35: 0.023947657 | K35: =I35=H35 -> TRUE
A36: España | B36: 2.3540281e+08 | C36: 5.2209524e+08 | D36: =+A36='Ene-Abr 2021_Destino'!A54 -> TRUE | E36: =+B36-'Ene-Abr 2021_Destino'!B54 -> 36944338 | F36: =+E36/$E$8 -> 0.021966144 | H36: España | I36: España | J36: 0.021514628 | K36: =I36=H36 -> TRUE
A37: República de Yemen | B37: 38763833 | C37: 1.0578245e+08 | D37: =+A37='Ene-Abr 2021_Destino'!A121 -> TRUE | E37: =+B37-'Ene-Abr 2021_Destino'!B121 -> 33820364 | F37: =+E37/$E$8 -> 0.02010871 | H37: República de Yemen | I37: República de Yemen | J37: 0.019695373 | K37: =I37=H37 -> TRUE
A38: Sudáfrica | B38: 1.37712e+08 | C38: 2.8720904e+08 | D38: =+A38='Ene-Abr 2021_Destino'!A133 -> TRUE | E38: =+B38-'Ene-Abr 2021_Destino'!B133 -> 31290408 | F38: =+E38/$E$8 -> 0.018604464 | H38: Sudáfrica | I38: Sudáfrica | J38: 0.018222047 | K38: =I38=H38 -> TRUE
A39: Turquía | B39: 39773724 | C39: 86259567 | D39: =+A39='Ene-Abr 2021_Destino'!A141 -> TRUE | E39: =+B39-'Ene-Abr 2021_Destino'!B141 -> 29368286 | F39: =+E39/$E$8 -> 0.01746162 | H39: Turquía | I39: Turquía | J39: 0.017102695 | K39: =I39=H39 -> TRUE
A40: Irán | B40: 1.6229226e+08 | C40: 224894020 | D40: =+A40='Ene-Abr 2021_Destino'!A74 -> TRUE | E40: =+B40-'Ene-Abr 2021_Destino'!B74 -> 25450581 | F40: =+E40/$E$8 -> 0.015132254 | H40: Irán | I40: Irán | J40: 0.014821209 | K40: =I40=H40 -> TRUE
A41: Italia | B41: 1.3518922e+08 | C41: 2.9238276e+08 | D41: =+A41='Ene-Abr 2021_Destino'!A78 -> TRUE | E41: =+B41-'Ene-Abr 2021_Destino'!B78 -> 24803776 | F41: =+E41/$E$8 -> 0.014747681 | H41: Italia | I41: Italia | J41: 0.014444541 | K41: =I41=H41 -> TRUE
A42: Túnez | B42: 25458052 | C42: 65521880 | D42: =+A42='Ene-Abr 2021_Destino'!A140 -> TRUE | E42: =+B42-'Ene-Abr 2021_Destino'!B140 -> 22058632 | F42: =+E42/$E$8 -> 0.013115489 | H42: Túnez | I42: Túnez | J42: 0.012845899 | K42: =I42=H42 -> TRUE
A43: Bielorrusia | B43: 21769017 | C43: 50782189 | D43: =+A43='Ene-Abr 2021_Destino'!A27 -> TRUE | E43: =+B43-'Ene-Abr 2021_Destino'!B27 -> 21766028 | F43: =+E43/$E$8 -> 0.012941515 | H43: Bielorrusia | I43: Argelia | J43: 0 | K43: =I43=H43 -> FALSE
A44: Argelia | B44: 1.8577392e+08 | C44: 3.790201e+08 | D44: =+A44='Ene-Abr 2021_Destino'!A19 -> TRUE | E44: =+B44-'Ene-Abr 2021_Destino'!B19 -> 19342563 | F44: =+E44/$E$8 -> 0.011500585 | H44: Argelia | I44: Estados Unidos | J44: 0 | K44: =I44=H44 -> FALSE
A45: Estados Unidos | B45: 65548501 | C45: 24844286 | D45: =+A45='Ene-Abr 2021_Destino'!A55 -> TRUE | E45: =+B45-'Ene-Abr 2021_Destino'!B55 -> 18510905 | F45: =+E45/$E$8 -> 0.011006103 | H45: Estados Unidos | I45: Tailandia | J45: 0 | K45: =I45=H45 -> FALSE
A46: Mozambique | B46: 42606271 | C46: 42231626 | D46: =+A46='Ene-Abr 2021_Destino'!A100 -> TRUE | E46: =+B46-'Ene-Abr 2021_Destino'!B100 -> 18270874 | F46: =+E46/$E$8 -> 0.010863387 | H46: Mozambique | I46: Reino Unido | J46: 0 | K46: =I46=H46 -> FALSE
A47: Ecuador | B47: 1.0789335e+08 | C47: 2.4093634e+08 | D47: =+A47='Ene-Abr 2021_Destino'!A48 -> TRUE | E47: =+B47-'Ene-Abr 2021_Destino'!B48 -> 17420233 | F47: =+E47/$E$8 -> 0.010357618 | H47: Ecuador | I47: Jordania | J47: 0 | K47: =I47=H47 -> FALSE
A48: Filipinas | B48: 89595295 | C48: 2.074337e+08 | D48: =+A48='Ene-Abr 2021_Destino'!A58 -> TRUE | E48: =+B48-'Ene-Abr 2021_Destino'!B58 -> 15600642 | F48: =+E48/$E$8 -> 0.0092757365 | H48: Filipinas | I48: Dinamarca | J48: 0 | K48: =I48=H48 -> FALSE
A49: República Dominicana | B49: 37983823 | C49: 41837100 | D49: =+A49='Ene-Abr 2021_Destino'!A122 -> TRUE | E49: =+B49-'Ene-Abr 2021_Destino'!B122 -> 13215201 | F49: =+E49/$E$8 -> 0.0078574151 | H49: República Dominicana | I49: Uruguay | J49: 0 | K49: =I49=H49 -> FALSE
...

Sheet Ene-Jun 2021_Destino
A1: Evolución de las exportaciones con origen en la provincia de Santa Fe, según destino. Período enero - junio 2021
B4: Enero - junio 2021
A5: País de destino | B5: Valor F.O.B. | C5: Peso Neto
B6: (en Dólares) | C6: (en Kilos)
A8: TOTAL | B8: 8.9910639e+09 | C8: 1.6164534e+10
A10: AFRICA | B10: 8.8530787e+08 | C10: 2.0219894e+09
A11: Argelia | B11: 2.2174242e+08 | C11: 4.8193191e+08
A12: Camerún | B12: 400290.86 | C12: 1975627.5
A13: Congo | B13: 660236.51 | C13: 1975189.8
A14: Rep. Democrática del Congo (ex Zaire) | B14: - | C14: -
A15: Costa de Marfil | B15: 11550849 | C15: 33431399
A16: Benin | B16: 87595.2 | C16: 147772.35
A17: Egipto | B17: 2.596278e+08 | C17: 5.3617305e+08
A18: Gabón | B18: 8942.95 | C18: 15301
A19: Gambia | B19: 1901509.6 | C19: 7850213.6
A20: Ghana | B20: 9514583.8 | C20: 24432215
A21: Guinea | B21: 2542800.9 | C21: 11422822
A22: Kenya | B22: 6433564.1 | C22: 26960737
A23: Liberia | B23: 266603.54 | C23: 1089973.3
A24: Libia | B24: 120338.4 | C24: 142993.83
A25: Malawi | B25: - | C25: -
A26: Mali | B26: 712991.5 | C26: 3136286.2
A27: Marruecos | B27: 1.1257579e+08 | C27: 3.1395073e+08
A28: Mauricio | B28: 1428006.6 | C28: 6272855
A29: Mauritania | B29: 3835697.5 | C29: 15829678
A30: Níger | B30: 24174.87 | C30: 42430.85
A31: Nigeria | B31: 13291385 | C31: 51331651
A32: Senegal | B32: 12890470 | C32: 44912036
A33: Sierra Leona | B33: 49719.85 | C33: 85697.37
A34: Tanzania | B34: 2880598.2 | C34: 12484537
A35: Túnez | B35: 27349891 | C35: 72611703
A36: Uganda | B36: 5434287.6 | C36: 22885797
A37: Angola | B37: 4953773.1 | C37: 17208467
... A40: Sudáfrica | B40: 1.380503e+08 | C40: 2.8727253e+08
A41: Etiopía | B41: - | C41: -
A43: AMERICA | B43: 1.749263e+09 | C43: 2.71403e+09
A44: Bolivia | B44: 43392611 | C44: 69617549
A45: Brasil | B45: 5.4943315e+08 | C45: 7.8047633e+08
A46: Canadá | B46: 1588201.1 | C46: 857859.16
A47: Colombia | B47: 85955683 | C47: 1.9556138e+08
...

Sheet Ene-Jul 2021_Destino
A1: Evolución de las exportaciones con origen en la provincia de Santa Fe, según destino. Período enero - julio 2021
B4: Enero - julio 2021
A5: País de destino | B5: Valor F.O.B. | C5: Peso Neto
B6: (en Dólares) | C6: (en Kilos)
A8: TOTAL | B8: 1.0634122e+10 | C8: 1.903766e+10
A10: AFRICA | B10: 1.0228347e+09 | C10: 2.3240514e+09
A11: Argelia | B11: 2.654152e+08 | C11: 5.7195029e+08
A12: Camerún | B12: 4968452.8 | C12: 11723632
A13: Congo | B13: 733651.86 | C13: 2028361.2
A14: Rep. Democrática del Congo (ex Zaire) | B14: - | C14: -
A15: Costa de Marfil | B15: 16862583 | C15: 46609362
A16: Benin | B16: 115498.93 | C16: 193086.9
A17: Egipto | B17: 3.0977819e+08 | C17: 6.3235712e+08
A18: Gabón | B18: 14630.92 | C18: 24481.6
A19: Gambia | B19: 1921085.9 | C19: 7896925.7
A20: Ghana | B20: 9527433.2 | C20: 24453636
A21: Guinea | B21: 2542800.9 | C21: 11422822
A22: Kenya | B22: 6434500.5 | C22: 26961551
A23: Liberia | B23: 279452.14 | C23: 1111394.7
A24: Libia | B24: 822258.65 | C24: 2952255.9
A25: Malawi | B25: - | C25: -
A26: Mali | B26: 714818.44 | C26: 3139346.4
A27: Marruecos | B27: 1.2488574e+08 | C27: 3.583922e+08
A28: Mauricio | B28: 1793856.5 | C28: 7721800.1
A29: Mauritania | B29: 3835697.5 | C29: 15829678
A30: Níger | B30: 28063.45 | C30: 48551.3
A31: Nigeria | B31: 13403775 | C31: 51449712
A32: Senegal | B32: 13391171 | C32: 46794557
A33: Sierra Leona | B33: 51698.36 | C33: 88734
A34: Tanzania | B34: 2880598.2 | C34: 12484537
A35: Togo | B35: - | C35: -
A36: Túnez | B36: 28726044 | C36: 76488033
A37: Uganda | B37: 5434287.6 | C37: 22885797
A38: Angola | B38: 5241108.9 | C38: 17837683
A39: Cabo Verde | B39: - | C39: -
A40: Mozambique | B40: 49088192 | C40: 48084560
A41: Djibouti | B41: 136227.45 | C41: 234223
A42: Sudáfrica | B42: 1.5380766e+08 | C42: 3.2288704e+08
A43: Etiopía | B43: - | C43: -
A45: AMERICA | B45: 2.1138428e+09 | C45: 3.2490996e+09
...

Sheet Ene-Ago 2021_Destino
A1: Evolución de las exportaciones con origen en la provincia de Santa Fe, según destino. Período enero - agosto 2021
B4: Enero - agosto 2021
A5: País de destino | B5: Valor F.O.B. | C5: Peso Neto
B6: (en Dólares) | C6: (en Kilos)
A8: TOTAL | B8: 1.2210269e+10 | C8: 2.1930302e+10
A10: AFRICA | B10: 1.1680332e+09 | C10: 2.6229841e+09
A11: Burkina Faso | B11: - | C11: -
A12: Argelia | B12: 2.8721156e+08 | C12: 6.0966646e+08
A13: Camerún | B13: 4981594.6 | C13: 11744818
A14: Congo | B14: 2855173.3 | C14: 8040031.6
A15: Rep. Democrática del Congo (ex Zaire) | B15: - | C15: -
A16: Costa de Marfil | B16: 20669416 | C16: 56124083
A17: Benin | B17: 133854.83 | C17: 222864.95
A18: Egipto | B18: 3.3308132e+08 | C18: 7.1430381e+08
A19: Gabón | B19: 27248.48 | C19: 45691.14
A20: Gambia | B20: 1934878.1 | C20: 7931718.4
A21: Ghana | B21: 13401347 | C21: 34268262
A22: Guinea | B22: 2550715.1 | C22: 11435063
A23: Kenya | B23: 6434500.5 | C23: 26961551
A24: Liberia | B24: 281243.89 | C24: 1114454.9
A25: Libia | B25: 849398.14 | C25: 2983951.2
A26: Malawi | B26: - | C26: -
A27: Mali | B27: 722222.27 | C27: 3151587.2
A28: Marruecos | B28: 150070799 | C28: 3.9504293e+08
A29: Mauricio | B29: 16386074 | C29: 37116521
A30: Mauritania | B30: 3835697.5 | C30: 15829678
A31: Níger | B31: 28063.45 | C31: 48551.25
A32: Nigeria | B32: 13594338 | C32: 51667552
A33: Senegal | B33: 20721305 | C33: 66143736
A34: Sierra Leona | B34: 55232.89 | C34: 94854.43
A35: Tanzania | B35: 2884267.1 | C35: 12490658
A36: Togo | B36: - | C36: -
A37: Túnez | B37: 29429894 | C37: 79697303
A38: Uganda | B38: 5434287.6 | C38: 22885797
A39: Angola | B39: 6900593.2 | C39: 23058647
A40: Cabo Verde | B40: 671913.37 | C40: 3666824.9
A41: Mozambique | B41: 68302044 | C41: 64122640
A42: Djibouti | B42: 136227.45 | C42: 234223
A43: Sudáfrica | B43: 1.7444804e+08 | C43: 3.6288981e+08
A44: Etiopía | B44: - | C44: -
...

Sheet Ene-Sep 2021_Destino
A1: Evolución de las exportaciones con origen en la provincia de Santa Fe, según destino. Período enero - septiembre 2021
B4: Enero - septiembre 2021
A5: País de destino | B5: Valor F.O.B. | C5: Peso Neto
B6: (en Dólares) | C6: (en Kilos)
A8: TOTAL | B8: 1.390556e+10 | C8: 2.4909576e+10
A10: AFRICA | B10: 1.3083806e+09 | C10: 2.8876961e+09
A11: Burkina Faso | B11: 21586.18 | C11: 36133.9
A12: Argelia | B12: 3.3983361e+08 | C12: 7.1041775e+08
A13: Camerún | B13: 4991123.9 | C13: 11759824
A14: Congo | B14: 2863273.3 | C14: 8067031.6
A15: Rep. Democrática del Congo (ex Zaire) | B15: - | C15: -
A16: Costa de Marfil | B16: 25851641 | C16: 69920297
A17: Benin | B17: 152551.48 | C17: 253466.95
A18: Egipto | B18: 3.3716734e+08 | C18: 7.3106744e+08
A19: Gabón | B19: 27248.48 | C19: 45691.14
A20: Gambia | B20: 1942686.6 | C20: 7951600
A21: Ghana | B21: 21609415 | C21: 56268812
A22: Guinea | B22: 2564234.2 | C22: 11456484
A23: Kenya | B23: 6446245.1 | C23: 26964113
A24: Liberia | B24: 288935.12 | C24: 1126695.7
A25: Libia | B25: 876421.47 | C25: 3026794
A26: Malawi | B26: - | C26: -
A27: Mali | B27: 729677.4 | C27: 3163828
A28: Marruecos | B28: 1.5478185e+08 | C28: 4.1684197e+08
A29: Mauricio | B29: 16389071 | C29: 37121606
A30: Mauritania | B30: 3835697.5 | C30: 15829678
A31: Níger | B31: 31766.29 | C31: 54671.65
A32: Nigeria | B32: 37182138 | C32: 69375118
A33: Senegal | B33: 25837728 | C33: 80412941
A34: Sierra Leona | B34: 55232.89 | C34: 94854.43
A35: Tanzania | B35: 2884267.1 | C35: 12490658
A36: Togo | B36: 154882.74 | C36: 684744.63
A37: Túnez | B37: 40023941 | C37: 91333403
A38: Uganda | B38: 5434287.6 | C38: 22885797
... A43: Sudáfrica | B43: 1.8859334e+08 | C43: 3.984647e+08
A44: Etiopía | B44: - | C44: -
A46: AMERICA | B46: 2.9065513e+09 | C46: 4.3707688e+09
A47: Bolivia | B47: 65764394 | C47: 96164259
A48: Brasil | B48: 9.094667e+08 | C48: 1.2344036e+09
A49: Canadá | B49: 2814811 | C49: 2087245.9
...

Sheet Ene-Oct 2021_Destino
A1: Evolución de las exportaciones con origen en la provincia de Santa Fe, según destino. Período enero - octubre 2021
B4: Enero - octubre 2021
A5: País de destino | B5: Valor F.O.B. | C5: Peso Neto
B6: (en Dólares) | C6: (en Kilos)
A8: TOTAL | B8: 1.5404416e+10 | C8: 2.7486923e+10
A10: AFRICA | B10: 1.3986577e+09 | C10: 3.0558057e+09
A11: Burkina Faso | B11: 21586.18 | C11: 36133.9
A12: Argelia | B12: 3.7989141e+08 | C12: 7.7763116e+08
A13: Camerún | B13: 4992764.7 | C13: 11762863
A14: Congo | B14: 3025688.9 | C14: 8279912.7
A15: Rep. Democrática del Congo (ex Zaire) | B15: - | C15: -
A16: Costa de Marfil | B16: 29636422 | C16: 79940580
A17: Benin | B17: 152551.48 | C17: 253466.95
A18: Egipto | B18: 3.380791e+08 | C18: 7.3392756e+08
A19: Gabón | B19: 27248.48 | C19: 45691.14
A20: Gambia | B20: 1957622 | C20: 7991363.2
A21: Ghana | B21: 25187376 | C21: 65387387
A22: Guinea | B22: 2577063.5 | C22: 11477552
A23: Guinea Ecuatorial | B23: - | C23: -
A24: Kenya | B24: 8350040.1 | C24: 33777283
A25: Liberia | B25: 288935.12 | C25: 1126695.7
A26: Libia | B26: 876421.47 | C26: 3026794
A27: Madagascar | B27: - | C27: -
A28: Malawi | B28: - | C28: -
A29: Mali | B29: 735348.19 | C29: 3173008.6
A30: Marruecos | B30: 1.5489527e+08 | C30: 4.1702375e+08
A31: Mauricio | B31: 16867903 | C31: 39071188
A32: Mauritania | B32: 3965638.3 | C32: 16371098
A33: Níger | B33: 35469.13 | C33: 60792.05
A34: Nigeria | B34: 37262293 | C34: 69460203
A35: Senegal | B35: 27157862 | C35: 85779040
A36: Sierra Leona | B36: 58767.42 | C36: 100974.83
A37: Tanzania | B37: 2891862.1 | C37: 12502898
A38: Togo | B38: 154882.74 | C38: 684744.63
A39: Túnez | B39: 40034488 | C39: 91351411
A40: Uganda | B40: 6039108.5 | C40: 24995597
... A45: Sudáfrica | B45: 2.0915407e+08 | C45: 4.4208252e+08
A46: Etiopía | B46: - | C46: -
A47: Sudán | B47: 1185986.2 | C47: 120980.25
A49: AMERICA | B49: 3.2573587e+09 | C49: 4.8795932e+09
...

Sheet Ene-Nov 2021_Destino
A1: Evolución de las exportaciones con origen en la provincia de Santa Fe, según destino. Período enero - noviembre 2021
B4: Enero - noviembre 2021
A5: País de destino | B5: Valor F.O.B. | C5: Peso Neto
B6: (en Dólares) | C6: (en Kilos)
A8: TOTAL | B8: 1.6751806e+10 | C8: 2.9695883e+10
A10: AFRICA | B10: 1.59194e+09 | C10: 3.4050647e+09
A11: Burkina Faso | B11: 102223.91 | C11: 349774.7
A12: Argelia | B12: 4.2902629e+08 | C12: 8.2593821e+08
A13: Camerún | B13: 5662880.4 | C13: 14110282
A14: Congo | B14: 4028934.6 | C14: 11519369
A15: Rep. Democrática del Congo (ex Zaire) | B15: - | C15: -
A16: Costa de Marfil | B16: 38382285 | C16: 1.0415033e+08
A17: Benin | B17: 156284.92 | C17: 259587.35
A18: Egipto | B18: 4.0742127e+08 | C18: 8.4531101e+08
A19: Gabón | B19: 31032.53 | C19: 51811.54
A20: Gambia | B20: 1960969.5 | C20: 8001304
A21: Ghana | B21: 25655701 | C21: 67439076
A22: Guinea | B22: 2580918.9 | C22: 11483673
A23: Guinea Ecuatorial | B23: - | C23: -
A24: Kenya | B24: 12152532 | C24: 47813499
A25: Liberia | B25: 580916.37 | C25: 2068570.7
A26: Libia | B26: 905275.56 | C26: 3069445.3
A27: Madagascar | B27: - | C27: -
A28: Malawi | B28: - | C28: -
A29: Mali | B29: 1188991.1 | C29: 5047565.9
A30: Marruecos | B30: 1.6253105e+08 | C30: 4.4371435e+08
A31: Mauricio | B31: 20893483 | C31: 42196158
A32: Mauritania | B32: 5002678.8 | C32: 20491989
A33: Níger | B33: 39171.97 | C33: 66912.45
A34: Nigeria | B34: 39483881 | C34: 77558780
A35: Rwanda | B35: 1011950.5 | C35: 4219600
A36: Senegal | B36: 31227337 | C36: 98579443
A37: Sierra Leona | B37: 58767.42 | C37: 100974.83
A38: Tanzania | B38: 3997906.7 | C38: 16990744
A39: Togo | B39: 154882.74 | C39: 684744.63
A40: Túnez | B40: 48585420 | C40: 1.1254571e+08
... A46: Sudáfrica | B46: 2.2917027e+08 | C46: 4.8441256e+08
A47: Etiopía | B47: - | C47: -
A48: Sudán | B48: 1185986.2 | C48: 120980.25
A50: AMERICA | B50: 3598655563 | C50: 5.3366569e+09
...

Sheet Ene-Dic 2021_Destino
A1: Evolución de las exportaciones con origen en la provincia de Santa Fe, según destino. Período enero - diciembre 2021
B4: Enero - diciembre 2021
A5: País de destino | B5: Valor F.O.B. | C5: Peso Neto
B6: (en Dólares) | C6: (en Kilos)
A8: TOTAL | B8: 17920340707 | C8: 31828253608
A10: AFRICA | B10: 1720665398 | C10: 3725660852
A11: Burkina Faso | B11: 102224 | C11: 349775
A12: Argelia | B12: 453526780 | C12: 865103592
A13: Burundi | B13: 295071 | C13: 1175460
A14: Camerún | B14: 6067502 | C14: 14246651
A15: Congo | B15: 5175469 | C15: 15241637
A16: Rep. Democrática del Congo (ex Zaire) | B16: - | C16: -
A17: Costa de Marfil | B17: 40163416 | C17: 109521817
A18: Benin | B18: 168087 | C18: 280185
A19: Egipto | B19: 407588137 | C19: 845564195
A20: Gabón | B20: 42428 | C20: 70173
A21: Gambia | B21: 1948075 | C21: 7968785
A22: Ghana | B22: 25783529 | C22: 67596153
A23: Guinea | B23: 2599797 | C23: 11513877
A24: Guinea Ecuatorial | B24: - | C24: -
A25: Kenya | B25: 20384761 | C25: 77224803
A26: Liberia | B26: 580687 | C26: 2067808
A27: Libia | B27: 56825741 | C27: 130617387
A28: Madagascar | B28: - | C28: -
A29: Malawi | B29: - | C29: -
A30: Mali | B30: 1797707 | C30: 7313391
A31: Marruecos | B31: 175143996 | C31: 489320145
A32: Mauricio | B32: 24715131 | C32: 51365531
A33: Mauritania | B33: 8624364 | C33: 33498401
A34: Níger | B34: 39172 | C34: 66912
A35: Nigeria | B35: 40206135 | C35: 80350802
A36: Rwanda | B36: 1228959 | C36: 4973100
A37: Senegal | B37: 31951692 | C37: 100187595
A38: Sierra Leona | B38: 58767 | C38: 100975
A39: Tanzania | B39: 5254086 | C39: 21475716
A40: Togo | B40: 154883 | C40: 684744
A41: Túnez | B41: 49078528 | C41: 112670615
... A47: Sudáfrica | B47: 231934443 | C47: 491775475
A48: Etiopía | B48: - | C48: -
A49: Sudán | B49: 1185988 | C49: 120982
...
