Workbook

Sheet TCRB
A1: mes | B1: Afghanistan, Islamic Republic of | C1: Albania | D1: Algeria | E1: Angola | F1: Antigua and Barbuda | G1: Armenia, Republic of | H1: Aruba, Kingdom of the Netherlands | I1: Austria | J1: Azerbaijan, Republic of | K1: Bahamas, The | L1: Bahrain, Kingdom of | M1: Bangladesh | N1: Barbados | O1: Belarus, Republic of | P1: Belgium | Q1: Belize | R1: Benin | S1: Bolivia | T1: Bosnia and Herzegovina | U1: Botswana | V1: Brazil | W1: Brunei Darussalam | X1: Bulgaria | Y1: Burkina Faso | Z1: Burundi | AA1: Cabo Verde | AB1: Cambodia | AC1: Cameroon | AD1: Canada | AE1: Central African Republic | AF1: Chad | AG1: Chile | AH1: China, People's Republic of | AI1: Colombia | AJ1: Comoros, Union of the | AK1: Congo, Democratic Republic of the | AL1: Congo, Republic of | AM1: Costa Rica | AN1: Croatia, Republic of | AO1: Curaçao, Kingdom of the Netherlands | AP1: Czech Republic | AQ1: Côte d'Ivoire | AR1: Denmark | AS1: Djibouti | AT1: Dominica | AU1: Dominican Republic | AV1: Ecuador | AW1: Egypt, Arab Republic of | AX1: El Salvador | AY1: Equatorial Guinea, Republic of | AZ1: Estonia, Republic of | BA1: Ethiopia, The Federal Democratic Republic of | BB1: Fiji, Republic of | BC1: Finland | BD1: France | BE1: Gabon | BF1: Gambia, The | BG1: Georgia | BH1: Germany | BI1: Ghana | BJ1: Greece | BK1: Grenada | BL1: Guatemala | BM1: Guinea | BN1: Guinea-Bissau | BO1: Guyana | BP1: Haiti | BQ1: Honduras | BR1: Hong Kong Special Administrative Region, People's Republic of China | BS1: Hungary | BT1: Iceland | BU1: India | BV1: Indonesia | BW1: Iran, Islamic Republic of | BX1: Iraq | BY1: Ireland | BZ1: Israel | CA1: Italy | CB1: Jamaica | CC1: Japan | CD1: Jordan | CE1: Kazakhstan, Republic of | CF1: Kenya | CG1: Korea, Republic of | CH1: Kuwait | CI1: Latvia, Republic of | CJ1: Lebanon | CK1: Lesotho, Kingdom of | CL1: Liberia | CM1: Libya | CN1: Lithuania, Republic of | CO1: Luxembourg | CP1: Macao Special Administrative Region, People's Republic of China | CQ1: Madagascar, Republic of | CR1: Malawi | CS1: Malaysia | CT1: Maldives | CU1: Mali | CV1: Malta | CW1: Mauritania, Islamic Republic of | CX1: Mauritius | CY1: Mexico | CZ1: Moldova, Republic of | DA1: Mongolia | DB1: Montenegro | DC1: Morocco | DD1: Mozambique, Republic of | DE1: Myanmar | DF1: Namibia | DG1: Nepal | DH1: Netherlands, The | DI1: Nicaragua | DJ1: Niger | DK1: Nigeria | DL1: North Macedonia, Republic of | DM1: Norway | DN1: Oman | DO1: Pakistan | DP1: Panama | DQ1: Paraguay | DR1: Peru | DS1: Philippines | DT1: Poland, Republic of | DU1: Portugal | DV1: Qatar | DW1: Romania | DX1: Russian Federation | DY1: Rwanda | DZ1: Saudi Arabia | EA1: Senegal | EB1: Serbia, Republic of | EC1: Seychelles | ED1: Sierra Leone | EE1: Singapore | EF1: Slovak Republic | EG1: Slovenia, Republic of | EH1: South Africa | EI1: South Sudan, Republic of | EJ1: Spain | EK1: Sri Lanka | EL1: St. Kitts and Nevis | EM1: St. Lucia | EN1: St. Vincent and the Grenadines | EO1: Sudan | EP1: Suriname | EQ1: Sweden | ER1: Switzerland | ES1: Syrian Arab Republic | ET1: São Tomé and Príncipe, Democratic Republic of | EU1: Tanzania, United Republic of | EV1: Thailand | EW1: Togo | EX1: Trinidad and Tobago | EY1: Tunisia | EZ1: Türkiye, Republic of | FA1: Uganda | FB1: Ukraine | FC1: United Arab Emirates | FD1: United Kingdom | FE1: United States | FF1: Uruguay | FG1: Uzbekistan, Republic of | FH1: Vietnam | FI1: Zambia | FJ1: Zimbabwe
A2: 36892 | F2: 1.3747147 | H2: 1.9220818 | I2: 3.399199 | P2: 3.6984288 | V2: 44.862773 | X2: 90.820429 | Z2: 0.0017642173 | AB2: 0.001084742 | AD2: 3.316605 | AG2: 0.0039876402 | AH2: 0.40249633 | AI2: 0.00100983 | AM2: 0.0049040706 | AP2: 0.10319249 | AQ2: 0.0042678961 | AR2: 0.49941946 | AT2: 1.5521543 | AU2: 0.078833519 | AV2: 2.5609397 | AZ2: 5.8580315 | BA2: 0.099727094 | BC2: 3.8778119 | BD2: 3.8922393 | BH2: 3.7136869 | BI2: 0.55506871 | BJ2: 3.5158861 | BK2: 1.5064825 | BP2: 0.045362444 | BQ2: 0.37961259 | BS2: 0.01355492 | BT2: 0.043755297 | BU2: 0.051151907 | BV2: 0.00015581938 | BY2: 3.0601657 | BZ2: 0.82574257 | CA2: 3.7040202 | CB2: 0.02431832 | CC2: 0.042954542 | CG2: 0.0026276258 | CI2: 2.7036331 | CN2: 3.3585659 | CO2: 3.5744256 | CP2: 0.36486378 | CQ2: 0.0010918247 | CS2: 1.1103922 | CT2: 0.21449788 | CX2: 0.06624388 | CY2: 0.25738853 | CZ2: 0.059336283 | DH2: 3.7066864 | DM2: 0.45350757 | DN2: 8.8429353 | DT2: 1.1266777 | DU2: 3.6706931 | DW2: 0.6626247 | DX2: 0.062848489 | DZ2: 0.78649053 | EA2: 0.004556587 | EF2: 4.9460973 | EG2: 3.175772 | EH2: 0.20229579 | EJ2: 3.2940056 | EM2: 1.4249169 | EN2: 1.4538794 | EO2: 1.0132971 | EQ2: 1.4310903 | ER2: 2.9778554 | EW2: 0.0040320954 | EX2: 0.33038345 | EZ2: 3.3356465 | FD2: 5.6245869 | FE2: 4.1570974
A3: 36923 | F3: 1.3765299 | H3: 1.9291072 | I3: 3.3597675 | P3: 3.6569435 | Q3: 1.9254447 | V3: 44.100615 | X3: 89.709771 | Z3: 0.0019341892 | AB3: 0.0011003539 | AD3: 3.3002643 | AG3: 0.004040744 | AH3: 0.4038211 | AI3: 0.0010303723 | AM3: 0.004945846 | AP3: 0.10307481 | AQ3: 0.0042246807 | AR3: 0.49545203 | AT3: 1.5579373 | AU3: 0.078921519 | AV3: 2.6413875 | AZ3: 5.7864544 | BA3: 0.099192178 | BC3: 3.8412292 | BD3: 3.8424926 | BH3: 3.677342 | BI3: 0.56821145 | BJ3: 3.4580148 | BK3: 1.5069481 | BP3: 0.045771212 | BQ3: 0.38404671 | BS3: 0.01348741 | BT3: 0.043453384 | BU3: 0.051058345 | BV3: 0.00015446523 | BY3: 3.0414752 | BZ3: 0.82697542 | CA3: 3.6593958 | CB3: 0.024552502 | CC3: 0.043310708 | CG3: 0.0026893672 | CI3: 2.656434 | CN3: 3.3118939 | CO3: 3.5637864 | CP3: 0.36276839 | CQ3: 0.0011044196 | CS3: 1.1150594 | CT3: 0.21969247 | CX3: 0.066275638 | CY3: 0.25958057 | CZ3: 0.059621059 | DH3: 3.6813327 | DM3: 0.45096112 | DN3: 8.8269955 | DT3: 1.1366 | DU3: 3.6183034 | DW3: 0.66444297 | DX3: 0.063894831 | DZ3: 0.78663317 | EA3: 0.0044804375 | EF3: 4.983744 | EG3: 3.1624647 | EH3: 0.20248634 | EJ3: 3.2536477 | EM3: 1.4297318 | EN3: 1.4466194 | EO3: 0.98618431 | EQ3: 1.3997323 | ER3: 2.9149603 | EW3: 0.0040188988 | EX3: 0.33276503 | EZ3: 3.0095251 | FD3: 5.5589957 | FE3: 4.1829921
A4: 36951 | F4: 1.3759556 | H4: 1.928102 | I4: 3.315511 | P4: 3.6097032 | V4: 42.338443 | X4: 88.375099 | Z4: 0.0019258023 | AB4: 0.0011123802 | AD4: 3.2263751 | AG4: 0.0038821978 | AH4: 0.40060651 | AI4: 0.0010273506 | AM4: 0.0049942015 | AP4: 0.10191874 | AQ4: 0.0041845567 | AR4: 0.49028792 | AT4: 1.5614737 | AU4: 0.078437205 | AV4: 2.6941735 | AZ4: 5.7225853 | BA4: 0.096531799 | BC4: 3.8036955 | BD4: 3.801398 | BH4: 3.6217865 | BI4: 0.58160406 | BJ4: 3.4725467 | BK4: 1.5013761 | BP4: 0.045514426 | BQ4: 0.38532991 | BS4: 0.013378437 | BT4: 0.042602832 | BU4: 0.051079029 | BV4: 0.00014783032 | BY4: 3.0190759 | BZ4: 0.81819164 | CA4: 3.6072451 | CB4: 0.024644132 | CC4: 0.041328279 | CG4: 0.0026321058 | CI4: 2.6290023 | CN4: 3.279616 | CO4: 3.5196598 | CP4: 0.36111102 | CQ4: 0.0010862471 | CS4: 1.1107281 | CT4: 0.21780497 | CX4: 0.065595597 | CY4: 0.26302357 | CZ4: 0.058859623 | DH4: 3.6596286 | DM4: 0.44836288 | DN4: 8.7923233 | DT4: 1.1475236 | DU4: 3.5792769 | DW4: 0.664691 | DX4: 0.064771245 | DZ4: 0.78512621 | EA4: 0.0044048058 | EF4: 4.9470266 | EG4: 3.1481284 | EH4: 0.20182689 | EJ4: 3.2179957 | EM4: 1.4319277 | EN4: 1.4432664 | EO4: 1.006078 | EQ4: 1.3681715 | ER4: 2.8770368 | EW4: 0.0040124936 | EX4: 0.3311719 | EZ4: 2.525994 | FD4: 5.5297998 | FE4: 4.1844781
A5: 36982 | F5: 1.3642643 | H5: 1.9196095 | I5: 3.2459733 | P5: 3.5470419 | V5: 40.306559 | X5: 86.009251 | Z5: 0.0018454709 | AB5: 0.0010757675 | AD5: 3.2302561 | AG5: 0.0038039844 | AH5: 0.39877484 | AI5: 0.0010125264 | AM5: 0.0049989266 | AP5: 0.099502683 | AQ5: 0.0040929122 | AR5: 0.48001059 | AT5: 1.5446736 | AU5: 0.078401834 | AV5: 2.7224454 | AZ5: 5.6119434 | BA5: 0.094497237 | BC5: 3.7228196 | BD5: 3.7214114 | BH5: 3.544771 | BI5: 0.58546061 | BJ5: 3.4149644 | BK5: 1.4924038 | BP5: 0.045957424 | BQ5: 0.38362655 | BS5: 0.013110531 | BT5: 0.040358693 | BU5: 0.050902745 | BV5: 0.00013430874 | BY5: 2.9642808 | BZ5: 0.81918714 | CA5: 3.5296288 | CB5: 0.024600241 | CC5: 0.040240448 | CG5: 0.0025512649 | CI5: 2.5702682 | CN5: 3.2014233 | CO5: 3.4397561 | CP5: 0.35911702 | CQ5: 0.0010391229 | CS5: 1.1044759 | CT5: 0.22094912 | CX5: 0.065101446 | CY5: 0.27010393 | CZ5: 0.059035542 | DH5: 3.5851279 | DM5: 0.44121586 | DN5: 8.734201 | DT5: 1.1616705 | DU5: 3.5067993 | DW5: 0.66374429 | DX5: 0.065109976 | DZ5: 0.77993607 | EA5: 0.0042825443 | EF5: 4.8415654 | EG5: 3.0872572 | EH5: 0.19637845 | EJ5: 3.151416 | EM5: 1.4396196 | EN5: 1.4379152 | EO5: 0.99423289 | EQ5: 1.3462022 | ER5: 2.822305 | EW5: 0.0039575462 | EX5: 0.33050754 | EZ5: 2.2039668 | FD5: 5.4912927 | FE5: 4.1733303
A6: 37012 | F6: 1.386244 | H6: 1.9246317 | I6: 3.1853599 | P6: 3.4960494 | Q6: 1.9193548 | V6: 38.60204 | X6: 84.390792 | Z6: 0.0017120376 | AB6: 0.0010745717 | AD6: 3.2885712 | AG6: 0.0037812644 | AH6: 0.39653551 | AI6: 0.0010059249 | AM6: 0.005005637 | AP6: 0.098712352 | AQ6: 0.0040575602 | AR6: 0.47279464 | AT6: 1.549295 | AU6: 0.078559794 | AV6: 2.7252493 | AZ6: 5.532378 | BA6: 0.09378317 | BC6: 3.6703692 | BD6: 3.667279 | BH6: 3.4837344 | BI6: 0.59400669 | BJ6: 3.3588038 | BK6: 1.4924595 | BP6: 0.046142146 | BQ6: 0.38654068 | BS6: 0.013383722 | BT6: 0.037937872 | BU6: 0.051069545 | BV6: 0.0001351652 | BY6: 2.9212394 | BZ6: 0.82829788 | CA6: 3.4659445 | CB6: 0.024754872 | CC6: 0.040883556 | CG6: 0.0026004337 | CI6: 2.5441051 | CN6: 3.1536083 | CO6: 3.3877955 | CP6: 0.35838043 | CQ6: 0.001025359 | CS6: 1.1049022 | CT6: 0.22689901 | CX6: 0.064501418 | CY6: 0.27659844 | CZ6: 0.058548446 | DH6: 3.5230147 | DM6: 0.44080798 | DN6: 8.7201381 | DT6: 1.1851263 | DU6: 3.4633315 | DW6: 0.66039528 | DX6: 0.065836808 | DZ6: 0.77787686 | EA6: 0.0041819703 | EF6: 4.7572429 | EG6: 3.0587624 | EH6: 0.1997078 | EJ6: 3.0982189 | EM6: 1.4354888 | EN6: 1.4327201 | EO6: 1.02929 | EQ6: 1.3394212 | ER6: 2.772857 | EW6: 0.003920733 | EX6: 0.33153039 | EZ6: 2.4601794 | FD6: 5.4880259 | FE6: 4.1896856
A7: 37043 | F7: 1.374993 | H7: 1.9423067 | I7: 3.1375158 | P7: 3.4430315 | V7: 37.79118 | X7: 82.764298 | Z7: 0.0015978629 | AB7: 0.0010817552 | AD7: 3.3529109 | AG7: 0.0037391388 | AH7: 0.39463118 | AI7: 0.0010318339 | AM7: 0.0050290917 | AP7: 0.099203133 | AQ7: 0.0040132094 | AR7: 0.46489363 | AT7: 1.5639579 | AU7: 0.078683716 | AV7: 2.7581674 | AZ7: 5.4519452 | BA7: 0.093847942 | BC7: 3.6078645 | BD7: 3.6073851 | BH7: 3.4286488 | BI7: 0.60157718 | BJ7: 3.2983999 | BK7: 1.5057874 | BP7: 0.045984379 | BQ7: 0.39023043 | BS7: 0.0137995 | BT7: 0.037360723 | BU7: 0.052027064 | BV7: 0.00013740197 | BY7: 2.8894426 | BZ7: 0.83218934 | CA7: 3.4160704 | CB7: 0.025266524 | CC7: 0.040980122 | CG7: 0.0026362495 | CI7: 2.5129358 | CN7: 3.1172711 | CO7: 3.3404479 | CP7: 0.36156675 | CQ7: 0.0010171317 | CS7: 1.1118257 | CT7: 0.23656448 | CX7: 0.064650536 | CY7: 0.28083122 | CZ7: 0.05921582 | DH7: 3.4501005 | DM7: 0.4366126 | DN7: 8.836729 | DT7: 1.1956393 | DU7: 3.4135627 | DW7: 0.66501778 | DX7: 0.067166602 | DZ7: 0.78352388 | EA7: 0.0041725212 | EF7: 4.6887435 | EG7: 3.0188931 | EH7: 0.2000824 | EJ7: 3.0560154 | EM7: 1.4623592 | EN7: 1.4320681 | EO7: 1.0791816 | EQ7: 1.2884891 | ER7: 2.7501738 | EW7: 0.0038711841 | EX7: 0.33970686 | EZ7: 2.38618 | FD7: 5.4414868 | FE7: 4.2272253
A8: 37073 | F8: 1.3837204 | H8: 1.9521927 | I8: 3.1784171 | P8: 3.4818461 | V8: 37.012083 | X8: 83.586686 | Z8: 0.0017162246 | AB8: 0.0010980537 | AD8: 3.3404543 | AG8: 0.0035136435 | AH8: 0.39393615 | AI8: 0.0010368954 | AM8: 0.0050462491 | AP8: 0.10169919 | AQ8: 0.0040481981 | AR8: 0.46869092 | AT8: 1.5688645 | AU8: 0.078751254 | AV8: 2.7738238 | AZ8: 5.5400119 | BA8: 0.092232744 | BC8: 3.624105 | BD8: 3.6432621 | BH8: 3.47393 | BI8: 0.60867306 | BJ8: 3.2798659 | BK8: 1.514125 | BP8: 0.045653651 | BQ8: 0.3921448 | BS8: 0.013854462 | BT8: 0.039303582 | BU8: 0.052727546 | BV8: 0.00014872818 | BY8: 2.9153251 | BZ8: 0.83163503 | CA8: 3.4602181 | CB8: 0.025683136 | CC8: 0.040166765 | CG8: 0.0026320016 | CI8: 2.5324132 | CN8: 3.1296104 | CO8: 3.3475135 | CP8: 0.36233555 | CQ8: 0.0010491683 | CS8: 1.1154245 | CT8: 0.21441461 | CX8: 0.065116989 | CY8: 0.27915754 | CZ8: 0.058492628 | DH8: 3.4867646 | DM8: 0.4340792 | DN8: 8.8564227 | DT8: 1.1345676 | DU8: 3.458595 | DW8: 0.6664788 | DX8: 0.067448854 | DZ8: 0.78445254 | EA8: 0.0042770509 | EF8: 4.7483044 | EG8: 3.0619856 | EH8: 0.19816734 | EJ8: 3.1004393 | EM8: 1.4662676 | EN8: 1.4534824 | EO8: 1.1278593 | EQ8: 1.2880758 | ER8: 2.7935764 | EW8: 0.0039879938 | EX8: 0.345178 | EZ8: 2.2501001 | FD8: 5.4720023 | FE8: 4.2289958
A9: 37104 | F9: 1.3907134 | H9: 1.9607307 | I9: 3.3308032 | P9: 3.6554088 | Q9: 1.9401436 | V9: 36.738726 | X9: 88.032131 | Z9: 0.0016885773 | AB9: 0.0011038836 | AD9: 3.3310065 | AG9: 0.003463476 | AH9: 0.39572729 | AI9: 0.0010502743 | AM9: 0.0050735828 | AP9: 0.10587106 | AQ9: 0.0042483273 | AR9: 0.49250597 | AT9: 1.5766271 | AU9: 0.07961463 | AV9: 2.7957771 | AZ9: 5.8122221 | BA9: 0.092117866 | BC9: 3.8171355 | BD9: 3.8253623 | BH9: 3.6392576 | BI9: 0.60219729 | BJ9: 3.4446519 | BK9: 1.518346 | BP9: 0.04493205 | BQ9: 0.39536409 | BS9: 0.014385461 | BT9: 0.040320088 | BU9: 0.053275276 | BV9: 0.00018064898 | BY9: 3.0704307 | BZ9: 0.83009362 | CA9: 3.6331693 | CB9: 0.026014599 | CC9: 0.041486186 | CG9: 0.0026869799 | CI9: 2.6415286 | CN9: 3.3063938 | CO9: 3.5554949 | CP9: 0.36155068 | CQ9: 0.0010998181 | CS9: 1.1182826 | CT9: 0.20664499 | CX9: 0.065099023 | CY9: 0.2827325 | CZ9: 0.058478113 | DH9: 3.6746577 | DM9: 0.45045628 | DN9: 8.8431813 | DT9: 1.1193258 | DU9: 3.6244698 | DW9: 0.67355387 | DX9: 0.067400229 | DZ9: 0.78643316 | EA9: 0.0045648447 | EF9: 4.9792292 | EG9: 3.2136236 | EH9: 0.19458427 | EJ9: 3.2632829 | EM9: 1.4623684 | EN9: 1.4530825 | EO9: 1.1517355 | EQ9: 1.3488666 | ER9: 2.9184306 | EW9: 0.0041675504 | EX9: 0.3505748 | EZ9: 2.1943177 | FD9: 5.6036343 | FE9: 4.2440211
A10: 37135 | F10: 1.3903196 | H10: 1.9674839 | I10: 3.3826389 | P10: 3.7119535 | V10: 34.648426 | X10: 90.524683 | Z10: 0.0017350222 | AB10: 0.0011160918 | AD10: 3.2818509 | AG10: 0.0034530621 | AH10: 0.39962109 | AI10: 0.0010371258 | AM10: 0.0050759411 | AP10: 0.10586198 | AQ10: 0.0042775205 | AR10: 0.5006872 | AT10: 1.5666444 | AU10: 0.080404366 | AV10: 2.8552099 | AZ10: 5.8902541 | BA10: 0.093420195 | BC10: 3.8930981 | BD10: 3.8807219 | BH10: 3.6851398 | BI10: 0.59566217 | BJ10: 3.5547046 | BK10: 1.5218991 | BP10: 0.044472599 | BQ10: 0.39693405 | BS10: 0.014376639 | BT10: 0.040057276 | BU10: 0.052623885 | BV10: 0.00017259738 | BY10: 3.1234035 | BZ10: 0.8160387 | CA10: 3.6789747 | CB10: 0.026094542 | CC10: 0.042352294 | CG10: 0.0026693491 | CI10: 2.6925136 | CN10: 3.3418801 | CO10: 3.6045697 | CP10: 0.36021626 | CQ10: 0.0011242624 | CS10: 1.1202974 | CT10: 0.21174066 | CX10: 0.064792554 | CY10: 0.27774435 | CZ10: 0.059140957 | DH10: 3.7666249 | DM10: 0.46174354 | DN10: 8.8682663 | DT10: 1.130718 | DU10: 3.6688819 | DW10: 0.67752452 | DX10: 0.067666956 | DZ10: 0.78707234 | EA10: 0.0046237472 | EF10: 5.0517367 | EG10: 3.2826638 | EH10: 0.1879975 | EJ10: 3.3039904 | EM10: 1.4660432 | EN10: 1.464961 | EO10: 1.0849695 | EQ10: 1.3256993 | ER10: 3.0035676 | EW10: 0.0040925109 | EX10: 0.34983251 | EZ10: 2.2112788 | FD10: 5.7237682 | FE10: 4.266614
A11: 37165 | F11: 1.3985075 | H11: 1.9820896 | I11: 3.3812559 | P11: 3.7011432 | V11: 34.211739 | X11: 91.712254 | Z11: 0.0017138321 | AB11: 0.0011064945 | AD11: 3.2722335 | AG11: 0.0033411822 | AH11: 0.40257867 | AI11: 0.0010471281 | AM11: 0.005063407 | AP11: 0.10790662 | AQ11: 0.0042799283 | AR11: 0.501233 | AT11: 1.582475 | AU11: 0.080959441 | AV11: 2.9013928 | AZ11: 5.88214 | BA11: 0.093166733 | BC11: 3.8790947 | BD11: 3.8777498 | BH11: 3.6758623 | BI11: 0.6147074 | BJ11: 3.5610533 | BK11: 1.5262476 | BP11: 0.043770036 | BQ11: 0.39669647 | BS11: 0.014446177 | BT11: 0.039514505 | BU11: 0.052780908 | BV11: 0.00016056896 | BY11: 3.1285959 | BZ11: 0.82108193 | CA11: 3.6802248 | CB11: 0.026073693 | CC11: 0.041729286 | CG11: 0.0026627432 | CI11: 2.6923362 | CN11: 3.3471893 | CO11: 3.6058045 | CP11: 0.36003096 | CQ11: 0.0011390407 | CS11: 1.1241022 | CT11: 0.21249471 | CX11: 0.064586066 | CY11: 0.28069046 | CZ11: 0.06020963 | DH11: 3.7576383 | DM11: 0.46124128 | DN11: 8.9071781 | DT11: 1.1634994 | DU11: 3.6780229 | DW11: 0.68468257 | DX11: 0.068459025 | DZ11: 0.79133652 | EA11: 0.0046767015 | EF11: 5.0480203 | EG11: 3.2933338 | EH11: 0.1756575 | EJ11: 3.2959881 | EM11: 1.4624873 | EN11: 1.4582895 | EO11: 1.0467466 | EQ11: 1.3358376 | ER11: 3.0174468 | EW11: 0.0040485932 | EX11: 0.35103985 | EZ11: 2.1643321 | FD11: 5.6970556 | FE11: 4.2709142
A12: 37196 | F12: 1.4067192 | H12: 1.9900516 | I12: 3.323364 | P12: 3.6455068 | Q12: 1.9638076 | V12: 37.247688 | X12: 90.426323 | Z12: 0.0016989558 | AB12: 0.0011101818 | AD12: 3.2094343 | AG12: 0.0034427403 | AH12: 0.40308631 | AI12: 0.0010562992 | AM12: 0.0050864744 | AP12: 0.10691391 | AQ12: 0.0042149526 | AR12: 0.4912064 | AT12: 1.5813533 | AU12: 0.080664404 | AV12: 2.9574313 | AZ12: 5.7870376 | BA12: 0.093993694 | BC12: 3.7993766 | BD12: 3.8047787 | BH12: 3.6081647 | BI12: 0.61151735 | BJ12: 3.5071998 | BK12: 1.5330002 | BP12: 0.042752433 | BQ12: 0.39721965 | BS12: 0.014428638 | BT12: 0.037915524 | BU12: 0.053432165 | BV12: 0.00015673102 | BY12: 3.0780127 | BZ12: 0.83356025 | CA12: 3.6269387 | CB12: 0.025698345 | CC12: 0.041303376 | CG12: 0.002694686 | CI12: 2.6548869 | CN12: 3.2918109 | CO12: 3.5526432 | CP12: 0.35998034 | CQ12: 0.0011325089 | CS12: 1.1367 | CT12: 0.2142016 | CX12: 0.064441022 | CY12: 0.28715196 | CZ12: 0.060992609 | DH12: 3.6922141 | DM12: 0.45805175 | DN12: 8.9363581 | DT12: 1.1795113 | DU12: 3.6426109 | DW12: 0.69415696 | DX12: 0.069007091 | DZ12: 0.79311558 | EA12: 0.0045516853 | EF12: 4.9632138 | EG12: 3.2536323 | EH12: 0.1683729 | EJ12: 3.2402768 | EM12: 1.4873209 | EN12: 1.4666109 | EO12: 1.0600488 | EQ12: 1.3358774 | ER12: 2.9983865 | EW12: 0.0040232693 | EX12: 0.34769809 | EZ12: 2.3870429 | FD12: 5.6568535 | FE12: 4.2776718
A13: 37226 | F13: 1.4084312 | H13: 1.99915 | I13: 3.3477834 | P13: 3.6572 | V13: 40.385845 | X13: 91.489775 | Z13: 0.0016975822 | AB13: 0.0011081314 | AD13: 3.2491893 | AG13: 0.0035389243 | AH13: 0.40382066 | AI13: 0.0010624629 | AM13: 0.0051075351 | AP13: 0.10993529 | AQ13: 0.0042490355 | AR13: 0.49587318 | AT13: 1.5878561 | AU13: 0.079902765 | AV13: 2.9797335 | AZ13: 5.8276646 | BA13: 0.092444941 | BC13: 3.8183967 | BD13: 3.8300107 | BH13: 3.6608826 | BI13: 0.60979211 | BJ13: 3.5593361 | BK13: 1.5344517 | BP13: 0.043538399 | BQ13: 0.3969157 | BS13: 0.014760542 | BT13: 0.039050356 | BU13: 0.053225116 | BV13: 0.00016004712 | BY13: 3.1087139 | BZ13: 0.8258326 | CA13: 3.6496395 | CB13: 0.0258237 | CC13: 0.039657438 | CG13: 0.0026902 | CI13: 2.6796959 | CN13: 3.3209189 | CO13: 3.5650393 | CP13: 0.35912762 | CQ13: 0.0011380604 | CS13: 1.1387471 | CT13: 0.21821823 | CX13: 0.064796334 | CY13: 0.28951508 | CZ13: 0.061155018 | DH13: 3.7008723 | DM13: 0.45776111 | DN13: 8.9601004 | DT13: 1.2062388 | DU13: 3.6694564 | DW13: 0.70389865 | DX13: 0.06947845 | DZ13: 0.79539383 | EA13: 0.0045617479 | EF13: 5.0028223 | EG13: 3.2744807 | EH13: 0.14255097 | EJ13: 3.2695814 | EM13: 1.4835253 | EN13: 1.4573202 | EO13: 1.0813668 | EQ13: 1.3439846 | ER13: 2.9985372 | EW13: 0.0040806155 | EX13: 0.34858337 | EZ13: 2.5824575 | FD13: 5.6799816 | FE13: 4.2642851 | FH13: 0.00010297255
A14: 37257 | E14: 0.0046947696 | F14: 1.95723 | H14: 2.7437451 | I14: 4.550538 | P14: 4.9866368 | V14: 55.231546 | X14: 127.30626 | Z14: 0.0022788648 | AB14: 0.0015135172 | AD14: 4.3945997 | AG14: 0.004855328 | AH14: 0.55461413 | AI14: 0.0014869453 | AM14: 0.007022199 | AP14: 0.15373165 | AQ14: 0.0058417998 | AR14: 0.67279042 | AT14: 2.1696739 | AU14: 0.10956448 | AV14: 4.1537186 | AZ14: 8.0002584 | BA14: 0.12573452 | BC14: 5.1968545 | BD14: 5.2151247 | BH14: 4.9673464 | BI14: 0.88218743 | BJ14: 4.811146 | BK14: 2.099751 | BP14: 0.059045167 | BQ14: 0.54207933 | BS14: 0.020552221 | BT14: 0.055197772 | BU14: 0.071940469 | BV14: 0.00022714592 | BY14: 4.2069775 | BZ14: 1.0783472 | CA14: 4.9676513 | CB14: 0.035434195 | CC14: 0.052023233 | CG14: 0.0036261816 | CI14: 3.663837 | CN14: 4.5437903 | CO14: 4.792002 | CP14: 0.49057812 | CQ14: 0.0015605468 | CS14: 1.5623116 | CT14: 0.30539641 | CX14: 0.089891155 | CY14: 0.40033831 | CZ14: 0.084841494 | DH14: 5.0521918 | DL14: 0.089799542 | DM14: 0.62668145 | DN14: 12.221641 | DT14: 1.6449366 | DU14: 4.9812905 | DW14: 0.97094645 | DX14: 0.096866629 | DZ14: 1.091342 | EA14: 0.0061350044 | EF14: 6.8673658 | EG14: 4.5092944 | EH14: 0.19859113 | EJ14: 4.4252821 | EM14: 1.9809985 | EN14: 2.0620476 | EO14: 1.7028227 | EQ14: 1.8555636 | ER14: 4.0751379 | EW14: 0.0056326444 | EX14: 0.48465888 | EZ14: 3.9557821 | FD14: 7.7194963 | FE14: 5.8521941 | FH14: 0.00014216802
A15: 37288 | E15: 0.0063974273 | F15: 2.6235239 | H15: 3.6991342 | I15: 6.0625538 | P15: 6.6481621 | Q15: 3.6444314 | V15: 73.609546 | X15: 172.23635 | Z15: 0.0030396802 | AB15: 0.0020417552 | AD15: 5.9913772 | AG15: 0.0064496735 | AH15: 0.75767033 | AI15: 0.0020241948 | AM15: 0.0094523088 | AP15: 0.20651468 | AQ15: 0.0077774405 | AR15: 0.90297397 | AT15: 2.9323758 | AU15: 0.14722908 | AV15: 5.6726486 | AZ15: 10.707539 | BA15: 0.16836035 | BC15: 6.9276713 | BD15: 6.9497352 | BH15: 6.6339619 | BI15: 1.1578806 | BJ15: 6.3357824 | BK15: 2.8275714 | BP15: 0.07971822 | BQ15: 0.73556339 | BS15: 0.027653786 | BT15: 0.075208637 | BU15: 0.096293227 | BV15: 0.00031490167 | BY15: 5.6333178 | BZ15: 1.4306197 | CA15: 6.634427 | CB15: 0.047807529 | CC15: 0.069489223 | CG15: 0.0049190812 | CI15: 4.8607663 | CN15: 6.0340204 | CO15: 6.4561236 | CP15: 0.66515153 | CQ15: 0.0020287972 | CS15: 2.1172788 | CT15: 0.4102332 | CX15: 0.12239715 | CY15: 0.54389019 | CZ15: 0.11403012 | DH15: 6.7608285 | DL15: 0.11956413 | DM15: 0.84978983 | DN15: 16.531303 | DT15: 2.1598749 | DU15: 6.6185978 | DW15: 1.3197364 | DX15: 0.13097529 | DZ15: 1.4761922 | EA15: 0.00822815 | EF15: 9.1742604 | EG15: 6.0568755 | EH15: 0.27417294 | EJ15: 5.8950765 | EM15: 2.6845746 | EN15: 2.7836265 | EO15: 2.2902239 | EQ15: 2.4843169 | ER15: 5.4029908 | EW15: 0.0074355615 | EX15: 0.65202292 | EZ15: 5.4860943 | FD15: 10.387519 | FE15: 7.9390876 | FH15: 0.00019568427
A16: 37316 | E16: 0.0075585249 | F16: 3.1098972 | H16: 4.3550955 | I16: 7.1871436 | P16: 7.8872583 | V16: 89.748671 | X16: 205.33408 | Z16: 0.0036292699 | AB16: 0.0024292405 | AD16: 7.1320455 | AG16: 0.0078001999 | AH16: 0.878965 | AI16: 0.002400649 | AM16: 0.011101874 | AP16: 0.24745226 | AQ16: 0.0092034778 | AR16: 1.0750129 | AT16: 3.4612056 | AU16: 0.17500439 | AV16: 6.7426371 | AZ16: 12.699398 | BA16: 0.19915411 | BC16: 8.2405512 | BD16: 8.2591192 | BH16: 7.8671468 | BI16: 1.3327842 | BJ16: 7.686233 | BK16: 3.3252995 | BP16: 0.093537206 | BQ16: 0.86552296 | BS16: 0.032800719 | BT16: 0.088759311 | BU16: 0.11355962 | BV16: 0.0003849207 | BY16: 6.7255691 | BZ16: 1.6856311 | CA16: 7.8699673 | CB16: 0.056285161 | CC16: 0.083297109 | CG16: 0.005798249 | CI16: 5.7737026 | CN16: 7.0927591 | CO16: 7.645187 | CP16: 0.77584402 | CQ16: 0.0025687855 | CS16: 2.5056864 | CT16: 0.47838153 | CX16: 0.14459658 | CY16: 0.6443637 | CZ16: 0.13146243 | DH16: 8.0706829 | DL16: 0.15307454 | DM16: 1.0182467 | DN16: 19.411714 | DT16: 2.5707589 | DU16: 7.8650068 | DW16: 1.5312732 | DX16: 0.15432041 | DZ16: 1.7333857 | EA16: 0.0097539385 | EF16: 10.865152 | EG16: 7.2136991 | EH16: 0.32458776 | EJ16: 7.0327803 | EM16: 3.1918757 | EN16: 3.2655218 | EO16: 2.6906523 | EQ16: 3.0075235 | ER16: 6.4363421 | EW16: 0.0089017617 | EX16: 0.76290472 | EZ16: 6.5250651 | FD16: 12.24146 | FE16: 9.3843036 | FH16: 0.00022681022
A17: 37347 | E17: 0.0081118759 | F17: 3.3568418 | H17: 4.7172397 | I17: 7.8685573 | P17: 8.6041193 | V17: 98.649241 | X17: 223.55971 | Z17: 0.0041543683 | AB17: 0.0025899697 | AD17: 7.7644761 | AG17: 0.0086031967 | AH17: 0.94488439 | AI17: 0.0026344532 | AM17: 0.011894953 | AP17: 0.27907837 | AQ17: 0.010068319 | AR17: 1.1755166 | AT17: 3.7386941 | AU17: 0.1841144 | AV17: 7.3789725 | AZ17: 13.981284 | BA17: 0.21357222 | BC17: 9.0244335 | BD17: 9.0413761 | BH17: 8.5703259 | BI17: 1.4074948 | BJ17: 8.4472589 | BK17: 3.5795525 | BP17: 0.1024337 | BQ17: 0.93577419 | BS17: 0.03644175 | BT17: 0.099658943 | BU17: 0.12225535 | BV17: 0.00043464498 | BY17: 7.4005702 | BZ17: 1.7921461 | CA17: 8.6048955 | CB17: 0.060797879 | CC17: 0.090176688 | CG17: 0.0063043741 | CI17: 6.3019484 | CN17: 7.7319561 | CO17: 8.3702394 | CP17: 0.83485138 | CQ17: 0.0029682714 | CS17: 2.6991333 | CT17: 0.5042998 | CX17: 0.1564148 | CY17: 0.69469215 | CZ17: 0.14386817 | DH17: 8.8435174 | DL17: 0.15584674 | DM17: 1.1257021 | DN17: 20.888295 | DT17: 2.8422064 | DU17: 8.6472984 | DW17: 1.6678827 | DX17: 0.16771713 | DZ17: 1.8671088 | EA17: 0.010637129 | EF17: 11.893383 | EG17: 7.9755628 | EH17: 0.37049018 | EJ17: 7.7742061 | EM17: 3.4651494 | EN17: 3.5106422 | EO17: 2.8930551 | EQ17: 3.2666915 | ER17: 7.0903995 | EW17: 0.009894795 | EX17: 0.82450005 | EZ17: 7.3858538 | FD17: 13.457885 | FE17: 10.175189 | FH17: 0.00024500752
A18: 37377 | E18: 0.0092258488 | F18: 3.7870547 | H18: 5.3503269 | I18: 9.1504399 | P18: 9.9923475 | Q18: 5.2582744 | V18: 103.59103 | X18: 254.25525 | Z18: 0.0044281342 | AB18: 0.0029073959 | AD18: 8.8933816 | AG18: 0.0096002715 | AH18: 1.0552898 | AI18: 0.0029079749 | AM18: 0.013292139 | AP18: 0.32116871 | AQ18: 0.011693292 | AR18: 1.3630506 | AT18: 4.1718375 | AU18: 0.20479197 | AV18: 8.3061892 | AZ18: 16.250399 | BA18: 0.23984801 | BC18: 10.487592 | BD18: 10.496845 | BH18: 9.9491673 | BI18: 1.5423079 | BJ18: 9.7941218 | BK18: 4.0097342 | BP18: 0.11446086 | BQ18: 1.0482925 | BS18: 0.042228701 | BT18: 0.11819608 | BU18: 0.1375973 | BV18: 0.00050840782 | BY18: 8.6322322 | BZ18: 1.9912776 | CA18: 10.003341 | CB18: 0.067566832 | CC18: 0.10500016 | CG18: 0.007384438 | CI18: 7.3205575 | CN18: 8.9344237 | CO18: 9.7346899 | CP18: 0.9329797 | CQ18: 0.0033805758 | CS18: 3.0264381 | CT18: 0.58088637 | CX18: 0.17600861 | CY18: 0.75032365 | CZ18: 0.16270617 | DH18: 10.257272 | DL18: 0.18092723 | DM18: 1.3279798 | DN18: 23.458978 | DT18: 3.1885741 | DU18: 10.093374 | DW18: 1.8808704 | DX18: 0.19058397 | DZ18: 2.0914932 | EA18: 0.012314159 | EF18: 13.816642 | EG18: 9.2761637 | EH18: 0.45318251 | EJ18: 9.0472385 | EM18: 3.8771914 | EN18: 3.9014857 | EO18: 3.2717453 | EQ18: 3.7541597 | ER18: 8.2809808 | EW18: 0.011636957 | EX18: 0.93380085 | EZ18: 7.8651799 | FD18: 15.290235 | FE18: 11.398017 | FH18: 0.00027475154
A19: 37408 | E19: 0.0096831163 | F19: 3.9778715 | H19: 5.6334085 | I19: 10.029813 | P19: 10.911632 | V19: 99.918746 | X19: 273.40805 | Z19: 0.0045576245 | AB19: 0.003076097 | AD19: 9.475552 | AG19: 0.009780028 | AH19: 1.0991173 | AI19: 0.0029993239 | AM19: 0.013931661 | AP19: 0.35305977 | AQ19: 0.012944116 | AR19: 1.4948401 | AT19: 4.3580216 | AU19: 0.21545385 | AV19: 8.7631064 | AZ19: 17.781199 | BA19: 0.25658501 | BC19: 11.460325 | BD19: 11.493234 | BH19: 10.894885 | BI19: 1.5894229 | BJ19: 10.705881 | BK19: 4.2750247 | BP19: 0.11936973 | BQ19: 1.1081857 | BS19: 0.046198968 | BT19: 0.12848678 | BU19: 0.14595581 | BV19: 0.00055612783 | BY19: 9.4666492 | BZ19: 2.1000639 | CA19: 10.963444 | CB19: 0.071180935 | CC19: 0.11281696 | CG19: 0.0080237153 | CI19: 7.9725288 | CN19: 9.7500934 | CO19: 10.67624 | CP19: 0.98139059 | CQ19: 0.0035211125 | CS19: 3.1838591 | CT19: 0.61148227 | CX19: 0.18581721 | CY19: 0.77226002 | CZ19: 0.16262795 | DH19: 11.194798 | DL19: 0.19633044 | DM19: 1.474678 | DN19: 24.56696 | DT19: 3.3559449 | DU19: 11.088472 | DW19: 2.0061247 | DX19: 0.2003742 | DZ19: 2.1936595 | EA19: 0.013374647 | EF19: 15.074459 | EG19: 10.134312 | EH19: 0.48267998 | EJ19: 9.9076396 | EM19: 4.0726124 | EN19: 4.0841329 | EO19: 3.5598355 | EQ19: 4.1535493 | ER19: 8.9729004 | EW19: 0.012681448 | EX19: 0.99692136 | EZ19: 7.590611 | FD19: 16.364691 | FE19: 11.985954 | FH19: 0.00028791873
A20: 37438 | E20: 0.0094529632 | F20: 3.8237473 | H20: 5.4231004 | I20: 9.9985278 | P20: 10.924006 | V20: 89.845787 | X20: 273.17038 | Z20: 0.0042922004 | AB20: 0.0029792755 | AD20: 9.0751315 | AG20: 0.009133313 | AH20: 1.0487606 | AI20: 0.0027185857 | AM20: 0.013460979 | AP20: 0.36111676 | AQ20: 0.012773647 | AR20: 1.4883187 | AT20: 4.1858696 | AU20: 0.20785123 | AV20: 8.4147353 | AZ20: 17.687277 | BA20: 0.25067888 | BC20: 11.414675 | BD20: 11.468336 | BH20: 10.88354 | BI20: 1.5115847 | BJ20: 10.499032 | BK20: 4.1124469 | BP20: 0.11182238 | BQ20: 1.0688346 | BS20: 0.045317752 | BT20: 0.12885347 | BU20: 0.14229259 | BV20: 0.00052407066 | BY20: 9.4045899 | BZ20: 2.1260495 | CA20: 10.958127 | CB20: 0.069394897 | CC20: 0.1130183 | CG20: 0.007937067 | CI20: 7.9230609 | CN20: 9.7021572 | CO20: 10.577896 | CP20: 0.94317416 | CQ20: 0.0033373122 | CS20: 3.0593124 | CT20: 0.58691699 | CX20: 0.18152935 | CY20: 0.73962368 | CZ20: 0.15465703 | DH20: 11.155312 | DL20: 0.1930622 | DM20: 1.4696273 | DN20: 23.70171 | DT20: 3.1371901 | DU20: 11.083427 | DW20: 1.9619603 | DX20: 0.19323118 | DZ20: 2.1143268 | EA20: 0.01347838 | EF20: 15.000252 | EG20: 10.166376 | EH20: 0.47104004 | EJ20: 9.8176162 | EM20: 3.9088649 | EN20: 3.9478918 | EO20: 3.43176 | EQ20: 4.0688214 | ER20: 8.9540923 | EW20: 0.012413612 | EX20: 0.96186111 | EZ20: 6.8319998 | FD20: 16.393674 | FE20: 11.52989 | FH20: 0.00027637922
A21: 37469 | E21: 0.0095385173 | F21: 3.7286812 | H21: 5.3228238 | I21: 9.6555962 | P21: 10.525196 | Q21: 5.2222649 | V21: 83.455638 | X21: 261.5779 | Z21: 0.0040321103 | AB21: 0.0029211823 | AD21: 8.7864605 | AG21: 0.0088905366 | AH21: 1.0288589 | AI21: 0.0025203828 | AM21: 0.013212247 | AP21: 0.33554618 | AQ21: 0.012303798 | AR21: 1.4361765 | AT21: 4.1198948 | AU21: 0.20510722 | AV21: 8.2662186 | AZ21: 16.96794 | BA21: 0.25287498 | BC21: 11.002136 | BD21: 11.079224 | BH21: 10.478384 | BI21: 1.4917407 | BJ21: 10.142237 | BK21: 4.0227971 | BP21: 0.10802547 | BQ21: 1.0467094 | BS21: 0.043807344 | BT21: 0.12456968 | BU21: 0.14055215 | BV21: 0.00051773893 | BY21: 9.1180983 | BZ21: 2.0935232 | CA21: 10.579855 | CB21: 0.067890684 | CC21: 0.11000541 | CG21: 0.0077405103 | CI21: 7.5783706 | CN21: 9.2985646 | CO21: 10.296546 | CP21: 0.92232739 | CQ21: 0.0032420742 | CS21: 2.9893505 | CT21: 0.56963436 | CX21: 0.17932944 | CY21: 0.72409051 | CZ21: 0.15167328 | DH21: 10.788192 | DL21: 0.18597246 | DM21: 1.4071206 | DN21: 23.182107 | DT21: 3.0121857 | DU21: 10.690737 | DW21: 1.9279784 | DX21: 0.18891397 | DZ21: 2.0722001 | EA21: 0.013122595 | EF21: 14.538227 | EG21: 9.806962 | EH21: 0.44336272 | EJ21: 9.4898978 | EM21: 3.8123297 | EN21: 3.9265304 | EO21: 3.5055041 | EQ21: 3.9303561 | ER21: 8.6161322 | EW21: 0.011796693 | EX21: 0.94832741 | EZ21: 6.8945427 | FD21: 15.897906 | FE21: 11.314694 | FH21: 0.00027013164
A22: 37500 | E22: 0.0099793964 | F22: 3.6969486 | H22: 5.326311 | I22: 9.6397074 | P22: 10.537198 | V22: 77.851091 | X22: 263.05783 | Z22: 0.0035574825 | AB22: 0.0028922507 | AD22: 8.7009694 | AG22: 0.0086201559 | AH22: 1.0341936 | AI22: 0.0024222331 | AM22: 0.013087655 | AP22: 0.33987039 | AQ22: 0.01229479 | AR22: 1.4409961 | AT22: 4.1093462 | AU22: 0.20700589 | AV22: 8.2745148 | AZ22: 16.953346 | BA22: 0.2552439 | BC22: 11.024108 | BD22: 11.080984 | BH22: 10.461141 | BI22: 1.5052926 | BJ22: 10.316727 | BK22: 4.0495451 | BP22: 0.10785016 | BQ22: 1.0376707 | BS22: 0.044265876 | BT22: 0.12259938 | BU22: 0.14058784 | BV22: 0.00051586511 | BY22: 9.1564064 | BZ22: 2.0461878 | CA22: 10.580182 | CB22: 0.068359624 | CC22: 0.10824668 | CG22: 0.0076692548 | CI22: 7.6241464 | CN22: 9.2303107 | CO22: 10.309838 | CP22: 0.91442987 | CQ22: 0.003241342 | CS22: 2.9780729 | CT22: 0.55572883 | CX22: 0.17970204 | CY22: 0.7093516 | CZ22: 0.1523825 | DH22: 10.887727 | DL22: 0.18676506 | DM22: 1.4263593 | DN22: 23.025705 | DT22: 3.0273572 | DU22: 10.66688 | DW22: 1.9290368 | DX22: 0.18836065 | DZ22: 2.0644881 | EA22: 0.013235937 | EF22: 14.554288 | EG22: 9.8654614 | EH22: 0.44465638 | EJ22: 9.5097344 | EM22: 3.792116 | EN22: 3.9003014 | EO22: 3.4313136 | EQ22: 3.9888807 | ER22: 8.6120711 | EW22: 0.011622981 | EX22: 0.93778867 | EZ22: 7.0538853 | FD22: 16.054998 | FE22: 11.279803 | FH22: 0.00026921436
A23: 37530 | E23: 0.0095065939 | F23: 3.7311704 | H23: 5.3294149 | I23: 9.6433173 | P23: 10.509088 | V23: 69.127725 | X23: 265.39876 | Z23: 0.003526704 | AB23: 0.0028796249 | AD23: 8.6998262 | AG23: 0.0084998011 | AH23: 1.0343398 | AI23: 0.002365627 | AM23: 0.013034873 | AP23: 0.33306249 | AQ23: 0.012350007 | AR23: 1.4412826 | AT23: 4.0997104 | AU23: 0.21263074 | AV23: 8.3124933 | AZ23: 17.020544 | BA23: 0.25628143 | BC23: 11.035662 | BD23: 11.081319 | BH23: 10.433349 | BI23: 1.5173676 | BJ23: 10.354338 | BK23: 4.0425557 | BP23: 0.10114373 | BQ23: 1.0360834 | BS23: 0.044488053 | BT23: 0.12277779 | BU23: 0.14112395 | BV23: 0.00050454512 | BY23: 9.1823108 | BZ23: 2.0437919 | CA23: 10.590549 | CB23: 0.067484193 | CC23: 0.10478124 | CG23: 0.0074329366 | CI23: 7.6706323 | CN23: 9.2755179 | CO23: 10.331558 | CP23: 0.91446068 | CQ23: 0.0032396816 | CS23: 2.9696886 | CT23: 0.56327458 | CX23: 0.18109001 | CY23: 0.70738443 | CZ23: 0.1534442 | DH23: 10.844442 | DL23: 0.187243 | DM23: 1.4339415 | DN23: 22.936582 | DP23: 9.1588925 | DT23: 3.0499992 | DU23: 10.719217 | DW23: 1.9499918 | DX23: 0.1896192 | DZ23: 2.0606687 | EA23: 0.013059103 | EF23: 14.532005 | EG23: 9.8956033 | EH23: 0.46210627 | EJ23: 9.5892602 | EM23: 3.7937176 | EN23: 3.8130908 | EO23: 3.3379486 | EQ23: 4.025468 | ER23: 8.6434506 | EW23: 0.011665117 | EX23: 0.9264748 | EZ23: 7.2543314 | FD23: 16.073368 | FE23: 11.277596 | FH23: 0.00026920654
A24: 37561 | E24: 0.0092443662 | F24: 3.5808821 | H24: 5.164761 | I24: 9.4643568 | P24: 10.316048 | Q24: 5.0339049 | V24: 72.945729 | X24: 261.14429 | Z24: 0.0035372096 | AB24: 0.0027759436 | AD24: 8.4327028 | AG24: 0.0085522377 | AH24: 0.99454822 | AI24: 0.0023794908 | AM24: 0.012564267 | AP24: 0.32557951 | AQ24: 0.01221817 | AR24: 1.4025983 | AT24: 3.9420911 | AU24: 0.20563575 | AV24: 8.0564303 | AZ24: 16.694454 | BA24: 0.24865214 | BC24: 10.80705 | BD24: 10.886039 | BH24: 10.214784 | BI24: 1.4550895 | BJ24: 10.174055 | BK24: 3.8934111 | BP24: 0.08506293 | BQ24: 0.99911614 | BS24: 0.044721195 | BT24: 0.12015269 | BU24: 0.13637511 | BV24: 0.00050159292 | BY24: 9.0204961 | BZ24: 1.9973379 | CA24: 10.438713 | CB24: 0.065229668 | CC24: 0.1019335 | CG24: 0.0073336521 | CI24: 7.5488283 | CN24: 9.1225323 | CO24: 10.158477 | CP24: 0.87662253 | CQ24: 0.0031655614 | CS24: 2.8666511 | CT24: 0.54143521 | CX24: 0.17495488 | CY24: 0.6791655 | CZ24: 0.14657727 | DH24: 10.621961 | DL24: 0.1842606 | DM24: 1.418056 | DN24: 22.188602 | DP24: 8.8243257 | DT24: 3.0569566 | DU24: 10.606665 | DW24: 1.9074425 | DX24: 0.1847739 | DZ24: 1.9854309 | EA24: 0.012884023 | EF24: 14.275916 | EG24: 9.7212187 | EH24: 0.46682546 | EJ24: 9.4347852 | EM24: 3.6369701 | EN24: 3.6701316 | EO24: 3.2388843 | EQ24: 3.9069501 | ER24: 8.4028627 | EW24: 0.011442599 | EX24: 0.89301611 | EZ24: 7.3976517 | FD24: 15.51472 | FE24: 10.85478 | FH24: 0.00025956973
A25: 37591 | E25: 0.0091962735 | F25: 3.5221183 | H25: 5.077425 | I25: 9.4867285 | P25: 10.316174 | V25: 72.205623 | X25: 263.75898 | Z25: 0.0034500013 | AB25: 0.0027239905 | AD25: 8.3200754 | AG25: 0.0084588473 | AH25: 0.98048572 | AI25: 0.0022719122 | AM25: 0.012332904 | AP25: 0.32108364 | AQ25: 0.012344411 | AR25: 1.4179788 | AT25: 3.8859314 | AU25: 0.20579468 | AV25: 7.946069 | AZ25: 16.660065 | BA25: 0.24672928 | BC25: 10.800672 | BD25: 10.898949 | BH25: 10.302233 | BI25: 1.4464737 | BJ25: 10.239549 | BK25: 3.8274004 | BP25: 0.082645842 | BQ25: 0.98422433 | BS25: 0.045104826 | BT25: 0.12179622 | BU25: 0.13333026 | BV25: 0.00050700835 | BY25: 9.0813689 | BZ25: 1.9575265 | CA25: 10.442245 | CB25: 0.063784212 | CC25: 0.10042063 | CG25: 0.0072596377 | CI25: 7.5596751 | CN25: 9.1503612 | CO25: 10.141777 | CP25: 0.86203671 | CQ25: 0.0031279153 | CS25: 2.8231381 | CT25: 0.53242101 | CX25: 0.17261228 | CY25: 0.67080231 | CZ25: 0.14633557 | DH25: 10.580121 | DL25: 0.18358167 | DM25: 1.4332401 | DN25: 21.831705 | DP25: 8.6563067 | DT25: 3.0416204 | DU25: 10.616055 | DW25: 1.8966235 | DX25: 0.18424873 | DZ25: 1.9535116 | EA25: 0.0128842 | EF25: 14.37339 | EG25: 9.7725983 | EH25: 0.51127187 | EJ25: 9.4614797 | EM25: 3.5932063 | EN25: 3.6398931 | EO25: 3.2240923 | EQ25: 3.9456536 | ER25: 8.4537552 | EW25: 0.011530772 | EX25: 0.88413325 | EZ25: 7.4727072 | FD25: 15.530936 | FE25: 10.645878 | FH25: 0.00025557016
A26: 37622 | E26: 0.0085455782 | F26: 3.2520879 | H26: 4.6963012 | I26: 9.1476144 | P26: 9.9725492 | V26: 71.834051 | X26: 255.94003 | Z26: 0.0033177826 | AB26: 0.002511829 | AD26: 7.836546 | AG26: 0.0075899462 | AH26: 0.91461287 | AI26: 0.0020490575 | AM26: 0.011363341 | AP26: 0.30783502 | AQ26: 0.011915389 | AR26: 1.3634817 | AT26: 3.5855885 | AU26: 0.19611427 | AV26: 7.5134713 | AZ26: 16.210108 | BA26: 0.23137446 | BC26: 10.407762 | BD26: 10.509533 | BH26: 9.9151171 | BI26: 1.4183529 | BJ26: 9.804413 | BK26: 3.5369322 | BP26: 0.073606015 | BQ26: 0.91129746 | BS26: 0.043205924 | BT26: 0.11849159 | BU26: 0.12329037 | BV26: 0.00047339597 | BY26: 8.7149768 | BZ26: 1.7552831 | CA26: 10.091708 | CB26: 0.05709519 | CC26: 0.095180381 | CG26: 0.0069108003 | CI26: 7.3422661 | CN26: 8.802944 | CO26: 9.6872111 | CP26: 0.79600881 | CQ26: 0.0029826894 | CS26: 2.6096991 | CT26: 0.4883437 | CX26: 0.16460207 | CY26: 0.59918597 | CZ26: 0.1371472 | DH26: 10.217776 | DL26: 0.17719016 | DM26: 1.4034549 | DN26: 20.081428 | DP26: 8.0024606 | DT26: 2.8750057 | DU26: 10.232238 | DW26: 1.7832831 | DX26: 0.17419095 | DZ26: 1.8023466 | EA26: 0.012326402 | EF26: 14.562689 | EG26: 9.4971868 | EH26: 0.48957824 | EJ26: 9.0684804 | EM26: 3.3245618 | EN26: 3.361559 | EO26: 3.0361759 | EQ26: 3.782652 | ER26: 8.1771811 | EW26: 0.011108588 | EX26: 0.81465122 | EZ26: 6.7657136 | FD26: 14.523084 | FE26: 9.8655241 | FH26: 0.0002373456
A27: 37653 | E27: 0.0083090964 | F27: 3.1851324 | H27: 4.5866742 | I27: 8.9542386 | P27: 9.8201211 | Q27: 4.4285721 | V27: 67.364702 | X27: 250.65823 | Z27: 0.0031057243 | AB27: 0.0024356084 | AD27: 7.7597563 | AG27: 0.0071523479 | AH27: 0.88977426 | AI27: 0.0019715921 | AM27: 0.010949277 | AP27: 0.30041643 | AQ27: 0.011729474 | AR27: 1.3470097 | AT27: 3.4566026 | AU27: 0.19012302 | AV27: 7.3000023 | AZ27: 15.913884 | BA27: 0.22517658 | BC27: 10.245237 | BD27: 10.348944 | BH27: 9.7507273 | BI27: 1.4862142 | BJ27: 9.5972825 | BK27: 3.4112175 | BP27: 0.065552959 | BQ27: 0.88626664 | BS27: 0.041693623 | BT27: 0.11677632 | BU27: 0.11960944 | BV27: 0.00045694439 | BY27: 8.5964492 | BZ27: 1.6891826 | CA27: 9.8853767 | CB27: 0.053270799 | CC27: 0.09101747 | CG27: 0.0066330598 | CI27: 7.2031111 | CN27: 8.5866106 | CO27: 9.6027847 | CP27: 0.76367615 | CQ27: 0.0029176501 | CS27: 2.5211565 | CT27: 0.46738072 | CX27: 0.16482864 | CY27: 0.56102982 | CZ27: 0.13265895 | DH27: 10.053787 | DL27: 0.17164126 | DM27: 1.3372823 | DN27: 19.304129 | DP27: 7.7161124 | DT27: 2.7527952 | DU27: 10.00484 | DW27: 1.7631997 | DX27: 0.17130625 | DZ27: 1.7360882 | EA27: 0.012027908 | EF27: 14.327415 | EG27: 9.3343418 | EH27: 0.49427863 | EJ27: 8.8871789 | EM27: 3.2219187 | EN27: 3.2252439 | EO27: 2.8987201 | EQ27: 3.7436824 | ER27: 7.9754374 | EW27: 0.010834862 | EX27: 0.78859218 | EZ27: 6.7540619 | FD27: 13.981785 | FE27: 9.5858048 | FH27: 0.00023411508
A28: 37681 | E28: 0.0081221249 | F28: 3.0605554 | H28: 4.4297746 | I28: 8.6892839 | P28: 9.5287049 | V28: 68.529176 | X28: 243.40826 | Z28: 0.0030605807 | AB28: 0.0023450774 | AD28: 7.6926651 | AG28: 0.0069982182 | AH28: 0.85317685 | AI28: 0.0019170466 | AM28: 0.010537815 | AP28: 0.28923538 | AQ28: 0.011368095 | AR28: 1.3135225 | AT28: 3.3403623 | AU28: 0.14957748 | AV28: 7.08166 | AZ28: 15.434907 | BA28: 0.22011227 | BC28: 9.9411989 | BD28: 10.054706 | BH28: 9.4459062 | BI28: 1.4613125 | BJ28: 9.4978137 | BK28: 3.2943091 | BP28: 0.068153419 | BQ28: 0.85451963 | BS28: 0.040608613 | BT28: 0.11328685 | BU28: 0.11630845 | BV28: 0.00043837414 | BY28: 8.3779296 | BZ28: 1.6607476 | CA28: 9.5973432 | CB28: 0.050003211 | CC28: 0.088618866 | CG28: 0.0062579959 | CI28: 7.0077752 | CN28: 8.329816 | CO28: 9.3183939 | CP28: 0.73547852 | CQ28: 0.0027916248 | CS28: 2.4273711 | CT28: 0.45309146 | CX28: 0.1610577 | CY28: 0.54356474 | CZ28: 0.12749155 | DH28: 9.8214564 | DL28: 0.16617243 | DM28: 1.2344268 | DN28: 18.659543 | DP28: 7.4508006 | DT28: 2.5692901 | DU28: 9.6880522 | DW28: 1.7059601 | DX28: 0.16830272 | DZ28: 1.6747213 | EA28: 0.011594064 | EF28: 13.923548 | EG28: 9.0967179 | EH28: 0.49477085 | EJ28: 8.6593757 | EM28: 3.1150271 | EN28: 3.0834044 | EO28: 2.7778311 | EQ28: 3.6085501 | ER28: 7.7257938 | EW28: 0.010466734 | EX28: 0.76420214 | EZ28: 6.5033059 | FD28: 13.31613 | FE28: 9.30252 | FH28: 0.00022435362
A29: 37712 | E29: 0.0078739194 | F29: 2.8628539 | H29: 4.1547277 | I29: 8.1902965 | P29: 8.9675558 | V29: 71.880424 | X29: 230.19445 | Z29: 0.0028786459 | AB29: 0.0021920096 | AD29: 7.2670177 | AG29: 0.0068002741 | AH29: 0.80030034 | AI29: 0.0018427438 | AM29: 0.0099166546 | AP29: 0.27476086 | AQ29: 0.010810758 | AR29: 1.2377126 | AT29: 3.1197243 | AU29: 0.13473685 | AV29: 6.7207424 | AZ29: 14.539858 | BA29: 0.20967626 | BC29: 9.3676354 | BD29: 9.4728018 | BH29: 8.8820872 | BI29: 1.3660743 | BJ29: 8.9690973 | BK29: 3.0943834 | BP29: 0.06729173 | BQ29: 0.80391033 | BS29: 0.038380526 | BT29: 0.10798216 | BU29: 0.11129836 | BV29: 0.00041948289 | BY29: 7.9267489 | BZ29: 1.6135718 | CA29: 9.0771818 | CB29: 0.046111933 | CC29: 0.082675703 | CG29: 0.0058692681 | CI29: 6.6324793 | CN29: 7.8623918 | CO29: 8.786187 | CP29: 0.69149484 | CQ29: 0.0025604137 | CS29: 2.2858581 | CT29: 0.42233348 | CX29: 0.15316959 | CY29: 0.52670078 | CZ29: 0.11925906 | DH29: 9.2751945 | DL29: 0.15924889 | DM29: 1.1577618 | DN29: 17.520234 | DP29: 7.00296 | DT29: 2.4451636 | DU29: 9.2106353 | DW29: 1.5932811 | DX29: 0.16103711 | DZ29: 1.5724583 | EA29: 0.010867129 | EF29: 13.158852 | EG29: 8.6251112 | EH29: 0.48502653 | EJ29: 8.2362963 | EM29: 2.9195746 | EN29: 2.8951654 | EO29: 2.2430775 | EQ29: 3.4183908 | ER29: 7.1803177 | EW29: 0.0099700208 | EX29: 0.72266621 | EZ29: 6.3185585 | FD29: 12.512947 | FE29: 8.7243926 | FH29: 0.00021052738
A30: 37742 | E30: 0.0078285142 | F30: 2.8261181 | H30: 4.0856427 | I30: 8.6150694 | P30: 9.4066576 | Q30: 3.964574 | V30: 75.176416 | X30: 241.56372 | Z30: 0.0029019961 | AB30: 0.0021394752 | AD30: 7.5492801 | AG30: 0.0068130266 | AH30: 0.78294316 | AI30: 0.0018673769 | AM30: 0.0097437645 | AP30: 0.29128958 | AQ30: 0.011443126 | AR30: 1.2979158 | AT30: 3.0707442 | AU30: 0.12485627 | AV30: 6.6328741 | AZ30: 15.246698 | BA30: 0.20713565 | BC30: 9.8413208 | BD30: 9.9522792 | BH30: 9.3218371 | BI30: 1.3556101 | BJ30: 9.4735588 | BK30: 3.0587274 | BP30: 0.06958378 | BQ30: 0.79094336 | BS30: 0.040418962 | BT30: 0.11222668 | BU30: 0.11055834 | BV30: 0.00043364718 | BY30: 8.3260435 | BZ30: 1.6327433 | CA30: 9.5715263 | CB30: 0.043098625 | CC30: 0.083375118 | CG30: 0.0059308226 | CI30: 6.9885384 | CN30: 8.2577227 | CO30: 9.2451123 | CP30: 0.68064739 | CQ30: 0.002629462 | CS30: 2.2541471 | CT30: 0.42462485 | CX30: 0.15147927 | CY30: 0.53648648 | CZ30: 0.12128363 | DH30: 9.7491473 | DL30: 0.16752631 | DM30: 1.2041477 | DN30: 17.365544 | DP30: 6.8854182 | DT30: 2.5456952 | DU30: 9.742888 | DW30: 1.6355155 | DX30: 0.16143444 | DZ30: 1.5507352 | EA30: 0.011362764 | EF30: 13.853119 | EG30: 9.1161318 | EH30: 0.47983092 | EJ30: 8.6554241 | EM30: 2.8941269 | EN30: 2.8723104 | EO30: 2.6297334 | EQ30: 3.5916405 | ER30: 7.4347148 | EW30: 0.010720587 | EX30: 0.71383333 | EZ30: 6.8229414 | FD30: 12.708419 | FE30: 8.5810842 | FH30: 0.00020685228
A31: 37773 | E31: 0.007827874 | F31: 2.7962885 | H31: 4.051693 | I31: 8.6090686 | P31: 9.4094451 | V31: 76.220704 | X31: 234.97433 | Z31: 0.0028719727 | AB31: 0.0021030988 | AD31: 7.6556623 | AG31: 0.0066949406 | AH31: 0.76617574 | AI31: 0.0018695491 | AM31: 0.0096313034 | AP31: 0.2902222 | AQ31: 0.011450922 | AR31: 1.296528 | AT31: 3.0400241 | AU31: 0.11532785 | AV31: 6.5561081 | AZ31: 15.136626 | BA31: 0.20931896 | BC31: 9.8047066 | BD31: 9.9454112 | BH31: 9.3290219 | BI31: 1.3480488 | BJ31: 9.4317213 | BK31: 3.0281394 | BP31: 0.070484662 | BQ31: 0.78296184 | BS31: 0.038061365 | BT31: 0.10950996 | BU31: 0.11103418 | BV31: 0.00043922424 | BY31: 8.3163098 | BZ31: 1.6425818 | CA31: 9.5546342 | CB31: 0.044893527 | CC31: 0.081632484 | CG31: 0.0058866808 | CI31: 7.0186745 | CN31: 8.2436422 | CO31: 9.2212244 | CP31: 0.67281579 | CQ31: 0.0026225845 | CS31: 2.2305672 | CT31: 0.41919474 | CX31: 0.14613059 | CY31: 0.51942333 | CZ31: 0.1222352 | DH31: 9.6791951 | DL31: 0.1667548 | DM31: 1.1554781 | DN31: 17.20038 | DP31: 6.8267506 | DT31: 2.48704 | DU31: 9.7172428 | DW31: 1.6281969 | DX31: 0.16349479 | DZ31: 1.5375484 | EA31: 0.011315524 | EF31: 13.876222 | EG31: 9.1161362 | EH31: 0.461774 | EJ31: 8.6388318 | EM31: 2.8601841 | EN31: 2.8733565 | EO31: 2.6765572 | EQ31: 3.587475 | ER31: 7.3072348 | EW31: 0.010711774 | EX31: 0.70967904 | EZ31: 7.1148309 | FD31: 12.863186 | FE31: 8.5087328 | FH31: 0.00020416472
A32: 37803 | E32: 0.0076394971 | F32: 2.7987412 | H32: 4.033326 | I32: 8.3305823 | P32: 9.1307874 | V32: 75.954998 | X32: 229.6212 | Z32: 0.0028272771 | AB32: 0.0021090434 | AD32: 7.451024 | AG32: 0.0067208755 | AH32: 0.75726183 | AI32: 0.0018337199 | AM32: 0.0095597556 | AP32: 0.27734884 | AQ32: 0.010961794 | AR32: 1.2473046 | AT32: 3.0974173 | AU32: 0.099131284 | AV32: 6.5146777 | AZ32: 14.683648 | BA32: 0.21027445 | BC32: 9.4468578 | BD32: 9.6225242 | BH32: 9.0559704 | BI32: 1.3416043 | BJ32: 8.9590333 | BK32: 3.0109759 | BP32: 0.069102958 | BQ32: 0.77694542 | BS32: 0.036524818 | BT32: 0.10432796 | BU32: 0.11235699 | BV32: 0.00042938504 | BY32: 7.9978533 | BZ32: 1.6250909 | CA32: 9.2694823 | CB32: 0.04527991 | CC32: 0.080631487 | CG32: 0.0059037863 | CI32: 6.7747134 | CN32: 7.9209781 | CO32: 8.8545101 | CP32: 0.66220517 | CQ32: 0.0025333613 | CS32: 2.2199874 | CT32: 0.41762784 | CX32: 0.13935856 | CY32: 0.51928506 | CZ32: 0.12356797 | DH32: 9.3829309 | DL32: 0.16124379 | DM32: 1.0982484 | DN32: 17.034383 | DP32: 6.7881294 | DT32: 2.3921855 | DU32: 9.3841859 | DW32: 1.6337345 | DX32: 0.16421582 | DZ32: 1.5366372 | EA32: 0.011080456 | EF32: 13.428635 | EG32: 8.8717985 | EH32: 0.4778116 | EJ32: 8.314801 | EM32: 2.8347909 | EN32: 2.8655201 | EO32: 2.7920278 | EQ32: 3.4375206 | ER32: 6.988946 | EW32: 0.010194402 | EX32: 0.70815299 | EZ32: 7.0842956 | FD32: 12.485872 | FE32: 8.4613545 | FH32: 0.00020188579
A33: 37834 | E33: 0.0079183107 | F33: 2.9292633 | H33: 4.2102992 | I33: 8.5482592 | P33: 9.3685649 | Q33: 4.101278 | V33: 76.36148 | X33: 236.66777 | Z33: 0.0028895787 | AB33: 0.0021945029 | AD33: 7.7274051 | AG33: 0.007006267 | AH33: 0.79662906 | AI33: 0.0019160546 | AM33: 0.0099461484 | AP33: 0.27937742 | AQ33: 0.011253404 | AR33: 1.2766576 | AT33: 3.2542481 | AU33: 0.10896452 | AV33: 6.8097247 | AZ33: 15.024727 | BA33: 0.22188153 | BC33: 9.6792266 | BD33: 9.8693892 | BH33: 9.2663268 | BI33: 1.431386 | BJ33: 9.1633846 | BK33: 3.1520064 | BP33: 0.075485045 | BQ33: 0.81520675 | BS33: 0.037945896 | BT33: 0.10523046 | BU33: 0.11765967 | BV33: 0.0004437237 | BY33: 8.2303281 | BZ33: 1.6409582 | CA33: 9.5081011 | CB33: 0.04796392 | CC33: 0.08430916 | CG33: 0.0062119799 | CI33: 6.8571801 | CN33: 8.0464007 | CO33: 9.1805609 | CP33: 0.69187537 | CQ33: 0.0026163672 | CS33: 2.3168821 | CT33: 0.43492862 | CX33: 0.14709185 | CY33: 0.52943082 | CZ33: 0.13045258 | DH33: 9.631235 | DL33: 0.16525221 | DM33: 1.1315314 | DN33: 17.812894 | DP33: 7.098277 | DT33: 2.4820921 | DU33: 9.6068359 | DW33: 1.6761559 | DX33: 0.17091122 | DZ33: 1.6020008 | EA33: 0.011452696 | EF33: 13.880653 | EG33: 9.0451889 | EH33: 0.5104627 | EJ33: 8.5470498 | EM33: 2.9463746 | EN33: 3.0022876 | EO33: 2.9189684 | EQ33: 3.4956877 | ER33: 7.1897708 | EW33: 0.010205052 | EX33: 0.73902527 | EZ33: 7.4909968 | FD33: 12.83078 | FE33: 8.8727751 | FH33: 0.00021056633
A34: 37865 | E34: 0.0086354657 | F34: 2.918072 | H34: 4.2165197 | I34: 8.6050841 | P34: 9.440077 | V34: 78.84408 | X34: 239.74648 | Z34: 0.0028461248 | AB34: 0.0021864054 | AD34: 7.9053183 | AG34: 0.0072944671 | AH34: 0.80401462 | AI34: 0.0019333312 | AM34: 0.0098518584 | AP34: 0.27898948 | AQ34: 0.011162291 | AR34: 1.2912637 | AT34: 3.2448888 | AU34: 0.11674831 | AV34: 6.8451502 | AZ34: 15.131336 | BA34: 0.22095675 | BC34: 9.7651473 | BD34: 9.9538386 | BH34: 9.2999936 | BI34: 1.408332 | BJ34: 9.3823398 | BK34: 3.1512909 | BP34: 0.07733283 | BQ34: 0.81299323 | BS34: 0.038912493 | BT34: 0.10655879 | BU34: 0.11756405 | BV34: 0.00044818997 | BY34: 8.2811808 | BZ34: 1.6504979 | CA34: 9.568908 | CB34: 0.04820424 | CC34: 0.086826653 | CG34: 0.0063170367 | CI34: 6.9214051 | CN34: 8.0549732 | CO34: 9.2653229 | CP34: 0.69480416 | CQ34: 0.0026459678 | CS34: 2.3150958 | CT34: 0.42982968 | CX34: 0.14797551 | CY34: 0.52178027 | CZ34: 0.13562367 | DH34: 9.772028 | DL34: 0.16592564 | DM34: 1.1496523 | DN34: 17.8368 | DP34: 7.0651132 | DT34: 2.447542 | DU34: 9.6708005 | DW34: 1.6851428 | DX34: 0.16964857 | DZ34: 1.600936 | EA34: 0.011664882 | EF34: 14.028743 | EG34: 9.1139908 | EH34: 0.51158533 | EJ34: 8.6132492 | EM34: 2.9285073 | EN34: 2.9824891 | EO34: 2.7660936 | EQ34: 3.6029031 | ER34: 7.2152426 | EW34: 0.010145934 | EX34: 0.73646179 | EZ34: 7.7139117 | FD34: 12.958987 | FE34: 8.8777272 | FH34: 0.00020996775
A35: 37895 | E35: 0.0087180734 | F35: 2.8425608 | H35: 4.0980931 | I35: 8.6989928 | P35: 9.5301992 | V35: 78.512744 | X35: 244.85787 | Z35: 0.0029099028 | AB35: 0.0021277118 | AD35: 7.9021665 | AG35: 0.0074016548 | AH35: 0.78864002 | AI35: 0.0018570007 | AM35: 0.0096077617 | AP35: 0.28602476 | AQ35: 0.011230604 | AR35: 1.3046684 | AT35: 3.1509685 | AU35: 0.10657325 | AV35: 6.6542575 | AZ35: 15.349062 | BA35: 0.21362004 | BC35: 9.8799843 | BD35: 10.102819 | BH35: 9.4192083 | BI35: 1.4245996 | BJ35: 9.5367653 | BK35: 3.0655922 | BP35: 0.076241379 | BQ35: 0.79092306 | BS35: 0.039720955 | BT35: 0.10811477 | BU35: 0.11636629 | BV35: 0.00043781433 | BY35: 8.3873356 | BZ35: 1.6104902 | CA35: 9.6994748 | CB35: 0.047112378 | CC35: 0.088724633 | CG35: 0.006145595 | CI35: 7.0708851 | CN35: 8.1703816 | CO35: 9.3783765 | CP35: 0.67924072 | CQ35: 0.0026025403 | CS35: 2.2526319 | CT35: 0.42436722 | CX35: 0.14632637 | CY35: 0.49791546 | CZ35: 0.13790425 | DH35: 9.8699694 | DL35: 0.16859355 | DM35: 1.1604251 | DN35: 17.338952 | DP35: 6.8473333 | DT35: 2.4286918 | DU35: 9.8479913 | DW35: 1.6952684 | DX35: 0.16893916 | DZ35: 1.553108 | EA35: 0.011770622 | EF35: 14.220454 | EG35: 9.2605214 | EH35: 0.51888917 | EJ35: 8.782467 | EM35: 2.8596793 | EN35: 2.9163654 | EO35: 2.701277 | EQ35: 3.6771183 | ER35: 7.3432737 | EW35: 0.010271253 | EX35: 0.719363 | EZ35: 7.2744536 | FD35: 13.131214 | FE35: 8.6206185 | FH35: 0.00020322817
A36: 37926 | E36: 0.0090209525 | F36: 2.8859093 | H36: 4.1358809 | I36: 8.7924655 | P36: 9.6324573 | Q36: 4.0418341 | V36: 77.982672 | X36: 251.52129 | Z36: 0.0029842229 | AB36: 0.0021424524 | AD36: 8.0448531 | AG36: 0.0076829284 | AH36: 0.80286877 | AI36: 0.0018991771 | AM36: 0.0097381678 | AP36: 0.28992101 | AQ36: 0.01131583 | AR36: 1.3149362 | AT36: 3.1690448 | AU36: 0.099722122 | AV36: 6.7297307 | AZ36: 15.460831 | BA36: 0.21080803 | BC36: 9.9578742 | BD36: 10.204148 | BH36: 9.4812971 | BI36: 1.4404603 | BJ36: 9.6392888 | BK36: 3.0923261 | BP36: 0.076639076 | BQ36: 0.79901121 | BS36: 0.039687298 | BT36: 0.10975198 | BU36: 0.11717938 | BV36: 0.00044171927 | BY36: 8.4615091 | BZ36: 1.6045865 | CA36: 9.8091782 | CB36: 0.047922636 | CC36: 0.089285826 | CG36: 0.0060864916 | CI36: 7.1713063 | CN36: 8.28172 | CO36: 9.4843821 | CP36: 0.68201464 | CQ36: 0.0026024977 | CS36: 2.2727747 | CT36: 0.41506597 | CX36: 0.14928778 | CY36: 0.50859881 | CZ36: 0.13963854 | DH36: 9.9320858 | DL36: 0.17087152 | DM36: 1.1766839 | DN36: 17.494851 | DP36: 6.9088786 | DT36: 2.4382388 | DU36: 9.9626479 | DW36: 1.6851405 | DX36: 0.17394637 | DZ36: 1.565499 | EA36: 0.011751925 | EF36: 14.370183 | EG36: 9.3651887 | EH36: 0.53428093 | EJ36: 8.889019 | EM36: 2.874361 | EN36: 2.9597672 | EO36: 2.8421356 | EQ36: 3.7079174 | ER36: 7.342787 | EW36: 0.010322825 | EX36: 0.72738973 | EZ36: 7.2015009 | FD36: 13.336121 | FE36: 8.6659107 | FH36: 0.00020520897
A37: 37956 | E37: 0.0097074711 | F37: 2.9470327 | H37: 4.2683429 | I37: 9.5232417 | P37: 10.406978 | V37: 80.401577 | X37: 276.62463 | Z37: 0.003073007 | AB37: 0.0022177897 | AD37: 8.2903719 | AG37: 0.0081808824 | AH37: 0.83168106 | AI37: 0.001993702 | AM37: 0.010070009 | AP37: 0.31054156 | AQ37: 0.012228051 | AR37: 1.4176986 | AT37: 3.2840974 | AU37: 0.113314 | AV37: 6.9268908 | AZ37: 16.688481 | BA37: 0.21312471 | BC37: 10.774487 | BD37: 11.043162 | BH37: 10.330298 | BI37: 1.4830333 | BJ37: 10.465757 | BK37: 3.1971192 | BP37: 0.079304832 | BQ37: 0.82269603 | BS37: 0.042074152 | BT37: 0.11760106 | BU37: 0.12000913 | BV37: 0.00046020489 | BY37: 9.1864389 | BZ37: 1.6853868 | CA37: 10.613127 | CB37: 0.049354981 | CC37: 0.09310915 | CG37: 0.0062529554 | CI37: 7.7672131 | CN37: 8.9530204 | CO37: 10.264064 | CP37: 0.70197783 | CQ37: 0.0027863603 | CS37: 2.3470267 | CT37: 0.42519697 | CX37: 0.16241721 | CY37: 0.51903551 | CZ37: 0.14685614 | DH37: 10.668708 | DL37: 0.18556522 | DM37: 1.2652527 | DN37: 17.942444 | DP37: 7.0999658 | DT37: 2.6221618 | DU37: 10.776639 | DW37: 1.8136093 | DX37: 0.18339114 | DZ37: 1.6152883 | EA37: 0.012585516 | EF37: 15.561231 | EG37: 10.137475 | EH37: 0.5689658 | EJ37: 9.6261959 | EM37: 2.9681613 | EN37: 3.0566162 | EO37: 2.8913994 | EQ37: 3.9998209 | ER37: 7.9563159 | EW37: 0.011235745 | EX37: 0.74807408 | EZ37: 7.6794851 | FD37: 14.268094 | FE37: 8.913786 | FH37: 0.00021294372
A38: 37987 | E38: 0.0096408526 | F38: 2.8569243 | H38: 4.1844705 | I38: 9.5707893 | P38: 10.480348 | V38: 81.268437 | X38: 281.88245 | Z38: 0.0029210144 | AB38: 0.0021732393 | AD38: 8.221101 | AG38: 0.0083933497 | AH38: 0.8223106 | AI38: 0.0020085125 | AM38: 0.0099511586 | AP38: 0.3136084 | AQ38: 0.012362281 | AR38: 1.4251566 | AT38: 3.2210397 | AU38: 0.098144542 | AV38: 6.8020942 | AZ38: 16.847134 | BA38: 0.2068499 | BC38: 10.788269 | BD38: 11.087886 | BH38: 10.372135 | BI38: 1.5270634 | BJ38: 10.439395 | BK38: 3.1301382 | BP38: 0.077366861 | BQ38: 0.80944012 | BS38: 0.043221269 | BT38: 0.12104046 | BU38: 0.11817636 | BV38: 0.00045855114 | BY38: 9.1716059 | BZ38: 1.6344939 | CA38: 10.673422 | CB38: 0.048691485 | CC38: 0.092085055 | CG38: 0.0061982832 | CI38: 7.8918143 | CN38: 8.9875233 | CO38: 10.232303 | CP38: 0.69014118 | CQ38: 0.0025629793 | CS38: 2.2953315 | CT38: 0.41571812 | CX38: 0.16592724 | CY38: 0.5262761 | CZ38: 0.14596462 | DD38: 0.10126839 | DH38: 10.713216 | DL38: 0.1867508 | DM38: 1.2176998 | DN38: 17.509979 | DP38: 6.9714413 | DT38: 2.6021892 | DU38: 10.820934 | DW38: 1.8172909 | DX38: 0.18574422 | DY38: 0.0082275031 | DZ38: 1.5844974 | EA38: 0.012661153 | EF38: 16.31375 | EG38: 10.216258 | EH38: 0.52083655 | EJ38: 9.5974025 | EM38: 2.8978708 | EN38: 3.0269476 | EO38: 2.8274883 | EQ38: 3.9573021 | ER38: 7.9098075 | EW38: 0.01139982 | EX38: 0.7334299 | EZ38: 8.0200606 | FD38: 14.466568 | FE38: 8.760023 | FH38: 0.00021018147
A39: 38018 | E39: 0.010001848 | F39: 2.9448561 | H39: 4.2490514 | I39: 9.750881 | P39: 10.677254 | Q39: 4.1573347 | V39: 80.555549 | X39: 286.94982 | Z39: 0.0029544026 | AB39: 0.0022026888 | AD39: 8.1317802 | AG39: 0.0083424875 | AH39: 0.83077896 | AI39: 0.002081305 | AM39: 0.010127769 | AP39: 0.31784176 | AQ39: 0.012537325 | AR39: 1.456566 | AT39: 3.2520179 | AU39: 0.10220545 | AV39: 6.9332412 | AZ39: 17.166003 | BA39: 0.21100431 | BC39: 11.011828 | BD39: 11.301832 | BH39: 10.551172 | BI39: 1.5472292 | BJ39: 10.563259 | BK39: 3.1679868 | BP39: 0.078200836 | BQ39: 0.82542267 | BS39: 0.044689877 | BT39: 0.12379408 | BU39: 0.12012447 | BV39: 0.00046104375 | BY39: 9.388483 | BZ39: 1.6420989 | CA39: 10.859971 | CB39: 0.049350341 | CC39: 0.093189409 | CG39: 0.0063977724 | CI39: 8.0667351 | CN39: 9.1010977 | CO39: 10.52021 | CP39: 0.69800585 | CQ39: 0.0024518323 | CS39: 2.3258662 | CT39: 0.42021496 | CX39: 0.17119619 | CY39: 0.53196586 | CZ39: 0.15252742 | DD39: 0.10233517 | DH39: 10.92286 | DL39: 0.18745386 | DM39: 1.2111379 | DN39: 17.690749 | DP39: 7.0574605 | DT39: 2.5687599 | DU39: 10.966699 | DW39: 1.8804057 | DX39: 0.19261472 | DY39: 0.0084328945 | DZ39: 1.6056635 | EA39: 0.012895165 | EF39: 16.690636 | EG39: 10.382791 | EH39: 0.54519954 | EJ39: 9.745932 | EM39: 2.9253353 | EN39: 3.026176 | EO39: 2.9318253 | EQ39: 3.9896782 | ER39: 7.9895678 | EW39: 0.011542444 | EX39: 0.74263783 | EZ39: 8.2827775 | FD39: 15.050192 | FE39: 8.9159951 | FH39: 0.00021834992
A40: 38047 | E40: 0.010001445 | F40: 2.9083794 | H40: 4.1830427 | I40: 9.3141096 | P40: 10.174824 | V40: 80.117671 | X40: 273.00933 | Z40: 0.0030447943 | AB40: 0.0021833265 | AD40: 8.015944 | AG40: 0.0079558545 | AH40: 0.81786657 | AI40: 0.0020995092 | AM40: 0.0099109083 | AP40: 0.3013323 | AQ40: 0.012036906 | AR40: 1.3916064 | AT40: 3.1949744 | AU40: 0.10976439 | AV40: 6.8526359 | AZ40: 16.361147 | BA40: 0.20999933 | BC40: 10.443603 | BD40: 10.798106 | BH40: 10.074374 | BI40: 1.5042487 | BJ40: 10.301333 | BK40: 3.1325777 | BP40: 0.083834128 | BQ40: 0.80914155 | BS40: 0.044400569 | BT40: 0.1178913 | BU40: 0.11856465 | BV40: 0.00044561005 | BY40: 8.972242 | BZ40: 1.5953655 | CA40: 10.36833 | CB40: 0.048636081 | CC40: 0.089905152 | CG40: 0.0063423689 | CI40: 7.7538204 | CN40: 8.70501 | CO40: 10.01587 | CP40: 0.68224726 | CQ40: 0.0022613445 | CS40: 2.2806986 | CT40: 0.4123221 | CX40: 0.16429378 | CY40: 0.5245873 | CZ40: 0.15388105 | DD40: 0.10142631 | DH40: 10.485208 | DL40: 0.17842865 | DM40: 1.1895139 | DN40: 17.434194 | DP40: 6.9131575 | DT40: 2.4991976 | DU40: 10.460579 | DW40: 1.8220359 | DX40: 0.19035182 | DY40: 0.0083628583 | DZ40: 1.5728105 | EA40: 0.012259404 | EF40: 15.908765 | EG40: 9.94235 | EH40: 0.54784386 | EJ40: 9.3394254 | EM40: 2.8842797 | EN40: 2.9875035 | EO40: 2.8414731 | EQ40: 3.801459 | ER40: 7.6610961 | EW40: 0.010916392 | EX40: 0.73054114 | EZ40: 8.2646008 | FD40: 14.477816 | FE40: 8.8075743 | FH40: 0.00021567152
...

Sheet TCRB_2001.12-100
